I1003 08:32:06.957692       1 log.go:194] css-host-128 has 4 gpu, falcon-pod-01 requires 8 gpu -> score: -4
I1003 08:32:06.957716       1 log.go:194] css-host-129 has 4 gpu, falcon-pod-01 requires 8 gpu -> score: -4
I1003 08:32:06.968861       1 event.go:307] "Event occurred" object="default/falcon-pod-01" fieldPath="" kind="Pod" apiVersion="v1" type="Normal" reason="Reconfig" message="Pod falcon-pod-01 needs reconfiguration"
I1003 08:34:16.661234       1 schedule_one.go:252] "Successfully bound pod to node" pod="default/falcon-pod-01" node="css-host-128" evaluatedNodes=2 feasibleNodes=2
I1003 08:37:13.750000       1 log.go:194] falcon-pod-02 in Prefilter
I1003 08:37:13.750525       1 log.go:194] falcon-pod-02 requires 4 gpu(s), and currently has 8 gpus(s) in total
I1003 08:37:13.758044       1 log.go:194] css-host-129 has 0 gpu, falcon-pod-02 requires 4 gpu -> score: -4
I1003 08:37:13.758077       1 log.go:194] css-host-128 has 8 gpu, falcon-pod-02 requires 4 gpu -> score: 50
I1003 08:37:13.766541       1 schedule_one.go:252] "Successfully bound pod to node" pod="default/falcon-pod-02" node="css-host-128" evaluatedNodes=2 feasibleNodes=2
I1003 08:37:42.977984       1 log.go:194] falcon-pod-03 in Prefilter
I1003 08:37:42.978449       1 log.go:194] falcon-pod-03 requires 4 gpu(s), and currently has 4 gpus(s) in total
I1003 08:37:42.998158       1 event.go:307] "Event occurred" object="default/falcon-pod-03" fieldPath="" kind="Pod" apiVersion="v1" type="Normal" reason="Reconfig" message="Pod falcon-pod-03 needs reconfiguration"
I1003 08:39:48.683404       1 schedule_one.go:252] "Successfully bound pod to node" pod="default/falcon-pod-03" node="css-host-129" evaluatedNodes=2 feasibleNodes=1
I1003 08:42:35.112387       1 log.go:194] falcon-pod-01 in Prefilter
I1003 08:42:35.112923       1 log.go:194] falcon-pod-01 requires 8 gpu(s), and currently has 8 gpus(s) in total
I1003 08:42:35.119644       1 log.go:194] css-host-128 has 4 gpu, falcon-pod-01 requires 8 gpu -> score: -4
I1003 08:42:35.119686       1 log.go:194] css-host-129 has 4 gpu, falcon-pod-01 requires 8 gpu -> score: -4
I1003 08:42:35.130503       1 event.go:307] "Event occurred" object="default/falcon-pod-01" fieldPath="" kind="Pod" apiVersion="v1" type="Normal" reason="Reconfig" message="Pod falcon-pod-01 needs reconfiguration"
I1003 08:44:40.452691       1 schedule_one.go:252] "Successfully bound pod to node" pod="default/falcon-pod-01" node="css-host-128" evaluatedNodes=2 feasibleNodes=2
I1003 08:46:16.776528       1 log.go:194] falcon-pod-02 in Prefilter
I1003 08:46:16.777000       1 log.go:194] falcon-pod-02 requires 4 gpu(s), and currently has 8 gpus(s) in total
I1003 08:46:16.784261       1 log.go:194] css-host-129 has 0 gpu, falcon-pod-02 requires 4 gpu -> score: -4
I1003 08:46:16.784354       1 log.go:194] css-host-128 has 8 gpu, falcon-pod-02 requires 4 gpu -> score: 50
I1003 08:46:16.793040       1 schedule_one.go:252] "Successfully bound pod to node" pod="default/falcon-pod-02" node="css-host-128" evaluatedNodes=2 feasibleNodes=2
I1003 08:46:47.197767       1 log.go:194] falcon-pod-03 in Prefilter
I1003 08:46:47.198216       1 log.go:194] falcon-pod-03 requires 4 gpu(s), and currently has 4 gpus(s) in total
I1003 08:46:47.216334       1 event.go:307] "Event occurred" object="default/falcon-pod-03" fieldPath="" kind="Pod" apiVersion="v1" type="Normal" reason="Reconfig" message="Pod falcon-pod-03 needs reconfiguration"
I1003 08:48:50.037061       1 schedule_one.go:252] "Successfully bound pod to node" pod="default/falcon-pod-03" node="css-host-129" evaluatedNodes=2 feasibleNodes=1
I1003 08:49:59.569927       1 log.go:194] falcon-pod-01 in Prefilter
I1003 08:49:59.570387       1 log.go:194] falcon-pod-01 requires 8 gpu(s), and currently has 8 gpus(s) in total
I1003 08:49:59.577529       1 log.go:194] css-host-128 has 4 gpu, falcon-pod-01 requires 8 gpu -> score: -4
I1003 08:49:59.577558       1 log.go:194] css-host-129 has 4 gpu, falcon-pod-01 requires 8 gpu -> score: -4
I1003 08:49:59.589474       1 event.go:307] "Event occurred" object="default/falcon-pod-01" fieldPath="" kind="Pod" apiVersion="v1" type="Normal" reason="Reconfig" message="Pod falcon-pod-01 needs reconfiguration"
I1003 08:52:00.441972       1 schedule_one.go:252] "Successfully bound pod to node" pod="default/falcon-pod-01" node="css-host-128" evaluatedNodes=2 feasibleNodes=2
I1003 08:53:00.394652       1 log.go:194] falcon-pod-02 in Prefilter
I1003 08:53:00.395049       1 log.go:194] falcon-pod-02 requires 4 gpu(s), and currently has 8 gpus(s) in total
I1003 08:53:00.402429       1 log.go:194] css-host-128 has 8 gpu, falcon-pod-02 requires 4 gpu -> score: 50
I1003 08:53:00.402483       1 log.go:194] css-host-129 has 0 gpu, falcon-pod-02 requires 4 gpu -> score: -4
I1003 08:53:00.411198       1 schedule_one.go:252] "Successfully bound pod to node" pod="default/falcon-pod-02" node="css-host-128" evaluatedNodes=2 feasibleNodes=2
I1003 08:53:31.755478       1 log.go:194] falcon-pod-03 in Prefilter
I1003 08:53:31.755986       1 log.go:194] falcon-pod-03 requires 4 gpu(s), and currently has 4 gpus(s) in total
I1003 08:53:31.790878       1 event.go:307] "Event occurred" object="default/falcon-pod-03" fieldPath="" kind="Pod" apiVersion="v1" type="Normal" reason="Reconfig" message="Pod falcon-pod-03 needs reconfiguration"
I1003 08:55:39.093644       1 schedule_one.go:252] "Successfully bound pod to node" pod="default/falcon-pod-03" node="css-host-129" evaluatedNodes=2 feasibleNodes=1
I1003 13:22:21.875676       1 log.go:194] falcon-pod-01 in Prefilter
I1003 13:22:21.876215       1 log.go:194] falcon-pod-01 requires 8 gpu(s), and currently has 8 gpus(s) in total
I1003 13:22:21.882765       1 log.go:194] css-host-128 has 4 gpu, falcon-pod-01 requires 8 gpu -> score: -4
I1003 13:22:21.882807       1 log.go:194] css-host-129 has 4 gpu, falcon-pod-01 requires 8 gpu -> score: -4
I1003 13:22:21.902672       1 event.go:307] "Event occurred" object="default/falcon-pod-01" fieldPath="" kind="Pod" apiVersion="v1" type="Normal" reason="Reconfig" message="Pod falcon-pod-01 needs reconfiguration"
I1003 13:23:49.837855       1 schedule_one.go:252] "Successfully bound pod to node" pod="default/falcon-pod-01" node="css-host-128" evaluatedNodes=2 feasibleNodes=2
I1003 13:27:43.355692       1 log.go:194] falcon-pod-02 in Prefilter
I1003 13:27:43.356252       1 log.go:194] falcon-pod-02 requires 3 gpu(s), and currently has 8 gpus(s) in total
I1003 13:27:43.377323       1 log.go:194] css-host-128 has 8 gpu, falcon-pod-02 requires 3 gpu -> score: 37
I1003 13:27:43.377372       1 log.go:194] css-host-129 has 0 gpu, falcon-pod-02 requires 3 gpu -> score: -3
I1003 13:27:43.386739       1 schedule_one.go:252] "Successfully bound pod to node" pod="default/falcon-pod-02" node="css-host-128" evaluatedNodes=2 feasibleNodes=2
I1003 13:28:19.260047       1 log.go:194] falcon-pod-03 in Prefilter
I1003 13:28:19.260621       1 log.go:194] falcon-pod-03 requires 5 gpu(s), and currently has 5 gpus(s) in total
I1003 13:28:19.276079       1 event.go:307] "Event occurred" object="default/falcon-pod-03" fieldPath="" kind="Pod" apiVersion="v1" type="Normal" reason="Reconfig" message="Pod falcon-pod-03 needs reconfiguration"
I1003 13:29:58.990980       1 schedule_one.go:252] "Successfully bound pod to node" pod="default/falcon-pod-03" node="css-host-129" evaluatedNodes=2 feasibleNodes=1
I1003 13:36:51.729781       1 log.go:194] falcon-pod-01 in Prefilter
I1003 13:36:51.730228       1 log.go:194] falcon-pod-01 requires 8 gpu(s), and currently has 8 gpus(s) in total
I1003 13:36:51.737060       1 log.go:194] css-host-128 has 3 gpu, falcon-pod-01 requires 8 gpu -> score: -5
I1003 13:36:51.737171       1 log.go:194] css-host-129 has 5 gpu, falcon-pod-01 requires 8 gpu -> score: -3
I1003 13:36:51.751066       1 event.go:307] "Event occurred" object="default/falcon-pod-01" fieldPath="" kind="Pod" apiVersion="v1" type="Normal" reason="Reconfig" message="Pod falcon-pod-01 needs reconfiguration"
I1003 13:38:20.250853       1 schedule_one.go:252] "Successfully bound pod to node" pod="default/falcon-pod-01" node="css-host-129" evaluatedNodes=2 feasibleNodes=2
I1003 13:39:19.407292       1 log.go:194] falcon-pod-03 in Prefilter
I1003 13:39:19.407731       1 log.go:194] falcon-pod-03 requires 5 gpu(s), and currently has 8 gpus(s) in total
I1003 13:39:19.425302       1 event.go:307] "Event occurred" object="default/falcon-pod-03" fieldPath="" kind="Pod" apiVersion="v1" type="Normal" reason="Reconfig" message="Pod falcon-pod-03 needs reconfiguration"
I1003 13:41:34.763152       1 schedule_one.go:252] "Successfully bound pod to node" pod="default/falcon-pod-03" node="css-host-128" evaluatedNodes=2 feasibleNodes=1
I1003 13:45:32.705296       1 log.go:194] falcon-pod-01 in Prefilter
I1003 13:45:32.705828       1 log.go:194] falcon-pod-01 requires 8 gpu(s), and currently has 8 gpus(s) in total
I1003 13:45:32.727350       1 event.go:307] "Event occurred" object="default/falcon-pod-01" fieldPath="" kind="Pod" apiVersion="v1" type="Normal" reason="Reconfig" message="Pod falcon-pod-01 needs reconfiguration"
I1003 13:47:53.461367       1 schedule_one.go:252] "Successfully bound pod to node" pod="default/falcon-pod-01" node="css-host-129" evaluatedNodes=2 feasibleNodes=1
I1003 13:48:59.219671       1 log.go:194] falcon-pod-03 in Prefilter
I1003 13:48:59.220154       1 log.go:194] falcon-pod-03 requires 5 gpu(s), and currently has 8 gpus(s) in total
I1003 13:48:59.237669       1 event.go:307] "Event occurred" object="default/falcon-pod-03" fieldPath="" kind="Pod" apiVersion="v1" type="Normal" reason="Reconfig" message="Pod falcon-pod-03 needs reconfiguration"
I1003 13:51:07.339274       1 schedule_one.go:252] "Successfully bound pod to node" pod="default/falcon-pod-03" node="css-host-128" evaluatedNodes=2 feasibleNodes=1
I1003 13:52:38.612799       1 log.go:194] falcon-pod-01 in Prefilter
I1003 13:52:38.613216       1 log.go:194] falcon-pod-01 requires 8 gpu(s), and currently has 8 gpus(s) in total
I1003 13:52:38.633167       1 event.go:307] "Event occurred" object="default/falcon-pod-01" fieldPath="" kind="Pod" apiVersion="v1" type="Normal" reason="Reconfig" message="Pod falcon-pod-01 needs reconfiguration"
I1003 13:54:51.733447       1 schedule_one.go:252] "Successfully bound pod to node" pod="default/falcon-pod-01" node="css-host-129" evaluatedNodes=2 feasibleNodes=1
I1003 13:55:58.974095       1 log.go:194] falcon-pod-03 in Prefilter
I1003 13:55:58.974549       1 log.go:194] falcon-pod-03 requires 5 gpu(s), and currently has 8 gpus(s) in total
I1003 13:55:58.993786       1 event.go:307] "Event occurred" object="default/falcon-pod-03" fieldPath="" kind="Pod" apiVersion="v1" type="Normal" reason="Reconfig" message="Pod falcon-pod-03 needs reconfiguration"
I1003 13:57:57.879043       1 schedule_one.go:252] "Successfully bound pod to node" pod="default/falcon-pod-03" node="css-host-128" evaluatedNodes=2 feasibleNodes=1
I1003 13:59:29.369091       1 log.go:194] falcon-pod-01 in Prefilter
I1003 13:59:29.369596       1 log.go:194] falcon-pod-01 requires 8 gpu(s), and currently has 8 gpus(s) in total
I1003 13:59:29.388530       1 event.go:307] "Event occurred" object="default/falcon-pod-01" fieldPath="" kind="Pod" apiVersion="v1" type="Normal" reason="Reconfig" message="Pod falcon-pod-01 needs reconfiguration"
I1003 14:01:19.987530       1 schedule_one.go:252] "Successfully bound pod to node" pod="default/falcon-pod-01" node="css-host-129" evaluatedNodes=2 feasibleNodes=1
I1003 14:02:49.719718       1 log.go:194] falcon-pod-03 in Prefilter
I1003 14:02:49.720225       1 log.go:194] falcon-pod-03 requires 5 gpu(s), and currently has 8 gpus(s) in total
I1003 14:02:49.739765       1 event.go:307] "Event occurred" object="default/falcon-pod-03" fieldPath="" kind="Pod" apiVersion="v1" type="Normal" reason="Reconfig" message="Pod falcon-pod-03 needs reconfiguration"
I1003 14:04:55.884291       1 schedule_one.go:252] "Successfully bound pod to node" pod="default/falcon-pod-03" node="css-host-128" evaluatedNodes=2 feasibleNodes=1
I1003 14:06:20.169786       1 log.go:194] falcon-pod-01 in Prefilter
I1003 14:06:20.170260       1 log.go:194] falcon-pod-01 requires 8 gpu(s), and currently has 8 gpus(s) in total
I1003 14:06:20.188621       1 event.go:307] "Event occurred" object="default/falcon-pod-01" fieldPath="" kind="Pod" apiVersion="v1" type="Normal" reason="Reconfig" message="Pod falcon-pod-01 needs reconfiguration"
I1003 14:08:30.099008       1 schedule_one.go:252] "Successfully bound pod to node" pod="default/falcon-pod-01" node="css-host-129" evaluatedNodes=2 feasibleNodes=1
I1003 14:09:40.529109       1 log.go:194] falcon-pod-03 in Prefilter
I1003 14:09:40.529547       1 log.go:194] falcon-pod-03 requires 5 gpu(s), and currently has 8 gpus(s) in total
I1003 14:09:40.547264       1 event.go:307] "Event occurred" object="default/falcon-pod-03" fieldPath="" kind="Pod" apiVersion="v1" type="Normal" reason="Reconfig" message="Pod falcon-pod-03 needs reconfiguration"
I1003 14:11:45.028051       1 schedule_one.go:252] "Successfully bound pod to node" pod="default/falcon-pod-03" node="css-host-128" evaluatedNodes=2 feasibleNodes=1
