2023/10/03 02:28:14 falconresources-scheduler starts!
I1003 02:28:14.287448       1 flags.go:64] FLAG: --allow-metric-labels="[]"
I1003 02:28:14.287467       1 flags.go:64] FLAG: --authentication-kubeconfig=""
I1003 02:28:14.287474       1 flags.go:64] FLAG: --authentication-skip-lookup="false"
I1003 02:28:14.287481       1 flags.go:64] FLAG: --authentication-token-webhook-cache-ttl="10s"
I1003 02:28:14.287488       1 flags.go:64] FLAG: --authentication-tolerate-lookup-failure="true"
I1003 02:28:14.287493       1 flags.go:64] FLAG: --authorization-always-allow-paths="[/healthz,/readyz,/livez]"
I1003 02:28:14.287505       1 flags.go:64] FLAG: --authorization-kubeconfig=""
I1003 02:28:14.287511       1 flags.go:64] FLAG: --authorization-webhook-cache-authorized-ttl="10s"
I1003 02:28:14.287516       1 flags.go:64] FLAG: --authorization-webhook-cache-unauthorized-ttl="10s"
I1003 02:28:14.287522       1 flags.go:64] FLAG: --bind-address="0.0.0.0"
I1003 02:28:14.287530       1 flags.go:64] FLAG: --cert-dir=""
I1003 02:28:14.287539       1 flags.go:64] FLAG: --client-ca-file=""
I1003 02:28:14.287549       1 flags.go:64] FLAG: --config="/etc/kubernetes/scheduler-config.yaml"
I1003 02:28:14.287555       1 flags.go:64] FLAG: --contention-profiling="true"
I1003 02:28:14.287562       1 flags.go:64] FLAG: --disabled-metrics="[]"
I1003 02:28:14.287573       1 flags.go:64] FLAG: --feature-gates=""
I1003 02:28:14.287580       1 flags.go:64] FLAG: --help="false"
I1003 02:28:14.287586       1 flags.go:64] FLAG: --http2-max-streams-per-connection="0"
I1003 02:28:14.287592       1 flags.go:64] FLAG: --kube-api-burst="100"
I1003 02:28:14.287600       1 flags.go:64] FLAG: --kube-api-content-type="application/vnd.kubernetes.protobuf"
I1003 02:28:14.287607       1 flags.go:64] FLAG: --kube-api-qps="50"
I1003 02:28:14.287615       1 flags.go:64] FLAG: --kubeconfig=""
I1003 02:28:14.287620       1 flags.go:64] FLAG: --leader-elect="true"
I1003 02:28:14.287625       1 flags.go:64] FLAG: --leader-elect-lease-duration="15s"
I1003 02:28:14.287631       1 flags.go:64] FLAG: --leader-elect-renew-deadline="10s"
I1003 02:28:14.287640       1 flags.go:64] FLAG: --leader-elect-resource-lock="leases"
I1003 02:28:14.287645       1 flags.go:64] FLAG: --leader-elect-resource-name="kube-scheduler"
I1003 02:28:14.287650       1 flags.go:64] FLAG: --leader-elect-resource-namespace="kube-system"
I1003 02:28:14.287655       1 flags.go:64] FLAG: --leader-elect-retry-period="2s"
I1003 02:28:14.287671       1 flags.go:64] FLAG: --lock-object-name="kube-scheduler"
I1003 02:28:14.287677       1 flags.go:64] FLAG: --lock-object-namespace="kube-system"
I1003 02:28:14.287681       1 flags.go:64] FLAG: --log-flush-frequency="5s"
I1003 02:28:14.287686       1 flags.go:64] FLAG: --logging-format="text"
I1003 02:28:14.287690       1 flags.go:64] FLAG: --master=""
I1003 02:28:14.287694       1 flags.go:64] FLAG: --permit-address-sharing="false"
I1003 02:28:14.287698       1 flags.go:64] FLAG: --permit-port-sharing="false"
I1003 02:28:14.287703       1 flags.go:64] FLAG: --pod-max-in-unschedulable-pods-duration="5m0s"
I1003 02:28:14.287707       1 flags.go:64] FLAG: --profiling="true"
I1003 02:28:14.287712       1 flags.go:64] FLAG: --requestheader-allowed-names="[]"
I1003 02:28:14.287720       1 flags.go:64] FLAG: --requestheader-client-ca-file=""
I1003 02:28:14.287726       1 flags.go:64] FLAG: --requestheader-extra-headers-prefix="[x-remote-extra-]"
I1003 02:28:14.287735       1 flags.go:64] FLAG: --requestheader-group-headers="[x-remote-group]"
I1003 02:28:14.287742       1 flags.go:64] FLAG: --requestheader-username-headers="[x-remote-user]"
I1003 02:28:14.287749       1 flags.go:64] FLAG: --secure-port="10259"
I1003 02:28:14.287754       1 flags.go:64] FLAG: --show-hidden-metrics-for-version=""
I1003 02:28:14.287758       1 flags.go:64] FLAG: --tls-cert-file=""
I1003 02:28:14.287763       1 flags.go:64] FLAG: --tls-cipher-suites="[]"
I1003 02:28:14.287774       1 flags.go:64] FLAG: --tls-min-version=""
I1003 02:28:14.287779       1 flags.go:64] FLAG: --tls-private-key-file=""
I1003 02:28:14.287783       1 flags.go:64] FLAG: --tls-sni-cert-key="[]"
I1003 02:28:14.287796       1 flags.go:64] FLAG: --v="2"
I1003 02:28:14.287801       1 flags.go:64] FLAG: --version="false"
I1003 02:28:14.287810       1 flags.go:64] FLAG: --vmodule=""
I1003 02:28:14.287816       1 flags.go:64] FLAG: --write-config-to=""
I1003 02:28:14.609361       1 serving.go:348] Generated self-signed cert in-memory
I1003 02:28:14.610949       1 configfile.go:59] "KubeSchedulerConfiguration v1beta3 is deprecated in v1.26, will be removed in v1.29"
W1003 02:28:14.611054       1 client_config.go:618] Neither --kubeconfig nor --master was specified.  Using the inClusterConfig.  This might not work.
I1003 02:28:15.045773       1 requestheader_controller.go:244] Loaded a new request header values for RequestHeaderAuthRequestController
I1003 02:28:15.062271       1 configfile.go:105] "Using component config" config=<
	apiVersion: kubescheduler.config.k8s.io/v1beta3
	clientConnection:
	  acceptContentTypes: ""
	  burst: 100
	  contentType: application/vnd.kubernetes.protobuf
	  kubeconfig: ""
	  qps: 50
	enableContentionProfiling: true
	enableProfiling: true
	kind: KubeSchedulerConfiguration
	leaderElection:
	  leaderElect: false
	  leaseDuration: 15s
	  renewDeadline: 10s
	  resourceLock: leases
	  resourceName: kube-scheduler
	  resourceNamespace: kube-system
	  retryPeriod: 2s
	parallelism: 16
	percentageOfNodesToScore: 0
	podInitialBackoffSeconds: 1
	podMaxBackoffSeconds: 10
	profiles:
	- pluginConfig:
	  - args:
	      apiVersion: kubescheduler.config.k8s.io/v1beta3
	      kind: DefaultPreemptionArgs
	      minCandidateNodesAbsolute: 100
	      minCandidateNodesPercentage: 10
	    name: DefaultPreemption
	  - args:
	      apiVersion: kubescheduler.config.k8s.io/v1beta3
	      hardPodAffinityWeight: 1
	      ignorePreferredTermsOfExistingPods: false
	      kind: InterPodAffinityArgs
	    name: InterPodAffinity
	  - args:
	      apiVersion: kubescheduler.config.k8s.io/v1beta3
	      kind: NodeAffinityArgs
	    name: NodeAffinity
	  - args:
	      apiVersion: kubescheduler.config.k8s.io/v1beta3
	      kind: NodeResourcesBalancedAllocationArgs
	      resources:
	      - name: cpu
	        weight: 1
	      - name: memory
	        weight: 1
	    name: NodeResourcesBalancedAllocation
	  - args:
	      apiVersion: kubescheduler.config.k8s.io/v1beta3
	      ignoredResourceGroups:
	      - falcon.com
	      kind: NodeResourcesFitArgs
	      scoringStrategy:
	        resources:
	        - name: cpu
	          weight: 1
	        - name: memory
	          weight: 1
	        type: LeastAllocated
	    name: NodeResourcesFit
	  - args:
	      apiVersion: kubescheduler.config.k8s.io/v1beta3
	      defaultingType: System
	      kind: PodTopologySpreadArgs
	    name: PodTopologySpread
	  - args:
	      apiVersion: kubescheduler.config.k8s.io/v1beta3
	      bindTimeoutSeconds: 600
	      kind: VolumeBindingArgs
	    name: VolumeBinding
	  plugins:
	    bind: {}
	    filter: {}
	    multiPoint:
	      enabled:
	      - name: PrioritySort
	        weight: 0
	      - name: NodeUnschedulable
	        weight: 0
	      - name: NodeName
	        weight: 0
	      - name: TaintToleration
	        weight: 3
	      - name: NodeAffinity
	        weight: 2
	      - name: NodePorts
	        weight: 0
	      - name: NodeResourcesFit
	        weight: 1
	      - name: VolumeRestrictions
	        weight: 0
	      - name: EBSLimits
	        weight: 0
	      - name: GCEPDLimits
	        weight: 0
	      - name: NodeVolumeLimits
	        weight: 0
	      - name: AzureDiskLimits
	        weight: 0
	      - name: VolumeBinding
	        weight: 0
	      - name: VolumeZone
	        weight: 0
	      - name: PodTopologySpread
	        weight: 2
	      - name: InterPodAffinity
	        weight: 2
	      - name: DefaultPreemption
	        weight: 0
	      - name: NodeResourcesBalancedAllocation
	        weight: 1
	      - name: ImageLocality
	        weight: 1
	      - name: DefaultBinder
	        weight: 0
	      - name: SchedulingGates
	        weight: 0
	      - name: FalconResources
	        weight: 0
	    permit: {}
	    postBind: {}
	    postFilter: {}
	    preBind: {}
	    preEnqueue: {}
	    preFilter: {}
	    preScore: {}
	    queueSort: {}
	    reserve: {}
	    score: {}
	  schedulerName: my-scheduler
 >
I1003 02:28:15.062787       1 server.go:154] "Starting Kubernetes Scheduler" version="v0.0.0-master+$Format:%H$"
I1003 02:28:15.062800       1 server.go:156] "Golang settings" GOGC="" GOMAXPROCS="" GOTRACEBACK=""
I1003 02:28:15.067866       1 requestheader_controller.go:169] Starting RequestHeaderAuthRequestController
I1003 02:28:15.067914       1 configmap_cafile_content.go:202] "Starting controller" name="client-ca::kube-system::extension-apiserver-authentication::client-ca-file"
I1003 02:28:15.067978       1 shared_informer.go:311] Waiting for caches to sync for client-ca::kube-system::extension-apiserver-authentication::client-ca-file
I1003 02:28:15.067931       1 shared_informer.go:311] Waiting for caches to sync for RequestHeaderAuthRequestController
I1003 02:28:15.067992       1 configmap_cafile_content.go:202] "Starting controller" name="client-ca::kube-system::extension-apiserver-authentication::requestheader-client-ca-file"
I1003 02:28:15.068333       1 shared_informer.go:311] Waiting for caches to sync for client-ca::kube-system::extension-apiserver-authentication::requestheader-client-ca-file
I1003 02:28:15.068510       1 tlsconfig.go:200] "Loaded serving cert" certName="Generated self signed cert" certDetail="\"localhost@1696300094\" [serving] validServingFor=[127.0.0.1,localhost,localhost] issuer=\"localhost-ca@1696300094\" (2023-10-03 01:28:14 +0000 UTC to 2024-10-02 01:28:14 +0000 UTC (now=2023-10-03 02:28:15.068428317 +0000 UTC))"
I1003 02:28:15.069263       1 named_certificates.go:53] "Loaded SNI cert" index=0 certName="self-signed loopback" certDetail="\"apiserver-loopback-client@1696300095\" [serving] validServingFor=[apiserver-loopback-client] issuer=\"apiserver-loopback-client-ca@1696300094\" (2023-10-03 01:28:14 +0000 UTC to 2024-10-02 01:28:14 +0000 UTC (now=2023-10-03 02:28:15.069193893 +0000 UTC))"
I1003 02:28:15.069329       1 secure_serving.go:210] Serving securely on [::]:10259
I1003 02:28:15.069400       1 tlsconfig.go:240] "Starting DynamicServingCertificateController"
I1003 02:28:15.080426       1 node_tree.go:65] "Added node in listed group to NodeTree" node="css-host-128" zone=""
I1003 02:28:15.080651       1 node_tree.go:65] "Added node in listed group to NodeTree" node="css-host-129" zone=""
I1003 02:28:15.168743       1 shared_informer.go:318] Caches are synced for client-ca::kube-system::extension-apiserver-authentication::client-ca-file
I1003 02:28:15.168818       1 shared_informer.go:318] Caches are synced for client-ca::kube-system::extension-apiserver-authentication::requestheader-client-ca-file
I1003 02:28:15.169048       1 shared_informer.go:318] Caches are synced for RequestHeaderAuthRequestController
I1003 02:28:15.169136       1 tlsconfig.go:178] "Loaded client CA" index=0 certName="client-ca::kube-system::extension-apiserver-authentication::client-ca-file,client-ca::kube-system::extension-apiserver-authentication::requestheader-client-ca-file" certDetail="\"kubernetes\" [] validServingFor=[kubernetes] issuer=\"<self>\" (2023-02-25 05:20:24 +0000 UTC to 2033-02-22 05:20:24 +0000 UTC (now=2023-10-03 02:28:15.169092406 +0000 UTC))"
I1003 02:28:15.169696       1 tlsconfig.go:200] "Loaded serving cert" certName="Generated self signed cert" certDetail="\"localhost@1696300094\" [serving] validServingFor=[127.0.0.1,localhost,localhost] issuer=\"localhost-ca@1696300094\" (2023-10-03 01:28:14 +0000 UTC to 2024-10-02 01:28:14 +0000 UTC (now=2023-10-03 02:28:15.169668867 +0000 UTC))"
I1003 02:28:15.170183       1 named_certificates.go:53] "Loaded SNI cert" index=0 certName="self-signed loopback" certDetail="\"apiserver-loopback-client@1696300095\" [serving] validServingFor=[apiserver-loopback-client] issuer=\"apiserver-loopback-client-ca@1696300094\" (2023-10-03 01:28:14 +0000 UTC to 2024-10-02 01:28:14 +0000 UTC (now=2023-10-03 02:28:15.17015877 +0000 UTC))"
I1003 02:28:15.170272       1 tlsconfig.go:178] "Loaded client CA" index=0 certName="client-ca::kube-system::extension-apiserver-authentication::client-ca-file,client-ca::kube-system::extension-apiserver-authentication::requestheader-client-ca-file" certDetail="\"kubernetes\" [] validServingFor=[kubernetes] issuer=\"<self>\" (2023-02-25 05:20:24 +0000 UTC to 2033-02-22 05:20:24 +0000 UTC (now=2023-10-03 02:28:15.170248914 +0000 UTC))"
I1003 02:28:15.170302       1 tlsconfig.go:178] "Loaded client CA" index=1 certName="client-ca::kube-system::extension-apiserver-authentication::client-ca-file,client-ca::kube-system::extension-apiserver-authentication::requestheader-client-ca-file" certDetail="\"front-proxy-ca\" [] validServingFor=[front-proxy-ca] issuer=\"<self>\" (2023-02-25 05:20:25 +0000 UTC to 2033-02-22 05:20:25 +0000 UTC (now=2023-10-03 02:28:15.170283327 +0000 UTC))"
I1003 02:28:15.170776       1 tlsconfig.go:200] "Loaded serving cert" certName="Generated self signed cert" certDetail="\"localhost@1696300094\" [serving] validServingFor=[127.0.0.1,localhost,localhost] issuer=\"localhost-ca@1696300094\" (2023-10-03 01:28:14 +0000 UTC to 2024-10-02 01:28:14 +0000 UTC (now=2023-10-03 02:28:15.17075681 +0000 UTC))"
I1003 02:28:15.171416       1 named_certificates.go:53] "Loaded SNI cert" index=0 certName="self-signed loopback" certDetail="\"apiserver-loopback-client@1696300095\" [serving] validServingFor=[apiserver-loopback-client] issuer=\"apiserver-loopback-client-ca@1696300094\" (2023-10-03 01:28:14 +0000 UTC to 2024-10-02 01:28:14 +0000 UTC (now=2023-10-03 02:28:15.171397017 +0000 UTC))"
I1003 03:03:04.569448       1 log.go:194] falcon-pod-01 in Prefilter
I1003 03:03:04.569961       1 log.go:194] falcon-pod-01 requires 5 gpu(s), and currently has 8 gpus(s) in total
I1003 03:03:04.578840       1 log.go:194] css-host-128 has 4 gpu, falcon-pod-01 requires 5 gpu -> score: -1
I1003 03:03:04.578865       1 log.go:194] css-host-129 has 4 gpu, falcon-pod-01 requires 5 gpu -> score: -1
I1003 03:03:04.592051       1 event.go:307] "Event occurred" object="default/falcon-pod-01" fieldPath="" kind="Pod" apiVersion="v1" type="Normal" reason="Reconfig" message="Pod falcon-pod-01 needs reconfiguration"
I1003 03:03:39.784032       1 schedule_one.go:252] "Successfully bound pod to node" pod="default/falcon-pod-01" node="css-host-128" evaluatedNodes=2 feasibleNodes=2
I1003 05:05:00.352337       1 log.go:194] falcon-pod-02 in Prefilter
I1003 05:05:00.352924       1 log.go:194] falcon-pod-02 requires 4 gpu(s), and currently has 8 gpus(s) in total
I1003 05:05:00.581462       1 log.go:194] css-host-128 has 5 gpu, falcon-pod-02 requires 4 gpu -> score: 80
I1003 05:05:00.581498       1 log.go:194] css-host-129 has 3 gpu, falcon-pod-02 requires 4 gpu -> score: -1
I1003 05:05:00.581923       1 trace.go:219] Trace[840239516]: "Scheduling" namespace:default,name:falcon-pod-02 (03-Oct-2023 05:05:00.351) (total time: 229ms):
Trace[840239516]: ---"Computing predicates done" 229ms (05:05:00.581)
Trace[840239516]: [229.893745ms] [229.893745ms] END
I1003 05:05:00.593182       1 schedule_one.go:252] "Successfully bound pod to node" pod="default/falcon-pod-02" node="css-host-128" evaluatedNodes=2 feasibleNodes=2
I1003 05:05:26.771560       1 log.go:194] falcon-pod-03 in Prefilter
I1003 05:05:26.772112       1 log.go:194] falcon-pod-03 requires 4 gpu(s), and currently has 4 gpus(s) in total
I1003 05:05:26.779291       1 log.go:194] css-host-128 has 1 gpu, falcon-pod-03 requires 4 gpu -> score: -3
I1003 05:05:26.779325       1 log.go:194] css-host-129 has 3 gpu, falcon-pod-03 requires 4 gpu -> score: -1
I1003 05:05:26.792241       1 event.go:307] "Event occurred" object="default/falcon-pod-03" fieldPath="" kind="Pod" apiVersion="v1" type="Normal" reason="Reconfig" message="Pod falcon-pod-03 needs reconfiguration"
I1003 05:06:07.007459       1 schedule_one.go:252] "Successfully bound pod to node" pod="default/falcon-pod-03" node="css-host-129" evaluatedNodes=2 feasibleNodes=2
I1003 05:21:56.610005       1 log.go:194] falcon-pod-01 in Prefilter
I1003 05:21:56.610569       1 log.go:194] falcon-pod-01 requires 5 gpu(s), and currently has 8 gpus(s) in total
I1003 05:21:56.618170       1 log.go:194] css-host-128 has 4 gpu, falcon-pod-01 requires 5 gpu -> score: -1
I1003 05:21:56.618201       1 log.go:194] css-host-129 has 4 gpu, falcon-pod-01 requires 5 gpu -> score: -1
I1003 05:21:56.630206       1 event.go:307] "Event occurred" object="default/falcon-pod-01" fieldPath="" kind="Pod" apiVersion="v1" type="Normal" reason="Reconfig" message="Pod falcon-pod-01 needs reconfiguration"
I1003 05:22:30.023316       1 schedule_one.go:252] "Successfully bound pod to node" pod="default/falcon-pod-01" node="css-host-128" evaluatedNodes=2 feasibleNodes=2
I1003 05:24:03.771867       1 log.go:194] falcon-pod-02 in Prefilter
I1003 05:24:03.772325       1 log.go:194] falcon-pod-02 requires 4 gpu(s), and currently has 8 gpus(s) in total
I1003 05:24:03.779132       1 log.go:194] css-host-128 has 5 gpu, falcon-pod-02 requires 4 gpu -> score: 80
I1003 05:24:03.779166       1 log.go:194] css-host-129 has 3 gpu, falcon-pod-02 requires 4 gpu -> score: -1
I1003 05:24:03.788202       1 schedule_one.go:252] "Successfully bound pod to node" pod="default/falcon-pod-02" node="css-host-128" evaluatedNodes=2 feasibleNodes=2
I1003 05:24:31.571668       1 log.go:194] falcon-pod-03 in Prefilter
I1003 05:24:31.572083       1 log.go:194] falcon-pod-03 requires 4 gpu(s), and currently has 4 gpus(s) in total
I1003 05:24:31.579520       1 log.go:194] css-host-128 has 1 gpu, falcon-pod-03 requires 4 gpu -> score: -3
I1003 05:24:31.579553       1 log.go:194] css-host-129 has 3 gpu, falcon-pod-03 requires 4 gpu -> score: -1
I1003 05:24:31.591324       1 event.go:307] "Event occurred" object="default/falcon-pod-03" fieldPath="" kind="Pod" apiVersion="v1" type="Normal" reason="Reconfig" message="Pod falcon-pod-03 needs reconfiguration"
I1003 05:25:10.798985       1 schedule_one.go:252] "Successfully bound pod to node" pod="default/falcon-pod-03" node="css-host-129" evaluatedNodes=2 feasibleNodes=2
I1003 05:26:18.832227       1 log.go:194] falcon-pod-01 in Prefilter
I1003 05:26:18.832754       1 log.go:194] falcon-pod-01 requires 5 gpu(s), and currently has 8 gpus(s) in total
I1003 05:26:18.840966       1 log.go:194] css-host-128 has 4 gpu, falcon-pod-01 requires 5 gpu -> score: -1
I1003 05:26:18.841001       1 log.go:194] css-host-129 has 4 gpu, falcon-pod-01 requires 5 gpu -> score: -1
I1003 05:26:18.853025       1 event.go:307] "Event occurred" object="default/falcon-pod-01" fieldPath="" kind="Pod" apiVersion="v1" type="Normal" reason="Reconfig" message="Pod falcon-pod-01 needs reconfiguration"
I1003 05:26:55.464801       1 schedule_one.go:252] "Successfully bound pod to node" pod="default/falcon-pod-01" node="css-host-128" evaluatedNodes=2 feasibleNodes=2
I1003 05:27:41.270452       1 log.go:194] falcon-pod-02 in Prefilter
I1003 05:27:41.270973       1 log.go:194] falcon-pod-02 requires 4 gpu(s), and currently has 3 gpus(s) in total
I1003 05:27:41.278215       1 schedule_one.go:867] "Unable to schedule pod; no fit; waiting" pod="default/falcon-pod-02" err="0/2 nodes are available: falcon-pod-02 requires 4 gpu but only 3 gpu in the pool.. preemption: 0/2 nodes are available: 2 No preemption victims found for incoming pod.."
E1003 05:27:41.278354       1 schedule_one.go:902] "Error occurred" err="Pod default/falcon-pod-02 is already present in the active queue"
I1003 05:27:41.287434       1 log.go:194] falcon-pod-02 in Prefilter
I1003 05:27:41.287753       1 log.go:194] falcon-pod-02 requires 4 gpu(s), and currently has 3 gpus(s) in total
I1003 05:27:41.293372       1 schedule_one.go:867] "Unable to schedule pod; no fit; waiting" pod="default/falcon-pod-02" err="0/2 nodes are available: falcon-pod-02 requires 4 gpu but only 3 gpu in the pool.. preemption: 0/2 nodes are available: 2 No preemption victims found for incoming pod.."
E1003 05:27:41.293424       1 schedule_one.go:902] "Error occurred" err="Pod default/falcon-pod-02 is already present in the active queue"
I1003 05:27:41.297781       1 log.go:194] falcon-pod-02 in Prefilter
I1003 05:27:41.298210       1 log.go:194] falcon-pod-02 requires 4 gpu(s), and currently has 3 gpus(s) in total
I1003 05:27:41.304315       1 schedule_one.go:867] "Unable to schedule pod; no fit; waiting" pod="default/falcon-pod-02" err="0/2 nodes are available: falcon-pod-02 requires 4 gpu but only 3 gpu in the pool.. preemption: 0/2 nodes are available: 2 No preemption victims found for incoming pod.."
I1003 05:27:49.469509       1 log.go:194] falcon-pod-02 in Prefilter
I1003 05:27:49.469983       1 log.go:194] falcon-pod-02 requires 4 gpu(s), and currently has 8 gpus(s) in total
I1003 05:27:49.476661       1 log.go:194] css-host-128 has 5 gpu, falcon-pod-02 requires 4 gpu -> score: 80
I1003 05:27:49.476743       1 log.go:194] css-host-129 has 3 gpu, falcon-pod-02 requires 4 gpu -> score: -1
I1003 05:27:49.485980       1 schedule_one.go:252] "Successfully bound pod to node" pod="default/falcon-pod-02" node="css-host-128" evaluatedNodes=2 feasibleNodes=2
I1003 05:28:12.889794       1 log.go:194] falcon-pod-03 in Prefilter
I1003 05:28:12.890282       1 log.go:194] falcon-pod-03 requires 4 gpu(s), and currently has 4 gpus(s) in total
I1003 05:28:12.899322       1 log.go:194] css-host-128 has 1 gpu, falcon-pod-03 requires 4 gpu -> score: -3
I1003 05:28:12.899391       1 log.go:194] css-host-129 has 3 gpu, falcon-pod-03 requires 4 gpu -> score: -1
I1003 05:28:12.910142       1 event.go:307] "Event occurred" object="default/falcon-pod-03" fieldPath="" kind="Pod" apiVersion="v1" type="Normal" reason="Reconfig" message="Pod falcon-pod-03 needs reconfiguration"
I1003 05:28:55.138069       1 schedule_one.go:252] "Successfully bound pod to node" pod="default/falcon-pod-03" node="css-host-129" evaluatedNodes=2 feasibleNodes=2
I1003 05:29:55.371219       1 log.go:194] falcon-pod-01 in Prefilter
I1003 05:29:55.371767       1 log.go:194] falcon-pod-01 requires 5 gpu(s), and currently has 8 gpus(s) in total
I1003 05:29:55.378805       1 log.go:194] css-host-128 has 4 gpu, falcon-pod-01 requires 5 gpu -> score: -1
I1003 05:29:55.378847       1 log.go:194] css-host-129 has 4 gpu, falcon-pod-01 requires 5 gpu -> score: -1
I1003 05:29:55.390187       1 event.go:307] "Event occurred" object="default/falcon-pod-01" fieldPath="" kind="Pod" apiVersion="v1" type="Normal" reason="Reconfig" message="Pod falcon-pod-01 needs reconfiguration"
I1003 05:30:40.647305       1 schedule_one.go:252] "Successfully bound pod to node" pod="default/falcon-pod-01" node="css-host-128" evaluatedNodes=2 feasibleNodes=2
I1003 05:31:33.044526       1 log.go:194] falcon-pod-02 in Prefilter
I1003 05:31:33.044997       1 log.go:194] falcon-pod-02 requires 4 gpu(s), and currently has 3 gpus(s) in total
I1003 05:31:33.073508       1 schedule_one.go:867] "Unable to schedule pod; no fit; waiting" pod="default/falcon-pod-02" err="0/2 nodes are available: falcon-pod-02 requires 4 gpu but only 3 gpu in the pool.. preemption: 0/2 nodes are available: 2 No preemption victims found for incoming pod.."
E1003 05:31:33.073577       1 schedule_one.go:902] "Error occurred" err="Pod default/falcon-pod-02 is already present in the active queue"
I1003 05:31:33.080112       1 log.go:194] falcon-pod-02 in Prefilter
I1003 05:31:33.080613       1 log.go:194] falcon-pod-02 requires 4 gpu(s), and currently has 3 gpus(s) in total
I1003 05:31:33.087137       1 schedule_one.go:867] "Unable to schedule pod; no fit; waiting" pod="default/falcon-pod-02" err="0/2 nodes are available: falcon-pod-02 requires 4 gpu but only 3 gpu in the pool.. preemption: 0/2 nodes are available: 2 No preemption victims found for incoming pod.."
E1003 05:31:33.087273       1 schedule_one.go:902] "Error occurred" err="Pod default/falcon-pod-02 is already present in the active queue"
I1003 05:31:33.096287       1 log.go:194] falcon-pod-02 in Prefilter
I1003 05:31:33.096592       1 log.go:194] falcon-pod-02 requires 4 gpu(s), and currently has 3 gpus(s) in total
I1003 05:31:33.102591       1 schedule_one.go:867] "Unable to schedule pod; no fit; waiting" pod="default/falcon-pod-02" err="0/2 nodes are available: falcon-pod-02 requires 4 gpu but only 3 gpu in the pool.. preemption: 0/2 nodes are available: 2 No preemption victims found for incoming pod.."
I1003 05:31:34.662491       1 log.go:194] falcon-pod-02 in Prefilter
I1003 05:31:34.662865       1 log.go:194] falcon-pod-02 requires 4 gpu(s), and currently has 8 gpus(s) in total
I1003 05:31:34.669511       1 log.go:194] css-host-128 has 5 gpu, falcon-pod-02 requires 4 gpu -> score: 80
I1003 05:31:34.669606       1 log.go:194] css-host-129 has 3 gpu, falcon-pod-02 requires 4 gpu -> score: -1
I1003 05:31:34.678234       1 schedule_one.go:252] "Successfully bound pod to node" pod="default/falcon-pod-02" node="css-host-128" evaluatedNodes=2 feasibleNodes=2
I1003 05:31:54.800947       1 log.go:194] falcon-pod-03 in Prefilter
I1003 05:31:54.801449       1 log.go:194] falcon-pod-03 requires 4 gpu(s), and currently has 4 gpus(s) in total
I1003 05:31:54.807312       1 log.go:194] css-host-129 has 3 gpu, falcon-pod-03 requires 4 gpu -> score: -1
I1003 05:31:54.807357       1 log.go:194] css-host-128 has 1 gpu, falcon-pod-03 requires 4 gpu -> score: -3
I1003 05:31:54.818707       1 event.go:307] "Event occurred" object="default/falcon-pod-03" fieldPath="" kind="Pod" apiVersion="v1" type="Normal" reason="Reconfig" message="Pod falcon-pod-03 needs reconfiguration"
I1003 05:32:39.252959       1 schedule_one.go:252] "Successfully bound pod to node" pod="default/falcon-pod-03" node="css-host-129" evaluatedNodes=2 feasibleNodes=2
I1003 05:33:40.784866       1 log.go:194] falcon-pod-01 in Prefilter
I1003 05:33:40.785340       1 log.go:194] falcon-pod-01 requires 5 gpu(s), and currently has 8 gpus(s) in total
I1003 05:33:40.794223       1 log.go:194] css-host-128 has 4 gpu, falcon-pod-01 requires 5 gpu -> score: -1
I1003 05:33:40.794255       1 log.go:194] css-host-129 has 4 gpu, falcon-pod-01 requires 5 gpu -> score: -1
I1003 05:33:40.818250       1 event.go:307] "Event occurred" object="default/falcon-pod-01" fieldPath="" kind="Pod" apiVersion="v1" type="Normal" reason="Reconfig" message="Pod falcon-pod-01 needs reconfiguration"
I1003 05:34:16.010173       1 schedule_one.go:252] "Successfully bound pod to node" pod="default/falcon-pod-01" node="css-host-128" evaluatedNodes=2 feasibleNodes=2
I1003 05:35:05.420079       1 log.go:194] falcon-pod-02 in Prefilter
I1003 05:35:05.420560       1 log.go:194] falcon-pod-02 requires 4 gpu(s), and currently has 3 gpus(s) in total
I1003 05:35:05.427845       1 schedule_one.go:867] "Unable to schedule pod; no fit; waiting" pod="default/falcon-pod-02" err="0/2 nodes are available: falcon-pod-02 requires 4 gpu but only 3 gpu in the pool.. preemption: 0/2 nodes are available: 2 No preemption victims found for incoming pod.."
E1003 05:35:05.427941       1 schedule_one.go:902] "Error occurred" err="Pod default/falcon-pod-02 is already present in the active queue"
I1003 05:35:05.434040       1 log.go:194] falcon-pod-02 in Prefilter
I1003 05:35:05.434470       1 log.go:194] falcon-pod-02 requires 4 gpu(s), and currently has 3 gpus(s) in total
I1003 05:35:05.440530       1 schedule_one.go:867] "Unable to schedule pod; no fit; waiting" pod="default/falcon-pod-02" err="0/2 nodes are available: falcon-pod-02 requires 4 gpu but only 3 gpu in the pool.. preemption: 0/2 nodes are available: 2 No preemption victims found for incoming pod.."
I1003 05:35:09.624476       1 log.go:194] falcon-pod-02 in Prefilter
I1003 05:35:09.624965       1 log.go:194] falcon-pod-02 requires 4 gpu(s), and currently has 8 gpus(s) in total
I1003 05:35:09.631338       1 log.go:194] css-host-128 has 5 gpu, falcon-pod-02 requires 4 gpu -> score: 80
I1003 05:35:09.631367       1 log.go:194] css-host-129 has 3 gpu, falcon-pod-02 requires 4 gpu -> score: -1
I1003 05:35:09.639945       1 schedule_one.go:252] "Successfully bound pod to node" pod="default/falcon-pod-02" node="css-host-128" evaluatedNodes=2 feasibleNodes=2
I1003 05:35:30.909887       1 log.go:194] falcon-pod-03 in Prefilter
I1003 05:35:30.910455       1 log.go:194] falcon-pod-03 requires 4 gpu(s), and currently has 4 gpus(s) in total
I1003 05:35:30.919378       1 log.go:194] css-host-128 has 1 gpu, falcon-pod-03 requires 4 gpu -> score: -3
I1003 05:35:30.919503       1 log.go:194] css-host-129 has 3 gpu, falcon-pod-03 requires 4 gpu -> score: -1
I1003 05:35:30.933194       1 event.go:307] "Event occurred" object="default/falcon-pod-03" fieldPath="" kind="Pod" apiVersion="v1" type="Normal" reason="Reconfig" message="Pod falcon-pod-03 needs reconfiguration"
I1003 05:36:13.393882       1 schedule_one.go:252] "Successfully bound pod to node" pod="default/falcon-pod-03" node="css-host-129" evaluatedNodes=2 feasibleNodes=2
I1003 05:37:14.949985       1 log.go:194] falcon-pod-01 in Prefilter
I1003 05:37:14.950449       1 log.go:194] falcon-pod-01 requires 5 gpu(s), and currently has 8 gpus(s) in total
I1003 05:37:14.956923       1 log.go:194] css-host-128 has 4 gpu, falcon-pod-01 requires 5 gpu -> score: -1
I1003 05:37:14.957007       1 log.go:194] css-host-129 has 4 gpu, falcon-pod-01 requires 5 gpu -> score: -1
I1003 05:37:14.968751       1 event.go:307] "Event occurred" object="default/falcon-pod-01" fieldPath="" kind="Pod" apiVersion="v1" type="Normal" reason="Reconfig" message="Pod falcon-pod-01 needs reconfiguration"
I1003 05:38:01.227369       1 schedule_one.go:252] "Successfully bound pod to node" pod="default/falcon-pod-01" node="css-host-128" evaluatedNodes=2 feasibleNodes=2
I1003 05:38:38.334555       1 log.go:194] falcon-pod-02 in Prefilter
I1003 05:38:38.334997       1 log.go:194] falcon-pod-02 requires 4 gpu(s), and currently has 3 gpus(s) in total
I1003 05:38:38.342950       1 schedule_one.go:867] "Unable to schedule pod; no fit; waiting" pod="default/falcon-pod-02" err="0/2 nodes are available: falcon-pod-02 requires 4 gpu but only 3 gpu in the pool.. preemption: 0/2 nodes are available: 2 No preemption victims found for incoming pod.."
E1003 05:38:38.343042       1 schedule_one.go:902] "Error occurred" err="Pod default/falcon-pod-02 is already present in the active queue"
I1003 05:38:38.349476       1 log.go:194] falcon-pod-02 in Prefilter
I1003 05:38:38.349823       1 log.go:194] falcon-pod-02 requires 4 gpu(s), and currently has 3 gpus(s) in total
I1003 05:38:38.356525       1 schedule_one.go:867] "Unable to schedule pod; no fit; waiting" pod="default/falcon-pod-02" err="0/2 nodes are available: falcon-pod-02 requires 4 gpu but only 3 gpu in the pool.. preemption: 0/2 nodes are available: 2 No preemption victims found for incoming pod.."
I1003 05:38:54.768339       1 log.go:194] falcon-pod-02 in Prefilter
I1003 05:38:54.768909       1 log.go:194] falcon-pod-02 requires 4 gpu(s), and currently has 8 gpus(s) in total
I1003 05:38:54.776307       1 log.go:194] css-host-128 has 5 gpu, falcon-pod-02 requires 4 gpu -> score: 80
I1003 05:38:54.776338       1 log.go:194] css-host-129 has 3 gpu, falcon-pod-02 requires 4 gpu -> score: -1
I1003 05:38:54.798176       1 schedule_one.go:252] "Successfully bound pod to node" pod="default/falcon-pod-02" node="css-host-128" evaluatedNodes=2 feasibleNodes=2
I1003 05:39:19.712361       1 log.go:194] falcon-pod-03 in Prefilter
I1003 05:39:19.712872       1 log.go:194] falcon-pod-03 requires 4 gpu(s), and currently has 4 gpus(s) in total
I1003 05:39:19.719922       1 log.go:194] css-host-128 has 1 gpu, falcon-pod-03 requires 4 gpu -> score: -3
I1003 05:39:19.720016       1 log.go:194] css-host-129 has 3 gpu, falcon-pod-03 requires 4 gpu -> score: -1
I1003 05:39:19.732788       1 event.go:307] "Event occurred" object="default/falcon-pod-03" fieldPath="" kind="Pod" apiVersion="v1" type="Normal" reason="Reconfig" message="Pod falcon-pod-03 needs reconfiguration"
I1003 05:39:58.977887       1 schedule_one.go:252] "Successfully bound pod to node" pod="default/falcon-pod-03" node="css-host-129" evaluatedNodes=2 feasibleNodes=2
I1003 06:32:12.990539       1 log.go:194] falcon-pod-01 in Prefilter
I1003 06:32:12.991068       1 log.go:194] falcon-pod-01 requires 6 gpu(s), and currently has 8 gpus(s) in total
I1003 06:32:12.999123       1 log.go:194] css-host-128 has 4 gpu, falcon-pod-01 requires 6 gpu -> score: -2
I1003 06:32:12.999167       1 log.go:194] css-host-129 has 4 gpu, falcon-pod-01 requires 6 gpu -> score: -2
I1003 06:32:13.011996       1 event.go:307] "Event occurred" object="default/falcon-pod-01" fieldPath="" kind="Pod" apiVersion="v1" type="Normal" reason="Reconfig" message="Pod falcon-pod-01 needs reconfiguration"
I1003 06:33:25.403387       1 schedule_one.go:252] "Successfully bound pod to node" pod="default/falcon-pod-01" node="css-host-128" evaluatedNodes=2 feasibleNodes=2
I1003 06:35:58.231439       1 log.go:194] falcon-pod-02 in Prefilter
I1003 06:35:58.231971       1 log.go:194] falcon-pod-02 requires 4 gpu(s), and currently has 8 gpus(s) in total
I1003 06:35:58.238243       1 log.go:194] css-host-128 has 6 gpu, falcon-pod-02 requires 4 gpu -> score: 66
I1003 06:35:58.238277       1 log.go:194] css-host-129 has 2 gpu, falcon-pod-02 requires 4 gpu -> score: -2
I1003 06:35:58.246631       1 schedule_one.go:252] "Successfully bound pod to node" pod="default/falcon-pod-02" node="css-host-128" evaluatedNodes=2 feasibleNodes=2
I1003 06:36:28.502685       1 log.go:194] falcon-pod-03 in Prefilter
I1003 06:36:28.503169       1 log.go:194] falcon-pod-03 requires 4 gpu(s), and currently has 4 gpus(s) in total
I1003 06:36:28.510811       1 log.go:194] css-host-128 has 2 gpu, falcon-pod-03 requires 4 gpu -> score: -2
I1003 06:36:28.510918       1 log.go:194] css-host-129 has 2 gpu, falcon-pod-03 requires 4 gpu -> score: -2
I1003 06:36:28.522149       1 event.go:307] "Event occurred" object="default/falcon-pod-03" fieldPath="" kind="Pod" apiVersion="v1" type="Normal" reason="Reconfig" message="Pod falcon-pod-03 needs reconfiguration"
I1003 06:37:40.096511       1 schedule_one.go:252] "Successfully bound pod to node" pod="default/falcon-pod-03" node="css-host-129" evaluatedNodes=2 feasibleNodes=2
I1003 06:38:46.370989       1 log.go:194] falcon-pod-01 in Prefilter
I1003 06:38:46.371545       1 log.go:194] falcon-pod-01 requires 6 gpu(s), and currently has 8 gpus(s) in total
I1003 06:38:46.376894       1 log.go:194] css-host-128 has 4 gpu, falcon-pod-01 requires 6 gpu -> score: -2
I1003 06:38:46.377001       1 log.go:194] css-host-129 has 4 gpu, falcon-pod-01 requires 6 gpu -> score: -2
I1003 06:38:46.388242       1 event.go:307] "Event occurred" object="default/falcon-pod-01" fieldPath="" kind="Pod" apiVersion="v1" type="Normal" reason="Reconfig" message="Pod falcon-pod-01 needs reconfiguration"
I1003 06:39:55.027285       1 schedule_one.go:252] "Successfully bound pod to node" pod="default/falcon-pod-01" node="css-host-128" evaluatedNodes=2 feasibleNodes=2
I1003 06:41:02.955971       1 log.go:194] falcon-pod-02 in Prefilter
I1003 06:41:02.956525       1 log.go:194] falcon-pod-02 requires 4 gpu(s), and currently has 8 gpus(s) in total
I1003 06:41:02.962884       1 log.go:194] css-host-128 has 6 gpu, falcon-pod-02 requires 4 gpu -> score: 66
I1003 06:41:02.962908       1 log.go:194] css-host-129 has 2 gpu, falcon-pod-02 requires 4 gpu -> score: -2
I1003 06:41:02.974086       1 schedule_one.go:252] "Successfully bound pod to node" pod="default/falcon-pod-02" node="css-host-128" evaluatedNodes=2 feasibleNodes=2
I1003 06:41:31.810050       1 log.go:194] falcon-pod-03 in Prefilter
I1003 06:41:31.810536       1 log.go:194] falcon-pod-03 requires 4 gpu(s), and currently has 4 gpus(s) in total
I1003 06:41:31.818135       1 log.go:194] css-host-128 has 2 gpu, falcon-pod-03 requires 4 gpu -> score: -2
I1003 06:41:31.818167       1 log.go:194] css-host-129 has 2 gpu, falcon-pod-03 requires 4 gpu -> score: -2
I1003 06:41:31.827781       1 event.go:307] "Event occurred" object="default/falcon-pod-03" fieldPath="" kind="Pod" apiVersion="v1" type="Normal" reason="Reconfig" message="Pod falcon-pod-03 needs reconfiguration"
I1003 06:42:45.473933       1 schedule_one.go:252] "Successfully bound pod to node" pod="default/falcon-pod-03" node="css-host-129" evaluatedNodes=2 feasibleNodes=2
I1003 06:43:52.730679       1 log.go:194] falcon-pod-01 in Prefilter
I1003 06:43:52.731119       1 log.go:194] falcon-pod-01 requires 6 gpu(s), and currently has 8 gpus(s) in total
I1003 06:43:52.737760       1 log.go:194] css-host-128 has 4 gpu, falcon-pod-01 requires 6 gpu -> score: -2
I1003 06:43:52.737809       1 log.go:194] css-host-129 has 4 gpu, falcon-pod-01 requires 6 gpu -> score: -2
I1003 06:43:52.765462       1 event.go:307] "Event occurred" object="default/falcon-pod-01" fieldPath="" kind="Pod" apiVersion="v1" type="Normal" reason="Reconfig" message="Pod falcon-pod-01 needs reconfiguration"
I1003 06:45:11.392021       1 schedule_one.go:252] "Successfully bound pod to node" pod="default/falcon-pod-01" node="css-host-128" evaluatedNodes=2 feasibleNodes=2
I1003 06:46:24.312643       1 log.go:194] falcon-pod-02 in Prefilter
I1003 06:46:24.313100       1 log.go:194] falcon-pod-02 requires 4 gpu(s), and currently has 8 gpus(s) in total
I1003 06:46:24.526935       1 log.go:194] css-host-129 has 2 gpu, falcon-pod-02 requires 4 gpu -> score: -2
I1003 06:46:24.526985       1 log.go:194] css-host-128 has 6 gpu, falcon-pod-02 requires 4 gpu -> score: 66
I1003 06:46:24.527165       1 trace.go:219] Trace[279823697]: "Scheduling" namespace:default,name:falcon-pod-02 (03-Oct-2023 06:46:24.312) (total time: 214ms):
Trace[279823697]: ---"Computing predicates done" 214ms (06:46:24.526)
Trace[279823697]: [214.639714ms] [214.639714ms] END
I1003 06:46:24.535944       1 schedule_one.go:252] "Successfully bound pod to node" pod="default/falcon-pod-02" node="css-host-128" evaluatedNodes=2 feasibleNodes=2
I1003 06:46:50.088713       1 log.go:194] falcon-pod-03 in Prefilter
I1003 06:46:50.089125       1 log.go:194] falcon-pod-03 requires 4 gpu(s), and currently has 4 gpus(s) in total
I1003 06:46:50.097125       1 log.go:194] css-host-128 has 2 gpu, falcon-pod-03 requires 4 gpu -> score: -2
I1003 06:46:50.097163       1 log.go:194] css-host-129 has 2 gpu, falcon-pod-03 requires 4 gpu -> score: -2
I1003 06:46:50.107994       1 event.go:307] "Event occurred" object="default/falcon-pod-03" fieldPath="" kind="Pod" apiVersion="v1" type="Normal" reason="Reconfig" message="Pod falcon-pod-03 needs reconfiguration"
I1003 06:48:04.495122       1 schedule_one.go:252] "Successfully bound pod to node" pod="default/falcon-pod-03" node="css-host-128" evaluatedNodes=2 feasibleNodes=2
