2023/09/16 08:18:54 falconresources-scheduler starts!
I0916 08:18:54.633022       1 flags.go:64] FLAG: --allow-metric-labels="[]"
I0916 08:18:54.633526       1 flags.go:64] FLAG: --authentication-kubeconfig=""
I0916 08:18:54.633535       1 flags.go:64] FLAG: --authentication-skip-lookup="false"
I0916 08:18:54.633542       1 flags.go:64] FLAG: --authentication-token-webhook-cache-ttl="10s"
I0916 08:18:54.633550       1 flags.go:64] FLAG: --authentication-tolerate-lookup-failure="true"
I0916 08:18:54.633555       1 flags.go:64] FLAG: --authorization-always-allow-paths="[/healthz,/readyz,/livez]"
I0916 08:18:54.633631       1 flags.go:64] FLAG: --authorization-kubeconfig=""
I0916 08:18:54.633635       1 flags.go:64] FLAG: --authorization-webhook-cache-authorized-ttl="10s"
I0916 08:18:54.633639       1 flags.go:64] FLAG: --authorization-webhook-cache-unauthorized-ttl="10s"
I0916 08:18:54.633642       1 flags.go:64] FLAG: --bind-address="0.0.0.0"
I0916 08:18:54.633648       1 flags.go:64] FLAG: --cert-dir=""
I0916 08:18:54.633651       1 flags.go:64] FLAG: --client-ca-file=""
I0916 08:18:54.633654       1 flags.go:64] FLAG: --config="/etc/kubernetes/scheduler-config.yaml"
I0916 08:18:54.633658       1 flags.go:64] FLAG: --contention-profiling="true"
I0916 08:18:54.633661       1 flags.go:64] FLAG: --disabled-metrics="[]"
I0916 08:18:54.633668       1 flags.go:64] FLAG: --feature-gates=""
I0916 08:18:54.633679       1 flags.go:64] FLAG: --help="false"
I0916 08:18:54.633683       1 flags.go:64] FLAG: --http2-max-streams-per-connection="0"
I0916 08:18:54.633690       1 flags.go:64] FLAG: --kube-api-burst="100"
I0916 08:18:54.633699       1 flags.go:64] FLAG: --kube-api-content-type="application/vnd.kubernetes.protobuf"
I0916 08:18:54.633704       1 flags.go:64] FLAG: --kube-api-qps="50"
I0916 08:18:54.633772       1 flags.go:64] FLAG: --kubeconfig=""
I0916 08:18:54.633776       1 flags.go:64] FLAG: --leader-elect="true"
I0916 08:18:54.633780       1 flags.go:64] FLAG: --leader-elect-lease-duration="15s"
I0916 08:18:54.633783       1 flags.go:64] FLAG: --leader-elect-renew-deadline="10s"
I0916 08:18:54.633787       1 flags.go:64] FLAG: --leader-elect-resource-lock="leases"
I0916 08:18:54.633791       1 flags.go:64] FLAG: --leader-elect-resource-name="kube-scheduler"
I0916 08:18:54.633796       1 flags.go:64] FLAG: --leader-elect-resource-namespace="kube-system"
I0916 08:18:54.633801       1 flags.go:64] FLAG: --leader-elect-retry-period="2s"
I0916 08:18:54.633805       1 flags.go:64] FLAG: --lock-object-name="kube-scheduler"
I0916 08:18:54.633809       1 flags.go:64] FLAG: --lock-object-namespace="kube-system"
I0916 08:18:54.633813       1 flags.go:64] FLAG: --log-flush-frequency="5s"
I0916 08:18:54.633817       1 flags.go:64] FLAG: --logging-format="text"
I0916 08:18:54.633821       1 flags.go:64] FLAG: --master=""
I0916 08:18:54.633826       1 flags.go:64] FLAG: --permit-address-sharing="false"
I0916 08:18:54.633830       1 flags.go:64] FLAG: --permit-port-sharing="false"
I0916 08:18:54.633835       1 flags.go:64] FLAG: --pod-max-in-unschedulable-pods-duration="5m0s"
I0916 08:18:54.633841       1 flags.go:64] FLAG: --profiling="true"
I0916 08:18:54.633845       1 flags.go:64] FLAG: --requestheader-allowed-names="[]"
I0916 08:18:54.633867       1 flags.go:64] FLAG: --requestheader-client-ca-file=""
I0916 08:18:54.633870       1 flags.go:64] FLAG: --requestheader-extra-headers-prefix="[x-remote-extra-]"
I0916 08:18:54.633877       1 flags.go:64] FLAG: --requestheader-group-headers="[x-remote-group]"
I0916 08:18:54.633884       1 flags.go:64] FLAG: --requestheader-username-headers="[x-remote-user]"
I0916 08:18:54.633889       1 flags.go:64] FLAG: --secure-port="10259"
I0916 08:18:54.633892       1 flags.go:64] FLAG: --show-hidden-metrics-for-version=""
I0916 08:18:54.633895       1 flags.go:64] FLAG: --tls-cert-file=""
I0916 08:18:54.633898       1 flags.go:64] FLAG: --tls-cipher-suites="[]"
I0916 08:18:54.633904       1 flags.go:64] FLAG: --tls-min-version=""
I0916 08:18:54.633907       1 flags.go:64] FLAG: --tls-private-key-file=""
I0916 08:18:54.633910       1 flags.go:64] FLAG: --tls-sni-cert-key="[]"
I0916 08:18:54.633916       1 flags.go:64] FLAG: --v="3"
I0916 08:18:54.633922       1 flags.go:64] FLAG: --version="false"
I0916 08:18:54.633933       1 flags.go:64] FLAG: --vmodule=""
I0916 08:18:54.633939       1 flags.go:64] FLAG: --write-config-to=""
I0916 08:18:54.991957       1 serving.go:348] Generated self-signed cert in-memory
I0916 08:18:54.992903       1 configfile.go:59] "KubeSchedulerConfiguration v1beta3 is deprecated in v1.26, will be removed in v1.29"
W0916 08:18:54.992984       1 client_config.go:618] Neither --kubeconfig nor --master was specified.  Using the inClusterConfig.  This might not work.
I0916 08:18:55.596033       1 requestheader_controller.go:244] Loaded a new request header values for RequestHeaderAuthRequestController
I0916 08:18:55.608918       1 configfile.go:105] "Using component config" config=<
	apiVersion: kubescheduler.config.k8s.io/v1beta3
	clientConnection:
	  acceptContentTypes: ""
	  burst: 100
	  contentType: application/vnd.kubernetes.protobuf
	  kubeconfig: ""
	  qps: 50
	enableContentionProfiling: true
	enableProfiling: true
	kind: KubeSchedulerConfiguration
	leaderElection:
	  leaderElect: false
	  leaseDuration: 15s
	  renewDeadline: 10s
	  resourceLock: leases
	  resourceName: kube-scheduler
	  resourceNamespace: kube-system
	  retryPeriod: 2s
	parallelism: 16
	percentageOfNodesToScore: 0
	podInitialBackoffSeconds: 1
	podMaxBackoffSeconds: 10
	profiles:
	- pluginConfig:
	  - args:
	      apiVersion: kubescheduler.config.k8s.io/v1beta3
	      kind: DefaultPreemptionArgs
	      minCandidateNodesAbsolute: 100
	      minCandidateNodesPercentage: 10
	    name: DefaultPreemption
	  - args:
	      apiVersion: kubescheduler.config.k8s.io/v1beta3
	      hardPodAffinityWeight: 1
	      ignorePreferredTermsOfExistingPods: false
	      kind: InterPodAffinityArgs
	    name: InterPodAffinity
	  - args:
	      apiVersion: kubescheduler.config.k8s.io/v1beta3
	      kind: NodeAffinityArgs
	    name: NodeAffinity
	  - args:
	      apiVersion: kubescheduler.config.k8s.io/v1beta3
	      kind: NodeResourcesBalancedAllocationArgs
	      resources:
	      - name: cpu
	        weight: 1
	      - name: memory
	        weight: 1
	    name: NodeResourcesBalancedAllocation
	  - args:
	      apiVersion: kubescheduler.config.k8s.io/v1beta3
	      ignoredResourceGroups:
	      - falcon.com
	      kind: NodeResourcesFitArgs
	      scoringStrategy:
	        resources:
	        - name: cpu
	          weight: 1
	        - name: memory
	          weight: 1
	        type: LeastAllocated
	    name: NodeResourcesFit
	  - args:
	      apiVersion: kubescheduler.config.k8s.io/v1beta3
	      defaultingType: System
	      kind: PodTopologySpreadArgs
	    name: PodTopologySpread
	  - args:
	      apiVersion: kubescheduler.config.k8s.io/v1beta3
	      bindTimeoutSeconds: 600
	      kind: VolumeBindingArgs
	    name: VolumeBinding
	  plugins:
	    bind: {}
	    filter: {}
	    multiPoint:
	      enabled:
	      - name: PrioritySort
	        weight: 0
	      - name: NodeUnschedulable
	        weight: 0
	      - name: NodeName
	        weight: 0
	      - name: TaintToleration
	        weight: 3
	      - name: NodeAffinity
	        weight: 2
	      - name: NodePorts
	        weight: 0
	      - name: NodeResourcesFit
	        weight: 1
	      - name: VolumeRestrictions
	        weight: 0
	      - name: EBSLimits
	        weight: 0
	      - name: GCEPDLimits
	        weight: 0
	      - name: NodeVolumeLimits
	        weight: 0
	      - name: AzureDiskLimits
	        weight: 0
	      - name: VolumeBinding
	        weight: 0
	      - name: VolumeZone
	        weight: 0
	      - name: PodTopologySpread
	        weight: 2
	      - name: InterPodAffinity
	        weight: 2
	      - name: DefaultPreemption
	        weight: 0
	      - name: NodeResourcesBalancedAllocation
	        weight: 1
	      - name: ImageLocality
	        weight: 1
	      - name: DefaultBinder
	        weight: 0
	      - name: SchedulingGates
	        weight: 0
	      - name: FalconResources
	        weight: 0
	    permit: {}
	    postBind: {}
	    postFilter: {}
	    preBind: {}
	    preEnqueue: {}
	    preFilter: {}
	    preScore: {}
	    queueSort: {}
	    reserve: {}
	    score: {}
	  schedulerName: my-scheduler
 >
I0916 08:18:55.609486       1 server.go:154] "Starting Kubernetes Scheduler" version="v0.0.0-master+$Format:%H$"
I0916 08:18:55.609505       1 server.go:156] "Golang settings" GOGC="" GOMAXPROCS="" GOTRACEBACK=""
I0916 08:18:55.614670       1 requestheader_controller.go:169] Starting RequestHeaderAuthRequestController
I0916 08:18:55.614715       1 shared_informer.go:311] Waiting for caches to sync for RequestHeaderAuthRequestController
I0916 08:18:55.614734       1 configmap_cafile_content.go:202] "Starting controller" name="client-ca::kube-system::extension-apiserver-authentication::client-ca-file"
I0916 08:18:55.614756       1 configmap_cafile_content.go:202] "Starting controller" name="client-ca::kube-system::extension-apiserver-authentication::requestheader-client-ca-file"
I0916 08:18:55.614857       1 shared_informer.go:311] Waiting for caches to sync for client-ca::kube-system::extension-apiserver-authentication::requestheader-client-ca-file
I0916 08:18:55.614860       1 reflector.go:287] Starting reflector *v1.ConfigMap (12h0m0s) from pkg/mod/k8s.io/client-go@v0.27.1/tools/cache/reflector.go:231
I0916 08:18:55.614874       1 reflector.go:323] Listing and watching *v1.ConfigMap from pkg/mod/k8s.io/client-go@v0.27.1/tools/cache/reflector.go:231
I0916 08:18:55.614885       1 reflector.go:287] Starting reflector *v1.ConfigMap (12h0m0s) from pkg/mod/k8s.io/client-go@v0.27.1/tools/cache/reflector.go:231
I0916 08:18:55.614904       1 reflector.go:323] Listing and watching *v1.ConfigMap from pkg/mod/k8s.io/client-go@v0.27.1/tools/cache/reflector.go:231
I0916 08:18:55.614768       1 shared_informer.go:311] Waiting for caches to sync for client-ca::kube-system::extension-apiserver-authentication::client-ca-file
I0916 08:18:55.615034       1 reflector.go:287] Starting reflector *v1.ConfigMap (12h0m0s) from pkg/mod/k8s.io/client-go@v0.27.1/tools/cache/reflector.go:231
I0916 08:18:55.615068       1 reflector.go:323] Listing and watching *v1.ConfigMap from pkg/mod/k8s.io/client-go@v0.27.1/tools/cache/reflector.go:231
I0916 08:18:55.615173       1 tlsconfig.go:200] "Loaded serving cert" certName="Generated self signed cert" certDetail="\"localhost@1694852334\" [serving] validServingFor=[127.0.0.1,localhost,localhost] issuer=\"localhost-ca@1694852334\" (2023-09-16 07:18:54 +0000 UTC to 2024-09-15 07:18:54 +0000 UTC (now=2023-09-16 08:18:55.615119949 +0000 UTC))"
I0916 08:18:55.615684       1 named_certificates.go:53] "Loaded SNI cert" index=0 certName="self-signed loopback" certDetail="\"apiserver-loopback-client@1694852335\" [serving] validServingFor=[apiserver-loopback-client] issuer=\"apiserver-loopback-client-ca@1694852335\" (2023-09-16 07:18:54 +0000 UTC to 2024-09-15 07:18:54 +0000 UTC (now=2023-09-16 08:18:55.615644341 +0000 UTC))"
I0916 08:18:55.615724       1 secure_serving.go:210] Serving securely on [::]:10259
I0916 08:18:55.615812       1 tlsconfig.go:240] "Starting DynamicServingCertificateController"
I0916 08:18:55.615860       1 reflector.go:287] Starting reflector *v1.ReplicationController (0s) from pkg/mod/k8s.io/client-go@v0.27.1/tools/cache/reflector.go:231
I0916 08:18:55.615908       1 reflector.go:287] Starting reflector *v1.Pod (0s) from pkg/mod/k8s.io/client-go@v0.27.1/tools/cache/reflector.go:231
I0916 08:18:55.615914       1 reflector.go:323] Listing and watching *v1.ReplicationController from pkg/mod/k8s.io/client-go@v0.27.1/tools/cache/reflector.go:231
I0916 08:18:55.615920       1 reflector.go:323] Listing and watching *v1.Pod from pkg/mod/k8s.io/client-go@v0.27.1/tools/cache/reflector.go:231
I0916 08:18:55.615962       1 reflector.go:287] Starting reflector *v1.PersistentVolumeClaim (0s) from pkg/mod/k8s.io/client-go@v0.27.1/tools/cache/reflector.go:231
I0916 08:18:55.615979       1 reflector.go:323] Listing and watching *v1.PersistentVolumeClaim from pkg/mod/k8s.io/client-go@v0.27.1/tools/cache/reflector.go:231
I0916 08:18:55.616045       1 reflector.go:287] Starting reflector *v1.Node (0s) from pkg/mod/k8s.io/client-go@v0.27.1/tools/cache/reflector.go:231
I0916 08:18:55.616062       1 reflector.go:323] Listing and watching *v1.Node from pkg/mod/k8s.io/client-go@v0.27.1/tools/cache/reflector.go:231
I0916 08:18:55.616103       1 reflector.go:287] Starting reflector *v1.CSIStorageCapacity (0s) from pkg/mod/k8s.io/client-go@v0.27.1/tools/cache/reflector.go:231
I0916 08:18:55.615861       1 reflector.go:287] Starting reflector *v1.Namespace (0s) from pkg/mod/k8s.io/client-go@v0.27.1/tools/cache/reflector.go:231
I0916 08:18:55.616139       1 reflector.go:323] Listing and watching *v1.CSIStorageCapacity from pkg/mod/k8s.io/client-go@v0.27.1/tools/cache/reflector.go:231
I0916 08:18:55.616144       1 reflector.go:323] Listing and watching *v1.Namespace from pkg/mod/k8s.io/client-go@v0.27.1/tools/cache/reflector.go:231
I0916 08:18:55.616169       1 reflector.go:287] Starting reflector *v1.CSINode (0s) from pkg/mod/k8s.io/client-go@v0.27.1/tools/cache/reflector.go:231
I0916 08:18:55.616213       1 reflector.go:323] Listing and watching *v1.CSINode from pkg/mod/k8s.io/client-go@v0.27.1/tools/cache/reflector.go:231
I0916 08:18:55.615903       1 reflector.go:287] Starting reflector *v1.ReplicaSet (0s) from pkg/mod/k8s.io/client-go@v0.27.1/tools/cache/reflector.go:231
I0916 08:18:55.616275       1 reflector.go:323] Listing and watching *v1.ReplicaSet from pkg/mod/k8s.io/client-go@v0.27.1/tools/cache/reflector.go:231
I0916 08:18:55.616313       1 reflector.go:287] Starting reflector *v1.PodDisruptionBudget (0s) from pkg/mod/k8s.io/client-go@v0.27.1/tools/cache/reflector.go:231
I0916 08:18:55.616327       1 reflector.go:323] Listing and watching *v1.PodDisruptionBudget from pkg/mod/k8s.io/client-go@v0.27.1/tools/cache/reflector.go:231
I0916 08:18:55.616304       1 reflector.go:287] Starting reflector *v1.StatefulSet (0s) from pkg/mod/k8s.io/client-go@v0.27.1/tools/cache/reflector.go:231
I0916 08:18:55.619994       1 reflector.go:323] Listing and watching *v1.StatefulSet from pkg/mod/k8s.io/client-go@v0.27.1/tools/cache/reflector.go:231
I0916 08:18:55.620423       1 reflector.go:287] Starting reflector *v1.CSIDriver (0s) from pkg/mod/k8s.io/client-go@v0.27.1/tools/cache/reflector.go:231
I0916 08:18:55.620468       1 reflector.go:323] Listing and watching *v1.CSIDriver from pkg/mod/k8s.io/client-go@v0.27.1/tools/cache/reflector.go:231
I0916 08:18:55.620599       1 reflector.go:287] Starting reflector *v1.PersistentVolume (0s) from pkg/mod/k8s.io/client-go@v0.27.1/tools/cache/reflector.go:231
I0916 08:18:55.620686       1 reflector.go:323] Listing and watching *v1.PersistentVolume from pkg/mod/k8s.io/client-go@v0.27.1/tools/cache/reflector.go:231
I0916 08:18:55.621419       1 reflector.go:287] Starting reflector *v1.StorageClass (0s) from pkg/mod/k8s.io/client-go@v0.27.1/tools/cache/reflector.go:231
I0916 08:18:55.621480       1 reflector.go:323] Listing and watching *v1.StorageClass from pkg/mod/k8s.io/client-go@v0.27.1/tools/cache/reflector.go:231
I0916 08:18:55.623295       1 reflector.go:287] Starting reflector *v1.Service (0s) from pkg/mod/k8s.io/client-go@v0.27.1/tools/cache/reflector.go:231
I0916 08:18:55.623328       1 reflector.go:323] Listing and watching *v1.Service from pkg/mod/k8s.io/client-go@v0.27.1/tools/cache/reflector.go:231
I0916 08:18:55.624302       1 node_tree.go:65] "Added node in listed group to NodeTree" node="css-host-128" zone=""
I0916 08:18:55.624577       1 eventhandlers.go:71] "Add event for node" node="css-host-128"
I0916 08:18:55.624601       1 node_tree.go:65] "Added node in listed group to NodeTree" node="css-host-129" zone=""
I0916 08:18:55.624653       1 eventhandlers.go:71] "Add event for node" node="css-host-129"
I0916 08:18:55.626401       1 httplog.go:132] "HTTP" verb="GET" URI="/healthz" latency="118.161µs" userAgent="kube-probe/1.27" audit-ID="" srcIP="10.44.0.0:57430" resp=200
I0916 08:18:55.627002       1 eventhandlers.go:186] "Add event for scheduled pod" pod="scheduler-plugins/my-scheduler-56978dd65-vpfqd"
I0916 08:18:55.627088       1 eventhandlers.go:186] "Add event for scheduled pod" pod="kube-system/falcon-m929b"
I0916 08:18:55.627141       1 eventhandlers.go:186] "Add event for scheduled pod" pod="kube-system/coredns-787d4945fb-fxpw5"
I0916 08:18:55.627195       1 eventhandlers.go:186] "Add event for scheduled pod" pod="kube-system/etcd-css-host-129"
I0916 08:18:55.627232       1 eventhandlers.go:186] "Add event for scheduled pod" pod="kube-system/falcon-4lr2s"
I0916 08:18:55.627287       1 eventhandlers.go:186] "Add event for scheduled pod" pod="kube-system/kube-apiserver-css-host-129"
I0916 08:18:55.627303       1 eventhandlers.go:186] "Add event for scheduled pod" pod="kube-system/kube-controller-manager-css-host-129"
I0916 08:18:55.627317       1 eventhandlers.go:186] "Add event for scheduled pod" pod="kube-system/kube-proxy-297fd"
I0916 08:18:55.627326       1 eventhandlers.go:186] "Add event for scheduled pod" pod="default/gpu-exporter-7876f49579-7qrtj"
I0916 08:18:55.627349       1 eventhandlers.go:186] "Add event for scheduled pod" pod="kube-system/reconfig-daemon-wbrbz"
I0916 08:18:55.627361       1 eventhandlers.go:186] "Add event for scheduled pod" pod="monitoring/gpu-exporter-7876f49579-w4l57"
I0916 08:18:55.627370       1 eventhandlers.go:186] "Add event for scheduled pod" pod="monitoring/prometheus-prometheus-node-exporter-dv98k"
I0916 08:18:55.627385       1 eventhandlers.go:186] "Add event for scheduled pod" pod="kube-system/coredns-787d4945fb-fnx4g"
I0916 08:18:55.627406       1 eventhandlers.go:186] "Add event for scheduled pod" pod="kube-system/kube-scheduler-css-host-129"
I0916 08:18:55.627417       1 eventhandlers.go:186] "Add event for scheduled pod" pod="kube-system/weave-net-sgvv7"
I0916 08:18:55.627432       1 eventhandlers.go:186] "Add event for scheduled pod" pod="monitoring/prometheus-server-7c9757cccb-844wl"
I0916 08:18:55.627448       1 eventhandlers.go:186] "Add event for scheduled pod" pod="kube-system/kube-proxy-q8lnh"
I0916 08:18:55.627457       1 eventhandlers.go:186] "Add event for scheduled pod" pod="kube-system/weave-net-fdqkm"
I0916 08:18:55.627478       1 eventhandlers.go:186] "Add event for scheduled pod" pod="monitoring/prometheus-kube-state-metrics-86894fb745-nj2nr"
I0916 08:18:55.627519       1 eventhandlers.go:186] "Add event for scheduled pod" pod="monitoring/prometheus-prometheus-node-exporter-cwvqp"
I0916 08:18:55.627530       1 eventhandlers.go:186] "Add event for scheduled pod" pod="monitoring/prometheus-prometheus-pushgateway-7cb5dd797-6zmbm"
I0916 08:18:55.715302       1 shared_informer.go:318] Caches are synced for client-ca::kube-system::extension-apiserver-authentication::requestheader-client-ca-file
I0916 08:18:55.715324       1 shared_informer.go:318] Caches are synced for client-ca::kube-system::extension-apiserver-authentication::client-ca-file
I0916 08:18:55.715391       1 shared_informer.go:318] Caches are synced for RequestHeaderAuthRequestController
I0916 08:18:55.715756       1 tlsconfig.go:178] "Loaded client CA" index=0 certName="client-ca::kube-system::extension-apiserver-authentication::client-ca-file,client-ca::kube-system::extension-apiserver-authentication::requestheader-client-ca-file" certDetail="\"kubernetes\" [] validServingFor=[kubernetes] issuer=\"<self>\" (2023-02-25 05:20:24 +0000 UTC to 2033-02-22 05:20:24 +0000 UTC (now=2023-09-16 08:18:55.715711719 +0000 UTC))"
I0916 08:18:55.715816       1 tlsconfig.go:178] "Loaded client CA" index=1 certName="client-ca::kube-system::extension-apiserver-authentication::client-ca-file,client-ca::kube-system::extension-apiserver-authentication::requestheader-client-ca-file" certDetail="\"front-proxy-ca\" [] validServingFor=[front-proxy-ca] issuer=\"<self>\" (2023-02-25 05:20:25 +0000 UTC to 2033-02-22 05:20:25 +0000 UTC (now=2023-09-16 08:18:55.71578182 +0000 UTC))"
I0916 08:18:55.716595       1 tlsconfig.go:200] "Loaded serving cert" certName="Generated self signed cert" certDetail="\"localhost@1694852334\" [serving] validServingFor=[127.0.0.1,localhost,localhost] issuer=\"localhost-ca@1694852334\" (2023-09-16 07:18:54 +0000 UTC to 2024-09-15 07:18:54 +0000 UTC (now=2023-09-16 08:18:55.716562253 +0000 UTC))"
I0916 08:18:55.717288       1 named_certificates.go:53] "Loaded SNI cert" index=0 certName="self-signed loopback" certDetail="\"apiserver-loopback-client@1694852335\" [serving] validServingFor=[apiserver-loopback-client] issuer=\"apiserver-loopback-client-ca@1694852335\" (2023-09-16 07:18:54 +0000 UTC to 2024-09-15 07:18:54 +0000 UTC (now=2023-09-16 08:18:55.71725463 +0000 UTC))"
I0916 08:19:01.703684       1 httplog.go:132] "HTTP" verb="GET" URI="/healthz" latency="135.233µs" userAgent="kube-probe/1.27" audit-ID="" srcIP="10.44.0.0:44298" resp=200
I0916 08:19:11.702079       1 httplog.go:132] "HTTP" verb="GET" URI="/healthz" latency="136.485µs" userAgent="kube-probe/1.27" audit-ID="" srcIP="10.44.0.0:54196" resp=200
I0916 08:19:11.706306       1 httplog.go:132] "HTTP" verb="GET" URI="/healthz" latency="168.165µs" userAgent="kube-probe/1.27" audit-ID="" srcIP="10.44.0.0:54204" resp=200
I0916 08:19:21.707046       1 httplog.go:132] "HTTP" verb="GET" URI="/healthz" latency="123.441µs" userAgent="kube-probe/1.27" audit-ID="" srcIP="10.44.0.0:58416" resp=200
I0916 08:19:21.708145       1 httplog.go:132] "HTTP" verb="GET" URI="/healthz" latency="52.739µs" userAgent="kube-probe/1.27" audit-ID="" srcIP="10.44.0.0:58412" resp=200
I0916 08:19:31.702276       1 httplog.go:132] "HTTP" verb="GET" URI="/healthz" latency="96.461µs" userAgent="kube-probe/1.27" audit-ID="" srcIP="10.44.0.0:43274" resp=200
I0916 08:19:31.709603       1 httplog.go:132] "HTTP" verb="GET" URI="/healthz" latency="38.282µs" userAgent="kube-probe/1.27" audit-ID="" srcIP="10.44.0.0:43278" resp=200
I0916 08:19:41.706845       1 httplog.go:132] "HTTP" verb="GET" URI="/healthz" latency="108.534µs" userAgent="kube-probe/1.27" audit-ID="" srcIP="10.44.0.0:42218" resp=200
I0916 08:19:41.708182       1 httplog.go:132] "HTTP" verb="GET" URI="/healthz" latency="124.714µs" userAgent="kube-probe/1.27" audit-ID="" srcIP="10.44.0.0:42220" resp=200
I0916 08:19:51.706562       1 httplog.go:132] "HTTP" verb="GET" URI="/healthz" latency="134.953µs" userAgent="kube-probe/1.27" audit-ID="" srcIP="10.44.0.0:34258" resp=200
I0916 08:19:51.707669       1 httplog.go:132] "HTTP" verb="GET" URI="/healthz" latency="80.771µs" userAgent="kube-probe/1.27" audit-ID="" srcIP="10.44.0.0:34270" resp=200
I0916 08:20:01.706755       1 httplog.go:132] "HTTP" verb="GET" URI="/healthz" latency="98.504µs" userAgent="kube-probe/1.27" audit-ID="" srcIP="10.44.0.0:46314" resp=200
I0916 08:20:01.707864       1 httplog.go:132] "HTTP" verb="GET" URI="/healthz" latency="29.706µs" userAgent="kube-probe/1.27" audit-ID="" srcIP="10.44.0.0:46310" resp=200
I0916 08:20:11.707268       1 httplog.go:132] "HTTP" verb="GET" URI="/healthz" latency="151.043µs" userAgent="kube-probe/1.27" audit-ID="" srcIP="10.44.0.0:43488" resp=200
I0916 08:20:11.708270       1 httplog.go:132] "HTTP" verb="GET" URI="/healthz" latency="70.632µs" userAgent="kube-probe/1.27" audit-ID="" srcIP="10.44.0.0:43472" resp=200
I0916 08:20:21.706994       1 httplog.go:132] "HTTP" verb="GET" URI="/healthz" latency="99.256µs" userAgent="kube-probe/1.27" audit-ID="" srcIP="10.44.0.0:37438" resp=200
I0916 08:20:21.708101       1 httplog.go:132] "HTTP" verb="GET" URI="/healthz" latency="136.566µs" userAgent="kube-probe/1.27" audit-ID="" srcIP="10.44.0.0:37424" resp=200
I0916 08:20:31.706711       1 httplog.go:132] "HTTP" verb="GET" URI="/healthz" latency="98.364µs" userAgent="kube-probe/1.27" audit-ID="" srcIP="10.44.0.0:50784" resp=200
I0916 08:20:31.707753       1 httplog.go:132] "HTTP" verb="GET" URI="/healthz" latency="78.999µs" userAgent="kube-probe/1.27" audit-ID="" srcIP="10.44.0.0:50778" resp=200
I0916 08:20:41.702162       1 httplog.go:132] "HTTP" verb="GET" URI="/healthz" latency="149.149µs" userAgent="kube-probe/1.27" audit-ID="" srcIP="10.44.0.0:40850" resp=200
I0916 08:20:41.703420       1 httplog.go:132] "HTTP" verb="GET" URI="/healthz" latency="73.398µs" userAgent="kube-probe/1.27" audit-ID="" srcIP="10.44.0.0:40848" resp=200
I0916 08:20:51.706744       1 httplog.go:132] "HTTP" verb="GET" URI="/healthz" latency="110.247µs" userAgent="kube-probe/1.27" audit-ID="" srcIP="10.44.0.0:51320" resp=200
I0916 08:20:51.707920       1 httplog.go:132] "HTTP" verb="GET" URI="/healthz" latency="101.37µs" userAgent="kube-probe/1.27" audit-ID="" srcIP="10.44.0.0:51304" resp=200
I0916 08:21:01.701585       1 httplog.go:132] "HTTP" verb="GET" URI="/healthz" latency="180.798µs" userAgent="kube-probe/1.27" audit-ID="" srcIP="10.44.0.0:51280" resp=200
I0916 08:21:01.703266       1 httplog.go:132] "HTTP" verb="GET" URI="/healthz" latency="66.514µs" userAgent="kube-probe/1.27" audit-ID="" srcIP="10.44.0.0:51276" resp=200
I0916 08:21:04.536751       1 eventhandlers.go:118] "Add event for unscheduled pod" pod="default/falcon-pod-502950"
I0916 08:21:04.536883       1 schedule_one.go:80] "Attempting to schedule pod" pod="default/falcon-pod-502950"
I0916 08:21:04.537617       1 log.go:194] require 2 gpu(s), and currently has 8 gpus(s) in total
I0916 08:21:04.548352       1 log.go:194] css-host-128 has 4 gpu, the pod requires 2 gpu -> score: 50
I0916 08:21:04.548446       1 log.go:194] css-host-129 has 4 gpu, the pod requires 2 gpu -> score: 50
I0916 08:21:04.549122       1 log.go:194] permit plugin
I0916 08:21:04.554411       1 log.go:194] alloc: 4, used: 0, required: 2
I0916 08:21:04.558371       1 log.go:194] alloc: 4, used: 0, required: 2
I0916 08:21:04.558581       1 default_binder.go:53] "Attempting to bind pod to node" pod="default/falcon-pod-502950" node="css-host-128"
I0916 08:21:04.562749       1 eventhandlers.go:161] "Delete event for unscheduled pod" pod="default/falcon-pod-502950"
I0916 08:21:04.562798       1 eventhandlers.go:186] "Add event for scheduled pod" pod="default/falcon-pod-502950"
I0916 08:21:04.563139       1 schedule_one.go:252] "Successfully bound pod to node" pod="default/falcon-pod-502950" node="css-host-128" evaluatedNodes=2 feasibleNodes=2
I0916 08:21:06.790029       1 eventhandlers.go:118] "Add event for unscheduled pod" pod="default/falcon-pod-458562"
I0916 08:21:06.790106       1 schedule_one.go:80] "Attempting to schedule pod" pod="default/falcon-pod-458562"
I0916 08:21:06.790705       1 log.go:194] require 4 gpu(s), and currently has 6 gpus(s) in total
I0916 08:21:06.803289       1 log.go:194] css-host-128 has 2 gpu, the pod requires 4 gpu -> score: -2
I0916 08:21:06.803383       1 log.go:194] css-host-129 has 4 gpu, the pod requires 4 gpu -> score: 1
I0916 08:21:06.803745       1 log.go:194] permit plugin
I0916 08:21:06.808179       1 log.go:194] alloc: 4, used: 0, required: 4
I0916 08:21:06.812021       1 log.go:194] alloc: 4, used: 0, required: 4
I0916 08:21:06.812139       1 default_binder.go:53] "Attempting to bind pod to node" pod="default/falcon-pod-458562" node="css-host-129"
I0916 08:21:06.815882       1 schedule_one.go:252] "Successfully bound pod to node" pod="default/falcon-pod-458562" node="css-host-129" evaluatedNodes=2 feasibleNodes=2
I0916 08:21:06.816063       1 eventhandlers.go:186] "Add event for scheduled pod" pod="default/falcon-pod-458562"
I0916 08:21:06.816187       1 eventhandlers.go:161] "Delete event for unscheduled pod" pod="default/falcon-pod-458562"
I0916 08:21:10.039352       1 eventhandlers.go:118] "Add event for unscheduled pod" pod="default/falcon-pod-867106"
I0916 08:21:10.039467       1 schedule_one.go:80] "Attempting to schedule pod" pod="default/falcon-pod-867106"
I0916 08:21:10.040119       1 log.go:194] require 4 gpu(s), and currently has 2 gpus(s) in total
I0916 08:21:10.046895       1 schedule_one.go:867] "Unable to schedule pod; no fit; waiting" pod="default/falcon-pod-867106" err="0/2 nodes are available: Require 4 gpu but only 2 gpu in the pool.. preemption: 0/2 nodes are available: 2 No preemption victims found for incoming pod.."
E0916 08:21:10.046977       1 schedule_one.go:902] "Error occurred" err="Pod default/falcon-pod-867106 is already present in the active queue"
I0916 08:21:10.047095       1 schedule_one.go:943] "Updating pod condition" pod="default/falcon-pod-867106" conditionType=PodScheduled conditionStatus=False conditionReason="Unschedulable"
I0916 08:21:10.056027       1 schedule_one.go:80] "Attempting to schedule pod" pod="default/falcon-pod-867106"
I0916 08:21:10.056436       1 log.go:194] require 4 gpu(s), and currently has 2 gpus(s) in total
I0916 08:21:10.062866       1 schedule_one.go:867] "Unable to schedule pod; no fit; waiting" pod="default/falcon-pod-867106" err="0/2 nodes are available: Require 4 gpu but only 2 gpu in the pool.. preemption: 0/2 nodes are available: 2 No preemption victims found for incoming pod.."
E0916 08:21:10.062947       1 schedule_one.go:902] "Error occurred" err="Pod default/falcon-pod-867106 is already present in the active queue"
I0916 08:21:10.063055       1 schedule_one.go:943] "Updating pod condition" pod="default/falcon-pod-867106" conditionType=PodScheduled conditionStatus=False conditionReason="Unschedulable"
I0916 08:21:10.068327       1 schedule_one.go:80] "Attempting to schedule pod" pod="default/falcon-pod-867106"
I0916 08:21:10.068730       1 log.go:194] require 4 gpu(s), and currently has 2 gpus(s) in total
I0916 08:21:10.091421       1 schedule_one.go:867] "Unable to schedule pod; no fit; waiting" pod="default/falcon-pod-867106" err="0/2 nodes are available: Require 4 gpu but only 2 gpu in the pool.. preemption: 0/2 nodes are available: 2 No preemption victims found for incoming pod.."
I0916 08:21:10.091529       1 schedule_one.go:943] "Updating pod condition" pod="default/falcon-pod-867106" conditionType=PodScheduled conditionStatus=False conditionReason="Unschedulable"
I0916 08:21:11.707342       1 httplog.go:132] "HTTP" verb="GET" URI="/healthz" latency="112.07µs" userAgent="kube-probe/1.27" audit-ID="" srcIP="10.44.0.0:53256" resp=200
I0916 08:21:11.708467       1 httplog.go:132] "HTTP" verb="GET" URI="/healthz" latency="58.66µs" userAgent="kube-probe/1.27" audit-ID="" srcIP="10.44.0.0:53242" resp=200
I0916 08:21:16.307298       1 eventhandlers.go:118] "Add event for unscheduled pod" pod="default/falcon-pod-398210"
I0916 08:21:16.307411       1 schedule_one.go:80] "Attempting to schedule pod" pod="default/falcon-pod-398210"
I0916 08:21:16.308112       1 log.go:194] require 4 gpu(s), and currently has 2 gpus(s) in total
I0916 08:21:16.316365       1 schedule_one.go:867] "Unable to schedule pod; no fit; waiting" pod="default/falcon-pod-398210" err="0/2 nodes are available: Require 4 gpu but only 2 gpu in the pool.. preemption: 0/2 nodes are available: 2 No preemption victims found for incoming pod.."
E0916 08:21:16.316508       1 schedule_one.go:902] "Error occurred" err="Pod default/falcon-pod-398210 is already present in the active queue"
I0916 08:21:16.316612       1 schedule_one.go:943] "Updating pod condition" pod="default/falcon-pod-398210" conditionType=PodScheduled conditionStatus=False conditionReason="Unschedulable"
I0916 08:21:16.322436       1 schedule_one.go:80] "Attempting to schedule pod" pod="default/falcon-pod-398210"
I0916 08:21:16.322913       1 log.go:194] require 4 gpu(s), and currently has 2 gpus(s) in total
I0916 08:21:16.328566       1 schedule_one.go:867] "Unable to schedule pod; no fit; waiting" pod="default/falcon-pod-398210" err="0/2 nodes are available: Require 4 gpu but only 2 gpu in the pool.. preemption: 0/2 nodes are available: 2 No preemption victims found for incoming pod.."
E0916 08:21:16.328647       1 schedule_one.go:902] "Error occurred" err="Pod default/falcon-pod-398210 is already present in the active queue"
I0916 08:21:16.328718       1 schedule_one.go:943] "Updating pod condition" pod="default/falcon-pod-398210" conditionType=PodScheduled conditionStatus=False conditionReason="Unschedulable"
I0916 08:21:16.333561       1 schedule_one.go:80] "Attempting to schedule pod" pod="default/falcon-pod-398210"
I0916 08:21:16.333958       1 log.go:194] require 4 gpu(s), and currently has 2 gpus(s) in total
I0916 08:21:16.340826       1 schedule_one.go:867] "Unable to schedule pod; no fit; waiting" pod="default/falcon-pod-398210" err="0/2 nodes are available: Require 4 gpu but only 2 gpu in the pool.. preemption: 0/2 nodes are available: 2 No preemption victims found for incoming pod.."
I0916 08:21:16.340930       1 schedule_one.go:943] "Updating pod condition" pod="default/falcon-pod-398210" conditionType=PodScheduled conditionStatus=False conditionReason="Unschedulable"
I0916 08:21:19.552816       1 eventhandlers.go:118] "Add event for unscheduled pod" pod="default/falcon-pod-593250"
I0916 08:21:19.552891       1 schedule_one.go:80] "Attempting to schedule pod" pod="default/falcon-pod-593250"
I0916 08:21:19.553421       1 log.go:194] require 4 gpu(s), and currently has 2 gpus(s) in total
I0916 08:21:19.560771       1 schedule_one.go:867] "Unable to schedule pod; no fit; waiting" pod="default/falcon-pod-593250" err="0/2 nodes are available: Require 4 gpu but only 2 gpu in the pool.. preemption: 0/2 nodes are available: 2 No preemption victims found for incoming pod.."
E0916 08:21:19.560830       1 schedule_one.go:902] "Error occurred" err="Pod default/falcon-pod-593250 is already present in the active queue"
I0916 08:21:19.560863       1 schedule_one.go:943] "Updating pod condition" pod="default/falcon-pod-593250" conditionType=PodScheduled conditionStatus=False conditionReason="Unschedulable"
I0916 08:21:19.566573       1 schedule_one.go:80] "Attempting to schedule pod" pod="default/falcon-pod-593250"
I0916 08:21:19.567030       1 log.go:194] require 4 gpu(s), and currently has 2 gpus(s) in total
I0916 08:21:19.572980       1 schedule_one.go:867] "Unable to schedule pod; no fit; waiting" pod="default/falcon-pod-593250" err="0/2 nodes are available: Require 4 gpu but only 2 gpu in the pool.. preemption: 0/2 nodes are available: 2 No preemption victims found for incoming pod.."
E0916 08:21:19.573066       1 schedule_one.go:902] "Error occurred" err="Pod default/falcon-pod-593250 is already present in the active queue"
I0916 08:21:19.573165       1 schedule_one.go:943] "Updating pod condition" pod="default/falcon-pod-593250" conditionType=PodScheduled conditionStatus=False conditionReason="Unschedulable"
I0916 08:21:19.578359       1 schedule_one.go:80] "Attempting to schedule pod" pod="default/falcon-pod-593250"
I0916 08:21:19.578917       1 log.go:194] require 4 gpu(s), and currently has 2 gpus(s) in total
I0916 08:21:19.583855       1 schedule_one.go:867] "Unable to schedule pod; no fit; waiting" pod="default/falcon-pod-593250" err="0/2 nodes are available: Require 4 gpu but only 2 gpu in the pool.. preemption: 0/2 nodes are available: 2 No preemption victims found for incoming pod.."
I0916 08:21:19.584007       1 schedule_one.go:943] "Updating pod condition" pod="default/falcon-pod-593250" conditionType=PodScheduled conditionStatus=False conditionReason="Unschedulable"
I0916 08:21:21.700191       1 httplog.go:132] "HTTP" verb="GET" URI="/healthz" latency="106.239µs" userAgent="kube-probe/1.27" audit-ID="" srcIP="10.44.0.0:49648" resp=200
I0916 08:21:21.701247       1 httplog.go:132] "HTTP" verb="GET" URI="/healthz" latency="84.779µs" userAgent="kube-probe/1.27" audit-ID="" srcIP="10.44.0.0:49662" resp=200
I0916 08:21:21.809379       1 eventhandlers.go:118] "Add event for unscheduled pod" pod="default/falcon-pod-519337"
I0916 08:21:21.809465       1 schedule_one.go:80] "Attempting to schedule pod" pod="default/falcon-pod-519337"
I0916 08:21:21.810104       1 log.go:194] require 2 gpu(s), and currently has 2 gpus(s) in total
I0916 08:21:21.817071       1 log.go:194] css-host-128 has 2 gpu, the pod requires 2 gpu -> score: 1
I0916 08:21:21.817107       1 log.go:194] css-host-129 has 0 gpu, the pod requires 2 gpu -> score: -2
I0916 08:21:21.817539       1 log.go:194] permit plugin
I0916 08:21:21.822115       1 log.go:194] alloc: 4, used: 2, required: 2
I0916 08:21:21.826652       1 log.go:194] alloc: 4, used: 2, required: 2
I0916 08:21:21.826802       1 default_binder.go:53] "Attempting to bind pod to node" pod="default/falcon-pod-519337" node="css-host-128"
I0916 08:21:21.830636       1 schedule_one.go:252] "Successfully bound pod to node" pod="default/falcon-pod-519337" node="css-host-128" evaluatedNodes=2 feasibleNodes=2
I0916 08:21:21.830776       1 eventhandlers.go:186] "Add event for scheduled pod" pod="default/falcon-pod-519337"
I0916 08:21:21.830849       1 eventhandlers.go:161] "Delete event for unscheduled pod" pod="default/falcon-pod-519337"
I0916 08:21:26.056212       1 eventhandlers.go:118] "Add event for unscheduled pod" pod="default/falcon-pod-581104"
I0916 08:21:26.056326       1 schedule_one.go:80] "Attempting to schedule pod" pod="default/falcon-pod-581104"
I0916 08:21:26.057002       1 log.go:194] require 4 gpu(s), and currently has 0 gpus(s) in total
I0916 08:21:26.087303       1 schedule_one.go:867] "Unable to schedule pod; no fit; waiting" pod="default/falcon-pod-581104" err="0/2 nodes are available: Require 4 gpu but only 0 gpu in the pool.. preemption: 0/2 nodes are available: 2 No preemption victims found for incoming pod.."
E0916 08:21:26.087375       1 schedule_one.go:902] "Error occurred" err="Pod default/falcon-pod-581104 is already present in the active queue"
I0916 08:21:26.087420       1 schedule_one.go:943] "Updating pod condition" pod="default/falcon-pod-581104" conditionType=PodScheduled conditionStatus=False conditionReason="Unschedulable"
I0916 08:21:26.092606       1 schedule_one.go:80] "Attempting to schedule pod" pod="default/falcon-pod-581104"
I0916 08:21:26.092999       1 log.go:194] require 4 gpu(s), and currently has 0 gpus(s) in total
I0916 08:21:26.098905       1 schedule_one.go:867] "Unable to schedule pod; no fit; waiting" pod="default/falcon-pod-581104" err="0/2 nodes are available: Require 4 gpu but only 0 gpu in the pool.. preemption: 0/2 nodes are available: 2 No preemption victims found for incoming pod.."
I0916 08:21:26.098984       1 schedule_one.go:943] "Updating pod condition" pod="default/falcon-pod-581104" conditionType=PodScheduled conditionStatus=False conditionReason="Unschedulable"
I0916 08:21:31.706981       1 httplog.go:132] "HTTP" verb="GET" URI="/healthz" latency="151.013µs" userAgent="kube-probe/1.27" audit-ID="" srcIP="10.44.0.0:55072" resp=200
I0916 08:21:31.708215       1 httplog.go:132] "HTTP" verb="GET" URI="/healthz" latency="100.298µs" userAgent="kube-probe/1.27" audit-ID="" srcIP="10.44.0.0:55068" resp=200
I0916 08:21:32.308181       1 eventhandlers.go:118] "Add event for unscheduled pod" pod="default/falcon-pod-399023"
I0916 08:21:32.308298       1 schedule_one.go:80] "Attempting to schedule pod" pod="default/falcon-pod-399023"
I0916 08:21:32.308915       1 log.go:194] require 2 gpu(s), and currently has 0 gpus(s) in total
I0916 08:21:32.317504       1 schedule_one.go:867] "Unable to schedule pod; no fit; waiting" pod="default/falcon-pod-399023" err="0/2 nodes are available: Require 2 gpu but only 0 gpu in the pool.. preemption: 0/2 nodes are available: 2 No preemption victims found for incoming pod.."
E0916 08:21:32.317581       1 schedule_one.go:902] "Error occurred" err="Pod default/falcon-pod-399023 is already present in the active queue"
I0916 08:21:32.317627       1 schedule_one.go:943] "Updating pod condition" pod="default/falcon-pod-399023" conditionType=PodScheduled conditionStatus=False conditionReason="Unschedulable"
I0916 08:21:32.323218       1 schedule_one.go:80] "Attempting to schedule pod" pod="default/falcon-pod-399023"
I0916 08:21:32.323791       1 log.go:194] require 2 gpu(s), and currently has 0 gpus(s) in total
I0916 08:21:32.329730       1 schedule_one.go:867] "Unable to schedule pod; no fit; waiting" pod="default/falcon-pod-399023" err="0/2 nodes are available: Require 2 gpu but only 0 gpu in the pool.. preemption: 0/2 nodes are available: 2 No preemption victims found for incoming pod.."
E0916 08:21:32.329812       1 schedule_one.go:902] "Error occurred" err="Pod default/falcon-pod-399023 is already present in the active queue"
I0916 08:21:32.329913       1 schedule_one.go:943] "Updating pod condition" pod="default/falcon-pod-399023" conditionType=PodScheduled conditionStatus=False conditionReason="Unschedulable"
I0916 08:21:32.335130       1 schedule_one.go:80] "Attempting to schedule pod" pod="default/falcon-pod-399023"
I0916 08:21:32.335530       1 log.go:194] require 2 gpu(s), and currently has 0 gpus(s) in total
I0916 08:21:32.341000       1 schedule_one.go:867] "Unable to schedule pod; no fit; waiting" pod="default/falcon-pod-399023" err="0/2 nodes are available: Require 2 gpu but only 0 gpu in the pool.. preemption: 0/2 nodes are available: 2 No preemption victims found for incoming pod.."
I0916 08:21:32.341079       1 schedule_one.go:943] "Updating pod condition" pod="default/falcon-pod-399023" conditionType=PodScheduled conditionStatus=False conditionReason="Unschedulable"
I0916 08:21:34.556486       1 eventhandlers.go:118] "Add event for unscheduled pod" pod="default/falcon-pod-381278"
I0916 08:21:34.556602       1 schedule_one.go:80] "Attempting to schedule pod" pod="default/falcon-pod-381278"
I0916 08:21:34.557209       1 log.go:194] require 2 gpu(s), and currently has 0 gpus(s) in total
I0916 08:21:34.563186       1 schedule_one.go:867] "Unable to schedule pod; no fit; waiting" pod="default/falcon-pod-381278" err="0/2 nodes are available: Require 2 gpu but only 0 gpu in the pool.. preemption: 0/2 nodes are available: 2 No preemption victims found for incoming pod.."
E0916 08:21:34.563263       1 schedule_one.go:902] "Error occurred" err="Pod default/falcon-pod-381278 is already present in the active queue"
I0916 08:21:34.563304       1 schedule_one.go:943] "Updating pod condition" pod="default/falcon-pod-381278" conditionType=PodScheduled conditionStatus=False conditionReason="Unschedulable"
I0916 08:21:34.569492       1 schedule_one.go:80] "Attempting to schedule pod" pod="default/falcon-pod-381278"
I0916 08:21:34.569883       1 log.go:194] require 2 gpu(s), and currently has 0 gpus(s) in total
I0916 08:21:34.576123       1 schedule_one.go:867] "Unable to schedule pod; no fit; waiting" pod="default/falcon-pod-381278" err="0/2 nodes are available: Require 2 gpu but only 0 gpu in the pool.. preemption: 0/2 nodes are available: 2 No preemption victims found for incoming pod.."
I0916 08:21:34.576196       1 schedule_one.go:943] "Updating pod condition" pod="default/falcon-pod-381278" conditionType=PodScheduled conditionStatus=False conditionReason="Unschedulable"
I0916 08:21:35.799232       1 eventhandlers.go:118] "Add event for unscheduled pod" pod="default/falcon-pod-534716"
I0916 08:21:35.799349       1 schedule_one.go:80] "Attempting to schedule pod" pod="default/falcon-pod-534716"
I0916 08:21:35.799880       1 log.go:194] require 4 gpu(s), and currently has 0 gpus(s) in total
I0916 08:21:35.806118       1 schedule_one.go:867] "Unable to schedule pod; no fit; waiting" pod="default/falcon-pod-534716" err="0/2 nodes are available: Require 4 gpu but only 0 gpu in the pool.. preemption: 0/2 nodes are available: 2 No preemption victims found for incoming pod.."
E0916 08:21:35.806180       1 schedule_one.go:902] "Error occurred" err="Pod default/falcon-pod-534716 is already present in the active queue"
I0916 08:21:35.806240       1 schedule_one.go:943] "Updating pod condition" pod="default/falcon-pod-534716" conditionType=PodScheduled conditionStatus=False conditionReason="Unschedulable"
I0916 08:21:35.810954       1 schedule_one.go:80] "Attempting to schedule pod" pod="default/falcon-pod-534716"
I0916 08:21:35.811340       1 log.go:194] require 4 gpu(s), and currently has 0 gpus(s) in total
I0916 08:21:35.816536       1 schedule_one.go:867] "Unable to schedule pod; no fit; waiting" pod="default/falcon-pod-534716" err="0/2 nodes are available: Require 4 gpu but only 0 gpu in the pool.. preemption: 0/2 nodes are available: 2 No preemption victims found for incoming pod.."
I0916 08:21:35.816698       1 schedule_one.go:943] "Updating pod condition" pod="default/falcon-pod-534716" conditionType=PodScheduled conditionStatus=False conditionReason="Unschedulable"
I0916 08:21:41.702729       1 httplog.go:132] "HTTP" verb="GET" URI="/healthz" latency="142.206µs" userAgent="kube-probe/1.27" audit-ID="" srcIP="10.44.0.0:53146" resp=200
I0916 08:21:41.708278       1 httplog.go:132] "HTTP" verb="GET" URI="/healthz" latency="87.334µs" userAgent="kube-probe/1.27" audit-ID="" srcIP="10.44.0.0:53158" resp=200
I0916 08:21:51.700921       1 httplog.go:132] "HTTP" verb="GET" URI="/healthz" latency="117.06µs" userAgent="kube-probe/1.27" audit-ID="" srcIP="10.44.0.0:34530" resp=200
I0916 08:21:51.702118       1 httplog.go:132] "HTTP" verb="GET" URI="/healthz" latency="131.126µs" userAgent="kube-probe/1.27" audit-ID="" srcIP="10.44.0.0:34538" resp=200
I0916 08:22:01.702389       1 httplog.go:132] "HTTP" verb="GET" URI="/healthz" latency="94.467µs" userAgent="kube-probe/1.27" audit-ID="" srcIP="10.44.0.0:32874" resp=200
I0916 08:22:01.710485       1 httplog.go:132] "HTTP" verb="GET" URI="/healthz" latency="46.197µs" userAgent="kube-probe/1.27" audit-ID="" srcIP="10.44.0.0:32890" resp=200
I0916 08:22:11.706964       1 httplog.go:132] "HTTP" verb="GET" URI="/healthz" latency="72.797µs" userAgent="kube-probe/1.27" audit-ID="" srcIP="10.44.0.0:54360" resp=200
I0916 08:22:11.708200       1 httplog.go:132] "HTTP" verb="GET" URI="/healthz" latency="116.007µs" userAgent="kube-probe/1.27" audit-ID="" srcIP="10.44.0.0:54348" resp=200
I0916 08:22:21.707351       1 httplog.go:132] "HTTP" verb="GET" URI="/healthz" latency="116.869µs" userAgent="kube-probe/1.27" audit-ID="" srcIP="10.44.0.0:49700" resp=200
I0916 08:22:21.708488       1 httplog.go:132] "HTTP" verb="GET" URI="/healthz" latency="119.274µs" userAgent="kube-probe/1.27" audit-ID="" srcIP="10.44.0.0:49702" resp=200
I0916 08:22:26.605565       1 eventhandlers.go:231] "Delete event for scheduled pod" pod="default/falcon-pod-502950"
I0916 08:22:26.605802       1 schedule_one.go:80] "Attempting to schedule pod" pod="default/falcon-pod-867106"
I0916 08:22:26.606151       1 log.go:194] require 4 gpu(s), and currently has 2 gpus(s) in total
I0916 08:22:26.613940       1 schedule_one.go:867] "Unable to schedule pod; no fit; waiting" pod="default/falcon-pod-867106" err="0/2 nodes are available: Require 4 gpu but only 2 gpu in the pool.. preemption: 0/2 nodes are available: 2 No preemption victims found for incoming pod.."
I0916 08:22:26.614092       1 schedule_one.go:943] "Updating pod condition" pod="default/falcon-pod-867106" conditionType=PodScheduled conditionStatus=False conditionReason="Unschedulable"
I0916 08:22:26.614172       1 schedule_one.go:80] "Attempting to schedule pod" pod="default/falcon-pod-398210"
I0916 08:22:26.614841       1 log.go:194] require 4 gpu(s), and currently has 2 gpus(s) in total
I0916 08:22:26.619653       1 schedule_one.go:867] "Unable to schedule pod; no fit; waiting" pod="default/falcon-pod-398210" err="0/2 nodes are available: Require 4 gpu but only 2 gpu in the pool.. preemption: 0/2 nodes are available: 2 No preemption victims found for incoming pod.."
I0916 08:22:26.619757       1 schedule_one.go:943] "Updating pod condition" pod="default/falcon-pod-398210" conditionType=PodScheduled conditionStatus=False conditionReason="Unschedulable"
I0916 08:22:26.619801       1 schedule_one.go:80] "Attempting to schedule pod" pod="default/falcon-pod-593250"
I0916 08:22:26.620022       1 log.go:194] require 4 gpu(s), and currently has 2 gpus(s) in total
I0916 08:22:26.624420       1 schedule_one.go:867] "Unable to schedule pod; no fit; waiting" pod="default/falcon-pod-593250" err="0/2 nodes are available: Require 4 gpu but only 2 gpu in the pool.. preemption: 0/2 nodes are available: 2 No preemption victims found for incoming pod.."
I0916 08:22:26.624606       1 schedule_one.go:943] "Updating pod condition" pod="default/falcon-pod-593250" conditionType=PodScheduled conditionStatus=False conditionReason="Unschedulable"
I0916 08:22:26.624673       1 schedule_one.go:80] "Attempting to schedule pod" pod="default/falcon-pod-581104"
I0916 08:22:26.624964       1 log.go:194] require 4 gpu(s), and currently has 2 gpus(s) in total
I0916 08:22:26.631036       1 schedule_one.go:867] "Unable to schedule pod; no fit; waiting" pod="default/falcon-pod-581104" err="0/2 nodes are available: Require 4 gpu but only 2 gpu in the pool.. preemption: 0/2 nodes are available: 2 No preemption victims found for incoming pod.."
I0916 08:22:26.631122       1 schedule_one.go:943] "Updating pod condition" pod="default/falcon-pod-581104" conditionType=PodScheduled conditionStatus=False conditionReason="Unschedulable"
I0916 08:22:26.636884       1 schedule_one.go:80] "Attempting to schedule pod" pod="default/falcon-pod-399023"
I0916 08:22:26.637452       1 log.go:194] require 2 gpu(s), and currently has 2 gpus(s) in total
I0916 08:22:26.642903       1 log.go:194] css-host-128 has 2 gpu, the pod requires 2 gpu -> score: 1
I0916 08:22:26.642933       1 log.go:194] css-host-129 has 0 gpu, the pod requires 2 gpu -> score: -2
I0916 08:22:26.643116       1 log.go:194] permit plugin
I0916 08:22:26.647335       1 log.go:194] alloc: 4, used: 2, required: 2
I0916 08:22:26.651242       1 log.go:194] alloc: 4, used: 2, required: 2
I0916 08:22:26.651310       1 schedule_one.go:80] "Attempting to schedule pod" pod="default/falcon-pod-381278"
I0916 08:22:26.651386       1 default_binder.go:53] "Attempting to bind pod to node" pod="default/falcon-pod-399023" node="css-host-128"
I0916 08:22:26.651819       1 log.go:194] require 2 gpu(s), and currently has 0 gpus(s) in total
I0916 08:22:26.656867       1 schedule_one.go:867] "Unable to schedule pod; no fit; waiting" pod="default/falcon-pod-381278" err="0/2 nodes are available: Require 2 gpu but only 0 gpu in the pool.. preemption: 0/2 nodes are available: 2 No preemption victims found for incoming pod.."
I0916 08:22:26.656951       1 schedule_one.go:943] "Updating pod condition" pod="default/falcon-pod-381278" conditionType=PodScheduled conditionStatus=False conditionReason="Unschedulable"
I0916 08:22:26.657060       1 schedule_one.go:80] "Attempting to schedule pod" pod="default/falcon-pod-534716"
I0916 08:22:26.657490       1 log.go:194] require 4 gpu(s), and currently has 0 gpus(s) in total
I0916 08:22:26.658656       1 schedule_one.go:252] "Successfully bound pod to node" pod="default/falcon-pod-399023" node="css-host-128" evaluatedNodes=2 feasibleNodes=2
I0916 08:22:26.658741       1 eventhandlers.go:161] "Delete event for unscheduled pod" pod="default/falcon-pod-399023"
I0916 08:22:26.658782       1 eventhandlers.go:186] "Add event for scheduled pod" pod="default/falcon-pod-399023"
I0916 08:22:26.662606       1 schedule_one.go:867] "Unable to schedule pod; no fit; waiting" pod="default/falcon-pod-534716" err="0/2 nodes are available: Require 4 gpu but only 0 gpu in the pool.. preemption: 0/2 nodes are available: 2 No preemption victims found for incoming pod.."
I0916 08:22:26.662689       1 schedule_one.go:943] "Updating pod condition" pod="default/falcon-pod-534716" conditionType=PodScheduled conditionStatus=False conditionReason="Unschedulable"
I0916 08:22:28.834895       1 schedule_one.go:80] "Attempting to schedule pod" pod="default/falcon-pod-534716"
I0916 08:22:28.835413       1 log.go:194] require 4 gpu(s), and currently has 0 gpus(s) in total
I0916 08:22:28.841817       1 schedule_one.go:867] "Unable to schedule pod; no fit; waiting" pod="default/falcon-pod-534716" err="0/2 nodes are available: Require 4 gpu but only 0 gpu in the pool.. preemption: 0/2 nodes are available: 2 No preemption victims found for incoming pod.."
I0916 08:22:28.841924       1 schedule_one.go:943] "Updating pod condition" pod="default/falcon-pod-534716" conditionType=PodScheduled conditionStatus=False conditionReason="Unschedulable"
I0916 08:22:31.706934       1 httplog.go:132] "HTTP" verb="GET" URI="/healthz" latency="104.496µs" userAgent="kube-probe/1.27" audit-ID="" srcIP="10.44.0.0:44344" resp=200
I0916 08:22:31.708227       1 httplog.go:132] "HTTP" verb="GET" URI="/healthz" latency="124.394µs" userAgent="kube-probe/1.27" audit-ID="" srcIP="10.44.0.0:44342" resp=200
I0916 08:22:41.702908       1 httplog.go:132] "HTTP" verb="GET" URI="/healthz" latency="138.58µs" userAgent="kube-probe/1.27" audit-ID="" srcIP="10.44.0.0:49130" resp=200
I0916 08:22:41.704039       1 httplog.go:132] "HTTP" verb="GET" URI="/healthz" latency="139.14µs" userAgent="kube-probe/1.27" audit-ID="" srcIP="10.44.0.0:49122" resp=200
I0916 08:22:51.706094       1 httplog.go:132] "HTTP" verb="GET" URI="/healthz" latency="99.837µs" userAgent="kube-probe/1.27" audit-ID="" srcIP="10.44.0.0:57962" resp=200
I0916 08:22:51.707056       1 httplog.go:132] "HTTP" verb="GET" URI="/healthz" latency="139.843µs" userAgent="kube-probe/1.27" audit-ID="" srcIP="10.44.0.0:57954" resp=200
I0916 08:23:01.707576       1 httplog.go:132] "HTTP" verb="GET" URI="/healthz" latency="147.878µs" userAgent="kube-probe/1.27" audit-ID="" srcIP="10.44.0.0:33328" resp=200
I0916 08:23:01.709097       1 httplog.go:132] "HTTP" verb="GET" URI="/healthz" latency="142.287µs" userAgent="kube-probe/1.27" audit-ID="" srcIP="10.44.0.0:33326" resp=200
I0916 08:23:11.706017       1 httplog.go:132] "HTTP" verb="GET" URI="/healthz" latency="94.748µs" userAgent="kube-probe/1.27" audit-ID="" srcIP="10.44.0.0:43282" resp=200
I0916 08:23:11.707451       1 httplog.go:132] "HTTP" verb="GET" URI="/healthz" latency="132.398µs" userAgent="kube-probe/1.27" audit-ID="" srcIP="10.44.0.0:43270" resp=200
I0916 08:23:15.618587       1 eventhandlers.go:231] "Delete event for scheduled pod" pod="default/falcon-pod-519337"
I0916 08:23:15.618774       1 schedule_one.go:80] "Attempting to schedule pod" pod="default/falcon-pod-867106"
I0916 08:23:15.619359       1 log.go:194] require 4 gpu(s), and currently has 2 gpus(s) in total
I0916 08:23:15.627065       1 schedule_one.go:867] "Unable to schedule pod; no fit; waiting" pod="default/falcon-pod-867106" err="0/2 nodes are available: Require 4 gpu but only 2 gpu in the pool.. preemption: 0/2 nodes are available: 2 No preemption victims found for incoming pod.."
I0916 08:23:15.627219       1 schedule_one.go:943] "Updating pod condition" pod="default/falcon-pod-867106" conditionType=PodScheduled conditionStatus=False conditionReason="Unschedulable"
I0916 08:23:15.627293       1 schedule_one.go:80] "Attempting to schedule pod" pod="default/falcon-pod-398210"
I0916 08:23:15.627898       1 log.go:194] require 4 gpu(s), and currently has 2 gpus(s) in total
I0916 08:23:15.634180       1 schedule_one.go:867] "Unable to schedule pod; no fit; waiting" pod="default/falcon-pod-398210" err="0/2 nodes are available: Require 4 gpu but only 2 gpu in the pool.. preemption: 0/2 nodes are available: 2 No preemption victims found for incoming pod.."
I0916 08:23:15.634276       1 schedule_one.go:943] "Updating pod condition" pod="default/falcon-pod-398210" conditionType=PodScheduled conditionStatus=False conditionReason="Unschedulable"
I0916 08:23:15.634360       1 schedule_one.go:80] "Attempting to schedule pod" pod="default/falcon-pod-593250"
I0916 08:23:15.634998       1 log.go:194] require 4 gpu(s), and currently has 2 gpus(s) in total
I0916 08:23:15.641746       1 schedule_one.go:867] "Unable to schedule pod; no fit; waiting" pod="default/falcon-pod-593250" err="0/2 nodes are available: Require 4 gpu but only 2 gpu in the pool.. preemption: 0/2 nodes are available: 2 No preemption victims found for incoming pod.."
I0916 08:23:15.641832       1 schedule_one.go:943] "Updating pod condition" pod="default/falcon-pod-593250" conditionType=PodScheduled conditionStatus=False conditionReason="Unschedulable"
I0916 08:23:15.642025       1 schedule_one.go:80] "Attempting to schedule pod" pod="default/falcon-pod-581104"
I0916 08:23:15.642392       1 log.go:194] require 4 gpu(s), and currently has 2 gpus(s) in total
I0916 08:23:15.649201       1 schedule_one.go:867] "Unable to schedule pod; no fit; waiting" pod="default/falcon-pod-581104" err="0/2 nodes are available: Require 4 gpu but only 2 gpu in the pool.. preemption: 0/2 nodes are available: 2 No preemption victims found for incoming pod.."
I0916 08:23:15.649281       1 schedule_one.go:943] "Updating pod condition" pod="default/falcon-pod-581104" conditionType=PodScheduled conditionStatus=False conditionReason="Unschedulable"
I0916 08:23:15.649330       1 schedule_one.go:80] "Attempting to schedule pod" pod="default/falcon-pod-381278"
I0916 08:23:15.649843       1 log.go:194] require 2 gpu(s), and currently has 2 gpus(s) in total
I0916 08:23:15.695793       1 log.go:194] css-host-128 has 2 gpu, the pod requires 2 gpu -> score: 1
I0916 08:23:15.695834       1 log.go:194] css-host-129 has 0 gpu, the pod requires 2 gpu -> score: -2
I0916 08:23:15.696066       1 log.go:194] permit plugin
I0916 08:23:15.701248       1 log.go:194] alloc: 4, used: 2, required: 2
I0916 08:23:15.705895       1 log.go:194] alloc: 4, used: 2, required: 2
I0916 08:23:15.705960       1 schedule_one.go:80] "Attempting to schedule pod" pod="default/falcon-pod-534716"
I0916 08:23:15.706025       1 default_binder.go:53] "Attempting to bind pod to node" pod="default/falcon-pod-381278" node="css-host-128"
I0916 08:23:15.706470       1 log.go:194] require 4 gpu(s), and currently has 0 gpus(s) in total
I0916 08:23:15.709825       1 schedule_one.go:252] "Successfully bound pod to node" pod="default/falcon-pod-381278" node="css-host-128" evaluatedNodes=2 feasibleNodes=2
I0916 08:23:15.709854       1 eventhandlers.go:161] "Delete event for unscheduled pod" pod="default/falcon-pod-381278"
I0916 08:23:15.709909       1 eventhandlers.go:186] "Add event for scheduled pod" pod="default/falcon-pod-381278"
I0916 08:23:15.712268       1 schedule_one.go:867] "Unable to schedule pod; no fit; waiting" pod="default/falcon-pod-534716" err="0/2 nodes are available: Require 4 gpu but only 0 gpu in the pool.. preemption: 0/2 nodes are available: 2 No preemption victims found for incoming pod.."
I0916 08:23:15.712363       1 schedule_one.go:943] "Updating pod condition" pod="default/falcon-pod-534716" conditionType=PodScheduled conditionStatus=False conditionReason="Unschedulable"
I0916 08:23:21.707302       1 httplog.go:132] "HTTP" verb="GET" URI="/healthz" latency="111.619µs" userAgent="kube-probe/1.27" audit-ID="" srcIP="10.44.0.0:38510" resp=200
I0916 08:23:21.708621       1 httplog.go:132] "HTTP" verb="GET" URI="/healthz" latency="117.881µs" userAgent="kube-probe/1.27" audit-ID="" srcIP="10.44.0.0:38516" resp=200
I0916 08:23:23.862896       1 schedule_one.go:80] "Attempting to schedule pod" pod="default/falcon-pod-534716"
I0916 08:23:23.863501       1 log.go:194] require 4 gpu(s), and currently has 0 gpus(s) in total
I0916 08:23:23.870587       1 schedule_one.go:867] "Unable to schedule pod; no fit; waiting" pod="default/falcon-pod-534716" err="0/2 nodes are available: Require 4 gpu but only 0 gpu in the pool.. preemption: 0/2 nodes are available: 2 No preemption victims found for incoming pod.."
I0916 08:23:23.870733       1 schedule_one.go:943] "Updating pod condition" pod="default/falcon-pod-534716" conditionType=PodScheduled conditionStatus=False conditionReason="Unschedulable"
I0916 08:23:31.703401       1 httplog.go:132] "HTTP" verb="GET" URI="/healthz" latency="154.71µs" userAgent="kube-probe/1.27" audit-ID="" srcIP="10.44.0.0:34440" resp=200
I0916 08:23:31.704504       1 httplog.go:132] "HTTP" verb="GET" URI="/healthz" latency="103.163µs" userAgent="kube-probe/1.27" audit-ID="" srcIP="10.44.0.0:34424" resp=200
I0916 08:23:41.702471       1 httplog.go:132] "HTTP" verb="GET" URI="/healthz" latency="135.534µs" userAgent="kube-probe/1.27" audit-ID="" srcIP="10.44.0.0:41154" resp=200
I0916 08:23:41.703314       1 httplog.go:132] "HTTP" verb="GET" URI="/healthz" latency="99.747µs" userAgent="kube-probe/1.27" audit-ID="" srcIP="10.44.0.0:41168" resp=200
I0916 08:23:51.702605       1 httplog.go:132] "HTTP" verb="GET" URI="/healthz" latency="105.317µs" userAgent="kube-probe/1.27" audit-ID="" srcIP="10.44.0.0:56900" resp=200
I0916 08:23:51.703988       1 httplog.go:132] "HTTP" verb="GET" URI="/healthz" latency="94.938µs" userAgent="kube-probe/1.27" audit-ID="" srcIP="10.44.0.0:56898" resp=200
I0916 08:24:01.702551       1 httplog.go:132] "HTTP" verb="GET" URI="/healthz" latency="127.66µs" userAgent="kube-probe/1.27" audit-ID="" srcIP="10.44.0.0:33890" resp=200
I0916 08:24:01.703466       1 httplog.go:132] "HTTP" verb="GET" URI="/healthz" latency="53.43µs" userAgent="kube-probe/1.27" audit-ID="" srcIP="10.44.0.0:33904" resp=200
I0916 08:24:11.699830       1 httplog.go:132] "HTTP" verb="GET" URI="/healthz" latency="132.258µs" userAgent="kube-probe/1.27" audit-ID="" srcIP="10.44.0.0:49334" resp=200
I0916 08:24:11.700789       1 httplog.go:132] "HTTP" verb="GET" URI="/healthz" latency="43.872µs" userAgent="kube-probe/1.27" audit-ID="" srcIP="10.44.0.0:49336" resp=200
I0916 08:24:21.702074       1 httplog.go:132] "HTTP" verb="GET" URI="/healthz" latency="100.559µs" userAgent="kube-probe/1.27" audit-ID="" srcIP="10.44.0.0:60748" resp=200
I0916 08:24:21.703170       1 httplog.go:132] "HTTP" verb="GET" URI="/healthz" latency="67.176µs" userAgent="kube-probe/1.27" audit-ID="" srcIP="10.44.0.0:60746" resp=200
I0916 08:24:31.706848       1 httplog.go:132] "HTTP" verb="GET" URI="/healthz" latency="125.125µs" userAgent="kube-probe/1.27" audit-ID="" srcIP="10.44.0.0:55666" resp=200
I0916 08:24:31.708020       1 httplog.go:132] "HTTP" verb="GET" URI="/healthz" latency="139.361µs" userAgent="kube-probe/1.27" audit-ID="" srcIP="10.44.0.0:55656" resp=200
I0916 08:24:41.706141       1 httplog.go:132] "HTTP" verb="GET" URI="/healthz" latency="135.985µs" userAgent="kube-probe/1.27" audit-ID="" srcIP="10.44.0.0:47368" resp=200
I0916 08:24:41.707384       1 httplog.go:132] "HTTP" verb="GET" URI="/healthz" latency="121.437µs" userAgent="kube-probe/1.27" audit-ID="" srcIP="10.44.0.0:47370" resp=200
I0916 08:24:51.705842       1 httplog.go:132] "HTTP" verb="GET" URI="/healthz" latency="139.712µs" userAgent="kube-probe/1.27" audit-ID="" srcIP="10.44.0.0:37142" resp=200
I0916 08:24:51.706637       1 httplog.go:132] "HTTP" verb="GET" URI="/healthz" latency="57.538µs" userAgent="kube-probe/1.27" audit-ID="" srcIP="10.44.0.0:37132" resp=200
I0916 08:25:01.702461       1 httplog.go:132] "HTTP" verb="GET" URI="/healthz" latency="119.424µs" userAgent="kube-probe/1.27" audit-ID="" srcIP="10.44.0.0:60462" resp=200
I0916 08:25:01.702721       1 httplog.go:132] "HTTP" verb="GET" URI="/healthz" latency="141.105µs" userAgent="kube-probe/1.27" audit-ID="" srcIP="10.44.0.0:60450" resp=200
I0916 08:25:11.706563       1 httplog.go:132] "HTTP" verb="GET" URI="/healthz" latency="122.099µs" userAgent="kube-probe/1.27" audit-ID="" srcIP="10.44.0.0:54034" resp=200
I0916 08:25:11.707761       1 httplog.go:132] "HTTP" verb="GET" URI="/healthz" latency="66.234µs" userAgent="kube-probe/1.27" audit-ID="" srcIP="10.44.0.0:54050" resp=200
I0916 08:25:21.707260       1 httplog.go:132] "HTTP" verb="GET" URI="/healthz" latency="124.173µs" userAgent="kube-probe/1.27" audit-ID="" srcIP="10.44.0.0:36478" resp=200
I0916 08:25:21.708497       1 httplog.go:132] "HTTP" verb="GET" URI="/healthz" latency="130.685µs" userAgent="kube-probe/1.27" audit-ID="" srcIP="10.44.0.0:36482" resp=200
I0916 08:25:31.706519       1 httplog.go:132] "HTTP" verb="GET" URI="/healthz" latency="87.855µs" userAgent="kube-probe/1.27" audit-ID="" srcIP="10.44.0.0:39228" resp=200
I0916 08:25:31.707961       1 httplog.go:132] "HTTP" verb="GET" URI="/healthz" latency="126.517µs" userAgent="kube-probe/1.27" audit-ID="" srcIP="10.44.0.0:39240" resp=200
I0916 08:25:41.702418       1 httplog.go:132] "HTTP" verb="GET" URI="/healthz" latency="123.972µs" userAgent="kube-probe/1.27" audit-ID="" srcIP="10.44.0.0:40302" resp=200
I0916 08:25:41.703539       1 httplog.go:132] "HTTP" verb="GET" URI="/healthz" latency="111.719µs" userAgent="kube-probe/1.27" audit-ID="" srcIP="10.44.0.0:40292" resp=200
I0916 08:25:51.706635       1 httplog.go:132] "HTTP" verb="GET" URI="/healthz" latency="134.923µs" userAgent="kube-probe/1.27" audit-ID="" srcIP="10.44.0.0:55042" resp=200
I0916 08:25:51.707848       1 httplog.go:132] "HTTP" verb="GET" URI="/healthz" latency="169.668µs" userAgent="kube-probe/1.27" audit-ID="" srcIP="10.44.0.0:55032" resp=200
I0916 08:26:01.706275       1 httplog.go:132] "HTTP" verb="GET" URI="/healthz" latency="83.086µs" userAgent="kube-probe/1.27" audit-ID="" srcIP="10.44.0.0:38408" resp=200
I0916 08:26:01.707532       1 httplog.go:132] "HTTP" verb="GET" URI="/healthz" latency="54.722µs" userAgent="kube-probe/1.27" audit-ID="" srcIP="10.44.0.0:38414" resp=200
I0916 08:26:11.702461       1 httplog.go:132] "HTTP" verb="GET" URI="/healthz" latency="76.253µs" userAgent="kube-probe/1.27" audit-ID="" srcIP="10.44.0.0:32972" resp=200
I0916 08:26:11.703723       1 httplog.go:132] "HTTP" verb="GET" URI="/healthz" latency="55.775µs" userAgent="kube-probe/1.27" audit-ID="" srcIP="10.44.0.0:32962" resp=200
I0916 08:26:21.071294       1 eventhandlers.go:231] "Delete event for scheduled pod" pod="default/falcon-pod-399023"
I0916 08:26:21.071457       1 schedule_one.go:80] "Attempting to schedule pod" pod="default/falcon-pod-867106"
I0916 08:26:21.071996       1 log.go:194] require 4 gpu(s), and currently has 2 gpus(s) in total
I0916 08:26:21.079747       1 schedule_one.go:867] "Unable to schedule pod; no fit; waiting" pod="default/falcon-pod-867106" err="0/2 nodes are available: Require 4 gpu but only 2 gpu in the pool.. preemption: 0/2 nodes are available: 2 No preemption victims found for incoming pod.."
I0916 08:26:21.079860       1 schedule_one.go:943] "Updating pod condition" pod="default/falcon-pod-867106" conditionType=PodScheduled conditionStatus=False conditionReason="Unschedulable"
I0916 08:26:21.079932       1 schedule_one.go:80] "Attempting to schedule pod" pod="default/falcon-pod-398210"
I0916 08:26:21.080520       1 log.go:194] require 4 gpu(s), and currently has 2 gpus(s) in total
I0916 08:26:21.087282       1 schedule_one.go:867] "Unable to schedule pod; no fit; waiting" pod="default/falcon-pod-398210" err="0/2 nodes are available: Require 4 gpu but only 2 gpu in the pool.. preemption: 0/2 nodes are available: 2 No preemption victims found for incoming pod.."
I0916 08:26:21.087370       1 schedule_one.go:943] "Updating pod condition" pod="default/falcon-pod-398210" conditionType=PodScheduled conditionStatus=False conditionReason="Unschedulable"
I0916 08:26:21.087432       1 schedule_one.go:80] "Attempting to schedule pod" pod="default/falcon-pod-593250"
I0916 08:26:21.087947       1 log.go:194] require 4 gpu(s), and currently has 2 gpus(s) in total
I0916 08:26:21.094314       1 schedule_one.go:867] "Unable to schedule pod; no fit; waiting" pod="default/falcon-pod-593250" err="0/2 nodes are available: Require 4 gpu but only 2 gpu in the pool.. preemption: 0/2 nodes are available: 2 No preemption victims found for incoming pod.."
I0916 08:26:21.094461       1 schedule_one.go:943] "Updating pod condition" pod="default/falcon-pod-593250" conditionType=PodScheduled conditionStatus=False conditionReason="Unschedulable"
I0916 08:26:21.094581       1 schedule_one.go:80] "Attempting to schedule pod" pod="default/falcon-pod-581104"
I0916 08:26:21.095134       1 log.go:194] require 4 gpu(s), and currently has 2 gpus(s) in total
I0916 08:26:21.115968       1 schedule_one.go:867] "Unable to schedule pod; no fit; waiting" pod="default/falcon-pod-581104" err="0/2 nodes are available: Require 4 gpu but only 2 gpu in the pool.. preemption: 0/2 nodes are available: 2 No preemption victims found for incoming pod.."
I0916 08:26:21.116063       1 schedule_one.go:943] "Updating pod condition" pod="default/falcon-pod-581104" conditionType=PodScheduled conditionStatus=False conditionReason="Unschedulable"
I0916 08:26:21.116101       1 schedule_one.go:80] "Attempting to schedule pod" pod="default/falcon-pod-534716"
I0916 08:26:21.116543       1 log.go:194] require 4 gpu(s), and currently has 2 gpus(s) in total
I0916 08:26:21.122438       1 schedule_one.go:867] "Unable to schedule pod; no fit; waiting" pod="default/falcon-pod-534716" err="0/2 nodes are available: Require 4 gpu but only 2 gpu in the pool.. preemption: 0/2 nodes are available: 2 No preemption victims found for incoming pod.."
I0916 08:26:21.122517       1 schedule_one.go:943] "Updating pod condition" pod="default/falcon-pod-534716" conditionType=PodScheduled conditionStatus=False conditionReason="Unschedulable"
I0916 08:26:21.702361       1 httplog.go:132] "HTTP" verb="GET" URI="/healthz" latency="102.543µs" userAgent="kube-probe/1.27" audit-ID="" srcIP="10.44.0.0:50208" resp=200
I0916 08:26:21.702454       1 httplog.go:132] "HTTP" verb="GET" URI="/healthz" latency="89.057µs" userAgent="kube-probe/1.27" audit-ID="" srcIP="10.44.0.0:50210" resp=200
I0916 08:26:31.707334       1 httplog.go:132] "HTTP" verb="GET" URI="/healthz" latency="64.842µs" userAgent="kube-probe/1.27" audit-ID="" srcIP="10.44.0.0:39958" resp=200
I0916 08:26:31.708959       1 httplog.go:132] "HTTP" verb="GET" URI="/healthz" latency="90.579µs" userAgent="kube-probe/1.27" audit-ID="" srcIP="10.44.0.0:39960" resp=200
I0916 08:26:41.706145       1 httplog.go:132] "HTTP" verb="GET" URI="/healthz" latency="38.442µs" userAgent="kube-probe/1.27" audit-ID="" srcIP="10.44.0.0:53300" resp=200
I0916 08:26:41.707529       1 httplog.go:132] "HTTP" verb="GET" URI="/healthz" latency="135.855µs" userAgent="kube-probe/1.27" audit-ID="" srcIP="10.44.0.0:53316" resp=200
I0916 08:26:51.702298       1 httplog.go:132] "HTTP" verb="GET" URI="/healthz" latency="115.706µs" userAgent="kube-probe/1.27" audit-ID="" srcIP="10.44.0.0:44272" resp=200
I0916 08:26:51.714337       1 httplog.go:132] "HTTP" verb="GET" URI="/healthz" latency="132.208µs" userAgent="kube-probe/1.27" audit-ID="" srcIP="10.44.0.0:44290" resp=200
I0916 08:27:01.701779       1 httplog.go:132] "HTTP" verb="GET" URI="/healthz" latency="70.532µs" userAgent="kube-probe/1.27" audit-ID="" srcIP="10.44.0.0:56708" resp=200
I0916 08:27:01.703111       1 httplog.go:132] "HTTP" verb="GET" URI="/healthz" latency="99.106µs" userAgent="kube-probe/1.27" audit-ID="" srcIP="10.44.0.0:56694" resp=200
I0916 08:27:11.706570       1 httplog.go:132] "HTTP" verb="GET" URI="/healthz" latency="126.908µs" userAgent="kube-probe/1.27" audit-ID="" srcIP="10.44.0.0:33954" resp=200
I0916 08:27:11.707598       1 httplog.go:132] "HTTP" verb="GET" URI="/healthz" latency="69.029µs" userAgent="kube-probe/1.27" audit-ID="" srcIP="10.44.0.0:33952" resp=200
I0916 08:27:21.706592       1 httplog.go:132] "HTTP" verb="GET" URI="/healthz" latency="104.085µs" userAgent="kube-probe/1.27" audit-ID="" srcIP="10.44.0.0:47810" resp=200
I0916 08:27:21.708055       1 httplog.go:132] "HTTP" verb="GET" URI="/healthz" latency="69.711µs" userAgent="kube-probe/1.27" audit-ID="" srcIP="10.44.0.0:47798" resp=200
I0916 08:27:31.702814       1 httplog.go:132] "HTTP" verb="GET" URI="/healthz" latency="74.911µs" userAgent="kube-probe/1.27" audit-ID="" srcIP="10.44.0.0:36592" resp=200
I0916 08:27:31.704059       1 httplog.go:132] "HTTP" verb="GET" URI="/healthz" latency="57.648µs" userAgent="kube-probe/1.27" audit-ID="" srcIP="10.44.0.0:36596" resp=200
I0916 08:27:41.700467       1 httplog.go:132] "HTTP" verb="GET" URI="/healthz" latency="103.764µs" userAgent="kube-probe/1.27" audit-ID="" srcIP="10.44.0.0:41394" resp=200
I0916 08:27:41.701943       1 httplog.go:132] "HTTP" verb="GET" URI="/healthz" latency="43.732µs" userAgent="kube-probe/1.27" audit-ID="" srcIP="10.44.0.0:41398" resp=200
I0916 08:27:51.702779       1 httplog.go:132] "HTTP" verb="GET" URI="/healthz" latency="74.39µs" userAgent="kube-probe/1.27" audit-ID="" srcIP="10.44.0.0:36236" resp=200
I0916 08:27:51.704404       1 httplog.go:132] "HTTP" verb="GET" URI="/healthz" latency="86.602µs" userAgent="kube-probe/1.27" audit-ID="" srcIP="10.44.0.0:36234" resp=200
I0916 08:28:01.706625       1 httplog.go:132] "HTTP" verb="GET" URI="/healthz" latency="107.181µs" userAgent="kube-probe/1.27" audit-ID="" srcIP="10.44.0.0:44118" resp=200
I0916 08:28:01.707967       1 httplog.go:132] "HTTP" verb="GET" URI="/healthz" latency="99.306µs" userAgent="kube-probe/1.27" audit-ID="" srcIP="10.44.0.0:44128" resp=200
I0916 08:28:11.702239       1 httplog.go:132] "HTTP" verb="GET" URI="/healthz" latency="124.073µs" userAgent="kube-probe/1.27" audit-ID="" srcIP="10.44.0.0:45962" resp=200
I0916 08:28:11.707781       1 httplog.go:132] "HTTP" verb="GET" URI="/healthz" latency="94.818µs" userAgent="kube-probe/1.27" audit-ID="" srcIP="10.44.0.0:45968" resp=200
I0916 08:28:21.706721       1 httplog.go:132] "HTTP" verb="GET" URI="/healthz" latency="96.151µs" userAgent="kube-probe/1.27" audit-ID="" srcIP="10.44.0.0:56740" resp=200
I0916 08:28:21.707893       1 httplog.go:132] "HTTP" verb="GET" URI="/healthz" latency="91.892µs" userAgent="kube-probe/1.27" audit-ID="" srcIP="10.44.0.0:56750" resp=200
I0916 08:28:31.702614       1 httplog.go:132] "HTTP" verb="GET" URI="/healthz" latency="75.312µs" userAgent="kube-probe/1.27" audit-ID="" srcIP="10.44.0.0:57174" resp=200
I0916 08:28:31.703814       1 httplog.go:132] "HTTP" verb="GET" URI="/healthz" latency="44.504µs" userAgent="kube-probe/1.27" audit-ID="" srcIP="10.44.0.0:57172" resp=200
I0916 08:28:41.701697       1 httplog.go:132] "HTTP" verb="GET" URI="/healthz" latency="71.845µs" userAgent="kube-probe/1.27" audit-ID="" srcIP="10.44.0.0:41624" resp=200
I0916 08:28:41.709410       1 httplog.go:132] "HTTP" verb="GET" URI="/healthz" latency="56.797µs" userAgent="kube-probe/1.27" audit-ID="" srcIP="10.44.0.0:41648" resp=200
I0916 08:28:51.706673       1 httplog.go:132] "HTTP" verb="GET" URI="/healthz" latency="104.787µs" userAgent="kube-probe/1.27" audit-ID="" srcIP="10.44.0.0:53454" resp=200
I0916 08:28:51.707939       1 httplog.go:132] "HTTP" verb="GET" URI="/healthz" latency="164.389µs" userAgent="kube-probe/1.27" audit-ID="" srcIP="10.44.0.0:53438" resp=200
I0916 08:29:01.701754       1 httplog.go:132] "HTTP" verb="GET" URI="/healthz" latency="147.066µs" userAgent="kube-probe/1.27" audit-ID="" srcIP="10.44.0.0:39834" resp=200
I0916 08:29:01.703154       1 httplog.go:132] "HTTP" verb="GET" URI="/healthz" latency="122.92µs" userAgent="kube-probe/1.27" audit-ID="" srcIP="10.44.0.0:39850" resp=200
I0916 08:29:11.706608       1 httplog.go:132] "HTTP" verb="GET" URI="/healthz" latency="184.055µs" userAgent="kube-probe/1.27" audit-ID="" srcIP="10.44.0.0:55728" resp=200
I0916 08:29:11.707852       1 httplog.go:132] "HTTP" verb="GET" URI="/healthz" latency="88.376µs" userAgent="kube-probe/1.27" audit-ID="" srcIP="10.44.0.0:55726" resp=200
I0916 08:29:21.702462       1 httplog.go:132] "HTTP" verb="GET" URI="/healthz" latency="71.694µs" userAgent="kube-probe/1.27" audit-ID="" srcIP="10.44.0.0:38794" resp=200
I0916 08:29:21.703672       1 httplog.go:132] "HTTP" verb="GET" URI="/healthz" latency="52.799µs" userAgent="kube-probe/1.27" audit-ID="" srcIP="10.44.0.0:38800" resp=200
I0916 08:29:31.702240       1 httplog.go:132] "HTTP" verb="GET" URI="/healthz" latency="121.889µs" userAgent="kube-probe/1.27" audit-ID="" srcIP="10.44.0.0:41726" resp=200
I0916 08:29:31.703513       1 httplog.go:132] "HTTP" verb="GET" URI="/healthz" latency="107.001µs" userAgent="kube-probe/1.27" audit-ID="" srcIP="10.44.0.0:41716" resp=200
I0916 08:29:41.702146       1 httplog.go:132] "HTTP" verb="GET" URI="/healthz" latency="139.241µs" userAgent="kube-probe/1.27" audit-ID="" srcIP="10.44.0.0:51306" resp=200
I0916 08:29:41.702242       1 httplog.go:132] "HTTP" verb="GET" URI="/healthz" latency="84.068µs" userAgent="kube-probe/1.27" audit-ID="" srcIP="10.44.0.0:51314" resp=200
I0916 08:29:51.707188       1 httplog.go:132] "HTTP" verb="GET" URI="/healthz" latency="135.474µs" userAgent="kube-probe/1.27" audit-ID="" srcIP="10.44.0.0:36168" resp=200
I0916 08:29:51.708232       1 httplog.go:132] "HTTP" verb="GET" URI="/healthz" latency="113.733µs" userAgent="kube-probe/1.27" audit-ID="" srcIP="10.44.0.0:36172" resp=200
I0916 08:30:01.702460       1 httplog.go:132] "HTTP" verb="GET" URI="/healthz" latency="120.055µs" userAgent="kube-probe/1.27" audit-ID="" srcIP="10.44.0.0:36688" resp=200
I0916 08:30:01.703618       1 httplog.go:132] "HTTP" verb="GET" URI="/healthz" latency="119.043µs" userAgent="kube-probe/1.27" audit-ID="" srcIP="10.44.0.0:36678" resp=200
I0916 08:30:11.702212       1 httplog.go:132] "HTTP" verb="GET" URI="/healthz" latency="95.64µs" userAgent="kube-probe/1.27" audit-ID="" srcIP="10.44.0.0:39512" resp=200
I0916 08:30:11.703359       1 httplog.go:132] "HTTP" verb="GET" URI="/healthz" latency="54.302µs" userAgent="kube-probe/1.27" audit-ID="" srcIP="10.44.0.0:39496" resp=200
I0916 08:30:21.702825       1 httplog.go:132] "HTTP" verb="GET" URI="/healthz" latency="126.126µs" userAgent="kube-probe/1.27" audit-ID="" srcIP="10.44.0.0:40530" resp=200
I0916 08:30:21.703901       1 httplog.go:132] "HTTP" verb="GET" URI="/healthz" latency="128.24µs" userAgent="kube-probe/1.27" audit-ID="" srcIP="10.44.0.0:40524" resp=200
I0916 08:30:31.702042       1 httplog.go:132] "HTTP" verb="GET" URI="/healthz" latency="151.463µs" userAgent="kube-probe/1.27" audit-ID="" srcIP="10.44.0.0:55958" resp=200
I0916 08:30:31.702330       1 httplog.go:132] "HTTP" verb="GET" URI="/healthz" latency="105.538µs" userAgent="kube-probe/1.27" audit-ID="" srcIP="10.44.0.0:55970" resp=200
I0916 08:30:41.702549       1 httplog.go:132] "HTTP" verb="GET" URI="/healthz" latency="131.927µs" userAgent="kube-probe/1.27" audit-ID="" srcIP="10.44.0.0:52214" resp=200
I0916 08:30:41.703736       1 httplog.go:132] "HTTP" verb="GET" URI="/healthz" latency="58.97µs" userAgent="kube-probe/1.27" audit-ID="" srcIP="10.44.0.0:52210" resp=200
I0916 08:30:51.702203       1 httplog.go:132] "HTTP" verb="GET" URI="/healthz" latency="135.343µs" userAgent="kube-probe/1.27" audit-ID="" srcIP="10.44.0.0:60596" resp=200
I0916 08:30:51.703568       1 httplog.go:132] "HTTP" verb="GET" URI="/healthz" latency="122.699µs" userAgent="kube-probe/1.27" audit-ID="" srcIP="10.44.0.0:60610" resp=200
I0916 08:31:01.702708       1 httplog.go:132] "HTTP" verb="GET" URI="/healthz" latency="151.143µs" userAgent="kube-probe/1.27" audit-ID="" srcIP="10.44.0.0:37382" resp=200
I0916 08:31:01.710354       1 httplog.go:132] "HTTP" verb="GET" URI="/healthz" latency="90.57µs" userAgent="kube-probe/1.27" audit-ID="" srcIP="10.44.0.0:37386" resp=200
I0916 08:31:11.702280       1 httplog.go:132] "HTTP" verb="GET" URI="/healthz" latency="116.869µs" userAgent="kube-probe/1.27" audit-ID="" srcIP="10.44.0.0:45636" resp=200
I0916 08:31:11.703512       1 httplog.go:132] "HTTP" verb="GET" URI="/healthz" latency="75.752µs" userAgent="kube-probe/1.27" audit-ID="" srcIP="10.44.0.0:45652" resp=200
I0916 08:31:21.706338       1 httplog.go:132] "HTTP" verb="GET" URI="/healthz" latency="80.39µs" userAgent="kube-probe/1.27" audit-ID="" srcIP="10.44.0.0:39244" resp=200
I0916 08:31:21.707661       1 httplog.go:132] "HTTP" verb="GET" URI="/healthz" latency="60.895µs" userAgent="kube-probe/1.27" audit-ID="" srcIP="10.44.0.0:39246" resp=200
I0916 08:31:25.731126       1 schedule_one.go:80] "Attempting to schedule pod" pod="default/falcon-pod-867106"
I0916 08:31:25.731854       1 log.go:194] require 4 gpu(s), and currently has 2 gpus(s) in total
I0916 08:31:25.739563       1 schedule_one.go:867] "Unable to schedule pod; no fit; waiting" pod="default/falcon-pod-867106" err="0/2 nodes are available: Require 4 gpu but only 2 gpu in the pool.. preemption: 0/2 nodes are available: 2 No preemption victims found for incoming pod.."
I0916 08:31:25.739674       1 schedule_one.go:943] "Updating pod condition" pod="default/falcon-pod-867106" conditionType=PodScheduled conditionStatus=False conditionReason="Unschedulable"
I0916 08:31:25.739780       1 schedule_one.go:80] "Attempting to schedule pod" pod="default/falcon-pod-398210"
I0916 08:31:25.740353       1 log.go:194] require 4 gpu(s), and currently has 2 gpus(s) in total
I0916 08:31:25.747236       1 schedule_one.go:867] "Unable to schedule pod; no fit; waiting" pod="default/falcon-pod-398210" err="0/2 nodes are available: Require 4 gpu but only 2 gpu in the pool.. preemption: 0/2 nodes are available: 2 No preemption victims found for incoming pod.."
I0916 08:31:25.747312       1 schedule_one.go:943] "Updating pod condition" pod="default/falcon-pod-398210" conditionType=PodScheduled conditionStatus=False conditionReason="Unschedulable"
I0916 08:31:25.747415       1 schedule_one.go:80] "Attempting to schedule pod" pod="default/falcon-pod-593250"
I0916 08:31:25.747866       1 log.go:194] require 4 gpu(s), and currently has 2 gpus(s) in total
I0916 08:31:25.753393       1 schedule_one.go:867] "Unable to schedule pod; no fit; waiting" pod="default/falcon-pod-593250" err="0/2 nodes are available: Require 4 gpu but only 2 gpu in the pool.. preemption: 0/2 nodes are available: 2 No preemption victims found for incoming pod.."
I0916 08:31:25.753470       1 schedule_one.go:943] "Updating pod condition" pod="default/falcon-pod-593250" conditionType=PodScheduled conditionStatus=False conditionReason="Unschedulable"
I0916 08:31:25.753576       1 schedule_one.go:80] "Attempting to schedule pod" pod="default/falcon-pod-581104"
I0916 08:31:25.753986       1 log.go:194] require 4 gpu(s), and currently has 2 gpus(s) in total
I0916 08:31:25.759780       1 schedule_one.go:867] "Unable to schedule pod; no fit; waiting" pod="default/falcon-pod-581104" err="0/2 nodes are available: Require 4 gpu but only 2 gpu in the pool.. preemption: 0/2 nodes are available: 2 No preemption victims found for incoming pod.."
I0916 08:31:25.759857       1 schedule_one.go:943] "Updating pod condition" pod="default/falcon-pod-581104" conditionType=PodScheduled conditionStatus=False conditionReason="Unschedulable"
I0916 08:31:25.759956       1 schedule_one.go:80] "Attempting to schedule pod" pod="default/falcon-pod-534716"
I0916 08:31:25.760331       1 log.go:194] require 4 gpu(s), and currently has 2 gpus(s) in total
I0916 08:31:25.766113       1 schedule_one.go:867] "Unable to schedule pod; no fit; waiting" pod="default/falcon-pod-534716" err="0/2 nodes are available: Require 4 gpu but only 2 gpu in the pool.. preemption: 0/2 nodes are available: 2 No preemption victims found for incoming pod.."
I0916 08:31:25.766236       1 schedule_one.go:943] "Updating pod condition" pod="default/falcon-pod-534716" conditionType=PodScheduled conditionStatus=False conditionReason="Unschedulable"
I0916 08:31:29.617846       1 eventhandlers.go:231] "Delete event for scheduled pod" pod="default/falcon-pod-381278"
I0916 08:31:31.703031       1 httplog.go:132] "HTTP" verb="GET" URI="/healthz" latency="100.829µs" userAgent="kube-probe/1.27" audit-ID="" srcIP="10.44.0.0:37470" resp=200
I0916 08:31:31.704257       1 httplog.go:132] "HTTP" verb="GET" URI="/healthz" latency="63.078µs" userAgent="kube-probe/1.27" audit-ID="" srcIP="10.44.0.0:37476" resp=200
I0916 08:31:36.133739       1 schedule_one.go:80] "Attempting to schedule pod" pod="default/falcon-pod-867106"
I0916 08:31:36.134243       1 log.go:194] require 4 gpu(s), and currently has 4 gpus(s) in total
I0916 08:31:36.141887       1 log.go:194] css-host-128 has 4 gpu, the pod requires 4 gpu -> score: 1
I0916 08:31:36.141920       1 log.go:194] css-host-129 has 0 gpu, the pod requires 4 gpu -> score: -4
I0916 08:31:36.142063       1 log.go:194] permit plugin
I0916 08:31:36.147190       1 log.go:194] alloc: 4, used: 0, required: 4
I0916 08:31:36.151898       1 log.go:194] alloc: 4, used: 0, required: 4
I0916 08:31:36.151998       1 schedule_one.go:80] "Attempting to schedule pod" pod="default/falcon-pod-398210"
I0916 08:31:36.152098       1 default_binder.go:53] "Attempting to bind pod to node" pod="default/falcon-pod-867106" node="css-host-128"
I0916 08:31:36.152449       1 log.go:194] require 4 gpu(s), and currently has 0 gpus(s) in total
I0916 08:31:36.155952       1 schedule_one.go:252] "Successfully bound pod to node" pod="default/falcon-pod-867106" node="css-host-128" evaluatedNodes=2 feasibleNodes=2
I0916 08:31:36.156020       1 eventhandlers.go:161] "Delete event for unscheduled pod" pod="default/falcon-pod-867106"
I0916 08:31:36.156090       1 eventhandlers.go:186] "Add event for scheduled pod" pod="default/falcon-pod-867106"
I0916 08:31:36.159397       1 schedule_one.go:867] "Unable to schedule pod; no fit; waiting" pod="default/falcon-pod-398210" err="0/2 nodes are available: Require 4 gpu but only 0 gpu in the pool.. preemption: 0/2 nodes are available: 2 No preemption victims found for incoming pod.."
I0916 08:31:36.159478       1 schedule_one.go:943] "Updating pod condition" pod="default/falcon-pod-398210" conditionType=PodScheduled conditionStatus=False conditionReason="Unschedulable"
I0916 08:31:36.166667       1 schedule_one.go:80] "Attempting to schedule pod" pod="default/falcon-pod-593250"
I0916 08:31:36.167117       1 log.go:194] require 4 gpu(s), and currently has 0 gpus(s) in total
I0916 08:31:36.173237       1 schedule_one.go:867] "Unable to schedule pod; no fit; waiting" pod="default/falcon-pod-593250" err="0/2 nodes are available: Require 4 gpu but only 0 gpu in the pool.. preemption: 0/2 nodes are available: 2 No preemption victims found for incoming pod.."
I0916 08:31:36.173323       1 schedule_one.go:943] "Updating pod condition" pod="default/falcon-pod-593250" conditionType=PodScheduled conditionStatus=False conditionReason="Unschedulable"
I0916 08:31:36.178925       1 schedule_one.go:80] "Attempting to schedule pod" pod="default/falcon-pod-581104"
I0916 08:31:36.179382       1 log.go:194] require 4 gpu(s), and currently has 0 gpus(s) in total
I0916 08:31:36.185200       1 schedule_one.go:867] "Unable to schedule pod; no fit; waiting" pod="default/falcon-pod-581104" err="0/2 nodes are available: Require 4 gpu but only 0 gpu in the pool.. preemption: 0/2 nodes are available: 2 No preemption victims found for incoming pod.."
I0916 08:31:36.185314       1 schedule_one.go:943] "Updating pod condition" pod="default/falcon-pod-581104" conditionType=PodScheduled conditionStatus=False conditionReason="Unschedulable"
I0916 08:31:36.191938       1 schedule_one.go:80] "Attempting to schedule pod" pod="default/falcon-pod-534716"
I0916 08:31:36.192482       1 log.go:194] require 4 gpu(s), and currently has 0 gpus(s) in total
I0916 08:31:36.198466       1 schedule_one.go:867] "Unable to schedule pod; no fit; waiting" pod="default/falcon-pod-534716" err="0/2 nodes are available: Require 4 gpu but only 0 gpu in the pool.. preemption: 0/2 nodes are available: 2 No preemption victims found for incoming pod.."
I0916 08:31:36.198559       1 schedule_one.go:943] "Updating pod condition" pod="default/falcon-pod-534716" conditionType=PodScheduled conditionStatus=False conditionReason="Unschedulable"
I0916 08:31:41.707553       1 httplog.go:132] "HTTP" verb="GET" URI="/healthz" latency="129.673µs" userAgent="kube-probe/1.27" audit-ID="" srcIP="10.44.0.0:55598" resp=200
I0916 08:31:41.708595       1 httplog.go:132] "HTTP" verb="GET" URI="/healthz" latency="103.053µs" userAgent="kube-probe/1.27" audit-ID="" srcIP="10.44.0.0:55600" resp=200
I0916 08:31:47.141293       1 schedule_one.go:80] "Attempting to schedule pod" pod="default/falcon-pod-398210"
I0916 08:31:47.141845       1 log.go:194] require 4 gpu(s), and currently has 0 gpus(s) in total
I0916 08:31:47.149377       1 schedule_one.go:867] "Unable to schedule pod; no fit; waiting" pod="default/falcon-pod-398210" err="0/2 nodes are available: Require 4 gpu but only 0 gpu in the pool.. preemption: 0/2 nodes are available: 2 No preemption victims found for incoming pod.."
I0916 08:31:47.149476       1 schedule_one.go:943] "Updating pod condition" pod="default/falcon-pod-398210" conditionType=PodScheduled conditionStatus=False conditionReason="Unschedulable"
I0916 08:31:47.149516       1 schedule_one.go:80] "Attempting to schedule pod" pod="default/falcon-pod-593250"
I0916 08:31:47.149972       1 log.go:194] require 4 gpu(s), and currently has 0 gpus(s) in total
I0916 08:31:47.155876       1 schedule_one.go:867] "Unable to schedule pod; no fit; waiting" pod="default/falcon-pod-593250" err="0/2 nodes are available: Require 4 gpu but only 0 gpu in the pool.. preemption: 0/2 nodes are available: 2 No preemption victims found for incoming pod.."
I0916 08:31:47.155961       1 schedule_one.go:943] "Updating pod condition" pod="default/falcon-pod-593250" conditionType=PodScheduled conditionStatus=False conditionReason="Unschedulable"
I0916 08:31:51.706990       1 httplog.go:132] "HTTP" verb="GET" URI="/healthz" latency="118.502µs" userAgent="kube-probe/1.27" audit-ID="" srcIP="10.44.0.0:46278" resp=200
I0916 08:31:51.708190       1 httplog.go:132] "HTTP" verb="GET" URI="/healthz" latency="88.255µs" userAgent="kube-probe/1.27" audit-ID="" srcIP="10.44.0.0:46280" resp=200
I0916 08:32:01.707568       1 httplog.go:132] "HTTP" verb="GET" URI="/healthz" latency="149.65µs" userAgent="kube-probe/1.27" audit-ID="" srcIP="10.44.0.0:40380" resp=200
I0916 08:32:01.708682       1 httplog.go:132] "HTTP" verb="GET" URI="/healthz" latency="86.091µs" userAgent="kube-probe/1.27" audit-ID="" srcIP="10.44.0.0:40366" resp=200
I0916 08:32:11.702975       1 httplog.go:132] "HTTP" verb="GET" URI="/healthz" latency="76.934µs" userAgent="kube-probe/1.27" audit-ID="" srcIP="10.44.0.0:54552" resp=200
I0916 08:32:11.708981       1 httplog.go:132] "HTTP" verb="GET" URI="/healthz" latency="54.312µs" userAgent="kube-probe/1.27" audit-ID="" srcIP="10.44.0.0:54578" resp=200
I0916 08:32:21.702936       1 httplog.go:132] "HTTP" verb="GET" URI="/healthz" latency="148.558µs" userAgent="kube-probe/1.27" audit-ID="" srcIP="10.44.0.0:33018" resp=200
I0916 08:32:21.704339       1 httplog.go:132] "HTTP" verb="GET" URI="/healthz" latency="105.558µs" userAgent="kube-probe/1.27" audit-ID="" srcIP="10.44.0.0:33010" resp=200
I0916 08:32:31.706676       1 httplog.go:132] "HTTP" verb="GET" URI="/healthz" latency="79.179µs" userAgent="kube-probe/1.27" audit-ID="" srcIP="10.44.0.0:38528" resp=200
I0916 08:32:31.708314       1 httplog.go:132] "HTTP" verb="GET" URI="/healthz" latency="103.414µs" userAgent="kube-probe/1.27" audit-ID="" srcIP="10.44.0.0:38542" resp=200
I0916 08:32:41.700410       1 httplog.go:132] "HTTP" verb="GET" URI="/healthz" latency="113.442µs" userAgent="kube-probe/1.27" audit-ID="" srcIP="10.44.0.0:46230" resp=200
I0916 08:32:41.702231       1 httplog.go:132] "HTTP" verb="GET" URI="/healthz" latency="120.496µs" userAgent="kube-probe/1.27" audit-ID="" srcIP="10.44.0.0:46220" resp=200
I0916 08:32:51.706306       1 httplog.go:132] "HTTP" verb="GET" URI="/healthz" latency="118.452µs" userAgent="kube-probe/1.27" audit-ID="" srcIP="10.44.0.0:50808" resp=200
I0916 08:32:51.707587       1 httplog.go:132] "HTTP" verb="GET" URI="/healthz" latency="61.716µs" userAgent="kube-probe/1.27" audit-ID="" srcIP="10.44.0.0:50794" resp=200
I0916 08:33:01.706212       1 httplog.go:132] "HTTP" verb="GET" URI="/healthz" latency="201.558µs" userAgent="kube-probe/1.27" audit-ID="" srcIP="10.44.0.0:60412" resp=200
I0916 08:33:01.711677       1 httplog.go:132] "HTTP" verb="GET" URI="/healthz" latency="117.59µs" userAgent="kube-probe/1.27" audit-ID="" srcIP="10.44.0.0:60414" resp=200
I0916 08:33:11.702895       1 httplog.go:132] "HTTP" verb="GET" URI="/healthz" latency="151.964µs" userAgent="kube-probe/1.27" audit-ID="" srcIP="10.44.0.0:41958" resp=200
I0916 08:33:11.703986       1 httplog.go:132] "HTTP" verb="GET" URI="/healthz" latency="99.506µs" userAgent="kube-probe/1.27" audit-ID="" srcIP="10.44.0.0:41968" resp=200
I0916 08:33:21.706976       1 httplog.go:132] "HTTP" verb="GET" URI="/healthz" latency="128.27µs" userAgent="kube-probe/1.27" audit-ID="" srcIP="10.44.0.0:35484" resp=200
I0916 08:33:21.708131       1 httplog.go:132] "HTTP" verb="GET" URI="/healthz" latency="102.712µs" userAgent="kube-probe/1.27" audit-ID="" srcIP="10.44.0.0:35486" resp=200
I0916 08:33:31.702390       1 httplog.go:132] "HTTP" verb="GET" URI="/healthz" latency="95.168µs" userAgent="kube-probe/1.27" audit-ID="" srcIP="10.44.0.0:50636" resp=200
I0916 08:33:31.703621       1 httplog.go:132] "HTTP" verb="GET" URI="/healthz" latency="127.869µs" userAgent="kube-probe/1.27" audit-ID="" srcIP="10.44.0.0:50642" resp=200
I0916 08:33:41.707079       1 httplog.go:132] "HTTP" verb="GET" URI="/healthz" latency="115.356µs" userAgent="kube-probe/1.27" audit-ID="" srcIP="10.44.0.0:56178" resp=200
I0916 08:33:41.708132       1 httplog.go:132] "HTTP" verb="GET" URI="/healthz" latency="85.621µs" userAgent="kube-probe/1.27" audit-ID="" srcIP="10.44.0.0:56186" resp=200
I0916 08:33:51.702815       1 httplog.go:132] "HTTP" verb="GET" URI="/healthz" latency="118.943µs" userAgent="kube-probe/1.27" audit-ID="" srcIP="10.44.0.0:59050" resp=200
I0916 08:33:51.703730       1 httplog.go:132] "HTTP" verb="GET" URI="/healthz" latency="110.898µs" userAgent="kube-probe/1.27" audit-ID="" srcIP="10.44.0.0:59038" resp=200
I0916 08:34:01.702179       1 httplog.go:132] "HTTP" verb="GET" URI="/healthz" latency="110.267µs" userAgent="kube-probe/1.27" audit-ID="" srcIP="10.44.0.0:47744" resp=200
I0916 08:34:01.708168       1 httplog.go:132] "HTTP" verb="GET" URI="/healthz" latency="81.292µs" userAgent="kube-probe/1.27" audit-ID="" srcIP="10.44.0.0:47752" resp=200
I0916 08:34:09.445317       1 eventhandlers.go:231] "Delete event for scheduled pod" pod="default/falcon-pod-867106"
I0916 08:34:09.445545       1 schedule_one.go:80] "Attempting to schedule pod" pod="default/falcon-pod-581104"
I0916 08:34:09.446157       1 log.go:194] require 4 gpu(s), and currently has 4 gpus(s) in total
I0916 08:34:09.454343       1 log.go:194] css-host-128 has 4 gpu, the pod requires 4 gpu -> score: 1
I0916 08:34:09.454383       1 log.go:194] css-host-129 has 0 gpu, the pod requires 4 gpu -> score: -4
I0916 08:34:09.454637       1 log.go:194] permit plugin
I0916 08:34:09.459241       1 log.go:194] alloc: 4, used: 0, required: 4
I0916 08:34:09.463943       1 log.go:194] alloc: 4, used: 0, required: 4
I0916 08:34:09.464009       1 schedule_one.go:80] "Attempting to schedule pod" pod="default/falcon-pod-534716"
I0916 08:34:09.464077       1 default_binder.go:53] "Attempting to bind pod to node" pod="default/falcon-pod-581104" node="css-host-128"
I0916 08:34:09.464440       1 log.go:194] require 4 gpu(s), and currently has 0 gpus(s) in total
I0916 08:34:09.468108       1 eventhandlers.go:186] "Add event for scheduled pod" pod="default/falcon-pod-581104"
I0916 08:34:09.468116       1 eventhandlers.go:161] "Delete event for unscheduled pod" pod="default/falcon-pod-581104"
I0916 08:34:09.468428       1 schedule_one.go:252] "Successfully bound pod to node" pod="default/falcon-pod-581104" node="css-host-128" evaluatedNodes=2 feasibleNodes=2
I0916 08:34:09.469735       1 schedule_one.go:867] "Unable to schedule pod; no fit; waiting" pod="default/falcon-pod-534716" err="0/2 nodes are available: Require 4 gpu but only 0 gpu in the pool.. preemption: 0/2 nodes are available: 2 No preemption victims found for incoming pod.."
I0916 08:34:09.469894       1 schedule_one.go:943] "Updating pod condition" pod="default/falcon-pod-534716" conditionType=PodScheduled conditionStatus=False conditionReason="Unschedulable"
I0916 08:34:09.469960       1 schedule_one.go:80] "Attempting to schedule pod" pod="default/falcon-pod-398210"
I0916 08:34:09.470617       1 log.go:194] require 4 gpu(s), and currently has 0 gpus(s) in total
I0916 08:34:09.482588       1 schedule_one.go:867] "Unable to schedule pod; no fit; waiting" pod="default/falcon-pod-398210" err="0/2 nodes are available: Require 4 gpu but only 0 gpu in the pool.. preemption: 0/2 nodes are available: 2 No preemption victims found for incoming pod.."
I0916 08:34:09.482686       1 schedule_one.go:943] "Updating pod condition" pod="default/falcon-pod-398210" conditionType=PodScheduled conditionStatus=False conditionReason="Unschedulable"
I0916 08:34:09.482769       1 schedule_one.go:80] "Attempting to schedule pod" pod="default/falcon-pod-593250"
I0916 08:34:09.483250       1 log.go:194] require 4 gpu(s), and currently has 0 gpus(s) in total
I0916 08:34:09.487217       1 schedule_one.go:867] "Unable to schedule pod; no fit; waiting" pod="default/falcon-pod-593250" err="0/2 nodes are available: Require 4 gpu but only 0 gpu in the pool.. preemption: 0/2 nodes are available: 2 No preemption victims found for incoming pod.."
I0916 08:34:09.487311       1 schedule_one.go:943] "Updating pod condition" pod="default/falcon-pod-593250" conditionType=PodScheduled conditionStatus=False conditionReason="Unschedulable"
I0916 08:34:11.702449       1 httplog.go:132] "HTTP" verb="GET" URI="/healthz" latency="115.035µs" userAgent="kube-probe/1.27" audit-ID="" srcIP="10.44.0.0:56344" resp=200
I0916 08:34:11.703190       1 httplog.go:132] "HTTP" verb="GET" URI="/healthz" latency="117.62µs" userAgent="kube-probe/1.27" audit-ID="" srcIP="10.44.0.0:56346" resp=200
I0916 08:34:20.230136       1 schedule_one.go:80] "Attempting to schedule pod" pod="default/falcon-pod-534716"
I0916 08:34:20.230738       1 log.go:194] require 4 gpu(s), and currently has 0 gpus(s) in total
I0916 08:34:20.238169       1 schedule_one.go:867] "Unable to schedule pod; no fit; waiting" pod="default/falcon-pod-534716" err="0/2 nodes are available: Require 4 gpu but only 0 gpu in the pool.. preemption: 0/2 nodes are available: 2 No preemption victims found for incoming pod.."
I0916 08:34:20.238272       1 schedule_one.go:943] "Updating pod condition" pod="default/falcon-pod-534716" conditionType=PodScheduled conditionStatus=False conditionReason="Unschedulable"
I0916 08:34:20.238352       1 schedule_one.go:80] "Attempting to schedule pod" pod="default/falcon-pod-593250"
I0916 08:34:20.238774       1 log.go:194] require 4 gpu(s), and currently has 0 gpus(s) in total
I0916 08:34:20.248504       1 schedule_one.go:867] "Unable to schedule pod; no fit; waiting" pod="default/falcon-pod-593250" err="0/2 nodes are available: Require 4 gpu but only 0 gpu in the pool.. preemption: 0/2 nodes are available: 2 No preemption victims found for incoming pod.."
I0916 08:34:20.248623       1 schedule_one.go:943] "Updating pod condition" pod="default/falcon-pod-593250" conditionType=PodScheduled conditionStatus=False conditionReason="Unschedulable"
I0916 08:34:21.702409       1 httplog.go:132] "HTTP" verb="GET" URI="/healthz" latency="134.011µs" userAgent="kube-probe/1.27" audit-ID="" srcIP="10.44.0.0:38372" resp=200
I0916 08:34:21.703596       1 httplog.go:132] "HTTP" verb="GET" URI="/healthz" latency="106.59µs" userAgent="kube-probe/1.27" audit-ID="" srcIP="10.44.0.0:38364" resp=200
I0916 08:34:31.706772       1 httplog.go:132] "HTTP" verb="GET" URI="/healthz" latency="96.04µs" userAgent="kube-probe/1.27" audit-ID="" srcIP="10.44.0.0:54582" resp=200
I0916 08:34:31.707981       1 httplog.go:132] "HTTP" verb="GET" URI="/healthz" latency="27.371µs" userAgent="kube-probe/1.27" audit-ID="" srcIP="10.44.0.0:54598" resp=200
I0916 08:34:41.706697       1 httplog.go:132] "HTTP" verb="GET" URI="/healthz" latency="110.306µs" userAgent="kube-probe/1.27" audit-ID="" srcIP="10.44.0.0:42934" resp=200
I0916 08:34:41.707859       1 httplog.go:132] "HTTP" verb="GET" URI="/healthz" latency="65.472µs" userAgent="kube-probe/1.27" audit-ID="" srcIP="10.44.0.0:42946" resp=200
I0916 08:34:51.702551       1 httplog.go:132] "HTTP" verb="GET" URI="/healthz" latency="105.247µs" userAgent="kube-probe/1.27" audit-ID="" srcIP="10.44.0.0:48306" resp=200
I0916 08:34:51.703762       1 httplog.go:132] "HTTP" verb="GET" URI="/healthz" latency="62.858µs" userAgent="kube-probe/1.27" audit-ID="" srcIP="10.44.0.0:48314" resp=200
I0916 08:35:01.702225       1 httplog.go:132] "HTTP" verb="GET" URI="/healthz" latency="126.958µs" userAgent="kube-probe/1.27" audit-ID="" srcIP="10.44.0.0:36766" resp=200
I0916 08:35:01.703354       1 httplog.go:132] "HTTP" verb="GET" URI="/healthz" latency="136.706µs" userAgent="kube-probe/1.27" audit-ID="" srcIP="10.44.0.0:36754" resp=200
I0916 08:35:11.707241       1 httplog.go:132] "HTTP" verb="GET" URI="/healthz" latency="102.001µs" userAgent="kube-probe/1.27" audit-ID="" srcIP="10.44.0.0:52166" resp=200
I0916 08:35:11.708539       1 httplog.go:132] "HTTP" verb="GET" URI="/healthz" latency="120.035µs" userAgent="kube-probe/1.27" audit-ID="" srcIP="10.44.0.0:52176" resp=200
I0916 08:35:21.702483       1 httplog.go:132] "HTTP" verb="GET" URI="/healthz" latency="115.106µs" userAgent="kube-probe/1.27" audit-ID="" srcIP="10.44.0.0:60208" resp=200
I0916 08:35:21.708801       1 httplog.go:132] "HTTP" verb="GET" URI="/healthz" latency="37.1µs" userAgent="kube-probe/1.27" audit-ID="" srcIP="10.44.0.0:60226" resp=200
I0916 08:35:31.706989       1 httplog.go:132] "HTTP" verb="GET" URI="/healthz" latency="62.056µs" userAgent="kube-probe/1.27" audit-ID="" srcIP="10.44.0.0:52364" resp=200
I0916 08:35:31.708156       1 httplog.go:132] "HTTP" verb="GET" URI="/healthz" latency="28.042µs" userAgent="kube-probe/1.27" audit-ID="" srcIP="10.44.0.0:52360" resp=200
I0916 08:35:41.701666       1 httplog.go:132] "HTTP" verb="GET" URI="/healthz" latency="103.585µs" userAgent="kube-probe/1.27" audit-ID="" srcIP="10.44.0.0:32768" resp=200
I0916 08:35:41.702748       1 httplog.go:132] "HTTP" verb="GET" URI="/healthz" latency="98.544µs" userAgent="kube-probe/1.27" audit-ID="" srcIP="10.44.0.0:60998" resp=200
I0916 08:35:46.079153       1 eventhandlers.go:231] "Delete event for scheduled pod" pod="default/falcon-pod-581104"
I0916 08:35:46.079324       1 schedule_one.go:80] "Attempting to schedule pod" pod="default/falcon-pod-398210"
I0916 08:35:46.079865       1 log.go:194] require 4 gpu(s), and currently has 4 gpus(s) in total
I0916 08:35:46.086610       1 log.go:194] css-host-128 has 4 gpu, the pod requires 4 gpu -> score: 1
I0916 08:35:46.086635       1 log.go:194] css-host-129 has 0 gpu, the pod requires 4 gpu -> score: -4
I0916 08:35:46.086791       1 log.go:194] permit plugin
I0916 08:35:46.091571       1 log.go:194] alloc: 4, used: 0, required: 4
I0916 08:35:46.095667       1 log.go:194] alloc: 4, used: 0, required: 4
I0916 08:35:46.095736       1 schedule_one.go:80] "Attempting to schedule pod" pod="default/falcon-pod-534716"
I0916 08:35:46.095871       1 default_binder.go:53] "Attempting to bind pod to node" pod="default/falcon-pod-398210" node="css-host-128"
I0916 08:35:46.096193       1 log.go:194] require 4 gpu(s), and currently has 0 gpus(s) in total
I0916 08:35:46.099859       1 eventhandlers.go:186] "Add event for scheduled pod" pod="default/falcon-pod-398210"
I0916 08:35:46.099879       1 schedule_one.go:252] "Successfully bound pod to node" pod="default/falcon-pod-398210" node="css-host-128" evaluatedNodes=2 feasibleNodes=2
I0916 08:35:46.099903       1 eventhandlers.go:161] "Delete event for unscheduled pod" pod="default/falcon-pod-398210"
I0916 08:35:46.102035       1 schedule_one.go:867] "Unable to schedule pod; no fit; waiting" pod="default/falcon-pod-534716" err="0/2 nodes are available: Require 4 gpu but only 0 gpu in the pool.. preemption: 0/2 nodes are available: 2 No preemption victims found for incoming pod.."
I0916 08:35:46.102124       1 schedule_one.go:943] "Updating pod condition" pod="default/falcon-pod-534716" conditionType=PodScheduled conditionStatus=False conditionReason="Unschedulable"
I0916 08:35:46.102166       1 schedule_one.go:80] "Attempting to schedule pod" pod="default/falcon-pod-593250"
I0916 08:35:46.102541       1 log.go:194] require 4 gpu(s), and currently has 0 gpus(s) in total
I0916 08:35:46.109154       1 schedule_one.go:867] "Unable to schedule pod; no fit; waiting" pod="default/falcon-pod-593250" err="0/2 nodes are available: Require 4 gpu but only 0 gpu in the pool.. preemption: 0/2 nodes are available: 2 No preemption victims found for incoming pod.."
I0916 08:35:46.109243       1 schedule_one.go:943] "Updating pod condition" pod="default/falcon-pod-593250" conditionType=PodScheduled conditionStatus=False conditionReason="Unschedulable"
I0916 08:35:51.701994       1 httplog.go:132] "HTTP" verb="GET" URI="/healthz" latency="121.497µs" userAgent="kube-probe/1.27" audit-ID="" srcIP="10.44.0.0:38562" resp=200
I0916 08:35:51.703141       1 httplog.go:132] "HTTP" verb="GET" URI="/healthz" latency="109.455µs" userAgent="kube-probe/1.27" audit-ID="" srcIP="10.44.0.0:38564" resp=200
I0916 08:35:56.282157       1 schedule_one.go:80] "Attempting to schedule pod" pod="default/falcon-pod-534716"
I0916 08:35:56.282679       1 log.go:194] require 4 gpu(s), and currently has 0 gpus(s) in total
I0916 08:35:56.290263       1 schedule_one.go:867] "Unable to schedule pod; no fit; waiting" pod="default/falcon-pod-534716" err="0/2 nodes are available: Require 4 gpu but only 0 gpu in the pool.. preemption: 0/2 nodes are available: 2 No preemption victims found for incoming pod.."
I0916 08:35:56.290412       1 schedule_one.go:943] "Updating pod condition" pod="default/falcon-pod-534716" conditionType=PodScheduled conditionStatus=False conditionReason="Unschedulable"
I0916 08:36:01.707834       1 httplog.go:132] "HTTP" verb="GET" URI="/healthz" latency="138.118µs" userAgent="kube-probe/1.27" audit-ID="" srcIP="10.44.0.0:53502" resp=200
I0916 08:36:01.709035       1 httplog.go:132] "HTTP" verb="GET" URI="/healthz" latency="151.174µs" userAgent="kube-probe/1.27" audit-ID="" srcIP="10.44.0.0:53490" resp=200
I0916 08:36:11.702198       1 httplog.go:132] "HTTP" verb="GET" URI="/healthz" latency="82.023µs" userAgent="kube-probe/1.27" audit-ID="" srcIP="10.44.0.0:49428" resp=200
I0916 08:36:11.703466       1 httplog.go:132] "HTTP" verb="GET" URI="/healthz" latency="121.227µs" userAgent="kube-probe/1.27" audit-ID="" srcIP="10.44.0.0:49436" resp=200
I0916 08:36:21.706786       1 httplog.go:132] "HTTP" verb="GET" URI="/healthz" latency="131.466µs" userAgent="kube-probe/1.27" audit-ID="" srcIP="10.44.0.0:44600" resp=200
I0916 08:36:21.707925       1 httplog.go:132] "HTTP" verb="GET" URI="/healthz" latency="61.575µs" userAgent="kube-probe/1.27" audit-ID="" srcIP="10.44.0.0:44598" resp=200
I0916 08:36:31.706108       1 httplog.go:132] "HTTP" verb="GET" URI="/healthz" latency="113.172µs" userAgent="kube-probe/1.27" audit-ID="" srcIP="10.44.0.0:53080" resp=200
I0916 08:36:31.707697       1 httplog.go:132] "HTTP" verb="GET" URI="/healthz" latency="56.856µs" userAgent="kube-probe/1.27" audit-ID="" srcIP="10.44.0.0:53094" resp=200
I0916 08:36:41.703122       1 httplog.go:132] "HTTP" verb="GET" URI="/healthz" latency="114.093µs" userAgent="kube-probe/1.27" audit-ID="" srcIP="10.44.0.0:54410" resp=200
I0916 08:36:41.704198       1 httplog.go:132] "HTTP" verb="GET" URI="/healthz" latency="90.61µs" userAgent="kube-probe/1.27" audit-ID="" srcIP="10.44.0.0:54424" resp=200
I0916 08:36:51.702449       1 httplog.go:132] "HTTP" verb="GET" URI="/healthz" latency="108.724µs" userAgent="kube-probe/1.27" audit-ID="" srcIP="10.44.0.0:39696" resp=200
I0916 08:36:51.703682       1 httplog.go:132] "HTTP" verb="GET" URI="/healthz" latency="132.698µs" userAgent="kube-probe/1.27" audit-ID="" srcIP="10.44.0.0:39708" resp=200
I0916 08:37:01.703394       1 httplog.go:132] "HTTP" verb="GET" URI="/healthz" latency="106.008µs" userAgent="kube-probe/1.27" audit-ID="" srcIP="10.44.0.0:35120" resp=200
I0916 08:37:01.704545       1 httplog.go:132] "HTTP" verb="GET" URI="/healthz" latency="130.124µs" userAgent="kube-probe/1.27" audit-ID="" srcIP="10.44.0.0:35124" resp=200
I0916 08:37:11.706254       1 httplog.go:132] "HTTP" verb="GET" URI="/healthz" latency="155.682µs" userAgent="kube-probe/1.27" audit-ID="" srcIP="10.44.0.0:36300" resp=200
I0916 08:37:11.707510       1 httplog.go:132] "HTTP" verb="GET" URI="/healthz" latency="110.497µs" userAgent="kube-probe/1.27" audit-ID="" srcIP="10.44.0.0:36302" resp=200
I0916 08:37:21.702246       1 httplog.go:132] "HTTP" verb="GET" URI="/healthz" latency="87.875µs" userAgent="kube-probe/1.27" audit-ID="" srcIP="10.44.0.0:45906" resp=200
I0916 08:37:21.709960       1 httplog.go:132] "HTTP" verb="GET" URI="/healthz" latency="132.939µs" userAgent="kube-probe/1.27" audit-ID="" srcIP="10.44.0.0:45914" resp=200
I0916 08:37:31.706219       1 httplog.go:132] "HTTP" verb="GET" URI="/healthz" latency="118.472µs" userAgent="kube-probe/1.27" audit-ID="" srcIP="10.44.0.0:37210" resp=200
I0916 08:37:31.707315       1 httplog.go:132] "HTTP" verb="GET" URI="/healthz" latency="36.979µs" userAgent="kube-probe/1.27" audit-ID="" srcIP="10.44.0.0:37212" resp=200
I0916 08:37:41.702935       1 httplog.go:132] "HTTP" verb="GET" URI="/healthz" latency="109.716µs" userAgent="kube-probe/1.27" audit-ID="" srcIP="10.44.0.0:43524" resp=200
I0916 08:37:41.704122       1 httplog.go:132] "HTTP" verb="GET" URI="/healthz" latency="120.476µs" userAgent="kube-probe/1.27" audit-ID="" srcIP="10.44.0.0:43526" resp=200
I0916 08:37:51.702195       1 httplog.go:132] "HTTP" verb="GET" URI="/healthz" latency="128.581µs" userAgent="kube-probe/1.27" audit-ID="" srcIP="10.44.0.0:59080" resp=200
I0916 08:37:51.702245       1 httplog.go:132] "HTTP" verb="GET" URI="/healthz" latency="61.876µs" userAgent="kube-probe/1.27" audit-ID="" srcIP="10.44.0.0:59076" resp=200
I0916 08:38:01.702478       1 httplog.go:132] "HTTP" verb="GET" URI="/healthz" latency="121.718µs" userAgent="kube-probe/1.27" audit-ID="" srcIP="10.44.0.0:40520" resp=200
I0916 08:38:01.708910       1 httplog.go:132] "HTTP" verb="GET" URI="/healthz" latency="37.871µs" userAgent="kube-probe/1.27" audit-ID="" srcIP="10.44.0.0:40538" resp=200
I0916 08:38:11.706341       1 httplog.go:132] "HTTP" verb="GET" URI="/healthz" latency="69.771µs" userAgent="kube-probe/1.27" audit-ID="" srcIP="10.44.0.0:55228" resp=200
I0916 08:38:11.707652       1 httplog.go:132] "HTTP" verb="GET" URI="/healthz" latency="132.118µs" userAgent="kube-probe/1.27" audit-ID="" srcIP="10.44.0.0:55238" resp=200
I0916 08:38:21.702558       1 httplog.go:132] "HTTP" verb="GET" URI="/healthz" latency="68.258µs" userAgent="kube-probe/1.27" audit-ID="" srcIP="10.44.0.0:55004" resp=200
I0916 08:38:21.703787       1 httplog.go:132] "HTTP" verb="GET" URI="/healthz" latency="55.995µs" userAgent="kube-probe/1.27" audit-ID="" srcIP="10.44.0.0:55018" resp=200
I0916 08:38:31.701899       1 httplog.go:132] "HTTP" verb="GET" URI="/healthz" latency="68.088µs" userAgent="kube-probe/1.27" audit-ID="" srcIP="10.44.0.0:42390" resp=200
I0916 08:38:31.703106       1 httplog.go:132] "HTTP" verb="GET" URI="/healthz" latency="127.829µs" userAgent="kube-probe/1.27" audit-ID="" srcIP="10.44.0.0:42394" resp=200
I0916 08:38:41.707208       1 httplog.go:132] "HTTP" verb="GET" URI="/healthz" latency="110.347µs" userAgent="kube-probe/1.27" audit-ID="" srcIP="10.44.0.0:50604" resp=200
I0916 08:38:41.708185       1 httplog.go:132] "HTTP" verb="GET" URI="/healthz" latency="82.825µs" userAgent="kube-probe/1.27" audit-ID="" srcIP="10.44.0.0:50588" resp=200
I0916 08:38:51.702664       1 httplog.go:132] "HTTP" verb="GET" URI="/healthz" latency="116.97µs" userAgent="kube-probe/1.27" audit-ID="" srcIP="10.44.0.0:55266" resp=200
I0916 08:38:51.703764       1 httplog.go:132] "HTTP" verb="GET" URI="/healthz" latency="61.304µs" userAgent="kube-probe/1.27" audit-ID="" srcIP="10.44.0.0:55268" resp=200
I0916 08:39:01.703064       1 httplog.go:132] "HTTP" verb="GET" URI="/healthz" latency="105.288µs" userAgent="kube-probe/1.27" audit-ID="" srcIP="10.44.0.0:46834" resp=200
I0916 08:39:01.704105       1 httplog.go:132] "HTTP" verb="GET" URI="/healthz" latency="51.216µs" userAgent="kube-probe/1.27" audit-ID="" srcIP="10.44.0.0:46842" resp=200
I0916 08:39:11.706133       1 httplog.go:132] "HTTP" verb="GET" URI="/healthz" latency="116.308µs" userAgent="kube-probe/1.27" audit-ID="" srcIP="10.44.0.0:46404" resp=200
I0916 08:39:11.707317       1 httplog.go:132] "HTTP" verb="GET" URI="/healthz" latency="52.248µs" userAgent="kube-probe/1.27" audit-ID="" srcIP="10.44.0.0:46412" resp=200
I0916 08:39:21.705644       1 httplog.go:132] "HTTP" verb="GET" URI="/healthz" latency="45.345µs" userAgent="kube-probe/1.27" audit-ID="" srcIP="10.44.0.0:55866" resp=200
I0916 08:39:21.707064       1 httplog.go:132] "HTTP" verb="GET" URI="/healthz" latency="138.86µs" userAgent="kube-probe/1.27" audit-ID="" srcIP="10.44.0.0:55850" resp=200
I0916 08:39:31.705919       1 httplog.go:132] "HTTP" verb="GET" URI="/healthz" latency="116.007µs" userAgent="kube-probe/1.27" audit-ID="" srcIP="10.44.0.0:54386" resp=200
I0916 08:39:31.707176       1 httplog.go:132] "HTTP" verb="GET" URI="/healthz" latency="61.636µs" userAgent="kube-probe/1.27" audit-ID="" srcIP="10.44.0.0:54394" resp=200
I0916 08:39:41.703298       1 httplog.go:132] "HTTP" verb="GET" URI="/healthz" latency="72.736µs" userAgent="kube-probe/1.27" audit-ID="" srcIP="10.44.0.0:53826" resp=200
I0916 08:39:41.704303       1 httplog.go:132] "HTTP" verb="GET" URI="/healthz" latency="41.788µs" userAgent="kube-probe/1.27" audit-ID="" srcIP="10.44.0.0:53840" resp=200
I0916 08:39:51.706117       1 httplog.go:132] "HTTP" verb="GET" URI="/healthz" latency="70.843µs" userAgent="kube-probe/1.27" audit-ID="" srcIP="10.44.0.0:41074" resp=200
I0916 08:39:51.707458       1 httplog.go:132] "HTTP" verb="GET" URI="/healthz" latency="69.109µs" userAgent="kube-probe/1.27" audit-ID="" srcIP="10.44.0.0:41058" resp=200
I0916 08:40:01.701849       1 httplog.go:132] "HTTP" verb="GET" URI="/healthz" latency="112.661µs" userAgent="kube-probe/1.27" audit-ID="" srcIP="10.44.0.0:43310" resp=200
I0916 08:40:01.703042       1 httplog.go:132] "HTTP" verb="GET" URI="/healthz" latency="54.141µs" userAgent="kube-probe/1.27" audit-ID="" srcIP="10.44.0.0:43306" resp=200
I0916 08:40:11.706068       1 httplog.go:132] "HTTP" verb="GET" URI="/healthz" latency="75.071µs" userAgent="kube-probe/1.27" audit-ID="" srcIP="10.44.0.0:40768" resp=200
I0916 08:40:11.707312       1 httplog.go:132] "HTTP" verb="GET" URI="/healthz" latency="83.005µs" userAgent="kube-probe/1.27" audit-ID="" srcIP="10.44.0.0:40770" resp=200
I0916 08:40:21.702617       1 httplog.go:132] "HTTP" verb="GET" URI="/healthz" latency="132.338µs" userAgent="kube-probe/1.27" audit-ID="" srcIP="10.44.0.0:56086" resp=200
I0916 08:40:21.704081       1 httplog.go:132] "HTTP" verb="GET" URI="/healthz" latency="84.829µs" userAgent="kube-probe/1.27" audit-ID="" srcIP="10.44.0.0:56078" resp=200
I0916 08:40:31.702607       1 httplog.go:132] "HTTP" verb="GET" URI="/healthz" latency="106.55µs" userAgent="kube-probe/1.27" audit-ID="" srcIP="10.44.0.0:34556" resp=200
I0916 08:40:31.710355       1 httplog.go:132] "HTTP" verb="GET" URI="/healthz" latency="55.203µs" userAgent="kube-probe/1.27" audit-ID="" srcIP="10.44.0.0:34576" resp=200
I0916 08:40:41.702653       1 httplog.go:132] "HTTP" verb="GET" URI="/healthz" latency="123.632µs" userAgent="kube-probe/1.27" audit-ID="" srcIP="10.44.0.0:55160" resp=200
I0916 08:40:41.703963       1 httplog.go:132] "HTTP" verb="GET" URI="/healthz" latency="108.524µs" userAgent="kube-probe/1.27" audit-ID="" srcIP="10.44.0.0:55152" resp=200
I0916 08:40:51.707383       1 httplog.go:132] "HTTP" verb="GET" URI="/healthz" latency="138.61µs" userAgent="kube-probe/1.27" audit-ID="" srcIP="10.44.0.0:39440" resp=200
I0916 08:40:51.708236       1 httplog.go:132] "HTTP" verb="GET" URI="/healthz" latency="101.109µs" userAgent="kube-probe/1.27" audit-ID="" srcIP="10.44.0.0:39446" resp=200
I0916 08:40:55.741458       1 schedule_one.go:80] "Attempting to schedule pod" pod="default/falcon-pod-593250"
I0916 08:40:55.742063       1 log.go:194] require 4 gpu(s), and currently has 0 gpus(s) in total
I0916 08:40:55.750120       1 schedule_one.go:867] "Unable to schedule pod; no fit; waiting" pod="default/falcon-pod-593250" err="0/2 nodes are available: Require 4 gpu but only 0 gpu in the pool.. preemption: 0/2 nodes are available: 2 No preemption victims found for incoming pod.."
I0916 08:40:55.750232       1 schedule_one.go:943] "Updating pod condition" pod="default/falcon-pod-593250" conditionType=PodScheduled conditionStatus=False conditionReason="Unschedulable"
I0916 08:41:01.706153       1 httplog.go:132] "HTTP" verb="GET" URI="/healthz" latency="146.554µs" userAgent="kube-probe/1.27" audit-ID="" srcIP="10.44.0.0:50670" resp=200
I0916 08:41:01.707425       1 httplog.go:132] "HTTP" verb="GET" URI="/healthz" latency="93.836µs" userAgent="kube-probe/1.27" audit-ID="" srcIP="10.44.0.0:50680" resp=200
I0916 08:41:11.706252       1 httplog.go:132] "HTTP" verb="GET" URI="/healthz" latency="62.037µs" userAgent="kube-probe/1.27" audit-ID="" srcIP="10.44.0.0:41630" resp=200
I0916 08:41:11.707649       1 httplog.go:132] "HTTP" verb="GET" URI="/healthz" latency="97.622µs" userAgent="kube-probe/1.27" audit-ID="" srcIP="10.44.0.0:41646" resp=200
I0916 08:41:21.702694       1 httplog.go:132] "HTTP" verb="GET" URI="/healthz" latency="126.598µs" userAgent="kube-probe/1.27" audit-ID="" srcIP="10.44.0.0:35054" resp=200
I0916 08:41:21.710559       1 httplog.go:132] "HTTP" verb="GET" URI="/healthz" latency="54.542µs" userAgent="kube-probe/1.27" audit-ID="" srcIP="10.44.0.0:35066" resp=200
I0916 08:41:25.742212       1 schedule_one.go:80] "Attempting to schedule pod" pod="default/falcon-pod-534716"
I0916 08:41:25.742709       1 log.go:194] require 4 gpu(s), and currently has 0 gpus(s) in total
I0916 08:41:25.749140       1 schedule_one.go:867] "Unable to schedule pod; no fit; waiting" pod="default/falcon-pod-534716" err="0/2 nodes are available: Require 4 gpu but only 0 gpu in the pool.. preemption: 0/2 nodes are available: 2 No preemption victims found for incoming pod.."
I0916 08:41:25.749251       1 schedule_one.go:943] "Updating pod condition" pod="default/falcon-pod-534716" conditionType=PodScheduled conditionStatus=False conditionReason="Unschedulable"
I0916 08:41:31.701938       1 httplog.go:132] "HTTP" verb="GET" URI="/healthz" latency="93.706µs" userAgent="kube-probe/1.27" audit-ID="" srcIP="10.44.0.0:33958" resp=200
I0916 08:41:31.709526       1 httplog.go:132] "HTTP" verb="GET" URI="/healthz" latency="39.324µs" userAgent="kube-probe/1.27" audit-ID="" srcIP="10.44.0.0:33974" resp=200
I0916 08:41:41.701140       1 httplog.go:132] "HTTP" verb="GET" URI="/healthz" latency="84.999µs" userAgent="kube-probe/1.27" audit-ID="" srcIP="10.44.0.0:56206" resp=200
I0916 08:41:41.702470       1 httplog.go:132] "HTTP" verb="GET" URI="/healthz" latency="97.673µs" userAgent="kube-probe/1.27" audit-ID="" srcIP="10.44.0.0:56196" resp=200
I0916 08:41:51.705827       1 httplog.go:132] "HTTP" verb="GET" URI="/healthz" latency="104.616µs" userAgent="kube-probe/1.27" audit-ID="" srcIP="10.44.0.0:49458" resp=200
I0916 08:41:51.706974       1 httplog.go:132] "HTTP" verb="GET" URI="/healthz" latency="73.958µs" userAgent="kube-probe/1.27" audit-ID="" srcIP="10.44.0.0:49452" resp=200
I0916 08:42:01.705940       1 httplog.go:132] "HTTP" verb="GET" URI="/healthz" latency="93.966µs" userAgent="kube-probe/1.27" audit-ID="" srcIP="10.44.0.0:41722" resp=200
I0916 08:42:01.707057       1 httplog.go:132] "HTTP" verb="GET" URI="/healthz" latency="54.903µs" userAgent="kube-probe/1.27" audit-ID="" srcIP="10.44.0.0:41714" resp=200
I0916 08:42:11.702429       1 httplog.go:132] "HTTP" verb="GET" URI="/healthz" latency="110.257µs" userAgent="kube-probe/1.27" audit-ID="" srcIP="10.44.0.0:43748" resp=200
I0916 08:42:11.703513       1 httplog.go:132] "HTTP" verb="GET" URI="/healthz" latency="113.994µs" userAgent="kube-probe/1.27" audit-ID="" srcIP="10.44.0.0:43758" resp=200
I0916 08:42:21.702058       1 httplog.go:132] "HTTP" verb="GET" URI="/healthz" latency="119.534µs" userAgent="kube-probe/1.27" audit-ID="" srcIP="10.44.0.0:43888" resp=200
I0916 08:42:21.703160       1 httplog.go:132] "HTTP" verb="GET" URI="/healthz" latency="114.635µs" userAgent="kube-probe/1.27" audit-ID="" srcIP="10.44.0.0:43902" resp=200
I0916 08:42:31.706203       1 httplog.go:132] "HTTP" verb="GET" URI="/healthz" latency="65.312µs" userAgent="kube-probe/1.27" audit-ID="" srcIP="10.44.0.0:60058" resp=200
I0916 08:42:31.707466       1 httplog.go:132] "HTTP" verb="GET" URI="/healthz" latency="21.1µs" userAgent="kube-probe/1.27" audit-ID="" srcIP="10.44.0.0:60054" resp=200
I0916 08:42:41.702204       1 httplog.go:132] "HTTP" verb="GET" URI="/healthz" latency="90.851µs" userAgent="kube-probe/1.27" audit-ID="" srcIP="10.44.0.0:52786" resp=200
I0916 08:42:41.703381       1 httplog.go:132] "HTTP" verb="GET" URI="/healthz" latency="58.62µs" userAgent="kube-probe/1.27" audit-ID="" srcIP="10.44.0.0:52770" resp=200
I0916 08:42:51.702369       1 httplog.go:132] "HTTP" verb="GET" URI="/healthz" latency="118.683µs" userAgent="kube-probe/1.27" audit-ID="" srcIP="10.44.0.0:60256" resp=200
I0916 08:42:51.703385       1 httplog.go:132] "HTTP" verb="GET" URI="/healthz" latency="68.218µs" userAgent="kube-probe/1.27" audit-ID="" srcIP="10.44.0.0:60254" resp=200
I0916 08:43:01.702743       1 httplog.go:132] "HTTP" verb="GET" URI="/healthz" latency="126.878µs" userAgent="kube-probe/1.27" audit-ID="" srcIP="10.44.0.0:50764" resp=200
I0916 08:43:01.703884       1 httplog.go:132] "HTTP" verb="GET" URI="/healthz" latency="107.662µs" userAgent="kube-probe/1.27" audit-ID="" srcIP="10.44.0.0:50778" resp=200
I0916 08:43:11.702648       1 httplog.go:132] "HTTP" verb="GET" URI="/healthz" latency="95.97µs" userAgent="kube-probe/1.27" audit-ID="" srcIP="10.44.0.0:39628" resp=200
I0916 08:43:11.703802       1 httplog.go:132] "HTTP" verb="GET" URI="/healthz" latency="108.724µs" userAgent="kube-probe/1.27" audit-ID="" srcIP="10.44.0.0:39644" resp=200
I0916 08:43:15.321876       1 eventhandlers.go:231] "Delete event for scheduled pod" pod="default/falcon-pod-398210"
I0916 08:43:15.322022       1 schedule_one.go:80] "Attempting to schedule pod" pod="default/falcon-pod-593250"
I0916 08:43:15.322538       1 log.go:194] require 4 gpu(s), and currently has 4 gpus(s) in total
I0916 08:43:15.328442       1 log.go:194] css-host-128 has 4 gpu, the pod requires 4 gpu -> score: 1
I0916 08:43:15.328481       1 log.go:194] css-host-129 has 0 gpu, the pod requires 4 gpu -> score: -4
I0916 08:43:15.328637       1 log.go:194] permit plugin
I0916 08:43:15.333134       1 log.go:194] alloc: 4, used: 0, required: 4
I0916 08:43:15.337750       1 log.go:194] alloc: 4, used: 0, required: 4
I0916 08:43:15.337827       1 schedule_one.go:80] "Attempting to schedule pod" pod="default/falcon-pod-534716"
I0916 08:43:15.337898       1 default_binder.go:53] "Attempting to bind pod to node" pod="default/falcon-pod-593250" node="css-host-128"
I0916 08:43:15.338369       1 log.go:194] require 4 gpu(s), and currently has 0 gpus(s) in total
I0916 08:43:15.341466       1 schedule_one.go:252] "Successfully bound pod to node" pod="default/falcon-pod-593250" node="css-host-128" evaluatedNodes=2 feasibleNodes=2
I0916 08:43:15.341585       1 eventhandlers.go:161] "Delete event for unscheduled pod" pod="default/falcon-pod-593250"
I0916 08:43:15.341640       1 eventhandlers.go:186] "Add event for scheduled pod" pod="default/falcon-pod-593250"
I0916 08:43:15.346308       1 schedule_one.go:867] "Unable to schedule pod; no fit; waiting" pod="default/falcon-pod-534716" err="0/2 nodes are available: Require 4 gpu but only 0 gpu in the pool.. preemption: 0/2 nodes are available: 2 No preemption victims found for incoming pod.."
I0916 08:43:15.346413       1 schedule_one.go:943] "Updating pod condition" pod="default/falcon-pod-534716" conditionType=PodScheduled conditionStatus=False conditionReason="Unschedulable"
I0916 08:43:21.707203       1 httplog.go:132] "HTTP" verb="GET" URI="/healthz" latency="92.073µs" userAgent="kube-probe/1.27" audit-ID="" srcIP="10.44.0.0:57320" resp=200
I0916 08:43:21.707370       1 httplog.go:132] "HTTP" verb="GET" URI="/healthz" latency="27.902µs" userAgent="kube-probe/1.27" audit-ID="" srcIP="10.44.0.0:57312" resp=200
I0916 08:43:25.552329       1 schedule_one.go:80] "Attempting to schedule pod" pod="default/falcon-pod-534716"
I0916 08:43:25.552959       1 log.go:194] require 4 gpu(s), and currently has 0 gpus(s) in total
I0916 08:43:25.559883       1 schedule_one.go:867] "Unable to schedule pod; no fit; waiting" pod="default/falcon-pod-534716" err="0/2 nodes are available: Require 4 gpu but only 0 gpu in the pool.. preemption: 0/2 nodes are available: 2 No preemption victims found for incoming pod.."
I0916 08:43:25.559984       1 schedule_one.go:943] "Updating pod condition" pod="default/falcon-pod-534716" conditionType=PodScheduled conditionStatus=False conditionReason="Unschedulable"
I0916 08:43:31.706809       1 httplog.go:132] "HTTP" verb="GET" URI="/healthz" latency="78.046µs" userAgent="kube-probe/1.27" audit-ID="" srcIP="10.44.0.0:52832" resp=200
I0916 08:43:31.707901       1 httplog.go:132] "HTTP" verb="GET" URI="/healthz" latency="57.217µs" userAgent="kube-probe/1.27" audit-ID="" srcIP="10.44.0.0:52834" resp=200
I0916 08:43:41.706430       1 httplog.go:132] "HTTP" verb="GET" URI="/healthz" latency="105.107µs" userAgent="kube-probe/1.27" audit-ID="" srcIP="10.44.0.0:39438" resp=200
I0916 08:43:41.707593       1 httplog.go:132] "HTTP" verb="GET" URI="/healthz" latency="65.663µs" userAgent="kube-probe/1.27" audit-ID="" srcIP="10.44.0.0:39448" resp=200
I0916 08:43:51.701824       1 httplog.go:132] "HTTP" verb="GET" URI="/healthz" latency="86.142µs" userAgent="kube-probe/1.27" audit-ID="" srcIP="10.44.0.0:58988" resp=200
I0916 08:43:51.702986       1 httplog.go:132] "HTTP" verb="GET" URI="/healthz" latency="50.976µs" userAgent="kube-probe/1.27" audit-ID="" srcIP="10.44.0.0:59000" resp=200
I0916 08:44:01.706810       1 httplog.go:132] "HTTP" verb="GET" URI="/healthz" latency="93.977µs" userAgent="kube-probe/1.27" audit-ID="" srcIP="10.44.0.0:39110" resp=200
I0916 08:44:01.707939       1 httplog.go:132] "HTTP" verb="GET" URI="/healthz" latency="43.141µs" userAgent="kube-probe/1.27" audit-ID="" srcIP="10.44.0.0:39094" resp=200
I0916 08:44:11.707070       1 httplog.go:132] "HTTP" verb="GET" URI="/healthz" latency="131.887µs" userAgent="kube-probe/1.27" audit-ID="" srcIP="10.44.0.0:34434" resp=200
I0916 08:44:11.708379       1 httplog.go:132] "HTTP" verb="GET" URI="/healthz" latency="71.023µs" userAgent="kube-probe/1.27" audit-ID="" srcIP="10.44.0.0:34444" resp=200
I0916 08:44:21.703874       1 httplog.go:132] "HTTP" verb="GET" URI="/healthz" latency="105.377µs" userAgent="kube-probe/1.27" audit-ID="" srcIP="10.44.0.0:41182" resp=200
I0916 08:44:21.705195       1 httplog.go:132] "HTTP" verb="GET" URI="/healthz" latency="70.282µs" userAgent="kube-probe/1.27" audit-ID="" srcIP="10.44.0.0:41198" resp=200
I0916 08:44:31.707355       1 httplog.go:132] "HTTP" verb="GET" URI="/healthz" latency="101.851µs" userAgent="kube-probe/1.27" audit-ID="" srcIP="10.44.0.0:48882" resp=200
I0916 08:44:31.708497       1 httplog.go:132] "HTTP" verb="GET" URI="/healthz" latency="60.523µs" userAgent="kube-probe/1.27" audit-ID="" srcIP="10.44.0.0:48874" resp=200
I0916 08:44:41.702340       1 httplog.go:132] "HTTP" verb="GET" URI="/healthz" latency="105.047µs" userAgent="kube-probe/1.27" audit-ID="" srcIP="10.44.0.0:51322" resp=200
I0916 08:44:41.703432       1 httplog.go:132] "HTTP" verb="GET" URI="/healthz" latency="50.625µs" userAgent="kube-probe/1.27" audit-ID="" srcIP="10.44.0.0:51330" resp=200
I0916 08:44:51.701886       1 httplog.go:132] "HTTP" verb="GET" URI="/healthz" latency="106.68µs" userAgent="kube-probe/1.27" audit-ID="" srcIP="10.44.0.0:43378" resp=200
I0916 08:44:51.702980       1 httplog.go:132] "HTTP" verb="GET" URI="/healthz" latency="109.415µs" userAgent="kube-probe/1.27" audit-ID="" srcIP="10.44.0.0:43384" resp=200
I0916 08:45:01.702316       1 httplog.go:132] "HTTP" verb="GET" URI="/healthz" latency="101.72µs" userAgent="kube-probe/1.27" audit-ID="" srcIP="10.44.0.0:58710" resp=200
I0916 08:45:01.709683       1 httplog.go:132] "HTTP" verb="GET" URI="/healthz" latency="69.771µs" userAgent="kube-probe/1.27" audit-ID="" srcIP="10.44.0.0:58724" resp=200
I0916 08:45:11.702017       1 httplog.go:132] "HTTP" verb="GET" URI="/healthz" latency="102.582µs" userAgent="kube-probe/1.27" audit-ID="" srcIP="10.44.0.0:52660" resp=200
I0916 08:45:11.709770       1 httplog.go:132] "HTTP" verb="GET" URI="/healthz" latency="43.762µs" userAgent="kube-probe/1.27" audit-ID="" srcIP="10.44.0.0:52676" resp=200
I0916 08:45:21.706654       1 httplog.go:132] "HTTP" verb="GET" URI="/healthz" latency="108.864µs" userAgent="kube-probe/1.27" audit-ID="" srcIP="10.44.0.0:37966" resp=200
I0916 08:45:21.707832       1 httplog.go:132] "HTTP" verb="GET" URI="/healthz" latency="59.431µs" userAgent="kube-probe/1.27" audit-ID="" srcIP="10.44.0.0:37976" resp=200
I0916 08:45:31.702714       1 httplog.go:132] "HTTP" verb="GET" URI="/healthz" latency="141.265µs" userAgent="kube-probe/1.27" audit-ID="" srcIP="10.44.0.0:60284" resp=200
I0916 08:45:31.710701       1 httplog.go:132] "HTTP" verb="GET" URI="/healthz" latency="115.567µs" userAgent="kube-probe/1.27" audit-ID="" srcIP="10.44.0.0:60296" resp=200
I0916 08:45:41.702963       1 httplog.go:132] "HTTP" verb="GET" URI="/healthz" latency="100.398µs" userAgent="kube-probe/1.27" audit-ID="" srcIP="10.44.0.0:40712" resp=200
I0916 08:45:41.704086       1 httplog.go:132] "HTTP" verb="GET" URI="/healthz" latency="62.497µs" userAgent="kube-probe/1.27" audit-ID="" srcIP="10.44.0.0:40720" resp=200
I0916 08:45:51.707288       1 httplog.go:132] "HTTP" verb="GET" URI="/healthz" latency="114.955µs" userAgent="kube-probe/1.27" audit-ID="" srcIP="10.44.0.0:46582" resp=200
I0916 08:45:51.708435       1 httplog.go:132] "HTTP" verb="GET" URI="/healthz" latency="56.656µs" userAgent="kube-probe/1.27" audit-ID="" srcIP="10.44.0.0:46598" resp=200
I0916 08:46:01.706402       1 httplog.go:132] "HTTP" verb="GET" URI="/healthz" latency="98.274µs" userAgent="kube-probe/1.27" audit-ID="" srcIP="10.44.0.0:47542" resp=200
I0916 08:46:01.707665       1 httplog.go:132] "HTTP" verb="GET" URI="/healthz" latency="101.34µs" userAgent="kube-probe/1.27" audit-ID="" srcIP="10.44.0.0:47540" resp=200
I0916 08:46:11.707234       1 httplog.go:132] "HTTP" verb="GET" URI="/healthz" latency="93.776µs" userAgent="kube-probe/1.27" audit-ID="" srcIP="10.44.0.0:36582" resp=200
I0916 08:46:11.708238       1 httplog.go:132] "HTTP" verb="GET" URI="/healthz" latency="55.154µs" userAgent="kube-probe/1.27" audit-ID="" srcIP="10.44.0.0:36580" resp=200
I0916 08:46:21.702269       1 httplog.go:132] "HTTP" verb="GET" URI="/healthz" latency="108.624µs" userAgent="kube-probe/1.27" audit-ID="" srcIP="10.44.0.0:42374" resp=200
I0916 08:46:21.708057       1 httplog.go:132] "HTTP" verb="GET" URI="/healthz" latency="100.449µs" userAgent="kube-probe/1.27" audit-ID="" srcIP="10.44.0.0:42358" resp=200
I0916 08:46:31.703297       1 httplog.go:132] "HTTP" verb="GET" URI="/healthz" latency="100.638µs" userAgent="kube-probe/1.27" audit-ID="" srcIP="10.44.0.0:47134" resp=200
I0916 08:46:31.704525       1 httplog.go:132] "HTTP" verb="GET" URI="/healthz" latency="56.246µs" userAgent="kube-probe/1.27" audit-ID="" srcIP="10.44.0.0:47150" resp=200
I0916 08:46:41.702890       1 httplog.go:132] "HTTP" verb="GET" URI="/healthz" latency="96.811µs" userAgent="kube-probe/1.27" audit-ID="" srcIP="10.44.0.0:55522" resp=200
I0916 08:46:41.709010       1 httplog.go:132] "HTTP" verb="GET" URI="/healthz" latency="110.097µs" userAgent="kube-probe/1.27" audit-ID="" srcIP="10.44.0.0:55534" resp=200
I0916 08:46:51.705844       1 httplog.go:132] "HTTP" verb="GET" URI="/healthz" latency="121.067µs" userAgent="kube-probe/1.27" audit-ID="" srcIP="10.44.0.0:55918" resp=200
I0916 08:46:51.707089       1 httplog.go:132] "HTTP" verb="GET" URI="/healthz" latency="98.154µs" userAgent="kube-probe/1.27" audit-ID="" srcIP="10.44.0.0:55934" resp=200
I0916 08:47:01.707374       1 httplog.go:132] "HTTP" verb="GET" URI="/healthz" latency="102.031µs" userAgent="kube-probe/1.27" audit-ID="" srcIP="10.44.0.0:42076" resp=200
I0916 08:47:01.708454       1 httplog.go:132] "HTTP" verb="GET" URI="/healthz" latency="27.833µs" userAgent="kube-probe/1.27" audit-ID="" srcIP="10.44.0.0:42060" resp=200
I0916 08:47:11.707545       1 httplog.go:132] "HTTP" verb="GET" URI="/healthz" latency="107.101µs" userAgent="kube-probe/1.27" audit-ID="" srcIP="10.44.0.0:54532" resp=200
I0916 08:47:11.708875       1 httplog.go:132] "HTTP" verb="GET" URI="/healthz" latency="105.297µs" userAgent="kube-probe/1.27" audit-ID="" srcIP="10.44.0.0:54542" resp=200
I0916 08:47:21.707165       1 httplog.go:132] "HTTP" verb="GET" URI="/healthz" latency="81.363µs" userAgent="kube-probe/1.27" audit-ID="" srcIP="10.44.0.0:55230" resp=200
I0916 08:47:21.708002       1 httplog.go:132] "HTTP" verb="GET" URI="/healthz" latency="29.626µs" userAgent="kube-probe/1.27" audit-ID="" srcIP="10.44.0.0:55232" resp=200
I0916 08:47:31.702115       1 httplog.go:132] "HTTP" verb="GET" URI="/healthz" latency="126.738µs" userAgent="kube-probe/1.27" audit-ID="" srcIP="10.44.0.0:57260" resp=200
I0916 08:47:31.702221       1 httplog.go:132] "HTTP" verb="GET" URI="/healthz" latency="106.068µs" userAgent="kube-probe/1.27" audit-ID="" srcIP="10.44.0.0:57270" resp=200
I0916 08:47:41.702684       1 httplog.go:132] "HTTP" verb="GET" URI="/healthz" latency="103.544µs" userAgent="kube-probe/1.27" audit-ID="" srcIP="10.44.0.0:59140" resp=200
I0916 08:47:41.703789       1 httplog.go:132] "HTTP" verb="GET" URI="/healthz" latency="110.517µs" userAgent="kube-probe/1.27" audit-ID="" srcIP="10.44.0.0:59148" resp=200
I0916 08:47:51.706436       1 httplog.go:132] "HTTP" verb="GET" URI="/healthz" latency="131.808µs" userAgent="kube-probe/1.27" audit-ID="" srcIP="10.44.0.0:42896" resp=200
I0916 08:47:51.707556       1 httplog.go:132] "HTTP" verb="GET" URI="/healthz" latency="71.193µs" userAgent="kube-probe/1.27" audit-ID="" srcIP="10.44.0.0:42890" resp=200
I0916 08:48:01.706458       1 httplog.go:132] "HTTP" verb="GET" URI="/healthz" latency="104.967µs" userAgent="kube-probe/1.27" audit-ID="" srcIP="10.44.0.0:55292" resp=200
I0916 08:48:01.707712       1 httplog.go:132] "HTTP" verb="GET" URI="/healthz" latency="75.201µs" userAgent="kube-probe/1.27" audit-ID="" srcIP="10.44.0.0:55296" resp=200
I0916 08:48:11.706627       1 httplog.go:132] "HTTP" verb="GET" URI="/healthz" latency="95.819µs" userAgent="kube-probe/1.27" audit-ID="" srcIP="10.44.0.0:36694" resp=200
I0916 08:48:11.707819       1 httplog.go:132] "HTTP" verb="GET" URI="/healthz" latency="77.395µs" userAgent="kube-probe/1.27" audit-ID="" srcIP="10.44.0.0:36708" resp=200
I0916 08:48:21.707305       1 httplog.go:132] "HTTP" verb="GET" URI="/healthz" latency="130.826µs" userAgent="kube-probe/1.27" audit-ID="" srcIP="10.44.0.0:51898" resp=200
I0916 08:48:21.708369       1 httplog.go:132] "HTTP" verb="GET" URI="/healthz" latency="62.707µs" userAgent="kube-probe/1.27" audit-ID="" srcIP="10.44.0.0:51914" resp=200
I0916 08:48:25.751923       1 schedule_one.go:80] "Attempting to schedule pod" pod="default/falcon-pod-534716"
I0916 08:48:25.752591       1 log.go:194] require 4 gpu(s), and currently has 0 gpus(s) in total
I0916 08:48:25.967933       1 trace.go:219] Trace[1055942282]: "Scheduling" namespace:default,name:falcon-pod-534716 (16-Sep-2023 08:48:25.751) (total time: 215ms):
Trace[1055942282]: ---"Computing predicates done" 215ms (08:48:25.967)
Trace[1055942282]: [215.935545ms] [215.935545ms] END
I0916 08:48:25.968162       1 schedule_one.go:867] "Unable to schedule pod; no fit; waiting" pod="default/falcon-pod-534716" err="0/2 nodes are available: Require 4 gpu but only 0 gpu in the pool.. preemption: 0/2 nodes are available: 2 No preemption victims found for incoming pod.."
I0916 08:48:25.968296       1 schedule_one.go:943] "Updating pod condition" pod="default/falcon-pod-534716" conditionType=PodScheduled conditionStatus=False conditionReason="Unschedulable"
I0916 08:48:31.707626       1 httplog.go:132] "HTTP" verb="GET" URI="/healthz" latency="111.85µs" userAgent="kube-probe/1.27" audit-ID="" srcIP="10.44.0.0:42204" resp=200
I0916 08:48:31.708833       1 httplog.go:132] "HTTP" verb="GET" URI="/healthz" latency="114.605µs" userAgent="kube-probe/1.27" audit-ID="" srcIP="10.44.0.0:42220" resp=200
I0916 08:48:41.706837       1 httplog.go:132] "HTTP" verb="GET" URI="/healthz" latency="132.378µs" userAgent="kube-probe/1.27" audit-ID="" srcIP="10.44.0.0:47796" resp=200
I0916 08:48:41.707915       1 httplog.go:132] "HTTP" verb="GET" URI="/healthz" latency="66.845µs" userAgent="kube-probe/1.27" audit-ID="" srcIP="10.44.0.0:47800" resp=200
I0916 08:48:51.702593       1 httplog.go:132] "HTTP" verb="GET" URI="/healthz" latency="123.582µs" userAgent="kube-probe/1.27" audit-ID="" srcIP="10.44.0.0:42716" resp=200
I0916 08:48:51.703635       1 httplog.go:132] "HTTP" verb="GET" URI="/healthz" latency="59.231µs" userAgent="kube-probe/1.27" audit-ID="" srcIP="10.44.0.0:42732" resp=200
I0916 08:49:01.707558       1 httplog.go:132] "HTTP" verb="GET" URI="/healthz" latency="122.97µs" userAgent="kube-probe/1.27" audit-ID="" srcIP="10.44.0.0:43380" resp=200
I0916 08:49:01.708702       1 httplog.go:132] "HTTP" verb="GET" URI="/healthz" latency="86.993µs" userAgent="kube-probe/1.27" audit-ID="" srcIP="10.44.0.0:43378" resp=200
I0916 08:49:11.701590       1 httplog.go:132] "HTTP" verb="GET" URI="/healthz" latency="101.761µs" userAgent="kube-probe/1.27" audit-ID="" srcIP="10.44.0.0:54234" resp=200
I0916 08:49:11.701757       1 httplog.go:132] "HTTP" verb="GET" URI="/healthz" latency="77.636µs" userAgent="kube-probe/1.27" audit-ID="" srcIP="10.44.0.0:54218" resp=200
I0916 08:49:21.702344       1 httplog.go:132] "HTTP" verb="GET" URI="/healthz" latency="146.985µs" userAgent="kube-probe/1.27" audit-ID="" srcIP="10.44.0.0:48522" resp=200
I0916 08:49:21.710034       1 httplog.go:132] "HTTP" verb="GET" URI="/healthz" latency="38.162µs" userAgent="kube-probe/1.27" audit-ID="" srcIP="10.44.0.0:48536" resp=200
I0916 08:49:31.707376       1 httplog.go:132] "HTTP" verb="GET" URI="/healthz" latency="116.749µs" userAgent="kube-probe/1.27" audit-ID="" srcIP="10.44.0.0:45784" resp=200
I0916 08:49:31.708600       1 httplog.go:132] "HTTP" verb="GET" URI="/healthz" latency="89.287µs" userAgent="kube-probe/1.27" audit-ID="" srcIP="10.44.0.0:45794" resp=200
I0916 08:49:41.706248       1 httplog.go:132] "HTTP" verb="GET" URI="/healthz" latency="96.551µs" userAgent="kube-probe/1.27" audit-ID="" srcIP="10.44.0.0:52554" resp=200
I0916 08:49:41.707294       1 httplog.go:132] "HTTP" verb="GET" URI="/healthz" latency="95.038µs" userAgent="kube-probe/1.27" audit-ID="" srcIP="10.44.0.0:52556" resp=200
I0916 08:49:51.702476       1 httplog.go:132] "HTTP" verb="GET" URI="/healthz" latency="95.809µs" userAgent="kube-probe/1.27" audit-ID="" srcIP="10.44.0.0:57666" resp=200
I0916 08:49:51.703414       1 httplog.go:132] "HTTP" verb="GET" URI="/healthz" latency="39.715µs" userAgent="kube-probe/1.27" audit-ID="" srcIP="10.44.0.0:57664" resp=200
I0916 08:50:01.706850       1 httplog.go:132] "HTTP" verb="GET" URI="/healthz" latency="100.589µs" userAgent="kube-probe/1.27" audit-ID="" srcIP="10.44.0.0:39444" resp=200
I0916 08:50:01.707869       1 httplog.go:132] "HTTP" verb="GET" URI="/healthz" latency="31.219µs" userAgent="kube-probe/1.27" audit-ID="" srcIP="10.44.0.0:39440" resp=200
I0916 08:50:11.702808       1 httplog.go:132] "HTTP" verb="GET" URI="/healthz" latency="95.609µs" userAgent="kube-probe/1.27" audit-ID="" srcIP="10.44.0.0:51864" resp=200
I0916 08:50:11.703924       1 httplog.go:132] "HTTP" verb="GET" URI="/healthz" latency="41.017µs" userAgent="kube-probe/1.27" audit-ID="" srcIP="10.44.0.0:51866" resp=200
I0916 08:50:21.705988       1 httplog.go:132] "HTTP" verb="GET" URI="/healthz" latency="123.912µs" userAgent="kube-probe/1.27" audit-ID="" srcIP="10.44.0.0:58514" resp=200
I0916 08:50:21.706857       1 httplog.go:132] "HTTP" verb="GET" URI="/healthz" latency="56.055µs" userAgent="kube-probe/1.27" audit-ID="" srcIP="10.44.0.0:58512" resp=200
I0916 08:50:31.701167       1 httplog.go:132] "HTTP" verb="GET" URI="/healthz" latency="77.576µs" userAgent="kube-probe/1.27" audit-ID="" srcIP="10.44.0.0:38116" resp=200
I0916 08:50:31.702451       1 httplog.go:132] "HTTP" verb="GET" URI="/healthz" latency="131.276µs" userAgent="kube-probe/1.27" audit-ID="" srcIP="10.44.0.0:38104" resp=200
I0916 08:50:41.707497       1 httplog.go:132] "HTTP" verb="GET" URI="/healthz" latency="100.328µs" userAgent="kube-probe/1.27" audit-ID="" srcIP="10.44.0.0:55394" resp=200
I0916 08:50:41.708435       1 httplog.go:132] "HTTP" verb="GET" URI="/healthz" latency="77.906µs" userAgent="kube-probe/1.27" audit-ID="" srcIP="10.44.0.0:55396" resp=200
I0916 08:50:51.702177       1 httplog.go:132] "HTTP" verb="GET" URI="/healthz" latency="94.196µs" userAgent="kube-probe/1.27" audit-ID="" srcIP="10.44.0.0:41320" resp=200
I0916 08:50:51.703309       1 httplog.go:132] "HTTP" verb="GET" URI="/healthz" latency="44.253µs" userAgent="kube-probe/1.27" audit-ID="" srcIP="10.44.0.0:41318" resp=200
I0916 08:51:01.702506       1 httplog.go:132] "HTTP" verb="GET" URI="/healthz" latency="125.145µs" userAgent="kube-probe/1.27" audit-ID="" srcIP="10.44.0.0:57572" resp=200
I0916 08:51:01.703688       1 httplog.go:132] "HTTP" verb="GET" URI="/healthz" latency="113.693µs" userAgent="kube-probe/1.27" audit-ID="" srcIP="10.44.0.0:57570" resp=200
I0916 08:51:11.706922       1 httplog.go:132] "HTTP" verb="GET" URI="/healthz" latency="95.79µs" userAgent="kube-probe/1.27" audit-ID="" srcIP="10.44.0.0:58098" resp=200
I0916 08:51:11.707994       1 httplog.go:132] "HTTP" verb="GET" URI="/healthz" latency="98.484µs" userAgent="kube-probe/1.27" audit-ID="" srcIP="10.44.0.0:58094" resp=200
I0916 08:51:21.702421       1 httplog.go:132] "HTTP" verb="GET" URI="/healthz" latency="94.297µs" userAgent="kube-probe/1.27" audit-ID="" srcIP="10.44.0.0:47060" resp=200
I0916 08:51:21.709769       1 httplog.go:132] "HTTP" verb="GET" URI="/healthz" latency="143.048µs" userAgent="kube-probe/1.27" audit-ID="" srcIP="10.44.0.0:47070" resp=200
I0916 08:51:31.701854       1 httplog.go:132] "HTTP" verb="GET" URI="/healthz" latency="93.265µs" userAgent="kube-probe/1.27" audit-ID="" srcIP="10.44.0.0:59266" resp=200
I0916 08:51:31.703092       1 httplog.go:132] "HTTP" verb="GET" URI="/healthz" latency="105.587µs" userAgent="kube-probe/1.27" audit-ID="" srcIP="10.44.0.0:59264" resp=200
I0916 08:51:41.707418       1 httplog.go:132] "HTTP" verb="GET" URI="/healthz" latency="125.355µs" userAgent="kube-probe/1.27" audit-ID="" srcIP="10.44.0.0:38928" resp=200
I0916 08:51:41.708471       1 httplog.go:132] "HTTP" verb="GET" URI="/healthz" latency="126.247µs" userAgent="kube-probe/1.27" audit-ID="" srcIP="10.44.0.0:38920" resp=200
I0916 08:51:51.702065       1 httplog.go:132] "HTTP" verb="GET" URI="/healthz" latency="110.627µs" userAgent="kube-probe/1.27" audit-ID="" srcIP="10.44.0.0:45466" resp=200
I0916 08:51:51.703115       1 httplog.go:132] "HTTP" verb="GET" URI="/healthz" latency="59.341µs" userAgent="kube-probe/1.27" audit-ID="" srcIP="10.44.0.0:45482" resp=200
I0916 08:52:01.707288       1 httplog.go:132] "HTTP" verb="GET" URI="/healthz" latency="78.838µs" userAgent="kube-probe/1.27" audit-ID="" srcIP="10.44.0.0:49206" resp=200
I0916 08:52:01.708328       1 httplog.go:132] "HTTP" verb="GET" URI="/healthz" latency="53µs" userAgent="kube-probe/1.27" audit-ID="" srcIP="10.44.0.0:49190" resp=200
I0916 08:52:11.706679       1 httplog.go:132] "HTTP" verb="GET" URI="/healthz" latency="109.786µs" userAgent="kube-probe/1.27" audit-ID="" srcIP="10.44.0.0:34272" resp=200
I0916 08:52:11.707909       1 httplog.go:132] "HTTP" verb="GET" URI="/healthz" latency="117.159µs" userAgent="kube-probe/1.27" audit-ID="" srcIP="10.44.0.0:34278" resp=200
I0916 08:52:21.702524       1 httplog.go:132] "HTTP" verb="GET" URI="/healthz" latency="103.994µs" userAgent="kube-probe/1.27" audit-ID="" srcIP="10.44.0.0:35898" resp=200
I0916 08:52:21.702680       1 httplog.go:132] "HTTP" verb="GET" URI="/healthz" latency="86.111µs" userAgent="kube-probe/1.27" audit-ID="" srcIP="10.44.0.0:35896" resp=200
I0916 08:52:31.707193       1 httplog.go:132] "HTTP" verb="GET" URI="/healthz" latency="121.798µs" userAgent="kube-probe/1.27" audit-ID="" srcIP="10.44.0.0:42152" resp=200
I0916 08:52:31.708340       1 httplog.go:132] "HTTP" verb="GET" URI="/healthz" latency="100.058µs" userAgent="kube-probe/1.27" audit-ID="" srcIP="10.44.0.0:42168" resp=200
I0916 08:52:41.707116       1 httplog.go:132] "HTTP" verb="GET" URI="/healthz" latency="105.477µs" userAgent="kube-probe/1.27" audit-ID="" srcIP="10.44.0.0:40464" resp=200
I0916 08:52:41.708112       1 httplog.go:132] "HTTP" verb="GET" URI="/healthz" latency="46.337µs" userAgent="kube-probe/1.27" audit-ID="" srcIP="10.44.0.0:40466" resp=200
I0916 08:52:51.706873       1 httplog.go:132] "HTTP" verb="GET" URI="/healthz" latency="88.836µs" userAgent="kube-probe/1.27" audit-ID="" srcIP="10.44.0.0:33656" resp=200
I0916 08:52:51.707935       1 httplog.go:132] "HTTP" verb="GET" URI="/healthz" latency="46.217µs" userAgent="kube-probe/1.27" audit-ID="" srcIP="10.44.0.0:33652" resp=200
I0916 08:53:01.702585       1 httplog.go:132] "HTTP" verb="GET" URI="/healthz" latency="124.062µs" userAgent="kube-probe/1.27" audit-ID="" srcIP="10.44.0.0:37696" resp=200
I0916 08:53:01.709948       1 httplog.go:132] "HTTP" verb="GET" URI="/healthz" latency="24.606µs" userAgent="kube-probe/1.27" audit-ID="" srcIP="10.44.0.0:37720" resp=200
I0916 08:53:11.698979       1 httplog.go:132] "HTTP" verb="GET" URI="/healthz" latency="150.422µs" userAgent="kube-probe/1.27" audit-ID="" srcIP="10.44.0.0:36694" resp=200
I0916 08:53:11.702156       1 httplog.go:132] "HTTP" verb="GET" URI="/healthz" latency="110.958µs" userAgent="kube-probe/1.27" audit-ID="" srcIP="10.44.0.0:36698" resp=200
I0916 08:53:21.707027       1 httplog.go:132] "HTTP" verb="GET" URI="/healthz" latency="159.289µs" userAgent="kube-probe/1.27" audit-ID="" srcIP="10.44.0.0:51974" resp=200
I0916 08:53:21.708136       1 httplog.go:132] "HTTP" verb="GET" URI="/healthz" latency="66.274µs" userAgent="kube-probe/1.27" audit-ID="" srcIP="10.44.0.0:51968" resp=200
I0916 08:53:31.701984       1 httplog.go:132] "HTTP" verb="GET" URI="/healthz" latency="103.734µs" userAgent="kube-probe/1.27" audit-ID="" srcIP="10.44.0.0:33524" resp=200
I0916 08:53:31.703162       1 httplog.go:132] "HTTP" verb="GET" URI="/healthz" latency="122.26µs" userAgent="kube-probe/1.27" audit-ID="" srcIP="10.44.0.0:33514" resp=200
I0916 08:53:41.707172       1 httplog.go:132] "HTTP" verb="GET" URI="/healthz" latency="131.006µs" userAgent="kube-probe/1.27" audit-ID="" srcIP="10.44.0.0:41308" resp=200
I0916 08:53:41.708482       1 httplog.go:132] "HTTP" verb="GET" URI="/healthz" latency="85.81µs" userAgent="kube-probe/1.27" audit-ID="" srcIP="10.44.0.0:41292" resp=200
I0916 08:53:51.701765       1 httplog.go:132] "HTTP" verb="GET" URI="/healthz" latency="115.997µs" userAgent="kube-probe/1.27" audit-ID="" srcIP="10.44.0.0:54544" resp=200
I0916 08:53:51.703227       1 httplog.go:132] "HTTP" verb="GET" URI="/healthz" latency="96.591µs" userAgent="kube-probe/1.27" audit-ID="" srcIP="10.44.0.0:54546" resp=200
I0916 08:53:55.759337       1 schedule_one.go:80] "Attempting to schedule pod" pod="default/falcon-pod-534716"
I0916 08:53:55.759943       1 log.go:194] require 4 gpu(s), and currently has 0 gpus(s) in total
I0916 08:53:55.767155       1 schedule_one.go:867] "Unable to schedule pod; no fit; waiting" pod="default/falcon-pod-534716" err="0/2 nodes are available: Require 4 gpu but only 0 gpu in the pool.. preemption: 0/2 nodes are available: 2 No preemption victims found for incoming pod.."
I0916 08:53:55.767258       1 schedule_one.go:943] "Updating pod condition" pod="default/falcon-pod-534716" conditionType=PodScheduled conditionStatus=False conditionReason="Unschedulable"
I0916 08:54:01.706401       1 httplog.go:132] "HTTP" verb="GET" URI="/healthz" latency="106.82µs" userAgent="kube-probe/1.27" audit-ID="" srcIP="10.44.0.0:45150" resp=200
I0916 08:54:01.707553       1 httplog.go:132] "HTTP" verb="GET" URI="/healthz" latency="156.263µs" userAgent="kube-probe/1.27" audit-ID="" srcIP="10.44.0.0:45148" resp=200
I0916 08:54:11.706486       1 httplog.go:132] "HTTP" verb="GET" URI="/healthz" latency="92.594µs" userAgent="kube-probe/1.27" audit-ID="" srcIP="10.44.0.0:58390" resp=200
I0916 08:54:11.707682       1 httplog.go:132] "HTTP" verb="GET" URI="/healthz" latency="96.29µs" userAgent="kube-probe/1.27" audit-ID="" srcIP="10.44.0.0:58394" resp=200
I0916 08:54:21.706433       1 httplog.go:132] "HTTP" verb="GET" URI="/healthz" latency="95.66µs" userAgent="kube-probe/1.27" audit-ID="" srcIP="10.44.0.0:39950" resp=200
I0916 08:54:21.713686       1 httplog.go:132] "HTTP" verb="GET" URI="/healthz" latency="152.726µs" userAgent="kube-probe/1.27" audit-ID="" srcIP="10.44.0.0:39952" resp=200
I0916 08:54:31.702253       1 httplog.go:132] "HTTP" verb="GET" URI="/healthz" latency="110.167µs" userAgent="kube-probe/1.27" audit-ID="" srcIP="10.44.0.0:54246" resp=200
I0916 08:54:31.703308       1 httplog.go:132] "HTTP" verb="GET" URI="/healthz" latency="52.468µs" userAgent="kube-probe/1.27" audit-ID="" srcIP="10.44.0.0:54232" resp=200
I0916 08:54:41.702610       1 httplog.go:132] "HTTP" verb="GET" URI="/healthz" latency="149.32µs" userAgent="kube-probe/1.27" audit-ID="" srcIP="10.44.0.0:40300" resp=200
I0916 08:54:41.702613       1 httplog.go:132] "HTTP" verb="GET" URI="/healthz" latency="178.254µs" userAgent="kube-probe/1.27" audit-ID="" srcIP="10.44.0.0:40290" resp=200
I0916 08:54:51.702627       1 httplog.go:132] "HTTP" verb="GET" URI="/healthz" latency="149.31µs" userAgent="kube-probe/1.27" audit-ID="" srcIP="10.44.0.0:55334" resp=200
I0916 08:54:51.710332       1 httplog.go:132] "HTTP" verb="GET" URI="/healthz" latency="91.17µs" userAgent="kube-probe/1.27" audit-ID="" srcIP="10.44.0.0:55344" resp=200
I0916 08:55:01.707624       1 httplog.go:132] "HTTP" verb="GET" URI="/healthz" latency="161.142µs" userAgent="kube-probe/1.27" audit-ID="" srcIP="10.44.0.0:32852" resp=200
I0916 08:55:01.708599       1 httplog.go:132] "HTTP" verb="GET" URI="/healthz" latency="83.346µs" userAgent="kube-probe/1.27" audit-ID="" srcIP="10.44.0.0:32840" resp=200
I0916 08:55:11.707330       1 httplog.go:132] "HTTP" verb="GET" URI="/healthz" latency="157.705µs" userAgent="kube-probe/1.27" audit-ID="" srcIP="10.44.0.0:34658" resp=200
I0916 08:55:11.708661       1 httplog.go:132] "HTTP" verb="GET" URI="/healthz" latency="123.701µs" userAgent="kube-probe/1.27" audit-ID="" srcIP="10.44.0.0:34670" resp=200
I0916 08:55:21.706592       1 httplog.go:132] "HTTP" verb="GET" URI="/healthz" latency="161.283µs" userAgent="kube-probe/1.27" audit-ID="" srcIP="10.44.0.0:55346" resp=200
I0916 08:55:21.707621       1 httplog.go:132] "HTTP" verb="GET" URI="/healthz" latency="112.711µs" userAgent="kube-probe/1.27" audit-ID="" srcIP="10.44.0.0:55362" resp=200
I0916 08:55:31.706804       1 httplog.go:132] "HTTP" verb="GET" URI="/healthz" latency="156.954µs" userAgent="kube-probe/1.27" audit-ID="" srcIP="10.44.0.0:47724" resp=200
I0916 08:55:31.708018       1 httplog.go:132] "HTTP" verb="GET" URI="/healthz" latency="140.403µs" userAgent="kube-probe/1.27" audit-ID="" srcIP="10.44.0.0:47718" resp=200
I0916 08:55:41.707079       1 httplog.go:132] "HTTP" verb="GET" URI="/healthz" latency="137.197µs" userAgent="kube-probe/1.27" audit-ID="" srcIP="10.44.0.0:44592" resp=200
I0916 08:55:41.708178       1 httplog.go:132] "HTTP" verb="GET" URI="/healthz" latency="60.073µs" userAgent="kube-probe/1.27" audit-ID="" srcIP="10.44.0.0:44596" resp=200
I0916 08:55:51.702062       1 httplog.go:132] "HTTP" verb="GET" URI="/healthz" latency="95.91µs" userAgent="kube-probe/1.27" audit-ID="" srcIP="10.44.0.0:54132" resp=200
I0916 08:55:51.702703       1 httplog.go:132] "HTTP" verb="GET" URI="/healthz" latency="111.73µs" userAgent="kube-probe/1.27" audit-ID="" srcIP="10.44.0.0:54140" resp=200
I0916 08:56:01.702177       1 httplog.go:132] "HTTP" verb="GET" URI="/healthz" latency="143.569µs" userAgent="kube-probe/1.27" audit-ID="" srcIP="10.44.0.0:35302" resp=200
I0916 08:56:01.703190       1 httplog.go:132] "HTTP" verb="GET" URI="/healthz" latency="100.338µs" userAgent="kube-probe/1.27" audit-ID="" srcIP="10.44.0.0:35314" resp=200
I0916 08:56:11.706824       1 httplog.go:132] "HTTP" verb="GET" URI="/healthz" latency="125.525µs" userAgent="kube-probe/1.27" audit-ID="" srcIP="10.44.0.0:59462" resp=200
I0916 08:56:11.707956       1 httplog.go:132] "HTTP" verb="GET" URI="/healthz" latency="115.577µs" userAgent="kube-probe/1.27" audit-ID="" srcIP="10.44.0.0:59472" resp=200
I0916 08:56:21.702303       1 httplog.go:132] "HTTP" verb="GET" URI="/healthz" latency="117.71µs" userAgent="kube-probe/1.27" audit-ID="" srcIP="10.44.0.0:60124" resp=200
I0916 08:56:21.703682       1 httplog.go:132] "HTTP" verb="GET" URI="/healthz" latency="127.188µs" userAgent="kube-probe/1.27" audit-ID="" srcIP="10.44.0.0:60130" resp=200
I0916 08:56:31.707241       1 httplog.go:132] "HTTP" verb="GET" URI="/healthz" latency="107.231µs" userAgent="kube-probe/1.27" audit-ID="" srcIP="10.44.0.0:39696" resp=200
I0916 08:56:31.708410       1 httplog.go:132] "HTTP" verb="GET" URI="/healthz" latency="84.559µs" userAgent="kube-probe/1.27" audit-ID="" srcIP="10.44.0.0:39688" resp=200
I0916 08:56:41.701785       1 httplog.go:132] "HTTP" verb="GET" URI="/healthz" latency="87.604µs" userAgent="kube-probe/1.27" audit-ID="" srcIP="10.44.0.0:39048" resp=200
I0916 08:56:41.703064       1 httplog.go:132] "HTTP" verb="GET" URI="/healthz" latency="89.188µs" userAgent="kube-probe/1.27" audit-ID="" srcIP="10.44.0.0:39040" resp=200
I0916 08:56:51.706414       1 httplog.go:132] "HTTP" verb="GET" URI="/healthz" latency="111.229µs" userAgent="kube-probe/1.27" audit-ID="" srcIP="10.44.0.0:46602" resp=200
I0916 08:56:51.707549       1 httplog.go:132] "HTTP" verb="GET" URI="/healthz" latency="57.718µs" userAgent="kube-probe/1.27" audit-ID="" srcIP="10.44.0.0:46588" resp=200
I0916 08:57:01.702585       1 httplog.go:132] "HTTP" verb="GET" URI="/healthz" latency="123.972µs" userAgent="kube-probe/1.27" audit-ID="" srcIP="10.44.0.0:56660" resp=200
I0916 08:57:01.703699       1 httplog.go:132] "HTTP" verb="GET" URI="/healthz" latency="72.626µs" userAgent="kube-probe/1.27" audit-ID="" srcIP="10.44.0.0:56674" resp=200
I0916 08:57:11.700502       1 httplog.go:132] "HTTP" verb="GET" URI="/healthz" latency="90.991µs" userAgent="kube-probe/1.27" audit-ID="" srcIP="10.44.0.0:49132" resp=200
I0916 08:57:11.701978       1 httplog.go:132] "HTTP" verb="GET" URI="/healthz" latency="116.899µs" userAgent="kube-probe/1.27" audit-ID="" srcIP="10.44.0.0:49116" resp=200
I0916 08:57:21.707306       1 httplog.go:132] "HTTP" verb="GET" URI="/healthz" latency="104.656µs" userAgent="kube-probe/1.27" audit-ID="" srcIP="10.44.0.0:38662" resp=200
I0916 08:57:21.708422       1 httplog.go:132] "HTTP" verb="GET" URI="/healthz" latency="72.726µs" userAgent="kube-probe/1.27" audit-ID="" srcIP="10.44.0.0:38676" resp=200
I0916 08:57:29.162859       1 eventhandlers.go:231] "Delete event for scheduled pod" pod="default/falcon-pod-593250"
I0916 08:57:29.163036       1 schedule_one.go:80] "Attempting to schedule pod" pod="default/falcon-pod-534716"
I0916 08:57:29.163569       1 log.go:194] require 4 gpu(s), and currently has 4 gpus(s) in total
I0916 08:57:29.171455       1 log.go:194] css-host-128 has 4 gpu, the pod requires 4 gpu -> score: 1
I0916 08:57:29.171486       1 log.go:194] css-host-129 has 0 gpu, the pod requires 4 gpu -> score: -4
I0916 08:57:29.171750       1 log.go:194] permit plugin
I0916 08:57:29.176500       1 log.go:194] alloc: 4, used: 0, required: 4
I0916 08:57:29.180630       1 log.go:194] alloc: 4, used: 0, required: 4
I0916 08:57:29.180788       1 default_binder.go:53] "Attempting to bind pod to node" pod="default/falcon-pod-534716" node="css-host-128"
I0916 08:57:29.185836       1 eventhandlers.go:161] "Delete event for unscheduled pod" pod="default/falcon-pod-534716"
I0916 08:57:29.185870       1 eventhandlers.go:186] "Add event for scheduled pod" pod="default/falcon-pod-534716"
I0916 08:57:29.185971       1 schedule_one.go:252] "Successfully bound pod to node" pod="default/falcon-pod-534716" node="css-host-128" evaluatedNodes=2 feasibleNodes=2
I0916 08:57:31.707655       1 httplog.go:132] "HTTP" verb="GET" URI="/healthz" latency="104.786µs" userAgent="kube-probe/1.27" audit-ID="" srcIP="10.44.0.0:60918" resp=200
I0916 08:57:31.708691       1 httplog.go:132] "HTTP" verb="GET" URI="/healthz" latency="43.662µs" userAgent="kube-probe/1.27" audit-ID="" srcIP="10.44.0.0:60912" resp=200
I0916 08:57:41.702921       1 httplog.go:132] "HTTP" verb="GET" URI="/healthz" latency="140.824µs" userAgent="kube-probe/1.27" audit-ID="" srcIP="10.44.0.0:35502" resp=200
I0916 08:57:41.704081       1 httplog.go:132] "HTTP" verb="GET" URI="/healthz" latency="71.605µs" userAgent="kube-probe/1.27" audit-ID="" srcIP="10.44.0.0:35510" resp=200
I0916 08:57:51.702875       1 httplog.go:132] "HTTP" verb="GET" URI="/healthz" latency="99.747µs" userAgent="kube-probe/1.27" audit-ID="" srcIP="10.44.0.0:56194" resp=200
I0916 08:57:51.709150       1 httplog.go:132] "HTTP" verb="GET" URI="/healthz" latency="105.748µs" userAgent="kube-probe/1.27" audit-ID="" srcIP="10.44.0.0:56204" resp=200
I0916 08:58:01.699582       1 httplog.go:132] "HTTP" verb="GET" URI="/healthz" latency="59.852µs" userAgent="kube-probe/1.27" audit-ID="" srcIP="10.44.0.0:52644" resp=200
I0916 08:58:01.702348       1 httplog.go:132] "HTTP" verb="GET" URI="/healthz" latency="57.448µs" userAgent="kube-probe/1.27" audit-ID="" srcIP="10.44.0.0:52636" resp=200
I0916 08:58:11.700164       1 httplog.go:132] "HTTP" verb="GET" URI="/healthz" latency="79.389µs" userAgent="kube-probe/1.27" audit-ID="" srcIP="10.44.0.0:41268" resp=200
I0916 08:58:11.701163       1 httplog.go:132] "HTTP" verb="GET" URI="/healthz" latency="33.022µs" userAgent="kube-probe/1.27" audit-ID="" srcIP="10.44.0.0:41256" resp=200
I0916 08:58:21.700942       1 httplog.go:132] "HTTP" verb="GET" URI="/healthz" latency="77.996µs" userAgent="kube-probe/1.27" audit-ID="" srcIP="10.44.0.0:34558" resp=200
I0916 08:58:21.702079       1 httplog.go:132] "HTTP" verb="GET" URI="/healthz" latency="41.227µs" userAgent="kube-probe/1.27" audit-ID="" srcIP="10.44.0.0:34560" resp=200
I0916 08:58:31.702673       1 httplog.go:132] "HTTP" verb="GET" URI="/healthz" latency="110.006µs" userAgent="kube-probe/1.27" audit-ID="" srcIP="10.44.0.0:49534" resp=200
I0916 08:58:31.710208       1 httplog.go:132] "HTTP" verb="GET" URI="/healthz" latency="43.341µs" userAgent="kube-probe/1.27" audit-ID="" srcIP="10.44.0.0:49546" resp=200
I0916 08:58:41.702049       1 httplog.go:132] "HTTP" verb="GET" URI="/healthz" latency="117.861µs" userAgent="kube-probe/1.27" audit-ID="" srcIP="10.44.0.0:50612" resp=200
I0916 08:58:41.703183       1 httplog.go:132] "HTTP" verb="GET" URI="/healthz" latency="82.785µs" userAgent="kube-probe/1.27" audit-ID="" srcIP="10.44.0.0:50600" resp=200
I0916 08:58:51.702309       1 httplog.go:132] "HTTP" verb="GET" URI="/healthz" latency="103.645µs" userAgent="kube-probe/1.27" audit-ID="" srcIP="10.44.0.0:42494" resp=200
I0916 08:58:51.702678       1 httplog.go:132] "HTTP" verb="GET" URI="/healthz" latency="52.488µs" userAgent="kube-probe/1.27" audit-ID="" srcIP="10.44.0.0:42484" resp=200
I0916 08:59:01.707531       1 httplog.go:132] "HTTP" verb="GET" URI="/healthz" latency="142.387µs" userAgent="kube-probe/1.27" audit-ID="" srcIP="10.44.0.0:55132" resp=200
I0916 08:59:01.708769       1 httplog.go:132] "HTTP" verb="GET" URI="/healthz" latency="63.379µs" userAgent="kube-probe/1.27" audit-ID="" srcIP="10.44.0.0:55130" resp=200
I0916 08:59:11.701601       1 httplog.go:132] "HTTP" verb="GET" URI="/healthz" latency="88.395µs" userAgent="kube-probe/1.27" audit-ID="" srcIP="10.44.0.0:48096" resp=200
I0916 08:59:11.704296       1 httplog.go:132] "HTTP" verb="GET" URI="/healthz" latency="32.652µs" userAgent="kube-probe/1.27" audit-ID="" srcIP="10.44.0.0:48086" resp=200
I0916 08:59:21.704039       1 httplog.go:132] "HTTP" verb="GET" URI="/healthz" latency="99.367µs" userAgent="kube-probe/1.27" audit-ID="" srcIP="10.44.0.0:57596" resp=200
I0916 08:59:21.705224       1 httplog.go:132] "HTTP" verb="GET" URI="/healthz" latency="60.203µs" userAgent="kube-probe/1.27" audit-ID="" srcIP="10.44.0.0:57598" resp=200
I0916 08:59:31.700953       1 httplog.go:132] "HTTP" verb="GET" URI="/healthz" latency="131.627µs" userAgent="kube-probe/1.27" audit-ID="" srcIP="10.44.0.0:50424" resp=200
I0916 08:59:31.702268       1 httplog.go:132] "HTTP" verb="GET" URI="/healthz" latency="94.748µs" userAgent="kube-probe/1.27" audit-ID="" srcIP="10.44.0.0:50438" resp=200
I0916 08:59:41.707451       1 httplog.go:132] "HTTP" verb="GET" URI="/healthz" latency="135.684µs" userAgent="kube-probe/1.27" audit-ID="" srcIP="10.44.0.0:34226" resp=200
I0916 08:59:41.708948       1 httplog.go:132] "HTTP" verb="GET" URI="/healthz" latency="139.001µs" userAgent="kube-probe/1.27" audit-ID="" srcIP="10.44.0.0:34240" resp=200
I0916 08:59:51.702351       1 httplog.go:132] "HTTP" verb="GET" URI="/healthz" latency="113.512µs" userAgent="kube-probe/1.27" audit-ID="" srcIP="10.44.0.0:37976" resp=200
I0916 08:59:51.702489       1 httplog.go:132] "HTTP" verb="GET" URI="/healthz" latency="55.674µs" userAgent="kube-probe/1.27" audit-ID="" srcIP="10.44.0.0:37972" resp=200
I0916 09:00:01.702045       1 httplog.go:132] "HTTP" verb="GET" URI="/healthz" latency="100.428µs" userAgent="kube-probe/1.27" audit-ID="" srcIP="10.44.0.0:50572" resp=200
I0916 09:00:01.703191       1 httplog.go:132] "HTTP" verb="GET" URI="/healthz" latency="121.167µs" userAgent="kube-probe/1.27" audit-ID="" srcIP="10.44.0.0:50580" resp=200
I0916 09:00:11.702528       1 httplog.go:132] "HTTP" verb="GET" URI="/healthz" latency="206.687µs" userAgent="kube-probe/1.27" audit-ID="" srcIP="10.44.0.0:58934" resp=200
I0916 09:00:11.703735       1 httplog.go:132] "HTTP" verb="GET" URI="/healthz" latency="87.053µs" userAgent="kube-probe/1.27" audit-ID="" srcIP="10.44.0.0:58918" resp=200
I0916 09:00:21.702663       1 httplog.go:132] "HTTP" verb="GET" URI="/healthz" latency="92.834µs" userAgent="kube-probe/1.27" audit-ID="" srcIP="10.44.0.0:59410" resp=200
I0916 09:00:21.708174       1 httplog.go:132] "HTTP" verb="GET" URI="/healthz" latency="39.684µs" userAgent="kube-probe/1.27" audit-ID="" srcIP="10.44.0.0:59418" resp=200
I0916 09:00:31.700603       1 httplog.go:132] "HTTP" verb="GET" URI="/healthz" latency="92.163µs" userAgent="kube-probe/1.27" audit-ID="" srcIP="10.44.0.0:33004" resp=200
I0916 09:00:31.701742       1 httplog.go:132] "HTTP" verb="GET" URI="/healthz" latency="35.917µs" userAgent="kube-probe/1.27" audit-ID="" srcIP="10.44.0.0:32988" resp=200
I0916 09:00:41.702537       1 httplog.go:132] "HTTP" verb="GET" URI="/healthz" latency="67.516µs" userAgent="kube-probe/1.27" audit-ID="" srcIP="10.44.0.0:52530" resp=200
I0916 09:00:41.710182       1 httplog.go:132] "HTTP" verb="GET" URI="/healthz" latency="45.886µs" userAgent="kube-probe/1.27" audit-ID="" srcIP="10.44.0.0:52536" resp=200
I0916 09:00:51.707285       1 httplog.go:132] "HTTP" verb="GET" URI="/healthz" latency="76.443µs" userAgent="kube-probe/1.27" audit-ID="" srcIP="10.44.0.0:55172" resp=200
I0916 09:00:51.708385       1 httplog.go:132] "HTTP" verb="GET" URI="/healthz" latency="48.201µs" userAgent="kube-probe/1.27" audit-ID="" srcIP="10.44.0.0:55174" resp=200
I0916 09:01:01.702346       1 httplog.go:132] "HTTP" verb="GET" URI="/healthz" latency="108.593µs" userAgent="kube-probe/1.27" audit-ID="" srcIP="10.44.0.0:49068" resp=200
I0916 09:01:01.703532       1 httplog.go:132] "HTTP" verb="GET" URI="/healthz" latency="96.782µs" userAgent="kube-probe/1.27" audit-ID="" srcIP="10.44.0.0:49072" resp=200
I0916 09:01:11.702754       1 httplog.go:132] "HTTP" verb="GET" URI="/healthz" latency="108.884µs" userAgent="kube-probe/1.27" audit-ID="" srcIP="10.44.0.0:36360" resp=200
I0916 09:01:11.703746       1 httplog.go:132] "HTTP" verb="GET" URI="/healthz" latency="125.805µs" userAgent="kube-probe/1.27" audit-ID="" srcIP="10.44.0.0:36358" resp=200
I0916 09:01:21.702220       1 httplog.go:132] "HTTP" verb="GET" URI="/healthz" latency="106.419µs" userAgent="kube-probe/1.27" audit-ID="" srcIP="10.44.0.0:57282" resp=200
I0916 09:01:21.703252       1 httplog.go:132] "HTTP" verb="GET" URI="/healthz" latency="46.768µs" userAgent="kube-probe/1.27" audit-ID="" srcIP="10.44.0.0:57278" resp=200
I0916 09:01:31.707187       1 httplog.go:132] "HTTP" verb="GET" URI="/healthz" latency="111.079µs" userAgent="kube-probe/1.27" audit-ID="" srcIP="10.44.0.0:56956" resp=200
I0916 09:01:31.708364       1 httplog.go:132] "HTTP" verb="GET" URI="/healthz" latency="93.947µs" userAgent="kube-probe/1.27" audit-ID="" srcIP="10.44.0.0:56964" resp=200
I0916 09:01:41.706363       1 httplog.go:132] "HTTP" verb="GET" URI="/healthz" latency="92.704µs" userAgent="kube-probe/1.27" audit-ID="" srcIP="10.44.0.0:34356" resp=200
I0916 09:01:41.707555       1 httplog.go:132] "HTTP" verb="GET" URI="/healthz" latency="108.814µs" userAgent="kube-probe/1.27" audit-ID="" srcIP="10.44.0.0:34346" resp=200
I0916 09:01:51.699982       1 httplog.go:132] "HTTP" verb="GET" URI="/healthz" latency="99.066µs" userAgent="kube-probe/1.27" audit-ID="" srcIP="10.44.0.0:38534" resp=200
I0916 09:01:51.703155       1 httplog.go:132] "HTTP" verb="GET" URI="/healthz" latency="112.862µs" userAgent="kube-probe/1.27" audit-ID="" srcIP="10.44.0.0:38532" resp=200
I0916 09:02:01.704120       1 httplog.go:132] "HTTP" verb="GET" URI="/healthz" latency="129.423µs" userAgent="kube-probe/1.27" audit-ID="" srcIP="10.44.0.0:51700" resp=200
I0916 09:02:01.705181       1 httplog.go:132] "HTTP" verb="GET" URI="/healthz" latency="69.541µs" userAgent="kube-probe/1.27" audit-ID="" srcIP="10.44.0.0:51714" resp=200
I0916 09:02:11.700835       1 httplog.go:132] "HTTP" verb="GET" URI="/healthz" latency="118.742µs" userAgent="kube-probe/1.27" audit-ID="" srcIP="10.44.0.0:58578" resp=200
I0916 09:02:11.702049       1 httplog.go:132] "HTTP" verb="GET" URI="/healthz" latency="77.746µs" userAgent="kube-probe/1.27" audit-ID="" srcIP="10.44.0.0:58572" resp=200
I0916 09:02:21.709143       1 httplog.go:132] "HTTP" verb="GET" URI="/healthz" latency="102.763µs" userAgent="kube-probe/1.27" audit-ID="" srcIP="10.44.0.0:43362" resp=200
I0916 09:02:21.709796       1 httplog.go:132] "HTTP" verb="GET" URI="/healthz" latency="19.967µs" userAgent="kube-probe/1.27" audit-ID="" srcIP="10.44.0.0:43348" resp=200
I0916 09:02:31.702519       1 httplog.go:132] "HTTP" verb="GET" URI="/healthz" latency="96.571µs" userAgent="kube-probe/1.27" audit-ID="" srcIP="10.44.0.0:43342" resp=200
I0916 09:02:31.703934       1 httplog.go:132] "HTTP" verb="GET" URI="/healthz" latency="85.681µs" userAgent="kube-probe/1.27" audit-ID="" srcIP="10.44.0.0:43334" resp=200
I0916 09:02:33.791841       1 eventhandlers.go:231] "Delete event for scheduled pod" pod="default/falcon-pod-534716"
I0916 09:02:41.707155       1 httplog.go:132] "HTTP" verb="GET" URI="/healthz" latency="105.928µs" userAgent="kube-probe/1.27" audit-ID="" srcIP="10.44.0.0:43462" resp=200
I0916 09:02:41.708184       1 httplog.go:132] "HTTP" verb="GET" URI="/healthz" latency="61.215µs" userAgent="kube-probe/1.27" audit-ID="" srcIP="10.44.0.0:43478" resp=200
I0916 09:02:51.707212       1 httplog.go:132] "HTTP" verb="GET" URI="/healthz" latency="111.639µs" userAgent="kube-probe/1.27" audit-ID="" srcIP="10.44.0.0:53170" resp=200
I0916 09:02:51.708286       1 httplog.go:132] "HTTP" verb="GET" URI="/healthz" latency="45.986µs" userAgent="kube-probe/1.27" audit-ID="" srcIP="10.44.0.0:53168" resp=200
I0916 09:03:01.706440       1 httplog.go:132] "HTTP" verb="GET" URI="/healthz" latency="121.227µs" userAgent="kube-probe/1.27" audit-ID="" srcIP="10.44.0.0:57662" resp=200
I0916 09:03:01.707515       1 httplog.go:132] "HTTP" verb="GET" URI="/healthz" latency="89.066µs" userAgent="kube-probe/1.27" audit-ID="" srcIP="10.44.0.0:57664" resp=200
I0916 09:03:11.702827       1 httplog.go:132] "HTTP" verb="GET" URI="/healthz" latency="114.284µs" userAgent="kube-probe/1.27" audit-ID="" srcIP="10.44.0.0:56954" resp=200
I0916 09:03:11.703903       1 httplog.go:132] "HTTP" verb="GET" URI="/healthz" latency="45.856µs" userAgent="kube-probe/1.27" audit-ID="" srcIP="10.44.0.0:56948" resp=200
I0916 09:03:21.702541       1 httplog.go:132] "HTTP" verb="GET" URI="/healthz" latency="91.322µs" userAgent="kube-probe/1.27" audit-ID="" srcIP="10.44.0.0:42570" resp=200
I0916 09:03:21.710477       1 httplog.go:132] "HTTP" verb="GET" URI="/healthz" latency="119.434µs" userAgent="kube-probe/1.27" audit-ID="" srcIP="10.44.0.0:42590" resp=200
I0916 09:03:31.701423       1 httplog.go:132] "HTTP" verb="GET" URI="/healthz" latency="121.298µs" userAgent="kube-probe/1.27" audit-ID="" srcIP="10.44.0.0:45554" resp=200
I0916 09:03:31.702567       1 httplog.go:132] "HTTP" verb="GET" URI="/healthz" latency="52.348µs" userAgent="kube-probe/1.27" audit-ID="" srcIP="10.44.0.0:45566" resp=200
I0916 09:03:41.706313       1 httplog.go:132] "HTTP" verb="GET" URI="/healthz" latency="132.949µs" userAgent="kube-probe/1.27" audit-ID="" srcIP="10.44.0.0:53634" resp=200
I0916 09:03:41.707396       1 httplog.go:132] "HTTP" verb="GET" URI="/healthz" latency="68.769µs" userAgent="kube-probe/1.27" audit-ID="" srcIP="10.44.0.0:53632" resp=200
I0916 09:03:51.707263       1 httplog.go:132] "HTTP" verb="GET" URI="/healthz" latency="106.62µs" userAgent="kube-probe/1.27" audit-ID="" srcIP="10.44.0.0:52180" resp=200
I0916 09:03:51.708446       1 httplog.go:132] "HTTP" verb="GET" URI="/healthz" latency="115.427µs" userAgent="kube-probe/1.27" audit-ID="" srcIP="10.44.0.0:52182" resp=200
I0916 09:04:01.702053       1 httplog.go:132] "HTTP" verb="GET" URI="/healthz" latency="86.202µs" userAgent="kube-probe/1.27" audit-ID="" srcIP="10.44.0.0:36322" resp=200
I0916 09:04:01.703309       1 httplog.go:132] "HTTP" verb="GET" URI="/healthz" latency="107.793µs" userAgent="kube-probe/1.27" audit-ID="" srcIP="10.44.0.0:36338" resp=200
I0916 09:04:11.702102       1 httplog.go:132] "HTTP" verb="GET" URI="/healthz" latency="125.736µs" userAgent="kube-probe/1.27" audit-ID="" srcIP="10.44.0.0:57822" resp=200
I0916 09:04:11.708900       1 httplog.go:132] "HTTP" verb="GET" URI="/healthz" latency="75.993µs" userAgent="kube-probe/1.27" audit-ID="" srcIP="10.44.0.0:57844" resp=200
I0916 09:04:21.699381       1 httplog.go:132] "HTTP" verb="GET" URI="/healthz" latency="104.666µs" userAgent="kube-probe/1.27" audit-ID="" srcIP="10.44.0.0:44508" resp=200
I0916 09:04:21.701640       1 httplog.go:132] "HTTP" verb="GET" URI="/healthz" latency="85.03µs" userAgent="kube-probe/1.27" audit-ID="" srcIP="10.44.0.0:44514" resp=200
I0916 09:04:31.702883       1 httplog.go:132] "HTTP" verb="GET" URI="/healthz" latency="133.551µs" userAgent="kube-probe/1.27" audit-ID="" srcIP="10.44.0.0:51066" resp=200
I0916 09:04:31.703993       1 httplog.go:132] "HTTP" verb="GET" URI="/healthz" latency="91.401µs" userAgent="kube-probe/1.27" audit-ID="" srcIP="10.44.0.0:51058" resp=200
I0916 09:04:41.706526       1 httplog.go:132] "HTTP" verb="GET" URI="/healthz" latency="110.948µs" userAgent="kube-probe/1.27" audit-ID="" srcIP="10.44.0.0:44412" resp=200
I0916 09:04:41.707777       1 httplog.go:132] "HTTP" verb="GET" URI="/healthz" latency="100.378µs" userAgent="kube-probe/1.27" audit-ID="" srcIP="10.44.0.0:44422" resp=200
I0916 09:04:51.702655       1 httplog.go:132] "HTTP" verb="GET" URI="/healthz" latency="111.359µs" userAgent="kube-probe/1.27" audit-ID="" srcIP="10.44.0.0:48608" resp=200
I0916 09:04:51.710271       1 httplog.go:132] "HTTP" verb="GET" URI="/healthz" latency="54.463µs" userAgent="kube-probe/1.27" audit-ID="" srcIP="10.44.0.0:48618" resp=200
I0916 09:05:01.702528       1 httplog.go:132] "HTTP" verb="GET" URI="/healthz" latency="115.006µs" userAgent="kube-probe/1.27" audit-ID="" srcIP="10.44.0.0:42840" resp=200
I0916 09:05:01.703574       1 httplog.go:132] "HTTP" verb="GET" URI="/healthz" latency="103.965µs" userAgent="kube-probe/1.27" audit-ID="" srcIP="10.44.0.0:42826" resp=200
I0916 09:05:11.700131       1 httplog.go:132] "HTTP" verb="GET" URI="/healthz" latency="80.962µs" userAgent="kube-probe/1.27" audit-ID="" srcIP="10.44.0.0:48970" resp=200
I0916 09:05:11.701462       1 httplog.go:132] "HTTP" verb="GET" URI="/healthz" latency="43.221µs" userAgent="kube-probe/1.27" audit-ID="" srcIP="10.44.0.0:48974" resp=200
I0916 09:05:21.700793       1 httplog.go:132] "HTTP" verb="GET" URI="/healthz" latency="113.303µs" userAgent="kube-probe/1.27" audit-ID="" srcIP="10.44.0.0:35888" resp=200
I0916 09:05:21.701435       1 httplog.go:132] "HTTP" verb="GET" URI="/healthz" latency="94.467µs" userAgent="kube-probe/1.27" audit-ID="" srcIP="10.44.0.0:35902" resp=200
I0916 09:05:31.707032       1 httplog.go:132] "HTTP" verb="GET" URI="/healthz" latency="88.686µs" userAgent="kube-probe/1.27" audit-ID="" srcIP="10.44.0.0:55456" resp=200
I0916 09:05:31.708085       1 httplog.go:132] "HTTP" verb="GET" URI="/healthz" latency="42.19µs" userAgent="kube-probe/1.27" audit-ID="" srcIP="10.44.0.0:55458" resp=200
I0916 09:05:41.706293       1 httplog.go:132] "HTTP" verb="GET" URI="/healthz" latency="119.754µs" userAgent="kube-probe/1.27" audit-ID="" srcIP="10.44.0.0:54962" resp=200
I0916 09:05:41.707418       1 httplog.go:132] "HTTP" verb="GET" URI="/healthz" latency="110.697µs" userAgent="kube-probe/1.27" audit-ID="" srcIP="10.44.0.0:54968" resp=200
I0916 09:05:51.707246       1 httplog.go:132] "HTTP" verb="GET" URI="/healthz" latency="89.208µs" userAgent="kube-probe/1.27" audit-ID="" srcIP="10.44.0.0:48098" resp=200
I0916 09:05:51.708563       1 httplog.go:132] "HTTP" verb="GET" URI="/healthz" latency="111.489µs" userAgent="kube-probe/1.27" audit-ID="" srcIP="10.44.0.0:48088" resp=200
I0916 09:06:01.700215       1 httplog.go:132] "HTTP" verb="GET" URI="/healthz" latency="101.81µs" userAgent="kube-probe/1.27" audit-ID="" srcIP="10.44.0.0:36780" resp=200
I0916 09:06:01.702702       1 httplog.go:132] "HTTP" verb="GET" URI="/healthz" latency="115.366µs" userAgent="kube-probe/1.27" audit-ID="" srcIP="10.44.0.0:36782" resp=200
I0916 09:06:11.707069       1 httplog.go:132] "HTTP" verb="GET" URI="/healthz" latency="102.613µs" userAgent="kube-probe/1.27" audit-ID="" srcIP="10.44.0.0:58158" resp=200
I0916 09:06:11.708039       1 httplog.go:132] "HTTP" verb="GET" URI="/healthz" latency="48.711µs" userAgent="kube-probe/1.27" audit-ID="" srcIP="10.44.0.0:58162" resp=200
I0916 09:06:21.702641       1 httplog.go:132] "HTTP" verb="GET" URI="/healthz" latency="86.522µs" userAgent="kube-probe/1.27" audit-ID="" srcIP="10.44.0.0:42028" resp=200
I0916 09:06:21.703815       1 httplog.go:132] "HTTP" verb="GET" URI="/healthz" latency="39.714µs" userAgent="kube-probe/1.27" audit-ID="" srcIP="10.44.0.0:42044" resp=200
I0916 09:06:31.702719       1 httplog.go:132] "HTTP" verb="GET" URI="/healthz" latency="99.527µs" userAgent="kube-probe/1.27" audit-ID="" srcIP="10.44.0.0:40434" resp=200
I0916 09:06:31.703922       1 httplog.go:132] "HTTP" verb="GET" URI="/healthz" latency="52.539µs" userAgent="kube-probe/1.27" audit-ID="" srcIP="10.44.0.0:40446" resp=200
I0916 09:06:41.702215       1 httplog.go:132] "HTTP" verb="GET" URI="/healthz" latency="103.764µs" userAgent="kube-probe/1.27" audit-ID="" srcIP="10.44.0.0:47076" resp=200
I0916 09:06:41.703385       1 httplog.go:132] "HTTP" verb="GET" URI="/healthz" latency="95.86µs" userAgent="kube-probe/1.27" audit-ID="" srcIP="10.44.0.0:47074" resp=200
I0916 09:06:51.706821       1 httplog.go:132] "HTTP" verb="GET" URI="/healthz" latency="109.596µs" userAgent="kube-probe/1.27" audit-ID="" srcIP="10.44.0.0:36254" resp=200
I0916 09:06:51.707886       1 httplog.go:132] "HTTP" verb="GET" URI="/healthz" latency="76.393µs" userAgent="kube-probe/1.27" audit-ID="" srcIP="10.44.0.0:36266" resp=200
I0916 09:07:01.708171       1 httplog.go:132] "HTTP" verb="GET" URI="/healthz" latency="163.277µs" userAgent="kube-probe/1.27" audit-ID="" srcIP="10.44.0.0:58824" resp=200
I0916 09:07:01.710293       1 httplog.go:132] "HTTP" verb="GET" URI="/healthz" latency="56.807µs" userAgent="kube-probe/1.27" audit-ID="" srcIP="10.44.0.0:58822" resp=200
I0916 09:07:11.702227       1 httplog.go:132] "HTTP" verb="GET" URI="/healthz" latency="101.15µs" userAgent="kube-probe/1.27" audit-ID="" srcIP="10.44.0.0:38698" resp=200
I0916 09:07:11.703444       1 httplog.go:132] "HTTP" verb="GET" URI="/healthz" latency="106.018µs" userAgent="kube-probe/1.27" audit-ID="" srcIP="10.44.0.0:38714" resp=200
I0916 09:07:21.707426       1 httplog.go:132] "HTTP" verb="GET" URI="/healthz" latency="154.129µs" userAgent="kube-probe/1.27" audit-ID="" srcIP="10.44.0.0:42196" resp=200
I0916 09:07:21.708476       1 httplog.go:132] "HTTP" verb="GET" URI="/healthz" latency="121.528µs" userAgent="kube-probe/1.27" audit-ID="" srcIP="10.44.0.0:42198" resp=200
I0916 09:07:31.706712       1 httplog.go:132] "HTTP" verb="GET" URI="/healthz" latency="141.355µs" userAgent="kube-probe/1.27" audit-ID="" srcIP="10.44.0.0:35004" resp=200
I0916 09:07:31.707871       1 httplog.go:132] "HTTP" verb="GET" URI="/healthz" latency="81.293µs" userAgent="kube-probe/1.27" audit-ID="" srcIP="10.44.0.0:35006" resp=200
I0916 09:07:41.707348       1 httplog.go:132] "HTTP" verb="GET" URI="/healthz" latency="125.936µs" userAgent="kube-probe/1.27" audit-ID="" srcIP="10.44.0.0:53828" resp=200
I0916 09:07:41.708390       1 httplog.go:132] "HTTP" verb="GET" URI="/healthz" latency="64.05µs" userAgent="kube-probe/1.27" audit-ID="" srcIP="10.44.0.0:53812" resp=200
I0916 09:07:51.706423       1 httplog.go:132] "HTTP" verb="GET" URI="/healthz" latency="138.66µs" userAgent="kube-probe/1.27" audit-ID="" srcIP="10.44.0.0:59672" resp=200
I0916 09:07:51.707676       1 httplog.go:132] "HTTP" verb="GET" URI="/healthz" latency="81.273µs" userAgent="kube-probe/1.27" audit-ID="" srcIP="10.44.0.0:59670" resp=200
I0916 09:08:01.707387       1 httplog.go:132] "HTTP" verb="GET" URI="/healthz" latency="94.297µs" userAgent="kube-probe/1.27" audit-ID="" srcIP="10.44.0.0:48262" resp=200
I0916 09:08:01.708458       1 httplog.go:132] "HTTP" verb="GET" URI="/healthz" latency="28.112µs" userAgent="kube-probe/1.27" audit-ID="" srcIP="10.44.0.0:48278" resp=200
I0916 09:08:11.706333       1 httplog.go:132] "HTTP" verb="GET" URI="/healthz" latency="79.138µs" userAgent="kube-probe/1.27" audit-ID="" srcIP="10.44.0.0:45860" resp=200
I0916 09:08:11.706388       1 httplog.go:132] "HTTP" verb="GET" URI="/healthz" latency="120.996µs" userAgent="kube-probe/1.27" audit-ID="" srcIP="10.44.0.0:45858" resp=200
I0916 09:08:14.893659       1 eventhandlers.go:231] "Delete event for scheduled pod" pod="default/falcon-pod-458562"
I0916 09:08:21.707382       1 httplog.go:132] "HTTP" verb="GET" URI="/healthz" latency="112.551µs" userAgent="kube-probe/1.27" audit-ID="" srcIP="10.44.0.0:48442" resp=200
I0916 09:08:21.709443       1 httplog.go:132] "HTTP" verb="GET" URI="/healthz" latency="107.242µs" userAgent="kube-probe/1.27" audit-ID="" srcIP="10.44.0.0:48444" resp=200
I0916 09:08:31.707109       1 httplog.go:132] "HTTP" verb="GET" URI="/healthz" latency="102.132µs" userAgent="kube-probe/1.27" audit-ID="" srcIP="10.44.0.0:58080" resp=200
I0916 09:08:31.708326       1 httplog.go:132] "HTTP" verb="GET" URI="/healthz" latency="58.519µs" userAgent="kube-probe/1.27" audit-ID="" srcIP="10.44.0.0:58096" resp=200
I0916 09:08:41.706618       1 httplog.go:132] "HTTP" verb="GET" URI="/healthz" latency="103.174µs" userAgent="kube-probe/1.27" audit-ID="" srcIP="10.44.0.0:56700" resp=200
I0916 09:08:41.707750       1 httplog.go:132] "HTTP" verb="GET" URI="/healthz" latency="101.64µs" userAgent="kube-probe/1.27" audit-ID="" srcIP="10.44.0.0:56694" resp=200
I0916 09:08:51.702348       1 httplog.go:132] "HTTP" verb="GET" URI="/healthz" latency="103.174µs" userAgent="kube-probe/1.27" audit-ID="" srcIP="10.44.0.0:33334" resp=200
I0916 09:08:51.709880       1 httplog.go:132] "HTTP" verb="GET" URI="/healthz" latency="27.953µs" userAgent="kube-probe/1.27" audit-ID="" srcIP="10.44.0.0:33342" resp=200
I0916 09:09:01.702493       1 httplog.go:132] "HTTP" verb="GET" URI="/healthz" latency="132.459µs" userAgent="kube-probe/1.27" audit-ID="" srcIP="10.44.0.0:55310" resp=200
I0916 09:09:01.703675       1 httplog.go:132] "HTTP" verb="GET" URI="/healthz" latency="157.265µs" userAgent="kube-probe/1.27" audit-ID="" srcIP="10.44.0.0:55308" resp=200
I0916 09:09:11.702921       1 httplog.go:132] "HTTP" verb="GET" URI="/healthz" latency="112.701µs" userAgent="kube-probe/1.27" audit-ID="" srcIP="10.44.0.0:33340" resp=200
I0916 09:09:11.710424       1 httplog.go:132] "HTTP" verb="GET" URI="/healthz" latency="109.546µs" userAgent="kube-probe/1.27" audit-ID="" srcIP="10.44.0.0:33356" resp=200
I0916 09:09:21.702160       1 httplog.go:132] "HTTP" verb="GET" URI="/healthz" latency="84.779µs" userAgent="kube-probe/1.27" audit-ID="" srcIP="10.44.0.0:60436" resp=200
I0916 09:09:21.709767       1 httplog.go:132] "HTTP" verb="GET" URI="/healthz" latency="76.985µs" userAgent="kube-probe/1.27" audit-ID="" srcIP="10.44.0.0:60448" resp=200
I0916 09:09:31.706922       1 httplog.go:132] "HTTP" verb="GET" URI="/healthz" latency="114.715µs" userAgent="kube-probe/1.27" audit-ID="" srcIP="10.44.0.0:46784" resp=200
I0916 09:09:31.708073       1 httplog.go:132] "HTTP" verb="GET" URI="/healthz" latency="62.898µs" userAgent="kube-probe/1.27" audit-ID="" srcIP="10.44.0.0:46786" resp=200
I0916 09:09:41.706348       1 httplog.go:132] "HTTP" verb="GET" URI="/healthz" latency="91.311µs" userAgent="kube-probe/1.27" audit-ID="" srcIP="10.44.0.0:52220" resp=200
I0916 09:09:41.707659       1 httplog.go:132] "HTTP" verb="GET" URI="/healthz" latency="79.99µs" userAgent="kube-probe/1.27" audit-ID="" srcIP="10.44.0.0:52236" resp=200
I0916 09:09:51.706489       1 httplog.go:132] "HTTP" verb="GET" URI="/healthz" latency="81.373µs" userAgent="kube-probe/1.27" audit-ID="" srcIP="10.44.0.0:54356" resp=200
I0916 09:09:51.707564       1 httplog.go:132] "HTTP" verb="GET" URI="/healthz" latency="59.191µs" userAgent="kube-probe/1.27" audit-ID="" srcIP="10.44.0.0:54370" resp=200
I0916 09:10:01.707353       1 httplog.go:132] "HTTP" verb="GET" URI="/healthz" latency="88.846µs" userAgent="kube-probe/1.27" audit-ID="" srcIP="10.44.0.0:47194" resp=200
I0916 09:10:01.708663       1 httplog.go:132] "HTTP" verb="GET" URI="/healthz" latency="128.361µs" userAgent="kube-probe/1.27" audit-ID="" srcIP="10.44.0.0:47186" resp=200
I0916 09:10:11.702867       1 httplog.go:132] "HTTP" verb="GET" URI="/healthz" latency="123.271µs" userAgent="kube-probe/1.27" audit-ID="" srcIP="10.44.0.0:45948" resp=200
I0916 09:10:11.703801       1 httplog.go:132] "HTTP" verb="GET" URI="/healthz" latency="76.083µs" userAgent="kube-probe/1.27" audit-ID="" srcIP="10.44.0.0:45954" resp=200
I0916 09:10:21.701934       1 httplog.go:132] "HTTP" verb="GET" URI="/healthz" latency="110.918µs" userAgent="kube-probe/1.27" audit-ID="" srcIP="10.44.0.0:34822" resp=200
I0916 09:10:21.703134       1 httplog.go:132] "HTTP" verb="GET" URI="/healthz" latency="110.688µs" userAgent="kube-probe/1.27" audit-ID="" srcIP="10.44.0.0:34824" resp=200
I0916 09:10:31.702466       1 httplog.go:132] "HTTP" verb="GET" URI="/healthz" latency="96.881µs" userAgent="kube-probe/1.27" audit-ID="" srcIP="10.44.0.0:39286" resp=200
I0916 09:10:31.709910       1 httplog.go:132] "HTTP" verb="GET" URI="/healthz" latency="81.503µs" userAgent="kube-probe/1.27" audit-ID="" srcIP="10.44.0.0:39306" resp=200
I0916 09:10:41.706799       1 httplog.go:132] "HTTP" verb="GET" URI="/healthz" latency="111.449µs" userAgent="kube-probe/1.27" audit-ID="" srcIP="10.44.0.0:38604" resp=200
I0916 09:10:41.707734       1 httplog.go:132] "HTTP" verb="GET" URI="/healthz" latency="33.242µs" userAgent="kube-probe/1.27" audit-ID="" srcIP="10.44.0.0:38610" resp=200
I0916 09:10:51.702252       1 httplog.go:132] "HTTP" verb="GET" URI="/healthz" latency="125.515µs" userAgent="kube-probe/1.27" audit-ID="" srcIP="10.44.0.0:54400" resp=200
I0916 09:10:51.702643       1 httplog.go:132] "HTTP" verb="GET" URI="/healthz" latency="48.892µs" userAgent="kube-probe/1.27" audit-ID="" srcIP="10.44.0.0:54398" resp=200
I0916 09:11:01.703422       1 httplog.go:132] "HTTP" verb="GET" URI="/healthz" latency="126.958µs" userAgent="kube-probe/1.27" audit-ID="" srcIP="10.44.0.0:41126" resp=200
I0916 09:11:01.704789       1 httplog.go:132] "HTTP" verb="GET" URI="/healthz" latency="112.04µs" userAgent="kube-probe/1.27" audit-ID="" srcIP="10.44.0.0:41138" resp=200
I0916 09:11:11.701582       1 httplog.go:132] "HTTP" verb="GET" URI="/healthz" latency="111.129µs" userAgent="kube-probe/1.27" audit-ID="" srcIP="10.44.0.0:37038" resp=200
I0916 09:11:11.702640       1 httplog.go:132] "HTTP" verb="GET" URI="/healthz" latency="47.559µs" userAgent="kube-probe/1.27" audit-ID="" srcIP="10.44.0.0:37042" resp=200
I0916 09:11:21.706549       1 httplog.go:132] "HTTP" verb="GET" URI="/healthz" latency="73.718µs" userAgent="kube-probe/1.27" audit-ID="" srcIP="10.44.0.0:39992" resp=200
I0916 09:11:21.707791       1 httplog.go:132] "HTTP" verb="GET" URI="/healthz" latency="44.784µs" userAgent="kube-probe/1.27" audit-ID="" srcIP="10.44.0.0:40004" resp=200
I0916 09:11:31.702394       1 httplog.go:132] "HTTP" verb="GET" URI="/healthz" latency="77.375µs" userAgent="kube-probe/1.27" audit-ID="" srcIP="10.44.0.0:46478" resp=200
I0916 09:11:31.703605       1 httplog.go:132] "HTTP" verb="GET" URI="/healthz" latency="64.41µs" userAgent="kube-probe/1.27" audit-ID="" srcIP="10.44.0.0:46486" resp=200
I0916 09:11:41.700880       1 httplog.go:132] "HTTP" verb="GET" URI="/healthz" latency="148.178µs" userAgent="kube-probe/1.27" audit-ID="" srcIP="10.44.0.0:51924" resp=200
I0916 09:11:41.703473       1 httplog.go:132] "HTTP" verb="GET" URI="/healthz" latency="145.052µs" userAgent="kube-probe/1.27" audit-ID="" srcIP="10.44.0.0:51918" resp=200
I0916 09:11:51.707304       1 httplog.go:132] "HTTP" verb="GET" URI="/healthz" latency="143.459µs" userAgent="kube-probe/1.27" audit-ID="" srcIP="10.44.0.0:55710" resp=200
I0916 09:11:51.708758       1 httplog.go:132] "HTTP" verb="GET" URI="/healthz" latency="145.833µs" userAgent="kube-probe/1.27" audit-ID="" srcIP="10.44.0.0:55720" resp=200
I0916 09:12:01.706791       1 httplog.go:132] "HTTP" verb="GET" URI="/healthz" latency="254.818µs" userAgent="kube-probe/1.27" audit-ID="" srcIP="10.44.0.0:47174" resp=200
I0916 09:12:01.708096       1 httplog.go:132] "HTTP" verb="GET" URI="/healthz" latency="81.492µs" userAgent="kube-probe/1.27" audit-ID="" srcIP="10.44.0.0:47172" resp=200
I0916 09:12:11.702580       1 httplog.go:132] "HTTP" verb="GET" URI="/healthz" latency="447.82µs" userAgent="kube-probe/1.27" audit-ID="" srcIP="10.44.0.0:37394" resp=200
I0916 09:12:11.709889       1 httplog.go:132] "HTTP" verb="GET" URI="/healthz" latency="91.852µs" userAgent="kube-probe/1.27" audit-ID="" srcIP="10.44.0.0:37400" resp=200
I0916 09:12:21.704238       1 httplog.go:132] "HTTP" verb="GET" URI="/healthz" latency="159.8µs" userAgent="kube-probe/1.27" audit-ID="" srcIP="10.44.0.0:60042" resp=200
I0916 09:12:21.705581       1 httplog.go:132] "HTTP" verb="GET" URI="/healthz" latency="112.832µs" userAgent="kube-probe/1.27" audit-ID="" srcIP="10.44.0.0:60034" resp=200
I0916 09:12:31.702698       1 httplog.go:132] "HTTP" verb="GET" URI="/healthz" latency="106.89µs" userAgent="kube-probe/1.27" audit-ID="" srcIP="10.44.0.0:60804" resp=200
I0916 09:12:31.703028       1 httplog.go:132] "HTTP" verb="GET" URI="/healthz" latency="127.81µs" userAgent="kube-probe/1.27" audit-ID="" srcIP="10.44.0.0:60820" resp=200
I0916 09:12:41.706833       1 httplog.go:132] "HTTP" verb="GET" URI="/healthz" latency="234.62µs" userAgent="kube-probe/1.27" audit-ID="" srcIP="10.44.0.0:59838" resp=200
I0916 09:12:41.708053       1 httplog.go:132] "HTTP" verb="GET" URI="/healthz" latency="159.338µs" userAgent="kube-probe/1.27" audit-ID="" srcIP="10.44.0.0:59840" resp=200
I0916 09:12:51.705336       1 httplog.go:132] "HTTP" verb="GET" URI="/healthz" latency="138.269µs" userAgent="kube-probe/1.27" audit-ID="" srcIP="10.44.0.0:33830" resp=200
I0916 09:12:51.713740       1 httplog.go:132] "HTTP" verb="GET" URI="/healthz" latency="124.203µs" userAgent="kube-probe/1.27" audit-ID="" srcIP="10.44.0.0:33840" resp=200
I0916 09:13:01.707712       1 httplog.go:132] "HTTP" verb="GET" URI="/healthz" latency="118.452µs" userAgent="kube-probe/1.27" audit-ID="" srcIP="10.44.0.0:48352" resp=200
I0916 09:13:01.708953       1 httplog.go:132] "HTTP" verb="GET" URI="/healthz" latency="147.407µs" userAgent="kube-probe/1.27" audit-ID="" srcIP="10.44.0.0:48346" resp=200
I0916 09:13:11.707139       1 httplog.go:132] "HTTP" verb="GET" URI="/healthz" latency="113.894µs" userAgent="kube-probe/1.27" audit-ID="" srcIP="10.44.0.0:54154" resp=200
I0916 09:13:11.708419       1 httplog.go:132] "HTTP" verb="GET" URI="/healthz" latency="86.773µs" userAgent="kube-probe/1.27" audit-ID="" srcIP="10.44.0.0:54166" resp=200
I0916 09:13:21.702364       1 httplog.go:132] "HTTP" verb="GET" URI="/healthz" latency="129.051µs" userAgent="kube-probe/1.27" audit-ID="" srcIP="10.44.0.0:37730" resp=200
I0916 09:13:21.703465       1 httplog.go:132] "HTTP" verb="GET" URI="/healthz" latency="124.503µs" userAgent="kube-probe/1.27" audit-ID="" srcIP="10.44.0.0:37740" resp=200
I0916 09:13:31.706443       1 httplog.go:132] "HTTP" verb="GET" URI="/healthz" latency="96.17µs" userAgent="kube-probe/1.27" audit-ID="" srcIP="10.44.0.0:52346" resp=200
I0916 09:13:31.707381       1 httplog.go:132] "HTTP" verb="GET" URI="/healthz" latency="108.984µs" userAgent="kube-probe/1.27" audit-ID="" srcIP="10.44.0.0:52336" resp=200
I0916 09:13:41.706890       1 httplog.go:132] "HTTP" verb="GET" URI="/healthz" latency="91.802µs" userAgent="kube-probe/1.27" audit-ID="" srcIP="10.44.0.0:59354" resp=200
I0916 09:13:41.708168       1 httplog.go:132] "HTTP" verb="GET" URI="/healthz" latency="104.857µs" userAgent="kube-probe/1.27" audit-ID="" srcIP="10.44.0.0:59348" resp=200
I0916 09:13:51.706809       1 httplog.go:132] "HTTP" verb="GET" URI="/healthz" latency="94.347µs" userAgent="kube-probe/1.27" audit-ID="" srcIP="10.44.0.0:47772" resp=200
I0916 09:13:51.708088       1 httplog.go:132] "HTTP" verb="GET" URI="/healthz" latency="102.862µs" userAgent="kube-probe/1.27" audit-ID="" srcIP="10.44.0.0:47776" resp=200
I0916 09:14:01.707213       1 httplog.go:132] "HTTP" verb="GET" URI="/healthz" latency="130.224µs" userAgent="kube-probe/1.27" audit-ID="" srcIP="10.44.0.0:60378" resp=200
I0916 09:14:01.708428       1 httplog.go:132] "HTTP" verb="GET" URI="/healthz" latency="95.89µs" userAgent="kube-probe/1.27" audit-ID="" srcIP="10.44.0.0:60374" resp=200
I0916 09:14:11.702288       1 httplog.go:132] "HTTP" verb="GET" URI="/healthz" latency="126.608µs" userAgent="kube-probe/1.27" audit-ID="" srcIP="10.44.0.0:49728" resp=200
I0916 09:14:11.703361       1 httplog.go:132] "HTTP" verb="GET" URI="/healthz" latency="74.349µs" userAgent="kube-probe/1.27" audit-ID="" srcIP="10.44.0.0:49742" resp=200
I0916 09:14:21.701222       1 httplog.go:132] "HTTP" verb="GET" URI="/healthz" latency="116.849µs" userAgent="kube-probe/1.27" audit-ID="" srcIP="10.44.0.0:53830" resp=200
I0916 09:14:21.702561       1 httplog.go:132] "HTTP" verb="GET" URI="/healthz" latency="96.09µs" userAgent="kube-probe/1.27" audit-ID="" srcIP="10.44.0.0:53824" resp=200
I0916 09:14:31.707158       1 httplog.go:132] "HTTP" verb="GET" URI="/healthz" latency="74.048µs" userAgent="kube-probe/1.27" audit-ID="" srcIP="10.44.0.0:48292" resp=200
I0916 09:14:31.708446       1 httplog.go:132] "HTTP" verb="GET" URI="/healthz" latency="74.76µs" userAgent="kube-probe/1.27" audit-ID="" srcIP="10.44.0.0:48282" resp=200
I0916 09:14:32.046479       1 eventhandlers.go:231] "Delete event for scheduled pod" pod="monitoring/prometheus-prometheus-node-exporter-dv98k"
I0916 09:14:32.082452       1 eventhandlers.go:231] "Delete event for scheduled pod" pod="monitoring/prometheus-prometheus-node-exporter-cwvqp"
I0916 09:14:32.284702       1 eventhandlers.go:231] "Delete event for scheduled pod" pod="monitoring/prometheus-prometheus-pushgateway-7cb5dd797-6zmbm"
I0916 09:14:32.397421       1 eventhandlers.go:231] "Delete event for scheduled pod" pod="monitoring/prometheus-server-7c9757cccb-844wl"
I0916 09:14:32.445898       1 eventhandlers.go:231] "Delete event for scheduled pod" pod="monitoring/prometheus-kube-state-metrics-86894fb745-nj2nr"
I0916 09:14:41.706477       1 httplog.go:132] "HTTP" verb="GET" URI="/healthz" latency="106.058µs" userAgent="kube-probe/1.27" audit-ID="" srcIP="10.44.0.0:55170" resp=200
I0916 09:14:41.707560       1 httplog.go:132] "HTTP" verb="GET" URI="/healthz" latency="67.537µs" userAgent="kube-probe/1.27" audit-ID="" srcIP="10.44.0.0:55174" resp=200
I0916 09:14:51.706639       1 httplog.go:132] "HTTP" verb="GET" URI="/healthz" latency="129.443µs" userAgent="kube-probe/1.27" audit-ID="" srcIP="10.44.0.0:47584" resp=200
I0916 09:14:51.707740       1 httplog.go:132] "HTTP" verb="GET" URI="/healthz" latency="60.804µs" userAgent="kube-probe/1.27" audit-ID="" srcIP="10.44.0.0:47592" resp=200
I0916 09:14:53.531063       1 eventhandlers.go:186] "Add event for scheduled pod" pod="monitoring/gpu-exporter-7876f49579-xjh6t"
I0916 09:15:01.707035       1 httplog.go:132] "HTTP" verb="GET" URI="/healthz" latency="99.537µs" userAgent="kube-probe/1.27" audit-ID="" srcIP="10.44.0.0:36656" resp=200
I0916 09:15:01.708076       1 httplog.go:132] "HTTP" verb="GET" URI="/healthz" latency="25.608µs" userAgent="kube-probe/1.27" audit-ID="" srcIP="10.44.0.0:36650" resp=200
I0916 09:15:11.707044       1 httplog.go:132] "HTTP" verb="GET" URI="/healthz" latency="95.88µs" userAgent="kube-probe/1.27" audit-ID="" srcIP="10.44.0.0:48880" resp=200
I0916 09:15:11.708298       1 httplog.go:132] "HTTP" verb="GET" URI="/healthz" latency="46.126µs" userAgent="kube-probe/1.27" audit-ID="" srcIP="10.44.0.0:48890" resp=200
I0916 09:15:21.703033       1 httplog.go:132] "HTTP" verb="GET" URI="/healthz" latency="152.876µs" userAgent="kube-probe/1.27" audit-ID="" srcIP="10.44.0.0:44120" resp=200
I0916 09:15:21.703133       1 httplog.go:132] "HTTP" verb="GET" URI="/healthz" latency="95.649µs" userAgent="kube-probe/1.27" audit-ID="" srcIP="10.44.0.0:44122" resp=200
I0916 09:15:23.951408       1 eventhandlers.go:231] "Delete event for scheduled pod" pod="monitoring/gpu-exporter-7876f49579-w4l57"
I0916 09:15:31.703016       1 httplog.go:132] "HTTP" verb="GET" URI="/healthz" latency="119.044µs" userAgent="kube-probe/1.27" audit-ID="" srcIP="10.44.0.0:58232" resp=200
I0916 09:15:31.710341       1 httplog.go:132] "HTTP" verb="GET" URI="/healthz" latency="85.62µs" userAgent="kube-probe/1.27" audit-ID="" srcIP="10.44.0.0:58248" resp=200
I0916 09:15:41.706875       1 httplog.go:132] "HTTP" verb="GET" URI="/healthz" latency="102.553µs" userAgent="kube-probe/1.27" audit-ID="" srcIP="10.44.0.0:51012" resp=200
I0916 09:15:41.708024       1 httplog.go:132] "HTTP" verb="GET" URI="/healthz" latency="58.429µs" userAgent="kube-probe/1.27" audit-ID="" srcIP="10.44.0.0:51014" resp=200
I0916 09:15:51.706417       1 httplog.go:132] "HTTP" verb="GET" URI="/healthz" latency="167.975µs" userAgent="kube-probe/1.27" audit-ID="" srcIP="10.44.0.0:42752" resp=200
I0916 09:15:51.707565       1 httplog.go:132] "HTTP" verb="GET" URI="/healthz" latency="119.274µs" userAgent="kube-probe/1.27" audit-ID="" srcIP="10.44.0.0:42754" resp=200
I0916 09:16:01.702897       1 httplog.go:132] "HTTP" verb="GET" URI="/healthz" latency="90.85µs" userAgent="kube-probe/1.27" audit-ID="" srcIP="10.44.0.0:51842" resp=200
I0916 09:16:01.704342       1 httplog.go:132] "HTTP" verb="GET" URI="/healthz" latency="106.169µs" userAgent="kube-probe/1.27" audit-ID="" srcIP="10.44.0.0:51848" resp=200
I0916 09:16:11.703093       1 httplog.go:132] "HTTP" verb="GET" URI="/healthz" latency="110.597µs" userAgent="kube-probe/1.27" audit-ID="" srcIP="10.44.0.0:57358" resp=200
I0916 09:16:11.710643       1 httplog.go:132] "HTTP" verb="GET" URI="/healthz" latency="122.9µs" userAgent="kube-probe/1.27" audit-ID="" srcIP="10.44.0.0:57384" resp=200
I0916 09:16:21.706669       1 httplog.go:132] "HTTP" verb="GET" URI="/healthz" latency="105.067µs" userAgent="kube-probe/1.27" audit-ID="" srcIP="10.44.0.0:56906" resp=200
I0916 09:16:21.707939       1 httplog.go:132] "HTTP" verb="GET" URI="/healthz" latency="97.563µs" userAgent="kube-probe/1.27" audit-ID="" srcIP="10.44.0.0:56912" resp=200
I0916 09:16:31.701823       1 httplog.go:132] "HTTP" verb="GET" URI="/healthz" latency="107.331µs" userAgent="kube-probe/1.27" audit-ID="" srcIP="10.44.0.0:57188" resp=200
I0916 09:16:31.703016       1 httplog.go:132] "HTTP" verb="GET" URI="/healthz" latency="52.889µs" userAgent="kube-probe/1.27" audit-ID="" srcIP="10.44.0.0:57204" resp=200
I0916 09:16:32.570350       1 eventhandlers.go:186] "Add event for scheduled pod" pod="monitoring/prometheus-prometheus-pushgateway-7cb5dd797-jr65b"
I0916 09:16:32.572916       1 eventhandlers.go:186] "Add event for scheduled pod" pod="monitoring/prometheus-kube-state-metrics-86894fb745-t62x5"
I0916 09:16:32.572969       1 eventhandlers.go:186] "Add event for scheduled pod" pod="monitoring/prometheus-server-7c9757cccb-2bt6c"
I0916 09:16:32.574028       1 eventhandlers.go:186] "Add event for scheduled pod" pod="monitoring/prometheus-prometheus-node-exporter-69wjl"
I0916 09:16:32.579693       1 eventhandlers.go:186] "Add event for scheduled pod" pod="monitoring/prometheus-prometheus-node-exporter-fl467"
I0916 09:16:41.707039       1 httplog.go:132] "HTTP" verb="GET" URI="/healthz" latency="91.662µs" userAgent="kube-probe/1.27" audit-ID="" srcIP="10.44.0.0:53540" resp=200
I0916 09:16:41.707902       1 httplog.go:132] "HTTP" verb="GET" URI="/healthz" latency="26.87µs" userAgent="kube-probe/1.27" audit-ID="" srcIP="10.44.0.0:53556" resp=200
I0916 09:16:51.706344       1 httplog.go:132] "HTTP" verb="GET" URI="/healthz" latency="89.167µs" userAgent="kube-probe/1.27" audit-ID="" srcIP="10.44.0.0:37022" resp=200
I0916 09:16:51.707490       1 httplog.go:132] "HTTP" verb="GET" URI="/healthz" latency="61.095µs" userAgent="kube-probe/1.27" audit-ID="" srcIP="10.44.0.0:37026" resp=200
I0916 09:17:01.706886       1 httplog.go:132] "HTTP" verb="GET" URI="/healthz" latency="118.833µs" userAgent="kube-probe/1.27" audit-ID="" srcIP="10.44.0.0:48856" resp=200
I0916 09:17:01.707859       1 httplog.go:132] "HTTP" verb="GET" URI="/healthz" latency="64.07µs" userAgent="kube-probe/1.27" audit-ID="" srcIP="10.44.0.0:48860" resp=200
I0916 09:17:11.707088       1 httplog.go:132] "HTTP" verb="GET" URI="/healthz" latency="102.221µs" userAgent="kube-probe/1.27" audit-ID="" srcIP="10.44.0.0:53070" resp=200
I0916 09:17:11.708234       1 httplog.go:132] "HTTP" verb="GET" URI="/healthz" latency="79.71µs" userAgent="kube-probe/1.27" audit-ID="" srcIP="10.44.0.0:53078" resp=200
I0916 09:17:21.702924       1 httplog.go:132] "HTTP" verb="GET" URI="/healthz" latency="85.491µs" userAgent="kube-probe/1.27" audit-ID="" srcIP="10.44.0.0:57996" resp=200
I0916 09:17:21.708992       1 httplog.go:132] "HTTP" verb="GET" URI="/healthz" latency="41.187µs" userAgent="kube-probe/1.27" audit-ID="" srcIP="10.44.0.0:58000" resp=200
I0916 09:17:31.700955       1 httplog.go:132] "HTTP" verb="GET" URI="/healthz" latency="103.985µs" userAgent="kube-probe/1.27" audit-ID="" srcIP="10.44.0.0:51796" resp=200
I0916 09:17:31.702519       1 httplog.go:132] "HTTP" verb="GET" URI="/healthz" latency="53.621µs" userAgent="kube-probe/1.27" audit-ID="" srcIP="10.44.0.0:51798" resp=200
I0916 09:17:41.706599       1 httplog.go:132] "HTTP" verb="GET" URI="/healthz" latency="67.216µs" userAgent="kube-probe/1.27" audit-ID="" srcIP="10.44.0.0:54368" resp=200
I0916 09:17:41.708333       1 httplog.go:132] "HTTP" verb="GET" URI="/healthz" latency="92.373µs" userAgent="kube-probe/1.27" audit-ID="" srcIP="10.44.0.0:54370" resp=200
I0916 09:17:51.702301       1 httplog.go:132] "HTTP" verb="GET" URI="/healthz" latency="92.223µs" userAgent="kube-probe/1.27" audit-ID="" srcIP="10.44.0.0:33136" resp=200
I0916 09:17:51.708091       1 httplog.go:132] "HTTP" verb="GET" URI="/healthz" latency="90.429µs" userAgent="kube-probe/1.27" audit-ID="" srcIP="10.44.0.0:33126" resp=200
I0916 09:18:01.706374       1 httplog.go:132] "HTTP" verb="GET" URI="/healthz" latency="97.693µs" userAgent="kube-probe/1.27" audit-ID="" srcIP="10.44.0.0:44220" resp=200
I0916 09:18:01.707578       1 httplog.go:132] "HTTP" verb="GET" URI="/healthz" latency="77.234µs" userAgent="kube-probe/1.27" audit-ID="" srcIP="10.44.0.0:44228" resp=200
I0916 09:18:11.706193       1 httplog.go:132] "HTTP" verb="GET" URI="/healthz" latency="116.308µs" userAgent="kube-probe/1.27" audit-ID="" srcIP="10.44.0.0:56678" resp=200
I0916 09:18:11.707348       1 httplog.go:132] "HTTP" verb="GET" URI="/healthz" latency="33.292µs" userAgent="kube-probe/1.27" audit-ID="" srcIP="10.44.0.0:56672" resp=200
I0916 09:18:21.702738       1 httplog.go:132] "HTTP" verb="GET" URI="/healthz" latency="90.901µs" userAgent="kube-probe/1.27" audit-ID="" srcIP="10.44.0.0:55368" resp=200
I0916 09:18:21.710719       1 httplog.go:132] "HTTP" verb="GET" URI="/healthz" latency="120.967µs" userAgent="kube-probe/1.27" audit-ID="" srcIP="10.44.0.0:55382" resp=200
I0916 09:18:31.706753       1 httplog.go:132] "HTTP" verb="GET" URI="/healthz" latency="91.842µs" userAgent="kube-probe/1.27" audit-ID="" srcIP="10.44.0.0:49116" resp=200
I0916 09:18:31.707960       1 httplog.go:132] "HTTP" verb="GET" URI="/healthz" latency="58.81µs" userAgent="kube-probe/1.27" audit-ID="" srcIP="10.44.0.0:49118" resp=200
I0916 09:18:41.702527       1 httplog.go:132] "HTTP" verb="GET" URI="/healthz" latency="143.88µs" userAgent="kube-probe/1.27" audit-ID="" srcIP="10.44.0.0:52132" resp=200
I0916 09:18:41.703745       1 httplog.go:132] "HTTP" verb="GET" URI="/healthz" latency="78.327µs" userAgent="kube-probe/1.27" audit-ID="" srcIP="10.44.0.0:52120" resp=200
I0916 09:18:51.706721       1 httplog.go:132] "HTTP" verb="GET" URI="/healthz" latency="130.405µs" userAgent="kube-probe/1.27" audit-ID="" srcIP="10.44.0.0:43378" resp=200
I0916 09:18:51.707825       1 httplog.go:132] "HTTP" verb="GET" URI="/healthz" latency="99.246µs" userAgent="kube-probe/1.27" audit-ID="" srcIP="10.44.0.0:43376" resp=200
I0916 09:19:01.702006       1 httplog.go:132] "HTTP" verb="GET" URI="/healthz" latency="146.364µs" userAgent="kube-probe/1.27" audit-ID="" srcIP="10.44.0.0:48750" resp=200
I0916 09:19:01.703113       1 httplog.go:132] "HTTP" verb="GET" URI="/healthz" latency="118.402µs" userAgent="kube-probe/1.27" audit-ID="" srcIP="10.44.0.0:48748" resp=200
I0916 09:19:11.702129       1 httplog.go:132] "HTTP" verb="GET" URI="/healthz" latency="114.014µs" userAgent="kube-probe/1.27" audit-ID="" srcIP="10.44.0.0:50860" resp=200
I0916 09:19:11.703286       1 httplog.go:132] "HTTP" verb="GET" URI="/healthz" latency="62.998µs" userAgent="kube-probe/1.27" audit-ID="" srcIP="10.44.0.0:50866" resp=200
I0916 09:19:21.702679       1 httplog.go:132] "HTTP" verb="GET" URI="/healthz" latency="107.301µs" userAgent="kube-probe/1.27" audit-ID="" srcIP="10.44.0.0:39156" resp=200
I0916 09:19:21.703701       1 httplog.go:132] "HTTP" verb="GET" URI="/healthz" latency="97.473µs" userAgent="kube-probe/1.27" audit-ID="" srcIP="10.44.0.0:39146" resp=200
I0916 09:19:31.706395       1 httplog.go:132] "HTTP" verb="GET" URI="/healthz" latency="135.945µs" userAgent="kube-probe/1.27" audit-ID="" srcIP="10.44.0.0:34178" resp=200
I0916 09:19:31.707541       1 httplog.go:132] "HTTP" verb="GET" URI="/healthz" latency="51.947µs" userAgent="kube-probe/1.27" audit-ID="" srcIP="10.44.0.0:34188" resp=200
I0916 09:19:41.706999       1 httplog.go:132] "HTTP" verb="GET" URI="/healthz" latency="101.42µs" userAgent="kube-probe/1.27" audit-ID="" srcIP="10.44.0.0:37776" resp=200
I0916 09:19:41.708240       1 httplog.go:132] "HTTP" verb="GET" URI="/healthz" latency="117.36µs" userAgent="kube-probe/1.27" audit-ID="" srcIP="10.44.0.0:37774" resp=200
I0916 09:19:51.707588       1 httplog.go:132] "HTTP" verb="GET" URI="/healthz" latency="141.746µs" userAgent="kube-probe/1.27" audit-ID="" srcIP="10.44.0.0:59672" resp=200
I0916 09:19:51.715073       1 httplog.go:132] "HTTP" verb="GET" URI="/healthz" latency="59.451µs" userAgent="kube-probe/1.27" audit-ID="" srcIP="10.44.0.0:59674" resp=200
I0916 09:20:01.707001       1 httplog.go:132] "HTTP" verb="GET" URI="/healthz" latency="93.886µs" userAgent="kube-probe/1.27" audit-ID="" srcIP="10.44.0.0:52366" resp=200
I0916 09:20:01.708129       1 httplog.go:132] "HTTP" verb="GET" URI="/healthz" latency="74.76µs" userAgent="kube-probe/1.27" audit-ID="" srcIP="10.44.0.0:52368" resp=200
I0916 09:20:11.702009       1 httplog.go:132] "HTTP" verb="GET" URI="/healthz" latency="111.269µs" userAgent="kube-probe/1.27" audit-ID="" srcIP="10.44.0.0:47550" resp=200
I0916 09:20:11.703176       1 httplog.go:132] "HTTP" verb="GET" URI="/healthz" latency="108.684µs" userAgent="kube-probe/1.27" audit-ID="" srcIP="10.44.0.0:47546" resp=200
I0916 09:20:21.707361       1 httplog.go:132] "HTTP" verb="GET" URI="/healthz" latency="103.875µs" userAgent="kube-probe/1.27" audit-ID="" srcIP="10.44.0.0:47966" resp=200
I0916 09:20:21.708470       1 httplog.go:132] "HTTP" verb="GET" URI="/healthz" latency="104.015µs" userAgent="kube-probe/1.27" audit-ID="" srcIP="10.44.0.0:47950" resp=200
I0916 09:20:31.702188       1 httplog.go:132] "HTTP" verb="GET" URI="/healthz" latency="87.023µs" userAgent="kube-probe/1.27" audit-ID="" srcIP="10.44.0.0:42964" resp=200
I0916 09:20:31.703554       1 httplog.go:132] "HTTP" verb="GET" URI="/healthz" latency="42.98µs" userAgent="kube-probe/1.27" audit-ID="" srcIP="10.44.0.0:42968" resp=200
I0916 09:20:41.702573       1 httplog.go:132] "HTTP" verb="GET" URI="/healthz" latency="126.607µs" userAgent="kube-probe/1.27" audit-ID="" srcIP="10.44.0.0:54050" resp=200
I0916 09:20:41.709922       1 httplog.go:132] "HTTP" verb="GET" URI="/healthz" latency="85.57µs" userAgent="kube-probe/1.27" audit-ID="" srcIP="10.44.0.0:54076" resp=200
I0916 09:20:51.706493       1 httplog.go:132] "HTTP" verb="GET" URI="/healthz" latency="92.794µs" userAgent="kube-probe/1.27" audit-ID="" srcIP="10.44.0.0:55714" resp=200
I0916 09:20:51.707931       1 httplog.go:132] "HTTP" verb="GET" URI="/healthz" latency="55.444µs" userAgent="kube-probe/1.27" audit-ID="" srcIP="10.44.0.0:55724" resp=200
I0916 09:21:01.702252       1 httplog.go:132] "HTTP" verb="GET" URI="/healthz" latency="102.412µs" userAgent="kube-probe/1.27" audit-ID="" srcIP="10.44.0.0:54440" resp=200
I0916 09:21:01.709770       1 httplog.go:132] "HTTP" verb="GET" URI="/healthz" latency="40.666µs" userAgent="kube-probe/1.27" audit-ID="" srcIP="10.44.0.0:54442" resp=200
I0916 09:21:07.872429       1 eventhandlers.go:231] "Delete event for scheduled pod" pod="monitoring/prometheus-prometheus-node-exporter-69wjl"
I0916 09:21:07.876736       1 eventhandlers.go:231] "Delete event for scheduled pod" pod="monitoring/prometheus-prometheus-node-exporter-fl467"
I0916 09:21:07.999687       1 eventhandlers.go:231] "Delete event for scheduled pod" pod="monitoring/prometheus-server-7c9757cccb-2bt6c"
I0916 09:21:08.063603       1 eventhandlers.go:231] "Delete event for scheduled pod" pod="monitoring/prometheus-prometheus-pushgateway-7cb5dd797-jr65b"
I0916 09:21:08.207785       1 eventhandlers.go:231] "Delete event for scheduled pod" pod="monitoring/prometheus-kube-state-metrics-86894fb745-t62x5"
I0916 09:21:11.702614       1 httplog.go:132] "HTTP" verb="GET" URI="/healthz" latency="111.94µs" userAgent="kube-probe/1.27" audit-ID="" srcIP="10.44.0.0:51288" resp=200
I0916 09:21:11.703649       1 httplog.go:132] "HTTP" verb="GET" URI="/healthz" latency="63.769µs" userAgent="kube-probe/1.27" audit-ID="" srcIP="10.44.0.0:51304" resp=200
I0916 09:21:21.707350       1 httplog.go:132] "HTTP" verb="GET" URI="/healthz" latency="93.395µs" userAgent="kube-probe/1.27" audit-ID="" srcIP="10.44.0.0:55312" resp=200
I0916 09:21:21.708508       1 httplog.go:132] "HTTP" verb="GET" URI="/healthz" latency="48.862µs" userAgent="kube-probe/1.27" audit-ID="" srcIP="10.44.0.0:55322" resp=200
I0916 09:21:31.706570       1 httplog.go:132] "HTTP" verb="GET" URI="/healthz" latency="122.61µs" userAgent="kube-probe/1.27" audit-ID="" srcIP="10.44.0.0:42654" resp=200
I0916 09:21:31.707609       1 httplog.go:132] "HTTP" verb="GET" URI="/healthz" latency="51.908µs" userAgent="kube-probe/1.27" audit-ID="" srcIP="10.44.0.0:42644" resp=200
I0916 09:21:40.610409       1 eventhandlers.go:186] "Add event for scheduled pod" pod="monitoring/gpu-exporter-7876f49579-gvlx7"
I0916 09:21:41.702469       1 httplog.go:132] "HTTP" verb="GET" URI="/healthz" latency="98.104µs" userAgent="kube-probe/1.27" audit-ID="" srcIP="10.44.0.0:33960" resp=200
I0916 09:21:41.703589       1 httplog.go:132] "HTTP" verb="GET" URI="/healthz" latency="63.429µs" userAgent="kube-probe/1.27" audit-ID="" srcIP="10.44.0.0:33966" resp=200
I0916 09:21:41.797376       1 eventhandlers.go:231] "Delete event for scheduled pod" pod="monitoring/gpu-exporter-7876f49579-xjh6t"
I0916 09:21:51.702996       1 httplog.go:132] "HTTP" verb="GET" URI="/healthz" latency="121.167µs" userAgent="kube-probe/1.27" audit-ID="" srcIP="10.44.0.0:41882" resp=200
I0916 09:21:51.710589       1 httplog.go:132] "HTTP" verb="GET" URI="/healthz" latency="66.024µs" userAgent="kube-probe/1.27" audit-ID="" srcIP="10.44.0.0:41884" resp=200
I0916 09:22:01.706279       1 httplog.go:132] "HTTP" verb="GET" URI="/healthz" latency="81.853µs" userAgent="kube-probe/1.27" audit-ID="" srcIP="10.44.0.0:54036" resp=200
I0916 09:22:01.707490       1 httplog.go:132] "HTTP" verb="GET" URI="/healthz" latency="77.314µs" userAgent="kube-probe/1.27" audit-ID="" srcIP="10.44.0.0:54040" resp=200
I0916 09:22:11.706750       1 httplog.go:132] "HTTP" verb="GET" URI="/healthz" latency="70.442µs" userAgent="kube-probe/1.27" audit-ID="" srcIP="10.44.0.0:54082" resp=200
I0916 09:22:11.707864       1 httplog.go:132] "HTTP" verb="GET" URI="/healthz" latency="42.029µs" userAgent="kube-probe/1.27" audit-ID="" srcIP="10.44.0.0:54096" resp=200
I0916 09:22:21.702826       1 httplog.go:132] "HTTP" verb="GET" URI="/healthz" latency="118.783µs" userAgent="kube-probe/1.27" audit-ID="" srcIP="10.44.0.0:48406" resp=200
I0916 09:22:21.703931       1 httplog.go:132] "HTTP" verb="GET" URI="/healthz" latency="76.283µs" userAgent="kube-probe/1.27" audit-ID="" srcIP="10.44.0.0:48396" resp=200
I0916 09:22:31.702078       1 httplog.go:132] "HTTP" verb="GET" URI="/healthz" latency="118.773µs" userAgent="kube-probe/1.27" audit-ID="" srcIP="10.44.0.0:53830" resp=200
I0916 09:22:31.703359       1 httplog.go:132] "HTTP" verb="GET" URI="/healthz" latency="139.972µs" userAgent="kube-probe/1.27" audit-ID="" srcIP="10.44.0.0:53816" resp=200
I0916 09:22:41.702847       1 httplog.go:132] "HTTP" verb="GET" URI="/healthz" latency="106.64µs" userAgent="kube-probe/1.27" audit-ID="" srcIP="10.44.0.0:50644" resp=200
I0916 09:22:41.703886       1 httplog.go:132] "HTTP" verb="GET" URI="/healthz" latency="105.327µs" userAgent="kube-probe/1.27" audit-ID="" srcIP="10.44.0.0:50652" resp=200
I0916 09:22:51.707387       1 httplog.go:132] "HTTP" verb="GET" URI="/healthz" latency="89.238µs" userAgent="kube-probe/1.27" audit-ID="" srcIP="10.44.0.0:40564" resp=200
I0916 09:22:51.708567       1 httplog.go:132] "HTTP" verb="GET" URI="/healthz" latency="109.044µs" userAgent="kube-probe/1.27" audit-ID="" srcIP="10.44.0.0:40570" resp=200
I0916 09:23:00.561674       1 eventhandlers.go:186] "Add event for scheduled pod" pod="monitoring/prometheus-prometheus-node-exporter-5bknn"
I0916 09:23:00.565607       1 eventhandlers.go:186] "Add event for scheduled pod" pod="monitoring/prometheus-prometheus-pushgateway-7cb5dd797-jt44l"
I0916 09:23:00.572835       1 eventhandlers.go:186] "Add event for scheduled pod" pod="monitoring/prometheus-kube-state-metrics-86894fb745-bjjxr"
I0916 09:23:00.573890       1 eventhandlers.go:186] "Add event for scheduled pod" pod="monitoring/prometheus-prometheus-node-exporter-qfk4p"
I0916 09:23:01.706135       1 httplog.go:132] "HTTP" verb="GET" URI="/healthz" latency="116.278µs" userAgent="kube-probe/1.27" audit-ID="" srcIP="10.44.0.0:50550" resp=200
I0916 09:23:01.706819       1 httplog.go:132] "HTTP" verb="GET" URI="/healthz" latency="63.268µs" userAgent="kube-probe/1.27" audit-ID="" srcIP="10.44.0.0:50540" resp=200
I0916 09:23:11.701560       1 httplog.go:132] "HTTP" verb="GET" URI="/healthz" latency="91.001µs" userAgent="kube-probe/1.27" audit-ID="" srcIP="10.44.0.0:33020" resp=200
I0916 09:23:11.702655       1 httplog.go:132] "HTTP" verb="GET" URI="/healthz" latency="92.483µs" userAgent="kube-probe/1.27" audit-ID="" srcIP="10.44.0.0:33030" resp=200
I0916 09:23:21.707289       1 httplog.go:132] "HTTP" verb="GET" URI="/healthz" latency="119.234µs" userAgent="kube-probe/1.27" audit-ID="" srcIP="10.44.0.0:55708" resp=200
I0916 09:23:21.708152       1 httplog.go:132] "HTTP" verb="GET" URI="/healthz" latency="53.48µs" userAgent="kube-probe/1.27" audit-ID="" srcIP="10.44.0.0:55718" resp=200
I0916 09:23:31.707297       1 httplog.go:132] "HTTP" verb="GET" URI="/healthz" latency="127.86µs" userAgent="kube-probe/1.27" audit-ID="" srcIP="10.44.0.0:41908" resp=200
I0916 09:23:31.708414       1 httplog.go:132] "HTTP" verb="GET" URI="/healthz" latency="85.129µs" userAgent="kube-probe/1.27" audit-ID="" srcIP="10.44.0.0:41924" resp=200
I0916 09:23:41.702043       1 httplog.go:132] "HTTP" verb="GET" URI="/healthz" latency="110.407µs" userAgent="kube-probe/1.27" audit-ID="" srcIP="10.44.0.0:50360" resp=200
I0916 09:23:41.703215       1 httplog.go:132] "HTTP" verb="GET" URI="/healthz" latency="80.151µs" userAgent="kube-probe/1.27" audit-ID="" srcIP="10.44.0.0:50374" resp=200
I0916 09:23:51.707119       1 httplog.go:132] "HTTP" verb="GET" URI="/healthz" latency="105.288µs" userAgent="kube-probe/1.27" audit-ID="" srcIP="10.44.0.0:45224" resp=200
I0916 09:23:51.708230       1 httplog.go:132] "HTTP" verb="GET" URI="/healthz" latency="70.722µs" userAgent="kube-probe/1.27" audit-ID="" srcIP="10.44.0.0:45236" resp=200
I0916 09:24:01.707213       1 httplog.go:132] "HTTP" verb="GET" URI="/healthz" latency="108.092µs" userAgent="kube-probe/1.27" audit-ID="" srcIP="10.44.0.0:43830" resp=200
I0916 09:24:01.708386       1 httplog.go:132] "HTTP" verb="GET" URI="/healthz" latency="134.091µs" userAgent="kube-probe/1.27" audit-ID="" srcIP="10.44.0.0:43826" resp=200
I0916 09:24:11.702615       1 httplog.go:132] "HTTP" verb="GET" URI="/healthz" latency="79.309µs" userAgent="kube-probe/1.27" audit-ID="" srcIP="10.44.0.0:34012" resp=200
I0916 09:24:11.710246       1 httplog.go:132] "HTTP" verb="GET" URI="/healthz" latency="83.907µs" userAgent="kube-probe/1.27" audit-ID="" srcIP="10.44.0.0:34014" resp=200
I0916 09:24:21.707194       1 httplog.go:132] "HTTP" verb="GET" URI="/healthz" latency="144.881µs" userAgent="kube-probe/1.27" audit-ID="" srcIP="10.44.0.0:39152" resp=200
I0916 09:24:21.708144       1 httplog.go:132] "HTTP" verb="GET" URI="/healthz" latency="40.076µs" userAgent="kube-probe/1.27" audit-ID="" srcIP="10.44.0.0:39154" resp=200
I0916 09:24:31.702401       1 httplog.go:132] "HTTP" verb="GET" URI="/healthz" latency="129.002µs" userAgent="kube-probe/1.27" audit-ID="" srcIP="10.44.0.0:41546" resp=200
I0916 09:24:31.703475       1 httplog.go:132] "HTTP" verb="GET" URI="/healthz" latency="115.657µs" userAgent="kube-probe/1.27" audit-ID="" srcIP="10.44.0.0:41532" resp=200
I0916 09:24:41.699456       1 httplog.go:132] "HTTP" verb="GET" URI="/healthz" latency="90.57µs" userAgent="kube-probe/1.27" audit-ID="" srcIP="10.44.0.0:48994" resp=200
I0916 09:24:41.702620       1 httplog.go:132] "HTTP" verb="GET" URI="/healthz" latency="61.355µs" userAgent="kube-probe/1.27" audit-ID="" srcIP="10.44.0.0:48984" resp=200
I0916 09:24:51.706364       1 httplog.go:132] "HTTP" verb="GET" URI="/healthz" latency="66.495µs" userAgent="kube-probe/1.27" audit-ID="" srcIP="10.44.0.0:51022" resp=200
I0916 09:24:51.707578       1 httplog.go:132] "HTTP" verb="GET" URI="/healthz" latency="37.71µs" userAgent="kube-probe/1.27" audit-ID="" srcIP="10.44.0.0:51036" resp=200
I0916 09:25:01.707468       1 httplog.go:132] "HTTP" verb="GET" URI="/healthz" latency="182.713µs" userAgent="kube-probe/1.27" audit-ID="" srcIP="10.44.0.0:58968" resp=200
I0916 09:25:01.708228       1 httplog.go:132] "HTTP" verb="GET" URI="/healthz" latency="93.234µs" userAgent="kube-probe/1.27" audit-ID="" srcIP="10.44.0.0:58982" resp=200
I0916 09:25:11.706993       1 httplog.go:132] "HTTP" verb="GET" URI="/healthz" latency="115.967µs" userAgent="kube-probe/1.27" audit-ID="" srcIP="10.44.0.0:39872" resp=200
I0916 09:25:11.708197       1 httplog.go:132] "HTTP" verb="GET" URI="/healthz" latency="69.15µs" userAgent="kube-probe/1.27" audit-ID="" srcIP="10.44.0.0:39878" resp=200
I0916 09:25:21.702541       1 httplog.go:132] "HTTP" verb="GET" URI="/healthz" latency="115.676µs" userAgent="kube-probe/1.27" audit-ID="" srcIP="10.44.0.0:52590" resp=200
I0916 09:25:21.703607       1 httplog.go:132] "HTTP" verb="GET" URI="/healthz" latency="54.652µs" userAgent="kube-probe/1.27" audit-ID="" srcIP="10.44.0.0:52588" resp=200
I0916 09:25:31.702314       1 httplog.go:132] "HTTP" verb="GET" URI="/healthz" latency="127.749µs" userAgent="kube-probe/1.27" audit-ID="" srcIP="10.44.0.0:41274" resp=200
I0916 09:25:31.710124       1 httplog.go:132] "HTTP" verb="GET" URI="/healthz" latency="104.145µs" userAgent="kube-probe/1.27" audit-ID="" srcIP="10.44.0.0:41282" resp=200
I0916 09:25:35.043337       1 eventhandlers.go:231] "Delete event for scheduled pod" pod="monitoring/prometheus-prometheus-node-exporter-qfk4p"
I0916 09:25:35.084107       1 eventhandlers.go:231] "Delete event for scheduled pod" pod="monitoring/prometheus-prometheus-node-exporter-5bknn"
I0916 09:25:35.241973       1 eventhandlers.go:231] "Delete event for scheduled pod" pod="monitoring/prometheus-kube-state-metrics-86894fb745-bjjxr"
I0916 09:25:35.380773       1 eventhandlers.go:231] "Delete event for scheduled pod" pod="monitoring/prometheus-prometheus-pushgateway-7cb5dd797-jt44l"
I0916 09:25:41.707075       1 httplog.go:132] "HTTP" verb="GET" URI="/healthz" latency="93.315µs" userAgent="kube-probe/1.27" audit-ID="" srcIP="10.44.0.0:41582" resp=200
I0916 09:25:41.708171       1 httplog.go:132] "HTTP" verb="GET" URI="/healthz" latency="47.849µs" userAgent="kube-probe/1.27" audit-ID="" srcIP="10.44.0.0:41598" resp=200
I0916 09:25:51.706937       1 httplog.go:132] "HTTP" verb="GET" URI="/healthz" latency="91.932µs" userAgent="kube-probe/1.27" audit-ID="" srcIP="10.44.0.0:60900" resp=200
I0916 09:25:51.708085       1 httplog.go:132] "HTTP" verb="GET" URI="/healthz" latency="63.79µs" userAgent="kube-probe/1.27" audit-ID="" srcIP="10.44.0.0:60904" resp=200
I0916 09:26:01.707859       1 httplog.go:132] "HTTP" verb="GET" URI="/healthz" latency="119.213µs" userAgent="kube-probe/1.27" audit-ID="" srcIP="10.44.0.0:51626" resp=200
I0916 09:26:01.709082       1 httplog.go:132] "HTTP" verb="GET" URI="/healthz" latency="35.096µs" userAgent="kube-probe/1.27" audit-ID="" srcIP="10.44.0.0:51630" resp=200
I0916 09:26:08.813633       1 eventhandlers.go:186] "Add event for scheduled pod" pod="monitoring/prometheus-prometheus-node-exporter-6xtgn"
I0916 09:26:08.817462       1 eventhandlers.go:186] "Add event for scheduled pod" pod="monitoring/prometheus-kube-state-metrics-86894fb745-fmknk"
I0916 09:26:08.820998       1 eventhandlers.go:186] "Add event for scheduled pod" pod="monitoring/prometheus-prometheus-pushgateway-7cb5dd797-nthlz"
I0916 09:26:08.821254       1 eventhandlers.go:186] "Add event for scheduled pod" pod="monitoring/prometheus-server-7c9757cccb-wscfq"
I0916 09:26:08.822125       1 eventhandlers.go:186] "Add event for scheduled pod" pod="monitoring/prometheus-prometheus-node-exporter-7f5w5"
I0916 09:26:11.707237       1 httplog.go:132] "HTTP" verb="GET" URI="/healthz" latency="97.383µs" userAgent="kube-probe/1.27" audit-ID="" srcIP="10.44.0.0:34418" resp=200
I0916 09:26:11.708204       1 httplog.go:132] "HTTP" verb="GET" URI="/healthz" latency="56.776µs" userAgent="kube-probe/1.27" audit-ID="" srcIP="10.44.0.0:34432" resp=200
I0916 09:26:21.706334       1 httplog.go:132] "HTTP" verb="GET" URI="/healthz" latency="100.478µs" userAgent="kube-probe/1.27" audit-ID="" srcIP="10.44.0.0:45058" resp=200
I0916 09:26:21.707477       1 httplog.go:132] "HTTP" verb="GET" URI="/healthz" latency="50.735µs" userAgent="kube-probe/1.27" audit-ID="" srcIP="10.44.0.0:45048" resp=200
I0916 09:26:31.701782       1 httplog.go:132] "HTTP" verb="GET" URI="/healthz" latency="94.998µs" userAgent="kube-probe/1.27" audit-ID="" srcIP="10.44.0.0:56446" resp=200
I0916 09:26:31.709645       1 httplog.go:132] "HTTP" verb="GET" URI="/healthz" latency="88.445µs" userAgent="kube-probe/1.27" audit-ID="" srcIP="10.44.0.0:56456" resp=200
I0916 09:26:41.703174       1 httplog.go:132] "HTTP" verb="GET" URI="/healthz" latency="103.414µs" userAgent="kube-probe/1.27" audit-ID="" srcIP="10.44.0.0:47304" resp=200
I0916 09:26:41.710840       1 httplog.go:132] "HTTP" verb="GET" URI="/healthz" latency="43.522µs" userAgent="kube-probe/1.27" audit-ID="" srcIP="10.44.0.0:47306" resp=200
I0916 09:26:51.701864       1 httplog.go:132] "HTTP" verb="GET" URI="/healthz" latency="95.96µs" userAgent="kube-probe/1.27" audit-ID="" srcIP="10.44.0.0:57794" resp=200
I0916 09:26:51.702003       1 httplog.go:132] "HTTP" verb="GET" URI="/healthz" latency="69.831µs" userAgent="kube-probe/1.27" audit-ID="" srcIP="10.44.0.0:57808" resp=200
I0916 09:27:01.706761       1 httplog.go:132] "HTTP" verb="GET" URI="/healthz" latency="88.105µs" userAgent="kube-probe/1.27" audit-ID="" srcIP="10.44.0.0:47582" resp=200
I0916 09:27:01.707905       1 httplog.go:132] "HTTP" verb="GET" URI="/healthz" latency="69.17µs" userAgent="kube-probe/1.27" audit-ID="" srcIP="10.44.0.0:47598" resp=200
I0916 09:27:11.702385       1 httplog.go:132] "HTTP" verb="GET" URI="/healthz" latency="199.574µs" userAgent="kube-probe/1.27" audit-ID="" srcIP="10.44.0.0:51968" resp=200
I0916 09:27:11.709964       1 httplog.go:132] "HTTP" verb="GET" URI="/healthz" latency="98.985µs" userAgent="kube-probe/1.27" audit-ID="" srcIP="10.44.0.0:51980" resp=200
I0916 09:27:21.707152       1 httplog.go:132] "HTTP" verb="GET" URI="/healthz" latency="115.907µs" userAgent="kube-probe/1.27" audit-ID="" srcIP="10.44.0.0:48022" resp=200
I0916 09:27:21.708341       1 httplog.go:132] "HTTP" verb="GET" URI="/healthz" latency="66.164µs" userAgent="kube-probe/1.27" audit-ID="" srcIP="10.44.0.0:48014" resp=200
I0916 09:27:31.706373       1 httplog.go:132] "HTTP" verb="GET" URI="/healthz" latency="73.949µs" userAgent="kube-probe/1.27" audit-ID="" srcIP="10.44.0.0:36664" resp=200
I0916 09:27:31.707456       1 httplog.go:132] "HTTP" verb="GET" URI="/healthz" latency="23.514µs" userAgent="kube-probe/1.27" audit-ID="" srcIP="10.44.0.0:36650" resp=200
I0916 09:27:41.706624       1 httplog.go:132] "HTTP" verb="GET" URI="/healthz" latency="77.254µs" userAgent="kube-probe/1.27" audit-ID="" srcIP="10.44.0.0:35456" resp=200
I0916 09:27:41.710840       1 httplog.go:132] "HTTP" verb="GET" URI="/healthz" latency="49.473µs" userAgent="kube-probe/1.27" audit-ID="" srcIP="10.44.0.0:35460" resp=200
I0916 09:27:51.706716       1 httplog.go:132] "HTTP" verb="GET" URI="/healthz" latency="80.691µs" userAgent="kube-probe/1.27" audit-ID="" srcIP="10.44.0.0:52860" resp=200
I0916 09:27:51.711244       1 httplog.go:132] "HTTP" verb="GET" URI="/healthz" latency="49.323µs" userAgent="kube-probe/1.27" audit-ID="" srcIP="10.44.0.0:52878" resp=200
I0916 09:28:01.706247       1 httplog.go:132] "HTTP" verb="GET" URI="/healthz" latency="79.629µs" userAgent="kube-probe/1.27" audit-ID="" srcIP="10.44.0.0:54364" resp=200
I0916 09:28:01.707489       1 httplog.go:132] "HTTP" verb="GET" URI="/healthz" latency="61.796µs" userAgent="kube-probe/1.27" audit-ID="" srcIP="10.44.0.0:54380" resp=200
I0916 09:28:11.702560       1 httplog.go:132] "HTTP" verb="GET" URI="/healthz" latency="100.158µs" userAgent="kube-probe/1.27" audit-ID="" srcIP="10.44.0.0:54200" resp=200
I0916 09:28:11.702793       1 httplog.go:132] "HTTP" verb="GET" URI="/healthz" latency="91.341µs" userAgent="kube-probe/1.27" audit-ID="" srcIP="10.44.0.0:54184" resp=200
I0916 09:28:21.701741       1 httplog.go:132] "HTTP" verb="GET" URI="/healthz" latency="85.36µs" userAgent="kube-probe/1.27" audit-ID="" srcIP="10.44.0.0:42732" resp=200
I0916 09:28:21.709011       1 httplog.go:132] "HTTP" verb="GET" URI="/healthz" latency="39.825µs" userAgent="kube-probe/1.27" audit-ID="" srcIP="10.44.0.0:42734" resp=200
I0916 09:28:31.706850       1 httplog.go:132] "HTTP" verb="GET" URI="/healthz" latency="102.883µs" userAgent="kube-probe/1.27" audit-ID="" srcIP="10.44.0.0:50730" resp=200
I0916 09:28:31.707892       1 httplog.go:132] "HTTP" verb="GET" URI="/healthz" latency="66.615µs" userAgent="kube-probe/1.27" audit-ID="" srcIP="10.44.0.0:50732" resp=200
I0916 09:28:41.706557       1 httplog.go:132] "HTTP" verb="GET" URI="/healthz" latency="104.837µs" userAgent="kube-probe/1.27" audit-ID="" srcIP="10.44.0.0:38674" resp=200
I0916 09:28:41.708384       1 httplog.go:132] "HTTP" verb="GET" URI="/healthz" latency="55.314µs" userAgent="kube-probe/1.27" audit-ID="" srcIP="10.44.0.0:38672" resp=200
I0916 09:28:51.706975       1 httplog.go:132] "HTTP" verb="GET" URI="/healthz" latency="116.839µs" userAgent="kube-probe/1.27" audit-ID="" srcIP="10.44.0.0:50122" resp=200
I0916 09:28:51.708026       1 httplog.go:132] "HTTP" verb="GET" URI="/healthz" latency="69.4µs" userAgent="kube-probe/1.27" audit-ID="" srcIP="10.44.0.0:50136" resp=200
I0916 09:29:01.706638       1 httplog.go:132] "HTTP" verb="GET" URI="/healthz" latency="94.638µs" userAgent="kube-probe/1.27" audit-ID="" srcIP="10.44.0.0:48720" resp=200
I0916 09:29:01.707740       1 httplog.go:132] "HTTP" verb="GET" URI="/healthz" latency="120.275µs" userAgent="kube-probe/1.27" audit-ID="" srcIP="10.44.0.0:48728" resp=200
I0916 09:29:11.707321       1 httplog.go:132] "HTTP" verb="GET" URI="/healthz" latency="142.397µs" userAgent="kube-probe/1.27" audit-ID="" srcIP="10.44.0.0:51870" resp=200
I0916 09:29:11.708500       1 httplog.go:132] "HTTP" verb="GET" URI="/healthz" latency="78.287µs" userAgent="kube-probe/1.27" audit-ID="" srcIP="10.44.0.0:51872" resp=200
I0916 09:29:21.702451       1 httplog.go:132] "HTTP" verb="GET" URI="/healthz" latency="98.806µs" userAgent="kube-probe/1.27" audit-ID="" srcIP="10.44.0.0:49968" resp=200
I0916 09:29:21.703326       1 httplog.go:132] "HTTP" verb="GET" URI="/healthz" latency="101.62µs" userAgent="kube-probe/1.27" audit-ID="" srcIP="10.44.0.0:49962" resp=200
I0916 09:29:31.706424       1 httplog.go:132] "HTTP" verb="GET" URI="/healthz" latency="80.241µs" userAgent="kube-probe/1.27" audit-ID="" srcIP="10.44.0.0:55168" resp=200
I0916 09:29:31.707546       1 httplog.go:132] "HTTP" verb="GET" URI="/healthz" latency="75.471µs" userAgent="kube-probe/1.27" audit-ID="" srcIP="10.44.0.0:55178" resp=200
I0916 09:29:41.707250       1 httplog.go:132] "HTTP" verb="GET" URI="/healthz" latency="123.772µs" userAgent="kube-probe/1.27" audit-ID="" srcIP="10.44.0.0:58194" resp=200
I0916 09:29:41.708173       1 httplog.go:132] "HTTP" verb="GET" URI="/healthz" latency="76.393µs" userAgent="kube-probe/1.27" audit-ID="" srcIP="10.44.0.0:58204" resp=200
I0916 09:29:51.707198       1 httplog.go:132] "HTTP" verb="GET" URI="/healthz" latency="105.678µs" userAgent="kube-probe/1.27" audit-ID="" srcIP="10.44.0.0:58310" resp=200
I0916 09:29:51.708362       1 httplog.go:132] "HTTP" verb="GET" URI="/healthz" latency="49.443µs" userAgent="kube-probe/1.27" audit-ID="" srcIP="10.44.0.0:58324" resp=200
I0916 09:30:01.706799       1 httplog.go:132] "HTTP" verb="GET" URI="/healthz" latency="101.4µs" userAgent="kube-probe/1.27" audit-ID="" srcIP="10.44.0.0:58428" resp=200
I0916 09:30:01.707841       1 httplog.go:132] "HTTP" verb="GET" URI="/healthz" latency="68.168µs" userAgent="kube-probe/1.27" audit-ID="" srcIP="10.44.0.0:58412" resp=200
I0916 09:30:11.701124       1 httplog.go:132] "HTTP" verb="GET" URI="/healthz" latency="94.437µs" userAgent="kube-probe/1.27" audit-ID="" srcIP="10.44.0.0:58516" resp=200
I0916 09:30:11.702538       1 httplog.go:132] "HTTP" verb="GET" URI="/healthz" latency="59.892µs" userAgent="kube-probe/1.27" audit-ID="" srcIP="10.44.0.0:58512" resp=200
I0916 09:30:21.706603       1 httplog.go:132] "HTTP" verb="GET" URI="/healthz" latency="106.74µs" userAgent="kube-probe/1.27" audit-ID="" srcIP="10.44.0.0:59520" resp=200
I0916 09:30:21.707819       1 httplog.go:132] "HTTP" verb="GET" URI="/healthz" latency="107.973µs" userAgent="kube-probe/1.27" audit-ID="" srcIP="10.44.0.0:59522" resp=200
I0916 09:30:31.706911       1 httplog.go:132] "HTTP" verb="GET" URI="/healthz" latency="109.676µs" userAgent="kube-probe/1.27" audit-ID="" srcIP="10.44.0.0:39860" resp=200
I0916 09:30:31.708108       1 httplog.go:132] "HTTP" verb="GET" URI="/healthz" latency="126.838µs" userAgent="kube-probe/1.27" audit-ID="" srcIP="10.44.0.0:39858" resp=200
I0916 09:30:41.707101       1 httplog.go:132] "HTTP" verb="GET" URI="/healthz" latency="99.978µs" userAgent="kube-probe/1.27" audit-ID="" srcIP="10.44.0.0:38968" resp=200
I0916 09:30:41.708159       1 httplog.go:132] "HTTP" verb="GET" URI="/healthz" latency="55.655µs" userAgent="kube-probe/1.27" audit-ID="" srcIP="10.44.0.0:38962" resp=200
I0916 09:30:51.707303       1 httplog.go:132] "HTTP" verb="GET" URI="/healthz" latency="89.718µs" userAgent="kube-probe/1.27" audit-ID="" srcIP="10.44.0.0:33822" resp=200
I0916 09:30:51.708325       1 httplog.go:132] "HTTP" verb="GET" URI="/healthz" latency="40.816µs" userAgent="kube-probe/1.27" audit-ID="" srcIP="10.44.0.0:33826" resp=200
I0916 09:31:01.706587       1 httplog.go:132] "HTTP" verb="GET" URI="/healthz" latency="122.95µs" userAgent="kube-probe/1.27" audit-ID="" srcIP="10.44.0.0:52572" resp=200
I0916 09:31:01.708177       1 httplog.go:132] "HTTP" verb="GET" URI="/healthz" latency="106.56µs" userAgent="kube-probe/1.27" audit-ID="" srcIP="10.44.0.0:52564" resp=200
I0916 09:31:11.702560       1 httplog.go:132] "HTTP" verb="GET" URI="/healthz" latency="108.584µs" userAgent="kube-probe/1.27" audit-ID="" srcIP="10.44.0.0:57222" resp=200
I0916 09:31:11.703785       1 httplog.go:132] "HTTP" verb="GET" URI="/healthz" latency="113.994µs" userAgent="kube-probe/1.27" audit-ID="" srcIP="10.44.0.0:57206" resp=200
I0916 09:31:21.702590       1 httplog.go:132] "HTTP" verb="GET" URI="/healthz" latency="93.866µs" userAgent="kube-probe/1.27" audit-ID="" srcIP="10.44.0.0:60590" resp=200
I0916 09:31:21.710734       1 httplog.go:132] "HTTP" verb="GET" URI="/healthz" latency="89.838µs" userAgent="kube-probe/1.27" audit-ID="" srcIP="10.44.0.0:60602" resp=200
I0916 09:31:31.706998       1 httplog.go:132] "HTTP" verb="GET" URI="/healthz" latency="109.796µs" userAgent="kube-probe/1.27" audit-ID="" srcIP="10.44.0.0:41564" resp=200
I0916 09:31:31.708098       1 httplog.go:132] "HTTP" verb="GET" URI="/healthz" latency="54.833µs" userAgent="kube-probe/1.27" audit-ID="" srcIP="10.44.0.0:41548" resp=200
I0916 09:31:41.706554       1 httplog.go:132] "HTTP" verb="GET" URI="/healthz" latency="102.763µs" userAgent="kube-probe/1.27" audit-ID="" srcIP="10.44.0.0:51052" resp=200
I0916 09:31:41.707720       1 httplog.go:132] "HTTP" verb="GET" URI="/healthz" latency="50.154µs" userAgent="kube-probe/1.27" audit-ID="" srcIP="10.44.0.0:51062" resp=200
I0916 09:31:51.706627       1 httplog.go:132] "HTTP" verb="GET" URI="/healthz" latency="95.459µs" userAgent="kube-probe/1.27" audit-ID="" srcIP="10.44.0.0:33524" resp=200
I0916 09:31:51.707811       1 httplog.go:132] "HTTP" verb="GET" URI="/healthz" latency="89.117µs" userAgent="kube-probe/1.27" audit-ID="" srcIP="10.44.0.0:33518" resp=200
I0916 09:32:01.701087       1 httplog.go:132] "HTTP" verb="GET" URI="/healthz" latency="73.688µs" userAgent="kube-probe/1.27" audit-ID="" srcIP="10.44.0.0:53726" resp=200
I0916 09:32:01.701742       1 httplog.go:132] "HTTP" verb="GET" URI="/healthz" latency="29.194µs" userAgent="kube-probe/1.27" audit-ID="" srcIP="10.44.0.0:53728" resp=200
I0916 09:32:11.703431       1 httplog.go:132] "HTTP" verb="GET" URI="/healthz" latency="107.211µs" userAgent="kube-probe/1.27" audit-ID="" srcIP="10.44.0.0:39462" resp=200
I0916 09:32:11.704682       1 httplog.go:132] "HTTP" verb="GET" URI="/healthz" latency="111.058µs" userAgent="kube-probe/1.27" audit-ID="" srcIP="10.44.0.0:39470" resp=200
I0916 09:32:21.702635       1 httplog.go:132] "HTTP" verb="GET" URI="/healthz" latency="102.081µs" userAgent="kube-probe/1.27" audit-ID="" srcIP="10.44.0.0:56762" resp=200
I0916 09:32:21.703868       1 httplog.go:132] "HTTP" verb="GET" URI="/healthz" latency="56.546µs" userAgent="kube-probe/1.27" audit-ID="" srcIP="10.44.0.0:56746" resp=200
I0916 09:32:31.706571       1 httplog.go:132] "HTTP" verb="GET" URI="/healthz" latency="122.249µs" userAgent="kube-probe/1.27" audit-ID="" srcIP="10.44.0.0:38688" resp=200
I0916 09:32:31.707702       1 httplog.go:132] "HTTP" verb="GET" URI="/healthz" latency="97.743µs" userAgent="kube-probe/1.27" audit-ID="" srcIP="10.44.0.0:38700" resp=200
I0916 09:32:41.702111       1 httplog.go:132] "HTTP" verb="GET" URI="/healthz" latency="127.399µs" userAgent="kube-probe/1.27" audit-ID="" srcIP="10.44.0.0:36342" resp=200
I0916 09:32:41.703064       1 httplog.go:132] "HTTP" verb="GET" URI="/healthz" latency="48.932µs" userAgent="kube-probe/1.27" audit-ID="" srcIP="10.44.0.0:36334" resp=200
I0916 09:32:51.701988       1 httplog.go:132] "HTTP" verb="GET" URI="/healthz" latency="132.298µs" userAgent="kube-probe/1.27" audit-ID="" srcIP="10.44.0.0:36194" resp=200
I0916 09:32:51.707677       1 httplog.go:132] "HTTP" verb="GET" URI="/healthz" latency="69.691µs" userAgent="kube-probe/1.27" audit-ID="" srcIP="10.44.0.0:36206" resp=200
I0916 09:33:01.701334       1 httplog.go:132] "HTTP" verb="GET" URI="/healthz" latency="184.626µs" userAgent="kube-probe/1.27" audit-ID="" srcIP="10.44.0.0:56316" resp=200
I0916 09:33:01.702539       1 httplog.go:132] "HTTP" verb="GET" URI="/healthz" latency="186.92µs" userAgent="kube-probe/1.27" audit-ID="" srcIP="10.44.0.0:56318" resp=200
I0916 09:33:11.703277       1 httplog.go:132] "HTTP" verb="GET" URI="/healthz" latency="108.995µs" userAgent="kube-probe/1.27" audit-ID="" srcIP="10.44.0.0:38522" resp=200
I0916 09:33:11.710748       1 httplog.go:132] "HTTP" verb="GET" URI="/healthz" latency="130.976µs" userAgent="kube-probe/1.27" audit-ID="" srcIP="10.44.0.0:38552" resp=200
I0916 09:33:21.707297       1 httplog.go:132] "HTTP" verb="GET" URI="/healthz" latency="140.313µs" userAgent="kube-probe/1.27" audit-ID="" srcIP="10.44.0.0:56130" resp=200
I0916 09:33:21.708491       1 httplog.go:132] "HTTP" verb="GET" URI="/healthz" latency="100.058µs" userAgent="kube-probe/1.27" audit-ID="" srcIP="10.44.0.0:56120" resp=200
I0916 09:33:31.706278       1 httplog.go:132] "HTTP" verb="GET" URI="/healthz" latency="144.491µs" userAgent="kube-probe/1.27" audit-ID="" srcIP="10.44.0.0:46660" resp=200
I0916 09:33:31.707535       1 httplog.go:132] "HTTP" verb="GET" URI="/healthz" latency="90.82µs" userAgent="kube-probe/1.27" audit-ID="" srcIP="10.44.0.0:46644" resp=200
I0916 09:33:41.707071       1 httplog.go:132] "HTTP" verb="GET" URI="/healthz" latency="132.849µs" userAgent="kube-probe/1.27" audit-ID="" srcIP="10.44.0.0:49892" resp=200
I0916 09:33:41.708172       1 httplog.go:132] "HTTP" verb="GET" URI="/healthz" latency="89.488µs" userAgent="kube-probe/1.27" audit-ID="" srcIP="10.44.0.0:49886" resp=200
I0916 09:33:51.706871       1 httplog.go:132] "HTTP" verb="GET" URI="/healthz" latency="133.58µs" userAgent="kube-probe/1.27" audit-ID="" srcIP="10.44.0.0:57796" resp=200
I0916 09:33:51.707901       1 httplog.go:132] "HTTP" verb="GET" URI="/healthz" latency="61.315µs" userAgent="kube-probe/1.27" audit-ID="" srcIP="10.44.0.0:57808" resp=200
I0916 09:34:01.707204       1 httplog.go:132] "HTTP" verb="GET" URI="/healthz" latency="137.488µs" userAgent="kube-probe/1.27" audit-ID="" srcIP="10.44.0.0:38958" resp=200
I0916 09:34:01.708282       1 httplog.go:132] "HTTP" verb="GET" URI="/healthz" latency="51.346µs" userAgent="kube-probe/1.27" audit-ID="" srcIP="10.44.0.0:38956" resp=200
I0916 09:34:11.706825       1 httplog.go:132] "HTTP" verb="GET" URI="/healthz" latency="102.442µs" userAgent="kube-probe/1.27" audit-ID="" srcIP="10.44.0.0:33736" resp=200
I0916 09:34:11.712314       1 httplog.go:132] "HTTP" verb="GET" URI="/healthz" latency="24.466µs" userAgent="kube-probe/1.27" audit-ID="" srcIP="10.44.0.0:33748" resp=200
I0916 09:34:21.706968       1 httplog.go:132] "HTTP" verb="GET" URI="/healthz" latency="132.919µs" userAgent="kube-probe/1.27" audit-ID="" srcIP="10.44.0.0:50050" resp=200
I0916 09:34:21.707971       1 httplog.go:132] "HTTP" verb="GET" URI="/healthz" latency="76.594µs" userAgent="kube-probe/1.27" audit-ID="" srcIP="10.44.0.0:50046" resp=200
I0916 09:34:31.706259       1 httplog.go:132] "HTTP" verb="GET" URI="/healthz" latency="95.89µs" userAgent="kube-probe/1.27" audit-ID="" srcIP="10.44.0.0:46558" resp=200
I0916 09:34:31.707339       1 httplog.go:132] "HTTP" verb="GET" URI="/healthz" latency="47.249µs" userAgent="kube-probe/1.27" audit-ID="" srcIP="10.44.0.0:46550" resp=200
I0916 09:34:41.707997       1 httplog.go:132] "HTTP" verb="GET" URI="/healthz" latency="101.67µs" userAgent="kube-probe/1.27" audit-ID="" srcIP="10.44.0.0:43664" resp=200
I0916 09:34:41.709199       1 httplog.go:132] "HTTP" verb="GET" URI="/healthz" latency="126.948µs" userAgent="kube-probe/1.27" audit-ID="" srcIP="10.44.0.0:43676" resp=200
I0916 09:34:51.700126       1 httplog.go:132] "HTTP" verb="GET" URI="/healthz" latency="101.891µs" userAgent="kube-probe/1.27" audit-ID="" srcIP="10.44.0.0:46956" resp=200
I0916 09:34:51.702641       1 httplog.go:132] "HTTP" verb="GET" URI="/healthz" latency="113.122µs" userAgent="kube-probe/1.27" audit-ID="" srcIP="10.44.0.0:46962" resp=200
I0916 09:35:01.706471       1 httplog.go:132] "HTTP" verb="GET" URI="/healthz" latency="181.691µs" userAgent="kube-probe/1.27" audit-ID="" srcIP="10.44.0.0:53246" resp=200
I0916 09:35:01.707460       1 httplog.go:132] "HTTP" verb="GET" URI="/healthz" latency="86.252µs" userAgent="kube-probe/1.27" audit-ID="" srcIP="10.44.0.0:53236" resp=200
I0916 09:35:11.706601       1 httplog.go:132] "HTTP" verb="GET" URI="/healthz" latency="100.418µs" userAgent="kube-probe/1.27" audit-ID="" srcIP="10.44.0.0:39024" resp=200
I0916 09:35:11.707636       1 httplog.go:132] "HTTP" verb="GET" URI="/healthz" latency="63.419µs" userAgent="kube-probe/1.27" audit-ID="" srcIP="10.44.0.0:39038" resp=200
I0916 09:35:21.701712       1 httplog.go:132] "HTTP" verb="GET" URI="/healthz" latency="112.07µs" userAgent="kube-probe/1.27" audit-ID="" srcIP="10.44.0.0:40960" resp=200
I0916 09:35:21.702700       1 httplog.go:132] "HTTP" verb="GET" URI="/healthz" latency="49.513µs" userAgent="kube-probe/1.27" audit-ID="" srcIP="10.44.0.0:40972" resp=200
I0916 09:35:31.702313       1 httplog.go:132] "HTTP" verb="GET" URI="/healthz" latency="96.782µs" userAgent="kube-probe/1.27" audit-ID="" srcIP="10.44.0.0:51692" resp=200
I0916 09:35:31.709682       1 httplog.go:132] "HTTP" verb="GET" URI="/healthz" latency="49.773µs" userAgent="kube-probe/1.27" audit-ID="" srcIP="10.44.0.0:51708" resp=200
I0916 09:35:41.701365       1 httplog.go:132] "HTTP" verb="GET" URI="/healthz" latency="114.434µs" userAgent="kube-probe/1.27" audit-ID="" srcIP="10.44.0.0:35212" resp=200
I0916 09:35:41.702739       1 httplog.go:132] "HTTP" verb="GET" URI="/healthz" latency="105.648µs" userAgent="kube-probe/1.27" audit-ID="" srcIP="10.44.0.0:35202" resp=200
I0916 09:35:51.702971       1 httplog.go:132] "HTTP" verb="GET" URI="/healthz" latency="123.451µs" userAgent="kube-probe/1.27" audit-ID="" srcIP="10.44.0.0:44420" resp=200
I0916 09:35:51.710806       1 httplog.go:132] "HTTP" verb="GET" URI="/healthz" latency="36.609µs" userAgent="kube-probe/1.27" audit-ID="" srcIP="10.44.0.0:44432" resp=200
I0916 09:36:01.707436       1 httplog.go:132] "HTTP" verb="GET" URI="/healthz" latency="118.762µs" userAgent="kube-probe/1.27" audit-ID="" srcIP="10.44.0.0:59514" resp=200
I0916 09:36:01.708736       1 httplog.go:132] "HTTP" verb="GET" URI="/healthz" latency="51.175µs" userAgent="kube-probe/1.27" audit-ID="" srcIP="10.44.0.0:59502" resp=200
I0916 09:36:11.707005       1 httplog.go:132] "HTTP" verb="GET" URI="/healthz" latency="106.79µs" userAgent="kube-probe/1.27" audit-ID="" srcIP="10.44.0.0:46316" resp=200
I0916 09:36:11.708309       1 httplog.go:132] "HTTP" verb="GET" URI="/healthz" latency="152.366µs" userAgent="kube-probe/1.27" audit-ID="" srcIP="10.44.0.0:46310" resp=200
I0916 09:36:21.707084       1 httplog.go:132] "HTTP" verb="GET" URI="/healthz" latency="97.673µs" userAgent="kube-probe/1.27" audit-ID="" srcIP="10.44.0.0:38960" resp=200
I0916 09:36:21.708171       1 httplog.go:132] "HTTP" verb="GET" URI="/healthz" latency="28.253µs" userAgent="kube-probe/1.27" audit-ID="" srcIP="10.44.0.0:38954" resp=200
I0916 09:36:31.702269       1 httplog.go:132] "HTTP" verb="GET" URI="/healthz" latency="95.809µs" userAgent="kube-probe/1.27" audit-ID="" srcIP="10.44.0.0:42606" resp=200
I0916 09:36:31.709943       1 httplog.go:132] "HTTP" verb="GET" URI="/healthz" latency="104.316µs" userAgent="kube-probe/1.27" audit-ID="" srcIP="10.44.0.0:42608" resp=200
I0916 09:36:41.701969       1 httplog.go:132] "HTTP" verb="GET" URI="/healthz" latency="69.971µs" userAgent="kube-probe/1.27" audit-ID="" srcIP="10.44.0.0:57428" resp=200
I0916 09:36:41.703403       1 httplog.go:132] "HTTP" verb="GET" URI="/healthz" latency="94.247µs" userAgent="kube-probe/1.27" audit-ID="" srcIP="10.44.0.0:57420" resp=200
I0916 09:36:51.702901       1 httplog.go:132] "HTTP" verb="GET" URI="/healthz" latency="99.026µs" userAgent="kube-probe/1.27" audit-ID="" srcIP="10.44.0.0:45846" resp=200
I0916 09:36:51.703992       1 httplog.go:132] "HTTP" verb="GET" URI="/healthz" latency="64.361µs" userAgent="kube-probe/1.27" audit-ID="" srcIP="10.44.0.0:45860" resp=200
I0916 09:37:01.706647       1 httplog.go:132] "HTTP" verb="GET" URI="/healthz" latency="158.657µs" userAgent="kube-probe/1.27" audit-ID="" srcIP="10.44.0.0:36926" resp=200
I0916 09:37:01.707882       1 httplog.go:132] "HTTP" verb="GET" URI="/healthz" latency="131.757µs" userAgent="kube-probe/1.27" audit-ID="" srcIP="10.44.0.0:36938" resp=200
I0916 09:37:11.706964       1 httplog.go:132] "HTTP" verb="GET" URI="/healthz" latency="99.577µs" userAgent="kube-probe/1.27" audit-ID="" srcIP="10.44.0.0:43216" resp=200
I0916 09:37:11.708133       1 httplog.go:132] "HTTP" verb="GET" URI="/healthz" latency="117.08µs" userAgent="kube-probe/1.27" audit-ID="" srcIP="10.44.0.0:43202" resp=200
I0916 09:37:21.702747       1 httplog.go:132] "HTTP" verb="GET" URI="/healthz" latency="116.108µs" userAgent="kube-probe/1.27" audit-ID="" srcIP="10.44.0.0:54230" resp=200
I0916 09:37:21.703952       1 httplog.go:132] "HTTP" verb="GET" URI="/healthz" latency="125.977µs" userAgent="kube-probe/1.27" audit-ID="" srcIP="10.44.0.0:54222" resp=200
I0916 09:37:31.700221       1 httplog.go:132] "HTTP" verb="GET" URI="/healthz" latency="116.658µs" userAgent="kube-probe/1.27" audit-ID="" srcIP="10.44.0.0:45460" resp=200
I0916 09:37:31.701464       1 httplog.go:132] "HTTP" verb="GET" URI="/healthz" latency="62.527µs" userAgent="kube-probe/1.27" audit-ID="" srcIP="10.44.0.0:45466" resp=200
I0916 09:37:41.701936       1 httplog.go:132] "HTTP" verb="GET" URI="/healthz" latency="108.503µs" userAgent="kube-probe/1.27" audit-ID="" srcIP="10.44.0.0:34598" resp=200
I0916 09:37:41.703159       1 httplog.go:132] "HTTP" verb="GET" URI="/healthz" latency="57.959µs" userAgent="kube-probe/1.27" audit-ID="" srcIP="10.44.0.0:34608" resp=200
I0916 09:37:51.702943       1 httplog.go:132] "HTTP" verb="GET" URI="/healthz" latency="90.46µs" userAgent="kube-probe/1.27" audit-ID="" srcIP="10.44.0.0:39066" resp=200
I0916 09:37:51.703263       1 httplog.go:132] "HTTP" verb="GET" URI="/healthz" latency="170.74µs" userAgent="kube-probe/1.27" audit-ID="" srcIP="10.44.0.0:39080" resp=200
I0916 09:38:01.702722       1 httplog.go:132] "HTTP" verb="GET" URI="/healthz" latency="134.181µs" userAgent="kube-probe/1.27" audit-ID="" srcIP="10.44.0.0:39706" resp=200
I0916 09:38:01.703859       1 httplog.go:132] "HTTP" verb="GET" URI="/healthz" latency="142.397µs" userAgent="kube-probe/1.27" audit-ID="" srcIP="10.44.0.0:39702" resp=200
I0916 09:38:11.702149       1 httplog.go:132] "HTTP" verb="GET" URI="/healthz" latency="97.863µs" userAgent="kube-probe/1.27" audit-ID="" srcIP="10.44.0.0:59264" resp=200
I0916 09:38:11.709865       1 httplog.go:132] "HTTP" verb="GET" URI="/healthz" latency="101.771µs" userAgent="kube-probe/1.27" audit-ID="" srcIP="10.44.0.0:59268" resp=200
I0916 09:38:21.703106       1 httplog.go:132] "HTTP" verb="GET" URI="/healthz" latency="141.466µs" userAgent="kube-probe/1.27" audit-ID="" srcIP="10.44.0.0:44670" resp=200
I0916 09:38:21.710862       1 httplog.go:132] "HTTP" verb="GET" URI="/healthz" latency="66.715µs" userAgent="kube-probe/1.27" audit-ID="" srcIP="10.44.0.0:44686" resp=200
I0916 09:38:31.702451       1 httplog.go:132] "HTTP" verb="GET" URI="/healthz" latency="95.118µs" userAgent="kube-probe/1.27" audit-ID="" srcIP="10.44.0.0:42316" resp=200
I0916 09:38:31.703664       1 httplog.go:132] "HTTP" verb="GET" URI="/healthz" latency="114.635µs" userAgent="kube-probe/1.27" audit-ID="" srcIP="10.44.0.0:42302" resp=200
I0916 09:38:41.707097       1 httplog.go:132] "HTTP" verb="GET" URI="/healthz" latency="83.416µs" userAgent="kube-probe/1.27" audit-ID="" srcIP="10.44.0.0:40338" resp=200
I0916 09:38:41.708267       1 httplog.go:132] "HTTP" verb="GET" URI="/healthz" latency="33.022µs" userAgent="kube-probe/1.27" audit-ID="" srcIP="10.44.0.0:40346" resp=200
I0916 09:38:51.702337       1 httplog.go:132] "HTTP" verb="GET" URI="/healthz" latency="97.012µs" userAgent="kube-probe/1.27" audit-ID="" srcIP="10.44.0.0:37704" resp=200
I0916 09:38:51.706837       1 httplog.go:132] "HTTP" verb="GET" URI="/healthz" latency="114.064µs" userAgent="kube-probe/1.27" audit-ID="" srcIP="10.44.0.0:37718" resp=200
I0916 09:39:01.707728       1 httplog.go:132] "HTTP" verb="GET" URI="/healthz" latency="169.318µs" userAgent="kube-probe/1.27" audit-ID="" srcIP="10.44.0.0:34280" resp=200
I0916 09:39:01.708884       1 httplog.go:132] "HTTP" verb="GET" URI="/healthz" latency="82.655µs" userAgent="kube-probe/1.27" audit-ID="" srcIP="10.44.0.0:34282" resp=200
I0916 09:39:11.706331       1 httplog.go:132] "HTTP" verb="GET" URI="/healthz" latency="117.3µs" userAgent="kube-probe/1.27" audit-ID="" srcIP="10.44.0.0:42338" resp=200
I0916 09:39:11.707635       1 httplog.go:132] "HTTP" verb="GET" URI="/healthz" latency="84.619µs" userAgent="kube-probe/1.27" audit-ID="" srcIP="10.44.0.0:42336" resp=200
I0916 09:39:21.700753       1 httplog.go:132] "HTTP" verb="GET" URI="/healthz" latency="67.737µs" userAgent="kube-probe/1.27" audit-ID="" srcIP="10.44.0.0:47346" resp=200
I0916 09:39:21.702221       1 httplog.go:132] "HTTP" verb="GET" URI="/healthz" latency="126.928µs" userAgent="kube-probe/1.27" audit-ID="" srcIP="10.44.0.0:47344" resp=200
I0916 09:39:31.701755       1 httplog.go:132] "HTTP" verb="GET" URI="/healthz" latency="97.432µs" userAgent="kube-probe/1.27" audit-ID="" srcIP="10.44.0.0:35026" resp=200
I0916 09:39:31.702912       1 httplog.go:132] "HTTP" verb="GET" URI="/healthz" latency="56.886µs" userAgent="kube-probe/1.27" audit-ID="" srcIP="10.44.0.0:35036" resp=200
I0916 09:39:41.702776       1 httplog.go:132] "HTTP" verb="GET" URI="/healthz" latency="138.54µs" userAgent="kube-probe/1.27" audit-ID="" srcIP="10.44.0.0:57262" resp=200
I0916 09:39:41.703910       1 httplog.go:132] "HTTP" verb="GET" URI="/healthz" latency="116.789µs" userAgent="kube-probe/1.27" audit-ID="" srcIP="10.44.0.0:57266" resp=200
I0916 09:39:51.707201       1 httplog.go:132] "HTTP" verb="GET" URI="/healthz" latency="87.645µs" userAgent="kube-probe/1.27" audit-ID="" srcIP="10.44.0.0:56840" resp=200
I0916 09:39:51.708709       1 httplog.go:132] "HTTP" verb="GET" URI="/healthz" latency="146.755µs" userAgent="kube-probe/1.27" audit-ID="" srcIP="10.44.0.0:56836" resp=200
I0916 09:40:01.706290       1 httplog.go:132] "HTTP" verb="GET" URI="/healthz" latency="135.564µs" userAgent="kube-probe/1.27" audit-ID="" srcIP="10.44.0.0:37732" resp=200
I0916 09:40:01.707465       1 httplog.go:132] "HTTP" verb="GET" URI="/healthz" latency="93.785µs" userAgent="kube-probe/1.27" audit-ID="" srcIP="10.44.0.0:37730" resp=200
I0916 09:40:11.707039       1 httplog.go:132] "HTTP" verb="GET" URI="/healthz" latency="81.824µs" userAgent="kube-probe/1.27" audit-ID="" srcIP="10.44.0.0:58910" resp=200
I0916 09:40:11.708223       1 httplog.go:132] "HTTP" verb="GET" URI="/healthz" latency="54.592µs" userAgent="kube-probe/1.27" audit-ID="" srcIP="10.44.0.0:58924" resp=200
I0916 09:40:21.706767       1 httplog.go:132] "HTTP" verb="GET" URI="/healthz" latency="105.487µs" userAgent="kube-probe/1.27" audit-ID="" srcIP="10.44.0.0:33202" resp=200
I0916 09:40:21.707945       1 httplog.go:132] "HTTP" verb="GET" URI="/healthz" latency="71.083µs" userAgent="kube-probe/1.27" audit-ID="" srcIP="10.44.0.0:33210" resp=200
I0916 09:40:31.702090       1 httplog.go:132] "HTTP" verb="GET" URI="/healthz" latency="100.067µs" userAgent="kube-probe/1.27" audit-ID="" srcIP="10.44.0.0:55828" resp=200
I0916 09:40:31.703248       1 httplog.go:132] "HTTP" verb="GET" URI="/healthz" latency="91.452µs" userAgent="kube-probe/1.27" audit-ID="" srcIP="10.44.0.0:55814" resp=200
I0916 09:40:41.706555       1 httplog.go:132] "HTTP" verb="GET" URI="/healthz" latency="105.598µs" userAgent="kube-probe/1.27" audit-ID="" srcIP="10.44.0.0:43152" resp=200
I0916 09:40:41.707668       1 httplog.go:132] "HTTP" verb="GET" URI="/healthz" latency="55.474µs" userAgent="kube-probe/1.27" audit-ID="" srcIP="10.44.0.0:43156" resp=200
I0916 09:40:51.706974       1 httplog.go:132] "HTTP" verb="GET" URI="/healthz" latency="121.878µs" userAgent="kube-probe/1.27" audit-ID="" srcIP="10.44.0.0:34360" resp=200
I0916 09:40:51.707932       1 httplog.go:132] "HTTP" verb="GET" URI="/healthz" latency="65.062µs" userAgent="kube-probe/1.27" audit-ID="" srcIP="10.44.0.0:34356" resp=200
I0916 09:41:01.701551       1 httplog.go:132] "HTTP" verb="GET" URI="/healthz" latency="188.493µs" userAgent="kube-probe/1.27" audit-ID="" srcIP="10.44.0.0:48760" resp=200
I0916 09:41:01.702581       1 httplog.go:132] "HTTP" verb="GET" URI="/healthz" latency="130.214µs" userAgent="kube-probe/1.27" audit-ID="" srcIP="10.44.0.0:48770" resp=200
I0916 09:41:11.702242       1 httplog.go:132] "HTTP" verb="GET" URI="/healthz" latency="111.388µs" userAgent="kube-probe/1.27" audit-ID="" srcIP="10.44.0.0:37582" resp=200
I0916 09:41:11.708413       1 httplog.go:132] "HTTP" verb="GET" URI="/healthz" latency="57.608µs" userAgent="kube-probe/1.27" audit-ID="" srcIP="10.44.0.0:37598" resp=200
I0916 09:41:21.702286       1 httplog.go:132] "HTTP" verb="GET" URI="/healthz" latency="116.308µs" userAgent="kube-probe/1.27" audit-ID="" srcIP="10.44.0.0:51852" resp=200
I0916 09:41:21.708506       1 httplog.go:132] "HTTP" verb="GET" URI="/healthz" latency="147.156µs" userAgent="kube-probe/1.27" audit-ID="" srcIP="10.44.0.0:51858" resp=200
I0916 09:41:31.706739       1 httplog.go:132] "HTTP" verb="GET" URI="/healthz" latency="95.148µs" userAgent="kube-probe/1.27" audit-ID="" srcIP="10.44.0.0:59814" resp=200
I0916 09:41:31.707515       1 httplog.go:132] "HTTP" verb="GET" URI="/healthz" latency="53.971µs" userAgent="kube-probe/1.27" audit-ID="" srcIP="10.44.0.0:59818" resp=200
I0916 09:41:41.702105       1 httplog.go:132] "HTTP" verb="GET" URI="/healthz" latency="88.787µs" userAgent="kube-probe/1.27" audit-ID="" srcIP="10.44.0.0:36092" resp=200
I0916 09:41:41.702554       1 httplog.go:132] "HTTP" verb="GET" URI="/healthz" latency="134.453µs" userAgent="kube-probe/1.27" audit-ID="" srcIP="10.44.0.0:36082" resp=200
I0916 09:41:51.706771       1 httplog.go:132] "HTTP" verb="GET" URI="/healthz" latency="94.928µs" userAgent="kube-probe/1.27" audit-ID="" srcIP="10.44.0.0:37318" resp=200
I0916 09:41:51.707931       1 httplog.go:132] "HTTP" verb="GET" URI="/healthz" latency="110.186µs" userAgent="kube-probe/1.27" audit-ID="" srcIP="10.44.0.0:37306" resp=200
I0916 09:42:01.701325       1 httplog.go:132] "HTTP" verb="GET" URI="/healthz" latency="96.621µs" userAgent="kube-probe/1.27" audit-ID="" srcIP="10.44.0.0:43974" resp=200
I0916 09:42:01.702572       1 httplog.go:132] "HTTP" verb="GET" URI="/healthz" latency="98.555µs" userAgent="kube-probe/1.27" audit-ID="" srcIP="10.44.0.0:43968" resp=200
I0916 09:42:11.701034       1 httplog.go:132] "HTTP" verb="GET" URI="/healthz" latency="97.112µs" userAgent="kube-probe/1.27" audit-ID="" srcIP="10.44.0.0:41698" resp=200
I0916 09:42:11.702308       1 httplog.go:132] "HTTP" verb="GET" URI="/healthz" latency="97.663µs" userAgent="kube-probe/1.27" audit-ID="" srcIP="10.44.0.0:41710" resp=200
I0916 09:42:21.702350       1 httplog.go:132] "HTTP" verb="GET" URI="/healthz" latency="108.283µs" userAgent="kube-probe/1.27" audit-ID="" srcIP="10.44.0.0:44718" resp=200
I0916 09:42:21.707060       1 httplog.go:132] "HTTP" verb="GET" URI="/healthz" latency="83.366µs" userAgent="kube-probe/1.27" audit-ID="" srcIP="10.44.0.0:44724" resp=200
I0916 09:42:31.707127       1 httplog.go:132] "HTTP" verb="GET" URI="/healthz" latency="91.341µs" userAgent="kube-probe/1.27" audit-ID="" srcIP="10.44.0.0:38906" resp=200
I0916 09:42:31.708301       1 httplog.go:132] "HTTP" verb="GET" URI="/healthz" latency="97.162µs" userAgent="kube-probe/1.27" audit-ID="" srcIP="10.44.0.0:38890" resp=200
I0916 09:42:41.707635       1 httplog.go:132] "HTTP" verb="GET" URI="/healthz" latency="103.153µs" userAgent="kube-probe/1.27" audit-ID="" srcIP="10.44.0.0:51618" resp=200
I0916 09:42:41.708854       1 httplog.go:132] "HTTP" verb="GET" URI="/healthz" latency="89.538µs" userAgent="kube-probe/1.27" audit-ID="" srcIP="10.44.0.0:51612" resp=200
I0916 09:42:51.700410       1 httplog.go:132] "HTTP" verb="GET" URI="/healthz" latency="105.217µs" userAgent="kube-probe/1.27" audit-ID="" srcIP="10.44.0.0:34090" resp=200
I0916 09:42:51.701966       1 httplog.go:132] "HTTP" verb="GET" URI="/healthz" latency="121.618µs" userAgent="kube-probe/1.27" audit-ID="" srcIP="10.44.0.0:34088" resp=200
I0916 09:43:01.702864       1 httplog.go:132] "HTTP" verb="GET" URI="/healthz" latency="127.228µs" userAgent="kube-probe/1.27" audit-ID="" srcIP="10.44.0.0:55428" resp=200
I0916 09:43:01.710303       1 httplog.go:132] "HTTP" verb="GET" URI="/healthz" latency="57.908µs" userAgent="kube-probe/1.27" audit-ID="" srcIP="10.44.0.0:55436" resp=200
I0916 09:43:11.702423       1 httplog.go:132] "HTTP" verb="GET" URI="/healthz" latency="122.37µs" userAgent="kube-probe/1.27" audit-ID="" srcIP="10.44.0.0:53708" resp=200
I0916 09:43:11.709758       1 httplog.go:132] "HTTP" verb="GET" URI="/healthz" latency="60.554µs" userAgent="kube-probe/1.27" audit-ID="" srcIP="10.44.0.0:53716" resp=200
I0916 09:43:21.699173       1 httplog.go:132] "HTTP" verb="GET" URI="/healthz" latency="103.634µs" userAgent="kube-probe/1.27" audit-ID="" srcIP="10.44.0.0:55242" resp=200
I0916 09:43:21.701374       1 httplog.go:132] "HTTP" verb="GET" URI="/healthz" latency="60.593µs" userAgent="kube-probe/1.27" audit-ID="" srcIP="10.44.0.0:55240" resp=200
I0916 09:43:31.706893       1 httplog.go:132] "HTTP" verb="GET" URI="/healthz" latency="98.765µs" userAgent="kube-probe/1.27" audit-ID="" srcIP="10.44.0.0:48890" resp=200
I0916 09:43:31.708209       1 httplog.go:132] "HTTP" verb="GET" URI="/healthz" latency="75.853µs" userAgent="kube-probe/1.27" audit-ID="" srcIP="10.44.0.0:48886" resp=200
I0916 09:43:41.706833       1 httplog.go:132] "HTTP" verb="GET" URI="/healthz" latency="136.617µs" userAgent="kube-probe/1.27" audit-ID="" srcIP="10.44.0.0:46792" resp=200
I0916 09:43:41.707911       1 httplog.go:132] "HTTP" verb="GET" URI="/healthz" latency="93.696µs" userAgent="kube-probe/1.27" audit-ID="" srcIP="10.44.0.0:46808" resp=200
I0916 09:43:51.702042       1 httplog.go:132] "HTTP" verb="GET" URI="/healthz" latency="91.442µs" userAgent="kube-probe/1.27" audit-ID="" srcIP="10.44.0.0:44576" resp=200
I0916 09:43:51.703196       1 httplog.go:132] "HTTP" verb="GET" URI="/healthz" latency="76.914µs" userAgent="kube-probe/1.27" audit-ID="" srcIP="10.44.0.0:44592" resp=200
I0916 09:44:01.702092       1 httplog.go:132] "HTTP" verb="GET" URI="/healthz" latency="98.194µs" userAgent="kube-probe/1.27" audit-ID="" srcIP="10.44.0.0:51016" resp=200
I0916 09:44:01.703323       1 httplog.go:132] "HTTP" verb="GET" URI="/healthz" latency="76.523µs" userAgent="kube-probe/1.27" audit-ID="" srcIP="10.44.0.0:51004" resp=200
I0916 09:44:11.703277       1 httplog.go:132] "HTTP" verb="GET" URI="/healthz" latency="109.515µs" userAgent="kube-probe/1.27" audit-ID="" srcIP="10.44.0.0:49590" resp=200
I0916 09:44:11.704540       1 httplog.go:132] "HTTP" verb="GET" URI="/healthz" latency="73.327µs" userAgent="kube-probe/1.27" audit-ID="" srcIP="10.44.0.0:49592" resp=200
I0916 09:44:19.782078       1 eventhandlers.go:118] "Add event for unscheduled pod" pod="default/falcon-pod-502950"
I0916 09:44:19.782300       1 schedule_one.go:80] "Attempting to schedule pod" pod="default/falcon-pod-502950"
I0916 09:44:19.782938       1 log.go:194] require 2 gpu(s), and currently has 8 gpus(s) in total
I0916 09:44:19.810613       1 log.go:194] css-host-128 has 4 gpu, the pod requires 2 gpu -> score: 50
I0916 09:44:19.810640       1 log.go:194] css-host-129 has 4 gpu, the pod requires 2 gpu -> score: 50
I0916 09:44:19.811002       1 log.go:194] permit plugin
I0916 09:44:19.815878       1 log.go:194] alloc: 4, used: 0, required: 2
I0916 09:44:19.820026       1 log.go:194] alloc: 4, used: 0, required: 2
I0916 09:44:19.820133       1 default_binder.go:53] "Attempting to bind pod to node" pod="default/falcon-pod-502950" node="css-host-128"
I0916 09:44:19.823884       1 eventhandlers.go:161] "Delete event for unscheduled pod" pod="default/falcon-pod-502950"
I0916 09:44:19.823918       1 eventhandlers.go:186] "Add event for scheduled pod" pod="default/falcon-pod-502950"
I0916 09:44:19.824140       1 schedule_one.go:252] "Successfully bound pod to node" pod="default/falcon-pod-502950" node="css-host-128" evaluatedNodes=2 feasibleNodes=2
I0916 09:44:21.702554       1 httplog.go:132] "HTTP" verb="GET" URI="/healthz" latency="108.343µs" userAgent="kube-probe/1.27" audit-ID="" srcIP="10.44.0.0:60006" resp=200
I0916 09:44:21.702739       1 httplog.go:132] "HTTP" verb="GET" URI="/healthz" latency="102.602µs" userAgent="kube-probe/1.27" audit-ID="" srcIP="10.44.0.0:60012" resp=200
I0916 09:44:31.700098       1 httplog.go:132] "HTTP" verb="GET" URI="/healthz" latency="149.49µs" userAgent="kube-probe/1.27" audit-ID="" srcIP="10.44.0.0:60110" resp=200
I0916 09:44:31.702909       1 httplog.go:132] "HTTP" verb="GET" URI="/healthz" latency="78.537µs" userAgent="kube-probe/1.27" audit-ID="" srcIP="10.44.0.0:60118" resp=200
I0916 09:44:41.707314       1 httplog.go:132] "HTTP" verb="GET" URI="/healthz" latency="106.61µs" userAgent="kube-probe/1.27" audit-ID="" srcIP="10.44.0.0:45126" resp=200
I0916 09:44:41.708698       1 httplog.go:132] "HTTP" verb="GET" URI="/healthz" latency="110.397µs" userAgent="kube-probe/1.27" audit-ID="" srcIP="10.44.0.0:45136" resp=200
I0916 09:44:51.707014       1 httplog.go:132] "HTTP" verb="GET" URI="/healthz" latency="145.923µs" userAgent="kube-probe/1.27" audit-ID="" srcIP="10.44.0.0:55168" resp=200
I0916 09:44:51.709678       1 httplog.go:132] "HTTP" verb="GET" URI="/healthz" latency="89.208µs" userAgent="kube-probe/1.27" audit-ID="" srcIP="10.44.0.0:55178" resp=200
I0916 09:45:01.702494       1 httplog.go:132] "HTTP" verb="GET" URI="/healthz" latency="118.241µs" userAgent="kube-probe/1.27" audit-ID="" srcIP="10.44.0.0:47926" resp=200
I0916 09:45:01.703248       1 httplog.go:132] "HTTP" verb="GET" URI="/healthz" latency="134.122µs" userAgent="kube-probe/1.27" audit-ID="" srcIP="10.44.0.0:47936" resp=200
I0916 09:45:11.707238       1 httplog.go:132] "HTTP" verb="GET" URI="/healthz" latency="152.956µs" userAgent="kube-probe/1.27" audit-ID="" srcIP="10.44.0.0:49518" resp=200
I0916 09:45:11.708230       1 httplog.go:132] "HTTP" verb="GET" URI="/healthz" latency="50.204µs" userAgent="kube-probe/1.27" audit-ID="" srcIP="10.44.0.0:49504" resp=200
I0916 09:45:21.706895       1 httplog.go:132] "HTTP" verb="GET" URI="/healthz" latency="103.413µs" userAgent="kube-probe/1.27" audit-ID="" srcIP="10.44.0.0:60892" resp=200
I0916 09:45:21.708359       1 httplog.go:132] "HTTP" verb="GET" URI="/healthz" latency="135.604µs" userAgent="kube-probe/1.27" audit-ID="" srcIP="10.44.0.0:60898" resp=200
I0916 09:45:31.095100       1 eventhandlers.go:118] "Add event for unscheduled pod" pod="default/falcon-pod-458562"
I0916 09:45:31.095281       1 schedule_one.go:80] "Attempting to schedule pod" pod="default/falcon-pod-458562"
I0916 09:45:31.095919       1 log.go:194] require 4 gpu(s), and currently has 6 gpus(s) in total
I0916 09:45:31.102915       1 log.go:194] css-host-129 has 4 gpu, the pod requires 4 gpu -> score: 1
I0916 09:45:31.103013       1 log.go:194] css-host-128 has 2 gpu, the pod requires 4 gpu -> score: -2
I0916 09:45:31.103259       1 log.go:194] permit plugin
I0916 09:45:31.107682       1 log.go:194] alloc: 4, used: 0, required: 4
I0916 09:45:31.111128       1 log.go:194] alloc: 4, used: 0, required: 4
I0916 09:45:31.111235       1 default_binder.go:53] "Attempting to bind pod to node" pod="default/falcon-pod-458562" node="css-host-129"
I0916 09:45:31.114539       1 schedule_one.go:252] "Successfully bound pod to node" pod="default/falcon-pod-458562" node="css-host-129" evaluatedNodes=2 feasibleNodes=2
I0916 09:45:31.114818       1 eventhandlers.go:161] "Delete event for unscheduled pod" pod="default/falcon-pod-458562"
I0916 09:45:31.114909       1 eventhandlers.go:186] "Add event for scheduled pod" pod="default/falcon-pod-458562"
I0916 09:45:31.706757       1 httplog.go:132] "HTTP" verb="GET" URI="/healthz" latency="129.352µs" userAgent="kube-probe/1.27" audit-ID="" srcIP="10.44.0.0:54436" resp=200
I0916 09:45:31.707865       1 httplog.go:132] "HTTP" verb="GET" URI="/healthz" latency="86.242µs" userAgent="kube-probe/1.27" audit-ID="" srcIP="10.44.0.0:54438" resp=200
I0916 09:45:36.345501       1 eventhandlers.go:231] "Delete event for scheduled pod" pod="default/falcon-pod-458562"
I0916 09:45:41.256082       1 eventhandlers.go:231] "Delete event for scheduled pod" pod="default/falcon-pod-502950"
I0916 09:45:41.707014       1 httplog.go:132] "HTTP" verb="GET" URI="/healthz" latency="145.112µs" userAgent="kube-probe/1.27" audit-ID="" srcIP="10.44.0.0:39474" resp=200
I0916 09:45:41.711461       1 httplog.go:132] "HTTP" verb="GET" URI="/healthz" latency="107.141µs" userAgent="kube-probe/1.27" audit-ID="" srcIP="10.44.0.0:39490" resp=200
I0916 09:45:51.700933       1 httplog.go:132] "HTTP" verb="GET" URI="/healthz" latency="100.458µs" userAgent="kube-probe/1.27" audit-ID="" srcIP="10.44.0.0:55138" resp=200
I0916 09:45:51.702173       1 httplog.go:132] "HTTP" verb="GET" URI="/healthz" latency="28.815µs" userAgent="kube-probe/1.27" audit-ID="" srcIP="10.44.0.0:55122" resp=200
I0916 09:46:01.702225       1 httplog.go:132] "HTTP" verb="GET" URI="/healthz" latency="109.516µs" userAgent="kube-probe/1.27" audit-ID="" srcIP="10.44.0.0:56824" resp=200
I0916 09:46:01.703235       1 httplog.go:132] "HTTP" verb="GET" URI="/healthz" latency="52.108µs" userAgent="kube-probe/1.27" audit-ID="" srcIP="10.44.0.0:56828" resp=200
I0916 09:46:11.702653       1 httplog.go:132] "HTTP" verb="GET" URI="/healthz" latency="98.465µs" userAgent="kube-probe/1.27" audit-ID="" srcIP="10.44.0.0:38216" resp=200
I0916 09:46:11.703991       1 httplog.go:132] "HTTP" verb="GET" URI="/healthz" latency="113.723µs" userAgent="kube-probe/1.27" audit-ID="" srcIP="10.44.0.0:38232" resp=200
I0916 09:46:21.701998       1 httplog.go:132] "HTTP" verb="GET" URI="/healthz" latency="123.932µs" userAgent="kube-probe/1.27" audit-ID="" srcIP="10.44.0.0:52364" resp=200
I0916 09:46:21.709586       1 httplog.go:132] "HTTP" verb="GET" URI="/healthz" latency="103.675µs" userAgent="kube-probe/1.27" audit-ID="" srcIP="10.44.0.0:52378" resp=200
I0916 09:46:26.382723       1 eventhandlers.go:118] "Add event for unscheduled pod" pod="default/falcon-pod-867106"
I0916 09:46:26.382819       1 schedule_one.go:80] "Attempting to schedule pod" pod="default/falcon-pod-867106"
I0916 09:46:26.383377       1 log.go:194] require 4 gpu(s), and currently has 8 gpus(s) in total
I0916 09:46:26.388969       1 log.go:194] css-host-128 has 4 gpu, the pod requires 4 gpu -> score: 1
I0916 09:46:26.389008       1 log.go:194] css-host-129 has 4 gpu, the pod requires 4 gpu -> score: 1
I0916 09:46:26.389297       1 log.go:194] permit plugin
I0916 09:46:26.393785       1 log.go:194] alloc: 4, used: 0, required: 4
I0916 09:46:26.399042       1 log.go:194] alloc: 4, used: 0, required: 4
I0916 09:46:26.399243       1 default_binder.go:53] "Attempting to bind pod to node" pod="default/falcon-pod-867106" node="css-host-128"
I0916 09:46:26.404362       1 schedule_one.go:252] "Successfully bound pod to node" pod="default/falcon-pod-867106" node="css-host-128" evaluatedNodes=2 feasibleNodes=2
I0916 09:46:26.404491       1 eventhandlers.go:161] "Delete event for unscheduled pod" pod="default/falcon-pod-867106"
I0916 09:46:26.404563       1 eventhandlers.go:186] "Add event for scheduled pod" pod="default/falcon-pod-867106"
I0916 09:46:31.700185       1 httplog.go:132] "HTTP" verb="GET" URI="/healthz" latency="79.629µs" userAgent="kube-probe/1.27" audit-ID="" srcIP="10.44.0.0:35510" resp=200
I0916 09:46:31.702400       1 httplog.go:132] "HTTP" verb="GET" URI="/healthz" latency="26.991µs" userAgent="kube-probe/1.27" audit-ID="" srcIP="10.44.0.0:35508" resp=200
I0916 09:46:41.705926       1 httplog.go:132] "HTTP" verb="GET" URI="/healthz" latency="114.094µs" userAgent="kube-probe/1.27" audit-ID="" srcIP="10.44.0.0:37786" resp=200
I0916 09:46:41.707148       1 httplog.go:132] "HTTP" verb="GET" URI="/healthz" latency="39.133µs" userAgent="kube-probe/1.27" audit-ID="" srcIP="10.44.0.0:37802" resp=200
I0916 09:46:51.707059       1 httplog.go:132] "HTTP" verb="GET" URI="/healthz" latency="147.316µs" userAgent="kube-probe/1.27" audit-ID="" srcIP="10.44.0.0:55216" resp=200
I0916 09:46:51.708445       1 httplog.go:132] "HTTP" verb="GET" URI="/healthz" latency="172.964µs" userAgent="kube-probe/1.27" audit-ID="" srcIP="10.44.0.0:55232" resp=200
I0916 09:47:01.706720       1 httplog.go:132] "HTTP" verb="GET" URI="/healthz" latency="115.166µs" userAgent="kube-probe/1.27" audit-ID="" srcIP="10.44.0.0:42040" resp=200
I0916 09:47:01.707968       1 httplog.go:132] "HTTP" verb="GET" URI="/healthz" latency="126.256µs" userAgent="kube-probe/1.27" audit-ID="" srcIP="10.44.0.0:42044" resp=200
I0916 09:47:11.707358       1 httplog.go:132] "HTTP" verb="GET" URI="/healthz" latency="154.24µs" userAgent="kube-probe/1.27" audit-ID="" srcIP="10.44.0.0:52144" resp=200
I0916 09:47:11.708697       1 httplog.go:132] "HTTP" verb="GET" URI="/healthz" latency="167.204µs" userAgent="kube-probe/1.27" audit-ID="" srcIP="10.44.0.0:52160" resp=200
I0916 09:47:21.701798       1 httplog.go:132] "HTTP" verb="GET" URI="/healthz" latency="139.281µs" userAgent="kube-probe/1.27" audit-ID="" srcIP="10.44.0.0:51080" resp=200
I0916 09:47:21.702848       1 httplog.go:132] "HTTP" verb="GET" URI="/healthz" latency="99.636µs" userAgent="kube-probe/1.27" audit-ID="" srcIP="10.44.0.0:51086" resp=200
I0916 09:47:29.693508       1 eventhandlers.go:118] "Add event for unscheduled pod" pod="default/falcon-pod-398210"
I0916 09:47:29.693593       1 schedule_one.go:80] "Attempting to schedule pod" pod="default/falcon-pod-398210"
I0916 09:47:29.694255       1 log.go:194] require 4 gpu(s), and currently has 4 gpus(s) in total
I0916 09:47:29.702924       1 log.go:194] css-host-128 has 0 gpu, the pod requires 4 gpu -> score: -4
I0916 09:47:29.702998       1 log.go:194] css-host-129 has 4 gpu, the pod requires 4 gpu -> score: 1
I0916 09:47:29.703205       1 log.go:194] permit plugin
I0916 09:47:29.706787       1 log.go:194] alloc: 4, used: 0, required: 4
I0916 09:47:29.710099       1 log.go:194] alloc: 4, used: 0, required: 4
I0916 09:47:29.710195       1 default_binder.go:53] "Attempting to bind pod to node" pod="default/falcon-pod-398210" node="css-host-129"
I0916 09:47:29.713117       1 eventhandlers.go:161] "Delete event for unscheduled pod" pod="default/falcon-pod-398210"
I0916 09:47:29.713140       1 eventhandlers.go:186] "Add event for scheduled pod" pod="default/falcon-pod-398210"
I0916 09:47:29.713193       1 schedule_one.go:252] "Successfully bound pod to node" pod="default/falcon-pod-398210" node="css-host-129" evaluatedNodes=2 feasibleNodes=2
I0916 09:47:31.702076       1 httplog.go:132] "HTTP" verb="GET" URI="/healthz" latency="104.025µs" userAgent="kube-probe/1.27" audit-ID="" srcIP="10.44.0.0:44206" resp=200
I0916 09:47:31.703361       1 httplog.go:132] "HTTP" verb="GET" URI="/healthz" latency="114.374µs" userAgent="kube-probe/1.27" audit-ID="" srcIP="10.44.0.0:44204" resp=200
I0916 09:47:35.277967       1 eventhandlers.go:231] "Delete event for scheduled pod" pod="default/falcon-pod-398210"
I0916 09:47:41.706745       1 httplog.go:132] "HTTP" verb="GET" URI="/healthz" latency="155.292µs" userAgent="kube-probe/1.27" audit-ID="" srcIP="10.44.0.0:44252" resp=200
I0916 09:47:41.707709       1 httplog.go:132] "HTTP" verb="GET" URI="/healthz" latency="65.953µs" userAgent="kube-probe/1.27" audit-ID="" srcIP="10.44.0.0:44254" resp=200
I0916 09:47:51.706532       1 httplog.go:132] "HTTP" verb="GET" URI="/healthz" latency="97.463µs" userAgent="kube-probe/1.27" audit-ID="" srcIP="10.44.0.0:48910" resp=200
I0916 09:47:51.707577       1 httplog.go:132] "HTTP" verb="GET" URI="/healthz" latency="55.684µs" userAgent="kube-probe/1.27" audit-ID="" srcIP="10.44.0.0:48926" resp=200
I0916 09:48:01.702142       1 httplog.go:132] "HTTP" verb="GET" URI="/healthz" latency="94.527µs" userAgent="kube-probe/1.27" audit-ID="" srcIP="10.44.0.0:35040" resp=200
I0916 09:48:01.703534       1 httplog.go:132] "HTTP" verb="GET" URI="/healthz" latency="56.235µs" userAgent="kube-probe/1.27" audit-ID="" srcIP="10.44.0.0:35046" resp=200
I0916 09:48:11.706154       1 httplog.go:132] "HTTP" verb="GET" URI="/healthz" latency="96.431µs" userAgent="kube-probe/1.27" audit-ID="" srcIP="10.44.0.0:46548" resp=200
I0916 09:48:11.707342       1 httplog.go:132] "HTTP" verb="GET" URI="/healthz" latency="55.594µs" userAgent="kube-probe/1.27" audit-ID="" srcIP="10.44.0.0:46550" resp=200
I0916 09:48:21.702802       1 httplog.go:132] "HTTP" verb="GET" URI="/healthz" latency="77.755µs" userAgent="kube-probe/1.27" audit-ID="" srcIP="10.44.0.0:47882" resp=200
I0916 09:48:21.702907       1 httplog.go:132] "HTTP" verb="GET" URI="/healthz" latency="166.201µs" userAgent="kube-probe/1.27" audit-ID="" srcIP="10.44.0.0:47870" resp=200
I0916 09:48:31.706409       1 httplog.go:132] "HTTP" verb="GET" URI="/healthz" latency="150.873µs" userAgent="kube-probe/1.27" audit-ID="" srcIP="10.44.0.0:58332" resp=200
I0916 09:48:31.707425       1 httplog.go:132] "HTTP" verb="GET" URI="/healthz" latency="49.673µs" userAgent="kube-probe/1.27" audit-ID="" srcIP="10.44.0.0:58326" resp=200
I0916 09:48:41.699192       1 httplog.go:132] "HTTP" verb="GET" URI="/healthz" latency="87.143µs" userAgent="kube-probe/1.27" audit-ID="" srcIP="10.44.0.0:39172" resp=200
I0916 09:48:41.702355       1 httplog.go:132] "HTTP" verb="GET" URI="/healthz" latency="61.505µs" userAgent="kube-probe/1.27" audit-ID="" srcIP="10.44.0.0:39162" resp=200
I0916 09:48:42.013361       1 eventhandlers.go:118] "Add event for unscheduled pod" pod="default/falcon-pod-593250"
I0916 09:48:42.013494       1 schedule_one.go:80] "Attempting to schedule pod" pod="default/falcon-pod-593250"
I0916 09:48:42.014134       1 log.go:194] require 4 gpu(s), and currently has 4 gpus(s) in total
I0916 09:48:42.022000       1 log.go:194] css-host-128 has 0 gpu, the pod requires 4 gpu -> score: -4
I0916 09:48:42.022038       1 log.go:194] css-host-129 has 4 gpu, the pod requires 4 gpu -> score: 1
I0916 09:48:42.022262       1 log.go:194] permit plugin
I0916 09:48:42.026861       1 log.go:194] alloc: 4, used: 0, required: 4
I0916 09:48:42.030736       1 log.go:194] alloc: 4, used: 0, required: 4
I0916 09:48:42.030835       1 default_binder.go:53] "Attempting to bind pod to node" pod="default/falcon-pod-593250" node="css-host-129"
I0916 09:48:42.034327       1 schedule_one.go:252] "Successfully bound pod to node" pod="default/falcon-pod-593250" node="css-host-129" evaluatedNodes=2 feasibleNodes=2
I0916 09:48:42.034572       1 eventhandlers.go:161] "Delete event for unscheduled pod" pod="default/falcon-pod-593250"
I0916 09:48:42.034589       1 eventhandlers.go:186] "Add event for scheduled pod" pod="default/falcon-pod-593250"
I0916 09:48:47.321926       1 eventhandlers.go:231] "Delete event for scheduled pod" pod="default/falcon-pod-593250"
I0916 09:48:51.701933       1 httplog.go:132] "HTTP" verb="GET" URI="/healthz" latency="110.326µs" userAgent="kube-probe/1.27" audit-ID="" srcIP="10.44.0.0:44788" resp=200
I0916 09:48:51.703028       1 httplog.go:132] "HTTP" verb="GET" URI="/healthz" latency="67.526µs" userAgent="kube-probe/1.27" audit-ID="" srcIP="10.44.0.0:44786" resp=200
I0916 09:48:59.603439       1 eventhandlers.go:231] "Delete event for scheduled pod" pod="default/falcon-pod-867106"
I0916 09:49:01.703485       1 httplog.go:132] "HTTP" verb="GET" URI="/healthz" latency="127.249µs" userAgent="kube-probe/1.27" audit-ID="" srcIP="10.44.0.0:51280" resp=200
I0916 09:49:01.704450       1 httplog.go:132] "HTTP" verb="GET" URI="/healthz" latency="120.907µs" userAgent="kube-probe/1.27" audit-ID="" srcIP="10.44.0.0:51272" resp=200
I0916 09:49:11.707039       1 httplog.go:132] "HTTP" verb="GET" URI="/healthz" latency="147.016µs" userAgent="kube-probe/1.27" audit-ID="" srcIP="10.44.0.0:35654" resp=200
I0916 09:49:11.708050       1 httplog.go:132] "HTTP" verb="GET" URI="/healthz" latency="96.471µs" userAgent="kube-probe/1.27" audit-ID="" srcIP="10.44.0.0:35652" resp=200
I0916 09:49:21.699481       1 httplog.go:132] "HTTP" verb="GET" URI="/healthz" latency="96.801µs" userAgent="kube-probe/1.27" audit-ID="" srcIP="10.44.0.0:36088" resp=200
I0916 09:49:21.700312       1 httplog.go:132] "HTTP" verb="GET" URI="/healthz" latency="30.548µs" userAgent="kube-probe/1.27" audit-ID="" srcIP="10.44.0.0:36104" resp=200
I0916 09:49:31.706977       1 httplog.go:132] "HTTP" verb="GET" URI="/healthz" latency="106.459µs" userAgent="kube-probe/1.27" audit-ID="" srcIP="10.44.0.0:54116" resp=200
I0916 09:49:31.708017       1 httplog.go:132] "HTTP" verb="GET" URI="/healthz" latency="51.616µs" userAgent="kube-probe/1.27" audit-ID="" srcIP="10.44.0.0:54128" resp=200
I0916 09:49:41.702146       1 httplog.go:132] "HTTP" verb="GET" URI="/healthz" latency="91.371µs" userAgent="kube-probe/1.27" audit-ID="" srcIP="10.44.0.0:56694" resp=200
I0916 09:49:41.709452       1 httplog.go:132] "HTTP" verb="GET" URI="/healthz" latency="36.148µs" userAgent="kube-probe/1.27" audit-ID="" srcIP="10.44.0.0:56698" resp=200
I0916 09:49:42.315126       1 eventhandlers.go:118] "Add event for unscheduled pod" pod="default/falcon-pod-519337"
I0916 09:49:42.315241       1 schedule_one.go:80] "Attempting to schedule pod" pod="default/falcon-pod-519337"
I0916 09:49:42.315779       1 log.go:194] require 2 gpu(s), and currently has 8 gpus(s) in total
I0916 09:49:42.322865       1 log.go:194] css-host-128 has 4 gpu, the pod requires 2 gpu -> score: 50
I0916 09:49:42.322915       1 log.go:194] css-host-129 has 4 gpu, the pod requires 2 gpu -> score: 50
I0916 09:49:42.323219       1 log.go:194] permit plugin
I0916 09:49:42.327647       1 log.go:194] alloc: 4, used: 0, required: 2
I0916 09:49:42.331512       1 log.go:194] alloc: 4, used: 0, required: 2
I0916 09:49:42.331622       1 default_binder.go:53] "Attempting to bind pod to node" pod="default/falcon-pod-519337" node="css-host-128"
I0916 09:49:42.334965       1 eventhandlers.go:161] "Delete event for unscheduled pod" pod="default/falcon-pod-519337"
I0916 09:49:42.334986       1 eventhandlers.go:186] "Add event for scheduled pod" pod="default/falcon-pod-519337"
I0916 09:49:42.335433       1 schedule_one.go:252] "Successfully bound pod to node" pod="default/falcon-pod-519337" node="css-host-128" evaluatedNodes=2 feasibleNodes=2
I0916 09:49:51.699141       1 httplog.go:132] "HTTP" verb="GET" URI="/healthz" latency="97.252µs" userAgent="kube-probe/1.27" audit-ID="" srcIP="10.44.0.0:41630" resp=200
I0916 09:49:51.701846       1 httplog.go:132] "HTTP" verb="GET" URI="/healthz" latency="54.993µs" userAgent="kube-probe/1.27" audit-ID="" srcIP="10.44.0.0:41624" resp=200
I0916 09:50:01.702521       1 httplog.go:132] "HTTP" verb="GET" URI="/healthz" latency="96.481µs" userAgent="kube-probe/1.27" audit-ID="" srcIP="10.44.0.0:46662" resp=200
I0916 09:50:01.703387       1 httplog.go:132] "HTTP" verb="GET" URI="/healthz" latency="59.542µs" userAgent="kube-probe/1.27" audit-ID="" srcIP="10.44.0.0:46668" resp=200
I0916 09:50:11.702359       1 httplog.go:132] "HTTP" verb="GET" URI="/healthz" latency="86.162µs" userAgent="kube-probe/1.27" audit-ID="" srcIP="10.44.0.0:56088" resp=200
I0916 09:50:11.703366       1 httplog.go:132] "HTTP" verb="GET" URI="/healthz" latency="72.436µs" userAgent="kube-probe/1.27" audit-ID="" srcIP="10.44.0.0:56074" resp=200
I0916 09:50:21.702297       1 httplog.go:132] "HTTP" verb="GET" URI="/healthz" latency="59.301µs" userAgent="kube-probe/1.27" audit-ID="" srcIP="10.44.0.0:45674" resp=200
I0916 09:50:21.703350       1 httplog.go:132] "HTTP" verb="GET" URI="/healthz" latency="65.072µs" userAgent="kube-probe/1.27" audit-ID="" srcIP="10.44.0.0:45676" resp=200
I0916 09:50:31.706560       1 httplog.go:132] "HTTP" verb="GET" URI="/healthz" latency="106.279µs" userAgent="kube-probe/1.27" audit-ID="" srcIP="10.44.0.0:45958" resp=200
I0916 09:50:31.708363       1 httplog.go:132] "HTTP" verb="GET" URI="/healthz" latency="53.69µs" userAgent="kube-probe/1.27" audit-ID="" srcIP="10.44.0.0:45962" resp=200
I0916 09:50:41.706948       1 httplog.go:132] "HTTP" verb="GET" URI="/healthz" latency="99.737µs" userAgent="kube-probe/1.27" audit-ID="" srcIP="10.44.0.0:54394" resp=200
I0916 09:50:41.708067       1 httplog.go:132] "HTTP" verb="GET" URI="/healthz" latency="25.689µs" userAgent="kube-probe/1.27" audit-ID="" srcIP="10.44.0.0:54404" resp=200
I0916 09:50:49.572787       1 eventhandlers.go:118] "Add event for unscheduled pod" pod="default/falcon-pod-581104"
I0916 09:50:49.572867       1 schedule_one.go:80] "Attempting to schedule pod" pod="default/falcon-pod-581104"
I0916 09:50:49.573412       1 log.go:194] require 4 gpu(s), and currently has 6 gpus(s) in total
I0916 09:50:49.581395       1 log.go:194] css-host-128 has 2 gpu, the pod requires 4 gpu -> score: -2
I0916 09:50:49.581416       1 log.go:194] css-host-129 has 4 gpu, the pod requires 4 gpu -> score: 1
I0916 09:50:49.581718       1 log.go:194] permit plugin
I0916 09:50:49.585937       1 log.go:194] alloc: 4, used: 0, required: 4
I0916 09:50:49.589819       1 log.go:194] alloc: 4, used: 0, required: 4
I0916 09:50:49.589931       1 default_binder.go:53] "Attempting to bind pod to node" pod="default/falcon-pod-581104" node="css-host-129"
I0916 09:50:49.593286       1 schedule_one.go:252] "Successfully bound pod to node" pod="default/falcon-pod-581104" node="css-host-129" evaluatedNodes=2 feasibleNodes=2
I0916 09:50:49.593417       1 eventhandlers.go:186] "Add event for scheduled pod" pod="default/falcon-pod-581104"
I0916 09:50:49.593436       1 eventhandlers.go:161] "Delete event for unscheduled pod" pod="default/falcon-pod-581104"
I0916 09:50:51.702858       1 httplog.go:132] "HTTP" verb="GET" URI="/healthz" latency="93.635µs" userAgent="kube-probe/1.27" audit-ID="" srcIP="10.44.0.0:52356" resp=200
I0916 09:50:51.709316       1 httplog.go:132] "HTTP" verb="GET" URI="/healthz" latency="58.089µs" userAgent="kube-probe/1.27" audit-ID="" srcIP="10.44.0.0:52368" resp=200
I0916 09:50:54.826719       1 eventhandlers.go:231] "Delete event for scheduled pod" pod="default/falcon-pod-581104"
I0916 09:51:01.702743       1 httplog.go:132] "HTTP" verb="GET" URI="/healthz" latency="116.138µs" userAgent="kube-probe/1.27" audit-ID="" srcIP="10.44.0.0:50272" resp=200
I0916 09:51:01.703854       1 httplog.go:132] "HTTP" verb="GET" URI="/healthz" latency="98.044µs" userAgent="kube-probe/1.27" audit-ID="" srcIP="10.44.0.0:50258" resp=200
I0916 09:51:11.701952       1 httplog.go:132] "HTTP" verb="GET" URI="/healthz" latency="112.42µs" userAgent="kube-probe/1.27" audit-ID="" srcIP="10.44.0.0:51306" resp=200
I0916 09:51:11.703123       1 httplog.go:132] "HTTP" verb="GET" URI="/healthz" latency="52.298µs" userAgent="kube-probe/1.27" audit-ID="" srcIP="10.44.0.0:51322" resp=200
I0916 09:51:21.700509       1 httplog.go:132] "HTTP" verb="GET" URI="/healthz" latency="120.707µs" userAgent="kube-probe/1.27" audit-ID="" srcIP="10.44.0.0:52372" resp=200
I0916 09:51:21.701676       1 httplog.go:132] "HTTP" verb="GET" URI="/healthz" latency="98.695µs" userAgent="kube-probe/1.27" audit-ID="" srcIP="10.44.0.0:52370" resp=200
I0916 09:51:31.706365       1 httplog.go:132] "HTTP" verb="GET" URI="/healthz" latency="113.813µs" userAgent="kube-probe/1.27" audit-ID="" srcIP="10.44.0.0:58336" resp=200
I0916 09:51:31.707665       1 httplog.go:132] "HTTP" verb="GET" URI="/healthz" latency="89.357µs" userAgent="kube-probe/1.27" audit-ID="" srcIP="10.44.0.0:58342" resp=200
I0916 09:51:37.206023       1 eventhandlers.go:231] "Delete event for scheduled pod" pod="default/falcon-pod-519337"
I0916 09:51:39.877984       1 eventhandlers.go:118] "Add event for unscheduled pod" pod="default/falcon-pod-399023"
I0916 09:51:39.878035       1 schedule_one.go:80] "Attempting to schedule pod" pod="default/falcon-pod-399023"
I0916 09:51:39.878393       1 log.go:194] require 2 gpu(s), and currently has 8 gpus(s) in total
I0916 09:51:39.885453       1 log.go:194] css-host-128 has 4 gpu, the pod requires 2 gpu -> score: 50
I0916 09:51:39.885507       1 log.go:194] css-host-129 has 4 gpu, the pod requires 2 gpu -> score: 50
I0916 09:51:39.885652       1 log.go:194] permit plugin
I0916 09:51:39.889347       1 log.go:194] alloc: 4, used: 0, required: 2
I0916 09:51:39.893096       1 log.go:194] alloc: 4, used: 0, required: 2
I0916 09:51:39.893205       1 default_binder.go:53] "Attempting to bind pod to node" pod="default/falcon-pod-399023" node="css-host-129"
I0916 09:51:39.896848       1 eventhandlers.go:161] "Delete event for unscheduled pod" pod="default/falcon-pod-399023"
I0916 09:51:39.896868       1 eventhandlers.go:186] "Add event for scheduled pod" pod="default/falcon-pod-399023"
I0916 09:51:39.896981       1 schedule_one.go:252] "Successfully bound pod to node" pod="default/falcon-pod-399023" node="css-host-129" evaluatedNodes=2 feasibleNodes=2
I0916 09:51:41.706632       1 httplog.go:132] "HTTP" verb="GET" URI="/healthz" latency="95.058µs" userAgent="kube-probe/1.27" audit-ID="" srcIP="10.44.0.0:50362" resp=200
I0916 09:51:41.707778       1 httplog.go:132] "HTTP" verb="GET" URI="/healthz" latency="28.163µs" userAgent="kube-probe/1.27" audit-ID="" srcIP="10.44.0.0:50360" resp=200
I0916 09:51:45.298705       1 eventhandlers.go:231] "Delete event for scheduled pod" pod="default/falcon-pod-399023"
I0916 09:51:51.707196       1 httplog.go:132] "HTTP" verb="GET" URI="/healthz" latency="126.667µs" userAgent="kube-probe/1.27" audit-ID="" srcIP="10.44.0.0:49262" resp=200
I0916 09:51:51.708279       1 httplog.go:132] "HTTP" verb="GET" URI="/healthz" latency="55.764µs" userAgent="kube-probe/1.27" audit-ID="" srcIP="10.44.0.0:49264" resp=200
I0916 09:52:01.706784       1 httplog.go:132] "HTTP" verb="GET" URI="/healthz" latency="98.534µs" userAgent="kube-probe/1.27" audit-ID="" srcIP="10.44.0.0:60342" resp=200
I0916 09:52:01.708057       1 httplog.go:132] "HTTP" verb="GET" URI="/healthz" latency="102.833µs" userAgent="kube-probe/1.27" audit-ID="" srcIP="10.44.0.0:60340" resp=200
I0916 09:52:11.700711       1 httplog.go:132] "HTTP" verb="GET" URI="/healthz" latency="96.281µs" userAgent="kube-probe/1.27" audit-ID="" srcIP="10.44.0.0:48750" resp=200
I0916 09:52:11.701950       1 httplog.go:132] "HTTP" verb="GET" URI="/healthz" latency="119.354µs" userAgent="kube-probe/1.27" audit-ID="" srcIP="10.44.0.0:48744" resp=200
I0916 09:52:21.700230       1 httplog.go:132] "HTTP" verb="GET" URI="/healthz" latency="102.873µs" userAgent="kube-probe/1.27" audit-ID="" srcIP="10.44.0.0:38992" resp=200
I0916 09:52:21.701343       1 httplog.go:132] "HTTP" verb="GET" URI="/healthz" latency="65.864µs" userAgent="kube-probe/1.27" audit-ID="" srcIP="10.44.0.0:39008" resp=200
I0916 09:52:31.706722       1 httplog.go:132] "HTTP" verb="GET" URI="/healthz" latency="113.272µs" userAgent="kube-probe/1.27" audit-ID="" srcIP="10.44.0.0:38318" resp=200
I0916 09:52:31.707993       1 httplog.go:132] "HTTP" verb="GET" URI="/healthz" latency="132.799µs" userAgent="kube-probe/1.27" audit-ID="" srcIP="10.44.0.0:38320" resp=200
I0916 09:52:41.701927       1 httplog.go:132] "HTTP" verb="GET" URI="/healthz" latency="115.176µs" userAgent="kube-probe/1.27" audit-ID="" srcIP="10.44.0.0:37514" resp=200
I0916 09:52:41.703100       1 httplog.go:132] "HTTP" verb="GET" URI="/healthz" latency="79.9µs" userAgent="kube-probe/1.27" audit-ID="" srcIP="10.44.0.0:37526" resp=200
I0916 09:52:43.187610       1 eventhandlers.go:118] "Add event for unscheduled pod" pod="default/falcon-pod-381278"
I0916 09:52:43.187689       1 schedule_one.go:80] "Attempting to schedule pod" pod="default/falcon-pod-381278"
I0916 09:52:43.188218       1 log.go:194] require 2 gpu(s), and currently has 8 gpus(s) in total
I0916 09:52:43.194997       1 log.go:194] css-host-128 has 4 gpu, the pod requires 2 gpu -> score: 50
I0916 09:52:43.195021       1 log.go:194] css-host-129 has 4 gpu, the pod requires 2 gpu -> score: 50
I0916 09:52:43.195210       1 log.go:194] permit plugin
I0916 09:52:43.200821       1 log.go:194] alloc: 4, used: 0, required: 2
I0916 09:52:43.205187       1 log.go:194] alloc: 4, used: 0, required: 2
I0916 09:52:43.205321       1 default_binder.go:53] "Attempting to bind pod to node" pod="default/falcon-pod-381278" node="css-host-128"
I0916 09:52:43.209191       1 schedule_one.go:252] "Successfully bound pod to node" pod="default/falcon-pod-381278" node="css-host-128" evaluatedNodes=2 feasibleNodes=2
I0916 09:52:43.209846       1 eventhandlers.go:186] "Add event for scheduled pod" pod="default/falcon-pod-381278"
I0916 09:52:43.209954       1 eventhandlers.go:161] "Delete event for unscheduled pod" pod="default/falcon-pod-381278"
I0916 09:52:51.699882       1 httplog.go:132] "HTTP" verb="GET" URI="/healthz" latency="101.53µs" userAgent="kube-probe/1.27" audit-ID="" srcIP="10.44.0.0:50236" resp=200
I0916 09:52:51.702793       1 httplog.go:132] "HTTP" verb="GET" URI="/healthz" latency="54.993µs" userAgent="kube-probe/1.27" audit-ID="" srcIP="10.44.0.0:50220" resp=200
I0916 09:53:01.707228       1 httplog.go:132] "HTTP" verb="GET" URI="/healthz" latency="164.418µs" userAgent="kube-probe/1.27" audit-ID="" srcIP="10.44.0.0:50020" resp=200
I0916 09:53:01.708248       1 httplog.go:132] "HTTP" verb="GET" URI="/healthz" latency="70.122µs" userAgent="kube-probe/1.27" audit-ID="" srcIP="10.44.0.0:50022" resp=200
I0916 09:53:11.707831       1 httplog.go:132] "HTTP" verb="GET" URI="/healthz" latency="153.688µs" userAgent="kube-probe/1.27" audit-ID="" srcIP="10.44.0.0:43274" resp=200
I0916 09:53:11.709019       1 httplog.go:132] "HTTP" verb="GET" URI="/healthz" latency="105.097µs" userAgent="kube-probe/1.27" audit-ID="" srcIP="10.44.0.0:43290" resp=200
I0916 09:53:21.697927       1 httplog.go:132] "HTTP" verb="GET" URI="/healthz" latency="134.041µs" userAgent="kube-probe/1.27" audit-ID="" srcIP="10.44.0.0:53662" resp=200
I0916 09:53:21.700707       1 httplog.go:132] "HTTP" verb="GET" URI="/healthz" latency="89.137µs" userAgent="kube-probe/1.27" audit-ID="" srcIP="10.44.0.0:53646" resp=200
I0916 09:53:31.701935       1 httplog.go:132] "HTTP" verb="GET" URI="/healthz" latency="132.358µs" userAgent="kube-probe/1.27" audit-ID="" srcIP="10.44.0.0:35522" resp=200
I0916 09:53:31.703208       1 httplog.go:132] "HTTP" verb="GET" URI="/healthz" latency="91.903µs" userAgent="kube-probe/1.27" audit-ID="" srcIP="10.44.0.0:35520" resp=200
I0916 09:53:32.450570       1 eventhandlers.go:118] "Add event for unscheduled pod" pod="default/falcon-pod-534716"
I0916 09:53:32.450663       1 schedule_one.go:80] "Attempting to schedule pod" pod="default/falcon-pod-534716"
I0916 09:53:32.451318       1 log.go:194] require 4 gpu(s), and currently has 6 gpus(s) in total
I0916 09:53:32.458634       1 log.go:194] css-host-128 has 2 gpu, the pod requires 4 gpu -> score: -2
I0916 09:53:32.458667       1 log.go:194] css-host-129 has 4 gpu, the pod requires 4 gpu -> score: 1
I0916 09:53:32.459044       1 log.go:194] permit plugin
I0916 09:53:32.463698       1 log.go:194] alloc: 4, used: 0, required: 4
I0916 09:53:32.467587       1 log.go:194] alloc: 4, used: 0, required: 4
I0916 09:53:32.467705       1 default_binder.go:53] "Attempting to bind pod to node" pod="default/falcon-pod-534716" node="css-host-129"
I0916 09:53:32.471115       1 schedule_one.go:252] "Successfully bound pod to node" pod="default/falcon-pod-534716" node="css-host-129" evaluatedNodes=2 feasibleNodes=2
I0916 09:53:32.471246       1 eventhandlers.go:161] "Delete event for unscheduled pod" pod="default/falcon-pod-534716"
I0916 09:53:32.471322       1 eventhandlers.go:186] "Add event for scheduled pod" pod="default/falcon-pod-534716"
I0916 09:53:38.797261       1 eventhandlers.go:231] "Delete event for scheduled pod" pod="default/falcon-pod-534716"
I0916 09:53:41.707536       1 httplog.go:132] "HTTP" verb="GET" URI="/healthz" latency="134.141µs" userAgent="kube-probe/1.27" audit-ID="" srcIP="10.44.0.0:39156" resp=200
I0916 09:53:41.708708       1 httplog.go:132] "HTTP" verb="GET" URI="/healthz" latency="105.338µs" userAgent="kube-probe/1.27" audit-ID="" srcIP="10.44.0.0:39158" resp=200
I0916 09:53:51.702718       1 httplog.go:132] "HTTP" verb="GET" URI="/healthz" latency="93.495µs" userAgent="kube-probe/1.27" audit-ID="" srcIP="10.44.0.0:49358" resp=200
I0916 09:53:51.703936       1 httplog.go:132] "HTTP" verb="GET" URI="/healthz" latency="155.221µs" userAgent="kube-probe/1.27" audit-ID="" srcIP="10.44.0.0:49362" resp=200
I0916 09:54:01.702904       1 httplog.go:132] "HTTP" verb="GET" URI="/healthz" latency="112.01µs" userAgent="kube-probe/1.27" audit-ID="" srcIP="10.44.0.0:36072" resp=200
I0916 09:54:01.703951       1 httplog.go:132] "HTTP" verb="GET" URI="/healthz" latency="113.343µs" userAgent="kube-probe/1.27" audit-ID="" srcIP="10.44.0.0:36070" resp=200
I0916 09:54:11.699968       1 httplog.go:132] "HTTP" verb="GET" URI="/healthz" latency="124.904µs" userAgent="kube-probe/1.27" audit-ID="" srcIP="10.44.0.0:43400" resp=200
I0916 09:54:11.701998       1 httplog.go:132] "HTTP" verb="GET" URI="/healthz" latency="102.272µs" userAgent="kube-probe/1.27" audit-ID="" srcIP="10.44.0.0:43386" resp=200
I0916 09:54:21.702099       1 httplog.go:132] "HTTP" verb="GET" URI="/healthz" latency="102.462µs" userAgent="kube-probe/1.27" audit-ID="" srcIP="10.44.0.0:46026" resp=200
I0916 09:54:21.703517       1 httplog.go:132] "HTTP" verb="GET" URI="/healthz" latency="125.175µs" userAgent="kube-probe/1.27" audit-ID="" srcIP="10.44.0.0:46028" resp=200
I0916 09:54:31.706578       1 httplog.go:132] "HTTP" verb="GET" URI="/healthz" latency="134.171µs" userAgent="kube-probe/1.27" audit-ID="" srcIP="10.44.0.0:51694" resp=200
I0916 09:54:31.707830       1 httplog.go:132] "HTTP" verb="GET" URI="/healthz" latency="125.536µs" userAgent="kube-probe/1.27" audit-ID="" srcIP="10.44.0.0:51706" resp=200
I0916 09:54:41.707208       1 httplog.go:132] "HTTP" verb="GET" URI="/healthz" latency="104.957µs" userAgent="kube-probe/1.27" audit-ID="" srcIP="10.44.0.0:53908" resp=200
I0916 09:54:41.708219       1 httplog.go:132] "HTTP" verb="GET" URI="/healthz" latency="61.715µs" userAgent="kube-probe/1.27" audit-ID="" srcIP="10.44.0.0:53914" resp=200
I0916 09:54:51.706956       1 httplog.go:132] "HTTP" verb="GET" URI="/healthz" latency="137.648µs" userAgent="kube-probe/1.27" audit-ID="" srcIP="10.44.0.0:45028" resp=200
I0916 09:54:51.707825       1 httplog.go:132] "HTTP" verb="GET" URI="/healthz" latency="55.403µs" userAgent="kube-probe/1.27" audit-ID="" srcIP="10.44.0.0:45036" resp=200
I0916 09:55:01.701467       1 httplog.go:132] "HTTP" verb="GET" URI="/healthz" latency="161.282µs" userAgent="kube-probe/1.27" audit-ID="" srcIP="10.44.0.0:39862" resp=200
I0916 09:55:01.702618       1 httplog.go:132] "HTTP" verb="GET" URI="/healthz" latency="104.365µs" userAgent="kube-probe/1.27" audit-ID="" srcIP="10.44.0.0:39864" resp=200
I0916 09:55:11.706473       1 httplog.go:132] "HTTP" verb="GET" URI="/healthz" latency="96.992µs" userAgent="kube-probe/1.27" audit-ID="" srcIP="10.44.0.0:53820" resp=200
I0916 09:55:11.707614       1 httplog.go:132] "HTTP" verb="GET" URI="/healthz" latency="55.083µs" userAgent="kube-probe/1.27" audit-ID="" srcIP="10.44.0.0:53828" resp=200
I0916 09:55:21.702423       1 httplog.go:132] "HTTP" verb="GET" URI="/healthz" latency="101.941µs" userAgent="kube-probe/1.27" audit-ID="" srcIP="10.44.0.0:39814" resp=200
I0916 09:55:21.703636       1 httplog.go:132] "HTTP" verb="GET" URI="/healthz" latency="53.28µs" userAgent="kube-probe/1.27" audit-ID="" srcIP="10.44.0.0:39830" resp=200
I0916 09:55:31.702520       1 httplog.go:132] "HTTP" verb="GET" URI="/healthz" latency="99.817µs" userAgent="kube-probe/1.27" audit-ID="" srcIP="10.44.0.0:37602" resp=200
I0916 09:55:31.703350       1 httplog.go:132] "HTTP" verb="GET" URI="/healthz" latency="61.435µs" userAgent="kube-probe/1.27" audit-ID="" srcIP="10.44.0.0:37590" resp=200
I0916 09:55:41.707436       1 httplog.go:132] "HTTP" verb="GET" URI="/healthz" latency="141.115µs" userAgent="kube-probe/1.27" audit-ID="" srcIP="10.44.0.0:34332" resp=200
I0916 09:55:41.708271       1 httplog.go:132] "HTTP" verb="GET" URI="/healthz" latency="96.841µs" userAgent="kube-probe/1.27" audit-ID="" srcIP="10.44.0.0:34344" resp=200
I0916 09:55:51.702106       1 httplog.go:132] "HTTP" verb="GET" URI="/healthz" latency="95.459µs" userAgent="kube-probe/1.27" audit-ID="" srcIP="10.44.0.0:34124" resp=200
I0916 09:55:51.703237       1 httplog.go:132] "HTTP" verb="GET" URI="/healthz" latency="112.821µs" userAgent="kube-probe/1.27" audit-ID="" srcIP="10.44.0.0:34136" resp=200
I0916 09:56:01.702055       1 httplog.go:132] "HTTP" verb="GET" URI="/healthz" latency="97.773µs" userAgent="kube-probe/1.27" audit-ID="" srcIP="10.44.0.0:58454" resp=200
I0916 09:56:01.703224       1 httplog.go:132] "HTTP" verb="GET" URI="/healthz" latency="98.816µs" userAgent="kube-probe/1.27" audit-ID="" srcIP="10.44.0.0:58466" resp=200
I0916 09:56:11.707034       1 httplog.go:132] "HTTP" verb="GET" URI="/healthz" latency="93.265µs" userAgent="kube-probe/1.27" audit-ID="" srcIP="10.44.0.0:41488" resp=200
I0916 09:56:11.708290       1 httplog.go:132] "HTTP" verb="GET" URI="/healthz" latency="39.734µs" userAgent="kube-probe/1.27" audit-ID="" srcIP="10.44.0.0:41482" resp=200
I0916 09:56:21.706546       1 httplog.go:132] "HTTP" verb="GET" URI="/healthz" latency="78.327µs" userAgent="kube-probe/1.27" audit-ID="" srcIP="10.44.0.0:60488" resp=200
I0916 09:56:21.714563       1 httplog.go:132] "HTTP" verb="GET" URI="/healthz" latency="162.394µs" userAgent="kube-probe/1.27" audit-ID="" srcIP="10.44.0.0:60500" resp=200
I0916 09:56:31.702060       1 httplog.go:132] "HTTP" verb="GET" URI="/healthz" latency="134.612µs" userAgent="kube-probe/1.27" audit-ID="" srcIP="10.44.0.0:41822" resp=200
I0916 09:56:31.703190       1 httplog.go:132] "HTTP" verb="GET" URI="/healthz" latency="65.883µs" userAgent="kube-probe/1.27" audit-ID="" srcIP="10.44.0.0:41818" resp=200
I0916 09:56:41.702632       1 httplog.go:132] "HTTP" verb="GET" URI="/healthz" latency="114.454µs" userAgent="kube-probe/1.27" audit-ID="" srcIP="10.44.0.0:33070" resp=200
I0916 09:56:41.704102       1 httplog.go:132] "HTTP" verb="GET" URI="/healthz" latency="129.714µs" userAgent="kube-probe/1.27" audit-ID="" srcIP="10.44.0.0:33072" resp=200
I0916 09:56:51.702766       1 httplog.go:132] "HTTP" verb="GET" URI="/healthz" latency="110.217µs" userAgent="kube-probe/1.27" audit-ID="" srcIP="10.44.0.0:40246" resp=200
I0916 09:56:51.703779       1 httplog.go:132] "HTTP" verb="GET" URI="/healthz" latency="52.238µs" userAgent="kube-probe/1.27" audit-ID="" srcIP="10.44.0.0:40250" resp=200
I0916 09:57:01.702291       1 httplog.go:132] "HTTP" verb="GET" URI="/healthz" latency="107.521µs" userAgent="kube-probe/1.27" audit-ID="" srcIP="10.44.0.0:53530" resp=200
I0916 09:57:01.703383       1 httplog.go:132] "HTTP" verb="GET" URI="/healthz" latency="171.952µs" userAgent="kube-probe/1.27" audit-ID="" srcIP="10.44.0.0:53534" resp=200
I0916 09:57:11.706302       1 httplog.go:132] "HTTP" verb="GET" URI="/healthz" latency="134.783µs" userAgent="kube-probe/1.27" audit-ID="" srcIP="10.44.0.0:34236" resp=200
I0916 09:57:11.707488       1 httplog.go:132] "HTTP" verb="GET" URI="/healthz" latency="57.167µs" userAgent="kube-probe/1.27" audit-ID="" srcIP="10.44.0.0:34244" resp=200
I0916 09:57:21.706509       1 httplog.go:132] "HTTP" verb="GET" URI="/healthz" latency="127.458µs" userAgent="kube-probe/1.27" audit-ID="" srcIP="10.44.0.0:37960" resp=200
I0916 09:57:21.707750       1 httplog.go:132] "HTTP" verb="GET" URI="/healthz" latency="75.902µs" userAgent="kube-probe/1.27" audit-ID="" srcIP="10.44.0.0:37964" resp=200
I0916 09:57:31.702491       1 httplog.go:132] "HTTP" verb="GET" URI="/healthz" latency="110.748µs" userAgent="kube-probe/1.27" audit-ID="" srcIP="10.44.0.0:52176" resp=200
I0916 09:57:31.703717       1 httplog.go:132] "HTTP" verb="GET" URI="/healthz" latency="91.462µs" userAgent="kube-probe/1.27" audit-ID="" srcIP="10.44.0.0:52190" resp=200
I0916 09:57:41.707325       1 httplog.go:132] "HTTP" verb="GET" URI="/healthz" latency="129.322µs" userAgent="kube-probe/1.27" audit-ID="" srcIP="10.44.0.0:46818" resp=200
I0916 09:57:41.708344       1 httplog.go:132] "HTTP" verb="GET" URI="/healthz" latency="101.3µs" userAgent="kube-probe/1.27" audit-ID="" srcIP="10.44.0.0:46830" resp=200
I0916 09:57:51.707167       1 httplog.go:132] "HTTP" verb="GET" URI="/healthz" latency="104.035µs" userAgent="kube-probe/1.27" audit-ID="" srcIP="10.44.0.0:44436" resp=200
I0916 09:57:51.708264       1 httplog.go:132] "HTTP" verb="GET" URI="/healthz" latency="57.848µs" userAgent="kube-probe/1.27" audit-ID="" srcIP="10.44.0.0:44438" resp=200
I0916 09:58:01.707183       1 httplog.go:132] "HTTP" verb="GET" URI="/healthz" latency="89.799µs" userAgent="kube-probe/1.27" audit-ID="" srcIP="10.44.0.0:54234" resp=200
I0916 09:58:01.708421       1 httplog.go:132] "HTTP" verb="GET" URI="/healthz" latency="129.142µs" userAgent="kube-probe/1.27" audit-ID="" srcIP="10.44.0.0:54220" resp=200
I0916 09:58:11.699299       1 httplog.go:132] "HTTP" verb="GET" URI="/healthz" latency="100.749µs" userAgent="kube-probe/1.27" audit-ID="" srcIP="10.44.0.0:40938" resp=200
I0916 09:58:11.702031       1 httplog.go:132] "HTTP" verb="GET" URI="/healthz" latency="54.072µs" userAgent="kube-probe/1.27" audit-ID="" srcIP="10.44.0.0:40930" resp=200
I0916 09:58:21.698789       1 httplog.go:132] "HTTP" verb="GET" URI="/healthz" latency="145.122µs" userAgent="kube-probe/1.27" audit-ID="" srcIP="10.44.0.0:58774" resp=200
I0916 09:58:21.701331       1 httplog.go:132] "HTTP" verb="GET" URI="/healthz" latency="106.018µs" userAgent="kube-probe/1.27" audit-ID="" srcIP="10.44.0.0:58780" resp=200
I0916 09:58:31.699275       1 httplog.go:132] "HTTP" verb="GET" URI="/healthz" latency="70.492µs" userAgent="kube-probe/1.27" audit-ID="" srcIP="10.44.0.0:34882" resp=200
I0916 09:58:31.699270       1 httplog.go:132] "HTTP" verb="GET" URI="/healthz" latency="109.165µs" userAgent="kube-probe/1.27" audit-ID="" srcIP="10.44.0.0:34878" resp=200
I0916 09:58:41.702571       1 httplog.go:132] "HTTP" verb="GET" URI="/healthz" latency="129.051µs" userAgent="kube-probe/1.27" audit-ID="" srcIP="10.44.0.0:51130" resp=200
I0916 09:58:41.703766       1 httplog.go:132] "HTTP" verb="GET" URI="/healthz" latency="99.277µs" userAgent="kube-probe/1.27" audit-ID="" srcIP="10.44.0.0:51146" resp=200
I0916 09:58:51.702668       1 httplog.go:132] "HTTP" verb="GET" URI="/healthz" latency="132.057µs" userAgent="kube-probe/1.27" audit-ID="" srcIP="10.44.0.0:38022" resp=200
I0916 09:58:51.703815       1 httplog.go:132] "HTTP" verb="GET" URI="/healthz" latency="64.251µs" userAgent="kube-probe/1.27" audit-ID="" srcIP="10.44.0.0:38034" resp=200
I0916 09:59:01.702310       1 httplog.go:132] "HTTP" verb="GET" URI="/healthz" latency="231.925µs" userAgent="kube-probe/1.27" audit-ID="" srcIP="10.44.0.0:60680" resp=200
I0916 09:59:01.703547       1 httplog.go:132] "HTTP" verb="GET" URI="/healthz" latency="142.938µs" userAgent="kube-probe/1.27" audit-ID="" srcIP="10.44.0.0:60690" resp=200
I0916 09:59:11.702632       1 httplog.go:132] "HTTP" verb="GET" URI="/healthz" latency="123.892µs" userAgent="kube-probe/1.27" audit-ID="" srcIP="10.44.0.0:57120" resp=200
I0916 09:59:11.703874       1 httplog.go:132] "HTTP" verb="GET" URI="/healthz" latency="119.885µs" userAgent="kube-probe/1.27" audit-ID="" srcIP="10.44.0.0:57118" resp=200
I0916 09:59:21.702969       1 httplog.go:132] "HTTP" verb="GET" URI="/healthz" latency="353.893µs" userAgent="kube-probe/1.27" audit-ID="" srcIP="10.44.0.0:40018" resp=200
I0916 09:59:21.703800       1 httplog.go:132] "HTTP" verb="GET" URI="/healthz" latency="95.129µs" userAgent="kube-probe/1.27" audit-ID="" srcIP="10.44.0.0:40032" resp=200
I0916 09:59:31.702536       1 httplog.go:132] "HTTP" verb="GET" URI="/healthz" latency="119.814µs" userAgent="kube-probe/1.27" audit-ID="" srcIP="10.44.0.0:53894" resp=200
I0916 09:59:31.703537       1 httplog.go:132] "HTTP" verb="GET" URI="/healthz" latency="54.492µs" userAgent="kube-probe/1.27" audit-ID="" srcIP="10.44.0.0:53888" resp=200
I0916 09:59:41.707193       1 httplog.go:132] "HTTP" verb="GET" URI="/healthz" latency="146.475µs" userAgent="kube-probe/1.27" audit-ID="" srcIP="10.44.0.0:43460" resp=200
I0916 09:59:41.708350       1 httplog.go:132] "HTTP" verb="GET" URI="/healthz" latency="74.61µs" userAgent="kube-probe/1.27" audit-ID="" srcIP="10.44.0.0:43468" resp=200
I0916 09:59:51.707302       1 httplog.go:132] "HTTP" verb="GET" URI="/healthz" latency="138.239µs" userAgent="kube-probe/1.27" audit-ID="" srcIP="10.44.0.0:51680" resp=200
I0916 09:59:51.708539       1 httplog.go:132] "HTTP" verb="GET" URI="/healthz" latency="109.055µs" userAgent="kube-probe/1.27" audit-ID="" srcIP="10.44.0.0:51682" resp=200
I0916 10:00:01.702014       1 httplog.go:132] "HTTP" verb="GET" URI="/healthz" latency="143.299µs" userAgent="kube-probe/1.27" audit-ID="" srcIP="10.44.0.0:46452" resp=200
I0916 10:00:01.703080       1 httplog.go:132] "HTTP" verb="GET" URI="/healthz" latency="143.469µs" userAgent="kube-probe/1.27" audit-ID="" srcIP="10.44.0.0:46466" resp=200
I0916 10:00:11.702216       1 httplog.go:132] "HTTP" verb="GET" URI="/healthz" latency="102.211µs" userAgent="kube-probe/1.27" audit-ID="" srcIP="10.44.0.0:46772" resp=200
I0916 10:00:11.703245       1 httplog.go:132] "HTTP" verb="GET" URI="/healthz" latency="133.19µs" userAgent="kube-probe/1.27" audit-ID="" srcIP="10.44.0.0:46786" resp=200
I0916 10:00:21.702897       1 httplog.go:132] "HTTP" verb="GET" URI="/healthz" latency="118.222µs" userAgent="kube-probe/1.27" audit-ID="" srcIP="10.44.0.0:38482" resp=200
I0916 10:00:21.704124       1 httplog.go:132] "HTTP" verb="GET" URI="/healthz" latency="118.813µs" userAgent="kube-probe/1.27" audit-ID="" srcIP="10.44.0.0:38498" resp=200
I0916 10:00:31.703121       1 httplog.go:132] "HTTP" verb="GET" URI="/healthz" latency="106.45µs" userAgent="kube-probe/1.27" audit-ID="" srcIP="10.44.0.0:50302" resp=200
I0916 10:00:31.704390       1 httplog.go:132] "HTTP" verb="GET" URI="/healthz" latency="55.865µs" userAgent="kube-probe/1.27" audit-ID="" srcIP="10.44.0.0:50300" resp=200
I0916 10:00:41.706925       1 httplog.go:132] "HTTP" verb="GET" URI="/healthz" latency="142.477µs" userAgent="kube-probe/1.27" audit-ID="" srcIP="10.44.0.0:42724" resp=200
I0916 10:00:41.707847       1 httplog.go:132] "HTTP" verb="GET" URI="/healthz" latency="63.399µs" userAgent="kube-probe/1.27" audit-ID="" srcIP="10.44.0.0:42738" resp=200
I0916 10:00:51.703100       1 httplog.go:132] "HTTP" verb="GET" URI="/healthz" latency="93.014µs" userAgent="kube-probe/1.27" audit-ID="" srcIP="10.44.0.0:45844" resp=200
I0916 10:00:51.710509       1 httplog.go:132] "HTTP" verb="GET" URI="/healthz" latency="55.123µs" userAgent="kube-probe/1.27" audit-ID="" srcIP="10.44.0.0:45856" resp=200
I0916 10:00:58.698058       1 eventhandlers.go:231] "Delete event for scheduled pod" pod="default/falcon-pod-381278"
I0916 10:01:01.707270       1 httplog.go:132] "HTTP" verb="GET" URI="/healthz" latency="132.809µs" userAgent="kube-probe/1.27" audit-ID="" srcIP="10.44.0.0:50738" resp=200
I0916 10:01:01.708454       1 httplog.go:132] "HTTP" verb="GET" URI="/healthz" latency="122.38µs" userAgent="kube-probe/1.27" audit-ID="" srcIP="10.44.0.0:50746" resp=200
I0916 10:01:11.707271       1 httplog.go:132] "HTTP" verb="GET" URI="/healthz" latency="96.751µs" userAgent="kube-probe/1.27" audit-ID="" srcIP="10.44.0.0:59494" resp=200
I0916 10:01:11.708280       1 httplog.go:132] "HTTP" verb="GET" URI="/healthz" latency="30.437µs" userAgent="kube-probe/1.27" audit-ID="" srcIP="10.44.0.0:59504" resp=200
I0916 10:01:21.707384       1 httplog.go:132] "HTTP" verb="GET" URI="/healthz" latency="113.563µs" userAgent="kube-probe/1.27" audit-ID="" srcIP="10.44.0.0:50562" resp=200
I0916 10:01:21.708494       1 httplog.go:132] "HTTP" verb="GET" URI="/healthz" latency="118.302µs" userAgent="kube-probe/1.27" audit-ID="" srcIP="10.44.0.0:50574" resp=200
I0916 10:01:31.706793       1 httplog.go:132] "HTTP" verb="GET" URI="/healthz" latency="130.735µs" userAgent="kube-probe/1.27" audit-ID="" srcIP="10.44.0.0:50404" resp=200
I0916 10:01:31.707924       1 httplog.go:132] "HTTP" verb="GET" URI="/healthz" latency="117.6µs" userAgent="kube-probe/1.27" audit-ID="" srcIP="10.44.0.0:50412" resp=200
I0916 10:01:41.707805       1 httplog.go:132] "HTTP" verb="GET" URI="/healthz" latency="131.466µs" userAgent="kube-probe/1.27" audit-ID="" srcIP="10.44.0.0:36432" resp=200
I0916 10:01:41.708703       1 httplog.go:132] "HTTP" verb="GET" URI="/healthz" latency="50.464µs" userAgent="kube-probe/1.27" audit-ID="" srcIP="10.44.0.0:36442" resp=200
I0916 10:01:51.702178       1 httplog.go:132] "HTTP" verb="GET" URI="/healthz" latency="128.25µs" userAgent="kube-probe/1.27" audit-ID="" srcIP="10.44.0.0:55620" resp=200
I0916 10:01:51.707982       1 httplog.go:132] "HTTP" verb="GET" URI="/healthz" latency="98.595µs" userAgent="kube-probe/1.27" audit-ID="" srcIP="10.44.0.0:55626" resp=200
I0916 10:02:01.701068       1 httplog.go:132] "HTTP" verb="GET" URI="/healthz" latency="146.585µs" userAgent="kube-probe/1.27" audit-ID="" srcIP="10.44.0.0:58094" resp=200
I0916 10:02:01.702196       1 httplog.go:132] "HTTP" verb="GET" URI="/healthz" latency="51.396µs" userAgent="kube-probe/1.27" audit-ID="" srcIP="10.44.0.0:58078" resp=200
I0916 10:02:11.702241       1 httplog.go:132] "HTTP" verb="GET" URI="/healthz" latency="128.822µs" userAgent="kube-probe/1.27" audit-ID="" srcIP="10.44.0.0:40280" resp=200
I0916 10:02:11.703322       1 httplog.go:132] "HTTP" verb="GET" URI="/healthz" latency="152.767µs" userAgent="kube-probe/1.27" audit-ID="" srcIP="10.44.0.0:40272" resp=200
I0916 10:02:21.700105       1 httplog.go:132] "HTTP" verb="GET" URI="/healthz" latency="73.267µs" userAgent="kube-probe/1.27" audit-ID="" srcIP="10.44.0.0:50990" resp=200
I0916 10:02:21.703152       1 httplog.go:132] "HTTP" verb="GET" URI="/healthz" latency="119.023µs" userAgent="kube-probe/1.27" audit-ID="" srcIP="10.44.0.0:50992" resp=200
I0916 10:02:31.706859       1 httplog.go:132] "HTTP" verb="GET" URI="/healthz" latency="131.987µs" userAgent="kube-probe/1.27" audit-ID="" srcIP="10.44.0.0:33782" resp=200
I0916 10:02:31.708241       1 httplog.go:132] "HTTP" verb="GET" URI="/healthz" latency="72.987µs" userAgent="kube-probe/1.27" audit-ID="" srcIP="10.44.0.0:33786" resp=200
I0916 10:02:41.706959       1 httplog.go:132] "HTTP" verb="GET" URI="/healthz" latency="111.248µs" userAgent="kube-probe/1.27" audit-ID="" srcIP="10.44.0.0:33228" resp=200
I0916 10:02:41.708037       1 httplog.go:132] "HTTP" verb="GET" URI="/healthz" latency="82.745µs" userAgent="kube-probe/1.27" audit-ID="" srcIP="10.44.0.0:33230" resp=200
I0916 10:02:51.702412       1 httplog.go:132] "HTTP" verb="GET" URI="/healthz" latency="138.75µs" userAgent="kube-probe/1.27" audit-ID="" srcIP="10.44.0.0:45678" resp=200
I0916 10:02:51.709972       1 httplog.go:132] "HTTP" verb="GET" URI="/healthz" latency="102.753µs" userAgent="kube-probe/1.27" audit-ID="" srcIP="10.44.0.0:45706" resp=200
I0916 10:03:01.703523       1 httplog.go:132] "HTTP" verb="GET" URI="/healthz" latency="120.666µs" userAgent="kube-probe/1.27" audit-ID="" srcIP="10.44.0.0:42740" resp=200
I0916 10:03:01.710701       1 httplog.go:132] "HTTP" verb="GET" URI="/healthz" latency="124.463µs" userAgent="kube-probe/1.27" audit-ID="" srcIP="10.44.0.0:42752" resp=200
I0916 10:03:11.706552       1 httplog.go:132] "HTTP" verb="GET" URI="/healthz" latency="106.861µs" userAgent="kube-probe/1.27" audit-ID="" srcIP="10.44.0.0:35302" resp=200
I0916 10:03:11.708490       1 httplog.go:132] "HTTP" verb="GET" URI="/healthz" latency="84.689µs" userAgent="kube-probe/1.27" audit-ID="" srcIP="10.44.0.0:35318" resp=200
I0916 10:03:21.706253       1 httplog.go:132] "HTTP" verb="GET" URI="/healthz" latency="127.459µs" userAgent="kube-probe/1.27" audit-ID="" srcIP="10.44.0.0:47508" resp=200
I0916 10:03:21.707271       1 httplog.go:132] "HTTP" verb="GET" URI="/healthz" latency="61.114µs" userAgent="kube-probe/1.27" audit-ID="" srcIP="10.44.0.0:47494" resp=200
I0916 10:03:31.702606       1 httplog.go:132] "HTTP" verb="GET" URI="/healthz" latency="101.591µs" userAgent="kube-probe/1.27" audit-ID="" srcIP="10.44.0.0:52160" resp=200
I0916 10:03:31.703764       1 httplog.go:132] "HTTP" verb="GET" URI="/healthz" latency="96.401µs" userAgent="kube-probe/1.27" audit-ID="" srcIP="10.44.0.0:52162" resp=200
I0916 10:03:41.707496       1 httplog.go:132] "HTTP" verb="GET" URI="/healthz" latency="136.486µs" userAgent="kube-probe/1.27" audit-ID="" srcIP="10.44.0.0:34078" resp=200
I0916 10:03:41.708419       1 httplog.go:132] "HTTP" verb="GET" URI="/healthz" latency="85.009µs" userAgent="kube-probe/1.27" audit-ID="" srcIP="10.44.0.0:34070" resp=200
I0916 10:03:51.707410       1 httplog.go:132] "HTTP" verb="GET" URI="/healthz" latency="144.851µs" userAgent="kube-probe/1.27" audit-ID="" srcIP="10.44.0.0:50604" resp=200
I0916 10:03:51.708532       1 httplog.go:132] "HTTP" verb="GET" URI="/healthz" latency="124.263µs" userAgent="kube-probe/1.27" audit-ID="" srcIP="10.44.0.0:50620" resp=200
I0916 10:04:01.702774       1 httplog.go:132] "HTTP" verb="GET" URI="/healthz" latency="84.428µs" userAgent="kube-probe/1.27" audit-ID="" srcIP="10.44.0.0:37612" resp=200
I0916 10:04:01.704050       1 httplog.go:132] "HTTP" verb="GET" URI="/healthz" latency="117.851µs" userAgent="kube-probe/1.27" audit-ID="" srcIP="10.44.0.0:37614" resp=200
I0916 10:04:11.703097       1 httplog.go:132] "HTTP" verb="GET" URI="/healthz" latency="83.186µs" userAgent="kube-probe/1.27" audit-ID="" srcIP="10.44.0.0:49490" resp=200
I0916 10:04:11.710482       1 httplog.go:132] "HTTP" verb="GET" URI="/healthz" latency="105.047µs" userAgent="kube-probe/1.27" audit-ID="" srcIP="10.44.0.0:49496" resp=200
I0916 10:04:21.707160       1 httplog.go:132] "HTTP" verb="GET" URI="/healthz" latency="136.386µs" userAgent="kube-probe/1.27" audit-ID="" srcIP="10.44.0.0:38108" resp=200
I0916 10:04:21.708340       1 httplog.go:132] "HTTP" verb="GET" URI="/healthz" latency="123.331µs" userAgent="kube-probe/1.27" audit-ID="" srcIP="10.44.0.0:38114" resp=200
I0916 10:04:31.707151       1 httplog.go:132] "HTTP" verb="GET" URI="/healthz" latency="161.022µs" userAgent="kube-probe/1.27" audit-ID="" srcIP="10.44.0.0:44302" resp=200
I0916 10:04:31.708362       1 httplog.go:132] "HTTP" verb="GET" URI="/healthz" latency="64.882µs" userAgent="kube-probe/1.27" audit-ID="" srcIP="10.44.0.0:44318" resp=200
I0916 10:04:41.702418       1 httplog.go:132] "HTTP" verb="GET" URI="/healthz" latency="97.412µs" userAgent="kube-probe/1.27" audit-ID="" srcIP="10.44.0.0:53264" resp=200
I0916 10:04:41.703585       1 httplog.go:132] "HTTP" verb="GET" URI="/healthz" latency="124.343µs" userAgent="kube-probe/1.27" audit-ID="" srcIP="10.44.0.0:53266" resp=200
I0916 10:04:51.707539       1 httplog.go:132] "HTTP" verb="GET" URI="/healthz" latency="284.955µs" userAgent="kube-probe/1.27" audit-ID="" srcIP="10.44.0.0:32814" resp=200
I0916 10:04:51.708559       1 httplog.go:132] "HTTP" verb="GET" URI="/healthz" latency="108.974µs" userAgent="kube-probe/1.27" audit-ID="" srcIP="10.44.0.0:32822" resp=200
I0916 10:05:01.707615       1 httplog.go:132] "HTTP" verb="GET" URI="/healthz" latency="131.687µs" userAgent="kube-probe/1.27" audit-ID="" srcIP="10.44.0.0:33330" resp=200
I0916 10:05:01.708778       1 httplog.go:132] "HTTP" verb="GET" URI="/healthz" latency="164.768µs" userAgent="kube-probe/1.27" audit-ID="" srcIP="10.44.0.0:33332" resp=200
I0916 10:05:11.702739       1 httplog.go:132] "HTTP" verb="GET" URI="/healthz" latency="90.509µs" userAgent="kube-probe/1.27" audit-ID="" srcIP="10.44.0.0:56814" resp=200
I0916 10:05:11.703890       1 httplog.go:132] "HTTP" verb="GET" URI="/healthz" latency="77.295µs" userAgent="kube-probe/1.27" audit-ID="" srcIP="10.44.0.0:56818" resp=200
I0916 10:05:21.706574       1 httplog.go:132] "HTTP" verb="GET" URI="/healthz" latency="82.154µs" userAgent="kube-probe/1.27" audit-ID="" srcIP="10.44.0.0:36460" resp=200
I0916 10:05:21.707736       1 httplog.go:132] "HTTP" verb="GET" URI="/healthz" latency="57.869µs" userAgent="kube-probe/1.27" audit-ID="" srcIP="10.44.0.0:36462" resp=200
I0916 10:05:31.707149       1 httplog.go:132] "HTTP" verb="GET" URI="/healthz" latency="94.367µs" userAgent="kube-probe/1.27" audit-ID="" srcIP="10.44.0.0:45936" resp=200
I0916 10:05:31.708218       1 httplog.go:132] "HTTP" verb="GET" URI="/healthz" latency="27.762µs" userAgent="kube-probe/1.27" audit-ID="" srcIP="10.44.0.0:45934" resp=200
I0916 10:05:41.702150       1 httplog.go:132] "HTTP" verb="GET" URI="/healthz" latency="112.501µs" userAgent="kube-probe/1.27" audit-ID="" srcIP="10.44.0.0:57412" resp=200
I0916 10:05:41.703264       1 httplog.go:132] "HTTP" verb="GET" URI="/healthz" latency="91.021µs" userAgent="kube-probe/1.27" audit-ID="" srcIP="10.44.0.0:57400" resp=200
I0916 10:05:51.707072       1 httplog.go:132] "HTTP" verb="GET" URI="/healthz" latency="103.163µs" userAgent="kube-probe/1.27" audit-ID="" srcIP="10.44.0.0:55954" resp=200
I0916 10:05:51.708515       1 httplog.go:132] "HTTP" verb="GET" URI="/healthz" latency="109.084µs" userAgent="kube-probe/1.27" audit-ID="" srcIP="10.44.0.0:55960" resp=200
I0916 10:06:01.702100       1 httplog.go:132] "HTTP" verb="GET" URI="/healthz" latency="98.124µs" userAgent="kube-probe/1.27" audit-ID="" srcIP="10.44.0.0:48888" resp=200
I0916 10:06:01.702909       1 httplog.go:132] "HTTP" verb="GET" URI="/healthz" latency="83.076µs" userAgent="kube-probe/1.27" audit-ID="" srcIP="10.44.0.0:48898" resp=200
I0916 10:06:11.706416       1 httplog.go:132] "HTTP" verb="GET" URI="/healthz" latency="122.579µs" userAgent="kube-probe/1.27" audit-ID="" srcIP="10.44.0.0:46606" resp=200
I0916 10:06:11.707712       1 httplog.go:132] "HTTP" verb="GET" URI="/healthz" latency="95.639µs" userAgent="kube-probe/1.27" audit-ID="" srcIP="10.44.0.0:46604" resp=200
I0916 10:06:21.702433       1 httplog.go:132] "HTTP" verb="GET" URI="/healthz" latency="86.783µs" userAgent="kube-probe/1.27" audit-ID="" srcIP="10.44.0.0:41488" resp=200
I0916 10:06:21.702997       1 httplog.go:132] "HTTP" verb="GET" URI="/healthz" latency="160.601µs" userAgent="kube-probe/1.27" audit-ID="" srcIP="10.44.0.0:41502" resp=200
I0916 10:06:31.702443       1 httplog.go:132] "HTTP" verb="GET" URI="/healthz" latency="94.667µs" userAgent="kube-probe/1.27" audit-ID="" srcIP="10.44.0.0:38978" resp=200
I0916 10:06:31.703598       1 httplog.go:132] "HTTP" verb="GET" URI="/healthz" latency="105.438µs" userAgent="kube-probe/1.27" audit-ID="" srcIP="10.44.0.0:38984" resp=200
I0916 10:06:41.701972       1 httplog.go:132] "HTTP" verb="GET" URI="/healthz" latency="111.379µs" userAgent="kube-probe/1.27" audit-ID="" srcIP="10.44.0.0:54642" resp=200
I0916 10:06:41.709674       1 httplog.go:132] "HTTP" verb="GET" URI="/healthz" latency="108.374µs" userAgent="kube-probe/1.27" audit-ID="" srcIP="10.44.0.0:54660" resp=200
I0916 10:06:51.706875       1 httplog.go:132] "HTTP" verb="GET" URI="/healthz" latency="102.111µs" userAgent="kube-probe/1.27" audit-ID="" srcIP="10.44.0.0:50650" resp=200
I0916 10:06:51.707988       1 httplog.go:132] "HTTP" verb="GET" URI="/healthz" latency="86.853µs" userAgent="kube-probe/1.27" audit-ID="" srcIP="10.44.0.0:50644" resp=200
I0916 10:07:01.706592       1 httplog.go:132] "HTTP" verb="GET" URI="/healthz" latency="166.292µs" userAgent="kube-probe/1.27" audit-ID="" srcIP="10.44.0.0:55422" resp=200
I0916 10:07:01.707722       1 httplog.go:132] "HTTP" verb="GET" URI="/healthz" latency="104.566µs" userAgent="kube-probe/1.27" audit-ID="" srcIP="10.44.0.0:55416" resp=200
I0916 10:07:11.702878       1 httplog.go:132] "HTTP" verb="GET" URI="/healthz" latency="123.061µs" userAgent="kube-probe/1.27" audit-ID="" srcIP="10.44.0.0:36522" resp=200
I0916 10:07:11.703839       1 httplog.go:132] "HTTP" verb="GET" URI="/healthz" latency="141.445µs" userAgent="kube-probe/1.27" audit-ID="" srcIP="10.44.0.0:36512" resp=200
I0916 10:07:21.702801       1 httplog.go:132] "HTTP" verb="GET" URI="/healthz" latency="97.663µs" userAgent="kube-probe/1.27" audit-ID="" srcIP="10.44.0.0:58862" resp=200
I0916 10:07:21.710463       1 httplog.go:132] "HTTP" verb="GET" URI="/healthz" latency="113.102µs" userAgent="kube-probe/1.27" audit-ID="" srcIP="10.44.0.0:58880" resp=200
I0916 10:07:31.706347       1 httplog.go:132] "HTTP" verb="GET" URI="/healthz" latency="128.19µs" userAgent="kube-probe/1.27" audit-ID="" srcIP="10.44.0.0:56078" resp=200
I0916 10:07:31.707365       1 httplog.go:132] "HTTP" verb="GET" URI="/healthz" latency="79.088µs" userAgent="kube-probe/1.27" audit-ID="" srcIP="10.44.0.0:56092" resp=200
I0916 10:07:41.702460       1 httplog.go:132] "HTTP" verb="GET" URI="/healthz" latency="108.944µs" userAgent="kube-probe/1.27" audit-ID="" srcIP="10.44.0.0:45854" resp=200
I0916 10:07:41.709965       1 httplog.go:132] "HTTP" verb="GET" URI="/healthz" latency="51.637µs" userAgent="kube-probe/1.27" audit-ID="" srcIP="10.44.0.0:45874" resp=200
I0916 10:07:51.706839       1 httplog.go:132] "HTTP" verb="GET" URI="/healthz" latency="96.5µs" userAgent="kube-probe/1.27" audit-ID="" srcIP="10.44.0.0:48352" resp=200
I0916 10:07:51.707920       1 httplog.go:132] "HTTP" verb="GET" URI="/healthz" latency="32.791µs" userAgent="kube-probe/1.27" audit-ID="" srcIP="10.44.0.0:48350" resp=200
I0916 10:08:01.706548       1 httplog.go:132] "HTTP" verb="GET" URI="/healthz" latency="115.948µs" userAgent="kube-probe/1.27" audit-ID="" srcIP="10.44.0.0:44790" resp=200
I0916 10:08:01.707734       1 httplog.go:132] "HTTP" verb="GET" URI="/healthz" latency="101.27µs" userAgent="kube-probe/1.27" audit-ID="" srcIP="10.44.0.0:44804" resp=200
I0916 10:08:11.706605       1 httplog.go:132] "HTTP" verb="GET" URI="/healthz" latency="128µs" userAgent="kube-probe/1.27" audit-ID="" srcIP="10.44.0.0:58230" resp=200
I0916 10:08:11.707640       1 httplog.go:132] "HTTP" verb="GET" URI="/healthz" latency="78.417µs" userAgent="kube-probe/1.27" audit-ID="" srcIP="10.44.0.0:58226" resp=200
I0916 10:08:21.706322       1 httplog.go:132] "HTTP" verb="GET" URI="/healthz" latency="88.656µs" userAgent="kube-probe/1.27" audit-ID="" srcIP="10.44.0.0:48530" resp=200
I0916 10:08:21.707432       1 httplog.go:132] "HTTP" verb="GET" URI="/healthz" latency="31.539µs" userAgent="kube-probe/1.27" audit-ID="" srcIP="10.44.0.0:48542" resp=200
I0916 10:08:31.706319       1 httplog.go:132] "HTTP" verb="GET" URI="/healthz" latency="121.538µs" userAgent="kube-probe/1.27" audit-ID="" srcIP="10.44.0.0:58844" resp=200
I0916 10:08:31.707483       1 httplog.go:132] "HTTP" verb="GET" URI="/healthz" latency="101.07µs" userAgent="kube-probe/1.27" audit-ID="" srcIP="10.44.0.0:58836" resp=200
I0916 10:08:41.702856       1 httplog.go:132] "HTTP" verb="GET" URI="/healthz" latency="98.975µs" userAgent="kube-probe/1.27" audit-ID="" srcIP="10.44.0.0:36406" resp=200
I0916 10:08:41.705350       1 httplog.go:132] "HTTP" verb="GET" URI="/healthz" latency="54.983µs" userAgent="kube-probe/1.27" audit-ID="" srcIP="10.44.0.0:36414" resp=200
I0916 10:08:51.701918       1 httplog.go:132] "HTTP" verb="GET" URI="/healthz" latency="102.802µs" userAgent="kube-probe/1.27" audit-ID="" srcIP="10.44.0.0:59782" resp=200
I0916 10:08:51.703029       1 httplog.go:132] "HTTP" verb="GET" URI="/healthz" latency="60.082µs" userAgent="kube-probe/1.27" audit-ID="" srcIP="10.44.0.0:59780" resp=200
I0916 10:09:01.706451       1 httplog.go:132] "HTTP" verb="GET" URI="/healthz" latency="130.395µs" userAgent="kube-probe/1.27" audit-ID="" srcIP="10.44.0.0:49232" resp=200
I0916 10:09:01.707690       1 httplog.go:132] "HTTP" verb="GET" URI="/healthz" latency="50.655µs" userAgent="kube-probe/1.27" audit-ID="" srcIP="10.44.0.0:49240" resp=200
I0916 10:09:11.707795       1 httplog.go:132] "HTTP" verb="GET" URI="/healthz" latency="104.325µs" userAgent="kube-probe/1.27" audit-ID="" srcIP="10.44.0.0:41142" resp=200
I0916 10:09:11.708840       1 httplog.go:132] "HTTP" verb="GET" URI="/healthz" latency="60.193µs" userAgent="kube-probe/1.27" audit-ID="" srcIP="10.44.0.0:41156" resp=200
I0916 10:09:21.707291       1 httplog.go:132] "HTTP" verb="GET" URI="/healthz" latency="123.141µs" userAgent="kube-probe/1.27" audit-ID="" srcIP="10.44.0.0:39898" resp=200
I0916 10:09:21.708439       1 httplog.go:132] "HTTP" verb="GET" URI="/healthz" latency="110.237µs" userAgent="kube-probe/1.27" audit-ID="" srcIP="10.44.0.0:39910" resp=200
I0916 10:09:31.707106       1 httplog.go:132] "HTTP" verb="GET" URI="/healthz" latency="97.272µs" userAgent="kube-probe/1.27" audit-ID="" srcIP="10.44.0.0:51532" resp=200
I0916 10:09:31.708243       1 httplog.go:132] "HTTP" verb="GET" URI="/healthz" latency="75.902µs" userAgent="kube-probe/1.27" audit-ID="" srcIP="10.44.0.0:51516" resp=200
I0916 10:09:41.706708       1 httplog.go:132] "HTTP" verb="GET" URI="/healthz" latency="79.058µs" userAgent="kube-probe/1.27" audit-ID="" srcIP="10.44.0.0:53358" resp=200
I0916 10:09:41.711644       1 httplog.go:132] "HTTP" verb="GET" URI="/healthz" latency="131.687µs" userAgent="kube-probe/1.27" audit-ID="" srcIP="10.44.0.0:53356" resp=200
I0916 10:09:51.701582       1 httplog.go:132] "HTTP" verb="GET" URI="/healthz" latency="110.346µs" userAgent="kube-probe/1.27" audit-ID="" srcIP="10.44.0.0:32848" resp=200
I0916 10:09:51.702955       1 httplog.go:132] "HTTP" verb="GET" URI="/healthz" latency="61.936µs" userAgent="kube-probe/1.27" audit-ID="" srcIP="10.44.0.0:32862" resp=200
I0916 10:10:01.707325       1 httplog.go:132] "HTTP" verb="GET" URI="/healthz" latency="96.591µs" userAgent="kube-probe/1.27" audit-ID="" srcIP="10.44.0.0:42306" resp=200
I0916 10:10:01.708432       1 httplog.go:132] "HTTP" verb="GET" URI="/healthz" latency="114.355µs" userAgent="kube-probe/1.27" audit-ID="" srcIP="10.44.0.0:42314" resp=200
I0916 10:10:11.706637       1 httplog.go:132] "HTTP" verb="GET" URI="/healthz" latency="109.355µs" userAgent="kube-probe/1.27" audit-ID="" srcIP="10.44.0.0:57424" resp=200
I0916 10:10:11.708375       1 httplog.go:132] "HTTP" verb="GET" URI="/healthz" latency="50.114µs" userAgent="kube-probe/1.27" audit-ID="" srcIP="10.44.0.0:57432" resp=200
I0916 10:10:21.707290       1 httplog.go:132] "HTTP" verb="GET" URI="/healthz" latency="94.437µs" userAgent="kube-probe/1.27" audit-ID="" srcIP="10.44.0.0:54280" resp=200
I0916 10:10:21.714753       1 httplog.go:132] "HTTP" verb="GET" URI="/healthz" latency="52.208µs" userAgent="kube-probe/1.27" audit-ID="" srcIP="10.44.0.0:54292" resp=200
I0916 10:10:31.699355       1 httplog.go:132] "HTTP" verb="GET" URI="/healthz" latency="96.731µs" userAgent="kube-probe/1.27" audit-ID="" srcIP="10.44.0.0:39988" resp=200
I0916 10:10:31.700271       1 httplog.go:132] "HTTP" verb="GET" URI="/healthz" latency="83.396µs" userAgent="kube-probe/1.27" audit-ID="" srcIP="10.44.0.0:39986" resp=200
I0916 10:10:41.702601       1 httplog.go:132] "HTTP" verb="GET" URI="/healthz" latency="107.412µs" userAgent="kube-probe/1.27" audit-ID="" srcIP="10.44.0.0:38692" resp=200
I0916 10:10:41.709952       1 httplog.go:132] "HTTP" verb="GET" URI="/healthz" latency="58.82µs" userAgent="kube-probe/1.27" audit-ID="" srcIP="10.44.0.0:38704" resp=200
I0916 10:10:51.706869       1 httplog.go:132] "HTTP" verb="GET" URI="/healthz" latency="109.766µs" userAgent="kube-probe/1.27" audit-ID="" srcIP="10.44.0.0:56582" resp=200
I0916 10:10:51.708002       1 httplog.go:132] "HTTP" verb="GET" URI="/healthz" latency="100.198µs" userAgent="kube-probe/1.27" audit-ID="" srcIP="10.44.0.0:56570" resp=200
I0916 10:11:01.702141       1 httplog.go:132] "HTTP" verb="GET" URI="/healthz" latency="108.574µs" userAgent="kube-probe/1.27" audit-ID="" srcIP="10.44.0.0:37046" resp=200
I0916 10:11:01.703300       1 httplog.go:132] "HTTP" verb="GET" URI="/healthz" latency="72.556µs" userAgent="kube-probe/1.27" audit-ID="" srcIP="10.44.0.0:37052" resp=200
I0916 10:11:11.707485       1 httplog.go:132] "HTTP" verb="GET" URI="/healthz" latency="101.059µs" userAgent="kube-probe/1.27" audit-ID="" srcIP="10.44.0.0:54806" resp=200
I0916 10:11:11.709280       1 httplog.go:132] "HTTP" verb="GET" URI="/healthz" latency="118.642µs" userAgent="kube-probe/1.27" audit-ID="" srcIP="10.44.0.0:54814" resp=200
I0916 10:11:21.707196       1 httplog.go:132] "HTTP" verb="GET" URI="/healthz" latency="132.218µs" userAgent="kube-probe/1.27" audit-ID="" srcIP="10.44.0.0:45228" resp=200
I0916 10:11:21.708470       1 httplog.go:132] "HTTP" verb="GET" URI="/healthz" latency="93.155µs" userAgent="kube-probe/1.27" audit-ID="" srcIP="10.44.0.0:45214" resp=200
I0916 10:11:31.702491       1 httplog.go:132] "HTTP" verb="GET" URI="/healthz" latency="111.809µs" userAgent="kube-probe/1.27" audit-ID="" srcIP="10.44.0.0:42434" resp=200
I0916 10:11:31.703816       1 httplog.go:132] "HTTP" verb="GET" URI="/healthz" latency="127.459µs" userAgent="kube-probe/1.27" audit-ID="" srcIP="10.44.0.0:42442" resp=200
I0916 10:11:41.702302       1 httplog.go:132] "HTTP" verb="GET" URI="/healthz" latency="140.023µs" userAgent="kube-probe/1.27" audit-ID="" srcIP="10.44.0.0:56160" resp=200
I0916 10:11:41.728110       1 httplog.go:132] "HTTP" verb="GET" URI="/healthz" latency="121.748µs" userAgent="kube-probe/1.27" audit-ID="" srcIP="10.44.0.0:56166" resp=200
I0916 10:11:51.702803       1 httplog.go:132] "HTTP" verb="GET" URI="/healthz" latency="136.256µs" userAgent="kube-probe/1.27" audit-ID="" srcIP="10.44.0.0:35998" resp=200
I0916 10:11:51.704124       1 httplog.go:132] "HTTP" verb="GET" URI="/healthz" latency="165.039µs" userAgent="kube-probe/1.27" audit-ID="" srcIP="10.44.0.0:36000" resp=200
I0916 10:12:01.702483       1 httplog.go:132] "HTTP" verb="GET" URI="/healthz" latency="90.47µs" userAgent="kube-probe/1.27" audit-ID="" srcIP="10.44.0.0:59350" resp=200
I0916 10:12:01.710287       1 httplog.go:132] "HTTP" verb="GET" URI="/healthz" latency="65.994µs" userAgent="kube-probe/1.27" audit-ID="" srcIP="10.44.0.0:59376" resp=200
I0916 10:12:11.702392       1 httplog.go:132] "HTTP" verb="GET" URI="/healthz" latency="109.496µs" userAgent="kube-probe/1.27" audit-ID="" srcIP="10.44.0.0:34522" resp=200
I0916 10:12:11.703492       1 httplog.go:132] "HTTP" verb="GET" URI="/healthz" latency="55.745µs" userAgent="kube-probe/1.27" audit-ID="" srcIP="10.44.0.0:34536" resp=200
I0916 10:12:21.702241       1 httplog.go:132] "HTTP" verb="GET" URI="/healthz" latency="135.776µs" userAgent="kube-probe/1.27" audit-ID="" srcIP="10.44.0.0:55604" resp=200
I0916 10:12:21.703233       1 httplog.go:132] "HTTP" verb="GET" URI="/healthz" latency="57.779µs" userAgent="kube-probe/1.27" audit-ID="" srcIP="10.44.0.0:55610" resp=200
I0916 10:12:31.702649       1 httplog.go:132] "HTTP" verb="GET" URI="/healthz" latency="94.318µs" userAgent="kube-probe/1.27" audit-ID="" srcIP="10.44.0.0:58138" resp=200
I0916 10:12:31.709963       1 httplog.go:132] "HTTP" verb="GET" URI="/healthz" latency="113.423µs" userAgent="kube-probe/1.27" audit-ID="" srcIP="10.44.0.0:58146" resp=200
I0916 10:12:41.702544       1 httplog.go:132] "HTTP" verb="GET" URI="/healthz" latency="188.054µs" userAgent="kube-probe/1.27" audit-ID="" srcIP="10.44.0.0:49406" resp=200
I0916 10:12:41.703398       1 httplog.go:132] "HTTP" verb="GET" URI="/healthz" latency="117.33µs" userAgent="kube-probe/1.27" audit-ID="" srcIP="10.44.0.0:49416" resp=200
I0916 10:12:51.703243       1 httplog.go:132] "HTTP" verb="GET" URI="/healthz" latency="188.344µs" userAgent="kube-probe/1.27" audit-ID="" srcIP="10.44.0.0:41520" resp=200
I0916 10:12:51.708814       1 httplog.go:132] "HTTP" verb="GET" URI="/healthz" latency="125.266µs" userAgent="kube-probe/1.27" audit-ID="" srcIP="10.44.0.0:41514" resp=200
I0916 10:13:01.707529       1 httplog.go:132] "HTTP" verb="GET" URI="/healthz" latency="148.569µs" userAgent="kube-probe/1.27" audit-ID="" srcIP="10.44.0.0:33774" resp=200
I0916 10:13:01.708503       1 httplog.go:132] "HTTP" verb="GET" URI="/healthz" latency="95.068µs" userAgent="kube-probe/1.27" audit-ID="" srcIP="10.44.0.0:33786" resp=200
I0916 10:13:11.706963       1 httplog.go:132] "HTTP" verb="GET" URI="/healthz" latency="102.964µs" userAgent="kube-probe/1.27" audit-ID="" srcIP="10.44.0.0:40590" resp=200
I0916 10:13:11.708181       1 httplog.go:132] "HTTP" verb="GET" URI="/healthz" latency="87.805µs" userAgent="kube-probe/1.27" audit-ID="" srcIP="10.44.0.0:40588" resp=200
I0916 10:13:21.702564       1 httplog.go:132] "HTTP" verb="GET" URI="/healthz" latency="64.461µs" userAgent="kube-probe/1.27" audit-ID="" srcIP="10.44.0.0:43734" resp=200
I0916 10:13:21.710394       1 httplog.go:132] "HTTP" verb="GET" URI="/healthz" latency="137.799µs" userAgent="kube-probe/1.27" audit-ID="" srcIP="10.44.0.0:43752" resp=200
I0916 10:13:31.706374       1 httplog.go:132] "HTTP" verb="GET" URI="/healthz" latency="107.342µs" userAgent="kube-probe/1.27" audit-ID="" srcIP="10.44.0.0:35056" resp=200
I0916 10:13:31.707490       1 httplog.go:132] "HTTP" verb="GET" URI="/healthz" latency="32.942µs" userAgent="kube-probe/1.27" audit-ID="" srcIP="10.44.0.0:35058" resp=200
I0916 10:13:41.701874       1 httplog.go:132] "HTTP" verb="GET" URI="/healthz" latency="126.067µs" userAgent="kube-probe/1.27" audit-ID="" srcIP="10.44.0.0:45618" resp=200
I0916 10:13:41.703015       1 httplog.go:132] "HTTP" verb="GET" URI="/healthz" latency="104.586µs" userAgent="kube-probe/1.27" audit-ID="" srcIP="10.44.0.0:45620" resp=200
I0916 10:13:51.702700       1 httplog.go:132] "HTTP" verb="GET" URI="/healthz" latency="119.544µs" userAgent="kube-probe/1.27" audit-ID="" srcIP="10.44.0.0:44666" resp=200
I0916 10:13:51.710474       1 httplog.go:132] "HTTP" verb="GET" URI="/healthz" latency="103.705µs" userAgent="kube-probe/1.27" audit-ID="" srcIP="10.44.0.0:44698" resp=200
I0916 10:14:01.706981       1 httplog.go:132] "HTTP" verb="GET" URI="/healthz" latency="90.059µs" userAgent="kube-probe/1.27" audit-ID="" srcIP="10.44.0.0:39968" resp=200
I0916 10:14:01.708326       1 httplog.go:132] "HTTP" verb="GET" URI="/healthz" latency="102.352µs" userAgent="kube-probe/1.27" audit-ID="" srcIP="10.44.0.0:39972" resp=200
I0916 10:14:11.707364       1 httplog.go:132] "HTTP" verb="GET" URI="/healthz" latency="101.531µs" userAgent="kube-probe/1.27" audit-ID="" srcIP="10.44.0.0:47812" resp=200
I0916 10:14:11.708285       1 httplog.go:132] "HTTP" verb="GET" URI="/healthz" latency="65.082µs" userAgent="kube-probe/1.27" audit-ID="" srcIP="10.44.0.0:47818" resp=200
I0916 10:14:21.702285       1 httplog.go:132] "HTTP" verb="GET" URI="/healthz" latency="87.815µs" userAgent="kube-probe/1.27" audit-ID="" srcIP="10.44.0.0:59148" resp=200
I0916 10:14:21.703583       1 httplog.go:132] "HTTP" verb="GET" URI="/healthz" latency="133.2µs" userAgent="kube-probe/1.27" audit-ID="" srcIP="10.44.0.0:59164" resp=200
I0916 10:14:31.702712       1 httplog.go:132] "HTTP" verb="GET" URI="/healthz" latency="131.096µs" userAgent="kube-probe/1.27" audit-ID="" srcIP="10.44.0.0:50552" resp=200
I0916 10:14:31.704105       1 httplog.go:132] "HTTP" verb="GET" URI="/healthz" latency="122.42µs" userAgent="kube-probe/1.27" audit-ID="" srcIP="10.44.0.0:50562" resp=200
I0916 10:14:41.707275       1 httplog.go:132] "HTTP" verb="GET" URI="/healthz" latency="105.559µs" userAgent="kube-probe/1.27" audit-ID="" srcIP="10.44.0.0:58516" resp=200
I0916 10:14:41.708386       1 httplog.go:132] "HTTP" verb="GET" URI="/healthz" latency="84.128µs" userAgent="kube-probe/1.27" audit-ID="" srcIP="10.44.0.0:58530" resp=200
I0916 10:14:51.706894       1 httplog.go:132] "HTTP" verb="GET" URI="/healthz" latency="118.964µs" userAgent="kube-probe/1.27" audit-ID="" srcIP="10.44.0.0:39750" resp=200
I0916 10:14:51.708000       1 httplog.go:132] "HTTP" verb="GET" URI="/healthz" latency="106.279µs" userAgent="kube-probe/1.27" audit-ID="" srcIP="10.44.0.0:39762" resp=200
I0916 10:15:01.702359       1 httplog.go:132] "HTTP" verb="GET" URI="/healthz" latency="165.631µs" userAgent="kube-probe/1.27" audit-ID="" srcIP="10.44.0.0:54270" resp=200
I0916 10:15:01.703558       1 httplog.go:132] "HTTP" verb="GET" URI="/healthz" latency="113.664µs" userAgent="kube-probe/1.27" audit-ID="" srcIP="10.44.0.0:54264" resp=200
I0916 10:15:11.707131       1 httplog.go:132] "HTTP" verb="GET" URI="/healthz" latency="115.597µs" userAgent="kube-probe/1.27" audit-ID="" srcIP="10.44.0.0:43086" resp=200
I0916 10:15:11.708174       1 httplog.go:132] "HTTP" verb="GET" URI="/healthz" latency="30.597µs" userAgent="kube-probe/1.27" audit-ID="" srcIP="10.44.0.0:43094" resp=200
I0916 10:15:21.702731       1 httplog.go:132] "HTTP" verb="GET" URI="/healthz" latency="135.524µs" userAgent="kube-probe/1.27" audit-ID="" srcIP="10.44.0.0:53762" resp=200
I0916 10:15:21.704045       1 httplog.go:132] "HTTP" verb="GET" URI="/healthz" latency="131.037µs" userAgent="kube-probe/1.27" audit-ID="" srcIP="10.44.0.0:53764" resp=200
I0916 10:15:31.707058       1 httplog.go:132] "HTTP" verb="GET" URI="/healthz" latency="120.236µs" userAgent="kube-probe/1.27" audit-ID="" srcIP="10.44.0.0:41982" resp=200
I0916 10:15:31.708139       1 httplog.go:132] "HTTP" verb="GET" URI="/healthz" latency="58.811µs" userAgent="kube-probe/1.27" audit-ID="" srcIP="10.44.0.0:41978" resp=200
I0916 10:15:41.706543       1 httplog.go:132] "HTTP" verb="GET" URI="/healthz" latency="89.668µs" userAgent="kube-probe/1.27" audit-ID="" srcIP="10.44.0.0:40878" resp=200
I0916 10:15:41.707688       1 httplog.go:132] "HTTP" verb="GET" URI="/healthz" latency="111.289µs" userAgent="kube-probe/1.27" audit-ID="" srcIP="10.44.0.0:40876" resp=200
I0916 10:15:51.706767       1 httplog.go:132] "HTTP" verb="GET" URI="/healthz" latency="132.199µs" userAgent="kube-probe/1.27" audit-ID="" srcIP="10.44.0.0:39600" resp=200
I0916 10:15:51.708032       1 httplog.go:132] "HTTP" verb="GET" URI="/healthz" latency="89.838µs" userAgent="kube-probe/1.27" audit-ID="" srcIP="10.44.0.0:39612" resp=200
I0916 10:16:01.702544       1 httplog.go:132] "HTTP" verb="GET" URI="/healthz" latency="108.765µs" userAgent="kube-probe/1.27" audit-ID="" srcIP="10.44.0.0:57208" resp=200
I0916 10:16:01.703630       1 httplog.go:132] "HTTP" verb="GET" URI="/healthz" latency="40.707µs" userAgent="kube-probe/1.27" audit-ID="" srcIP="10.44.0.0:57210" resp=200
I0916 10:16:11.706679       1 httplog.go:132] "HTTP" verb="GET" URI="/healthz" latency="140.514µs" userAgent="kube-probe/1.27" audit-ID="" srcIP="10.44.0.0:48802" resp=200
I0916 10:16:11.707832       1 httplog.go:132] "HTTP" verb="GET" URI="/healthz" latency="73.037µs" userAgent="kube-probe/1.27" audit-ID="" srcIP="10.44.0.0:48800" resp=200
I0916 10:16:21.706693       1 httplog.go:132] "HTTP" verb="GET" URI="/healthz" latency="110.387µs" userAgent="kube-probe/1.27" audit-ID="" srcIP="10.44.0.0:42570" resp=200
I0916 10:16:21.707724       1 httplog.go:132] "HTTP" verb="GET" URI="/healthz" latency="51.186µs" userAgent="kube-probe/1.27" audit-ID="" srcIP="10.44.0.0:42568" resp=200
I0916 10:16:31.702687       1 httplog.go:132] "HTTP" verb="GET" URI="/healthz" latency="137.288µs" userAgent="kube-probe/1.27" audit-ID="" srcIP="10.44.0.0:48358" resp=200
I0916 10:16:31.703626       1 httplog.go:132] "HTTP" verb="GET" URI="/healthz" latency="53.6µs" userAgent="kube-probe/1.27" audit-ID="" srcIP="10.44.0.0:48374" resp=200
I0916 10:16:41.707089       1 httplog.go:132] "HTTP" verb="GET" URI="/healthz" latency="96.281µs" userAgent="kube-probe/1.27" audit-ID="" srcIP="10.44.0.0:58002" resp=200
I0916 10:16:41.708258       1 httplog.go:132] "HTTP" verb="GET" URI="/healthz" latency="99.497µs" userAgent="kube-probe/1.27" audit-ID="" srcIP="10.44.0.0:58000" resp=200
I0916 10:16:51.702724       1 httplog.go:132] "HTTP" verb="GET" URI="/healthz" latency="109.816µs" userAgent="kube-probe/1.27" audit-ID="" srcIP="10.44.0.0:50670" resp=200
I0916 10:16:51.702955       1 httplog.go:132] "HTTP" verb="GET" URI="/healthz" latency="97.954µs" userAgent="kube-probe/1.27" audit-ID="" srcIP="10.44.0.0:50656" resp=200
I0916 10:17:01.707495       1 httplog.go:132] "HTTP" verb="GET" URI="/healthz" latency="132.269µs" userAgent="kube-probe/1.27" audit-ID="" srcIP="10.44.0.0:36282" resp=200
I0916 10:17:01.708682       1 httplog.go:132] "HTTP" verb="GET" URI="/healthz" latency="81.774µs" userAgent="kube-probe/1.27" audit-ID="" srcIP="10.44.0.0:36294" resp=200
I0916 10:17:11.702088       1 httplog.go:132] "HTTP" verb="GET" URI="/healthz" latency="103.084µs" userAgent="kube-probe/1.27" audit-ID="" srcIP="10.44.0.0:44208" resp=200
I0916 10:17:11.702208       1 httplog.go:132] "HTTP" verb="GET" URI="/healthz" latency="54.122µs" userAgent="kube-probe/1.27" audit-ID="" srcIP="10.44.0.0:44210" resp=200
I0916 10:17:21.702550       1 httplog.go:132] "HTTP" verb="GET" URI="/healthz" latency="155.633µs" userAgent="kube-probe/1.27" audit-ID="" srcIP="10.44.0.0:50940" resp=200
I0916 10:17:21.710076       1 httplog.go:132] "HTTP" verb="GET" URI="/healthz" latency="68.458µs" userAgent="kube-probe/1.27" audit-ID="" srcIP="10.44.0.0:50958" resp=200
I0916 10:17:31.702597       1 httplog.go:132] "HTTP" verb="GET" URI="/healthz" latency="101.32µs" userAgent="kube-probe/1.27" audit-ID="" srcIP="10.44.0.0:59452" resp=200
I0916 10:17:31.703743       1 httplog.go:132] "HTTP" verb="GET" URI="/healthz" latency="90.22µs" userAgent="kube-probe/1.27" audit-ID="" srcIP="10.44.0.0:59468" resp=200
I0916 10:17:41.702473       1 httplog.go:132] "HTTP" verb="GET" URI="/healthz" latency="93.646µs" userAgent="kube-probe/1.27" audit-ID="" srcIP="10.44.0.0:41838" resp=200
I0916 10:17:41.710211       1 httplog.go:132] "HTTP" verb="GET" URI="/healthz" latency="107.993µs" userAgent="kube-probe/1.27" audit-ID="" srcIP="10.44.0.0:41854" resp=200
I0916 10:17:51.706988       1 httplog.go:132] "HTTP" verb="GET" URI="/healthz" latency="100.328µs" userAgent="kube-probe/1.27" audit-ID="" srcIP="10.44.0.0:40070" resp=200
I0916 10:17:51.708336       1 httplog.go:132] "HTTP" verb="GET" URI="/healthz" latency="121.208µs" userAgent="kube-probe/1.27" audit-ID="" srcIP="10.44.0.0:40064" resp=200
I0916 10:18:01.702591       1 httplog.go:132] "HTTP" verb="GET" URI="/healthz" latency="90.61µs" userAgent="kube-probe/1.27" audit-ID="" srcIP="10.44.0.0:41620" resp=200
I0916 10:18:01.710125       1 httplog.go:132] "HTTP" verb="GET" URI="/healthz" latency="90.77µs" userAgent="kube-probe/1.27" audit-ID="" srcIP="10.44.0.0:41622" resp=200
I0916 10:18:11.706476       1 httplog.go:132] "HTTP" verb="GET" URI="/healthz" latency="86.293µs" userAgent="kube-probe/1.27" audit-ID="" srcIP="10.44.0.0:49786" resp=200
I0916 10:18:11.706942       1 httplog.go:132] "HTTP" verb="GET" URI="/healthz" latency="49.423µs" userAgent="kube-probe/1.27" audit-ID="" srcIP="10.44.0.0:49788" resp=200
I0916 10:18:21.706542       1 httplog.go:132] "HTTP" verb="GET" URI="/healthz" latency="97.723µs" userAgent="kube-probe/1.27" audit-ID="" srcIP="10.44.0.0:60004" resp=200
I0916 10:18:21.707605       1 httplog.go:132] "HTTP" verb="GET" URI="/healthz" latency="49.933µs" userAgent="kube-probe/1.27" audit-ID="" srcIP="10.44.0.0:60006" resp=200
I0916 10:18:31.706795       1 httplog.go:132] "HTTP" verb="GET" URI="/healthz" latency="103.555µs" userAgent="kube-probe/1.27" audit-ID="" srcIP="10.44.0.0:46468" resp=200
I0916 10:18:31.707998       1 httplog.go:132] "HTTP" verb="GET" URI="/healthz" latency="90.4µs" userAgent="kube-probe/1.27" audit-ID="" srcIP="10.44.0.0:46470" resp=200
I0916 10:18:41.699976       1 httplog.go:132] "HTTP" verb="GET" URI="/healthz" latency="97.292µs" userAgent="kube-probe/1.27" audit-ID="" srcIP="10.44.0.0:53088" resp=200
I0916 10:18:41.703184       1 httplog.go:132] "HTTP" verb="GET" URI="/healthz" latency="49.122µs" userAgent="kube-probe/1.27" audit-ID="" srcIP="10.44.0.0:53084" resp=200
I0916 10:18:51.706998       1 httplog.go:132] "HTTP" verb="GET" URI="/healthz" latency="97.854µs" userAgent="kube-probe/1.27" audit-ID="" srcIP="10.44.0.0:55284" resp=200
I0916 10:18:51.708356       1 httplog.go:132] "HTTP" verb="GET" URI="/healthz" latency="65.002µs" userAgent="kube-probe/1.27" audit-ID="" srcIP="10.44.0.0:55286" resp=200
I0916 10:19:01.706951       1 httplog.go:132] "HTTP" verb="GET" URI="/healthz" latency="107.292µs" userAgent="kube-probe/1.27" audit-ID="" srcIP="10.44.0.0:54924" resp=200
I0916 10:19:01.708094       1 httplog.go:132] "HTTP" verb="GET" URI="/healthz" latency="105.859µs" userAgent="kube-probe/1.27" audit-ID="" srcIP="10.44.0.0:54940" resp=200
I0916 10:19:11.706667       1 httplog.go:132] "HTTP" verb="GET" URI="/healthz" latency="116.619µs" userAgent="kube-probe/1.27" audit-ID="" srcIP="10.44.0.0:59320" resp=200
I0916 10:19:11.707667       1 httplog.go:132] "HTTP" verb="GET" URI="/healthz" latency="58.169µs" userAgent="kube-probe/1.27" audit-ID="" srcIP="10.44.0.0:59312" resp=200
I0916 10:19:21.706427       1 httplog.go:132] "HTTP" verb="GET" URI="/healthz" latency="87.194µs" userAgent="kube-probe/1.27" audit-ID="" srcIP="10.44.0.0:40496" resp=200
I0916 10:19:21.707550       1 httplog.go:132] "HTTP" verb="GET" URI="/healthz" latency="40.937µs" userAgent="kube-probe/1.27" audit-ID="" srcIP="10.44.0.0:40494" resp=200
I0916 10:19:31.702865       1 httplog.go:132] "HTTP" verb="GET" URI="/healthz" latency="109.616µs" userAgent="kube-probe/1.27" audit-ID="" srcIP="10.44.0.0:53216" resp=200
I0916 10:19:31.710395       1 httplog.go:132] "HTTP" verb="GET" URI="/healthz" latency="74.74µs" userAgent="kube-probe/1.27" audit-ID="" srcIP="10.44.0.0:53232" resp=200
I0916 10:19:41.706716       1 httplog.go:132] "HTTP" verb="GET" URI="/healthz" latency="94.898µs" userAgent="kube-probe/1.27" audit-ID="" srcIP="10.44.0.0:48318" resp=200
I0916 10:19:41.708047       1 httplog.go:132] "HTTP" verb="GET" URI="/healthz" latency="99.988µs" userAgent="kube-probe/1.27" audit-ID="" srcIP="10.44.0.0:48328" resp=200
I0916 10:19:51.702386       1 httplog.go:132] "HTTP" verb="GET" URI="/healthz" latency="100.449µs" userAgent="kube-probe/1.27" audit-ID="" srcIP="10.44.0.0:57136" resp=200
I0916 10:19:51.703467       1 httplog.go:132] "HTTP" verb="GET" URI="/healthz" latency="93.756µs" userAgent="kube-probe/1.27" audit-ID="" srcIP="10.44.0.0:57124" resp=200
I0916 10:20:01.707284       1 httplog.go:132] "HTTP" verb="GET" URI="/healthz" latency="114.966µs" userAgent="kube-probe/1.27" audit-ID="" srcIP="10.44.0.0:36588" resp=200
I0916 10:20:01.708471       1 httplog.go:132] "HTTP" verb="GET" URI="/healthz" latency="73.368µs" userAgent="kube-probe/1.27" audit-ID="" srcIP="10.44.0.0:36590" resp=200
I0916 10:20:11.702399       1 httplog.go:132] "HTTP" verb="GET" URI="/healthz" latency="113.273µs" userAgent="kube-probe/1.27" audit-ID="" srcIP="10.44.0.0:56540" resp=200
I0916 10:20:11.703460       1 httplog.go:132] "HTTP" verb="GET" URI="/healthz" latency="55.134µs" userAgent="kube-probe/1.27" audit-ID="" srcIP="10.44.0.0:56542" resp=200
I0916 10:20:21.701936       1 httplog.go:132] "HTTP" verb="GET" URI="/healthz" latency="101.861µs" userAgent="kube-probe/1.27" audit-ID="" srcIP="10.44.0.0:57256" resp=200
I0916 10:20:21.709361       1 httplog.go:132] "HTTP" verb="GET" URI="/healthz" latency="60.103µs" userAgent="kube-probe/1.27" audit-ID="" srcIP="10.44.0.0:57260" resp=200
I0916 10:20:31.701786       1 httplog.go:132] "HTTP" verb="GET" URI="/healthz" latency="93.395µs" userAgent="kube-probe/1.27" audit-ID="" srcIP="10.44.0.0:48398" resp=200
I0916 10:20:31.709287       1 httplog.go:132] "HTTP" verb="GET" URI="/healthz" latency="51.567µs" userAgent="kube-probe/1.27" audit-ID="" srcIP="10.44.0.0:48404" resp=200
I0916 10:20:41.706931       1 httplog.go:132] "HTTP" verb="GET" URI="/healthz" latency="87.474µs" userAgent="kube-probe/1.27" audit-ID="" srcIP="10.44.0.0:41516" resp=200
I0916 10:20:41.708037       1 httplog.go:132] "HTTP" verb="GET" URI="/healthz" latency="53.911µs" userAgent="kube-probe/1.27" audit-ID="" srcIP="10.44.0.0:41500" resp=200
I0916 10:20:51.706441       1 httplog.go:132] "HTTP" verb="GET" URI="/healthz" latency="79.069µs" userAgent="kube-probe/1.27" audit-ID="" srcIP="10.44.0.0:35582" resp=200
I0916 10:20:51.707514       1 httplog.go:132] "HTTP" verb="GET" URI="/healthz" latency="61.726µs" userAgent="kube-probe/1.27" audit-ID="" srcIP="10.44.0.0:35592" resp=200
I0916 10:21:01.702488       1 httplog.go:132] "HTTP" verb="GET" URI="/healthz" latency="116.709µs" userAgent="kube-probe/1.27" audit-ID="" srcIP="10.44.0.0:47842" resp=200
I0916 10:21:01.703586       1 httplog.go:132] "HTTP" verb="GET" URI="/healthz" latency="77.345µs" userAgent="kube-probe/1.27" audit-ID="" srcIP="10.44.0.0:47830" resp=200
I0916 10:21:11.707133       1 httplog.go:132] "HTTP" verb="GET" URI="/healthz" latency="107.141µs" userAgent="kube-probe/1.27" audit-ID="" srcIP="10.44.0.0:58426" resp=200
I0916 10:21:11.708305       1 httplog.go:132] "HTTP" verb="GET" URI="/healthz" latency="56.035µs" userAgent="kube-probe/1.27" audit-ID="" srcIP="10.44.0.0:58420" resp=200
I0916 10:21:21.702139       1 httplog.go:132] "HTTP" verb="GET" URI="/healthz" latency="110.308µs" userAgent="kube-probe/1.27" audit-ID="" srcIP="10.44.0.0:42958" resp=200
I0916 10:21:21.709698       1 httplog.go:132] "HTTP" verb="GET" URI="/healthz" latency="80.982µs" userAgent="kube-probe/1.27" audit-ID="" srcIP="10.44.0.0:42960" resp=200
I0916 10:21:31.707453       1 httplog.go:132] "HTTP" verb="GET" URI="/healthz" latency="129.423µs" userAgent="kube-probe/1.27" audit-ID="" srcIP="10.44.0.0:46856" resp=200
I0916 10:21:31.711817       1 httplog.go:132] "HTTP" verb="GET" URI="/healthz" latency="69.61µs" userAgent="kube-probe/1.27" audit-ID="" srcIP="10.44.0.0:46864" resp=200
I0916 10:21:41.706762       1 httplog.go:132] "HTTP" verb="GET" URI="/healthz" latency="89.928µs" userAgent="kube-probe/1.27" audit-ID="" srcIP="10.44.0.0:47808" resp=200
I0916 10:21:41.707778       1 httplog.go:132] "HTTP" verb="GET" URI="/healthz" latency="70.502µs" userAgent="kube-probe/1.27" audit-ID="" srcIP="10.44.0.0:47804" resp=200
I0916 10:21:51.706809       1 httplog.go:132] "HTTP" verb="GET" URI="/healthz" latency="98.164µs" userAgent="kube-probe/1.27" audit-ID="" srcIP="10.44.0.0:60786" resp=200
I0916 10:21:51.708010       1 httplog.go:132] "HTTP" verb="GET" URI="/healthz" latency="104.356µs" userAgent="kube-probe/1.27" audit-ID="" srcIP="10.44.0.0:60774" resp=200
I0916 10:22:01.702378       1 httplog.go:132] "HTTP" verb="GET" URI="/healthz" latency="110.027µs" userAgent="kube-probe/1.27" audit-ID="" srcIP="10.44.0.0:49724" resp=200
I0916 10:22:01.703474       1 httplog.go:132] "HTTP" verb="GET" URI="/healthz" latency="90.62µs" userAgent="kube-probe/1.27" audit-ID="" srcIP="10.44.0.0:49734" resp=200
I0916 10:22:11.706554       1 httplog.go:132] "HTTP" verb="GET" URI="/healthz" latency="107.922µs" userAgent="kube-probe/1.27" audit-ID="" srcIP="10.44.0.0:47850" resp=200
I0916 10:22:11.707829       1 httplog.go:132] "HTTP" verb="GET" URI="/healthz" latency="153.999µs" userAgent="kube-probe/1.27" audit-ID="" srcIP="10.44.0.0:47856" resp=200
I0916 10:22:21.707119       1 httplog.go:132] "HTTP" verb="GET" URI="/healthz" latency="83.867µs" userAgent="kube-probe/1.27" audit-ID="" srcIP="10.44.0.0:42740" resp=200
I0916 10:22:21.708473       1 httplog.go:132] "HTTP" verb="GET" URI="/healthz" latency="115.897µs" userAgent="kube-probe/1.27" audit-ID="" srcIP="10.44.0.0:42738" resp=200
I0916 10:22:31.706961       1 httplog.go:132] "HTTP" verb="GET" URI="/healthz" latency="84.018µs" userAgent="kube-probe/1.27" audit-ID="" srcIP="10.44.0.0:45524" resp=200
I0916 10:22:31.708108       1 httplog.go:132] "HTTP" verb="GET" URI="/healthz" latency="62.167µs" userAgent="kube-probe/1.27" audit-ID="" srcIP="10.44.0.0:45540" resp=200
I0916 10:22:41.706734       1 httplog.go:132] "HTTP" verb="GET" URI="/healthz" latency="108.033µs" userAgent="kube-probe/1.27" audit-ID="" srcIP="10.44.0.0:37882" resp=200
I0916 10:22:41.708276       1 httplog.go:132] "HTTP" verb="GET" URI="/healthz" latency="52.308µs" userAgent="kube-probe/1.27" audit-ID="" srcIP="10.44.0.0:37896" resp=200
I0916 10:22:51.707217       1 httplog.go:132] "HTTP" verb="GET" URI="/healthz" latency="94.157µs" userAgent="kube-probe/1.27" audit-ID="" srcIP="10.44.0.0:34296" resp=200
I0916 10:22:51.708186       1 httplog.go:132] "HTTP" verb="GET" URI="/healthz" latency="39.975µs" userAgent="kube-probe/1.27" audit-ID="" srcIP="10.44.0.0:34302" resp=200
I0916 10:23:01.706774       1 httplog.go:132] "HTTP" verb="GET" URI="/healthz" latency="96.851µs" userAgent="kube-probe/1.27" audit-ID="" srcIP="10.44.0.0:40588" resp=200
I0916 10:23:01.707966       1 httplog.go:132] "HTTP" verb="GET" URI="/healthz" latency="69.541µs" userAgent="kube-probe/1.27" audit-ID="" srcIP="10.44.0.0:40586" resp=200
I0916 10:23:11.700017       1 httplog.go:132] "HTTP" verb="GET" URI="/healthz" latency="67.667µs" userAgent="kube-probe/1.27" audit-ID="" srcIP="10.44.0.0:59850" resp=200
I0916 10:23:11.702451       1 httplog.go:132] "HTTP" verb="GET" URI="/healthz" latency="52.479µs" userAgent="kube-probe/1.27" audit-ID="" srcIP="10.44.0.0:59838" resp=200
I0916 10:23:21.706180       1 httplog.go:132] "HTTP" verb="GET" URI="/healthz" latency="102.493µs" userAgent="kube-probe/1.27" audit-ID="" srcIP="10.44.0.0:49172" resp=200
I0916 10:23:21.713668       1 httplog.go:132] "HTTP" verb="GET" URI="/healthz" latency="37.621µs" userAgent="kube-probe/1.27" audit-ID="" srcIP="10.44.0.0:49188" resp=200
I0916 10:23:31.702044       1 httplog.go:132] "HTTP" verb="GET" URI="/healthz" latency="104.105µs" userAgent="kube-probe/1.27" audit-ID="" srcIP="10.44.0.0:34390" resp=200
I0916 10:23:31.709561       1 httplog.go:132] "HTTP" verb="GET" URI="/healthz" latency="52.739µs" userAgent="kube-probe/1.27" audit-ID="" srcIP="10.44.0.0:34406" resp=200
I0916 10:23:41.700834       1 httplog.go:132] "HTTP" verb="GET" URI="/healthz" latency="69.791µs" userAgent="kube-probe/1.27" audit-ID="" srcIP="10.44.0.0:42784" resp=200
I0916 10:23:41.702044       1 httplog.go:132] "HTTP" verb="GET" URI="/healthz" latency="60.103µs" userAgent="kube-probe/1.27" audit-ID="" srcIP="10.44.0.0:42782" resp=200
I0916 10:23:51.706833       1 httplog.go:132] "HTTP" verb="GET" URI="/healthz" latency="101.912µs" userAgent="kube-probe/1.27" audit-ID="" srcIP="10.44.0.0:40044" resp=200
I0916 10:23:51.707919       1 httplog.go:132] "HTTP" verb="GET" URI="/healthz" latency="57.728µs" userAgent="kube-probe/1.27" audit-ID="" srcIP="10.44.0.0:40058" resp=200
I0916 10:24:01.707007       1 httplog.go:132] "HTTP" verb="GET" URI="/healthz" latency="93.306µs" userAgent="kube-probe/1.27" audit-ID="" srcIP="10.44.0.0:37378" resp=200
I0916 10:24:01.707911       1 httplog.go:132] "HTTP" verb="GET" URI="/healthz" latency="55.834µs" userAgent="kube-probe/1.27" audit-ID="" srcIP="10.44.0.0:37394" resp=200
I0916 10:24:11.706975       1 httplog.go:132] "HTTP" verb="GET" URI="/healthz" latency="85.611µs" userAgent="kube-probe/1.27" audit-ID="" srcIP="10.44.0.0:51072" resp=200
I0916 10:24:11.708197       1 httplog.go:132] "HTTP" verb="GET" URI="/healthz" latency="63.349µs" userAgent="kube-probe/1.27" audit-ID="" srcIP="10.44.0.0:51070" resp=200
I0916 10:24:21.706594       1 httplog.go:132] "HTTP" verb="GET" URI="/healthz" latency="91.081µs" userAgent="kube-probe/1.27" audit-ID="" srcIP="10.44.0.0:58550" resp=200
I0916 10:24:21.707568       1 httplog.go:132] "HTTP" verb="GET" URI="/healthz" latency="37.56µs" userAgent="kube-probe/1.27" audit-ID="" srcIP="10.44.0.0:58552" resp=200
I0916 10:24:31.702446       1 httplog.go:132] "HTTP" verb="GET" URI="/healthz" latency="101.941µs" userAgent="kube-probe/1.27" audit-ID="" srcIP="10.44.0.0:33926" resp=200
I0916 10:24:31.710092       1 httplog.go:132] "HTTP" verb="GET" URI="/healthz" latency="60.203µs" userAgent="kube-probe/1.27" audit-ID="" srcIP="10.44.0.0:33938" resp=200
I0916 10:24:41.707038       1 httplog.go:132] "HTTP" verb="GET" URI="/healthz" latency="111.168µs" userAgent="kube-probe/1.27" audit-ID="" srcIP="10.44.0.0:58482" resp=200
I0916 10:24:41.708095       1 httplog.go:132] "HTTP" verb="GET" URI="/healthz" latency="75.662µs" userAgent="kube-probe/1.27" audit-ID="" srcIP="10.44.0.0:58470" resp=200
I0916 10:24:51.707050       1 httplog.go:132] "HTTP" verb="GET" URI="/healthz" latency="116.479µs" userAgent="kube-probe/1.27" audit-ID="" srcIP="10.44.0.0:43620" resp=200
I0916 10:24:51.708266       1 httplog.go:132] "HTTP" verb="GET" URI="/healthz" latency="105.068µs" userAgent="kube-probe/1.27" audit-ID="" srcIP="10.44.0.0:43628" resp=200
I0916 10:25:01.702178       1 httplog.go:132] "HTTP" verb="GET" URI="/healthz" latency="127.84µs" userAgent="kube-probe/1.27" audit-ID="" srcIP="10.44.0.0:57560" resp=200
I0916 10:25:01.703200       1 httplog.go:132] "HTTP" verb="GET" URI="/healthz" latency="57.448µs" userAgent="kube-probe/1.27" audit-ID="" srcIP="10.44.0.0:57572" resp=200
I0916 10:25:11.706850       1 httplog.go:132] "HTTP" verb="GET" URI="/healthz" latency="120.306µs" userAgent="kube-probe/1.27" audit-ID="" srcIP="10.44.0.0:42856" resp=200
I0916 10:25:11.707973       1 httplog.go:132] "HTTP" verb="GET" URI="/healthz" latency="71.565µs" userAgent="kube-probe/1.27" audit-ID="" srcIP="10.44.0.0:42872" resp=200
I0916 10:25:21.706482       1 httplog.go:132] "HTTP" verb="GET" URI="/healthz" latency="100.388µs" userAgent="kube-probe/1.27" audit-ID="" srcIP="10.44.0.0:60808" resp=200
I0916 10:25:21.707470       1 httplog.go:132] "HTTP" verb="GET" URI="/healthz" latency="50.545µs" userAgent="kube-probe/1.27" audit-ID="" srcIP="10.44.0.0:60800" resp=200
I0916 10:25:31.699259       1 httplog.go:132] "HTTP" verb="GET" URI="/healthz" latency="101µs" userAgent="kube-probe/1.27" audit-ID="" srcIP="10.44.0.0:47940" resp=200
I0916 10:25:31.702785       1 httplog.go:132] "HTTP" verb="GET" URI="/healthz" latency="49.763µs" userAgent="kube-probe/1.27" audit-ID="" srcIP="10.44.0.0:47934" resp=200
I0916 10:25:41.701841       1 httplog.go:132] "HTTP" verb="GET" URI="/healthz" latency="138.189µs" userAgent="kube-probe/1.27" audit-ID="" srcIP="10.44.0.0:32894" resp=200
I0916 10:25:41.703068       1 httplog.go:132] "HTTP" verb="GET" URI="/healthz" latency="57.658µs" userAgent="kube-probe/1.27" audit-ID="" srcIP="10.44.0.0:32886" resp=200
I0916 10:25:51.706695       1 httplog.go:132] "HTTP" verb="GET" URI="/healthz" latency="109.916µs" userAgent="kube-probe/1.27" audit-ID="" srcIP="10.44.0.0:50492" resp=200
I0916 10:25:51.707678       1 httplog.go:132] "HTTP" verb="GET" URI="/healthz" latency="61.896µs" userAgent="kube-probe/1.27" audit-ID="" srcIP="10.44.0.0:50494" resp=200
I0916 10:26:01.706626       1 httplog.go:132] "HTTP" verb="GET" URI="/healthz" latency="93.275µs" userAgent="kube-probe/1.27" audit-ID="" srcIP="10.44.0.0:34726" resp=200
I0916 10:26:01.707843       1 httplog.go:132] "HTTP" verb="GET" URI="/healthz" latency="62.167µs" userAgent="kube-probe/1.27" audit-ID="" srcIP="10.44.0.0:34712" resp=200
I0916 10:26:11.702472       1 httplog.go:132] "HTTP" verb="GET" URI="/healthz" latency="85.791µs" userAgent="kube-probe/1.27" audit-ID="" srcIP="10.44.0.0:50632" resp=200
I0916 10:26:11.708453       1 httplog.go:132] "HTTP" verb="GET" URI="/healthz" latency="50.755µs" userAgent="kube-probe/1.27" audit-ID="" srcIP="10.44.0.0:50646" resp=200
I0916 10:26:21.706797       1 httplog.go:132] "HTTP" verb="GET" URI="/healthz" latency="106.731µs" userAgent="kube-probe/1.27" audit-ID="" srcIP="10.44.0.0:47572" resp=200
I0916 10:26:21.707903       1 httplog.go:132] "HTTP" verb="GET" URI="/healthz" latency="72.606µs" userAgent="kube-probe/1.27" audit-ID="" srcIP="10.44.0.0:47582" resp=200
I0916 10:26:31.707428       1 httplog.go:132] "HTTP" verb="GET" URI="/healthz" latency="151.464µs" userAgent="kube-probe/1.27" audit-ID="" srcIP="10.44.0.0:50386" resp=200
I0916 10:26:31.708786       1 httplog.go:132] "HTTP" verb="GET" URI="/healthz" latency="149.43µs" userAgent="kube-probe/1.27" audit-ID="" srcIP="10.44.0.0:50394" resp=200
I0916 10:26:41.701874       1 httplog.go:132] "HTTP" verb="GET" URI="/healthz" latency="150.863µs" userAgent="kube-probe/1.27" audit-ID="" srcIP="10.44.0.0:41054" resp=200
I0916 10:26:41.702948       1 httplog.go:132] "HTTP" verb="GET" URI="/healthz" latency="78.107µs" userAgent="kube-probe/1.27" audit-ID="" srcIP="10.44.0.0:41062" resp=200
I0916 10:26:51.702449       1 httplog.go:132] "HTTP" verb="GET" URI="/healthz" latency="125.035µs" userAgent="kube-probe/1.27" audit-ID="" srcIP="10.44.0.0:58330" resp=200
I0916 10:26:51.709734       1 httplog.go:132] "HTTP" verb="GET" URI="/healthz" latency="27.712µs" userAgent="kube-probe/1.27" audit-ID="" srcIP="10.44.0.0:58334" resp=200
I0916 10:27:01.702586       1 httplog.go:132] "HTTP" verb="GET" URI="/healthz" latency="123.632µs" userAgent="kube-probe/1.27" audit-ID="" srcIP="10.44.0.0:53448" resp=200
I0916 10:27:01.703842       1 httplog.go:132] "HTTP" verb="GET" URI="/healthz" latency="103.704µs" userAgent="kube-probe/1.27" audit-ID="" srcIP="10.44.0.0:53436" resp=200
I0916 10:27:11.702581       1 httplog.go:132] "HTTP" verb="GET" URI="/healthz" latency="114.945µs" userAgent="kube-probe/1.27" audit-ID="" srcIP="10.44.0.0:54118" resp=200
I0916 10:27:11.703754       1 httplog.go:132] "HTTP" verb="GET" URI="/healthz" latency="122.64µs" userAgent="kube-probe/1.27" audit-ID="" srcIP="10.44.0.0:54114" resp=200
I0916 10:27:21.700887       1 httplog.go:132] "HTTP" verb="GET" URI="/healthz" latency="96.191µs" userAgent="kube-probe/1.27" audit-ID="" srcIP="10.44.0.0:60298" resp=200
I0916 10:27:21.701888       1 httplog.go:132] "HTTP" verb="GET" URI="/healthz" latency="75.582µs" userAgent="kube-probe/1.27" audit-ID="" srcIP="10.44.0.0:60300" resp=200
I0916 10:27:31.706694       1 httplog.go:132] "HTTP" verb="GET" URI="/healthz" latency="83.076µs" userAgent="kube-probe/1.27" audit-ID="" srcIP="10.44.0.0:33640" resp=200
I0916 10:27:31.711968       1 httplog.go:132] "HTTP" verb="GET" URI="/healthz" latency="53.771µs" userAgent="kube-probe/1.27" audit-ID="" srcIP="10.44.0.0:33654" resp=200
I0916 10:27:41.704507       1 httplog.go:132] "HTTP" verb="GET" URI="/healthz" latency="130.495µs" userAgent="kube-probe/1.27" audit-ID="" srcIP="10.44.0.0:49314" resp=200
I0916 10:27:41.711673       1 httplog.go:132] "HTTP" verb="GET" URI="/healthz" latency="48.521µs" userAgent="kube-probe/1.27" audit-ID="" srcIP="10.44.0.0:49316" resp=200
I0916 10:27:51.702590       1 httplog.go:132] "HTTP" verb="GET" URI="/healthz" latency="90.299µs" userAgent="kube-probe/1.27" audit-ID="" srcIP="10.44.0.0:34902" resp=200
I0916 10:27:51.703730       1 httplog.go:132] "HTTP" verb="GET" URI="/healthz" latency="73.357µs" userAgent="kube-probe/1.27" audit-ID="" srcIP="10.44.0.0:34898" resp=200
I0916 10:28:01.706390       1 httplog.go:132] "HTTP" verb="GET" URI="/healthz" latency="95.88µs" userAgent="kube-probe/1.27" audit-ID="" srcIP="10.44.0.0:55106" resp=200
I0916 10:28:01.707571       1 httplog.go:132] "HTTP" verb="GET" URI="/healthz" latency="57.488µs" userAgent="kube-probe/1.27" audit-ID="" srcIP="10.44.0.0:55108" resp=200
I0916 10:28:11.702659       1 httplog.go:132] "HTTP" verb="GET" URI="/healthz" latency="81.633µs" userAgent="kube-probe/1.27" audit-ID="" srcIP="10.44.0.0:38176" resp=200
I0916 10:28:11.702890       1 httplog.go:132] "HTTP" verb="GET" URI="/healthz" latency="76.734µs" userAgent="kube-probe/1.27" audit-ID="" srcIP="10.44.0.0:38174" resp=200
I0916 10:28:21.707056       1 httplog.go:132] "HTTP" verb="GET" URI="/healthz" latency="92.092µs" userAgent="kube-probe/1.27" audit-ID="" srcIP="10.44.0.0:40222" resp=200
I0916 10:28:21.708166       1 httplog.go:132] "HTTP" verb="GET" URI="/healthz" latency="63.95µs" userAgent="kube-probe/1.27" audit-ID="" srcIP="10.44.0.0:40224" resp=200
I0916 10:28:31.706296       1 httplog.go:132] "HTTP" verb="GET" URI="/healthz" latency="103.864µs" userAgent="kube-probe/1.27" audit-ID="" srcIP="10.44.0.0:34506" resp=200
I0916 10:28:31.713930       1 httplog.go:132] "HTTP" verb="GET" URI="/healthz" latency="83.136µs" userAgent="kube-probe/1.27" audit-ID="" srcIP="10.44.0.0:34526" resp=200
I0916 10:28:41.707050       1 httplog.go:132] "HTTP" verb="GET" URI="/healthz" latency="80.411µs" userAgent="kube-probe/1.27" audit-ID="" srcIP="10.44.0.0:57164" resp=200
I0916 10:28:41.708228       1 httplog.go:132] "HTTP" verb="GET" URI="/healthz" latency="70.763µs" userAgent="kube-probe/1.27" audit-ID="" srcIP="10.44.0.0:57174" resp=200
I0916 10:28:51.702622       1 httplog.go:132] "HTTP" verb="GET" URI="/healthz" latency="103.143µs" userAgent="kube-probe/1.27" audit-ID="" srcIP="10.44.0.0:47010" resp=200
I0916 10:28:51.703894       1 httplog.go:132] "HTTP" verb="GET" URI="/healthz" latency="102.242µs" userAgent="kube-probe/1.27" audit-ID="" srcIP="10.44.0.0:47024" resp=200
I0916 10:29:01.707455       1 httplog.go:132] "HTTP" verb="GET" URI="/healthz" latency="105.799µs" userAgent="kube-probe/1.27" audit-ID="" srcIP="10.44.0.0:45174" resp=200
I0916 10:29:01.708448       1 httplog.go:132] "HTTP" verb="GET" URI="/healthz" latency="108.503µs" userAgent="kube-probe/1.27" audit-ID="" srcIP="10.44.0.0:45190" resp=200
I0916 10:29:11.702755       1 httplog.go:132] "HTTP" verb="GET" URI="/healthz" latency="100.248µs" userAgent="kube-probe/1.27" audit-ID="" srcIP="10.44.0.0:42460" resp=200
I0916 10:29:11.710234       1 httplog.go:132] "HTTP" verb="GET" URI="/healthz" latency="43.562µs" userAgent="kube-probe/1.27" audit-ID="" srcIP="10.44.0.0:42476" resp=200
I0916 10:29:21.706898       1 httplog.go:132] "HTTP" verb="GET" URI="/healthz" latency="88.316µs" userAgent="kube-probe/1.27" audit-ID="" srcIP="10.44.0.0:39878" resp=200
I0916 10:29:21.707922       1 httplog.go:132] "HTTP" verb="GET" URI="/healthz" latency="66.185µs" userAgent="kube-probe/1.27" audit-ID="" srcIP="10.44.0.0:39886" resp=200
I0916 10:29:31.702230       1 httplog.go:132] "HTTP" verb="GET" URI="/healthz" latency="112.571µs" userAgent="kube-probe/1.27" audit-ID="" srcIP="10.44.0.0:59732" resp=200
I0916 10:29:31.709789       1 httplog.go:132] "HTTP" verb="GET" URI="/healthz" latency="79.659µs" userAgent="kube-probe/1.27" audit-ID="" srcIP="10.44.0.0:59736" resp=200
I0916 10:29:41.702701       1 httplog.go:132] "HTTP" verb="GET" URI="/healthz" latency="126.577µs" userAgent="kube-probe/1.27" audit-ID="" srcIP="10.44.0.0:34488" resp=200
I0916 10:29:41.708505       1 httplog.go:132] "HTTP" verb="GET" URI="/healthz" latency="35.476µs" userAgent="kube-probe/1.27" audit-ID="" srcIP="10.44.0.0:34500" resp=200
I0916 10:29:51.702175       1 httplog.go:132] "HTTP" verb="GET" URI="/healthz" latency="98.906µs" userAgent="kube-probe/1.27" audit-ID="" srcIP="10.44.0.0:33390" resp=200
I0916 10:29:51.707835       1 httplog.go:132] "HTTP" verb="GET" URI="/healthz" latency="40.015µs" userAgent="kube-probe/1.27" audit-ID="" srcIP="10.44.0.0:33396" resp=200
I0916 10:30:01.706798       1 httplog.go:132] "HTTP" verb="GET" URI="/healthz" latency="99.657µs" userAgent="kube-probe/1.27" audit-ID="" srcIP="10.44.0.0:43356" resp=200
I0916 10:30:01.707897       1 httplog.go:132] "HTTP" verb="GET" URI="/healthz" latency="42.279µs" userAgent="kube-probe/1.27" audit-ID="" srcIP="10.44.0.0:43348" resp=200
I0916 10:30:11.702760       1 httplog.go:132] "HTTP" verb="GET" URI="/healthz" latency="92.383µs" userAgent="kube-probe/1.27" audit-ID="" srcIP="10.44.0.0:51060" resp=200
I0916 10:30:11.710095       1 httplog.go:132] "HTTP" verb="GET" URI="/healthz" latency="49.913µs" userAgent="kube-probe/1.27" audit-ID="" srcIP="10.44.0.0:51074" resp=200
I0916 10:30:21.706934       1 httplog.go:132] "HTTP" verb="GET" URI="/healthz" latency="90.059µs" userAgent="kube-probe/1.27" audit-ID="" srcIP="10.44.0.0:59896" resp=200
I0916 10:30:21.708009       1 httplog.go:132] "HTTP" verb="GET" URI="/healthz" latency="53.19µs" userAgent="kube-probe/1.27" audit-ID="" srcIP="10.44.0.0:59900" resp=200
I0916 10:30:31.699189       1 httplog.go:132] "HTTP" verb="GET" URI="/healthz" latency="112.391µs" userAgent="kube-probe/1.27" audit-ID="" srcIP="10.44.0.0:35810" resp=200
I0916 10:30:31.701706       1 httplog.go:132] "HTTP" verb="GET" URI="/healthz" latency="62.247µs" userAgent="kube-probe/1.27" audit-ID="" srcIP="10.44.0.0:35808" resp=200
I0916 10:30:41.706796       1 httplog.go:132] "HTTP" verb="GET" URI="/healthz" latency="85.06µs" userAgent="kube-probe/1.27" audit-ID="" srcIP="10.44.0.0:58878" resp=200
I0916 10:30:41.711056       1 httplog.go:132] "HTTP" verb="GET" URI="/healthz" latency="47.689µs" userAgent="kube-probe/1.27" audit-ID="" srcIP="10.44.0.0:58900" resp=200
I0916 10:30:51.702344       1 httplog.go:132] "HTTP" verb="GET" URI="/healthz" latency="100.819µs" userAgent="kube-probe/1.27" audit-ID="" srcIP="10.44.0.0:38032" resp=200
I0916 10:30:51.710053       1 httplog.go:132] "HTTP" verb="GET" URI="/healthz" latency="79.739µs" userAgent="kube-probe/1.27" audit-ID="" srcIP="10.44.0.0:38038" resp=200
I0916 10:31:01.706542       1 httplog.go:132] "HTTP" verb="GET" URI="/healthz" latency="170.761µs" userAgent="kube-probe/1.27" audit-ID="" srcIP="10.44.0.0:58486" resp=200
I0916 10:31:01.707560       1 httplog.go:132] "HTTP" verb="GET" URI="/healthz" latency="145.463µs" userAgent="kube-probe/1.27" audit-ID="" srcIP="10.44.0.0:58482" resp=200
I0916 10:31:11.706077       1 httplog.go:132] "HTTP" verb="GET" URI="/healthz" latency="127.449µs" userAgent="kube-probe/1.27" audit-ID="" srcIP="10.44.0.0:50500" resp=200
I0916 10:31:11.707193       1 httplog.go:132] "HTTP" verb="GET" URI="/healthz" latency="75.682µs" userAgent="kube-probe/1.27" audit-ID="" srcIP="10.44.0.0:50508" resp=200
I0916 10:31:21.701600       1 httplog.go:132] "HTTP" verb="GET" URI="/healthz" latency="88.236µs" userAgent="kube-probe/1.27" audit-ID="" srcIP="10.44.0.0:41892" resp=200
I0916 10:31:21.708993       1 httplog.go:132] "HTTP" verb="GET" URI="/healthz" latency="93.696µs" userAgent="kube-probe/1.27" audit-ID="" srcIP="10.44.0.0:41906" resp=200
I0916 10:31:31.702623       1 httplog.go:132] "HTTP" verb="GET" URI="/healthz" latency="115.406µs" userAgent="kube-probe/1.27" audit-ID="" srcIP="10.44.0.0:36188" resp=200
I0916 10:31:31.703745       1 httplog.go:132] "HTTP" verb="GET" URI="/healthz" latency="65.102µs" userAgent="kube-probe/1.27" audit-ID="" srcIP="10.44.0.0:36186" resp=200
I0916 10:31:41.706484       1 httplog.go:132] "HTTP" verb="GET" URI="/healthz" latency="90.109µs" userAgent="kube-probe/1.27" audit-ID="" srcIP="10.44.0.0:45954" resp=200
I0916 10:31:41.707904       1 httplog.go:132] "HTTP" verb="GET" URI="/healthz" latency="48.501µs" userAgent="kube-probe/1.27" audit-ID="" srcIP="10.44.0.0:45952" resp=200
I0916 10:31:51.702385       1 httplog.go:132] "HTTP" verb="GET" URI="/healthz" latency="85.531µs" userAgent="kube-probe/1.27" audit-ID="" srcIP="10.44.0.0:51720" resp=200
I0916 10:31:51.703461       1 httplog.go:132] "HTTP" verb="GET" URI="/healthz" latency="53.681µs" userAgent="kube-probe/1.27" audit-ID="" srcIP="10.44.0.0:51712" resp=200
I0916 10:32:01.702004       1 httplog.go:132] "HTTP" verb="GET" URI="/healthz" latency="124.173µs" userAgent="kube-probe/1.27" audit-ID="" srcIP="10.44.0.0:40404" resp=200
I0916 10:32:01.713072       1 httplog.go:132] "HTTP" verb="GET" URI="/healthz" latency="108.573µs" userAgent="kube-probe/1.27" audit-ID="" srcIP="10.44.0.0:40418" resp=200
I0916 10:32:11.702685       1 httplog.go:132] "HTTP" verb="GET" URI="/healthz" latency="93.996µs" userAgent="kube-probe/1.27" audit-ID="" srcIP="10.44.0.0:37276" resp=200
I0916 10:32:11.708483       1 httplog.go:132] "HTTP" verb="GET" URI="/healthz" latency="54.332µs" userAgent="kube-probe/1.27" audit-ID="" srcIP="10.44.0.0:37284" resp=200
I0916 10:32:21.702978       1 httplog.go:132] "HTTP" verb="GET" URI="/healthz" latency="103.985µs" userAgent="kube-probe/1.27" audit-ID="" srcIP="10.44.0.0:47370" resp=200
I0916 10:32:21.710531       1 httplog.go:132] "HTTP" verb="GET" URI="/healthz" latency="88.276µs" userAgent="kube-probe/1.27" audit-ID="" srcIP="10.44.0.0:47390" resp=200
I0916 10:32:31.707724       1 httplog.go:132] "HTTP" verb="GET" URI="/healthz" latency="102.242µs" userAgent="kube-probe/1.27" audit-ID="" srcIP="10.44.0.0:45022" resp=200
I0916 10:32:31.708862       1 httplog.go:132] "HTTP" verb="GET" URI="/healthz" latency="113.352µs" userAgent="kube-probe/1.27" audit-ID="" srcIP="10.44.0.0:45008" resp=200
I0916 10:32:41.707274       1 httplog.go:132] "HTTP" verb="GET" URI="/healthz" latency="133.64µs" userAgent="kube-probe/1.27" audit-ID="" srcIP="10.44.0.0:33838" resp=200
I0916 10:32:41.708415       1 httplog.go:132] "HTTP" verb="GET" URI="/healthz" latency="58.399µs" userAgent="kube-probe/1.27" audit-ID="" srcIP="10.44.0.0:33844" resp=200
I0916 10:32:51.702453       1 httplog.go:132] "HTTP" verb="GET" URI="/healthz" latency="110.026µs" userAgent="kube-probe/1.27" audit-ID="" srcIP="10.44.0.0:34836" resp=200
I0916 10:32:51.702517       1 httplog.go:132] "HTTP" verb="GET" URI="/healthz" latency="55.965µs" userAgent="kube-probe/1.27" audit-ID="" srcIP="10.44.0.0:34850" resp=200
I0916 10:33:01.702961       1 httplog.go:132] "HTTP" verb="GET" URI="/healthz" latency="113.433µs" userAgent="kube-probe/1.27" audit-ID="" srcIP="10.44.0.0:37936" resp=200
I0916 10:33:01.710377       1 httplog.go:132] "HTTP" verb="GET" URI="/healthz" latency="107.782µs" userAgent="kube-probe/1.27" audit-ID="" srcIP="10.44.0.0:37966" resp=200
I0916 10:33:11.706724       1 httplog.go:132] "HTTP" verb="GET" URI="/healthz" latency="134.652µs" userAgent="kube-probe/1.27" audit-ID="" srcIP="10.44.0.0:44216" resp=200
I0916 10:33:11.707921       1 httplog.go:132] "HTTP" verb="GET" URI="/healthz" latency="60.794µs" userAgent="kube-probe/1.27" audit-ID="" srcIP="10.44.0.0:44228" resp=200
I0916 10:33:21.707441       1 httplog.go:132] "HTTP" verb="GET" URI="/healthz" latency="113.172µs" userAgent="kube-probe/1.27" audit-ID="" srcIP="10.44.0.0:39128" resp=200
I0916 10:33:21.708934       1 httplog.go:132] "HTTP" verb="GET" URI="/healthz" latency="151.584µs" userAgent="kube-probe/1.27" audit-ID="" srcIP="10.44.0.0:39134" resp=200
I0916 10:33:31.707242       1 httplog.go:132] "HTTP" verb="GET" URI="/healthz" latency="113.623µs" userAgent="kube-probe/1.27" audit-ID="" srcIP="10.44.0.0:34552" resp=200
I0916 10:33:31.708233       1 httplog.go:132] "HTTP" verb="GET" URI="/healthz" latency="68.108µs" userAgent="kube-probe/1.27" audit-ID="" srcIP="10.44.0.0:34558" resp=200
I0916 10:33:41.702715       1 httplog.go:132] "HTTP" verb="GET" URI="/healthz" latency="92.353µs" userAgent="kube-probe/1.27" audit-ID="" srcIP="10.44.0.0:58086" resp=200
I0916 10:33:41.703964       1 httplog.go:132] "HTTP" verb="GET" URI="/healthz" latency="131.627µs" userAgent="kube-probe/1.27" audit-ID="" srcIP="10.44.0.0:58090" resp=200
I0916 10:33:51.706754       1 httplog.go:132] "HTTP" verb="GET" URI="/healthz" latency="103.204µs" userAgent="kube-probe/1.27" audit-ID="" srcIP="10.44.0.0:46786" resp=200
I0916 10:33:51.707997       1 httplog.go:132] "HTTP" verb="GET" URI="/healthz" latency="153.898µs" userAgent="kube-probe/1.27" audit-ID="" srcIP="10.44.0.0:46780" resp=200
I0916 10:34:01.707006       1 httplog.go:132] "HTTP" verb="GET" URI="/healthz" latency="143.279µs" userAgent="kube-probe/1.27" audit-ID="" srcIP="10.44.0.0:58246" resp=200
I0916 10:34:01.708000       1 httplog.go:132] "HTTP" verb="GET" URI="/healthz" latency="74.921µs" userAgent="kube-probe/1.27" audit-ID="" srcIP="10.44.0.0:58248" resp=200
I0916 10:34:11.706579       1 httplog.go:132] "HTTP" verb="GET" URI="/healthz" latency="140.333µs" userAgent="kube-probe/1.27" audit-ID="" srcIP="10.44.0.0:49656" resp=200
I0916 10:34:11.707693       1 httplog.go:132] "HTTP" verb="GET" URI="/healthz" latency="83.998µs" userAgent="kube-probe/1.27" audit-ID="" srcIP="10.44.0.0:49660" resp=200
I0916 10:34:21.702655       1 httplog.go:132] "HTTP" verb="GET" URI="/healthz" latency="111.829µs" userAgent="kube-probe/1.27" audit-ID="" srcIP="10.44.0.0:60262" resp=200
I0916 10:34:21.710032       1 httplog.go:132] "HTTP" verb="GET" URI="/healthz" latency="98.865µs" userAgent="kube-probe/1.27" audit-ID="" srcIP="10.44.0.0:60284" resp=200
I0916 10:34:31.702695       1 httplog.go:132] "HTTP" verb="GET" URI="/healthz" latency="90.23µs" userAgent="kube-probe/1.27" audit-ID="" srcIP="10.44.0.0:44584" resp=200
I0916 10:34:31.710567       1 httplog.go:132] "HTTP" verb="GET" URI="/healthz" latency="90.83µs" userAgent="kube-probe/1.27" audit-ID="" srcIP="10.44.0.0:44594" resp=200
I0916 10:34:41.702087       1 httplog.go:132] "HTTP" verb="GET" URI="/healthz" latency="114.765µs" userAgent="kube-probe/1.27" audit-ID="" srcIP="10.44.0.0:58470" resp=200
I0916 10:34:41.703391       1 httplog.go:132] "HTTP" verb="GET" URI="/healthz" latency="88.025µs" userAgent="kube-probe/1.27" audit-ID="" srcIP="10.44.0.0:58484" resp=200
I0916 10:34:51.702903       1 httplog.go:132] "HTTP" verb="GET" URI="/healthz" latency="114.826µs" userAgent="kube-probe/1.27" audit-ID="" srcIP="10.44.0.0:47476" resp=200
I0916 10:34:51.703957       1 httplog.go:132] "HTTP" verb="GET" URI="/healthz" latency="58.71µs" userAgent="kube-probe/1.27" audit-ID="" srcIP="10.44.0.0:47478" resp=200
I0916 10:35:01.706830       1 httplog.go:132] "HTTP" verb="GET" URI="/healthz" latency="144.882µs" userAgent="kube-probe/1.27" audit-ID="" srcIP="10.44.0.0:37166" resp=200
I0916 10:35:01.707859       1 httplog.go:132] "HTTP" verb="GET" URI="/healthz" latency="84.048µs" userAgent="kube-probe/1.27" audit-ID="" srcIP="10.44.0.0:37172" resp=200
I0916 10:35:11.701749       1 httplog.go:132] "HTTP" verb="GET" URI="/healthz" latency="111.279µs" userAgent="kube-probe/1.27" audit-ID="" srcIP="10.44.0.0:56564" resp=200
I0916 10:35:11.702774       1 httplog.go:132] "HTTP" verb="GET" URI="/healthz" latency="90.92µs" userAgent="kube-probe/1.27" audit-ID="" srcIP="10.44.0.0:56576" resp=200
I0916 10:35:21.702026       1 httplog.go:132] "HTTP" verb="GET" URI="/healthz" latency="92.193µs" userAgent="kube-probe/1.27" audit-ID="" srcIP="10.44.0.0:35594" resp=200
I0916 10:35:21.709528       1 httplog.go:132] "HTTP" verb="GET" URI="/healthz" latency="89.318µs" userAgent="kube-probe/1.27" audit-ID="" srcIP="10.44.0.0:35620" resp=200
I0916 10:35:31.702571       1 httplog.go:132] "HTTP" verb="GET" URI="/healthz" latency="80.351µs" userAgent="kube-probe/1.27" audit-ID="" srcIP="10.44.0.0:46242" resp=200
I0916 10:35:31.703832       1 httplog.go:132] "HTTP" verb="GET" URI="/healthz" latency="35.848µs" userAgent="kube-probe/1.27" audit-ID="" srcIP="10.44.0.0:46244" resp=200
I0916 10:35:41.707027       1 httplog.go:132] "HTTP" verb="GET" URI="/healthz" latency="87.304µs" userAgent="kube-probe/1.27" audit-ID="" srcIP="10.44.0.0:60474" resp=200
I0916 10:35:41.708270       1 httplog.go:132] "HTTP" verb="GET" URI="/healthz" latency="37.219µs" userAgent="kube-probe/1.27" audit-ID="" srcIP="10.44.0.0:60490" resp=200
I0916 10:35:51.706680       1 httplog.go:132] "HTTP" verb="GET" URI="/healthz" latency="105.168µs" userAgent="kube-probe/1.27" audit-ID="" srcIP="10.44.0.0:39114" resp=200
I0916 10:35:51.707828       1 httplog.go:132] "HTTP" verb="GET" URI="/healthz" latency="54.011µs" userAgent="kube-probe/1.27" audit-ID="" srcIP="10.44.0.0:39116" resp=200
I0916 10:36:01.706664       1 httplog.go:132] "HTTP" verb="GET" URI="/healthz" latency="90.31µs" userAgent="kube-probe/1.27" audit-ID="" srcIP="10.44.0.0:42154" resp=200
I0916 10:36:01.707937       1 httplog.go:132] "HTTP" verb="GET" URI="/healthz" latency="112.921µs" userAgent="kube-probe/1.27" audit-ID="" srcIP="10.44.0.0:42142" resp=200
I0916 10:36:11.702272       1 httplog.go:132] "HTTP" verb="GET" URI="/healthz" latency="102.672µs" userAgent="kube-probe/1.27" audit-ID="" srcIP="10.44.0.0:57908" resp=200
I0916 10:36:11.703325       1 httplog.go:132] "HTTP" verb="GET" URI="/healthz" latency="114.595µs" userAgent="kube-probe/1.27" audit-ID="" srcIP="10.44.0.0:57912" resp=200
I0916 10:36:21.702517       1 httplog.go:132] "HTTP" verb="GET" URI="/healthz" latency="105.999µs" userAgent="kube-probe/1.27" audit-ID="" srcIP="10.44.0.0:48072" resp=200
I0916 10:36:21.709929       1 httplog.go:132] "HTTP" verb="GET" URI="/healthz" latency="25.087µs" userAgent="kube-probe/1.27" audit-ID="" srcIP="10.44.0.0:48090" resp=200
I0916 10:36:31.702524       1 httplog.go:132] "HTTP" verb="GET" URI="/healthz" latency="105.198µs" userAgent="kube-probe/1.27" audit-ID="" srcIP="10.44.0.0:48830" resp=200
I0916 10:36:31.702575       1 httplog.go:132] "HTTP" verb="GET" URI="/healthz" latency="55.784µs" userAgent="kube-probe/1.27" audit-ID="" srcIP="10.44.0.0:48838" resp=200
I0916 10:36:41.701959       1 httplog.go:132] "HTTP" verb="GET" URI="/healthz" latency="87.905µs" userAgent="kube-probe/1.27" audit-ID="" srcIP="10.44.0.0:36384" resp=200
I0916 10:36:41.703105       1 httplog.go:132] "HTTP" verb="GET" URI="/healthz" latency="105.898µs" userAgent="kube-probe/1.27" audit-ID="" srcIP="10.44.0.0:36390" resp=200
I0916 10:36:51.701799       1 httplog.go:132] "HTTP" verb="GET" URI="/healthz" latency="107.351µs" userAgent="kube-probe/1.27" audit-ID="" srcIP="10.44.0.0:59410" resp=200
I0916 10:36:51.709369       1 httplog.go:132] "HTTP" verb="GET" URI="/healthz" latency="46.216µs" userAgent="kube-probe/1.27" audit-ID="" srcIP="10.44.0.0:59412" resp=200
I0916 10:37:01.707152       1 httplog.go:132] "HTTP" verb="GET" URI="/healthz" latency="160.681µs" userAgent="kube-probe/1.27" audit-ID="" srcIP="10.44.0.0:44384" resp=200
I0916 10:37:01.708227       1 httplog.go:132] "HTTP" verb="GET" URI="/healthz" latency="90.079µs" userAgent="kube-probe/1.27" audit-ID="" srcIP="10.44.0.0:44368" resp=200
I0916 10:37:11.702403       1 httplog.go:132] "HTTP" verb="GET" URI="/healthz" latency="116.729µs" userAgent="kube-probe/1.27" audit-ID="" srcIP="10.44.0.0:56794" resp=200
I0916 10:37:11.703648       1 httplog.go:132] "HTTP" verb="GET" URI="/healthz" latency="83.116µs" userAgent="kube-probe/1.27" audit-ID="" srcIP="10.44.0.0:56810" resp=200
I0916 10:37:21.706827       1 httplog.go:132] "HTTP" verb="GET" URI="/healthz" latency="84.218µs" userAgent="kube-probe/1.27" audit-ID="" srcIP="10.44.0.0:57420" resp=200
I0916 10:37:21.707992       1 httplog.go:132] "HTTP" verb="GET" URI="/healthz" latency="45.956µs" userAgent="kube-probe/1.27" audit-ID="" srcIP="10.44.0.0:57426" resp=200
I0916 10:37:31.702533       1 httplog.go:132] "HTTP" verb="GET" URI="/healthz" latency="179.567µs" userAgent="kube-probe/1.27" audit-ID="" srcIP="10.44.0.0:42854" resp=200
I0916 10:37:31.703770       1 httplog.go:132] "HTTP" verb="GET" URI="/healthz" latency="142.206µs" userAgent="kube-probe/1.27" audit-ID="" srcIP="10.44.0.0:42856" resp=200
I0916 10:37:41.707138       1 httplog.go:132] "HTTP" verb="GET" URI="/healthz" latency="116.699µs" userAgent="kube-probe/1.27" audit-ID="" srcIP="10.44.0.0:59746" resp=200
I0916 10:37:41.708576       1 httplog.go:132] "HTTP" verb="GET" URI="/healthz" latency="158.638µs" userAgent="kube-probe/1.27" audit-ID="" srcIP="10.44.0.0:59760" resp=200
I0916 10:37:51.707199       1 httplog.go:132] "HTTP" verb="GET" URI="/healthz" latency="96.381µs" userAgent="kube-probe/1.27" audit-ID="" srcIP="10.44.0.0:41716" resp=200
I0916 10:37:51.708414       1 httplog.go:132] "HTTP" verb="GET" URI="/healthz" latency="139.822µs" userAgent="kube-probe/1.27" audit-ID="" srcIP="10.44.0.0:41718" resp=200
I0916 10:38:01.707249       1 httplog.go:132] "HTTP" verb="GET" URI="/healthz" latency="128.882µs" userAgent="kube-probe/1.27" audit-ID="" srcIP="10.44.0.0:46616" resp=200
I0916 10:38:01.708418       1 httplog.go:132] "HTTP" verb="GET" URI="/healthz" latency="52.589µs" userAgent="kube-probe/1.27" audit-ID="" srcIP="10.44.0.0:46612" resp=200
I0916 10:38:11.702967       1 httplog.go:132] "HTTP" verb="GET" URI="/healthz" latency="123.932µs" userAgent="kube-probe/1.27" audit-ID="" srcIP="10.44.0.0:56816" resp=200
I0916 10:38:11.704157       1 httplog.go:132] "HTTP" verb="GET" URI="/healthz" latency="53.921µs" userAgent="kube-probe/1.27" audit-ID="" srcIP="10.44.0.0:56822" resp=200
I0916 10:38:21.706293       1 httplog.go:132] "HTTP" verb="GET" URI="/healthz" latency="302.387µs" userAgent="kube-probe/1.27" audit-ID="" srcIP="10.44.0.0:56978" resp=200
I0916 10:38:21.707180       1 httplog.go:132] "HTTP" verb="GET" URI="/healthz" latency="70.001µs" userAgent="kube-probe/1.27" audit-ID="" srcIP="10.44.0.0:56966" resp=200
I0916 10:38:31.702701       1 httplog.go:132] "HTTP" verb="GET" URI="/healthz" latency="118.813µs" userAgent="kube-probe/1.27" audit-ID="" srcIP="10.44.0.0:52886" resp=200
I0916 10:38:31.703860       1 httplog.go:132] "HTTP" verb="GET" URI="/healthz" latency="127.189µs" userAgent="kube-probe/1.27" audit-ID="" srcIP="10.44.0.0:52898" resp=200
I0916 10:38:41.699202       1 httplog.go:132] "HTTP" verb="GET" URI="/healthz" latency="123.712µs" userAgent="kube-probe/1.27" audit-ID="" srcIP="10.44.0.0:38844" resp=200
I0916 10:38:41.702322       1 httplog.go:132] "HTTP" verb="GET" URI="/healthz" latency="60.464µs" userAgent="kube-probe/1.27" audit-ID="" srcIP="10.44.0.0:38850" resp=200
I0916 10:38:51.702392       1 httplog.go:132] "HTTP" verb="GET" URI="/healthz" latency="115.767µs" userAgent="kube-probe/1.27" audit-ID="" srcIP="10.44.0.0:36180" resp=200
I0916 10:38:51.708293       1 httplog.go:132] "HTTP" verb="GET" URI="/healthz" latency="59.892µs" userAgent="kube-probe/1.27" audit-ID="" srcIP="10.44.0.0:36198" resp=200
I0916 10:39:01.707063       1 httplog.go:132] "HTTP" verb="GET" URI="/healthz" latency="164.979µs" userAgent="kube-probe/1.27" audit-ID="" srcIP="10.44.0.0:56886" resp=200
I0916 10:39:01.707481       1 httplog.go:132] "HTTP" verb="GET" URI="/healthz" latency="34.124µs" userAgent="kube-probe/1.27" audit-ID="" srcIP="10.44.0.0:56892" resp=200
I0916 10:39:11.702394       1 httplog.go:132] "HTTP" verb="GET" URI="/healthz" latency="98.996µs" userAgent="kube-probe/1.27" audit-ID="" srcIP="10.44.0.0:48026" resp=200
I0916 10:39:11.703374       1 httplog.go:132] "HTTP" verb="GET" URI="/healthz" latency="115.677µs" userAgent="kube-probe/1.27" audit-ID="" srcIP="10.44.0.0:48022" resp=200
I0916 10:39:21.702695       1 httplog.go:132] "HTTP" verb="GET" URI="/healthz" latency="85.43µs" userAgent="kube-probe/1.27" audit-ID="" srcIP="10.44.0.0:47266" resp=200
I0916 10:39:21.703878       1 httplog.go:132] "HTTP" verb="GET" URI="/healthz" latency="138.159µs" userAgent="kube-probe/1.27" audit-ID="" srcIP="10.44.0.0:47272" resp=200
I0916 10:39:31.702441       1 httplog.go:132] "HTTP" verb="GET" URI="/healthz" latency="107.632µs" userAgent="kube-probe/1.27" audit-ID="" srcIP="10.44.0.0:53118" resp=200
I0916 10:39:31.703501       1 httplog.go:132] "HTTP" verb="GET" URI="/healthz" latency="85.611µs" userAgent="kube-probe/1.27" audit-ID="" srcIP="10.44.0.0:53116" resp=200
I0916 10:39:41.702700       1 httplog.go:132] "HTTP" verb="GET" URI="/healthz" latency="90.911µs" userAgent="kube-probe/1.27" audit-ID="" srcIP="10.44.0.0:37514" resp=200
I0916 10:39:41.702823       1 httplog.go:132] "HTTP" verb="GET" URI="/healthz" latency="127.309µs" userAgent="kube-probe/1.27" audit-ID="" srcIP="10.44.0.0:37512" resp=200
I0916 10:39:51.706446       1 httplog.go:132] "HTTP" verb="GET" URI="/healthz" latency="120.155µs" userAgent="kube-probe/1.27" audit-ID="" srcIP="10.44.0.0:37422" resp=200
I0916 10:39:51.707669       1 httplog.go:132] "HTTP" verb="GET" URI="/healthz" latency="111.709µs" userAgent="kube-probe/1.27" audit-ID="" srcIP="10.44.0.0:37408" resp=200
I0916 10:40:01.702855       1 httplog.go:132] "HTTP" verb="GET" URI="/healthz" latency="113.192µs" userAgent="kube-probe/1.27" audit-ID="" srcIP="10.44.0.0:44084" resp=200
I0916 10:40:01.708467       1 httplog.go:132] "HTTP" verb="GET" URI="/healthz" latency="80.511µs" userAgent="kube-probe/1.27" audit-ID="" srcIP="10.44.0.0:44094" resp=200
I0916 10:40:11.699675       1 httplog.go:132] "HTTP" verb="GET" URI="/healthz" latency="135.364µs" userAgent="kube-probe/1.27" audit-ID="" srcIP="10.44.0.0:42204" resp=200
I0916 10:40:11.702548       1 httplog.go:132] "HTTP" verb="GET" URI="/healthz" latency="101.711µs" userAgent="kube-probe/1.27" audit-ID="" srcIP="10.44.0.0:42210" resp=200
I0916 10:40:21.707233       1 httplog.go:132] "HTTP" verb="GET" URI="/healthz" latency="104.276µs" userAgent="kube-probe/1.27" audit-ID="" srcIP="10.44.0.0:56334" resp=200
I0916 10:40:21.708310       1 httplog.go:132] "HTTP" verb="GET" URI="/healthz" latency="81.664µs" userAgent="kube-probe/1.27" audit-ID="" srcIP="10.44.0.0:56342" resp=200
I0916 10:40:31.707196       1 httplog.go:132] "HTTP" verb="GET" URI="/healthz" latency="109.305µs" userAgent="kube-probe/1.27" audit-ID="" srcIP="10.44.0.0:59382" resp=200
I0916 10:40:31.711582       1 httplog.go:132] "HTTP" verb="GET" URI="/healthz" latency="118.483µs" userAgent="kube-probe/1.27" audit-ID="" srcIP="10.44.0.0:59392" resp=200
I0916 10:40:41.702126       1 httplog.go:132] "HTTP" verb="GET" URI="/healthz" latency="138.7µs" userAgent="kube-probe/1.27" audit-ID="" srcIP="10.44.0.0:51460" resp=200
I0916 10:40:41.703229       1 httplog.go:132] "HTTP" verb="GET" URI="/healthz" latency="97.784µs" userAgent="kube-probe/1.27" audit-ID="" srcIP="10.44.0.0:51474" resp=200
I0916 10:40:51.702264       1 httplog.go:132] "HTTP" verb="GET" URI="/healthz" latency="105.358µs" userAgent="kube-probe/1.27" audit-ID="" srcIP="10.44.0.0:47104" resp=200
I0916 10:40:51.710062       1 httplog.go:132] "HTTP" verb="GET" URI="/healthz" latency="115.206µs" userAgent="kube-probe/1.27" audit-ID="" srcIP="10.44.0.0:47114" resp=200
I0916 10:41:01.702622       1 httplog.go:132] "HTTP" verb="GET" URI="/healthz" latency="130.736µs" userAgent="kube-probe/1.27" audit-ID="" srcIP="10.44.0.0:40688" resp=200
I0916 10:41:01.703663       1 httplog.go:132] "HTTP" verb="GET" URI="/healthz" latency="57.338µs" userAgent="kube-probe/1.27" audit-ID="" srcIP="10.44.0.0:40686" resp=200
I0916 10:41:11.702498       1 httplog.go:132] "HTTP" verb="GET" URI="/healthz" latency="107.231µs" userAgent="kube-probe/1.27" audit-ID="" srcIP="10.44.0.0:50966" resp=200
I0916 10:41:11.703493       1 httplog.go:132] "HTTP" verb="GET" URI="/healthz" latency="57.237µs" userAgent="kube-probe/1.27" audit-ID="" srcIP="10.44.0.0:50952" resp=200
I0916 10:41:21.701925       1 httplog.go:132] "HTTP" verb="GET" URI="/healthz" latency="95.96µs" userAgent="kube-probe/1.27" audit-ID="" srcIP="10.44.0.0:54508" resp=200
I0916 10:41:21.709528       1 httplog.go:132] "HTTP" verb="GET" URI="/healthz" latency="40.075µs" userAgent="kube-probe/1.27" audit-ID="" srcIP="10.44.0.0:54518" resp=200
I0916 10:41:31.707169       1 httplog.go:132] "HTTP" verb="GET" URI="/healthz" latency="91.651µs" userAgent="kube-probe/1.27" audit-ID="" srcIP="10.44.0.0:59086" resp=200
I0916 10:41:31.708244       1 httplog.go:132] "HTTP" verb="GET" URI="/healthz" latency="63.499µs" userAgent="kube-probe/1.27" audit-ID="" srcIP="10.44.0.0:59102" resp=200
I0916 10:41:41.702184       1 httplog.go:132] "HTTP" verb="GET" URI="/healthz" latency="102.462µs" userAgent="kube-probe/1.27" audit-ID="" srcIP="10.44.0.0:37078" resp=200
I0916 10:41:41.703248       1 httplog.go:132] "HTTP" verb="GET" URI="/healthz" latency="63.78µs" userAgent="kube-probe/1.27" audit-ID="" srcIP="10.44.0.0:37066" resp=200
I0916 10:41:51.706758       1 httplog.go:132] "HTTP" verb="GET" URI="/healthz" latency="99.336µs" userAgent="kube-probe/1.27" audit-ID="" srcIP="10.44.0.0:35950" resp=200
I0916 10:41:51.709013       1 httplog.go:132] "HTTP" verb="GET" URI="/healthz" latency="55.835µs" userAgent="kube-probe/1.27" audit-ID="" srcIP="10.44.0.0:35964" resp=200
I0916 10:42:01.707594       1 httplog.go:132] "HTTP" verb="GET" URI="/healthz" latency="71.324µs" userAgent="kube-probe/1.27" audit-ID="" srcIP="10.44.0.0:37600" resp=200
I0916 10:42:01.708786       1 httplog.go:132] "HTTP" verb="GET" URI="/healthz" latency="41.057µs" userAgent="kube-probe/1.27" audit-ID="" srcIP="10.44.0.0:37598" resp=200
I0916 10:42:11.699965       1 httplog.go:132] "HTTP" verb="GET" URI="/healthz" latency="110.958µs" userAgent="kube-probe/1.27" audit-ID="" srcIP="10.44.0.0:35174" resp=200
I0916 10:42:11.702671       1 httplog.go:132] "HTTP" verb="GET" URI="/healthz" latency="98.705µs" userAgent="kube-probe/1.27" audit-ID="" srcIP="10.44.0.0:35158" resp=200
I0916 10:42:21.706522       1 httplog.go:132] "HTTP" verb="GET" URI="/healthz" latency="106.78µs" userAgent="kube-probe/1.27" audit-ID="" srcIP="10.44.0.0:57592" resp=200
I0916 10:42:21.707530       1 httplog.go:132] "HTTP" verb="GET" URI="/healthz" latency="40.115µs" userAgent="kube-probe/1.27" audit-ID="" srcIP="10.44.0.0:57576" resp=200
I0916 10:42:31.699191       1 httplog.go:132] "HTTP" verb="GET" URI="/healthz" latency="82.966µs" userAgent="kube-probe/1.27" audit-ID="" srcIP="10.44.0.0:42188" resp=200
I0916 10:42:31.700353       1 httplog.go:132] "HTTP" verb="GET" URI="/healthz" latency="62.287µs" userAgent="kube-probe/1.27" audit-ID="" srcIP="10.44.0.0:42190" resp=200
I0916 10:42:41.706901       1 httplog.go:132] "HTTP" verb="GET" URI="/healthz" latency="93.666µs" userAgent="kube-probe/1.27" audit-ID="" srcIP="10.44.0.0:57022" resp=200
I0916 10:42:41.708124       1 httplog.go:132] "HTTP" verb="GET" URI="/healthz" latency="114.104µs" userAgent="kube-probe/1.27" audit-ID="" srcIP="10.44.0.0:57012" resp=200
I0916 10:42:51.702174       1 httplog.go:132] "HTTP" verb="GET" URI="/healthz" latency="92.093µs" userAgent="kube-probe/1.27" audit-ID="" srcIP="10.44.0.0:52808" resp=200
I0916 10:42:51.703472       1 httplog.go:132] "HTTP" verb="GET" URI="/healthz" latency="121.127µs" userAgent="kube-probe/1.27" audit-ID="" srcIP="10.44.0.0:52796" resp=200
I0916 10:43:01.702013       1 httplog.go:132] "HTTP" verb="GET" URI="/healthz" latency="123.071µs" userAgent="kube-probe/1.27" audit-ID="" srcIP="10.44.0.0:34190" resp=200
I0916 10:43:01.703134       1 httplog.go:132] "HTTP" verb="GET" URI="/healthz" latency="97.893µs" userAgent="kube-probe/1.27" audit-ID="" srcIP="10.44.0.0:34194" resp=200
I0916 10:43:11.702602       1 httplog.go:132] "HTTP" verb="GET" URI="/healthz" latency="95.038µs" userAgent="kube-probe/1.27" audit-ID="" srcIP="10.44.0.0:60172" resp=200
I0916 10:43:11.702915       1 httplog.go:132] "HTTP" verb="GET" URI="/healthz" latency="115.326µs" userAgent="kube-probe/1.27" audit-ID="" srcIP="10.44.0.0:60180" resp=200
I0916 10:43:21.706519       1 httplog.go:132] "HTTP" verb="GET" URI="/healthz" latency="119.254µs" userAgent="kube-probe/1.27" audit-ID="" srcIP="10.44.0.0:56240" resp=200
I0916 10:43:21.708101       1 httplog.go:132] "HTTP" verb="GET" URI="/healthz" latency="117.43µs" userAgent="kube-probe/1.27" audit-ID="" srcIP="10.44.0.0:56234" resp=200
I0916 10:43:31.707403       1 httplog.go:132] "HTTP" verb="GET" URI="/healthz" latency="125.927µs" userAgent="kube-probe/1.27" audit-ID="" srcIP="10.44.0.0:41572" resp=200
I0916 10:43:31.708544       1 httplog.go:132] "HTTP" verb="GET" URI="/healthz" latency="73.047µs" userAgent="kube-probe/1.27" audit-ID="" srcIP="10.44.0.0:41556" resp=200
I0916 10:43:41.706332       1 httplog.go:132] "HTTP" verb="GET" URI="/healthz" latency="109.025µs" userAgent="kube-probe/1.27" audit-ID="" srcIP="10.44.0.0:45564" resp=200
I0916 10:43:41.707391       1 httplog.go:132] "HTTP" verb="GET" URI="/healthz" latency="61.115µs" userAgent="kube-probe/1.27" audit-ID="" srcIP="10.44.0.0:45580" resp=200
I0916 10:43:51.706842       1 httplog.go:132] "HTTP" verb="GET" URI="/healthz" latency="128.441µs" userAgent="kube-probe/1.27" audit-ID="" srcIP="10.44.0.0:40300" resp=200
I0916 10:43:51.708025       1 httplog.go:132] "HTTP" verb="GET" URI="/healthz" latency="74.961µs" userAgent="kube-probe/1.27" audit-ID="" srcIP="10.44.0.0:40288" resp=200
I0916 10:44:01.706831       1 httplog.go:132] "HTTP" verb="GET" URI="/healthz" latency="77.796µs" userAgent="kube-probe/1.27" audit-ID="" srcIP="10.44.0.0:44930" resp=200
I0916 10:44:01.707767       1 httplog.go:132] "HTTP" verb="GET" URI="/healthz" latency="59.432µs" userAgent="kube-probe/1.27" audit-ID="" srcIP="10.44.0.0:44940" resp=200
I0916 10:44:11.701679       1 httplog.go:132] "HTTP" verb="GET" URI="/healthz" latency="100.909µs" userAgent="kube-probe/1.27" audit-ID="" srcIP="10.44.0.0:46162" resp=200
I0916 10:44:11.703052       1 httplog.go:132] "HTTP" verb="GET" URI="/healthz" latency="85.891µs" userAgent="kube-probe/1.27" audit-ID="" srcIP="10.44.0.0:46178" resp=200
I0916 10:44:21.700690       1 httplog.go:132] "HTTP" verb="GET" URI="/healthz" latency="90.68µs" userAgent="kube-probe/1.27" audit-ID="" srcIP="10.44.0.0:57092" resp=200
I0916 10:44:21.701885       1 httplog.go:132] "HTTP" verb="GET" URI="/healthz" latency="29.946µs" userAgent="kube-probe/1.27" audit-ID="" srcIP="10.44.0.0:57094" resp=200
I0916 10:44:31.702159       1 httplog.go:132] "HTTP" verb="GET" URI="/healthz" latency="106.059µs" userAgent="kube-probe/1.27" audit-ID="" srcIP="10.44.0.0:46584" resp=200
I0916 10:44:31.703091       1 httplog.go:132] "HTTP" verb="GET" URI="/healthz" latency="58.219µs" userAgent="kube-probe/1.27" audit-ID="" srcIP="10.44.0.0:46578" resp=200
I0916 10:44:41.702314       1 httplog.go:132] "HTTP" verb="GET" URI="/healthz" latency="95.028µs" userAgent="kube-probe/1.27" audit-ID="" srcIP="10.44.0.0:59364" resp=200
I0916 10:44:41.709810       1 httplog.go:132] "HTTP" verb="GET" URI="/healthz" latency="68.99µs" userAgent="kube-probe/1.27" audit-ID="" srcIP="10.44.0.0:59380" resp=200
I0916 10:44:51.706848       1 httplog.go:132] "HTTP" verb="GET" URI="/healthz" latency="107.812µs" userAgent="kube-probe/1.27" audit-ID="" srcIP="10.44.0.0:59974" resp=200
I0916 10:44:51.707886       1 httplog.go:132] "HTTP" verb="GET" URI="/healthz" latency="61.786µs" userAgent="kube-probe/1.27" audit-ID="" srcIP="10.44.0.0:59988" resp=200
I0916 10:45:01.706968       1 httplog.go:132] "HTTP" verb="GET" URI="/healthz" latency="128.531µs" userAgent="kube-probe/1.27" audit-ID="" srcIP="10.44.0.0:44266" resp=200
I0916 10:45:01.708105       1 httplog.go:132] "HTTP" verb="GET" URI="/healthz" latency="50.936µs" userAgent="kube-probe/1.27" audit-ID="" srcIP="10.44.0.0:44268" resp=200
I0916 10:45:11.702107       1 httplog.go:132] "HTTP" verb="GET" URI="/healthz" latency="112.832µs" userAgent="kube-probe/1.27" audit-ID="" srcIP="10.44.0.0:59988" resp=200
I0916 10:45:11.709792       1 httplog.go:132] "HTTP" verb="GET" URI="/healthz" latency="75.973µs" userAgent="kube-probe/1.27" audit-ID="" srcIP="10.44.0.0:59994" resp=200
I0916 10:45:21.706626       1 httplog.go:132] "HTTP" verb="GET" URI="/healthz" latency="97.513µs" userAgent="kube-probe/1.27" audit-ID="" srcIP="10.44.0.0:50562" resp=200
I0916 10:45:21.707953       1 httplog.go:132] "HTTP" verb="GET" URI="/healthz" latency="54.162µs" userAgent="kube-probe/1.27" audit-ID="" srcIP="10.44.0.0:50560" resp=200
I0916 10:45:31.706607       1 httplog.go:132] "HTTP" verb="GET" URI="/healthz" latency="87.404µs" userAgent="kube-probe/1.27" audit-ID="" srcIP="10.44.0.0:36698" resp=200
I0916 10:45:31.707810       1 httplog.go:132] "HTTP" verb="GET" URI="/healthz" latency="94.777µs" userAgent="kube-probe/1.27" audit-ID="" srcIP="10.44.0.0:36690" resp=200
I0916 10:45:41.707058       1 httplog.go:132] "HTTP" verb="GET" URI="/healthz" latency="77.916µs" userAgent="kube-probe/1.27" audit-ID="" srcIP="10.44.0.0:48168" resp=200
I0916 10:45:41.708135       1 httplog.go:132] "HTTP" verb="GET" URI="/healthz" latency="58.129µs" userAgent="kube-probe/1.27" audit-ID="" srcIP="10.44.0.0:48174" resp=200
I0916 10:45:51.706723       1 httplog.go:132] "HTTP" verb="GET" URI="/healthz" latency="100.439µs" userAgent="kube-probe/1.27" audit-ID="" srcIP="10.44.0.0:34664" resp=200
I0916 10:45:51.707842       1 httplog.go:132] "HTTP" verb="GET" URI="/healthz" latency="83.206µs" userAgent="kube-probe/1.27" audit-ID="" srcIP="10.44.0.0:34662" resp=200
I0916 10:46:01.707414       1 httplog.go:132] "HTTP" verb="GET" URI="/healthz" latency="113.693µs" userAgent="kube-probe/1.27" audit-ID="" srcIP="10.44.0.0:33080" resp=200
I0916 10:46:01.708453       1 httplog.go:132] "HTTP" verb="GET" URI="/healthz" latency="95.289µs" userAgent="kube-probe/1.27" audit-ID="" srcIP="10.44.0.0:33066" resp=200
I0916 10:46:11.699745       1 httplog.go:132] "HTTP" verb="GET" URI="/healthz" latency="102.412µs" userAgent="kube-probe/1.27" audit-ID="" srcIP="10.44.0.0:50336" resp=200
I0916 10:46:11.702900       1 httplog.go:132] "HTTP" verb="GET" URI="/healthz" latency="49.984µs" userAgent="kube-probe/1.27" audit-ID="" srcIP="10.44.0.0:50344" resp=200
I0916 10:46:21.706404       1 httplog.go:132] "HTTP" verb="GET" URI="/healthz" latency="114.755µs" userAgent="kube-probe/1.27" audit-ID="" srcIP="10.44.0.0:50136" resp=200
I0916 10:46:21.707374       1 httplog.go:132] "HTTP" verb="GET" URI="/healthz" latency="72.305µs" userAgent="kube-probe/1.27" audit-ID="" srcIP="10.44.0.0:50132" resp=200
