2023/10/16 05:10:07 falconresources-scheduler starts!
I1016 05:10:07.708616       1 flags.go:64] FLAG: --allow-metric-labels="[]"
I1016 05:10:07.708648       1 flags.go:64] FLAG: --authentication-kubeconfig=""
I1016 05:10:07.708658       1 flags.go:64] FLAG: --authentication-skip-lookup="false"
I1016 05:10:07.708666       1 flags.go:64] FLAG: --authentication-token-webhook-cache-ttl="10s"
I1016 05:10:07.708675       1 flags.go:64] FLAG: --authentication-tolerate-lookup-failure="true"
I1016 05:10:07.708682       1 flags.go:64] FLAG: --authorization-always-allow-paths="[/healthz,/readyz,/livez]"
I1016 05:10:07.708702       1 flags.go:64] FLAG: --authorization-kubeconfig=""
I1016 05:10:07.708709       1 flags.go:64] FLAG: --authorization-webhook-cache-authorized-ttl="10s"
I1016 05:10:07.708715       1 flags.go:64] FLAG: --authorization-webhook-cache-unauthorized-ttl="10s"
I1016 05:10:07.708721       1 flags.go:64] FLAG: --bind-address="0.0.0.0"
I1016 05:10:07.708730       1 flags.go:64] FLAG: --cert-dir=""
I1016 05:10:07.708736       1 flags.go:64] FLAG: --client-ca-file=""
I1016 05:10:07.708742       1 flags.go:64] FLAG: --config="/etc/kubernetes/scheduler-config.yaml"
I1016 05:10:07.708750       1 flags.go:64] FLAG: --contention-profiling="true"
I1016 05:10:07.708759       1 flags.go:64] FLAG: --disabled-metrics="[]"
I1016 05:10:07.708825       1 flags.go:64] FLAG: --feature-gates=""
I1016 05:10:07.708834       1 flags.go:64] FLAG: --help="false"
I1016 05:10:07.708839       1 flags.go:64] FLAG: --http2-max-streams-per-connection="0"
I1016 05:10:07.708846       1 flags.go:64] FLAG: --kube-api-burst="100"
I1016 05:10:07.708855       1 flags.go:64] FLAG: --kube-api-content-type="application/vnd.kubernetes.protobuf"
I1016 05:10:07.708861       1 flags.go:64] FLAG: --kube-api-qps="50"
I1016 05:10:07.708931       1 flags.go:64] FLAG: --kubeconfig=""
I1016 05:10:07.708937       1 flags.go:64] FLAG: --leader-elect="true"
I1016 05:10:07.708942       1 flags.go:64] FLAG: --leader-elect-lease-duration="15s"
I1016 05:10:07.708947       1 flags.go:64] FLAG: --leader-elect-renew-deadline="10s"
I1016 05:10:07.708953       1 flags.go:64] FLAG: --leader-elect-resource-lock="leases"
I1016 05:10:07.708958       1 flags.go:64] FLAG: --leader-elect-resource-name="kube-scheduler"
I1016 05:10:07.708963       1 flags.go:64] FLAG: --leader-elect-resource-namespace="kube-system"
I1016 05:10:07.708968       1 flags.go:64] FLAG: --leader-elect-retry-period="2s"
I1016 05:10:07.708974       1 flags.go:64] FLAG: --lock-object-name="kube-scheduler"
I1016 05:10:07.708979       1 flags.go:64] FLAG: --lock-object-namespace="kube-system"
I1016 05:10:07.708984       1 flags.go:64] FLAG: --log-flush-frequency="5s"
I1016 05:10:07.709000       1 flags.go:64] FLAG: --logging-format="text"
I1016 05:10:07.709064       1 flags.go:64] FLAG: --master=""
I1016 05:10:07.709070       1 flags.go:64] FLAG: --permit-address-sharing="false"
I1016 05:10:07.709076       1 flags.go:64] FLAG: --permit-port-sharing="false"
I1016 05:10:07.709081       1 flags.go:64] FLAG: --pod-max-in-unschedulable-pods-duration="5m0s"
I1016 05:10:07.709086       1 flags.go:64] FLAG: --profiling="true"
I1016 05:10:07.709092       1 flags.go:64] FLAG: --requestheader-allowed-names="[]"
I1016 05:10:07.709101       1 flags.go:64] FLAG: --requestheader-client-ca-file=""
I1016 05:10:07.709107       1 flags.go:64] FLAG: --requestheader-extra-headers-prefix="[x-remote-extra-]"
I1016 05:10:07.709115       1 flags.go:64] FLAG: --requestheader-group-headers="[x-remote-group]"
I1016 05:10:07.709130       1 flags.go:64] FLAG: --requestheader-username-headers="[x-remote-user]"
I1016 05:10:07.709139       1 flags.go:64] FLAG: --secure-port="10259"
I1016 05:10:07.709146       1 flags.go:64] FLAG: --show-hidden-metrics-for-version=""
I1016 05:10:07.709151       1 flags.go:64] FLAG: --tls-cert-file=""
I1016 05:10:07.709157       1 flags.go:64] FLAG: --tls-cipher-suites="[]"
I1016 05:10:07.709168       1 flags.go:64] FLAG: --tls-min-version=""
I1016 05:10:07.709174       1 flags.go:64] FLAG: --tls-private-key-file=""
I1016 05:10:07.709179       1 flags.go:64] FLAG: --tls-sni-cert-key="[]"
I1016 05:10:07.709194       1 flags.go:64] FLAG: --v="2"
I1016 05:10:07.709201       1 flags.go:64] FLAG: --version="false"
I1016 05:10:07.709217       1 flags.go:64] FLAG: --vmodule=""
I1016 05:10:07.709225       1 flags.go:64] FLAG: --write-config-to=""
I1016 05:10:07.910762       1 serving.go:348] Generated self-signed cert in-memory
I1016 05:10:07.911567       1 configfile.go:59] "KubeSchedulerConfiguration v1beta3 is deprecated in v1.26, will be removed in v1.29"
W1016 05:10:07.915669       1 client_config.go:618] Neither --kubeconfig nor --master was specified.  Using the inClusterConfig.  This might not work.
I1016 05:10:08.191830       1 requestheader_controller.go:244] Loaded a new request header values for RequestHeaderAuthRequestController
I1016 05:10:08.208849       1 configfile.go:105] "Using component config" config=<
	apiVersion: kubescheduler.config.k8s.io/v1beta3
	clientConnection:
	  acceptContentTypes: ""
	  burst: 100
	  contentType: application/vnd.kubernetes.protobuf
	  kubeconfig: ""
	  qps: 50
	enableContentionProfiling: true
	enableProfiling: true
	kind: KubeSchedulerConfiguration
	leaderElection:
	  leaderElect: false
	  leaseDuration: 15s
	  renewDeadline: 10s
	  resourceLock: leases
	  resourceName: kube-scheduler
	  resourceNamespace: kube-system
	  retryPeriod: 2s
	parallelism: 16
	percentageOfNodesToScore: 0
	podInitialBackoffSeconds: 1
	podMaxBackoffSeconds: 10
	profiles:
	- pluginConfig:
	  - args:
	      apiVersion: kubescheduler.config.k8s.io/v1beta3
	      kind: DefaultPreemptionArgs
	      minCandidateNodesAbsolute: 100
	      minCandidateNodesPercentage: 10
	    name: DefaultPreemption
	  - args:
	      apiVersion: kubescheduler.config.k8s.io/v1beta3
	      hardPodAffinityWeight: 1
	      ignorePreferredTermsOfExistingPods: false
	      kind: InterPodAffinityArgs
	    name: InterPodAffinity
	  - args:
	      apiVersion: kubescheduler.config.k8s.io/v1beta3
	      kind: NodeAffinityArgs
	    name: NodeAffinity
	  - args:
	      apiVersion: kubescheduler.config.k8s.io/v1beta3
	      kind: NodeResourcesBalancedAllocationArgs
	      resources:
	      - name: cpu
	        weight: 1
	      - name: memory
	        weight: 1
	    name: NodeResourcesBalancedAllocation
	  - args:
	      apiVersion: kubescheduler.config.k8s.io/v1beta3
	      ignoredResourceGroups:
	      - falcon.com
	      kind: NodeResourcesFitArgs
	      scoringStrategy:
	        resources:
	        - name: cpu
	          weight: 1
	        - name: memory
	          weight: 1
	        type: LeastAllocated
	    name: NodeResourcesFit
	  - args:
	      apiVersion: kubescheduler.config.k8s.io/v1beta3
	      defaultingType: System
	      kind: PodTopologySpreadArgs
	    name: PodTopologySpread
	  - args:
	      apiVersion: kubescheduler.config.k8s.io/v1beta3
	      bindTimeoutSeconds: 600
	      kind: VolumeBindingArgs
	    name: VolumeBinding
	  plugins:
	    bind: {}
	    filter: {}
	    multiPoint:
	      enabled:
	      - name: PrioritySort
	        weight: 0
	      - name: NodeUnschedulable
	        weight: 0
	      - name: NodeName
	        weight: 0
	      - name: TaintToleration
	        weight: 3
	      - name: NodeAffinity
	        weight: 2
	      - name: NodePorts
	        weight: 0
	      - name: NodeResourcesFit
	        weight: 1
	      - name: VolumeRestrictions
	        weight: 0
	      - name: EBSLimits
	        weight: 0
	      - name: GCEPDLimits
	        weight: 0
	      - name: NodeVolumeLimits
	        weight: 0
	      - name: AzureDiskLimits
	        weight: 0
	      - name: VolumeBinding
	        weight: 0
	      - name: VolumeZone
	        weight: 0
	      - name: PodTopologySpread
	        weight: 2
	      - name: InterPodAffinity
	        weight: 2
	      - name: DefaultPreemption
	        weight: 0
	      - name: NodeResourcesBalancedAllocation
	        weight: 1
	      - name: ImageLocality
	        weight: 1
	      - name: DefaultBinder
	        weight: 0
	      - name: SchedulingGates
	        weight: 0
	      - name: FalconResources
	        weight: 0
	    permit: {}
	    postBind: {}
	    postFilter: {}
	    preBind: {}
	    preEnqueue: {}
	    preFilter: {}
	    preScore: {}
	    queueSort: {}
	    reserve: {}
	    score: {}
	  schedulerName: my-scheduler
 >
I1016 05:10:08.209266       1 server.go:154] "Starting Kubernetes Scheduler" version="v0.0.0-master+$Format:%H$"
I1016 05:10:08.209281       1 server.go:156] "Golang settings" GOGC="" GOMAXPROCS="" GOTRACEBACK=""
I1016 05:10:08.219950       1 requestheader_controller.go:169] Starting RequestHeaderAuthRequestController
I1016 05:10:08.219984       1 shared_informer.go:311] Waiting for caches to sync for RequestHeaderAuthRequestController
I1016 05:10:08.220036       1 configmap_cafile_content.go:202] "Starting controller" name="client-ca::kube-system::extension-apiserver-authentication::client-ca-file"
I1016 05:10:08.220131       1 shared_informer.go:311] Waiting for caches to sync for client-ca::kube-system::extension-apiserver-authentication::client-ca-file
I1016 05:10:08.220129       1 configmap_cafile_content.go:202] "Starting controller" name="client-ca::kube-system::extension-apiserver-authentication::requestheader-client-ca-file"
I1016 05:10:08.220277       1 shared_informer.go:311] Waiting for caches to sync for client-ca::kube-system::extension-apiserver-authentication::requestheader-client-ca-file
I1016 05:10:08.220569       1 tlsconfig.go:200] "Loaded serving cert" certName="Generated self signed cert" certDetail="\"localhost@1697433007\" [serving] validServingFor=[127.0.0.1,localhost,localhost] issuer=\"localhost-ca@1697433007\" (2023-10-16 04:10:07 +0000 UTC to 2024-10-15 04:10:07 +0000 UTC (now=2023-10-16 05:10:08.220518111 +0000 UTC))"
I1016 05:10:08.221303       1 named_certificates.go:53] "Loaded SNI cert" index=0 certName="self-signed loopback" certDetail="\"apiserver-loopback-client@1697433008\" [serving] validServingFor=[apiserver-loopback-client] issuer=\"apiserver-loopback-client-ca@1697433008\" (2023-10-16 04:10:07 +0000 UTC to 2024-10-15 04:10:07 +0000 UTC (now=2023-10-16 05:10:08.221261993 +0000 UTC))"
I1016 05:10:08.221349       1 secure_serving.go:210] Serving securely on [::]:10259
I1016 05:10:08.221405       1 tlsconfig.go:240] "Starting DynamicServingCertificateController"
I1016 05:10:08.241063       1 node_tree.go:65] "Added node in listed group to NodeTree" node="css-host-128" zone=""
I1016 05:10:08.241326       1 node_tree.go:65] "Added node in listed group to NodeTree" node="css-host-129" zone=""
I1016 05:10:08.320926       1 shared_informer.go:318] Caches are synced for client-ca::kube-system::extension-apiserver-authentication::client-ca-file
I1016 05:10:08.320983       1 shared_informer.go:318] Caches are synced for client-ca::kube-system::extension-apiserver-authentication::requestheader-client-ca-file
I1016 05:10:08.321069       1 shared_informer.go:318] Caches are synced for RequestHeaderAuthRequestController
I1016 05:10:08.321469       1 tlsconfig.go:178] "Loaded client CA" index=0 certName="client-ca::kube-system::extension-apiserver-authentication::client-ca-file,client-ca::kube-system::extension-apiserver-authentication::requestheader-client-ca-file" certDetail="\"kubernetes\" [] validServingFor=[kubernetes] issuer=\"<self>\" (2023-02-25 05:20:24 +0000 UTC to 2033-02-22 05:20:24 +0000 UTC (now=2023-10-16 05:10:08.321435123 +0000 UTC))"
I1016 05:10:08.321501       1 tlsconfig.go:178] "Loaded client CA" index=1 certName="client-ca::kube-system::extension-apiserver-authentication::client-ca-file,client-ca::kube-system::extension-apiserver-authentication::requestheader-client-ca-file" certDetail="\"front-proxy-ca\" [] validServingFor=[front-proxy-ca] issuer=\"<self>\" (2023-02-25 05:20:25 +0000 UTC to 2033-02-22 05:20:25 +0000 UTC (now=2023-10-16 05:10:08.321485148 +0000 UTC))"
I1016 05:10:08.321880       1 tlsconfig.go:200] "Loaded serving cert" certName="Generated self signed cert" certDetail="\"localhost@1697433007\" [serving] validServingFor=[127.0.0.1,localhost,localhost] issuer=\"localhost-ca@1697433007\" (2023-10-16 04:10:07 +0000 UTC to 2024-10-15 04:10:07 +0000 UTC (now=2023-10-16 05:10:08.321862785 +0000 UTC))"
I1016 05:10:08.322215       1 named_certificates.go:53] "Loaded SNI cert" index=0 certName="self-signed loopback" certDetail="\"apiserver-loopback-client@1697433008\" [serving] validServingFor=[apiserver-loopback-client] issuer=\"apiserver-loopback-client-ca@1697433008\" (2023-10-16 04:10:07 +0000 UTC to 2024-10-15 04:10:07 +0000 UTC (now=2023-10-16 05:10:08.322197691 +0000 UTC))"
I1016 05:17:54.690094       1 log.go:194] falcon-pod-01 in Prefilter
I1016 05:17:54.690116       1 log.go:194] falcon-pod-01 requires 5 gpu(s), and currently has 8 gpus(s) in total
I1016 05:17:54.713599       1 event.go:307] "Event occurred" object="default/falcon-pod-01" fieldPath="" kind="Pod" apiVersion="v1" type="Normal" reason="Reconfig" message="Pod falcon-pod-01 needs reconfiguration"
E1016 05:18:34.895739       1 schedule_one.go:883] "Error scheduling pod; retrying" err="" pod="default/falcon-pod-01"
E1016 05:18:34.895848       1 schedule_one.go:902] "Error occurred" err="Pod default/falcon-pod-01 is already present in the active queue"
I1016 05:18:34.904763       1 log.go:194] falcon-pod-01 in Prefilter
I1016 05:18:34.904787       1 log.go:194] falcon-pod-01 requires 5 gpu(s), and currently has 7 gpus(s) in total
I1016 05:18:35.098850       1 trace.go:219] Trace[697609148]: "Scheduling" namespace:default,name:falcon-pod-01 (16-Oct-2023 05:18:34.904) (total time: 194ms):
Trace[697609148]: ---"Computing predicates done" 194ms (05:18:35.098)
Trace[697609148]: [194.19214ms] [194.19214ms] END
I1016 05:18:35.498274       1 event.go:307] "Event occurred" object="default/falcon-pod-01" fieldPath="" kind="Pod" apiVersion="v1" type="Normal" reason="Reconfig" message="Pod falcon-pod-01 needs reconfiguration"
I1016 05:18:44.094046       1 log.go:194] falcon-pod-02 in Prefilter
I1016 05:18:44.094071       1 log.go:194] falcon-pod-02 requires 1 gpu(s), and currently has 3 gpus(s) in total
I1016 05:18:44.097975       1 schedule_one.go:252] "Successfully bound pod to node" pod="default/falcon-pod-01" node="css-host-128" evaluatedNodes=2 feasibleNodes=1
I1016 05:18:44.297585       1 trace.go:219] Trace[253056326]: "Scheduling" namespace:default,name:falcon-pod-02 (16-Oct-2023 05:18:44.093) (total time: 203ms):
Trace[253056326]: ---"Computing predicates done" 203ms (05:18:44.297)
Trace[253056326]: [203.621412ms] [203.621412ms] END
I1016 05:18:44.697166       1 event.go:307] "Event occurred" object="default/falcon-pod-02" fieldPath="" kind="Pod" apiVersion="v1" type="Normal" reason="Reconfig" message="Pod falcon-pod-02 needs reconfiguration"
I1016 05:19:14.893309       1 log.go:194] falcon-pod-03 in Prefilter
I1016 05:19:14.893326       1 log.go:194] falcon-pod-03 requires 1 gpu(s), and currently has 2 gpus(s) in total
I1016 05:19:14.897208       1 schedule_one.go:252] "Successfully bound pod to node" pod="default/falcon-pod-02" node="css-host-128" evaluatedNodes=2 feasibleNodes=1
I1016 05:19:15.096898       1 trace.go:219] Trace[398920468]: "Scheduling" namespace:default,name:falcon-pod-03 (16-Oct-2023 05:19:14.893) (total time: 203ms):
Trace[398920468]: ---"Computing predicates done" 203ms (05:19:15.096)
Trace[398920468]: [203.621093ms] [203.621093ms] END
I1016 05:19:15.498664       1 event.go:307] "Event occurred" object="default/falcon-pod-03" fieldPath="" kind="Pod" apiVersion="v1" type="Normal" reason="Reconfig" message="Pod falcon-pod-03 needs reconfiguration"
I1016 05:19:45.894807       1 log.go:194] falcon-pod-04 in Prefilter
I1016 05:19:45.894836       1 log.go:194] falcon-pod-04 requires 1 gpu(s), and currently has 1 gpus(s) in total
I1016 05:19:45.898898       1 schedule_one.go:252] "Successfully bound pod to node" pod="default/falcon-pod-03" node="css-host-128" evaluatedNodes=2 feasibleNodes=1
I1016 05:19:46.096544       1 trace.go:219] Trace[1194905157]: "Scheduling" namespace:default,name:falcon-pod-04 (16-Oct-2023 05:19:45.894) (total time: 201ms):
Trace[1194905157]: ---"Computing predicates done" 201ms (05:19:46.096)
Trace[1194905157]: [201.786717ms] [201.786717ms] END
I1016 05:19:46.497561       1 event.go:307] "Event occurred" object="default/falcon-pod-04" fieldPath="" kind="Pod" apiVersion="v1" type="Normal" reason="Reconfig" message="Pod falcon-pod-04 needs reconfiguration"
I1016 05:20:16.297851       1 schedule_one.go:252] "Successfully bound pod to node" pod="default/falcon-pod-04" node="css-host-128" evaluatedNodes=2 feasibleNodes=1
I1016 05:24:15.046447       1 log.go:194] falcon-pod-01 in Prefilter
I1016 05:24:15.046485       1 log.go:194] falcon-pod-01 requires 1 gpu(s), and currently has 8 gpus(s) in total
I1016 05:24:15.064107       1 event.go:307] "Event occurred" object="default/falcon-pod-01" fieldPath="" kind="Pod" apiVersion="v1" type="Normal" reason="Reconfig" message="Pod falcon-pod-01 needs reconfiguration"
I1016 05:24:54.651166       1 log.go:194] falcon-pod-02 in Prefilter
I1016 05:24:54.651190       1 log.go:194] falcon-pod-02 requires 1 gpu(s), and currently has 7 gpus(s) in total
I1016 05:24:54.654648       1 schedule_one.go:252] "Successfully bound pod to node" pod="default/falcon-pod-01" node="css-host-129" evaluatedNodes=2 feasibleNodes=1
I1016 05:24:54.853863       1 trace.go:219] Trace[2088775058]: "Scheduling" namespace:default,name:falcon-pod-02 (16-Oct-2023 05:24:54.651) (total time: 202ms):
Trace[2088775058]: ---"Computing predicates done" 202ms (05:24:54.853)
Trace[2088775058]: [202.79494ms] [202.79494ms] END
I1016 05:24:55.254341       1 event.go:307] "Event occurred" object="default/falcon-pod-02" fieldPath="" kind="Pod" apiVersion="v1" type="Normal" reason="Reconfig" message="Pod falcon-pod-02 needs reconfiguration"
E1016 05:25:35.450569       1 schedule_one.go:883] "Error scheduling pod; retrying" err="" pod="default/falcon-pod-02"
E1016 05:25:35.450666       1 schedule_one.go:902] "Error occurred" err="Pod default/falcon-pod-02 is already present in the active queue"
I1016 05:25:35.456376       1 log.go:194] falcon-pod-03 in Prefilter
I1016 05:25:35.456401       1 log.go:194] falcon-pod-03 requires 1 gpu(s), and currently has 6 gpus(s) in total
I1016 05:25:35.654421       1 trace.go:219] Trace[79764340]: "Scheduling" namespace:default,name:falcon-pod-03 (16-Oct-2023 05:25:35.456) (total time: 198ms):
Trace[79764340]: ---"Computing predicates done" 198ms (05:25:35.654)
Trace[79764340]: [198.131428ms] [198.131428ms] END
I1016 05:25:36.054761       1 event.go:307] "Event occurred" object="default/falcon-pod-03" fieldPath="" kind="Pod" apiVersion="v1" type="Normal" reason="Reconfig" message="Pod falcon-pod-03 needs reconfiguration"
I1016 05:25:46.051318       1 log.go:194] falcon-pod-04 in Prefilter
I1016 05:25:46.051349       1 log.go:194] falcon-pod-04 requires 1 gpu(s), and currently has 6 gpus(s) in total
I1016 05:25:46.054784       1 schedule_one.go:252] "Successfully bound pod to node" pod="default/falcon-pod-03" node="css-host-129" evaluatedNodes=2 feasibleNodes=1
I1016 05:25:46.254833       1 trace.go:219] Trace[939177614]: "Scheduling" namespace:default,name:falcon-pod-04 (16-Oct-2023 05:25:46.051) (total time: 203ms):
Trace[939177614]: ---"Computing predicates done" 203ms (05:25:46.254)
Trace[939177614]: [203.645533ms] [203.645533ms] END
I1016 05:25:46.655697       1 event.go:307] "Event occurred" object="default/falcon-pod-04" fieldPath="" kind="Pod" apiVersion="v1" type="Normal" reason="Reconfig" message="Pod falcon-pod-04 needs reconfiguration"
I1016 05:26:16.451125       1 log.go:194] falcon-pod-05 in Prefilter
I1016 05:26:16.451153       1 log.go:194] falcon-pod-05 requires 1 gpu(s), and currently has 5 gpus(s) in total
I1016 05:26:16.455515       1 schedule_one.go:252] "Successfully bound pod to node" pod="default/falcon-pod-04" node="css-host-129" evaluatedNodes=2 feasibleNodes=1
I1016 05:26:16.653324       1 trace.go:219] Trace[1218845458]: "Scheduling" namespace:default,name:falcon-pod-05 (16-Oct-2023 05:26:16.450) (total time: 202ms):
Trace[1218845458]: ---"Computing predicates done" 202ms (05:26:16.653)
Trace[1218845458]: [202.265019ms] [202.265019ms] END
I1016 05:26:17.056356       1 event.go:307] "Event occurred" object="default/falcon-pod-05" fieldPath="" kind="Pod" apiVersion="v1" type="Normal" reason="Reconfig" message="Pod falcon-pod-05 needs reconfiguration"
I1016 05:26:37.050713       1 log.go:194] falcon-pod-06 in Prefilter
I1016 05:26:37.050738       1 log.go:194] falcon-pod-06 requires 1 gpu(s), and currently has 4 gpus(s) in total
I1016 05:26:37.055025       1 schedule_one.go:252] "Successfully bound pod to node" pod="default/falcon-pod-05" node="css-host-129" evaluatedNodes=2 feasibleNodes=1
I1016 05:26:37.253142       1 trace.go:219] Trace[1734307125]: "Scheduling" namespace:default,name:falcon-pod-06 (16-Oct-2023 05:26:37.050) (total time: 202ms):
Trace[1734307125]: ---"Computing predicates done" 202ms (05:26:37.253)
Trace[1734307125]: [202.506882ms] [202.506882ms] END
I1016 05:26:37.653558       1 event.go:307] "Event occurred" object="default/falcon-pod-06" fieldPath="" kind="Pod" apiVersion="v1" type="Normal" reason="Reconfig" message="Pod falcon-pod-06 needs reconfiguration"
I1016 05:27:17.850353       1 log.go:194] falcon-pod-07 in Prefilter
I1016 05:27:17.850376       1 log.go:194] falcon-pod-07 requires 1 gpu(s), and currently has 3 gpus(s) in total
I1016 05:27:17.854548       1 schedule_one.go:252] "Successfully bound pod to node" pod="default/falcon-pod-06" node="css-host-129" evaluatedNodes=2 feasibleNodes=1
I1016 05:27:18.053734       1 trace.go:219] Trace[1593235482]: "Scheduling" namespace:default,name:falcon-pod-07 (16-Oct-2023 05:27:17.850) (total time: 203ms):
Trace[1593235482]: ---"Computing predicates done" 203ms (05:27:18.053)
Trace[1593235482]: [203.484537ms] [203.484537ms] END
I1016 05:27:18.453870       1 event.go:307] "Event occurred" object="default/falcon-pod-07" fieldPath="" kind="Pod" apiVersion="v1" type="Normal" reason="Reconfig" message="Pod falcon-pod-07 needs reconfiguration"
I1016 05:27:48.451235       1 log.go:194] falcon-pod-08 in Prefilter
I1016 05:27:48.451256       1 log.go:194] falcon-pod-08 requires 1 gpu(s), and currently has 2 gpus(s) in total
I1016 05:27:48.455555       1 schedule_one.go:252] "Successfully bound pod to node" pod="default/falcon-pod-07" node="css-host-129" evaluatedNodes=2 feasibleNodes=1
I1016 05:27:48.652787       1 trace.go:219] Trace[1609470362]: "Scheduling" namespace:default,name:falcon-pod-08 (16-Oct-2023 05:27:48.451) (total time: 201ms):
Trace[1609470362]: ---"Computing predicates done" 201ms (05:27:48.652)
Trace[1609470362]: [201.641604ms] [201.641604ms] END
I1016 05:27:49.055459       1 event.go:307] "Event occurred" object="default/falcon-pod-08" fieldPath="" kind="Pod" apiVersion="v1" type="Normal" reason="Reconfig" message="Pod falcon-pod-08 needs reconfiguration"
I1016 05:28:09.051680       1 log.go:194] falcon-pod-02 in Prefilter
I1016 05:28:09.051707       1 log.go:194] falcon-pod-02 requires 1 gpu(s), and currently has 1 gpus(s) in total
I1016 05:28:09.056022       1 schedule_one.go:252] "Successfully bound pod to node" pod="default/falcon-pod-08" node="css-host-129" evaluatedNodes=2 feasibleNodes=1
I1016 05:28:09.253075       1 trace.go:219] Trace[1857499062]: "Scheduling" namespace:default,name:falcon-pod-02 (16-Oct-2023 05:28:09.051) (total time: 201ms):
Trace[1857499062]: ---"Computing predicates done" 201ms (05:28:09.253)
Trace[1857499062]: [201.528184ms] [201.528184ms] END
I1016 05:28:09.654745       1 event.go:307] "Event occurred" object="default/falcon-pod-02" fieldPath="" kind="Pod" apiVersion="v1" type="Normal" reason="Reconfig" message="Pod falcon-pod-02 needs reconfiguration"
I1016 05:28:39.860337       1 schedule_one.go:252] "Successfully bound pod to node" pod="default/falcon-pod-02" node="css-host-129" evaluatedNodes=2 feasibleNodes=1
I1016 05:32:37.417382       1 log.go:194] falcon-pod-01 in Prefilter
I1016 05:32:37.417415       1 log.go:194] falcon-pod-01 requires 1 gpu(s), and currently has 8 gpus(s) in total
I1016 05:32:37.436892       1 event.go:307] "Event occurred" object="default/falcon-pod-01" fieldPath="" kind="Pod" apiVersion="v1" type="Normal" reason="Reconfig" message="Pod falcon-pod-01 needs reconfiguration"
I1016 05:33:02.426685       1 schedule_one.go:252] "Successfully bound pod to node" pod="default/falcon-pod-01" node="css-host-128" evaluatedNodes=2 feasibleNodes=1
I1016 05:33:18.478630       1 log.go:194] falcon-pod-02 in Prefilter
I1016 05:33:18.478661       1 log.go:194] falcon-pod-02 requires 1 gpu(s), and currently has 7 gpus(s) in total
I1016 05:33:18.495885       1 event.go:307] "Event occurred" object="default/falcon-pod-02" fieldPath="" kind="Pod" apiVersion="v1" type="Normal" reason="Reconfig" message="Pod falcon-pod-02 needs reconfiguration"
I1016 05:33:53.286438       1 schedule_one.go:252] "Successfully bound pod to node" pod="default/falcon-pod-02" node="css-host-128" evaluatedNodes=2 feasibleNodes=1
I1016 05:34:03.605034       1 log.go:194] falcon-pod-03 in Prefilter
I1016 05:34:03.605072       1 log.go:194] falcon-pod-03 requires 1 gpu(s), and currently has 6 gpus(s) in total
I1016 05:34:03.622615       1 event.go:307] "Event occurred" object="default/falcon-pod-03" fieldPath="" kind="Pod" apiVersion="v1" type="Normal" reason="Reconfig" message="Pod falcon-pod-03 needs reconfiguration"
I1016 05:34:34.413641       1 schedule_one.go:252] "Successfully bound pod to node" pod="default/falcon-pod-03" node="css-host-128" evaluatedNodes=2 feasibleNodes=1
I1016 05:34:53.274163       1 log.go:194] falcon-pod-04 in Prefilter
I1016 05:34:53.274195       1 log.go:194] falcon-pod-04 requires 1 gpu(s), and currently has 5 gpus(s) in total
I1016 05:34:53.295734       1 event.go:307] "Event occurred" object="default/falcon-pod-04" fieldPath="" kind="Pod" apiVersion="v1" type="Normal" reason="Reconfig" message="Pod falcon-pod-04 needs reconfiguration"
I1016 05:35:25.483182       1 schedule_one.go:252] "Successfully bound pod to node" pod="default/falcon-pod-04" node="css-host-128" evaluatedNodes=2 feasibleNodes=1
I1016 05:35:44.440762       1 log.go:194] falcon-pod-05 in Prefilter
I1016 05:35:44.440792       1 log.go:194] falcon-pod-05 requires 1 gpu(s), and currently has 4 gpus(s) in total
I1016 05:35:44.460304       1 event.go:307] "Event occurred" object="default/falcon-pod-05" fieldPath="" kind="Pod" apiVersion="v1" type="Normal" reason="Reconfig" message="Pod falcon-pod-05 needs reconfiguration"
I1016 05:36:16.850603       1 schedule_one.go:252] "Successfully bound pod to node" pod="default/falcon-pod-05" node="css-host-128" evaluatedNodes=2 feasibleNodes=1
I1016 05:36:28.788506       1 log.go:194] falcon-pod-06 in Prefilter
I1016 05:36:28.788536       1 log.go:194] falcon-pod-06 requires 1 gpu(s), and currently has 3 gpus(s) in total
I1016 05:36:28.806285       1 event.go:307] "Event occurred" object="default/falcon-pod-06" fieldPath="" kind="Pod" apiVersion="v1" type="Normal" reason="Reconfig" message="Pod falcon-pod-06 needs reconfiguration"
I1016 05:37:08.601195       1 schedule_one.go:252] "Successfully bound pod to node" pod="default/falcon-pod-06" node="css-host-128" evaluatedNodes=2 feasibleNodes=1
I1016 05:37:17.708411       1 log.go:194] falcon-pod-07 in Prefilter
I1016 05:37:17.708441       1 log.go:194] falcon-pod-07 requires 1 gpu(s), and currently has 2 gpus(s) in total
I1016 05:37:17.727273       1 event.go:307] "Event occurred" object="default/falcon-pod-07" fieldPath="" kind="Pod" apiVersion="v1" type="Normal" reason="Reconfig" message="Pod falcon-pod-07 needs reconfiguration"
E1016 05:37:57.912819       1 schedule_one.go:883] "Error scheduling pod; retrying" err="" pod="default/falcon-pod-07"
E1016 05:37:57.912901       1 schedule_one.go:902] "Error occurred" err="Pod default/falcon-pod-07 is already present in the active queue"
I1016 05:37:57.919454       1 log.go:194] falcon-pod-07 in Prefilter
I1016 05:37:57.919480       1 log.go:194] falcon-pod-07 requires 1 gpu(s), and currently has 1 gpus(s) in total
I1016 05:37:58.115685       1 trace.go:219] Trace[1012562838]: "Scheduling" namespace:default,name:falcon-pod-07 (16-Oct-2023 05:37:57.919) (total time: 196ms):
Trace[1012562838]: ---"Computing predicates done" 196ms (05:37:58.115)
Trace[1012562838]: [196.385622ms] [196.385622ms] END
I1016 05:37:58.516145       1 event.go:307] "Event occurred" object="default/falcon-pod-07" fieldPath="" kind="Pod" apiVersion="v1" type="Normal" reason="Reconfig" message="Pod falcon-pod-07 needs reconfiguration"
I1016 05:37:59.715873       1 schedule_one.go:252] "Successfully bound pod to node" pod="default/falcon-pod-07" node="css-host-128" evaluatedNodes=2 feasibleNodes=1
I1016 05:43:29.230660       1 log.go:194] falcon-pod-01 in Prefilter
I1016 05:43:29.230699       1 log.go:194] falcon-pod-01 requires 1 gpu(s), and currently has 8 gpus(s) in total
I1016 05:43:29.249050       1 event.go:307] "Event occurred" object="default/falcon-pod-01" fieldPath="" kind="Pod" apiVersion="v1" type="Normal" reason="Reconfig" message="Pod falcon-pod-01 needs reconfiguration"
I1016 05:44:09.238914       1 schedule_one.go:252] "Successfully bound pod to node" pod="default/falcon-pod-01" node="css-host-129" evaluatedNodes=2 feasibleNodes=1
I1016 05:44:30.488198       1 log.go:194] falcon-pod-02 in Prefilter
I1016 05:44:30.488228       1 log.go:194] falcon-pod-02 requires 1 gpu(s), and currently has 7 gpus(s) in total
I1016 05:44:30.507331       1 event.go:307] "Event occurred" object="default/falcon-pod-02" fieldPath="" kind="Pod" apiVersion="v1" type="Normal" reason="Reconfig" message="Pod falcon-pod-02 needs reconfiguration"
E1016 05:45:10.696382       1 schedule_one.go:883] "Error scheduling pod; retrying" err="" pod="default/falcon-pod-02"
E1016 05:45:10.696471       1 schedule_one.go:902] "Error occurred" err="Pod default/falcon-pod-02 is already present in the active queue"
I1016 05:45:10.703638       1 log.go:194] falcon-pod-02 in Prefilter
I1016 05:45:10.703667       1 log.go:194] falcon-pod-02 requires 1 gpu(s), and currently has 6 gpus(s) in total
I1016 05:45:10.896364       1 trace.go:219] Trace[2144204123]: "Scheduling" namespace:default,name:falcon-pod-02 (16-Oct-2023 05:45:10.703) (total time: 192ms):
Trace[2144204123]: ---"Computing predicates done" 192ms (05:45:10.896)
Trace[2144204123]: [192.822839ms] [192.822839ms] END
I1016 05:45:11.096695       1 schedule_one.go:252] "Successfully bound pod to node" pod="default/falcon-pod-02" node="css-host-129" evaluatedNodes=2 feasibleNodes=1
I1016 05:45:21.636946       1 log.go:194] falcon-pod-03 in Prefilter
I1016 05:45:21.636975       1 log.go:194] falcon-pod-03 requires 1 gpu(s), and currently has 6 gpus(s) in total
I1016 05:45:21.656235       1 event.go:307] "Event occurred" object="default/falcon-pod-03" fieldPath="" kind="Pod" apiVersion="v1" type="Normal" reason="Reconfig" message="Pod falcon-pod-03 needs reconfiguration"
E1016 05:46:01.846318       1 schedule_one.go:883] "Error scheduling pod; retrying" err="" pod="default/falcon-pod-03"
E1016 05:46:01.846435       1 schedule_one.go:902] "Error occurred" err="Pod default/falcon-pod-03 is already present in the active queue"
I1016 05:46:01.853942       1 log.go:194] falcon-pod-03 in Prefilter
I1016 05:46:01.853965       1 log.go:194] falcon-pod-03 requires 1 gpu(s), and currently has 5 gpus(s) in total
I1016 05:46:02.044420       1 trace.go:219] Trace[537128504]: "Scheduling" namespace:default,name:falcon-pod-03 (16-Oct-2023 05:46:01.853) (total time: 190ms):
Trace[537128504]: ---"Computing predicates done" 190ms (05:46:02.044)
Trace[537128504]: [190.571157ms] [190.571157ms] END
I1016 05:46:02.444292       1 event.go:307] "Event occurred" object="default/falcon-pod-03" fieldPath="" kind="Pod" apiVersion="v1" type="Normal" reason="Reconfig" message="Pod falcon-pod-03 needs reconfiguration"
I1016 05:46:12.046120       1 schedule_one.go:252] "Successfully bound pod to node" pod="default/falcon-pod-03" node="css-host-129" evaluatedNodes=2 feasibleNodes=1
I1016 05:47:02.376906       1 log.go:194] falcon-pod-04 in Prefilter
I1016 05:47:02.376933       1 log.go:194] falcon-pod-04 requires 1 gpu(s), and currently has 5 gpus(s) in total
I1016 05:47:02.391749       1 schedule_one.go:252] "Successfully bound pod to node" pod="default/falcon-pod-04" node="css-host-129" evaluatedNodes=2 feasibleNodes=1
I1016 05:48:10.994573       1 log.go:194] falcon-pod-05 in Prefilter
I1016 05:48:10.994604       1 log.go:194] falcon-pod-05 requires 1 gpu(s), and currently has 5 gpus(s) in total
I1016 05:48:11.009631       1 schedule_one.go:252] "Successfully bound pod to node" pod="default/falcon-pod-05" node="css-host-129" evaluatedNodes=2 feasibleNodes=1
I1016 05:48:24.205397       1 log.go:194] falcon-pod-06 in Prefilter
I1016 05:48:24.205424       1 log.go:194] falcon-pod-06 requires 1 gpu(s), and currently has 4 gpus(s) in total
I1016 05:48:24.222734       1 event.go:307] "Event occurred" object="default/falcon-pod-06" fieldPath="" kind="Pod" apiVersion="v1" type="Normal" reason="Reconfig" message="Pod falcon-pod-06 needs reconfiguration"
E1016 05:49:04.410197       1 schedule_one.go:883] "Error scheduling pod; retrying" err="" pod="default/falcon-pod-06"
E1016 05:49:04.410299       1 schedule_one.go:902] "Error occurred" err="Pod default/falcon-pod-06 is already present in the active queue"
I1016 05:49:04.417400       1 log.go:194] falcon-pod-06 in Prefilter
I1016 05:49:04.417433       1 log.go:194] falcon-pod-06 requires 1 gpu(s), and currently has 3 gpus(s) in total
I1016 05:49:04.612282       1 trace.go:219] Trace[1176934021]: "Scheduling" namespace:default,name:falcon-pod-06 (16-Oct-2023 05:49:04.417) (total time: 195ms):
Trace[1176934021]: ---"Computing predicates done" 195ms (05:49:04.612)
Trace[1176934021]: [195.044347ms] [195.044347ms] END
I1016 05:49:05.012883       1 event.go:307] "Event occurred" object="default/falcon-pod-06" fieldPath="" kind="Pod" apiVersion="v1" type="Normal" reason="Reconfig" message="Pod falcon-pod-06 needs reconfiguration"
I1016 05:49:05.612507       1 schedule_one.go:252] "Successfully bound pod to node" pod="default/falcon-pod-06" node="css-host-129" evaluatedNodes=2 feasibleNodes=1
I1016 05:49:16.368661       1 log.go:194] falcon-pod-07 in Prefilter
I1016 05:49:16.368690       1 log.go:194] falcon-pod-07 requires 1 gpu(s), and currently has 3 gpus(s) in total
I1016 05:49:16.386554       1 event.go:307] "Event occurred" object="default/falcon-pod-07" fieldPath="" kind="Pod" apiVersion="v1" type="Normal" reason="Reconfig" message="Pod falcon-pod-07 needs reconfiguration"
E1016 05:49:56.572639       1 schedule_one.go:883] "Error scheduling pod; retrying" err="" pod="default/falcon-pod-07"
E1016 05:49:56.572727       1 schedule_one.go:902] "Error occurred" err="Pod default/falcon-pod-07 is already present in the active queue"
I1016 05:49:56.579125       1 log.go:194] falcon-pod-07 in Prefilter
I1016 05:49:56.579144       1 log.go:194] falcon-pod-07 requires 1 gpu(s), and currently has 3 gpus(s) in total
I1016 05:49:56.779427       1 trace.go:219] Trace[1884350888]: "Scheduling" namespace:default,name:falcon-pod-07 (16-Oct-2023 05:49:56.579) (total time: 199ms):
Trace[1884350888]: ---"Computing predicates done" 199ms (05:49:56.778)
Trace[1884350888]: [199.97918ms] [199.97918ms] END
I1016 05:49:56.976763       1 schedule_one.go:252] "Successfully bound pod to node" pod="default/falcon-pod-07" node="css-host-129" evaluatedNodes=2 feasibleNodes=1
I1016 06:01:59.951383       1 log.go:194] falcon-pod-c02 in Prefilter
I1016 06:01:59.951418       1 log.go:194] falcon-pod-c02 requires 2 gpu(s), and currently has 8 gpus(s) in total
I1016 06:01:59.959779       1 log.go:194] css-host-128 has 1 gpu, falcon-pod-c02 requires 2 gpu -> score: -1
I1016 06:01:59.959832       1 log.go:194] css-host-129 has 7 gpu, falcon-pod-c02 requires 2 gpu -> score: 28
I1016 06:01:59.967694       1 schedule_one.go:252] "Successfully bound pod to node" pod="default/falcon-pod-c02" node="css-host-129" evaluatedNodes=2 feasibleNodes=2
I1016 06:07:13.252833       1 log.go:194] falcon-pod-c02 in Prefilter
I1016 06:07:13.252877       1 log.go:194] falcon-pod-c02 requires 2 gpu(s), and currently has 8 gpus(s) in total
I1016 06:07:13.260357       1 log.go:194] css-host-129 has 4 gpu, falcon-pod-c02 requires 2 gpu -> score: 50
I1016 06:07:13.260402       1 log.go:194] css-host-128 has 4 gpu, falcon-pod-c02 requires 2 gpu -> score: 50
I1016 06:07:13.268819       1 schedule_one.go:252] "Successfully bound pod to node" pod="default/falcon-pod-c02" node="css-host-129" evaluatedNodes=2 feasibleNodes=2
I1016 06:08:06.315625       1 log.go:194] falcon-pod-a01 in Prefilter
I1016 06:08:06.315658       1 log.go:194] falcon-pod-a01 requires 1 gpu(s), and currently has 6 gpus(s) in total
I1016 06:08:06.322882       1 log.go:194] css-host-128 has 4 gpu, falcon-pod-a01 requires 1 gpu -> score: 25
I1016 06:08:06.322931       1 log.go:194] css-host-129 has 2 gpu, falcon-pod-a01 requires 1 gpu -> score: 50
I1016 06:08:06.330648       1 schedule_one.go:252] "Successfully bound pod to node" pod="default/falcon-pod-a01" node="css-host-129" evaluatedNodes=2 feasibleNodes=2
I1016 06:09:04.361538       1 log.go:194] falcon-pod-b03 in Prefilter
I1016 06:09:04.361568       1 log.go:194] falcon-pod-b03 requires 1 gpu(s), and currently has 5 gpus(s) in total
I1016 06:09:04.369620       1 log.go:194] css-host-128 has 4 gpu, falcon-pod-b03 requires 1 gpu -> score: 25
I1016 06:09:04.369658       1 log.go:194] css-host-129 has 1 gpu, falcon-pod-b03 requires 1 gpu -> score: 100
I1016 06:09:04.376975       1 schedule_one.go:252] "Successfully bound pod to node" pod="default/falcon-pod-b03" node="css-host-129" evaluatedNodes=2 feasibleNodes=2
I1016 06:10:10.434015       1 log.go:194] falcon-pod-d04 in Prefilter
I1016 06:10:10.434045       1 log.go:194] falcon-pod-d04 requires 4 gpu(s), and currently has 4 gpus(s) in total
I1016 06:10:10.447298       1 schedule_one.go:252] "Successfully bound pod to node" pod="default/falcon-pod-d04" node="css-host-128" evaluatedNodes=2 feasibleNodes=1
I1016 06:11:11.493647       1 log.go:194] falcon-pod-a04 in Prefilter
I1016 06:11:11.493680       1 log.go:194] falcon-pod-a04 requires 1 gpu(s), and currently has 0 gpus(s) in total
I1016 06:11:11.500248       1 schedule_one.go:867] "Unable to schedule pod; no fit; waiting" pod="default/falcon-pod-a04" err="0/2 nodes are available: falcon-pod-a04 requires 1 gpu but only 0 gpu in the pool.. preemption: 0/2 nodes are available: 2 No preemption victims found for incoming pod.."
E1016 06:11:11.500362       1 schedule_one.go:902] "Error occurred" err="Pod default/falcon-pod-a04 is already present in the active queue"
I1016 06:11:11.507275       1 log.go:194] falcon-pod-a04 in Prefilter
I1016 06:11:11.507304       1 log.go:194] falcon-pod-a04 requires 1 gpu(s), and currently has 0 gpus(s) in total
I1016 06:11:11.511843       1 schedule_one.go:867] "Unable to schedule pod; no fit; waiting" pod="default/falcon-pod-a04" err="0/2 nodes are available: falcon-pod-a04 requires 1 gpu but only 0 gpu in the pool.. preemption: 0/2 nodes are available: 2 No preemption victims found for incoming pod.."
E1016 06:11:11.511919       1 schedule_one.go:902] "Error occurred" err="Pod default/falcon-pod-a04 is already present in the active queue"
I1016 06:11:11.516621       1 log.go:194] falcon-pod-a04 in Prefilter
I1016 06:11:11.516642       1 log.go:194] falcon-pod-a04 requires 1 gpu(s), and currently has 0 gpus(s) in total
I1016 06:11:11.522038       1 schedule_one.go:867] "Unable to schedule pod; no fit; waiting" pod="default/falcon-pod-a04" err="0/2 nodes are available: falcon-pod-a04 requires 1 gpu but only 0 gpu in the pool.. preemption: 0/2 nodes are available: 2 No preemption victims found for incoming pod.."
I1016 06:12:30.443128       1 log.go:194] falcon-pod-a04 in Prefilter
I1016 06:12:30.443157       1 log.go:194] falcon-pod-a04 requires 1 gpu(s), and currently has 2 gpus(s) in total
I1016 06:12:30.461190       1 event.go:307] "Event occurred" object="default/falcon-pod-a04" fieldPath="" kind="Pod" apiVersion="v1" type="Normal" reason="Reconfig" message="Pod falcon-pod-a04 needs reconfiguration"
E1016 06:13:10.647942       1 schedule_one.go:883] "Error scheduling pod; retrying" err="" pod="default/falcon-pod-a04"
I1016 06:13:13.584397       1 log.go:194] falcon-pod-a04 in Prefilter
I1016 06:13:13.584427       1 log.go:194] falcon-pod-a04 requires 1 gpu(s), and currently has 1 gpus(s) in total
I1016 06:13:13.601152       1 event.go:307] "Event occurred" object="default/falcon-pod-a04" fieldPath="" kind="Pod" apiVersion="v1" type="Normal" reason="Reconfig" message="Pod falcon-pod-a04 needs reconfiguration"
I1016 06:13:16.391909       1 schedule_one.go:252] "Successfully bound pod to node" pod="default/falcon-pod-a04" node="css-host-128" evaluatedNodes=2 feasibleNodes=1
I1016 06:13:23.542669       1 log.go:194] falcon-pod-d02 in Prefilter
I1016 06:13:23.542702       1 log.go:194] falcon-pod-d02 requires 4 gpu(s), and currently has 2 gpus(s) in total
I1016 06:13:23.549747       1 schedule_one.go:867] "Unable to schedule pod; no fit; waiting" pod="default/falcon-pod-d02" err="0/2 nodes are available: falcon-pod-d02 requires 4 gpu but only 2 gpu in the pool.. preemption: 0/2 nodes are available: 2 No preemption victims found for incoming pod.."
E1016 06:13:23.549854       1 schedule_one.go:902] "Error occurred" err="Pod default/falcon-pod-d02 is already present in the active queue"
I1016 06:13:23.555220       1 log.go:194] falcon-pod-d02 in Prefilter
I1016 06:13:23.555248       1 log.go:194] falcon-pod-d02 requires 4 gpu(s), and currently has 2 gpus(s) in total
I1016 06:13:23.561586       1 schedule_one.go:867] "Unable to schedule pod; no fit; waiting" pod="default/falcon-pod-d02" err="0/2 nodes are available: falcon-pod-d02 requires 4 gpu but only 2 gpu in the pool.. preemption: 0/2 nodes are available: 2 No preemption victims found for incoming pod.."
I1016 06:14:12.528897       1 log.go:194] falcon-pod-d02 in Prefilter
I1016 06:14:12.528924       1 log.go:194] falcon-pod-d02 requires 4 gpu(s), and currently has 3 gpus(s) in total
I1016 06:14:12.535758       1 schedule_one.go:867] "Unable to schedule pod; no fit; waiting" pod="default/falcon-pod-d02" err="0/2 nodes are available: falcon-pod-d02 requires 4 gpu but only 3 gpu in the pool.. preemption: 0/2 nodes are available: 2 No preemption victims found for incoming pod.."
I1016 06:15:30.117929       1 log.go:194] falcon-pod-d02 in Prefilter
I1016 06:15:30.117963       1 log.go:194] falcon-pod-d02 requires 4 gpu(s), and currently has 7 gpus(s) in total
I1016 06:15:30.126650       1 log.go:194] css-host-128 has 5 gpu, falcon-pod-d02 requires 4 gpu -> score: 80
I1016 06:15:30.126691       1 log.go:194] css-host-129 has 2 gpu, falcon-pod-d02 requires 4 gpu -> score: -2
I1016 06:15:30.135377       1 schedule_one.go:252] "Successfully bound pod to node" pod="default/falcon-pod-d02" node="css-host-128" evaluatedNodes=2 feasibleNodes=2
I1016 06:15:47.897881       1 log.go:194] falcon-pod-c01 in Prefilter
I1016 06:15:47.897916       1 log.go:194] falcon-pod-c01 requires 2 gpu(s), and currently has 3 gpus(s) in total
I1016 06:15:47.905459       1 log.go:194] css-host-128 has 1 gpu, falcon-pod-c01 requires 2 gpu -> score: -1
I1016 06:15:47.905502       1 log.go:194] css-host-129 has 2 gpu, falcon-pod-c01 requires 2 gpu -> score: 100
I1016 06:15:47.913075       1 schedule_one.go:252] "Successfully bound pod to node" pod="default/falcon-pod-c01" node="css-host-129" evaluatedNodes=2 feasibleNodes=2
I1016 06:15:57.089783       1 log.go:194] falcon-pod-d05 in Prefilter
I1016 06:15:57.089820       1 log.go:194] falcon-pod-d05 requires 4 gpu(s), and currently has 1 gpus(s) in total
I1016 06:15:57.096407       1 schedule_one.go:867] "Unable to schedule pod; no fit; waiting" pod="default/falcon-pod-d05" err="0/2 nodes are available: falcon-pod-d05 requires 4 gpu but only 1 gpu in the pool.. preemption: 0/2 nodes are available: 2 No preemption victims found for incoming pod.."
E1016 06:15:57.096513       1 schedule_one.go:902] "Error occurred" err="Pod default/falcon-pod-d05 is already present in the active queue"
I1016 06:15:57.102051       1 log.go:194] falcon-pod-d05 in Prefilter
I1016 06:15:57.102081       1 log.go:194] falcon-pod-d05 requires 4 gpu(s), and currently has 1 gpus(s) in total
I1016 06:15:57.108240       1 schedule_one.go:867] "Unable to schedule pod; no fit; waiting" pod="default/falcon-pod-d05" err="0/2 nodes are available: falcon-pod-d05 requires 4 gpu but only 1 gpu in the pool.. preemption: 0/2 nodes are available: 2 No preemption victims found for incoming pod.."
E1016 06:15:57.108351       1 schedule_one.go:902] "Error occurred" err="Pod default/falcon-pod-d05 is already present in the active queue"
I1016 06:15:57.113246       1 log.go:194] falcon-pod-d05 in Prefilter
I1016 06:15:57.113272       1 log.go:194] falcon-pod-d05 requires 4 gpu(s), and currently has 1 gpus(s) in total
I1016 06:15:57.119202       1 schedule_one.go:867] "Unable to schedule pod; no fit; waiting" pod="default/falcon-pod-d05" err="0/2 nodes are available: falcon-pod-d05 requires 4 gpu but only 1 gpu in the pool.. preemption: 0/2 nodes are available: 2 No preemption victims found for incoming pod.."
I1016 06:18:24.023011       1 log.go:194] falcon-pod-d05 in Prefilter
I1016 06:18:24.023043       1 log.go:194] falcon-pod-d05 requires 4 gpu(s), and currently has 2 gpus(s) in total
I1016 06:18:24.030174       1 schedule_one.go:867] "Unable to schedule pod; no fit; waiting" pod="default/falcon-pod-d05" err="0/2 nodes are available: falcon-pod-d05 requires 4 gpu but only 2 gpu in the pool.. preemption: 0/2 nodes are available: 2 No preemption victims found for incoming pod.."
I1016 06:20:51.570013       1 log.go:194] falcon-pod-d05 in Prefilter
I1016 06:20:51.570041       1 log.go:194] falcon-pod-d05 requires 4 gpu(s), and currently has 6 gpus(s) in total
I1016 06:20:51.576342       1 log.go:194] css-host-128 has 6 gpu, falcon-pod-d05 requires 4 gpu -> score: 66
I1016 06:20:51.576469       1 log.go:194] css-host-129 has 0 gpu, falcon-pod-d05 requires 4 gpu -> score: -4
I1016 06:20:51.583777       1 schedule_one.go:252] "Successfully bound pod to node" pod="default/falcon-pod-d05" node="css-host-128" evaluatedNodes=2 feasibleNodes=2
I1016 06:21:11.732877       1 log.go:194] falcon-pod-d03 in Prefilter
I1016 06:21:11.732914       1 log.go:194] falcon-pod-d03 requires 4 gpu(s), and currently has 4 gpus(s) in total
I1016 06:21:11.740844       1 log.go:194] css-host-128 has 2 gpu, falcon-pod-d03 requires 4 gpu -> score: -2
I1016 06:21:11.740887       1 log.go:194] css-host-129 has 2 gpu, falcon-pod-d03 requires 4 gpu -> score: -2
I1016 06:21:11.753863       1 event.go:307] "Event occurred" object="default/falcon-pod-d03" fieldPath="" kind="Pod" apiVersion="v1" type="Normal" reason="Reconfig" message="Pod falcon-pod-d03 needs reconfiguration"
I1016 06:22:09.740885       1 schedule_one.go:252] "Successfully bound pod to node" pod="default/falcon-pod-d03" node="css-host-129" evaluatedNodes=2 feasibleNodes=2
I1016 06:22:25.413178       1 log.go:194] falcon-pod-a05 in Prefilter
I1016 06:22:25.413221       1 log.go:194] falcon-pod-a05 requires 1 gpu(s), and currently has 0 gpus(s) in total
I1016 06:22:25.420647       1 schedule_one.go:867] "Unable to schedule pod; no fit; waiting" pod="default/falcon-pod-a05" err="0/2 nodes are available: falcon-pod-a05 requires 1 gpu but only 0 gpu in the pool.. preemption: 0/2 nodes are available: 2 No preemption victims found for incoming pod.."
E1016 06:22:25.420721       1 schedule_one.go:902] "Error occurred" err="Pod default/falcon-pod-a05 is already present in the active queue"
I1016 06:22:25.426808       1 log.go:194] falcon-pod-a05 in Prefilter
I1016 06:22:25.426845       1 log.go:194] falcon-pod-a05 requires 1 gpu(s), and currently has 0 gpus(s) in total
I1016 06:22:25.433347       1 schedule_one.go:867] "Unable to schedule pod; no fit; waiting" pod="default/falcon-pod-a05" err="0/2 nodes are available: falcon-pod-a05 requires 1 gpu but only 0 gpu in the pool.. preemption: 0/2 nodes are available: 2 No preemption victims found for incoming pod.."
I1016 06:26:15.494178       1 log.go:194] falcon-pod-a05 in Prefilter
I1016 06:26:15.494219       1 log.go:194] falcon-pod-a05 requires 1 gpu(s), and currently has 4 gpus(s) in total
I1016 06:26:15.502325       1 log.go:194] css-host-128 has 4 gpu, falcon-pod-a05 requires 1 gpu -> score: 25
I1016 06:26:15.502405       1 log.go:194] css-host-129 has 0 gpu, falcon-pod-a05 requires 1 gpu -> score: -1
I1016 06:26:15.511633       1 schedule_one.go:252] "Successfully bound pod to node" pod="default/falcon-pod-a05" node="css-host-128" evaluatedNodes=2 feasibleNodes=2
I1016 06:26:30.547875       1 log.go:194] falcon-pod-d01 in Prefilter
I1016 06:26:30.547908       1 log.go:194] falcon-pod-d01 requires 4 gpu(s), and currently has 3 gpus(s) in total
I1016 06:26:30.554884       1 schedule_one.go:867] "Unable to schedule pod; no fit; waiting" pod="default/falcon-pod-d01" err="0/2 nodes are available: falcon-pod-d01 requires 4 gpu but only 3 gpu in the pool.. preemption: 0/2 nodes are available: 2 No preemption victims found for incoming pod.."
E1016 06:26:30.555073       1 schedule_one.go:902] "Error occurred" err="Pod default/falcon-pod-d01 is already present in the active queue"
I1016 06:26:30.561516       1 log.go:194] falcon-pod-d01 in Prefilter
I1016 06:26:30.561540       1 log.go:194] falcon-pod-d01 requires 4 gpu(s), and currently has 3 gpus(s) in total
I1016 06:26:30.567018       1 schedule_one.go:867] "Unable to schedule pod; no fit; waiting" pod="default/falcon-pod-d01" err="0/2 nodes are available: falcon-pod-d01 requires 4 gpu but only 3 gpu in the pool.. preemption: 0/2 nodes are available: 2 No preemption victims found for incoming pod.."
E1016 06:26:30.567083       1 schedule_one.go:902] "Error occurred" err="Pod default/falcon-pod-d01 is already present in the active queue"
I1016 06:26:30.571910       1 log.go:194] falcon-pod-d01 in Prefilter
I1016 06:26:30.571937       1 log.go:194] falcon-pod-d01 requires 4 gpu(s), and currently has 3 gpus(s) in total
I1016 06:26:30.575997       1 schedule_one.go:867] "Unable to schedule pod; no fit; waiting" pod="default/falcon-pod-d01" err="0/2 nodes are available: falcon-pod-d01 requires 4 gpu but only 3 gpu in the pool.. preemption: 0/2 nodes are available: 2 No preemption victims found for incoming pod.."
I1016 06:27:29.024299       1 log.go:194] falcon-pod-d01 in Prefilter
I1016 06:27:29.024335       1 log.go:194] falcon-pod-d01 requires 4 gpu(s), and currently has 7 gpus(s) in total
I1016 06:27:29.031971       1 log.go:194] css-host-128 has 3 gpu, falcon-pod-d01 requires 4 gpu -> score: -1
I1016 06:27:29.032018       1 log.go:194] css-host-129 has 4 gpu, falcon-pod-d01 requires 4 gpu -> score: 100
I1016 06:27:29.039514       1 schedule_one.go:252] "Successfully bound pod to node" pod="default/falcon-pod-d01" node="css-host-129" evaluatedNodes=2 feasibleNodes=2
I1016 06:27:44.279069       1 log.go:194] falcon-pod-a03 in Prefilter
I1016 06:27:44.279094       1 log.go:194] falcon-pod-a03 requires 1 gpu(s), and currently has 3 gpus(s) in total
I1016 06:27:44.283198       1 log.go:194] css-host-129 has 0 gpu, falcon-pod-a03 requires 1 gpu -> score: -1
I1016 06:27:44.283231       1 log.go:194] css-host-128 has 3 gpu, falcon-pod-a03 requires 1 gpu -> score: 33
I1016 06:27:44.291642       1 schedule_one.go:252] "Successfully bound pod to node" pod="default/falcon-pod-a03" node="css-host-128" evaluatedNodes=2 feasibleNodes=2
I1016 06:27:55.653830       1 log.go:194] falcon-pod-a02 in Prefilter
I1016 06:27:55.653857       1 log.go:194] falcon-pod-a02 requires 1 gpu(s), and currently has 2 gpus(s) in total
I1016 06:27:55.670997       1 event.go:307] "Event occurred" object="default/falcon-pod-a02" fieldPath="" kind="Pod" apiVersion="v1" type="Normal" reason="Reconfig" message="Pod falcon-pod-a02 needs reconfiguration"
I1016 06:28:28.061310       1 schedule_one.go:252] "Successfully bound pod to node" pod="default/falcon-pod-a02" node="css-host-129" evaluatedNodes=2 feasibleNodes=1
I1016 06:28:34.367390       1 log.go:194] falcon-pod-c03 in Prefilter
I1016 06:28:34.367417       1 log.go:194] falcon-pod-c03 requires 2 gpu(s), and currently has 1 gpus(s) in total
I1016 06:28:34.370903       1 schedule_one.go:867] "Unable to schedule pod; no fit; waiting" pod="default/falcon-pod-c03" err="0/2 nodes are available: falcon-pod-c03 requires 2 gpu but only 1 gpu in the pool.. preemption: 0/2 nodes are available: 2 No preemption victims found for incoming pod.."
E1016 06:28:34.370963       1 schedule_one.go:902] "Error occurred" err="Pod default/falcon-pod-c03 is already present in the active queue"
I1016 06:28:34.380076       1 log.go:194] falcon-pod-c03 in Prefilter
I1016 06:28:34.380136       1 log.go:194] falcon-pod-c03 requires 2 gpu(s), and currently has 1 gpus(s) in total
I1016 06:28:34.390763       1 schedule_one.go:867] "Unable to schedule pod; no fit; waiting" pod="default/falcon-pod-c03" err="0/2 nodes are available: falcon-pod-c03 requires 2 gpu but only 1 gpu in the pool.. preemption: 0/2 nodes are available: 2 No preemption victims found for incoming pod.."
E1016 06:28:34.390895       1 schedule_one.go:902] "Error occurred" err="Pod default/falcon-pod-c03 is already present in the active queue"
I1016 06:28:34.404906       1 log.go:194] falcon-pod-c03 in Prefilter
I1016 06:28:34.404934       1 log.go:194] falcon-pod-c03 requires 2 gpu(s), and currently has 1 gpus(s) in total
I1016 06:28:34.410685       1 schedule_one.go:867] "Unable to schedule pod; no fit; waiting" pod="default/falcon-pod-c03" err="0/2 nodes are available: falcon-pod-c03 requires 2 gpu but only 1 gpu in the pool.. preemption: 0/2 nodes are available: 2 No preemption victims found for incoming pod.."
I1016 06:31:31.025007       1 log.go:194] falcon-pod-c03 in Prefilter
I1016 06:31:31.025033       1 log.go:194] falcon-pod-c03 requires 2 gpu(s), and currently has 2 gpus(s) in total
I1016 06:31:31.032323       1 log.go:194] css-host-128 has 2 gpu, falcon-pod-c03 requires 2 gpu -> score: 100
I1016 06:31:31.032451       1 log.go:194] css-host-129 has 0 gpu, falcon-pod-c03 requires 2 gpu -> score: -2
I1016 06:31:31.039929       1 schedule_one.go:252] "Successfully bound pod to node" pod="default/falcon-pod-c03" node="css-host-128" evaluatedNodes=2 feasibleNodes=2
I1016 06:31:39.894266       1 log.go:194] falcon-pod-b01 in Prefilter
I1016 06:31:39.894319       1 log.go:194] falcon-pod-b01 requires 1 gpu(s), and currently has 0 gpus(s) in total
I1016 06:31:39.900787       1 schedule_one.go:867] "Unable to schedule pod; no fit; waiting" pod="default/falcon-pod-b01" err="0/2 nodes are available: falcon-pod-b01 requires 1 gpu but only 0 gpu in the pool.. preemption: 0/2 nodes are available: 2 No preemption victims found for incoming pod.."
E1016 06:31:39.900870       1 schedule_one.go:902] "Error occurred" err="Pod default/falcon-pod-b01 is already present in the active queue"
I1016 06:31:39.909670       1 log.go:194] falcon-pod-b01 in Prefilter
I1016 06:31:39.909697       1 log.go:194] falcon-pod-b01 requires 1 gpu(s), and currently has 0 gpus(s) in total
I1016 06:31:39.915424       1 schedule_one.go:867] "Unable to schedule pod; no fit; waiting" pod="default/falcon-pod-b01" err="0/2 nodes are available: falcon-pod-b01 requires 1 gpu but only 0 gpu in the pool.. preemption: 0/2 nodes are available: 2 No preemption victims found for incoming pod.."
E1016 06:31:39.915511       1 schedule_one.go:902] "Error occurred" err="Pod default/falcon-pod-b01 is already present in the active queue"
I1016 06:31:39.920936       1 log.go:194] falcon-pod-b01 in Prefilter
I1016 06:31:39.920954       1 log.go:194] falcon-pod-b01 requires 1 gpu(s), and currently has 0 gpus(s) in total
I1016 06:31:39.926677       1 schedule_one.go:867] "Unable to schedule pod; no fit; waiting" pod="default/falcon-pod-b01" err="0/2 nodes are available: falcon-pod-b01 requires 1 gpu but only 0 gpu in the pool.. preemption: 0/2 nodes are available: 2 No preemption victims found for incoming pod.."
I1016 06:32:47.812122       1 log.go:194] falcon-pod-b01 in Prefilter
I1016 06:32:47.812153       1 log.go:194] falcon-pod-b01 requires 1 gpu(s), and currently has 4 gpus(s) in total
I1016 06:32:47.818958       1 log.go:194] css-host-128 has 0 gpu, falcon-pod-b01 requires 1 gpu -> score: -1
I1016 06:32:47.819000       1 log.go:194] css-host-129 has 4 gpu, falcon-pod-b01 requires 1 gpu -> score: 25
I1016 06:32:47.826290       1 schedule_one.go:252] "Successfully bound pod to node" pod="default/falcon-pod-b01" node="css-host-129" evaluatedNodes=2 feasibleNodes=2
I1016 06:33:02.552977       1 log.go:194] falcon-pod-c04 in Prefilter
I1016 06:33:02.553022       1 log.go:194] falcon-pod-c04 requires 2 gpu(s), and currently has 4 gpus(s) in total
I1016 06:33:02.559816       1 log.go:194] css-host-128 has 1 gpu, falcon-pod-c04 requires 2 gpu -> score: -1
I1016 06:33:02.559868       1 log.go:194] css-host-129 has 3 gpu, falcon-pod-c04 requires 2 gpu -> score: 66
I1016 06:33:02.569520       1 schedule_one.go:252] "Successfully bound pod to node" pod="default/falcon-pod-c04" node="css-host-129" evaluatedNodes=2 feasibleNodes=2
I1016 06:33:13.982684       1 log.go:194] falcon-pod-b02 in Prefilter
I1016 06:33:13.982721       1 log.go:194] falcon-pod-b02 requires 1 gpu(s), and currently has 2 gpus(s) in total
I1016 06:33:13.996938       1 schedule_one.go:252] "Successfully bound pod to node" pod="default/falcon-pod-b02" node="css-host-128" evaluatedNodes=2 feasibleNodes=1
I1016 06:33:21.002466       1 log.go:194] falcon-pod-b05 in Prefilter
I1016 06:33:21.002497       1 log.go:194] falcon-pod-b05 requires 1 gpu(s), and currently has 1 gpus(s) in total
I1016 06:33:21.018420       1 event.go:307] "Event occurred" object="default/falcon-pod-b05" fieldPath="" kind="Pod" apiVersion="v1" type="Normal" reason="Reconfig" message="Pod falcon-pod-b05 needs reconfiguration"
I1016 06:33:55.610718       1 schedule_one.go:252] "Successfully bound pod to node" pod="default/falcon-pod-b05" node="css-host-128" evaluatedNodes=2 feasibleNodes=1
I1016 06:34:02.040376       1 log.go:194] falcon-pod-b04 in Prefilter
I1016 06:34:02.040406       1 log.go:194] falcon-pod-b04 requires 1 gpu(s), and currently has 1 gpus(s) in total
I1016 06:34:02.046563       1 log.go:194] css-host-128 has 0 gpu, falcon-pod-b04 requires 1 gpu -> score: -1
I1016 06:34:02.046606       1 log.go:194] css-host-129 has 1 gpu, falcon-pod-b04 requires 1 gpu -> score: 100
I1016 06:34:02.053095       1 schedule_one.go:252] "Successfully bound pod to node" pod="default/falcon-pod-b04" node="css-host-129" evaluatedNodes=2 feasibleNodes=2
I1016 06:34:09.063221       1 log.go:194] falcon-pod-c05 in Prefilter
I1016 06:34:09.063253       1 log.go:194] falcon-pod-c05 requires 2 gpu(s), and currently has 0 gpus(s) in total
I1016 06:34:09.070703       1 schedule_one.go:867] "Unable to schedule pod; no fit; waiting" pod="default/falcon-pod-c05" err="0/2 nodes are available: falcon-pod-c05 requires 2 gpu but only 0 gpu in the pool.. preemption: 0/2 nodes are available: 2 No preemption victims found for incoming pod.."
E1016 06:34:09.070788       1 schedule_one.go:902] "Error occurred" err="Pod default/falcon-pod-c05 is already present in the active queue"
I1016 06:34:09.076765       1 log.go:194] falcon-pod-c05 in Prefilter
I1016 06:34:09.076792       1 log.go:194] falcon-pod-c05 requires 2 gpu(s), and currently has 0 gpus(s) in total
I1016 06:34:09.082231       1 schedule_one.go:867] "Unable to schedule pod; no fit; waiting" pod="default/falcon-pod-c05" err="0/2 nodes are available: falcon-pod-c05 requires 2 gpu but only 0 gpu in the pool.. preemption: 0/2 nodes are available: 2 No preemption victims found for incoming pod.."
I1016 06:36:41.878943       1 log.go:194] falcon-pod-c05 in Prefilter
I1016 06:36:41.878973       1 log.go:194] falcon-pod-c05 requires 2 gpu(s), and currently has 2 gpus(s) in total
I1016 06:36:41.886407       1 log.go:194] css-host-128 has 2 gpu, falcon-pod-c05 requires 2 gpu -> score: 100
I1016 06:36:41.886447       1 log.go:194] css-host-129 has 0 gpu, falcon-pod-c05 requires 2 gpu -> score: -2
I1016 06:36:41.893807       1 schedule_one.go:252] "Successfully bound pod to node" pod="default/falcon-pod-c05" node="css-host-128" evaluatedNodes=2 feasibleNodes=2
I1016 06:43:34.389252       1 log.go:194] falcon-pod-b02 in Prefilter
I1016 06:43:34.389283       1 log.go:194] falcon-pod-b02 requires 1 gpu(s), and currently has 8 gpus(s) in total
I1016 06:43:34.395781       1 log.go:194] css-host-128 has 4 gpu, falcon-pod-b02 requires 1 gpu -> score: 25
I1016 06:43:34.395826       1 log.go:194] css-host-129 has 4 gpu, falcon-pod-b02 requires 1 gpu -> score: 25
I1016 06:43:34.402495       1 schedule_one.go:252] "Successfully bound pod to node" pod="default/falcon-pod-b02" node="css-host-129" evaluatedNodes=2 feasibleNodes=2
I1016 06:44:19.427705       1 log.go:194] falcon-pod-c03 in Prefilter
I1016 06:44:19.427738       1 log.go:194] falcon-pod-c03 requires 2 gpu(s), and currently has 7 gpus(s) in total
I1016 06:44:19.435707       1 log.go:194] css-host-128 has 4 gpu, falcon-pod-c03 requires 2 gpu -> score: 50
I1016 06:44:19.435754       1 log.go:194] css-host-129 has 3 gpu, falcon-pod-c03 requires 2 gpu -> score: 66
I1016 06:44:19.447286       1 schedule_one.go:252] "Successfully bound pod to node" pod="default/falcon-pod-c03" node="css-host-129" evaluatedNodes=2 feasibleNodes=2
I1016 06:45:17.508041       1 log.go:194] falcon-pod-c06 in Prefilter
I1016 06:45:17.508079       1 log.go:194] falcon-pod-c06 requires 2 gpu(s), and currently has 5 gpus(s) in total
I1016 06:45:17.514219       1 log.go:194] css-host-129 has 1 gpu, falcon-pod-c06 requires 2 gpu -> score: -1
I1016 06:45:17.514255       1 log.go:194] css-host-128 has 4 gpu, falcon-pod-c06 requires 2 gpu -> score: 50
I1016 06:45:17.520489       1 schedule_one.go:252] "Successfully bound pod to node" pod="default/falcon-pod-c06" node="css-host-128" evaluatedNodes=2 feasibleNodes=2
I1016 06:46:14.515821       1 log.go:194] falcon-pod-c08 in Prefilter
I1016 06:46:14.515862       1 log.go:194] falcon-pod-c08 requires 2 gpu(s), and currently has 3 gpus(s) in total
I1016 06:46:14.523177       1 log.go:194] css-host-128 has 2 gpu, falcon-pod-c08 requires 2 gpu -> score: 100
I1016 06:46:14.523217       1 log.go:194] css-host-129 has 1 gpu, falcon-pod-c08 requires 2 gpu -> score: -1
I1016 06:46:14.530653       1 schedule_one.go:252] "Successfully bound pod to node" pod="default/falcon-pod-c08" node="css-host-128" evaluatedNodes=2 feasibleNodes=2
I1016 06:47:21.580718       1 log.go:194] falcon-pod-b03 in Prefilter
I1016 06:47:21.580766       1 log.go:194] falcon-pod-b03 requires 1 gpu(s), and currently has 1 gpus(s) in total
I1016 06:47:21.588158       1 log.go:194] css-host-128 has 0 gpu, falcon-pod-b03 requires 1 gpu -> score: -1
I1016 06:47:21.588267       1 log.go:194] css-host-129 has 1 gpu, falcon-pod-b03 requires 1 gpu -> score: 100
I1016 06:47:21.596631       1 schedule_one.go:252] "Successfully bound pod to node" pod="default/falcon-pod-b03" node="css-host-129" evaluatedNodes=2 feasibleNodes=2
I1016 06:48:02.614107       1 log.go:194] falcon-pod-a01 in Prefilter
I1016 06:48:02.614143       1 log.go:194] falcon-pod-a01 requires 1 gpu(s), and currently has 0 gpus(s) in total
I1016 06:48:02.620667       1 schedule_one.go:867] "Unable to schedule pod; no fit; waiting" pod="default/falcon-pod-a01" err="0/2 nodes are available: falcon-pod-a01 requires 1 gpu but only 0 gpu in the pool.. preemption: 0/2 nodes are available: 2 No preemption victims found for incoming pod.."
E1016 06:48:02.620792       1 schedule_one.go:902] "Error occurred" err="Pod default/falcon-pod-a01 is already present in the active queue"
I1016 06:48:02.627092       1 log.go:194] falcon-pod-a01 in Prefilter
I1016 06:48:02.627117       1 log.go:194] falcon-pod-a01 requires 1 gpu(s), and currently has 0 gpus(s) in total
I1016 06:48:02.632374       1 schedule_one.go:867] "Unable to schedule pod; no fit; waiting" pod="default/falcon-pod-a01" err="0/2 nodes are available: falcon-pod-a01 requires 1 gpu but only 0 gpu in the pool.. preemption: 0/2 nodes are available: 2 No preemption victims found for incoming pod.."
I1016 06:48:50.285961       1 log.go:194] falcon-pod-a01 in Prefilter
I1016 06:48:50.285995       1 log.go:194] falcon-pod-a01 requires 1 gpu(s), and currently has 1 gpus(s) in total
I1016 06:48:50.293712       1 log.go:194] css-host-128 has 0 gpu, falcon-pod-a01 requires 1 gpu -> score: -1
I1016 06:48:50.293758       1 log.go:194] css-host-129 has 1 gpu, falcon-pod-a01 requires 1 gpu -> score: 100
I1016 06:48:50.301833       1 schedule_one.go:252] "Successfully bound pod to node" pod="default/falcon-pod-a01" node="css-host-129" evaluatedNodes=2 feasibleNodes=2
I1016 06:49:05.669482       1 log.go:194] falcon-pod-b05 in Prefilter
I1016 06:49:05.669514       1 log.go:194] falcon-pod-b05 requires 1 gpu(s), and currently has 0 gpus(s) in total
I1016 06:49:05.676544       1 schedule_one.go:867] "Unable to schedule pod; no fit; waiting" pod="default/falcon-pod-b05" err="0/2 nodes are available: falcon-pod-b05 requires 1 gpu but only 0 gpu in the pool.. preemption: 0/2 nodes are available: 2 No preemption victims found for incoming pod.."
E1016 06:49:05.676624       1 schedule_one.go:902] "Error occurred" err="Pod default/falcon-pod-b05 is already present in the active queue"
I1016 06:49:05.682188       1 log.go:194] falcon-pod-b05 in Prefilter
I1016 06:49:05.682207       1 log.go:194] falcon-pod-b05 requires 1 gpu(s), and currently has 0 gpus(s) in total
I1016 06:49:05.686673       1 schedule_one.go:867] "Unable to schedule pod; no fit; waiting" pod="default/falcon-pod-b05" err="0/2 nodes are available: falcon-pod-b05 requires 1 gpu but only 0 gpu in the pool.. preemption: 0/2 nodes are available: 2 No preemption victims found for incoming pod.."
E1016 06:49:05.686733       1 schedule_one.go:902] "Error occurred" err="Pod default/falcon-pod-b05 is already present in the active queue"
I1016 06:49:05.692066       1 log.go:194] falcon-pod-b05 in Prefilter
I1016 06:49:05.692083       1 log.go:194] falcon-pod-b05 requires 1 gpu(s), and currently has 0 gpus(s) in total
I1016 06:49:05.696908       1 schedule_one.go:867] "Unable to schedule pod; no fit; waiting" pod="default/falcon-pod-b05" err="0/2 nodes are available: falcon-pod-b05 requires 1 gpu but only 0 gpu in the pool.. preemption: 0/2 nodes are available: 2 No preemption victims found for incoming pod.."
I1016 06:49:33.389231       1 log.go:194] falcon-pod-b05 in Prefilter
I1016 06:49:33.389263       1 log.go:194] falcon-pod-b05 requires 1 gpu(s), and currently has 2 gpus(s) in total
I1016 06:49:33.396224       1 log.go:194] css-host-128 has 0 gpu, falcon-pod-b05 requires 1 gpu -> score: -1
I1016 06:49:33.396259       1 log.go:194] css-host-129 has 2 gpu, falcon-pod-b05 requires 1 gpu -> score: 50
I1016 06:49:33.403543       1 schedule_one.go:252] "Successfully bound pod to node" pod="default/falcon-pod-b05" node="css-host-129" evaluatedNodes=2 feasibleNodes=2
I1016 06:50:17.748133       1 log.go:194] falcon-pod-a05 in Prefilter
I1016 06:50:17.748169       1 log.go:194] falcon-pod-a05 requires 1 gpu(s), and currently has 1 gpus(s) in total
I1016 06:50:17.766373       1 event.go:307] "Event occurred" object="default/falcon-pod-a05" fieldPath="" kind="Pod" apiVersion="v1" type="Normal" reason="Reconfig" message="Pod falcon-pod-a05 needs reconfiguration"
E1016 06:50:57.952548       1 schedule_one.go:883] "Error scheduling pod; retrying" err="" pod="default/falcon-pod-a05"
E1016 06:50:57.952631       1 schedule_one.go:902] "Error occurred" err="Pod default/falcon-pod-a05 is already present in the active queue"
I1016 06:50:57.959103       1 log.go:194] falcon-pod-a05 in Prefilter
I1016 06:50:57.959130       1 log.go:194] falcon-pod-a05 requires 1 gpu(s), and currently has 2 gpus(s) in total
I1016 06:50:58.154883       1 trace.go:219] Trace[690656317]: "Scheduling" namespace:default,name:falcon-pod-a05 (16-Oct-2023 06:50:57.958) (total time: 195ms):
Trace[690656317]: ---"Computing predicates done" 195ms (06:50:58.154)
Trace[690656317]: [195.844017ms] [195.844017ms] END
I1016 06:50:58.357174       1 schedule_one.go:252] "Successfully bound pod to node" pod="default/falcon-pod-a05" node="css-host-128" evaluatedNodes=2 feasibleNodes=1
I1016 06:51:21.828217       1 log.go:194] falcon-pod-c01 in Prefilter
I1016 06:51:21.828243       1 log.go:194] falcon-pod-c01 requires 2 gpu(s), and currently has 2 gpus(s) in total
I1016 06:51:21.842066       1 schedule_one.go:252] "Successfully bound pod to node" pod="default/falcon-pod-c01" node="css-host-128" evaluatedNodes=2 feasibleNodes=1
I1016 06:52:11.877721       1 log.go:194] falcon-pod-c02 in Prefilter
I1016 06:52:11.877751       1 log.go:194] falcon-pod-c02 requires 2 gpu(s), and currently has 2 gpus(s) in total
I1016 06:52:11.891285       1 schedule_one.go:252] "Successfully bound pod to node" pod="default/falcon-pod-c02" node="css-host-128" evaluatedNodes=2 feasibleNodes=1
I1016 06:53:04.934489       1 log.go:194] falcon-pod-a04 in Prefilter
I1016 06:53:04.934524       1 log.go:194] falcon-pod-a04 requires 1 gpu(s), and currently has 1 gpus(s) in total
I1016 06:53:04.941220       1 schedule_one.go:867] "Unable to schedule pod; no fit; waiting" pod="default/falcon-pod-a04" err="0/2 nodes are available: 2 Insufficient cpu. preemption: 0/2 nodes are available: 2 No preemption victims found for incoming pod.."
E1016 06:53:04.941325       1 schedule_one.go:902] "Error occurred" err="Pod default/falcon-pod-a04 is already present in the active queue"
I1016 06:53:04.945977       1 log.go:194] falcon-pod-a04 in Prefilter
I1016 06:53:04.945998       1 log.go:194] falcon-pod-a04 requires 1 gpu(s), and currently has 1 gpus(s) in total
I1016 06:53:04.951369       1 schedule_one.go:867] "Unable to schedule pod; no fit; waiting" pod="default/falcon-pod-a04" err="0/2 nodes are available: 2 Insufficient cpu. preemption: 0/2 nodes are available: 2 No preemption victims found for incoming pod.."
E1016 06:53:04.951444       1 schedule_one.go:902] "Error occurred" err="Pod default/falcon-pod-a04 is already present in the active queue"
I1016 06:53:04.956137       1 log.go:194] falcon-pod-a04 in Prefilter
I1016 06:53:04.956158       1 log.go:194] falcon-pod-a04 requires 1 gpu(s), and currently has 1 gpus(s) in total
I1016 06:53:04.961133       1 schedule_one.go:867] "Unable to schedule pod; no fit; waiting" pod="default/falcon-pod-a04" err="0/2 nodes are available: 2 Insufficient cpu. preemption: 0/2 nodes are available: 2 No preemption victims found for incoming pod.."
I1016 06:53:58.459696       1 log.go:194] falcon-pod-a04 in Prefilter
I1016 06:53:58.459727       1 log.go:194] falcon-pod-a04 requires 1 gpu(s), and currently has 2 gpus(s) in total
I1016 06:53:58.473913       1 schedule_one.go:252] "Successfully bound pod to node" pod="default/falcon-pod-a04" node="css-host-129" evaluatedNodes=2 feasibleNodes=1
I1016 06:54:07.378634       1 log.go:194] falcon-pod-b04 in Prefilter
I1016 06:54:07.378666       1 log.go:194] falcon-pod-b04 requires 1 gpu(s), and currently has 1 gpus(s) in total
I1016 06:54:07.391754       1 schedule_one.go:252] "Successfully bound pod to node" pod="default/falcon-pod-b04" node="css-host-129" evaluatedNodes=2 feasibleNodes=1
I1016 06:55:11.068489       1 log.go:194] falcon-pod-c10 in Prefilter
I1016 06:55:11.068524       1 log.go:194] falcon-pod-c10 requires 2 gpu(s), and currently has 1 gpus(s) in total
I1016 06:55:11.075730       1 schedule_one.go:867] "Unable to schedule pod; no fit; waiting" pod="default/falcon-pod-c10" err="0/2 nodes are available: falcon-pod-c10 requires 2 gpu but only 1 gpu in the pool.. preemption: 0/2 nodes are available: 2 No preemption victims found for incoming pod.."
E1016 06:55:11.075829       1 schedule_one.go:902] "Error occurred" err="Pod default/falcon-pod-c10 is already present in the active queue"
I1016 06:55:11.081800       1 log.go:194] falcon-pod-c10 in Prefilter
I1016 06:55:11.081833       1 log.go:194] falcon-pod-c10 requires 2 gpu(s), and currently has 1 gpus(s) in total
I1016 06:55:11.088398       1 schedule_one.go:867] "Unable to schedule pod; no fit; waiting" pod="default/falcon-pod-c10" err="0/2 nodes are available: falcon-pod-c10 requires 2 gpu but only 1 gpu in the pool.. preemption: 0/2 nodes are available: 2 No preemption victims found for incoming pod.."
E1016 06:55:11.088473       1 schedule_one.go:902] "Error occurred" err="Pod default/falcon-pod-c10 is already present in the active queue"
I1016 06:55:11.093693       1 log.go:194] falcon-pod-c10 in Prefilter
I1016 06:55:11.093716       1 log.go:194] falcon-pod-c10 requires 2 gpu(s), and currently has 1 gpus(s) in total
I1016 06:55:11.099496       1 schedule_one.go:867] "Unable to schedule pod; no fit; waiting" pod="default/falcon-pod-c10" err="0/2 nodes are available: falcon-pod-c10 requires 2 gpu but only 1 gpu in the pool.. preemption: 0/2 nodes are available: 2 No preemption victims found for incoming pod.."
I1016 06:56:12.301642       1 log.go:194] falcon-pod-c10 in Prefilter
I1016 06:56:12.301672       1 log.go:194] falcon-pod-c10 requires 2 gpu(s), and currently has 2 gpus(s) in total
I1016 06:56:12.308926       1 log.go:194] css-host-128 has 1 gpu, falcon-pod-c10 requires 2 gpu -> score: -1
I1016 06:56:12.308964       1 log.go:194] css-host-129 has 1 gpu, falcon-pod-c10 requires 2 gpu -> score: -1
I1016 06:56:12.319246       1 event.go:307] "Event occurred" object="default/falcon-pod-c10" fieldPath="" kind="Pod" apiVersion="v1" type="Normal" reason="Reconfig" message="Pod falcon-pod-c10 needs reconfiguration"
E1016 06:56:52.506197       1 schedule_one.go:883] "Error scheduling pod; retrying" err="" pod="default/falcon-pod-c10"
I1016 06:56:55.096211       1 log.go:194] falcon-pod-c10 in Prefilter
I1016 06:56:55.096238       1 log.go:194] falcon-pod-c10 requires 2 gpu(s), and currently has 3 gpus(s) in total
I1016 06:56:55.102602       1 log.go:194] css-host-128 has 3 gpu, falcon-pod-c10 requires 2 gpu -> score: 66
I1016 06:56:55.102641       1 log.go:194] css-host-129 has 0 gpu, falcon-pod-c10 requires 2 gpu -> score: -2
I1016 06:56:55.111319       1 schedule_one.go:252] "Successfully bound pod to node" pod="default/falcon-pod-c10" node="css-host-128" evaluatedNodes=2 feasibleNodes=2
I1016 06:57:10.724959       1 log.go:194] falcon-pod-c05 in Prefilter
I1016 06:57:10.724989       1 log.go:194] falcon-pod-c05 requires 2 gpu(s), and currently has 2 gpus(s) in total
I1016 06:57:10.730168       1 log.go:194] css-host-128 has 2 gpu, falcon-pod-c05 requires 2 gpu -> score: 100
I1016 06:57:10.730208       1 log.go:194] css-host-129 has 0 gpu, falcon-pod-c05 requires 2 gpu -> score: -2
I1016 06:57:10.736595       1 schedule_one.go:252] "Successfully bound pod to node" pod="default/falcon-pod-c05" node="css-host-128" evaluatedNodes=2 feasibleNodes=2
I1016 06:57:26.284734       1 log.go:194] falcon-pod-b01 in Prefilter
I1016 06:57:26.284769       1 log.go:194] falcon-pod-b01 requires 1 gpu(s), and currently has 0 gpus(s) in total
I1016 06:57:26.290928       1 schedule_one.go:867] "Unable to schedule pod; no fit; waiting" pod="default/falcon-pod-b01" err="0/2 nodes are available: falcon-pod-b01 requires 1 gpu but only 0 gpu in the pool.. preemption: 0/2 nodes are available: 2 No preemption victims found for incoming pod.."
E1016 06:57:26.291013       1 schedule_one.go:902] "Error occurred" err="Pod default/falcon-pod-b01 is already present in the active queue"
I1016 06:57:26.297922       1 log.go:194] falcon-pod-b01 in Prefilter
I1016 06:57:26.297942       1 log.go:194] falcon-pod-b01 requires 1 gpu(s), and currently has 0 gpus(s) in total
I1016 06:57:26.302741       1 schedule_one.go:867] "Unable to schedule pod; no fit; waiting" pod="default/falcon-pod-b01" err="0/2 nodes are available: falcon-pod-b01 requires 1 gpu but only 0 gpu in the pool.. preemption: 0/2 nodes are available: 2 No preemption victims found for incoming pod.."
I1016 06:57:27.310987       1 log.go:194] falcon-pod-b01 in Prefilter
I1016 06:57:27.311008       1 log.go:194] falcon-pod-b01 requires 1 gpu(s), and currently has 2 gpus(s) in total
I1016 06:57:27.317911       1 log.go:194] css-host-128 has 2 gpu, falcon-pod-b01 requires 1 gpu -> score: 50
I1016 06:57:27.317973       1 log.go:194] css-host-129 has 0 gpu, falcon-pod-b01 requires 1 gpu -> score: -1
I1016 06:57:27.325252       1 schedule_one.go:252] "Successfully bound pod to node" pod="default/falcon-pod-b01" node="css-host-128" evaluatedNodes=2 feasibleNodes=2
I1016 06:58:27.230533       1 log.go:194] falcon-pod-c04 in Prefilter
I1016 06:58:27.230567       1 log.go:194] falcon-pod-c04 requires 2 gpu(s), and currently has 1 gpus(s) in total
I1016 06:58:27.236621       1 schedule_one.go:867] "Unable to schedule pod; no fit; waiting" pod="default/falcon-pod-c04" err="0/2 nodes are available: falcon-pod-c04 requires 2 gpu but only 1 gpu in the pool.. preemption: 0/2 nodes are available: 2 No preemption victims found for incoming pod.."
E1016 06:58:27.236690       1 schedule_one.go:902] "Error occurred" err="Pod default/falcon-pod-c04 is already present in the active queue"
I1016 06:58:27.242313       1 log.go:194] falcon-pod-c04 in Prefilter
I1016 06:58:27.242348       1 log.go:194] falcon-pod-c04 requires 2 gpu(s), and currently has 1 gpus(s) in total
I1016 06:58:27.248647       1 schedule_one.go:867] "Unable to schedule pod; no fit; waiting" pod="default/falcon-pod-c04" err="0/2 nodes are available: falcon-pod-c04 requires 2 gpu but only 1 gpu in the pool.. preemption: 0/2 nodes are available: 2 No preemption victims found for incoming pod.."
I1016 06:59:08.640218       1 log.go:194] falcon-pod-c04 in Prefilter
I1016 06:59:08.640257       1 log.go:194] falcon-pod-c04 requires 2 gpu(s), and currently has 2 gpus(s) in total
I1016 06:59:08.646814       1 log.go:194] css-host-128 has 1 gpu, falcon-pod-c04 requires 2 gpu -> score: -1
I1016 06:59:08.646860       1 log.go:194] css-host-129 has 1 gpu, falcon-pod-c04 requires 2 gpu -> score: -1
I1016 06:59:08.657085       1 event.go:307] "Event occurred" object="default/falcon-pod-c04" fieldPath="" kind="Pod" apiVersion="v1" type="Normal" reason="Reconfig" message="Pod falcon-pod-c04 needs reconfiguration"
E1016 06:59:48.844918       1 schedule_one.go:883] "Error scheduling pod; retrying" err="" pod="default/falcon-pod-c04"
I1016 06:59:51.191458       1 log.go:194] falcon-pod-c04 in Prefilter
I1016 06:59:51.191496       1 log.go:194] falcon-pod-c04 requires 2 gpu(s), and currently has 3 gpus(s) in total
I1016 06:59:51.198624       1 log.go:194] css-host-128 has 0 gpu, falcon-pod-c04 requires 2 gpu -> score: -2
I1016 06:59:51.198662       1 log.go:194] css-host-129 has 3 gpu, falcon-pod-c04 requires 2 gpu -> score: 66
I1016 06:59:51.206552       1 schedule_one.go:252] "Successfully bound pod to node" pod="default/falcon-pod-c04" node="css-host-129" evaluatedNodes=2 feasibleNodes=2
I1016 07:00:03.990898       1 log.go:194] falcon-pod-c09 in Prefilter
I1016 07:00:03.990933       1 log.go:194] falcon-pod-c09 requires 2 gpu(s), and currently has 1 gpus(s) in total
I1016 07:00:03.998659       1 schedule_one.go:867] "Unable to schedule pod; no fit; waiting" pod="default/falcon-pod-c09" err="0/2 nodes are available: falcon-pod-c09 requires 2 gpu but only 1 gpu in the pool.. preemption: 0/2 nodes are available: 2 No preemption victims found for incoming pod.."
E1016 07:00:03.998740       1 schedule_one.go:902] "Error occurred" err="Pod default/falcon-pod-c09 is already present in the active queue"
I1016 07:00:04.005079       1 log.go:194] falcon-pod-c09 in Prefilter
I1016 07:00:04.005107       1 log.go:194] falcon-pod-c09 requires 2 gpu(s), and currently has 1 gpus(s) in total
I1016 07:00:04.010849       1 schedule_one.go:867] "Unable to schedule pod; no fit; waiting" pod="default/falcon-pod-c09" err="0/2 nodes are available: falcon-pod-c09 requires 2 gpu but only 1 gpu in the pool.. preemption: 0/2 nodes are available: 2 No preemption victims found for incoming pod.."
E1016 07:00:04.010930       1 schedule_one.go:902] "Error occurred" err="Pod default/falcon-pod-c09 is already present in the active queue"
I1016 07:00:04.016457       1 log.go:194] falcon-pod-c09 in Prefilter
I1016 07:00:04.016477       1 log.go:194] falcon-pod-c09 requires 2 gpu(s), and currently has 1 gpus(s) in total
I1016 07:00:04.021960       1 schedule_one.go:867] "Unable to schedule pod; no fit; waiting" pod="default/falcon-pod-c09" err="0/2 nodes are available: falcon-pod-c09 requires 2 gpu but only 1 gpu in the pool.. preemption: 0/2 nodes are available: 2 No preemption victims found for incoming pod.."
E1016 07:00:04.022024       1 schedule_one.go:902] "Error occurred" err="Pod default/falcon-pod-c09 is already present in the active queue"
I1016 07:00:04.022128       1 log.go:194] falcon-pod-c09 in Prefilter
I1016 07:00:04.022143       1 log.go:194] falcon-pod-c09 requires 2 gpu(s), and currently has 1 gpus(s) in total
I1016 07:00:04.027210       1 schedule_one.go:867] "Unable to schedule pod; no fit; waiting" pod="default/falcon-pod-c09" err="0/2 nodes are available: falcon-pod-c09 requires 2 gpu but only 1 gpu in the pool.. preemption: 0/2 nodes are available: 2 No preemption victims found for incoming pod.."
I1016 07:02:12.588672       1 log.go:194] falcon-pod-c09 in Prefilter
I1016 07:02:12.588709       1 log.go:194] falcon-pod-c09 requires 2 gpu(s), and currently has 3 gpus(s) in total
I1016 07:02:12.595459       1 log.go:194] css-host-128 has 2 gpu, falcon-pod-c09 requires 2 gpu -> score: 100
I1016 07:02:12.595549       1 log.go:194] css-host-129 has 1 gpu, falcon-pod-c09 requires 2 gpu -> score: -1
I1016 07:02:12.602773       1 schedule_one.go:252] "Successfully bound pod to node" pod="default/falcon-pod-c09" node="css-host-128" evaluatedNodes=2 feasibleNodes=2
I1016 07:02:21.466776       1 log.go:194] falcon-pod-a02 in Prefilter
I1016 07:02:21.466807       1 log.go:194] falcon-pod-a02 requires 1 gpu(s), and currently has 1 gpus(s) in total
I1016 07:02:21.481340       1 schedule_one.go:252] "Successfully bound pod to node" pod="default/falcon-pod-a02" node="css-host-129" evaluatedNodes=2 feasibleNodes=1
I1016 07:02:28.512278       1 log.go:194] falcon-pod-c07 in Prefilter
I1016 07:02:28.512307       1 log.go:194] falcon-pod-c07 requires 2 gpu(s), and currently has 0 gpus(s) in total
I1016 07:02:28.519402       1 schedule_one.go:867] "Unable to schedule pod; no fit; waiting" pod="default/falcon-pod-c07" err="0/2 nodes are available: falcon-pod-c07 requires 2 gpu but only 0 gpu in the pool.. preemption: 0/2 nodes are available: 2 No preemption victims found for incoming pod.."
E1016 07:02:28.519525       1 schedule_one.go:902] "Error occurred" err="Pod default/falcon-pod-c07 is already present in the active queue"
I1016 07:02:28.526282       1 log.go:194] falcon-pod-c07 in Prefilter
I1016 07:02:28.526301       1 log.go:194] falcon-pod-c07 requires 2 gpu(s), and currently has 0 gpus(s) in total
I1016 07:02:28.546747       1 schedule_one.go:867] "Unable to schedule pod; no fit; waiting" pod="default/falcon-pod-c07" err="0/2 nodes are available: falcon-pod-c07 requires 2 gpu but only 0 gpu in the pool.. preemption: 0/2 nodes are available: 2 No preemption victims found for incoming pod.."
E1016 07:02:28.546819       1 schedule_one.go:902] "Error occurred" err="Pod default/falcon-pod-c07 is already present in the active queue"
I1016 07:02:28.555987       1 log.go:194] falcon-pod-c07 in Prefilter
I1016 07:02:28.556007       1 log.go:194] falcon-pod-c07 requires 2 gpu(s), and currently has 0 gpus(s) in total
I1016 07:02:28.560658       1 schedule_one.go:867] "Unable to schedule pod; no fit; waiting" pod="default/falcon-pod-c07" err="0/2 nodes are available: falcon-pod-c07 requires 2 gpu but only 0 gpu in the pool.. preemption: 0/2 nodes are available: 2 No preemption victims found for incoming pod.."
I1016 07:02:30.278249       1 log.go:194] falcon-pod-c07 in Prefilter
I1016 07:02:30.278276       1 log.go:194] falcon-pod-c07 requires 2 gpu(s), and currently has 2 gpus(s) in total
I1016 07:02:30.284648       1 log.go:194] css-host-128 has 2 gpu, falcon-pod-c07 requires 2 gpu -> score: 100
I1016 07:02:30.284670       1 log.go:194] css-host-129 has 0 gpu, falcon-pod-c07 requires 2 gpu -> score: -2
I1016 07:02:30.292881       1 schedule_one.go:252] "Successfully bound pod to node" pod="default/falcon-pod-c07" node="css-host-128" evaluatedNodes=2 feasibleNodes=2
I1016 07:02:40.151593       1 log.go:194] falcon-pod-a03 in Prefilter
I1016 07:02:40.151629       1 log.go:194] falcon-pod-a03 requires 1 gpu(s), and currently has 0 gpus(s) in total
I1016 07:02:40.158603       1 schedule_one.go:867] "Unable to schedule pod; no fit; waiting" pod="default/falcon-pod-a03" err="0/2 nodes are available: falcon-pod-a03 requires 1 gpu but only 0 gpu in the pool.. preemption: 0/2 nodes are available: 2 No preemption victims found for incoming pod.."
E1016 07:02:40.158682       1 schedule_one.go:902] "Error occurred" err="Pod default/falcon-pod-a03 is already present in the active queue"
I1016 07:02:40.163968       1 log.go:194] falcon-pod-a03 in Prefilter
I1016 07:02:40.163998       1 log.go:194] falcon-pod-a03 requires 1 gpu(s), and currently has 0 gpus(s) in total
I1016 07:02:40.169694       1 schedule_one.go:867] "Unable to schedule pod; no fit; waiting" pod="default/falcon-pod-a03" err="0/2 nodes are available: falcon-pod-a03 requires 1 gpu but only 0 gpu in the pool.. preemption: 0/2 nodes are available: 2 No preemption victims found for incoming pod.."
E1016 07:02:40.169782       1 schedule_one.go:902] "Error occurred" err="Pod default/falcon-pod-a03 is already present in the active queue"
I1016 07:02:40.174560       1 log.go:194] falcon-pod-a03 in Prefilter
I1016 07:02:40.174578       1 log.go:194] falcon-pod-a03 requires 1 gpu(s), and currently has 0 gpus(s) in total
I1016 07:02:40.179664       1 schedule_one.go:867] "Unable to schedule pod; no fit; waiting" pod="default/falcon-pod-a03" err="0/2 nodes are available: falcon-pod-a03 requires 1 gpu but only 0 gpu in the pool.. preemption: 0/2 nodes are available: 2 No preemption victims found for incoming pod.."
I1016 07:02:41.288180       1 log.go:194] falcon-pod-a03 in Prefilter
I1016 07:02:41.288212       1 log.go:194] falcon-pod-a03 requires 1 gpu(s), and currently has 1 gpus(s) in total
I1016 07:02:41.301676       1 schedule_one.go:252] "Successfully bound pod to node" pod="default/falcon-pod-a03" node="css-host-128" evaluatedNodes=2 feasibleNodes=1
I1016 07:10:40.641944       1 log.go:194] falcon-pod-b08 in Prefilter
I1016 07:10:40.641973       1 log.go:194] falcon-pod-b08 requires 1 gpu(s), and currently has 8 gpus(s) in total
I1016 07:10:40.649643       1 log.go:194] css-host-129 has 3 gpu, falcon-pod-b08 requires 1 gpu -> score: 33
I1016 07:10:40.649683       1 log.go:194] css-host-128 has 5 gpu, falcon-pod-b08 requires 1 gpu -> score: 20
I1016 07:10:40.659259       1 schedule_one.go:252] "Successfully bound pod to node" pod="default/falcon-pod-b08" node="css-host-129" evaluatedNodes=2 feasibleNodes=2
I1016 07:11:28.692035       1 log.go:194] falcon-pod-b10 in Prefilter
I1016 07:11:28.692076       1 log.go:194] falcon-pod-b10 requires 1 gpu(s), and currently has 7 gpus(s) in total
I1016 07:11:28.700121       1 log.go:194] css-host-128 has 5 gpu, falcon-pod-b10 requires 1 gpu -> score: 20
I1016 07:11:28.700152       1 log.go:194] css-host-129 has 2 gpu, falcon-pod-b10 requires 1 gpu -> score: 50
I1016 07:11:28.706673       1 schedule_one.go:252] "Successfully bound pod to node" pod="default/falcon-pod-b10" node="css-host-129" evaluatedNodes=2 feasibleNodes=2
I1016 07:12:26.745680       1 log.go:194] falcon-pod-b09 in Prefilter
I1016 07:12:26.745720       1 log.go:194] falcon-pod-b09 requires 1 gpu(s), and currently has 6 gpus(s) in total
I1016 07:12:26.753129       1 log.go:194] css-host-128 has 5 gpu, falcon-pod-b09 requires 1 gpu -> score: 20
I1016 07:12:26.753167       1 log.go:194] css-host-129 has 1 gpu, falcon-pod-b09 requires 1 gpu -> score: 100
I1016 07:12:26.761710       1 schedule_one.go:252] "Successfully bound pod to node" pod="default/falcon-pod-b09" node="css-host-129" evaluatedNodes=2 feasibleNodes=2
I1016 07:13:32.822479       1 log.go:194] falcon-pod-a08 in Prefilter
I1016 07:13:32.822508       1 log.go:194] falcon-pod-a08 requires 1 gpu(s), and currently has 5 gpus(s) in total
I1016 07:13:32.834986       1 schedule_one.go:252] "Successfully bound pod to node" pod="default/falcon-pod-a08" node="css-host-128" evaluatedNodes=2 feasibleNodes=1
I1016 07:14:50.897338       1 log.go:194] falcon-pod-a02 in Prefilter
I1016 07:14:50.897386       1 log.go:194] falcon-pod-a02 requires 1 gpu(s), and currently has 4 gpus(s) in total
I1016 07:14:50.911108       1 schedule_one.go:252] "Successfully bound pod to node" pod="default/falcon-pod-a02" node="css-host-128" evaluatedNodes=2 feasibleNodes=1
I1016 07:15:44.941689       1 log.go:194] falcon-pod-a04 in Prefilter
I1016 07:15:44.941726       1 log.go:194] falcon-pod-a04 requires 1 gpu(s), and currently has 3 gpus(s) in total
I1016 07:15:44.949374       1 schedule_one.go:867] "Unable to schedule pod; no fit; waiting" pod="default/falcon-pod-a04" err="0/2 nodes are available: 2 Insufficient cpu. preemption: 0/2 nodes are available: 2 No preemption victims found for incoming pod.."
E1016 07:15:44.949486       1 schedule_one.go:902] "Error occurred" err="Pod default/falcon-pod-a04 is already present in the active queue"
I1016 07:15:44.954712       1 log.go:194] falcon-pod-a04 in Prefilter
I1016 07:15:44.954730       1 log.go:194] falcon-pod-a04 requires 1 gpu(s), and currently has 3 gpus(s) in total
I1016 07:15:44.960570       1 schedule_one.go:867] "Unable to schedule pod; no fit; waiting" pod="default/falcon-pod-a04" err="0/2 nodes are available: 2 Insufficient cpu. preemption: 0/2 nodes are available: 2 No preemption victims found for incoming pod.."
E1016 07:15:44.960638       1 schedule_one.go:902] "Error occurred" err="Pod default/falcon-pod-a04 is already present in the active queue"
I1016 07:15:44.966511       1 log.go:194] falcon-pod-a04 in Prefilter
I1016 07:15:44.966536       1 log.go:194] falcon-pod-a04 requires 1 gpu(s), and currently has 3 gpus(s) in total
I1016 07:15:44.972201       1 schedule_one.go:867] "Unable to schedule pod; no fit; waiting" pod="default/falcon-pod-a04" err="0/2 nodes are available: 2 Insufficient cpu. preemption: 0/2 nodes are available: 2 No preemption victims found for incoming pod.."
I1016 07:15:53.700811       1 log.go:194] falcon-pod-a04 in Prefilter
I1016 07:15:53.700840       1 log.go:194] falcon-pod-a04 requires 1 gpu(s), and currently has 4 gpus(s) in total
I1016 07:15:53.713880       1 schedule_one.go:252] "Successfully bound pod to node" pod="default/falcon-pod-a04" node="css-host-129" evaluatedNodes=2 feasibleNodes=1
I1016 07:16:49.011464       1 log.go:194] falcon-pod-a03 in Prefilter
I1016 07:16:49.011495       1 log.go:194] falcon-pod-a03 requires 1 gpu(s), and currently has 4 gpus(s) in total
I1016 07:16:49.017488       1 schedule_one.go:867] "Unable to schedule pod; no fit; waiting" pod="default/falcon-pod-a03" err="0/2 nodes are available: 2 Insufficient cpu. preemption: 0/2 nodes are available: 2 No preemption victims found for incoming pod.."
E1016 07:16:49.017562       1 schedule_one.go:902] "Error occurred" err="Pod default/falcon-pod-a03 is already present in the active queue"
I1016 07:16:49.023967       1 log.go:194] falcon-pod-a03 in Prefilter
I1016 07:16:49.023989       1 log.go:194] falcon-pod-a03 requires 1 gpu(s), and currently has 4 gpus(s) in total
I1016 07:16:49.029738       1 schedule_one.go:867] "Unable to schedule pod; no fit; waiting" pod="default/falcon-pod-a03" err="0/2 nodes are available: 2 Insufficient cpu. preemption: 0/2 nodes are available: 2 No preemption victims found for incoming pod.."
I1016 07:17:33.945537       1 log.go:194] falcon-pod-a03 in Prefilter
I1016 07:17:33.945585       1 log.go:194] falcon-pod-a03 requires 1 gpu(s), and currently has 5 gpus(s) in total
I1016 07:17:33.960368       1 schedule_one.go:252] "Successfully bound pod to node" pod="default/falcon-pod-a03" node="css-host-129" evaluatedNodes=2 feasibleNodes=1
I1016 07:17:46.077126       1 log.go:194] falcon-pod-a05 in Prefilter
I1016 07:17:46.077164       1 log.go:194] falcon-pod-a05 requires 1 gpu(s), and currently has 4 gpus(s) in total
I1016 07:17:46.085973       1 schedule_one.go:867] "Unable to schedule pod; no fit; waiting" pod="default/falcon-pod-a05" err="0/2 nodes are available: 2 Insufficient cpu. preemption: 0/2 nodes are available: 2 No preemption victims found for incoming pod.."
E1016 07:17:46.086088       1 schedule_one.go:902] "Error occurred" err="Pod default/falcon-pod-a05 is already present in the active queue"
I1016 07:17:46.091805       1 log.go:194] falcon-pod-a05 in Prefilter
I1016 07:17:46.091826       1 log.go:194] falcon-pod-a05 requires 1 gpu(s), and currently has 4 gpus(s) in total
I1016 07:17:46.096008       1 schedule_one.go:867] "Unable to schedule pod; no fit; waiting" pod="default/falcon-pod-a05" err="0/2 nodes are available: 2 Insufficient cpu. preemption: 0/2 nodes are available: 2 No preemption victims found for incoming pod.."
I1016 07:18:51.271044       1 log.go:194] falcon-pod-a05 in Prefilter
I1016 07:18:51.271079       1 log.go:194] falcon-pod-a05 requires 1 gpu(s), and currently has 5 gpus(s) in total
I1016 07:18:51.285247       1 schedule_one.go:252] "Successfully bound pod to node" pod="default/falcon-pod-a05" node="css-host-128" evaluatedNodes=2 feasibleNodes=1
I1016 07:19:06.689845       1 log.go:194] falcon-pod-b02 in Prefilter
I1016 07:19:06.689904       1 log.go:194] falcon-pod-b02 requires 1 gpu(s), and currently has 4 gpus(s) in total
I1016 07:19:06.697115       1 schedule_one.go:867] "Unable to schedule pod; no fit; waiting" pod="default/falcon-pod-b02" err="0/2 nodes are available: 2 Insufficient cpu. preemption: 0/2 nodes are available: 2 No preemption victims found for incoming pod.."
E1016 07:19:06.697187       1 schedule_one.go:902] "Error occurred" err="Pod default/falcon-pod-b02 is already present in the active queue"
I1016 07:19:06.702667       1 log.go:194] falcon-pod-b02 in Prefilter
I1016 07:19:06.702689       1 log.go:194] falcon-pod-b02 requires 1 gpu(s), and currently has 4 gpus(s) in total
I1016 07:19:06.708467       1 schedule_one.go:867] "Unable to schedule pod; no fit; waiting" pod="default/falcon-pod-b02" err="0/2 nodes are available: 2 Insufficient cpu. preemption: 0/2 nodes are available: 2 No preemption victims found for incoming pod.."
I1016 07:20:06.318967       1 log.go:194] falcon-pod-b02 in Prefilter
I1016 07:20:06.319001       1 log.go:194] falcon-pod-b02 requires 1 gpu(s), and currently has 5 gpus(s) in total
I1016 07:20:06.332690       1 schedule_one.go:252] "Successfully bound pod to node" pod="default/falcon-pod-b02" node="css-host-128" evaluatedNodes=2 feasibleNodes=1
I1016 07:20:20.567274       1 log.go:194] falcon-pod-a09 in Prefilter
I1016 07:20:20.567306       1 log.go:194] falcon-pod-a09 requires 1 gpu(s), and currently has 4 gpus(s) in total
I1016 07:20:20.574391       1 schedule_one.go:867] "Unable to schedule pod; no fit; waiting" pod="default/falcon-pod-a09" err="0/2 nodes are available: 2 Insufficient cpu. preemption: 0/2 nodes are available: 2 No preemption victims found for incoming pod.."
E1016 07:20:20.574479       1 schedule_one.go:902] "Error occurred" err="Pod default/falcon-pod-a09 is already present in the active queue"
I1016 07:20:20.580131       1 log.go:194] falcon-pod-a09 in Prefilter
I1016 07:20:20.580164       1 log.go:194] falcon-pod-a09 requires 1 gpu(s), and currently has 4 gpus(s) in total
I1016 07:20:20.585767       1 schedule_one.go:867] "Unable to schedule pod; no fit; waiting" pod="default/falcon-pod-a09" err="0/2 nodes are available: 2 Insufficient cpu. preemption: 0/2 nodes are available: 2 No preemption victims found for incoming pod.."
E1016 07:20:20.585832       1 schedule_one.go:902] "Error occurred" err="Pod default/falcon-pod-a09 is already present in the active queue"
I1016 07:20:20.589651       1 log.go:194] falcon-pod-a09 in Prefilter
I1016 07:20:20.589671       1 log.go:194] falcon-pod-a09 requires 1 gpu(s), and currently has 4 gpus(s) in total
I1016 07:20:20.594937       1 schedule_one.go:867] "Unable to schedule pod; no fit; waiting" pod="default/falcon-pod-a09" err="0/2 nodes are available: 2 Insufficient cpu. preemption: 0/2 nodes are available: 2 No preemption victims found for incoming pod.."
I1016 07:21:01.718987       1 log.go:194] falcon-pod-a09 in Prefilter
I1016 07:21:01.719017       1 log.go:194] falcon-pod-a09 requires 1 gpu(s), and currently has 5 gpus(s) in total
I1016 07:21:01.733660       1 schedule_one.go:252] "Successfully bound pod to node" pod="default/falcon-pod-a09" node="css-host-129" evaluatedNodes=2 feasibleNodes=1
I1016 07:21:11.598702       1 log.go:194] falcon-pod-a10 in Prefilter
I1016 07:21:11.598741       1 log.go:194] falcon-pod-a10 requires 1 gpu(s), and currently has 4 gpus(s) in total
I1016 07:21:11.605011       1 schedule_one.go:867] "Unable to schedule pod; no fit; waiting" pod="default/falcon-pod-a10" err="0/2 nodes are available: 2 Insufficient cpu. preemption: 0/2 nodes are available: 2 No preemption victims found for incoming pod.."
E1016 07:21:11.605114       1 schedule_one.go:902] "Error occurred" err="Pod default/falcon-pod-a10 is already present in the active queue"
I1016 07:21:11.610805       1 log.go:194] falcon-pod-a10 in Prefilter
I1016 07:21:11.610820       1 log.go:194] falcon-pod-a10 requires 1 gpu(s), and currently has 4 gpus(s) in total
I1016 07:21:11.616892       1 schedule_one.go:867] "Unable to schedule pod; no fit; waiting" pod="default/falcon-pod-a10" err="0/2 nodes are available: 2 Insufficient cpu. preemption: 0/2 nodes are available: 2 No preemption victims found for incoming pod.."
E1016 07:21:11.617004       1 schedule_one.go:902] "Error occurred" err="Pod default/falcon-pod-a10 is already present in the active queue"
I1016 07:21:11.622547       1 log.go:194] falcon-pod-a10 in Prefilter
I1016 07:21:11.622573       1 log.go:194] falcon-pod-a10 requires 1 gpu(s), and currently has 4 gpus(s) in total
I1016 07:21:11.627205       1 schedule_one.go:867] "Unable to schedule pod; no fit; waiting" pod="default/falcon-pod-a10" err="0/2 nodes are available: 2 Insufficient cpu. preemption: 0/2 nodes are available: 2 No preemption victims found for incoming pod.."
I1016 07:22:44.637472       1 log.go:194] falcon-pod-a10 in Prefilter
I1016 07:22:44.637503       1 log.go:194] falcon-pod-a10 requires 1 gpu(s), and currently has 5 gpus(s) in total
I1016 07:22:44.651846       1 schedule_one.go:252] "Successfully bound pod to node" pod="default/falcon-pod-a10" node="css-host-129" evaluatedNodes=2 feasibleNodes=1
I1016 07:22:53.274760       1 log.go:194] falcon-pod-a06 in Prefilter
I1016 07:22:53.274790       1 log.go:194] falcon-pod-a06 requires 1 gpu(s), and currently has 4 gpus(s) in total
I1016 07:22:53.281910       1 schedule_one.go:867] "Unable to schedule pod; no fit; waiting" pod="default/falcon-pod-a06" err="0/2 nodes are available: 2 Insufficient cpu. preemption: 0/2 nodes are available: 2 No preemption victims found for incoming pod.."
E1016 07:22:53.281994       1 schedule_one.go:902] "Error occurred" err="Pod default/falcon-pod-a06 is already present in the active queue"
I1016 07:22:53.287772       1 log.go:194] falcon-pod-a06 in Prefilter
I1016 07:22:53.287791       1 log.go:194] falcon-pod-a06 requires 1 gpu(s), and currently has 4 gpus(s) in total
I1016 07:22:53.293514       1 schedule_one.go:867] "Unable to schedule pod; no fit; waiting" pod="default/falcon-pod-a06" err="0/2 nodes are available: 2 Insufficient cpu. preemption: 0/2 nodes are available: 2 No preemption victims found for incoming pod.."
E1016 07:22:53.293590       1 schedule_one.go:902] "Error occurred" err="Pod default/falcon-pod-a06 is already present in the active queue"
I1016 07:22:53.299330       1 log.go:194] falcon-pod-a06 in Prefilter
I1016 07:22:53.299346       1 log.go:194] falcon-pod-a06 requires 1 gpu(s), and currently has 4 gpus(s) in total
I1016 07:22:53.304285       1 schedule_one.go:867] "Unable to schedule pod; no fit; waiting" pod="default/falcon-pod-a06" err="0/2 nodes are available: 2 Insufficient cpu. preemption: 0/2 nodes are available: 2 No preemption victims found for incoming pod.."
I1016 07:24:07.063703       1 log.go:194] falcon-pod-a06 in Prefilter
I1016 07:24:07.063743       1 log.go:194] falcon-pod-a06 requires 1 gpu(s), and currently has 5 gpus(s) in total
I1016 07:24:07.079417       1 schedule_one.go:252] "Successfully bound pod to node" pod="default/falcon-pod-a06" node="css-host-128" evaluatedNodes=2 feasibleNodes=1
I1016 07:24:22.218072       1 log.go:194] falcon-pod-a07 in Prefilter
I1016 07:24:22.218108       1 log.go:194] falcon-pod-a07 requires 1 gpu(s), and currently has 4 gpus(s) in total
I1016 07:24:22.224651       1 schedule_one.go:867] "Unable to schedule pod; no fit; waiting" pod="default/falcon-pod-a07" err="0/2 nodes are available: 2 Insufficient cpu. preemption: 0/2 nodes are available: 2 No preemption victims found for incoming pod.."
E1016 07:24:22.224744       1 schedule_one.go:902] "Error occurred" err="Pod default/falcon-pod-a07 is already present in the active queue"
I1016 07:24:22.231399       1 log.go:194] falcon-pod-a07 in Prefilter
I1016 07:24:22.231431       1 log.go:194] falcon-pod-a07 requires 1 gpu(s), and currently has 4 gpus(s) in total
I1016 07:24:22.236232       1 schedule_one.go:867] "Unable to schedule pod; no fit; waiting" pod="default/falcon-pod-a07" err="0/2 nodes are available: 2 Insufficient cpu. preemption: 0/2 nodes are available: 2 No preemption victims found for incoming pod.."
I1016 07:25:22.140936       1 log.go:194] falcon-pod-a07 in Prefilter
I1016 07:25:22.140969       1 log.go:194] falcon-pod-a07 requires 1 gpu(s), and currently has 5 gpus(s) in total
I1016 07:25:22.152739       1 schedule_one.go:252] "Successfully bound pod to node" pod="default/falcon-pod-a07" node="css-host-128" evaluatedNodes=2 feasibleNodes=1
I1016 07:25:37.063005       1 log.go:194] falcon-pod-b03 in Prefilter
I1016 07:25:37.063040       1 log.go:194] falcon-pod-b03 requires 1 gpu(s), and currently has 4 gpus(s) in total
I1016 07:25:37.069817       1 schedule_one.go:867] "Unable to schedule pod; no fit; waiting" pod="default/falcon-pod-b03" err="0/2 nodes are available: 2 Insufficient cpu. preemption: 0/2 nodes are available: 2 No preemption victims found for incoming pod.."
E1016 07:25:37.069905       1 schedule_one.go:902] "Error occurred" err="Pod default/falcon-pod-b03 is already present in the active queue"
I1016 07:25:37.075120       1 log.go:194] falcon-pod-b03 in Prefilter
I1016 07:25:37.075143       1 log.go:194] falcon-pod-b03 requires 1 gpu(s), and currently has 4 gpus(s) in total
I1016 07:25:37.081497       1 schedule_one.go:867] "Unable to schedule pod; no fit; waiting" pod="default/falcon-pod-b03" err="0/2 nodes are available: 2 Insufficient cpu. preemption: 0/2 nodes are available: 2 No preemption victims found for incoming pod.."
I1016 07:26:12.608684       1 log.go:194] falcon-pod-b03 in Prefilter
I1016 07:26:12.608720       1 log.go:194] falcon-pod-b03 requires 1 gpu(s), and currently has 5 gpus(s) in total
I1016 07:26:12.623334       1 schedule_one.go:252] "Successfully bound pod to node" pod="default/falcon-pod-b03" node="css-host-129" evaluatedNodes=2 feasibleNodes=1
I1016 07:26:22.374117       1 log.go:194] falcon-pod-b06 in Prefilter
I1016 07:26:22.374145       1 log.go:194] falcon-pod-b06 requires 1 gpu(s), and currently has 4 gpus(s) in total
I1016 07:26:22.386915       1 schedule_one.go:252] "Successfully bound pod to node" pod="default/falcon-pod-b06" node="css-host-129" evaluatedNodes=2 feasibleNodes=1
I1016 07:26:29.362688       1 log.go:194] falcon-pod-b05 in Prefilter
I1016 07:26:29.362732       1 log.go:194] falcon-pod-b05 requires 1 gpu(s), and currently has 3 gpus(s) in total
I1016 07:26:29.369383       1 schedule_one.go:867] "Unable to schedule pod; no fit; waiting" pod="default/falcon-pod-b05" err="0/2 nodes are available: 2 Insufficient cpu. preemption: 0/2 nodes are available: 2 No preemption victims found for incoming pod.."
E1016 07:26:29.369490       1 schedule_one.go:902] "Error occurred" err="Pod default/falcon-pod-b05 is already present in the active queue"
I1016 07:26:29.374764       1 log.go:194] falcon-pod-b05 in Prefilter
I1016 07:26:29.374798       1 log.go:194] falcon-pod-b05 requires 1 gpu(s), and currently has 3 gpus(s) in total
I1016 07:26:29.380089       1 schedule_one.go:867] "Unable to schedule pod; no fit; waiting" pod="default/falcon-pod-b05" err="0/2 nodes are available: 2 Insufficient cpu. preemption: 0/2 nodes are available: 2 No preemption victims found for incoming pod.."
E1016 07:26:29.380188       1 schedule_one.go:902] "Error occurred" err="Pod default/falcon-pod-b05 is already present in the active queue"
I1016 07:26:29.384240       1 log.go:194] falcon-pod-b05 in Prefilter
I1016 07:26:29.384259       1 log.go:194] falcon-pod-b05 requires 1 gpu(s), and currently has 3 gpus(s) in total
I1016 07:26:29.389375       1 schedule_one.go:867] "Unable to schedule pod; no fit; waiting" pod="default/falcon-pod-b05" err="0/2 nodes are available: 2 Insufficient cpu. preemption: 0/2 nodes are available: 2 No preemption victims found for incoming pod.."
I1016 07:27:55.385709       1 log.go:194] falcon-pod-b05 in Prefilter
I1016 07:27:55.385738       1 log.go:194] falcon-pod-b05 requires 1 gpu(s), and currently has 4 gpus(s) in total
I1016 07:27:55.400662       1 schedule_one.go:252] "Successfully bound pod to node" pod="default/falcon-pod-b05" node="css-host-129" evaluatedNodes=2 feasibleNodes=1
I1016 07:28:01.802618       1 log.go:194] falcon-pod-b07 in Prefilter
I1016 07:28:01.802661       1 log.go:194] falcon-pod-b07 requires 1 gpu(s), and currently has 3 gpus(s) in total
I1016 07:28:01.819562       1 event.go:307] "Event occurred" object="default/falcon-pod-b07" fieldPath="" kind="Pod" apiVersion="v1" type="Normal" reason="Reconfig" message="Pod falcon-pod-b07 needs reconfiguration"
E1016 07:28:42.006629       1 schedule_one.go:883] "Error scheduling pod; retrying" err="" pod="default/falcon-pod-b07"
E1016 07:28:42.006716       1 schedule_one.go:902] "Error occurred" err="Pod default/falcon-pod-b07 is already present in the active queue"
I1016 07:28:42.013420       1 log.go:194] falcon-pod-b07 in Prefilter
I1016 07:28:42.013451       1 log.go:194] falcon-pod-b07 requires 1 gpu(s), and currently has 2 gpus(s) in total
I1016 07:28:42.210179       1 trace.go:219] Trace[547365750]: "Scheduling" namespace:default,name:falcon-pod-b07 (16-Oct-2023 07:28:42.013) (total time: 196ms):
Trace[547365750]: ---"Computing predicates done" 196ms (07:28:42.210)
Trace[547365750]: [196.826804ms] [196.826804ms] END
I1016 07:28:42.609994       1 event.go:307] "Event occurred" object="default/falcon-pod-b07" fieldPath="" kind="Pod" apiVersion="v1" type="Normal" reason="Reconfig" message="Pod falcon-pod-b07 needs reconfiguration"
I1016 07:28:57.611035       1 schedule_one.go:252] "Successfully bound pod to node" pod="default/falcon-pod-b07" node="css-host-129" evaluatedNodes=2 feasibleNodes=1
I1016 07:29:04.751107       1 log.go:194] falcon-pod-b04 in Prefilter
I1016 07:29:04.751138       1 log.go:194] falcon-pod-b04 requires 1 gpu(s), and currently has 2 gpus(s) in total
I1016 07:29:04.758810       1 schedule_one.go:867] "Unable to schedule pod; no fit; waiting" pod="default/falcon-pod-b04" err="0/2 nodes are available: 2 Insufficient cpu. preemption: 0/2 nodes are available: 2 No preemption victims found for incoming pod.."
E1016 07:29:04.758892       1 schedule_one.go:902] "Error occurred" err="Pod default/falcon-pod-b04 is already present in the active queue"
I1016 07:29:04.765343       1 log.go:194] falcon-pod-b04 in Prefilter
I1016 07:29:04.765371       1 log.go:194] falcon-pod-b04 requires 1 gpu(s), and currently has 2 gpus(s) in total
I1016 07:29:04.770094       1 schedule_one.go:867] "Unable to schedule pod; no fit; waiting" pod="default/falcon-pod-b04" err="0/2 nodes are available: 2 Insufficient cpu. preemption: 0/2 nodes are available: 2 No preemption victims found for incoming pod.."
I1016 07:29:23.104815       1 log.go:194] falcon-pod-b04 in Prefilter
I1016 07:29:23.104851       1 log.go:194] falcon-pod-b04 requires 1 gpu(s), and currently has 2 gpus(s) in total
I1016 07:29:23.117893       1 schedule_one.go:252] "Successfully bound pod to node" pod="default/falcon-pod-b04" node="css-host-128" evaluatedNodes=2 feasibleNodes=1
I1016 07:29:32.587218       1 log.go:194] falcon-pod-a01 in Prefilter
I1016 07:29:32.587244       1 log.go:194] falcon-pod-a01 requires 1 gpu(s), and currently has 2 gpus(s) in total
I1016 07:29:32.594638       1 schedule_one.go:867] "Unable to schedule pod; no fit; waiting" pod="default/falcon-pod-a01" err="0/2 nodes are available: 2 Insufficient cpu. preemption: 0/2 nodes are available: 2 No preemption victims found for incoming pod.."
E1016 07:29:32.594752       1 schedule_one.go:902] "Error occurred" err="Pod default/falcon-pod-a01 is already present in the active queue"
I1016 07:29:32.600074       1 log.go:194] falcon-pod-a01 in Prefilter
I1016 07:29:32.600096       1 log.go:194] falcon-pod-a01 requires 1 gpu(s), and currently has 2 gpus(s) in total
I1016 07:29:32.604617       1 schedule_one.go:867] "Unable to schedule pod; no fit; waiting" pod="default/falcon-pod-a01" err="0/2 nodes are available: 2 Insufficient cpu. preemption: 0/2 nodes are available: 2 No preemption victims found for incoming pod.."
I1016 07:30:37.588319       1 log.go:194] falcon-pod-a01 in Prefilter
I1016 07:30:37.588362       1 log.go:194] falcon-pod-a01 requires 1 gpu(s), and currently has 3 gpus(s) in total
I1016 07:30:37.603381       1 schedule_one.go:252] "Successfully bound pod to node" pod="default/falcon-pod-a01" node="css-host-128" evaluatedNodes=2 feasibleNodes=1
I1016 07:30:46.489810       1 log.go:194] falcon-pod-b01 in Prefilter
I1016 07:30:46.489839       1 log.go:194] falcon-pod-b01 requires 1 gpu(s), and currently has 2 gpus(s) in total
I1016 07:30:46.502094       1 schedule_one.go:252] "Successfully bound pod to node" pod="default/falcon-pod-b01" node="css-host-128" evaluatedNodes=2 feasibleNodes=1
I1016 07:39:56.254669       1 log.go:194] falcon-pod-d03 in Prefilter
I1016 07:39:56.254695       1 log.go:194] falcon-pod-d03 requires 4 gpu(s), and currently has 8 gpus(s) in total
I1016 07:39:56.261562       1 log.go:194] css-host-129 has 5 gpu, falcon-pod-d03 requires 4 gpu -> score: 80
I1016 07:39:56.261630       1 log.go:194] css-host-128 has 3 gpu, falcon-pod-d03 requires 4 gpu -> score: -1
I1016 07:39:56.270078       1 schedule_one.go:252] "Successfully bound pod to node" pod="default/falcon-pod-d03" node="css-host-129" evaluatedNodes=2 feasibleNodes=2
I1016 07:41:04.315852       1 log.go:194] falcon-pod-d04 in Prefilter
I1016 07:41:04.315888       1 log.go:194] falcon-pod-d04 requires 4 gpu(s), and currently has 4 gpus(s) in total
I1016 07:41:04.322304       1 log.go:194] css-host-128 has 3 gpu, falcon-pod-d04 requires 4 gpu -> score: -1
I1016 07:41:04.322354       1 log.go:194] css-host-129 has 1 gpu, falcon-pod-d04 requires 4 gpu -> score: -3
I1016 07:41:04.331677       1 event.go:307] "Event occurred" object="default/falcon-pod-d04" fieldPath="" kind="Pod" apiVersion="v1" type="Normal" reason="Reconfig" message="Pod falcon-pod-d04 needs reconfiguration"
I1016 07:41:37.122818       1 schedule_one.go:252] "Successfully bound pod to node" pod="default/falcon-pod-d04" node="css-host-128" evaluatedNodes=2 feasibleNodes=2
I1016 07:42:09.389957       1 log.go:194] falcon-pod-b05 in Prefilter
I1016 07:42:09.390001       1 log.go:194] falcon-pod-b05 requires 1 gpu(s), and currently has 0 gpus(s) in total
I1016 07:42:09.396193       1 schedule_one.go:867] "Unable to schedule pod; no fit; waiting" pod="default/falcon-pod-b05" err="0/2 nodes are available: falcon-pod-b05 requires 1 gpu but only 0 gpu in the pool.. preemption: 0/2 nodes are available: 2 No preemption victims found for incoming pod.."
E1016 07:42:09.396311       1 schedule_one.go:902] "Error occurred" err="Pod default/falcon-pod-b05 is already present in the active queue"
I1016 07:42:09.402550       1 log.go:194] falcon-pod-b05 in Prefilter
I1016 07:42:09.402574       1 log.go:194] falcon-pod-b05 requires 1 gpu(s), and currently has 0 gpus(s) in total
I1016 07:42:09.408154       1 schedule_one.go:867] "Unable to schedule pod; no fit; waiting" pod="default/falcon-pod-b05" err="0/2 nodes are available: falcon-pod-b05 requires 1 gpu but only 0 gpu in the pool.. preemption: 0/2 nodes are available: 2 No preemption victims found for incoming pod.."
I1016 07:45:18.468400       1 log.go:194] falcon-pod-b05 in Prefilter
I1016 07:45:18.468441       1 log.go:194] falcon-pod-b05 requires 1 gpu(s), and currently has 4 gpus(s) in total
I1016 07:45:18.476196       1 log.go:194] css-host-128 has 0 gpu, falcon-pod-b05 requires 1 gpu -> score: -1
I1016 07:45:18.476240       1 log.go:194] css-host-129 has 4 gpu, falcon-pod-b05 requires 1 gpu -> score: 25
I1016 07:45:18.485732       1 schedule_one.go:252] "Successfully bound pod to node" pod="default/falcon-pod-b05" node="css-host-129" evaluatedNodes=2 feasibleNodes=2
I1016 07:45:33.376662       1 log.go:194] falcon-pod-c06 in Prefilter
I1016 07:45:33.376714       1 log.go:194] falcon-pod-c06 requires 2 gpu(s), and currently has 3 gpus(s) in total
I1016 07:45:33.389478       1 log.go:194] css-host-128 has 0 gpu, falcon-pod-c06 requires 2 gpu -> score: -2
I1016 07:45:33.389511       1 log.go:194] css-host-129 has 3 gpu, falcon-pod-c06 requires 2 gpu -> score: 66
I1016 07:45:33.397723       1 schedule_one.go:252] "Successfully bound pod to node" pod="default/falcon-pod-c06" node="css-host-129" evaluatedNodes=2 feasibleNodes=2
I1016 07:45:44.722727       1 log.go:194] falcon-pod-b01 in Prefilter
I1016 07:45:44.722757       1 log.go:194] falcon-pod-b01 requires 1 gpu(s), and currently has -1 gpus(s) in total
I1016 07:45:44.730052       1 schedule_one.go:867] "Unable to schedule pod; no fit; waiting" pod="default/falcon-pod-b01" err="0/2 nodes are available: falcon-pod-b01 requires 1 gpu but only -1 gpu in the pool.. preemption: 0/2 nodes are available: 2 No preemption victims found for incoming pod.."
E1016 07:45:44.730126       1 schedule_one.go:902] "Error occurred" err="Pod default/falcon-pod-b01 is already present in the active queue"
I1016 07:45:44.735823       1 log.go:194] falcon-pod-b01 in Prefilter
I1016 07:45:44.735844       1 log.go:194] falcon-pod-b01 requires 1 gpu(s), and currently has -1 gpus(s) in total
I1016 07:45:44.740250       1 schedule_one.go:867] "Unable to schedule pod; no fit; waiting" pod="default/falcon-pod-b01" err="0/2 nodes are available: falcon-pod-b01 requires 1 gpu but only -1 gpu in the pool.. preemption: 0/2 nodes are available: 2 No preemption victims found for incoming pod.."
E1016 07:45:44.740305       1 schedule_one.go:902] "Error occurred" err="Pod default/falcon-pod-b01 is already present in the active queue"
I1016 07:45:44.744632       1 log.go:194] falcon-pod-b01 in Prefilter
I1016 07:45:44.744649       1 log.go:194] falcon-pod-b01 requires 1 gpu(s), and currently has -1 gpus(s) in total
I1016 07:45:44.750116       1 schedule_one.go:867] "Unable to schedule pod; no fit; waiting" pod="default/falcon-pod-b01" err="0/2 nodes are available: falcon-pod-b01 requires 1 gpu but only -1 gpu in the pool.. preemption: 0/2 nodes are available: 2 No preemption victims found for incoming pod.."
I1016 07:46:55.541545       1 log.go:194] falcon-pod-b01 in Prefilter
I1016 07:46:55.541585       1 log.go:194] falcon-pod-b01 requires 1 gpu(s), and currently has 5 gpus(s) in total
I1016 07:46:55.546810       1 log.go:194] css-host-128 has 4 gpu, falcon-pod-b01 requires 1 gpu -> score: 25
I1016 07:46:55.546831       1 log.go:194] css-host-129 has 1 gpu, falcon-pod-b01 requires 1 gpu -> score: 100
I1016 07:46:55.553665       1 schedule_one.go:252] "Successfully bound pod to node" pod="default/falcon-pod-b01" node="css-host-129" evaluatedNodes=2 feasibleNodes=2
I1016 07:47:02.421168       1 log.go:194] falcon-pod-c03 in Prefilter
I1016 07:47:02.421200       1 log.go:194] falcon-pod-c03 requires 2 gpu(s), and currently has 4 gpus(s) in total
I1016 07:47:02.428706       1 log.go:194] css-host-129 has 0 gpu, falcon-pod-c03 requires 2 gpu -> score: -2
I1016 07:47:02.428730       1 log.go:194] css-host-128 has 4 gpu, falcon-pod-c03 requires 2 gpu -> score: 50
I1016 07:47:02.435141       1 schedule_one.go:252] "Successfully bound pod to node" pod="default/falcon-pod-c03" node="css-host-128" evaluatedNodes=2 feasibleNodes=2
I1016 07:47:17.001446       1 log.go:194] falcon-pod-a03 in Prefilter
I1016 07:47:17.001475       1 log.go:194] falcon-pod-a03 requires 1 gpu(s), and currently has 2 gpus(s) in total
I1016 07:47:17.015756       1 schedule_one.go:252] "Successfully bound pod to node" pod="default/falcon-pod-a03" node="css-host-128" evaluatedNodes=2 feasibleNodes=1
I1016 07:47:42.655120       1 log.go:194] falcon-pod-d05 in Prefilter
I1016 07:47:42.655148       1 log.go:194] falcon-pod-d05 requires 4 gpu(s), and currently has 1 gpus(s) in total
I1016 07:47:42.661637       1 schedule_one.go:867] "Unable to schedule pod; no fit; waiting" pod="default/falcon-pod-d05" err="0/2 nodes are available: falcon-pod-d05 requires 4 gpu but only 1 gpu in the pool.. preemption: 0/2 nodes are available: 2 No preemption victims found for incoming pod.."
E1016 07:47:42.661722       1 schedule_one.go:902] "Error occurred" err="Pod default/falcon-pod-d05 is already present in the active queue"
I1016 07:47:42.667971       1 log.go:194] falcon-pod-d05 in Prefilter
I1016 07:47:42.668000       1 log.go:194] falcon-pod-d05 requires 4 gpu(s), and currently has 1 gpus(s) in total
I1016 07:47:42.674231       1 schedule_one.go:867] "Unable to schedule pod; no fit; waiting" pod="default/falcon-pod-d05" err="0/2 nodes are available: falcon-pod-d05 requires 4 gpu but only 1 gpu in the pool.. preemption: 0/2 nodes are available: 2 No preemption victims found for incoming pod.."
I1016 07:50:34.837708       1 log.go:194] falcon-pod-d05 in Prefilter
I1016 07:50:34.837747       1 log.go:194] falcon-pod-d05 requires 4 gpu(s), and currently has 2 gpus(s) in total
I1016 07:50:34.844228       1 schedule_one.go:867] "Unable to schedule pod; no fit; waiting" pod="default/falcon-pod-d05" err="0/2 nodes are available: falcon-pod-d05 requires 4 gpu but only 2 gpu in the pool.. preemption: 0/2 nodes are available: 2 No preemption victims found for incoming pod.."
I1016 07:50:47.123056       1 log.go:194] falcon-pod-d05 in Prefilter
I1016 07:50:47.123099       1 log.go:194] falcon-pod-d05 requires 4 gpu(s), and currently has 4 gpus(s) in total
I1016 07:50:47.130378       1 log.go:194] css-host-129 has 3 gpu, falcon-pod-d05 requires 4 gpu -> score: -1
I1016 07:50:47.130419       1 log.go:194] css-host-128 has 1 gpu, falcon-pod-d05 requires 4 gpu -> score: -3
I1016 07:50:47.141559       1 event.go:307] "Event occurred" object="default/falcon-pod-d05" fieldPath="" kind="Pod" apiVersion="v1" type="Normal" reason="Reconfig" message="Pod falcon-pod-d05 needs reconfiguration"
I1016 07:51:26.131238       1 schedule_one.go:252] "Successfully bound pod to node" pod="default/falcon-pod-d05" node="css-host-129" evaluatedNodes=2 feasibleNodes=2
I1016 07:51:41.683729       1 log.go:194] falcon-pod-d01 in Prefilter
I1016 07:51:41.683767       1 log.go:194] falcon-pod-d01 requires 4 gpu(s), and currently has 0 gpus(s) in total
I1016 07:51:41.691766       1 schedule_one.go:867] "Unable to schedule pod; no fit; waiting" pod="default/falcon-pod-d01" err="0/2 nodes are available: falcon-pod-d01 requires 4 gpu but only 0 gpu in the pool.. preemption: 0/2 nodes are available: 2 No preemption victims found for incoming pod.."
E1016 07:51:41.691859       1 schedule_one.go:902] "Error occurred" err="Pod default/falcon-pod-d01 is already present in the active queue"
I1016 07:51:41.697640       1 log.go:194] falcon-pod-d01 in Prefilter
I1016 07:51:41.697661       1 log.go:194] falcon-pod-d01 requires 4 gpu(s), and currently has 0 gpus(s) in total
I1016 07:51:41.703034       1 schedule_one.go:867] "Unable to schedule pod; no fit; waiting" pod="default/falcon-pod-d01" err="0/2 nodes are available: falcon-pod-d01 requires 4 gpu but only 0 gpu in the pool.. preemption: 0/2 nodes are available: 2 No preemption victims found for incoming pod.."
E1016 07:51:41.703092       1 schedule_one.go:902] "Error occurred" err="Pod default/falcon-pod-d01 is already present in the active queue"
I1016 07:51:41.707651       1 log.go:194] falcon-pod-d01 in Prefilter
I1016 07:51:41.707683       1 log.go:194] falcon-pod-d01 requires 4 gpu(s), and currently has 0 gpus(s) in total
I1016 07:51:41.712821       1 schedule_one.go:867] "Unable to schedule pod; no fit; waiting" pod="default/falcon-pod-d01" err="0/2 nodes are available: falcon-pod-d01 requires 4 gpu but only 0 gpu in the pool.. preemption: 0/2 nodes are available: 2 No preemption victims found for incoming pod.."
I1016 07:52:03.338637       1 log.go:194] falcon-pod-d01 in Prefilter
I1016 07:52:03.338671       1 log.go:194] falcon-pod-d01 requires 4 gpu(s), and currently has 1 gpus(s) in total
I1016 07:52:03.345694       1 schedule_one.go:867] "Unable to schedule pod; no fit; waiting" pod="default/falcon-pod-d01" err="0/2 nodes are available: falcon-pod-d01 requires 4 gpu but only 1 gpu in the pool.. preemption: 0/2 nodes are available: 2 No preemption victims found for incoming pod.."
I1016 07:52:18.812619       1 log.go:194] falcon-pod-d01 in Prefilter
I1016 07:52:18.812655       1 log.go:194] falcon-pod-d01 requires 4 gpu(s), and currently has 3 gpus(s) in total
I1016 07:52:18.819166       1 schedule_one.go:867] "Unable to schedule pod; no fit; waiting" pod="default/falcon-pod-d01" err="0/2 nodes are available: falcon-pod-d01 requires 4 gpu but only 3 gpu in the pool.. preemption: 0/2 nodes are available: 2 No preemption victims found for incoming pod.."
I1016 07:52:27.850161       1 log.go:194] falcon-pod-d01 in Prefilter
I1016 07:52:27.850201       1 log.go:194] falcon-pod-d01 requires 4 gpu(s), and currently has 4 gpus(s) in total
I1016 07:52:27.856831       1 log.go:194] css-host-128 has 3 gpu, falcon-pod-d01 requires 4 gpu -> score: -1
I1016 07:52:27.856852       1 log.go:194] css-host-129 has 1 gpu, falcon-pod-d01 requires 4 gpu -> score: -3
I1016 07:52:27.874410       1 event.go:307] "Event occurred" object="default/falcon-pod-d01" fieldPath="" kind="Pod" apiVersion="v1" type="Normal" reason="Reconfig" message="Pod falcon-pod-d01 needs reconfiguration"
I1016 07:53:01.658311       1 schedule_one.go:252] "Successfully bound pod to node" pod="default/falcon-pod-d01" node="css-host-128" evaluatedNodes=2 feasibleNodes=2
I1016 07:53:17.069713       1 log.go:194] falcon-pod-c02 in Prefilter
I1016 07:53:17.069756       1 log.go:194] falcon-pod-c02 requires 2 gpu(s), and currently has 0 gpus(s) in total
I1016 07:53:17.077317       1 schedule_one.go:867] "Unable to schedule pod; no fit; waiting" pod="default/falcon-pod-c02" err="0/2 nodes are available: falcon-pod-c02 requires 2 gpu but only 0 gpu in the pool.. preemption: 0/2 nodes are available: 2 No preemption victims found for incoming pod.."
E1016 07:53:17.077419       1 schedule_one.go:902] "Error occurred" err="Pod default/falcon-pod-c02 is already present in the active queue"
I1016 07:53:17.088296       1 log.go:194] falcon-pod-c02 in Prefilter
I1016 07:53:17.088327       1 log.go:194] falcon-pod-c02 requires 2 gpu(s), and currently has 0 gpus(s) in total
I1016 07:53:17.093640       1 schedule_one.go:867] "Unable to schedule pod; no fit; waiting" pod="default/falcon-pod-c02" err="0/2 nodes are available: falcon-pod-c02 requires 2 gpu but only 0 gpu in the pool.. preemption: 0/2 nodes are available: 2 No preemption victims found for incoming pod.."
E1016 07:53:17.093773       1 schedule_one.go:902] "Error occurred" err="Pod default/falcon-pod-c02 is already present in the active queue"
I1016 07:53:17.098235       1 log.go:194] falcon-pod-c02 in Prefilter
I1016 07:53:17.098253       1 log.go:194] falcon-pod-c02 requires 2 gpu(s), and currently has 0 gpus(s) in total
I1016 07:53:17.102493       1 schedule_one.go:867] "Unable to schedule pod; no fit; waiting" pod="default/falcon-pod-c02" err="0/2 nodes are available: falcon-pod-c02 requires 2 gpu but only 0 gpu in the pool.. preemption: 0/2 nodes are available: 2 No preemption victims found for incoming pod.."
I1016 07:56:45.160538       1 log.go:194] falcon-pod-c02 in Prefilter
I1016 07:56:45.160569       1 log.go:194] falcon-pod-c02 requires 2 gpu(s), and currently has 4 gpus(s) in total
I1016 07:56:45.168678       1 log.go:194] css-host-128 has 0 gpu, falcon-pod-c02 requires 2 gpu -> score: -2
I1016 07:56:45.168731       1 log.go:194] css-host-129 has 4 gpu, falcon-pod-c02 requires 2 gpu -> score: 50
I1016 07:56:45.176131       1 schedule_one.go:252] "Successfully bound pod to node" pod="default/falcon-pod-c02" node="css-host-129" evaluatedNodes=2 feasibleNodes=2
I1016 07:57:00.397595       1 log.go:194] falcon-pod-a05 in Prefilter
I1016 07:57:00.397627       1 log.go:194] falcon-pod-a05 requires 1 gpu(s), and currently has 2 gpus(s) in total
I1016 07:57:00.404872       1 log.go:194] css-host-128 has 0 gpu, falcon-pod-a05 requires 1 gpu -> score: -1
I1016 07:57:00.405001       1 log.go:194] css-host-129 has 2 gpu, falcon-pod-a05 requires 1 gpu -> score: 50
I1016 07:57:00.413143       1 schedule_one.go:252] "Successfully bound pod to node" pod="default/falcon-pod-a05" node="css-host-129" evaluatedNodes=2 feasibleNodes=2
I1016 07:57:09.585429       1 log.go:194] falcon-pod-a04 in Prefilter
I1016 07:57:09.585466       1 log.go:194] falcon-pod-a04 requires 1 gpu(s), and currently has 1 gpus(s) in total
I1016 07:57:09.602688       1 event.go:307] "Event occurred" object="default/falcon-pod-a04" fieldPath="" kind="Pod" apiVersion="v1" type="Normal" reason="Reconfig" message="Pod falcon-pod-a04 needs reconfiguration"
E1016 07:57:49.789547       1 schedule_one.go:883] "Error scheduling pod; retrying" err="" pod="default/falcon-pod-a04"
E1016 07:57:49.789635       1 schedule_one.go:902] "Error occurred" err="Pod default/falcon-pod-a04 is already present in the active queue"
I1016 07:57:49.795171       1 log.go:194] falcon-pod-a04 in Prefilter
I1016 07:57:49.795200       1 log.go:194] falcon-pod-a04 requires 1 gpu(s), and currently has 0 gpus(s) in total
I1016 07:57:49.991230       1 trace.go:219] Trace[1440675069]: "Scheduling" namespace:default,name:falcon-pod-a04 (16-Oct-2023 07:57:49.795) (total time: 196ms):
Trace[1440675069]: ---"Computing predicates done" 196ms (07:57:49.991)
Trace[1440675069]: [196.158129ms] [196.158129ms] END
I1016 07:57:49.991459       1 schedule_one.go:867] "Unable to schedule pod; no fit; waiting" pod="default/falcon-pod-a04" err="0/2 nodes are available: falcon-pod-a04 requires 1 gpu but only 0 gpu in the pool.. preemption: 0/2 nodes are available: 2 No preemption victims found for incoming pod.."
E1016 07:57:49.991586       1 schedule_one.go:902] "Error occurred" err="Pod default/falcon-pod-a04 is already present in the active queue"
I1016 07:57:49.997148       1 log.go:194] falcon-pod-a04 in Prefilter
I1016 07:57:49.997171       1 log.go:194] falcon-pod-a04 requires 1 gpu(s), and currently has 0 gpus(s) in total
I1016 07:57:50.191501       1 trace.go:219] Trace[1561454390]: "Scheduling" namespace:default,name:falcon-pod-a04 (16-Oct-2023 07:57:49.997) (total time: 194ms):
Trace[1561454390]: ---"Computing predicates done" 194ms (07:57:50.191)
Trace[1561454390]: [194.420422ms] [194.420422ms] END
I1016 07:57:50.191648       1 schedule_one.go:867] "Unable to schedule pod; no fit; waiting" pod="default/falcon-pod-a04" err="0/2 nodes are available: falcon-pod-a04 requires 1 gpu but only 0 gpu in the pool.. preemption: 0/2 nodes are available: 2 No preemption victims found for incoming pod.."
E1016 07:57:50.191776       1 schedule_one.go:902] "Error occurred" err="Pod default/falcon-pod-a04 is already present in the active queue"
I1016 07:57:50.197365       1 log.go:194] falcon-pod-a04 in Prefilter
I1016 07:57:50.197392       1 log.go:194] falcon-pod-a04 requires 1 gpu(s), and currently has 0 gpus(s) in total
I1016 07:57:50.390733       1 trace.go:219] Trace[1680488369]: "Scheduling" namespace:default,name:falcon-pod-a04 (16-Oct-2023 07:57:50.197) (total time: 193ms):
Trace[1680488369]: ---"Computing predicates done" 193ms (07:57:50.390)
Trace[1680488369]: [193.428025ms] [193.428025ms] END
I1016 07:57:50.390889       1 schedule_one.go:867] "Unable to schedule pod; no fit; waiting" pod="default/falcon-pod-a04" err="0/2 nodes are available: falcon-pod-a04 requires 1 gpu but only 0 gpu in the pool.. preemption: 0/2 nodes are available: 2 No preemption victims found for incoming pod.."
I1016 07:57:58.068562       1 log.go:194] falcon-pod-a04 in Prefilter
I1016 07:57:58.068596       1 log.go:194] falcon-pod-a04 requires 1 gpu(s), and currently has 1 gpus(s) in total
I1016 07:57:58.082542       1 schedule_one.go:252] "Successfully bound pod to node" pod="default/falcon-pod-a04" node="css-host-128" evaluatedNodes=2 feasibleNodes=1
I1016 07:58:04.773535       1 log.go:194] falcon-pod-b06 in Prefilter
I1016 07:58:04.773582       1 log.go:194] falcon-pod-b06 requires 1 gpu(s), and currently has 0 gpus(s) in total
I1016 07:58:04.779389       1 schedule_one.go:867] "Unable to schedule pod; no fit; waiting" pod="default/falcon-pod-b06" err="0/2 nodes are available: falcon-pod-b06 requires 1 gpu but only 0 gpu in the pool.. preemption: 0/2 nodes are available: 2 No preemption victims found for incoming pod.."
E1016 07:58:04.779487       1 schedule_one.go:902] "Error occurred" err="Pod default/falcon-pod-b06 is already present in the active queue"
I1016 07:58:04.785717       1 log.go:194] falcon-pod-b06 in Prefilter
I1016 07:58:04.785743       1 log.go:194] falcon-pod-b06 requires 1 gpu(s), and currently has 0 gpus(s) in total
I1016 07:58:04.791869       1 schedule_one.go:867] "Unable to schedule pod; no fit; waiting" pod="default/falcon-pod-b06" err="0/2 nodes are available: falcon-pod-b06 requires 1 gpu but only 0 gpu in the pool.. preemption: 0/2 nodes are available: 2 No preemption victims found for incoming pod.."
E1016 07:58:04.792005       1 schedule_one.go:902] "Error occurred" err="Pod default/falcon-pod-b06 is already present in the active queue"
I1016 07:58:04.797170       1 log.go:194] falcon-pod-b06 in Prefilter
I1016 07:58:04.797197       1 log.go:194] falcon-pod-b06 requires 1 gpu(s), and currently has 0 gpus(s) in total
I1016 07:58:04.802713       1 schedule_one.go:867] "Unable to schedule pod; no fit; waiting" pod="default/falcon-pod-b06" err="0/2 nodes are available: falcon-pod-b06 requires 1 gpu but only 0 gpu in the pool.. preemption: 0/2 nodes are available: 2 No preemption victims found for incoming pod.."
I1016 07:58:20.632029       1 log.go:194] falcon-pod-b06 in Prefilter
I1016 07:58:20.632061       1 log.go:194] falcon-pod-b06 requires 1 gpu(s), and currently has 4 gpus(s) in total
I1016 07:58:20.636300       1 log.go:194] css-host-128 has 4 gpu, falcon-pod-b06 requires 1 gpu -> score: 25
I1016 07:58:20.636346       1 log.go:194] css-host-129 has 0 gpu, falcon-pod-b06 requires 1 gpu -> score: -1
I1016 07:58:20.642944       1 schedule_one.go:252] "Successfully bound pod to node" pod="default/falcon-pod-b06" node="css-host-128" evaluatedNodes=2 feasibleNodes=2
I1016 07:58:34.770638       1 log.go:194] falcon-pod-d02 in Prefilter
I1016 07:58:34.770679       1 log.go:194] falcon-pod-d02 requires 4 gpu(s), and currently has 3 gpus(s) in total
I1016 07:58:34.776281       1 schedule_one.go:867] "Unable to schedule pod; no fit; waiting" pod="default/falcon-pod-d02" err="0/2 nodes are available: falcon-pod-d02 requires 4 gpu but only 3 gpu in the pool.. preemption: 0/2 nodes are available: 2 No preemption victims found for incoming pod.."
E1016 07:58:34.776353       1 schedule_one.go:902] "Error occurred" err="Pod default/falcon-pod-d02 is already present in the active queue"
I1016 07:58:34.781319       1 log.go:194] falcon-pod-d02 in Prefilter
I1016 07:58:34.781345       1 log.go:194] falcon-pod-d02 requires 4 gpu(s), and currently has 3 gpus(s) in total
I1016 07:58:34.787658       1 schedule_one.go:867] "Unable to schedule pod; no fit; waiting" pod="default/falcon-pod-d02" err="0/2 nodes are available: falcon-pod-d02 requires 4 gpu but only 3 gpu in the pool.. preemption: 0/2 nodes are available: 2 No preemption victims found for incoming pod.."
I1016 08:02:02.354936       1 log.go:194] falcon-pod-d02 in Prefilter
I1016 08:02:02.354966       1 log.go:194] falcon-pod-d02 requires 4 gpu(s), and currently has 5 gpus(s) in total
I1016 08:02:02.360799       1 log.go:194] css-host-128 has 3 gpu, falcon-pod-d02 requires 4 gpu -> score: -1
I1016 08:02:02.360840       1 log.go:194] css-host-129 has 2 gpu, falcon-pod-d02 requires 4 gpu -> score: -2
I1016 08:02:02.371996       1 event.go:307] "Event occurred" object="default/falcon-pod-d02" fieldPath="" kind="Pod" apiVersion="v1" type="Normal" reason="Reconfig" message="Pod falcon-pod-d02 needs reconfiguration"
E1016 08:02:42.558798       1 schedule_one.go:883] "Error scheduling pod; retrying" err="" pod="default/falcon-pod-d02"
I1016 08:02:45.339142       1 log.go:194] falcon-pod-d02 in Prefilter
I1016 08:02:45.339177       1 log.go:194] falcon-pod-d02 requires 4 gpu(s), and currently has 6 gpus(s) in total
I1016 08:02:45.346161       1 log.go:194] css-host-128 has 4 gpu, falcon-pod-d02 requires 4 gpu -> score: 100
I1016 08:02:45.346202       1 log.go:194] css-host-129 has 2 gpu, falcon-pod-d02 requires 4 gpu -> score: -2
I1016 08:02:45.354101       1 schedule_one.go:252] "Successfully bound pod to node" pod="default/falcon-pod-d02" node="css-host-128" evaluatedNodes=2 feasibleNodes=2
I1016 08:03:00.306037       1 log.go:194] falcon-pod-a01 in Prefilter
I1016 08:03:00.306073       1 log.go:194] falcon-pod-a01 requires 1 gpu(s), and currently has 2 gpus(s) in total
I1016 08:03:00.320279       1 schedule_one.go:252] "Successfully bound pod to node" pod="default/falcon-pod-a01" node="css-host-129" evaluatedNodes=2 feasibleNodes=1
I1016 08:03:09.536708       1 log.go:194] falcon-pod-c04 in Prefilter
I1016 08:03:09.536749       1 log.go:194] falcon-pod-c04 requires 2 gpu(s), and currently has 2 gpus(s) in total
I1016 08:03:09.543461       1 log.go:194] css-host-128 has 1 gpu, falcon-pod-c04 requires 2 gpu -> score: -1
I1016 08:03:09.543496       1 log.go:194] css-host-129 has 1 gpu, falcon-pod-c04 requires 2 gpu -> score: -1
I1016 08:03:09.552923       1 event.go:307] "Event occurred" object="default/falcon-pod-c04" fieldPath="" kind="Pod" apiVersion="v1" type="Normal" reason="Reconfig" message="Pod falcon-pod-c04 needs reconfiguration"
I1016 08:03:46.344579       1 schedule_one.go:252] "Successfully bound pod to node" pod="default/falcon-pod-c04" node="css-host-128" evaluatedNodes=2 feasibleNodes=2
I1016 08:03:59.377145       1 log.go:194] falcon-pod-b04 in Prefilter
I1016 08:03:59.377175       1 log.go:194] falcon-pod-b04 requires 1 gpu(s), and currently has 1 gpus(s) in total
I1016 08:03:59.384884       1 log.go:194] css-host-128 has 1 gpu, falcon-pod-b04 requires 1 gpu -> score: 100
I1016 08:03:59.384925       1 log.go:194] css-host-129 has 0 gpu, falcon-pod-b04 requires 1 gpu -> score: -1
I1016 08:03:59.392570       1 schedule_one.go:252] "Successfully bound pod to node" pod="default/falcon-pod-b04" node="css-host-128" evaluatedNodes=2 feasibleNodes=2
I1016 08:04:06.391032       1 log.go:194] falcon-pod-d06 in Prefilter
I1016 08:04:06.391061       1 log.go:194] falcon-pod-d06 requires 4 gpu(s), and currently has 0 gpus(s) in total
I1016 08:04:06.410163       1 schedule_one.go:867] "Unable to schedule pod; no fit; waiting" pod="default/falcon-pod-d06" err="0/2 nodes are available: falcon-pod-d06 requires 4 gpu but only 0 gpu in the pool.. preemption: 0/2 nodes are available: 2 No preemption victims found for incoming pod.."
E1016 08:04:06.410270       1 schedule_one.go:902] "Error occurred" err="Pod default/falcon-pod-d06 is already present in the active queue"
I1016 08:04:06.416843       1 log.go:194] falcon-pod-d06 in Prefilter
I1016 08:04:06.416862       1 log.go:194] falcon-pod-d06 requires 4 gpu(s), and currently has 0 gpus(s) in total
I1016 08:04:06.422648       1 schedule_one.go:867] "Unable to schedule pod; no fit; waiting" pod="default/falcon-pod-d06" err="0/2 nodes are available: falcon-pod-d06 requires 4 gpu but only 0 gpu in the pool.. preemption: 0/2 nodes are available: 2 No preemption victims found for incoming pod.."
E1016 08:04:06.422725       1 schedule_one.go:902] "Error occurred" err="Pod default/falcon-pod-d06 is already present in the active queue"
I1016 08:04:06.426966       1 log.go:194] falcon-pod-d06 in Prefilter
I1016 08:04:06.426983       1 log.go:194] falcon-pod-d06 requires 4 gpu(s), and currently has 0 gpus(s) in total
I1016 08:04:06.432423       1 schedule_one.go:867] "Unable to schedule pod; no fit; waiting" pod="default/falcon-pod-d06" err="0/2 nodes are available: falcon-pod-d06 requires 4 gpu but only 0 gpu in the pool.. preemption: 0/2 nodes are available: 2 No preemption victims found for incoming pod.."
I1016 08:08:04.564620       1 log.go:194] falcon-pod-d06 in Prefilter
I1016 08:08:04.564653       1 log.go:194] falcon-pod-d06 requires 4 gpu(s), and currently has 4 gpus(s) in total
I1016 08:08:04.572053       1 log.go:194] css-host-129 has 0 gpu, falcon-pod-d06 requires 4 gpu -> score: -4
I1016 08:08:04.572148       1 log.go:194] css-host-128 has 4 gpu, falcon-pod-d06 requires 4 gpu -> score: 100
I1016 08:08:04.580220       1 schedule_one.go:252] "Successfully bound pod to node" pod="default/falcon-pod-d06" node="css-host-128" evaluatedNodes=2 feasibleNodes=2
I1016 08:08:18.946049       1 log.go:194] falcon-pod-c05 in Prefilter
I1016 08:08:18.946079       1 log.go:194] falcon-pod-c05 requires 2 gpu(s), and currently has 1 gpus(s) in total
I1016 08:08:18.953691       1 schedule_one.go:867] "Unable to schedule pod; no fit; waiting" pod="default/falcon-pod-c05" err="0/2 nodes are available: falcon-pod-c05 requires 2 gpu but only 1 gpu in the pool.. preemption: 0/2 nodes are available: 2 No preemption victims found for incoming pod.."
E1016 08:08:18.953768       1 schedule_one.go:902] "Error occurred" err="Pod default/falcon-pod-c05 is already present in the active queue"
I1016 08:08:18.958876       1 log.go:194] falcon-pod-c05 in Prefilter
I1016 08:08:18.958894       1 log.go:194] falcon-pod-c05 requires 2 gpu(s), and currently has 1 gpus(s) in total
I1016 08:08:18.964638       1 schedule_one.go:867] "Unable to schedule pod; no fit; waiting" pod="default/falcon-pod-c05" err="0/2 nodes are available: falcon-pod-c05 requires 2 gpu but only 1 gpu in the pool.. preemption: 0/2 nodes are available: 2 No preemption victims found for incoming pod.."
I1016 08:09:01.830919       1 log.go:194] falcon-pod-c05 in Prefilter
I1016 08:09:01.830947       1 log.go:194] falcon-pod-c05 requires 2 gpu(s), and currently has 3 gpus(s) in total
I1016 08:09:01.838176       1 log.go:194] css-host-128 has 2 gpu, falcon-pod-c05 requires 2 gpu -> score: 100
I1016 08:09:01.838226       1 log.go:194] css-host-129 has 1 gpu, falcon-pod-c05 requires 2 gpu -> score: -1
I1016 08:09:01.846363       1 schedule_one.go:252] "Successfully bound pod to node" pod="default/falcon-pod-c05" node="css-host-128" evaluatedNodes=2 feasibleNodes=2
I1016 08:09:13.142834       1 log.go:194] falcon-pod-b03 in Prefilter
I1016 08:09:13.142863       1 log.go:194] falcon-pod-b03 requires 1 gpu(s), and currently has 1 gpus(s) in total
I1016 08:09:13.150603       1 log.go:194] css-host-128 has 0 gpu, falcon-pod-b03 requires 1 gpu -> score: -1
I1016 08:09:13.150645       1 log.go:194] css-host-129 has 1 gpu, falcon-pod-b03 requires 1 gpu -> score: 100
I1016 08:09:13.159230       1 schedule_one.go:252] "Successfully bound pod to node" pod="default/falcon-pod-b03" node="css-host-129" evaluatedNodes=2 feasibleNodes=2
I1016 08:09:20.182963       1 log.go:194] falcon-pod-e01 in Prefilter
I1016 08:09:20.182993       1 log.go:194] falcon-pod-e01 requires 8 gpu(s), and currently has 1 gpus(s) in total
I1016 08:09:20.189652       1 schedule_one.go:867] "Unable to schedule pod; no fit; waiting" pod="default/falcon-pod-e01" err="0/2 nodes are available: falcon-pod-e01 requires 8 gpu but only 1 gpu in the pool.. preemption: 0/2 nodes are available: 2 No preemption victims found for incoming pod.."
E1016 08:09:20.189770       1 schedule_one.go:902] "Error occurred" err="Pod default/falcon-pod-e01 is already present in the active queue"
I1016 08:09:20.195794       1 log.go:194] falcon-pod-e01 in Prefilter
I1016 08:09:20.195857       1 log.go:194] falcon-pod-e01 requires 8 gpu(s), and currently has 1 gpus(s) in total
I1016 08:09:20.201270       1 schedule_one.go:867] "Unable to schedule pod; no fit; waiting" pod="default/falcon-pod-e01" err="0/2 nodes are available: falcon-pod-e01 requires 8 gpu but only 1 gpu in the pool.. preemption: 0/2 nodes are available: 2 No preemption victims found for incoming pod.."
E1016 08:09:20.201337       1 schedule_one.go:902] "Error occurred" err="Pod default/falcon-pod-e01 is already present in the active queue"
I1016 08:09:20.205360       1 log.go:194] falcon-pod-e01 in Prefilter
I1016 08:09:20.205379       1 log.go:194] falcon-pod-e01 requires 8 gpu(s), and currently has 1 gpus(s) in total
I1016 08:09:20.210881       1 schedule_one.go:867] "Unable to schedule pod; no fit; waiting" pod="default/falcon-pod-e01" err="0/2 nodes are available: falcon-pod-e01 requires 8 gpu but only 1 gpu in the pool.. preemption: 0/2 nodes are available: 2 No preemption victims found for incoming pod.."
I1016 08:13:22.902383       1 log.go:194] falcon-pod-e01 in Prefilter
I1016 08:13:22.902412       1 log.go:194] falcon-pod-e01 requires 8 gpu(s), and currently has 5 gpus(s) in total
I1016 08:13:22.910509       1 schedule_one.go:867] "Unable to schedule pod; no fit; waiting" pod="default/falcon-pod-e01" err="0/2 nodes are available: falcon-pod-e01 requires 8 gpu but only 5 gpu in the pool.. preemption: 0/2 nodes are available: 2 No preemption victims found for incoming pod.."
I1016 08:14:14.643822       1 log.go:194] falcon-pod-e01 in Prefilter
I1016 08:14:14.643855       1 log.go:194] falcon-pod-e01 requires 8 gpu(s), and currently has 7 gpus(s) in total
I1016 08:14:14.648942       1 schedule_one.go:867] "Unable to schedule pod; no fit; waiting" pod="default/falcon-pod-e01" err="0/2 nodes are available: falcon-pod-e01 requires 8 gpu but only 7 gpu in the pool.. preemption: 0/2 nodes are available: 2 No preemption victims found for incoming pod.."
I1016 08:14:20.904092       1 log.go:194] falcon-pod-e01 in Prefilter
I1016 08:14:20.904121       1 log.go:194] falcon-pod-e01 requires 8 gpu(s), and currently has 8 gpus(s) in total
I1016 08:14:20.911231       1 log.go:194] css-host-128 has 7 gpu, falcon-pod-e01 requires 8 gpu -> score: -1
I1016 08:14:20.911272       1 log.go:194] css-host-129 has 1 gpu, falcon-pod-e01 requires 8 gpu -> score: -7
I1016 08:14:20.923162       1 event.go:307] "Event occurred" object="default/falcon-pod-e01" fieldPath="" kind="Pod" apiVersion="v1" type="Normal" reason="Reconfig" message="Pod falcon-pod-e01 needs reconfiguration"
I1016 08:14:49.712623       1 schedule_one.go:252] "Successfully bound pod to node" pod="default/falcon-pod-e01" node="css-host-128" evaluatedNodes=2 feasibleNodes=2
I1016 08:15:16.488479       1 log.go:194] falcon-pod-b02 in Prefilter
I1016 08:15:16.488512       1 log.go:194] falcon-pod-b02 requires 1 gpu(s), and currently has 0 gpus(s) in total
I1016 08:15:16.495788       1 schedule_one.go:867] "Unable to schedule pod; no fit; waiting" pod="default/falcon-pod-b02" err="0/2 nodes are available: falcon-pod-b02 requires 1 gpu but only 0 gpu in the pool.. preemption: 0/2 nodes are available: 2 No preemption victims found for incoming pod.."
E1016 08:15:16.495892       1 schedule_one.go:902] "Error occurred" err="Pod default/falcon-pod-b02 is already present in the active queue"
I1016 08:15:16.501494       1 log.go:194] falcon-pod-b02 in Prefilter
I1016 08:15:16.501514       1 log.go:194] falcon-pod-b02 requires 1 gpu(s), and currently has 0 gpus(s) in total
I1016 08:15:16.506782       1 schedule_one.go:867] "Unable to schedule pod; no fit; waiting" pod="default/falcon-pod-b02" err="0/2 nodes are available: falcon-pod-b02 requires 1 gpu but only 0 gpu in the pool.. preemption: 0/2 nodes are available: 2 No preemption victims found for incoming pod.."
I1016 08:20:23.953251       1 log.go:194] falcon-pod-b02 in Prefilter
I1016 08:20:23.953290       1 log.go:194] falcon-pod-b02 requires 1 gpu(s), and currently has 8 gpus(s) in total
I1016 08:20:23.960448       1 log.go:194] css-host-129 has 0 gpu, falcon-pod-b02 requires 1 gpu -> score: -1
I1016 08:20:23.960477       1 log.go:194] css-host-128 has 8 gpu, falcon-pod-b02 requires 1 gpu -> score: 12
I1016 08:20:23.969614       1 schedule_one.go:252] "Successfully bound pod to node" pod="default/falcon-pod-b02" node="css-host-128" evaluatedNodes=2 feasibleNodes=2
I1016 08:20:49.916679       1 log.go:194] falcon-pod-c01 in Prefilter
I1016 08:20:49.916711       1 log.go:194] falcon-pod-c01 requires 2 gpu(s), and currently has 7 gpus(s) in total
I1016 08:20:49.923099       1 log.go:194] css-host-128 has 7 gpu, falcon-pod-c01 requires 2 gpu -> score: 28
I1016 08:20:49.923133       1 log.go:194] css-host-129 has 0 gpu, falcon-pod-c01 requires 2 gpu -> score: -2
I1016 08:20:49.930910       1 schedule_one.go:252] "Successfully bound pod to node" pod="default/falcon-pod-c01" node="css-host-128" evaluatedNodes=2 feasibleNodes=2
I1016 08:21:12.311123       1 log.go:194] falcon-pod-a06 in Prefilter
I1016 08:21:12.311158       1 log.go:194] falcon-pod-a06 requires 1 gpu(s), and currently has 5 gpus(s) in total
I1016 08:21:12.317263       1 log.go:194] css-host-128 has 5 gpu, falcon-pod-a06 requires 1 gpu -> score: 20
I1016 08:21:12.317307       1 log.go:194] css-host-129 has 0 gpu, falcon-pod-a06 requires 1 gpu -> score: -1
I1016 08:21:12.325324       1 schedule_one.go:252] "Successfully bound pod to node" pod="default/falcon-pod-a06" node="css-host-128" evaluatedNodes=2 feasibleNodes=2
I1016 08:21:30.353850       1 log.go:194] falcon-pod-a02 in Prefilter
I1016 08:21:30.353878       1 log.go:194] falcon-pod-a02 requires 1 gpu(s), and currently has 4 gpus(s) in total
I1016 08:21:30.370859       1 event.go:307] "Event occurred" object="default/falcon-pod-a02" fieldPath="" kind="Pod" apiVersion="v1" type="Normal" reason="Reconfig" message="Pod falcon-pod-a02 needs reconfiguration"
I1016 08:22:05.362426       1 schedule_one.go:252] "Successfully bound pod to node" pod="default/falcon-pod-a02" node="css-host-129" evaluatedNodes=2 feasibleNodes=1
I1016 14:04:27.179891       1 log.go:194] falcon-pod-c02 in Prefilter
I1016 14:04:27.179935       1 log.go:194] falcon-pod-c02 requires 2 gpu(s), and currently has 8 gpus(s) in total
I1016 14:04:27.187146       1 log.go:194] css-host-128 has 4 gpu, falcon-pod-c02 requires 2 gpu -> score: 50
I1016 14:04:27.187180       1 log.go:194] css-host-129 has 4 gpu, falcon-pod-c02 requires 2 gpu -> score: 50
I1016 14:04:27.193857       1 schedule_one.go:252] "Successfully bound pod to node" pod="default/falcon-pod-c02" node="css-host-129" evaluatedNodes=2 feasibleNodes=2
I1016 14:04:51.214463       1 log.go:194] falcon-pod-b04 in Prefilter
I1016 14:04:51.214507       1 log.go:194] falcon-pod-b04 requires 1 gpu(s), and currently has 6 gpus(s) in total
I1016 14:04:51.221268       1 log.go:194] css-host-128 has 4 gpu, falcon-pod-b04 requires 1 gpu -> score: 25
I1016 14:04:51.221299       1 log.go:194] css-host-129 has 2 gpu, falcon-pod-b04 requires 1 gpu -> score: 50
I1016 14:04:51.229787       1 schedule_one.go:252] "Successfully bound pod to node" pod="default/falcon-pod-b04" node="css-host-129" evaluatedNodes=2 feasibleNodes=2
I1016 14:05:20.239801       1 log.go:194] falcon-pod-b05 in Prefilter
I1016 14:05:20.239833       1 log.go:194] falcon-pod-b05 requires 1 gpu(s), and currently has 5 gpus(s) in total
I1016 14:05:20.246603       1 log.go:194] css-host-129 has 1 gpu, falcon-pod-b05 requires 1 gpu -> score: 100
I1016 14:05:20.246636       1 log.go:194] css-host-128 has 4 gpu, falcon-pod-b05 requires 1 gpu -> score: 25
I1016 14:05:20.253590       1 schedule_one.go:252] "Successfully bound pod to node" pod="default/falcon-pod-b05" node="css-host-129" evaluatedNodes=2 feasibleNodes=2
I1016 14:05:54.282918       1 log.go:194] falcon-pod-c04 in Prefilter
I1016 14:05:54.282968       1 log.go:194] falcon-pod-c04 requires 2 gpu(s), and currently has 4 gpus(s) in total
I1016 14:05:54.289773       1 log.go:194] css-host-129 has 0 gpu, falcon-pod-c04 requires 2 gpu -> score: -2
I1016 14:05:54.289874       1 log.go:194] css-host-128 has 4 gpu, falcon-pod-c04 requires 2 gpu -> score: 50
I1016 14:05:54.297643       1 schedule_one.go:252] "Successfully bound pod to node" pod="default/falcon-pod-c04" node="css-host-128" evaluatedNodes=2 feasibleNodes=2
I1016 14:06:25.309341       1 log.go:194] falcon-pod-a03 in Prefilter
I1016 14:06:25.309379       1 log.go:194] falcon-pod-a03 requires 1 gpu(s), and currently has 2 gpus(s) in total
I1016 14:06:25.321878       1 schedule_one.go:252] "Successfully bound pod to node" pod="default/falcon-pod-a03" node="css-host-128" evaluatedNodes=2 feasibleNodes=1
I1016 14:07:01.332168       1 log.go:194] falcon-pod-c10 in Prefilter
I1016 14:07:01.332203       1 log.go:194] falcon-pod-c10 requires 2 gpu(s), and currently has 1 gpus(s) in total
I1016 14:07:01.339163       1 schedule_one.go:867] "Unable to schedule pod; no fit; waiting" pod="default/falcon-pod-c10" err="0/2 nodes are available: falcon-pod-c10 requires 2 gpu but only 1 gpu in the pool.. preemption: 0/2 nodes are available: 2 No preemption victims found for incoming pod.."
E1016 14:07:01.339242       1 schedule_one.go:902] "Error occurred" err="Pod default/falcon-pod-c10 is already present in the active queue"
I1016 14:07:01.344595       1 log.go:194] falcon-pod-c10 in Prefilter
I1016 14:07:01.344619       1 log.go:194] falcon-pod-c10 requires 2 gpu(s), and currently has 1 gpus(s) in total
I1016 14:07:01.348909       1 schedule_one.go:867] "Unable to schedule pod; no fit; waiting" pod="default/falcon-pod-c10" err="0/2 nodes are available: falcon-pod-c10 requires 2 gpu but only 1 gpu in the pool.. preemption: 0/2 nodes are available: 2 No preemption victims found for incoming pod.."
I1016 14:09:44.471207       1 log.go:194] falcon-pod-c10 in Prefilter
I1016 14:09:44.471235       1 log.go:194] falcon-pod-c10 requires 2 gpu(s), and currently has 3 gpus(s) in total
I1016 14:09:44.477920       1 log.go:194] css-host-128 has 1 gpu, falcon-pod-c10 requires 2 gpu -> score: -1
I1016 14:09:44.477961       1 log.go:194] css-host-129 has 2 gpu, falcon-pod-c10 requires 2 gpu -> score: 100
I1016 14:09:44.484675       1 schedule_one.go:252] "Successfully bound pod to node" pod="default/falcon-pod-c10" node="css-host-129" evaluatedNodes=2 feasibleNodes=2
I1016 14:09:53.476477       1 log.go:194] falcon-pod-c08 in Prefilter
I1016 14:09:53.476514       1 log.go:194] falcon-pod-c08 requires 2 gpu(s), and currently has 1 gpus(s) in total
I1016 14:09:53.481537       1 schedule_one.go:867] "Unable to schedule pod; no fit; waiting" pod="default/falcon-pod-c08" err="0/2 nodes are available: falcon-pod-c08 requires 2 gpu but only 1 gpu in the pool.. preemption: 0/2 nodes are available: 2 No preemption victims found for incoming pod.."
E1016 14:09:53.481624       1 schedule_one.go:902] "Error occurred" err="Pod default/falcon-pod-c08 is already present in the active queue"
I1016 14:09:53.487136       1 log.go:194] falcon-pod-c08 in Prefilter
I1016 14:09:53.487161       1 log.go:194] falcon-pod-c08 requires 2 gpu(s), and currently has 1 gpus(s) in total
I1016 14:09:53.493562       1 schedule_one.go:867] "Unable to schedule pod; no fit; waiting" pod="default/falcon-pod-c08" err="0/2 nodes are available: falcon-pod-c08 requires 2 gpu but only 1 gpu in the pool.. preemption: 0/2 nodes are available: 2 No preemption victims found for incoming pod.."
I1016 14:10:01.561241       1 log.go:194] falcon-pod-c08 in Prefilter
I1016 14:10:01.561272       1 log.go:194] falcon-pod-c08 requires 2 gpu(s), and currently has 2 gpus(s) in total
I1016 14:10:01.567857       1 log.go:194] css-host-128 has 1 gpu, falcon-pod-c08 requires 2 gpu -> score: -1
I1016 14:10:01.567903       1 log.go:194] css-host-129 has 1 gpu, falcon-pod-c08 requires 2 gpu -> score: -1
I1016 14:10:01.579268       1 event.go:307] "Event occurred" object="default/falcon-pod-c08" fieldPath="" kind="Pod" apiVersion="v1" type="Normal" reason="Reconfig" message="Pod falcon-pod-c08 needs reconfiguration"
E1016 14:10:41.765533       1 schedule_one.go:883] "Error scheduling pod; retrying" err="" pod="default/falcon-pod-c08"
I1016 14:10:44.030140       1 log.go:194] falcon-pod-c08 in Prefilter
I1016 14:10:44.030179       1 log.go:194] falcon-pod-c08 requires 2 gpu(s), and currently has 2 gpus(s) in total
I1016 14:10:44.037064       1 log.go:194] css-host-128 has 0 gpu, falcon-pod-c08 requires 2 gpu -> score: -2
I1016 14:10:44.037103       1 log.go:194] css-host-129 has 2 gpu, falcon-pod-c08 requires 2 gpu -> score: 100
I1016 14:10:44.043531       1 schedule_one.go:252] "Successfully bound pod to node" pod="default/falcon-pod-c08" node="css-host-129" evaluatedNodes=2 feasibleNodes=2
I1016 14:10:57.225979       1 log.go:194] falcon-pod-a01 in Prefilter
I1016 14:10:57.226009       1 log.go:194] falcon-pod-a01 requires 1 gpu(s), and currently has 1 gpus(s) in total
I1016 14:10:57.240135       1 schedule_one.go:252] "Successfully bound pod to node" pod="default/falcon-pod-a01" node="css-host-129" evaluatedNodes=2 feasibleNodes=1
I1016 14:11:04.187141       1 log.go:194] falcon-pod-b01 in Prefilter
I1016 14:11:04.187172       1 log.go:194] falcon-pod-b01 requires 1 gpu(s), and currently has 0 gpus(s) in total
I1016 14:11:04.194082       1 schedule_one.go:867] "Unable to schedule pod; no fit; waiting" pod="default/falcon-pod-b01" err="0/2 nodes are available: falcon-pod-b01 requires 1 gpu but only 0 gpu in the pool.. preemption: 0/2 nodes are available: 2 No preemption victims found for incoming pod.."
E1016 14:11:04.194154       1 schedule_one.go:902] "Error occurred" err="Pod default/falcon-pod-b01 is already present in the active queue"
I1016 14:11:04.199063       1 log.go:194] falcon-pod-b01 in Prefilter
I1016 14:11:04.199087       1 log.go:194] falcon-pod-b01 requires 1 gpu(s), and currently has 0 gpus(s) in total
I1016 14:11:04.205101       1 schedule_one.go:867] "Unable to schedule pod; no fit; waiting" pod="default/falcon-pod-b01" err="0/2 nodes are available: falcon-pod-b01 requires 1 gpu but only 0 gpu in the pool.. preemption: 0/2 nodes are available: 2 No preemption victims found for incoming pod.."
E1016 14:11:04.205168       1 schedule_one.go:902] "Error occurred" err="Pod default/falcon-pod-b01 is already present in the active queue"
I1016 14:11:04.209684       1 log.go:194] falcon-pod-b01 in Prefilter
I1016 14:11:04.209703       1 log.go:194] falcon-pod-b01 requires 1 gpu(s), and currently has 0 gpus(s) in total
I1016 14:11:04.214574       1 schedule_one.go:867] "Unable to schedule pod; no fit; waiting" pod="default/falcon-pod-b01" err="0/2 nodes are available: falcon-pod-b01 requires 1 gpu but only 0 gpu in the pool.. preemption: 0/2 nodes are available: 2 No preemption victims found for incoming pod.."
I1016 14:11:10.646863       1 log.go:194] falcon-pod-b01 in Prefilter
I1016 14:11:10.646894       1 log.go:194] falcon-pod-b01 requires 1 gpu(s), and currently has 2 gpus(s) in total
I1016 14:11:10.660964       1 schedule_one.go:252] "Successfully bound pod to node" pod="default/falcon-pod-b01" node="css-host-128" evaluatedNodes=2 feasibleNodes=1
I1016 14:11:19.903389       1 log.go:194] falcon-pod-a02 in Prefilter
I1016 14:11:19.903414       1 log.go:194] falcon-pod-a02 requires 1 gpu(s), and currently has 1 gpus(s) in total
I1016 14:11:19.908589       1 schedule_one.go:867] "Unable to schedule pod; no fit; waiting" pod="default/falcon-pod-a02" err="0/2 nodes are available: 2 Insufficient cpu. preemption: 0/2 nodes are available: 2 No preemption victims found for incoming pod.."
E1016 14:11:19.908651       1 schedule_one.go:902] "Error occurred" err="Pod default/falcon-pod-a02 is already present in the active queue"
I1016 14:11:19.913399       1 log.go:194] falcon-pod-a02 in Prefilter
I1016 14:11:19.913421       1 log.go:194] falcon-pod-a02 requires 1 gpu(s), and currently has 1 gpus(s) in total
I1016 14:11:19.919294       1 schedule_one.go:867] "Unable to schedule pod; no fit; waiting" pod="default/falcon-pod-a02" err="0/2 nodes are available: 2 Insufficient cpu. preemption: 0/2 nodes are available: 2 No preemption victims found for incoming pod.."
E1016 14:11:19.919351       1 schedule_one.go:902] "Error occurred" err="Pod default/falcon-pod-a02 is already present in the active queue"
I1016 14:11:19.924018       1 log.go:194] falcon-pod-a02 in Prefilter
I1016 14:11:19.924039       1 log.go:194] falcon-pod-a02 requires 1 gpu(s), and currently has 1 gpus(s) in total
I1016 14:11:19.928992       1 schedule_one.go:867] "Unable to schedule pod; no fit; waiting" pod="default/falcon-pod-a02" err="0/2 nodes are available: 2 Insufficient cpu. preemption: 0/2 nodes are available: 2 No preemption victims found for incoming pod.."
I1016 14:11:35.576611       1 log.go:194] falcon-pod-a02 in Prefilter
I1016 14:11:35.576644       1 log.go:194] falcon-pod-a02 requires 1 gpu(s), and currently has 2 gpus(s) in total
I1016 14:11:35.590454       1 schedule_one.go:252] "Successfully bound pod to node" pod="default/falcon-pod-a02" node="css-host-128" evaluatedNodes=2 feasibleNodes=1
I1016 14:11:44.386791       1 log.go:194] falcon-pod-a05 in Prefilter
I1016 14:11:44.386819       1 log.go:194] falcon-pod-a05 requires 1 gpu(s), and currently has 1 gpus(s) in total
I1016 14:11:44.392982       1 schedule_one.go:867] "Unable to schedule pod; no fit; waiting" pod="default/falcon-pod-a05" err="0/2 nodes are available: 2 Insufficient cpu. preemption: 0/2 nodes are available: 2 No preemption victims found for incoming pod.."
E1016 14:11:44.393054       1 schedule_one.go:902] "Error occurred" err="Pod default/falcon-pod-a05 is already present in the active queue"
I1016 14:11:44.397314       1 log.go:194] falcon-pod-a05 in Prefilter
I1016 14:11:44.397337       1 log.go:194] falcon-pod-a05 requires 1 gpu(s), and currently has 1 gpus(s) in total
I1016 14:11:44.402355       1 schedule_one.go:867] "Unable to schedule pod; no fit; waiting" pod="default/falcon-pod-a05" err="0/2 nodes are available: 2 Insufficient cpu. preemption: 0/2 nodes are available: 2 No preemption victims found for incoming pod.."
I1016 14:14:56.393873       1 log.go:194] falcon-pod-a05 in Prefilter
I1016 14:14:56.393904       1 log.go:194] falcon-pod-a05 requires 1 gpu(s), and currently has 3 gpus(s) in total
I1016 14:14:56.400635       1 schedule_one.go:867] "Unable to schedule pod; no fit; waiting" pod="default/falcon-pod-a05" err="0/2 nodes are available: 2 Insufficient cpu. preemption: 0/2 nodes are available: 2 No preemption victims found for incoming pod.."
I1016 14:15:58.751927       1 log.go:194] falcon-pod-a05 in Prefilter
I1016 14:15:58.751962       1 log.go:194] falcon-pod-a05 requires 1 gpu(s), and currently has 5 gpus(s) in total
I1016 14:15:58.763999       1 schedule_one.go:252] "Successfully bound pod to node" pod="default/falcon-pod-a05" node="css-host-129" evaluatedNodes=2 feasibleNodes=1
I1016 14:16:15.681727       1 log.go:194] falcon-pod-c07 in Prefilter
I1016 14:16:15.681756       1 log.go:194] falcon-pod-c07 requires 2 gpu(s), and currently has 4 gpus(s) in total
I1016 14:16:15.699391       1 event.go:307] "Event occurred" object="default/falcon-pod-c07" fieldPath="" kind="Pod" apiVersion="v1" type="Normal" reason="Reconfig" message="Pod falcon-pod-c07 needs reconfiguration"
E1016 14:16:55.886275       1 schedule_one.go:883] "Error scheduling pod; retrying" err="" pod="default/falcon-pod-c07"
E1016 14:16:55.886445       1 schedule_one.go:902] "Error occurred" err="Pod default/falcon-pod-c07 is already present in the active queue"
I1016 14:16:55.893414       1 log.go:194] falcon-pod-c07 in Prefilter
I1016 14:16:55.893442       1 log.go:194] falcon-pod-c07 requires 2 gpu(s), and currently has 6 gpus(s) in total
I1016 14:16:56.089297       1 log.go:194] css-host-128 has 3 gpu, falcon-pod-c07 requires 2 gpu -> score: 66
I1016 14:16:56.089411       1 log.go:194] css-host-129 has 3 gpu, falcon-pod-c07 requires 2 gpu -> score: 66
I1016 14:16:56.089703       1 trace.go:219] Trace[1182905000]: "Scheduling" namespace:default,name:falcon-pod-c07 (16-Oct-2023 14:16:55.893) (total time: 196ms):
Trace[1182905000]: ---"Computing predicates done" 195ms (14:16:56.089)
Trace[1182905000]: [196.436459ms] [196.436459ms] END
I1016 14:16:56.289687       1 schedule_one.go:252] "Successfully bound pod to node" pod="default/falcon-pod-c07" node="css-host-128" evaluatedNodes=2 feasibleNodes=2
I1016 14:17:11.876164       1 log.go:194] falcon-pod-b02 in Prefilter
I1016 14:17:11.876199       1 log.go:194] falcon-pod-b02 requires 1 gpu(s), and currently has 5 gpus(s) in total
I1016 14:17:11.890557       1 log.go:194] css-host-128 has 2 gpu, falcon-pod-b02 requires 1 gpu -> score: 50
I1016 14:17:11.890639       1 log.go:194] css-host-129 has 3 gpu, falcon-pod-b02 requires 1 gpu -> score: 33
I1016 14:17:11.901960       1 schedule_one.go:252] "Successfully bound pod to node" pod="default/falcon-pod-b02" node="css-host-128" evaluatedNodes=2 feasibleNodes=2
I1016 14:17:21.051800       1 log.go:194] falcon-pod-c03 in Prefilter
I1016 14:17:21.051836       1 log.go:194] falcon-pod-c03 requires 2 gpu(s), and currently has 4 gpus(s) in total
I1016 14:17:21.059161       1 log.go:194] css-host-128 has 1 gpu, falcon-pod-c03 requires 2 gpu -> score: -1
I1016 14:17:21.059185       1 log.go:194] css-host-129 has 3 gpu, falcon-pod-c03 requires 2 gpu -> score: 66
I1016 14:17:21.066708       1 schedule_one.go:252] "Successfully bound pod to node" pod="default/falcon-pod-c03" node="css-host-129" evaluatedNodes=2 feasibleNodes=2
I1016 14:17:32.438857       1 log.go:194] falcon-pod-b03 in Prefilter
I1016 14:17:32.438882       1 log.go:194] falcon-pod-b03 requires 1 gpu(s), and currently has 2 gpus(s) in total
I1016 14:17:32.446291       1 log.go:194] css-host-128 has 1 gpu, falcon-pod-b03 requires 1 gpu -> score: 100
I1016 14:17:32.446324       1 log.go:194] css-host-129 has 1 gpu, falcon-pod-b03 requires 1 gpu -> score: 100
I1016 14:17:32.453510       1 schedule_one.go:252] "Successfully bound pod to node" pod="default/falcon-pod-b03" node="css-host-128" evaluatedNodes=2 feasibleNodes=2
I1016 14:17:39.445490       1 log.go:194] falcon-pod-a04 in Prefilter
I1016 14:17:39.445527       1 log.go:194] falcon-pod-a04 requires 1 gpu(s), and currently has 1 gpus(s) in total
I1016 14:17:39.453621       1 schedule_one.go:867] "Unable to schedule pod; no fit; waiting" pod="default/falcon-pod-a04" err="0/2 nodes are available: 2 Insufficient cpu. preemption: 0/2 nodes are available: 2 No preemption victims found for incoming pod.."
E1016 14:17:39.453700       1 schedule_one.go:902] "Error occurred" err="Pod default/falcon-pod-a04 is already present in the active queue"
I1016 14:17:39.459964       1 log.go:194] falcon-pod-a04 in Prefilter
I1016 14:17:39.459986       1 log.go:194] falcon-pod-a04 requires 1 gpu(s), and currently has 1 gpus(s) in total
I1016 14:17:39.465684       1 schedule_one.go:867] "Unable to schedule pod; no fit; waiting" pod="default/falcon-pod-a04" err="0/2 nodes are available: 2 Insufficient cpu. preemption: 0/2 nodes are available: 2 No preemption victims found for incoming pod.."
I1016 14:21:16.130361       1 log.go:194] falcon-pod-a04 in Prefilter
I1016 14:21:16.130400       1 log.go:194] falcon-pod-a04 requires 1 gpu(s), and currently has 2 gpus(s) in total
I1016 14:21:16.144592       1 schedule_one.go:252] "Successfully bound pod to node" pod="default/falcon-pod-a04" node="css-host-129" evaluatedNodes=2 feasibleNodes=1
I1016 14:21:25.502908       1 log.go:194] falcon-pod-c06 in Prefilter
I1016 14:21:25.502939       1 log.go:194] falcon-pod-c06 requires 2 gpu(s), and currently has 1 gpus(s) in total
I1016 14:21:25.509386       1 schedule_one.go:867] "Unable to schedule pod; no fit; waiting" pod="default/falcon-pod-c06" err="0/2 nodes are available: falcon-pod-c06 requires 2 gpu but only 1 gpu in the pool.. preemption: 0/2 nodes are available: 2 No preemption victims found for incoming pod.."
E1016 14:21:25.509514       1 schedule_one.go:902] "Error occurred" err="Pod default/falcon-pod-c06 is already present in the active queue"
I1016 14:21:25.515223       1 log.go:194] falcon-pod-c06 in Prefilter
I1016 14:21:25.515252       1 log.go:194] falcon-pod-c06 requires 2 gpu(s), and currently has 1 gpus(s) in total
I1016 14:21:25.520511       1 schedule_one.go:867] "Unable to schedule pod; no fit; waiting" pod="default/falcon-pod-c06" err="0/2 nodes are available: falcon-pod-c06 requires 2 gpu but only 1 gpu in the pool.. preemption: 0/2 nodes are available: 2 No preemption victims found for incoming pod.."
I1016 14:22:13.794827       1 log.go:194] falcon-pod-c06 in Prefilter
I1016 14:22:13.794857       1 log.go:194] falcon-pod-c06 requires 2 gpu(s), and currently has 3 gpus(s) in total
I1016 14:22:13.800230       1 log.go:194] css-host-128 has 2 gpu, falcon-pod-c06 requires 2 gpu -> score: 100
I1016 14:22:13.800269       1 log.go:194] css-host-129 has 1 gpu, falcon-pod-c06 requires 2 gpu -> score: -1
I1016 14:22:13.807762       1 schedule_one.go:252] "Successfully bound pod to node" pod="default/falcon-pod-c06" node="css-host-128" evaluatedNodes=2 feasibleNodes=2
I1016 14:22:22.953862       1 log.go:194] falcon-pod-c01 in Prefilter
I1016 14:22:22.953891       1 log.go:194] falcon-pod-c01 requires 2 gpu(s), and currently has 1 gpus(s) in total
I1016 14:22:22.960266       1 schedule_one.go:867] "Unable to schedule pod; no fit; waiting" pod="default/falcon-pod-c01" err="0/2 nodes are available: falcon-pod-c01 requires 2 gpu but only 1 gpu in the pool.. preemption: 0/2 nodes are available: 2 No preemption victims found for incoming pod.."
E1016 14:22:22.960356       1 schedule_one.go:902] "Error occurred" err="Pod default/falcon-pod-c01 is already present in the active queue"
I1016 14:22:22.966105       1 log.go:194] falcon-pod-c01 in Prefilter
I1016 14:22:22.966124       1 log.go:194] falcon-pod-c01 requires 2 gpu(s), and currently has 1 gpus(s) in total
I1016 14:22:22.971530       1 schedule_one.go:867] "Unable to schedule pod; no fit; waiting" pod="default/falcon-pod-c01" err="0/2 nodes are available: falcon-pod-c01 requires 2 gpu but only 1 gpu in the pool.. preemption: 0/2 nodes are available: 2 No preemption victims found for incoming pod.."
I1016 14:22:23.987988       1 log.go:194] falcon-pod-c01 in Prefilter
I1016 14:22:23.988018       1 log.go:194] falcon-pod-c01 requires 2 gpu(s), and currently has 2 gpus(s) in total
I1016 14:22:23.994392       1 log.go:194] css-host-128 has 1 gpu, falcon-pod-c01 requires 2 gpu -> score: -1
I1016 14:22:23.994417       1 log.go:194] css-host-129 has 1 gpu, falcon-pod-c01 requires 2 gpu -> score: -1
I1016 14:22:24.005146       1 event.go:307] "Event occurred" object="default/falcon-pod-c01" fieldPath="" kind="Pod" apiVersion="v1" type="Normal" reason="Reconfig" message="Pod falcon-pod-c01 needs reconfiguration"
I1016 14:22:53.795952       1 schedule_one.go:252] "Successfully bound pod to node" pod="default/falcon-pod-c01" node="css-host-128" evaluatedNodes=2 feasibleNodes=2
I1016 14:23:06.238744       1 log.go:194] falcon-pod-c05 in Prefilter
I1016 14:23:06.238774       1 log.go:194] falcon-pod-c05 requires 2 gpu(s), and currently has 3 gpus(s) in total
I1016 14:23:06.246425       1 log.go:194] css-host-128 has 1 gpu, falcon-pod-c05 requires 2 gpu -> score: -1
I1016 14:23:06.246467       1 log.go:194] css-host-129 has 2 gpu, falcon-pod-c05 requires 2 gpu -> score: 100
I1016 14:23:06.255703       1 schedule_one.go:252] "Successfully bound pod to node" pod="default/falcon-pod-c05" node="css-host-129" evaluatedNodes=2 feasibleNodes=2
I1016 14:23:15.477016       1 log.go:194] falcon-pod-c09 in Prefilter
I1016 14:23:15.477046       1 log.go:194] falcon-pod-c09 requires 2 gpu(s), and currently has 1 gpus(s) in total
I1016 14:23:15.482871       1 schedule_one.go:867] "Unable to schedule pod; no fit; waiting" pod="default/falcon-pod-c09" err="0/2 nodes are available: falcon-pod-c09 requires 2 gpu but only 1 gpu in the pool.. preemption: 0/2 nodes are available: 2 No preemption victims found for incoming pod.."
E1016 14:23:15.482962       1 schedule_one.go:902] "Error occurred" err="Pod default/falcon-pod-c09 is already present in the active queue"
I1016 14:23:15.488308       1 log.go:194] falcon-pod-c09 in Prefilter
I1016 14:23:15.488329       1 log.go:194] falcon-pod-c09 requires 2 gpu(s), and currently has 1 gpus(s) in total
I1016 14:23:15.494288       1 schedule_one.go:867] "Unable to schedule pod; no fit; waiting" pod="default/falcon-pod-c09" err="0/2 nodes are available: falcon-pod-c09 requires 2 gpu but only 1 gpu in the pool.. preemption: 0/2 nodes are available: 2 No preemption victims found for incoming pod.."
I1016 14:26:26.334594       1 log.go:194] falcon-pod-c09 in Prefilter
I1016 14:26:26.334627       1 log.go:194] falcon-pod-c09 requires 2 gpu(s), and currently has 2 gpus(s) in total
I1016 14:26:26.343228       1 log.go:194] css-host-128 has 1 gpu, falcon-pod-c09 requires 2 gpu -> score: -1
I1016 14:26:26.343268       1 log.go:194] css-host-129 has 1 gpu, falcon-pod-c09 requires 2 gpu -> score: -1
I1016 14:26:26.353699       1 event.go:307] "Event occurred" object="default/falcon-pod-c09" fieldPath="" kind="Pod" apiVersion="v1" type="Normal" reason="Reconfig" message="Pod falcon-pod-c09 needs reconfiguration"
I1016 14:26:51.342233       1 schedule_one.go:252] "Successfully bound pod to node" pod="default/falcon-pod-c09" node="css-host-129" evaluatedNodes=2 feasibleNodes=2
I1017 03:10:44.987201       1 log.go:194] falcon-pod-a01 in Prefilter
I1017 03:10:44.987244       1 log.go:194] falcon-pod-a01 requires 1 gpu(s), and currently has 8 gpus(s) in total
I1017 03:10:44.996075       1 log.go:194] css-host-128 has 4 gpu, falcon-pod-a01 requires 1 gpu -> score: 25
I1017 03:10:44.996128       1 log.go:194] css-host-129 has 4 gpu, falcon-pod-a01 requires 1 gpu -> score: 25
I1017 03:10:45.003637       1 schedule_one.go:252] "Successfully bound pod to node" pod="default/falcon-pod-a01" node="css-host-128" evaluatedNodes=2 feasibleNodes=2
I1017 03:11:22.025855       1 log.go:194] falcon-pod-a10 in Prefilter
I1017 03:11:22.025902       1 log.go:194] falcon-pod-a10 requires 1 gpu(s), and currently has 7 gpus(s) in total
I1017 03:11:22.032493       1 log.go:194] css-host-128 has 3 gpu, falcon-pod-a10 requires 1 gpu -> score: 33
I1017 03:11:22.032594       1 log.go:194] css-host-129 has 4 gpu, falcon-pod-a10 requires 1 gpu -> score: 25
I1017 03:11:22.040718       1 schedule_one.go:252] "Successfully bound pod to node" pod="default/falcon-pod-a10" node="css-host-128" evaluatedNodes=2 feasibleNodes=2
I1017 03:11:51.056044       1 log.go:194] falcon-pod-b09 in Prefilter
I1017 03:11:51.056084       1 log.go:194] falcon-pod-b09 requires 1 gpu(s), and currently has 6 gpus(s) in total
I1017 03:11:51.070393       1 schedule_one.go:252] "Successfully bound pod to node" pod="default/falcon-pod-b09" node="css-host-129" evaluatedNodes=2 feasibleNodes=1
I1017 03:12:27.067864       1 log.go:194] falcon-pod-b05 in Prefilter
I1017 03:12:27.067911       1 log.go:194] falcon-pod-b05 requires 1 gpu(s), and currently has 5 gpus(s) in total
I1017 03:12:27.081675       1 schedule_one.go:252] "Successfully bound pod to node" pod="default/falcon-pod-b05" node="css-host-129" evaluatedNodes=2 feasibleNodes=1
I1017 03:12:55.076412       1 log.go:194] falcon-pod-b03 in Prefilter
I1017 03:12:55.076446       1 log.go:194] falcon-pod-b03 requires 1 gpu(s), and currently has 4 gpus(s) in total
I1017 03:12:55.089955       1 schedule_one.go:252] "Successfully bound pod to node" pod="default/falcon-pod-b03" node="css-host-129" evaluatedNodes=2 feasibleNodes=1
I1017 03:13:20.115777       1 log.go:194] falcon-pod-a04 in Prefilter
I1017 03:13:20.115807       1 log.go:194] falcon-pod-a04 requires 1 gpu(s), and currently has 3 gpus(s) in total
I1017 03:13:20.121721       1 schedule_one.go:867] "Unable to schedule pod; no fit; waiting" pod="default/falcon-pod-a04" err="0/2 nodes are available: 2 Insufficient cpu. preemption: 0/2 nodes are available: 2 No preemption victims found for incoming pod.."
E1017 03:13:20.121795       1 schedule_one.go:902] "Error occurred" err="Pod default/falcon-pod-a04 is already present in the active queue"
I1017 03:13:20.127158       1 log.go:194] falcon-pod-a04 in Prefilter
I1017 03:13:20.127178       1 log.go:194] falcon-pod-a04 requires 1 gpu(s), and currently has 3 gpus(s) in total
I1017 03:13:20.131621       1 schedule_one.go:867] "Unable to schedule pod; no fit; waiting" pod="default/falcon-pod-a04" err="0/2 nodes are available: 2 Insufficient cpu. preemption: 0/2 nodes are available: 2 No preemption victims found for incoming pod.."
E1017 03:13:20.131681       1 schedule_one.go:902] "Error occurred" err="Pod default/falcon-pod-a04 is already present in the active queue"
I1017 03:13:20.137302       1 log.go:194] falcon-pod-a04 in Prefilter
I1017 03:13:20.137320       1 log.go:194] falcon-pod-a04 requires 1 gpu(s), and currently has 3 gpus(s) in total
I1017 03:13:20.142568       1 schedule_one.go:867] "Unable to schedule pod; no fit; waiting" pod="default/falcon-pod-a04" err="0/2 nodes are available: 2 Insufficient cpu. preemption: 0/2 nodes are available: 2 No preemption victims found for incoming pod.."
I1017 03:16:00.796688       1 log.go:194] falcon-pod-a04 in Prefilter
I1017 03:16:00.796716       1 log.go:194] falcon-pod-a04 requires 1 gpu(s), and currently has 4 gpus(s) in total
I1017 03:16:00.810437       1 schedule_one.go:252] "Successfully bound pod to node" pod="default/falcon-pod-a04" node="css-host-128" evaluatedNodes=2 feasibleNodes=1
I1017 03:16:13.225273       1 log.go:194] falcon-pod-a07 in Prefilter
I1017 03:16:13.225304       1 log.go:194] falcon-pod-a07 requires 1 gpu(s), and currently has 3 gpus(s) in total
I1017 03:16:13.230629       1 schedule_one.go:867] "Unable to schedule pod; no fit; waiting" pod="default/falcon-pod-a07" err="0/2 nodes are available: 2 Insufficient cpu. preemption: 0/2 nodes are available: 2 No preemption victims found for incoming pod.."
I1017 03:16:14.321191       1 log.go:194] falcon-pod-a07 in Prefilter
I1017 03:16:14.321222       1 log.go:194] falcon-pod-a07 requires 1 gpu(s), and currently has 3 gpus(s) in total
I1017 03:16:14.328215       1 schedule_one.go:867] "Unable to schedule pod; no fit; waiting" pod="default/falcon-pod-a07" err="0/2 nodes are available: 2 Insufficient cpu. preemption: 0/2 nodes are available: 2 No preemption victims found for incoming pod.."
I1017 03:16:34.346308       1 log.go:194] falcon-pod-a07 in Prefilter
I1017 03:16:34.346341       1 log.go:194] falcon-pod-a07 requires 1 gpu(s), and currently has 4 gpus(s) in total
I1017 03:16:34.358183       1 schedule_one.go:252] "Successfully bound pod to node" pod="default/falcon-pod-a07" node="css-host-128" evaluatedNodes=2 feasibleNodes=1
I1017 03:16:46.307054       1 log.go:194] falcon-pod-a03 in Prefilter
I1017 03:16:46.307086       1 log.go:194] falcon-pod-a03 requires 1 gpu(s), and currently has 3 gpus(s) in total
I1017 03:16:46.313046       1 schedule_one.go:867] "Unable to schedule pod; no fit; waiting" pod="default/falcon-pod-a03" err="0/2 nodes are available: 2 Insufficient cpu. preemption: 0/2 nodes are available: 2 No preemption victims found for incoming pod.."
E1017 03:16:46.313131       1 schedule_one.go:902] "Error occurred" err="Pod default/falcon-pod-a03 is already present in the active queue"
I1017 03:16:46.319476       1 log.go:194] falcon-pod-a03 in Prefilter
I1017 03:16:46.319497       1 log.go:194] falcon-pod-a03 requires 1 gpu(s), and currently has 3 gpus(s) in total
I1017 03:16:46.324592       1 schedule_one.go:867] "Unable to schedule pod; no fit; waiting" pod="default/falcon-pod-a03" err="0/2 nodes are available: 2 Insufficient cpu. preemption: 0/2 nodes are available: 2 No preemption victims found for incoming pod.."
I1017 03:17:07.453481       1 log.go:194] falcon-pod-a03 in Prefilter
I1017 03:17:07.453509       1 log.go:194] falcon-pod-a03 requires 1 gpu(s), and currently has 4 gpus(s) in total
I1017 03:17:07.466967       1 schedule_one.go:252] "Successfully bound pod to node" pod="default/falcon-pod-a03" node="css-host-129" evaluatedNodes=2 feasibleNodes=1
I1017 03:17:17.260808       1 log.go:194] falcon-pod-a05 in Prefilter
I1017 03:17:17.260839       1 log.go:194] falcon-pod-a05 requires 1 gpu(s), and currently has 3 gpus(s) in total
I1017 03:17:17.278762       1 schedule_one.go:867] "Unable to schedule pod; no fit; waiting" pod="default/falcon-pod-a05" err="0/2 nodes are available: 2 Insufficient cpu. preemption: 0/2 nodes are available: 2 No preemption victims found for incoming pod.."
E1017 03:17:17.278838       1 schedule_one.go:902] "Error occurred" err="Pod default/falcon-pod-a05 is already present in the active queue"
I1017 03:17:17.285584       1 log.go:194] falcon-pod-a05 in Prefilter
I1017 03:17:17.285603       1 log.go:194] falcon-pod-a05 requires 1 gpu(s), and currently has 3 gpus(s) in total
I1017 03:17:17.289509       1 schedule_one.go:867] "Unable to schedule pod; no fit; waiting" pod="default/falcon-pod-a05" err="0/2 nodes are available: 2 Insufficient cpu. preemption: 0/2 nodes are available: 2 No preemption victims found for incoming pod.."
I1017 03:17:39.893908       1 log.go:194] falcon-pod-a05 in Prefilter
I1017 03:17:39.893944       1 log.go:194] falcon-pod-a05 requires 1 gpu(s), and currently has 4 gpus(s) in total
I1017 03:17:39.900639       1 schedule_one.go:867] "Unable to schedule pod; no fit; waiting" pod="default/falcon-pod-a05" err="0/2 nodes are available: 2 Insufficient cpu. preemption: 0/2 nodes are available: 2 No preemption victims found for incoming pod.."
I1017 03:18:05.428140       1 log.go:194] falcon-pod-a05 in Prefilter
I1017 03:18:05.428167       1 log.go:194] falcon-pod-a05 requires 1 gpu(s), and currently has 5 gpus(s) in total
I1017 03:18:05.442184       1 schedule_one.go:252] "Successfully bound pod to node" pod="default/falcon-pod-a05" node="css-host-129" evaluatedNodes=2 feasibleNodes=1
I1017 03:18:17.780771       1 log.go:194] falcon-pod-a02 in Prefilter
I1017 03:18:17.780818       1 log.go:194] falcon-pod-a02 requires 1 gpu(s), and currently has 4 gpus(s) in total
I1017 03:18:17.786996       1 schedule_one.go:867] "Unable to schedule pod; no fit; waiting" pod="default/falcon-pod-a02" err="0/2 nodes are available: 2 Insufficient cpu. preemption: 0/2 nodes are available: 2 No preemption victims found for incoming pod.."
E1017 03:18:17.787113       1 schedule_one.go:902] "Error occurred" err="Pod default/falcon-pod-a02 is already present in the active queue"
I1017 03:18:17.792851       1 log.go:194] falcon-pod-a02 in Prefilter
I1017 03:18:17.792880       1 log.go:194] falcon-pod-a02 requires 1 gpu(s), and currently has 4 gpus(s) in total
I1017 03:18:17.798969       1 schedule_one.go:867] "Unable to schedule pod; no fit; waiting" pod="default/falcon-pod-a02" err="0/2 nodes are available: 2 Insufficient cpu. preemption: 0/2 nodes are available: 2 No preemption victims found for incoming pod.."
I1017 03:21:13.738387       1 log.go:194] falcon-pod-a02 in Prefilter
I1017 03:21:13.738419       1 log.go:194] falcon-pod-a02 requires 1 gpu(s), and currently has 5 gpus(s) in total
I1017 03:21:13.750679       1 schedule_one.go:252] "Successfully bound pod to node" pod="default/falcon-pod-a02" node="css-host-128" evaluatedNodes=2 feasibleNodes=1
I1017 03:21:25.894567       1 log.go:194] falcon-pod-b02 in Prefilter
I1017 03:21:25.894595       1 log.go:194] falcon-pod-b02 requires 1 gpu(s), and currently has 4 gpus(s) in total
I1017 03:21:25.901218       1 schedule_one.go:867] "Unable to schedule pod; no fit; waiting" pod="default/falcon-pod-b02" err="0/2 nodes are available: 2 Insufficient cpu. preemption: 0/2 nodes are available: 2 No preemption victims found for incoming pod.."
E1017 03:21:25.901291       1 schedule_one.go:902] "Error occurred" err="Pod default/falcon-pod-b02 is already present in the active queue"
I1017 03:21:25.906839       1 log.go:194] falcon-pod-b02 in Prefilter
I1017 03:21:25.906858       1 log.go:194] falcon-pod-b02 requires 1 gpu(s), and currently has 4 gpus(s) in total
I1017 03:21:25.912704       1 schedule_one.go:867] "Unable to schedule pod; no fit; waiting" pod="default/falcon-pod-b02" err="0/2 nodes are available: 2 Insufficient cpu. preemption: 0/2 nodes are available: 2 No preemption victims found for incoming pod.."
I1017 03:21:47.446948       1 log.go:194] falcon-pod-b02 in Prefilter
I1017 03:21:47.446979       1 log.go:194] falcon-pod-b02 requires 1 gpu(s), and currently has 5 gpus(s) in total
I1017 03:21:47.464039       1 schedule_one.go:252] "Successfully bound pod to node" pod="default/falcon-pod-b02" node="css-host-128" evaluatedNodes=2 feasibleNodes=1
I1017 03:21:59.084217       1 log.go:194] falcon-pod-b08 in Prefilter
I1017 03:21:59.084248       1 log.go:194] falcon-pod-b08 requires 1 gpu(s), and currently has 4 gpus(s) in total
I1017 03:21:59.099478       1 schedule_one.go:252] "Successfully bound pod to node" pod="default/falcon-pod-b08" node="css-host-128" evaluatedNodes=2 feasibleNodes=1
I1017 03:22:08.255243       1 log.go:194] falcon-pod-a06 in Prefilter
I1017 03:22:08.255275       1 log.go:194] falcon-pod-a06 requires 1 gpu(s), and currently has 3 gpus(s) in total
I1017 03:22:08.262168       1 schedule_one.go:867] "Unable to schedule pod; no fit; waiting" pod="default/falcon-pod-a06" err="0/2 nodes are available: 2 Insufficient cpu. preemption: 0/2 nodes are available: 2 No preemption victims found for incoming pod.."
E1017 03:22:08.262275       1 schedule_one.go:902] "Error occurred" err="Pod default/falcon-pod-a06 is already present in the active queue"
I1017 03:22:08.268208       1 log.go:194] falcon-pod-a06 in Prefilter
I1017 03:22:08.268227       1 log.go:194] falcon-pod-a06 requires 1 gpu(s), and currently has 3 gpus(s) in total
I1017 03:22:08.272573       1 schedule_one.go:867] "Unable to schedule pod; no fit; waiting" pod="default/falcon-pod-a06" err="0/2 nodes are available: 2 Insufficient cpu. preemption: 0/2 nodes are available: 2 No preemption victims found for incoming pod.."
E1017 03:22:08.272679       1 schedule_one.go:902] "Error occurred" err="Pod default/falcon-pod-a06 is already present in the active queue"
I1017 03:22:08.277747       1 log.go:194] falcon-pod-a06 in Prefilter
I1017 03:22:08.277766       1 log.go:194] falcon-pod-a06 requires 1 gpu(s), and currently has 3 gpus(s) in total
I1017 03:22:08.282588       1 schedule_one.go:867] "Unable to schedule pod; no fit; waiting" pod="default/falcon-pod-a06" err="0/2 nodes are available: 2 Insufficient cpu. preemption: 0/2 nodes are available: 2 No preemption victims found for incoming pod.."
I1017 03:22:18.021692       1 log.go:194] falcon-pod-a06 in Prefilter
I1017 03:22:18.021719       1 log.go:194] falcon-pod-a06 requires 1 gpu(s), and currently has 4 gpus(s) in total
I1017 03:22:18.034491       1 schedule_one.go:252] "Successfully bound pod to node" pod="default/falcon-pod-a06" node="css-host-129" evaluatedNodes=2 feasibleNodes=1
I1017 03:22:30.571612       1 log.go:194] falcon-pod-a08 in Prefilter
I1017 03:22:30.571644       1 log.go:194] falcon-pod-a08 requires 1 gpu(s), and currently has 3 gpus(s) in total
I1017 03:22:30.578598       1 schedule_one.go:867] "Unable to schedule pod; no fit; waiting" pod="default/falcon-pod-a08" err="0/2 nodes are available: 2 Insufficient cpu. preemption: 0/2 nodes are available: 2 No preemption victims found for incoming pod.."
E1017 03:22:30.578680       1 schedule_one.go:902] "Error occurred" err="Pod default/falcon-pod-a08 is already present in the active queue"
I1017 03:22:30.584018       1 log.go:194] falcon-pod-a08 in Prefilter
I1017 03:22:30.584036       1 log.go:194] falcon-pod-a08 requires 1 gpu(s), and currently has 3 gpus(s) in total
I1017 03:22:30.589319       1 schedule_one.go:867] "Unable to schedule pod; no fit; waiting" pod="default/falcon-pod-a08" err="0/2 nodes are available: 2 Insufficient cpu. preemption: 0/2 nodes are available: 2 No preemption victims found for incoming pod.."
I1017 03:23:18.635222       1 log.go:194] falcon-pod-a08 in Prefilter
I1017 03:23:18.635259       1 log.go:194] falcon-pod-a08 requires 1 gpu(s), and currently has 4 gpus(s) in total
I1017 03:23:18.649988       1 schedule_one.go:252] "Successfully bound pod to node" pod="default/falcon-pod-a08" node="css-host-129" evaluatedNodes=2 feasibleNodes=1
I1017 03:23:31.152648       1 log.go:194] falcon-pod-b06 in Prefilter
I1017 03:23:31.152688       1 log.go:194] falcon-pod-b06 requires 1 gpu(s), and currently has 3 gpus(s) in total
I1017 03:23:31.175863       1 schedule_one.go:867] "Unable to schedule pod; no fit; waiting" pod="default/falcon-pod-b06" err="0/2 nodes are available: 2 Insufficient cpu. preemption: 0/2 nodes are available: 2 No preemption victims found for incoming pod.."
E1017 03:23:31.175951       1 schedule_one.go:902] "Error occurred" err="Pod default/falcon-pod-b06 is already present in the active queue"
I1017 03:23:31.184861       1 log.go:194] falcon-pod-b06 in Prefilter
I1017 03:23:31.184879       1 log.go:194] falcon-pod-b06 requires 1 gpu(s), and currently has 3 gpus(s) in total
I1017 03:23:31.191030       1 schedule_one.go:867] "Unable to schedule pod; no fit; waiting" pod="default/falcon-pod-b06" err="0/2 nodes are available: 2 Insufficient cpu. preemption: 0/2 nodes are available: 2 No preemption victims found for incoming pod.."
I1017 03:26:27.059490       1 log.go:194] falcon-pod-b06 in Prefilter
I1017 03:26:27.059519       1 log.go:194] falcon-pod-b06 requires 1 gpu(s), and currently has 4 gpus(s) in total
I1017 03:26:27.072197       1 schedule_one.go:252] "Successfully bound pod to node" pod="default/falcon-pod-b06" node="css-host-128" evaluatedNodes=2 feasibleNodes=1
I1017 03:26:36.504364       1 log.go:194] falcon-pod-b07 in Prefilter
I1017 03:26:36.504395       1 log.go:194] falcon-pod-b07 requires 1 gpu(s), and currently has 3 gpus(s) in total
I1017 03:26:36.514187       1 schedule_one.go:252] "Successfully bound pod to node" pod="default/falcon-pod-b07" node="css-host-128" evaluatedNodes=2 feasibleNodes=1
I1017 03:26:42.429631       1 log.go:194] falcon-pod-b01 in Prefilter
I1017 03:26:42.429662       1 log.go:194] falcon-pod-b01 requires 1 gpu(s), and currently has 2 gpus(s) in total
I1017 03:26:42.435851       1 schedule_one.go:867] "Unable to schedule pod; no fit; waiting" pod="default/falcon-pod-b01" err="0/2 nodes are available: 2 Insufficient cpu. preemption: 0/2 nodes are available: 2 No preemption victims found for incoming pod.."
E1017 03:26:42.435953       1 schedule_one.go:902] "Error occurred" err="Pod default/falcon-pod-b01 is already present in the active queue"
I1017 03:26:42.441524       1 log.go:194] falcon-pod-b01 in Prefilter
I1017 03:26:42.441552       1 log.go:194] falcon-pod-b01 requires 1 gpu(s), and currently has 2 gpus(s) in total
I1017 03:26:42.446826       1 schedule_one.go:867] "Unable to schedule pod; no fit; waiting" pod="default/falcon-pod-b01" err="0/2 nodes are available: 2 Insufficient cpu. preemption: 0/2 nodes are available: 2 No preemption victims found for incoming pod.."
I1017 03:27:00.532439       1 log.go:194] falcon-pod-b01 in Prefilter
I1017 03:27:00.532473       1 log.go:194] falcon-pod-b01 requires 1 gpu(s), and currently has 3 gpus(s) in total
I1017 03:27:00.543200       1 schedule_one.go:252] "Successfully bound pod to node" pod="default/falcon-pod-b01" node="css-host-128" evaluatedNodes=2 feasibleNodes=1
I1017 03:27:06.915959       1 log.go:194] falcon-pod-b10 in Prefilter
I1017 03:27:06.915989       1 log.go:194] falcon-pod-b10 requires 1 gpu(s), and currently has 2 gpus(s) in total
I1017 03:27:06.922504       1 schedule_one.go:867] "Unable to schedule pod; no fit; waiting" pod="default/falcon-pod-b10" err="0/2 nodes are available: 2 Insufficient cpu. preemption: 0/2 nodes are available: 2 No preemption victims found for incoming pod.."
E1017 03:27:06.922580       1 schedule_one.go:902] "Error occurred" err="Pod default/falcon-pod-b10 is already present in the active queue"
I1017 03:27:06.928406       1 log.go:194] falcon-pod-b10 in Prefilter
I1017 03:27:06.928425       1 log.go:194] falcon-pod-b10 requires 1 gpu(s), and currently has 2 gpus(s) in total
I1017 03:27:06.933759       1 schedule_one.go:867] "Unable to schedule pod; no fit; waiting" pod="default/falcon-pod-b10" err="0/2 nodes are available: 2 Insufficient cpu. preemption: 0/2 nodes are available: 2 No preemption victims found for incoming pod.."
I1017 03:27:09.386454       1 log.go:194] falcon-pod-b10 in Prefilter
I1017 03:27:09.386486       1 log.go:194] falcon-pod-b10 requires 1 gpu(s), and currently has 3 gpus(s) in total
I1017 03:27:09.399775       1 schedule_one.go:252] "Successfully bound pod to node" pod="default/falcon-pod-b10" node="css-host-128" evaluatedNodes=2 feasibleNodes=1
I1017 03:27:16.166213       1 log.go:194] falcon-pod-b04 in Prefilter
I1017 03:27:16.166243       1 log.go:194] falcon-pod-b04 requires 1 gpu(s), and currently has 2 gpus(s) in total
I1017 03:27:16.173644       1 schedule_one.go:867] "Unable to schedule pod; no fit; waiting" pod="default/falcon-pod-b04" err="0/2 nodes are available: 2 Insufficient cpu. preemption: 0/2 nodes are available: 2 No preemption victims found for incoming pod.."
E1017 03:27:16.173751       1 schedule_one.go:902] "Error occurred" err="Pod default/falcon-pod-b04 is already present in the active queue"
I1017 03:27:16.180485       1 log.go:194] falcon-pod-b04 in Prefilter
I1017 03:27:16.180504       1 log.go:194] falcon-pod-b04 requires 1 gpu(s), and currently has 2 gpus(s) in total
I1017 03:27:16.186259       1 schedule_one.go:867] "Unable to schedule pod; no fit; waiting" pod="default/falcon-pod-b04" err="0/2 nodes are available: 2 Insufficient cpu. preemption: 0/2 nodes are available: 2 No preemption victims found for incoming pod.."
I1017 03:27:31.344883       1 log.go:194] falcon-pod-b04 in Prefilter
I1017 03:27:31.344928       1 log.go:194] falcon-pod-b04 requires 1 gpu(s), and currently has 3 gpus(s) in total
I1017 03:27:31.358715       1 schedule_one.go:252] "Successfully bound pod to node" pod="default/falcon-pod-b04" node="css-host-129" evaluatedNodes=2 feasibleNodes=1
I1017 03:27:42.918409       1 log.go:194] falcon-pod-a09 in Prefilter
I1017 03:27:42.918440       1 log.go:194] falcon-pod-a09 requires 1 gpu(s), and currently has 2 gpus(s) in total
I1017 03:27:42.925530       1 schedule_one.go:867] "Unable to schedule pod; no fit; waiting" pod="default/falcon-pod-a09" err="0/2 nodes are available: 2 Insufficient cpu. preemption: 0/2 nodes are available: 2 No preemption victims found for incoming pod.."
E1017 03:27:42.925631       1 schedule_one.go:902] "Error occurred" err="Pod default/falcon-pod-a09 is already present in the active queue"
I1017 03:27:42.931231       1 log.go:194] falcon-pod-a09 in Prefilter
I1017 03:27:42.931255       1 log.go:194] falcon-pod-a09 requires 1 gpu(s), and currently has 2 gpus(s) in total
I1017 03:27:42.937473       1 schedule_one.go:867] "Unable to schedule pod; no fit; waiting" pod="default/falcon-pod-a09" err="0/2 nodes are available: 2 Insufficient cpu. preemption: 0/2 nodes are available: 2 No preemption victims found for incoming pod.."
I1017 03:28:32.068669       1 log.go:194] falcon-pod-a09 in Prefilter
I1017 03:28:32.068698       1 log.go:194] falcon-pod-a09 requires 1 gpu(s), and currently has 3 gpus(s) in total
I1017 03:28:32.081565       1 schedule_one.go:252] "Successfully bound pod to node" pod="default/falcon-pod-a09" node="css-host-129" evaluatedNodes=2 feasibleNodes=1
I1017 04:37:27.578634       1 log.go:194] falcon-pod-c02 in Prefilter
I1017 04:37:27.578664       1 log.go:194] falcon-pod-c02 requires 2 gpu(s), and currently has 8 gpus(s) in total
I1017 04:37:27.585192       1 log.go:194] css-host-129 has 4 gpu, falcon-pod-c02 requires 2 gpu -> score: 50
I1017 04:37:27.585209       1 log.go:194] css-host-128 has 4 gpu, falcon-pod-c02 requires 2 gpu -> score: 50
I1017 04:37:27.592152       1 schedule_one.go:252] "Successfully bound pod to node" pod="default/falcon-pod-c02" node="css-host-129" evaluatedNodes=2 feasibleNodes=2
I1017 04:38:38.650514       1 log.go:194] falcon-pod-c03 in Prefilter
I1017 04:38:38.650559       1 log.go:194] falcon-pod-c03 requires 2 gpu(s), and currently has 6 gpus(s) in total
I1017 04:38:38.659091       1 log.go:194] css-host-129 has 2 gpu, falcon-pod-c03 requires 2 gpu -> score: 100
I1017 04:38:38.659183       1 log.go:194] css-host-128 has 4 gpu, falcon-pod-c03 requires 2 gpu -> score: 50
I1017 04:38:38.667368       1 schedule_one.go:252] "Successfully bound pod to node" pod="default/falcon-pod-c03" node="css-host-129" evaluatedNodes=2 feasibleNodes=2
I1017 04:39:37.704368       1 log.go:194] falcon-pod-a05 in Prefilter
I1017 04:39:37.704416       1 log.go:194] falcon-pod-a05 requires 1 gpu(s), and currently has 4 gpus(s) in total
I1017 04:39:37.711591       1 log.go:194] css-host-128 has 4 gpu, falcon-pod-a05 requires 1 gpu -> score: 25
I1017 04:39:37.711634       1 log.go:194] css-host-129 has 0 gpu, falcon-pod-a05 requires 1 gpu -> score: -1
I1017 04:39:37.718271       1 schedule_one.go:252] "Successfully bound pod to node" pod="default/falcon-pod-a05" node="css-host-128" evaluatedNodes=2 feasibleNodes=2
I1017 04:40:36.766036       1 log.go:194] falcon-pod-c07 in Prefilter
I1017 04:40:36.766076       1 log.go:194] falcon-pod-c07 requires 2 gpu(s), and currently has 3 gpus(s) in total
I1017 04:40:36.773121       1 log.go:194] css-host-128 has 3 gpu, falcon-pod-c07 requires 2 gpu -> score: 66
I1017 04:40:36.773176       1 log.go:194] css-host-129 has 0 gpu, falcon-pod-c07 requires 2 gpu -> score: -2
I1017 04:40:36.780666       1 schedule_one.go:252] "Successfully bound pod to node" pod="default/falcon-pod-c07" node="css-host-128" evaluatedNodes=2 feasibleNodes=2
I1017 04:41:38.834990       1 log.go:194] falcon-pod-c08 in Prefilter
I1017 04:41:38.835027       1 log.go:194] falcon-pod-c08 requires 2 gpu(s), and currently has 1 gpus(s) in total
I1017 04:41:38.841694       1 schedule_one.go:867] "Unable to schedule pod; no fit; waiting" pod="default/falcon-pod-c08" err="0/2 nodes are available: falcon-pod-c08 requires 2 gpu but only 1 gpu in the pool.. preemption: 0/2 nodes are available: 2 No preemption victims found for incoming pod.."
E1017 04:41:38.841828       1 schedule_one.go:902] "Error occurred" err="Pod default/falcon-pod-c08 is already present in the active queue"
I1017 04:41:38.847560       1 log.go:194] falcon-pod-c08 in Prefilter
I1017 04:41:38.847587       1 log.go:194] falcon-pod-c08 requires 2 gpu(s), and currently has 1 gpus(s) in total
I1017 04:41:38.851693       1 schedule_one.go:867] "Unable to schedule pod; no fit; waiting" pod="default/falcon-pod-c08" err="0/2 nodes are available: falcon-pod-c08 requires 2 gpu but only 1 gpu in the pool.. preemption: 0/2 nodes are available: 2 No preemption victims found for incoming pod.."
E1017 04:41:38.851772       1 schedule_one.go:902] "Error occurred" err="Pod default/falcon-pod-c08 is already present in the active queue"
I1017 04:41:38.856575       1 log.go:194] falcon-pod-c08 in Prefilter
I1017 04:41:38.856595       1 log.go:194] falcon-pod-c08 requires 2 gpu(s), and currently has 1 gpus(s) in total
I1017 04:41:38.860526       1 schedule_one.go:867] "Unable to schedule pod; no fit; waiting" pod="default/falcon-pod-c08" err="0/2 nodes are available: falcon-pod-c08 requires 2 gpu but only 1 gpu in the pool.. preemption: 0/2 nodes are available: 2 No preemption victims found for incoming pod.."
I1017 04:42:44.883106       1 log.go:194] falcon-pod-c08 in Prefilter
I1017 04:42:44.883128       1 log.go:194] falcon-pod-c08 requires 2 gpu(s), and currently has 3 gpus(s) in total
I1017 04:42:44.887805       1 log.go:194] css-host-128 has 1 gpu, falcon-pod-c08 requires 2 gpu -> score: -1
I1017 04:42:44.887841       1 log.go:194] css-host-129 has 2 gpu, falcon-pod-c08 requires 2 gpu -> score: 100
I1017 04:42:44.892761       1 schedule_one.go:252] "Successfully bound pod to node" pod="default/falcon-pod-c08" node="css-host-129" evaluatedNodes=2 feasibleNodes=2
I1017 04:42:54.009242       1 log.go:194] falcon-pod-c10 in Prefilter
I1017 04:42:54.009270       1 log.go:194] falcon-pod-c10 requires 2 gpu(s), and currently has 1 gpus(s) in total
I1017 04:42:54.015456       1 schedule_one.go:867] "Unable to schedule pod; no fit; waiting" pod="default/falcon-pod-c10" err="0/2 nodes are available: falcon-pod-c10 requires 2 gpu but only 1 gpu in the pool.. preemption: 0/2 nodes are available: 2 No preemption victims found for incoming pod.."
E1017 04:42:54.015513       1 schedule_one.go:902] "Error occurred" err="Pod default/falcon-pod-c10 is already present in the active queue"
I1017 04:42:54.020842       1 log.go:194] falcon-pod-c10 in Prefilter
I1017 04:42:54.020860       1 log.go:194] falcon-pod-c10 requires 2 gpu(s), and currently has 1 gpus(s) in total
I1017 04:42:54.026386       1 schedule_one.go:867] "Unable to schedule pod; no fit; waiting" pod="default/falcon-pod-c10" err="0/2 nodes are available: falcon-pod-c10 requires 2 gpu but only 1 gpu in the pool.. preemption: 0/2 nodes are available: 2 No preemption victims found for incoming pod.."
I1017 04:43:49.845309       1 log.go:194] falcon-pod-c10 in Prefilter
I1017 04:43:49.845339       1 log.go:194] falcon-pod-c10 requires 2 gpu(s), and currently has 3 gpus(s) in total
I1017 04:43:49.853060       1 log.go:194] css-host-128 has 1 gpu, falcon-pod-c10 requires 2 gpu -> score: -1
I1017 04:43:49.853101       1 log.go:194] css-host-129 has 2 gpu, falcon-pod-c10 requires 2 gpu -> score: 100
I1017 04:43:49.860571       1 schedule_one.go:252] "Successfully bound pod to node" pod="default/falcon-pod-c10" node="css-host-129" evaluatedNodes=2 feasibleNodes=2
I1017 04:43:59.539259       1 log.go:194] falcon-pod-c04 in Prefilter
I1017 04:43:59.539290       1 log.go:194] falcon-pod-c04 requires 2 gpu(s), and currently has 1 gpus(s) in total
I1017 04:43:59.545311       1 schedule_one.go:867] "Unable to schedule pod; no fit; waiting" pod="default/falcon-pod-c04" err="0/2 nodes are available: falcon-pod-c04 requires 2 gpu but only 1 gpu in the pool.. preemption: 0/2 nodes are available: 2 No preemption victims found for incoming pod.."
E1017 04:43:59.545399       1 schedule_one.go:902] "Error occurred" err="Pod default/falcon-pod-c04 is already present in the active queue"
I1017 04:43:59.550813       1 log.go:194] falcon-pod-c04 in Prefilter
I1017 04:43:59.550831       1 log.go:194] falcon-pod-c04 requires 2 gpu(s), and currently has 1 gpus(s) in total
I1017 04:43:59.556663       1 schedule_one.go:867] "Unable to schedule pod; no fit; waiting" pod="default/falcon-pod-c04" err="0/2 nodes are available: falcon-pod-c04 requires 2 gpu but only 1 gpu in the pool.. preemption: 0/2 nodes are available: 2 No preemption victims found for incoming pod.."
E1017 04:43:59.556735       1 schedule_one.go:902] "Error occurred" err="Pod default/falcon-pod-c04 is already present in the active queue"
I1017 04:43:59.561451       1 log.go:194] falcon-pod-c04 in Prefilter
I1017 04:43:59.561467       1 log.go:194] falcon-pod-c04 requires 2 gpu(s), and currently has 1 gpus(s) in total
I1017 04:43:59.566309       1 schedule_one.go:867] "Unable to schedule pod; no fit; waiting" pod="default/falcon-pod-c04" err="0/2 nodes are available: falcon-pod-c04 requires 2 gpu but only 1 gpu in the pool.. preemption: 0/2 nodes are available: 2 No preemption victims found for incoming pod.."
I1017 04:44:53.506419       1 log.go:194] falcon-pod-c04 in Prefilter
I1017 04:44:53.506458       1 log.go:194] falcon-pod-c04 requires 2 gpu(s), and currently has 2 gpus(s) in total
I1017 04:44:53.513361       1 log.go:194] css-host-128 has 2 gpu, falcon-pod-c04 requires 2 gpu -> score: 100
I1017 04:44:53.513396       1 log.go:194] css-host-129 has 0 gpu, falcon-pod-c04 requires 2 gpu -> score: -2
I1017 04:44:53.521191       1 schedule_one.go:252] "Successfully bound pod to node" pod="default/falcon-pod-c04" node="css-host-128" evaluatedNodes=2 feasibleNodes=2
I1017 04:45:03.185921       1 log.go:194] falcon-pod-a07 in Prefilter
I1017 04:45:03.185959       1 log.go:194] falcon-pod-a07 requires 1 gpu(s), and currently has 0 gpus(s) in total
I1017 04:45:03.192060       1 schedule_one.go:867] "Unable to schedule pod; no fit; waiting" pod="default/falcon-pod-a07" err="0/2 nodes are available: falcon-pod-a07 requires 1 gpu but only 0 gpu in the pool.. preemption: 0/2 nodes are available: 2 No preemption victims found for incoming pod.."
E1017 04:45:03.192173       1 schedule_one.go:902] "Error occurred" err="Pod default/falcon-pod-a07 is already present in the active queue"
I1017 04:45:03.198045       1 log.go:194] falcon-pod-a07 in Prefilter
I1017 04:45:03.198065       1 log.go:194] falcon-pod-a07 requires 1 gpu(s), and currently has 0 gpus(s) in total
I1017 04:45:03.203558       1 schedule_one.go:867] "Unable to schedule pod; no fit; waiting" pod="default/falcon-pod-a07" err="0/2 nodes are available: falcon-pod-a07 requires 1 gpu but only 0 gpu in the pool.. preemption: 0/2 nodes are available: 2 No preemption victims found for incoming pod.."
I1017 04:45:50.794565       1 log.go:194] falcon-pod-a07 in Prefilter
I1017 04:45:50.794595       1 log.go:194] falcon-pod-a07 requires 1 gpu(s), and currently has 2 gpus(s) in total
I1017 04:45:50.801082       1 log.go:194] css-host-128 has 2 gpu, falcon-pod-a07 requires 1 gpu -> score: 50
I1017 04:45:50.801119       1 log.go:194] css-host-129 has 0 gpu, falcon-pod-a07 requires 1 gpu -> score: -1
I1017 04:45:50.808251       1 schedule_one.go:252] "Successfully bound pod to node" pod="default/falcon-pod-a07" node="css-host-128" evaluatedNodes=2 feasibleNodes=2
I1017 04:46:00.057725       1 log.go:194] falcon-pod-a01 in Prefilter
I1017 04:46:00.057763       1 log.go:194] falcon-pod-a01 requires 1 gpu(s), and currently has 1 gpus(s) in total
I1017 04:46:00.072807       1 event.go:307] "Event occurred" object="default/falcon-pod-a01" fieldPath="" kind="Pod" apiVersion="v1" type="Normal" reason="Reconfig" message="Pod falcon-pod-a01 needs reconfiguration"
E1017 04:46:40.261692       1 schedule_one.go:883] "Error scheduling pod; retrying" err="" pod="default/falcon-pod-a01"
E1017 04:46:40.261780       1 schedule_one.go:902] "Error occurred" err="Pod default/falcon-pod-a01 is already present in the active queue"
I1017 04:46:40.270253       1 log.go:194] falcon-pod-a01 in Prefilter
I1017 04:46:40.270285       1 log.go:194] falcon-pod-a01 requires 1 gpu(s), and currently has 0 gpus(s) in total
I1017 04:46:40.464856       1 trace.go:219] Trace[2130735987]: "Scheduling" namespace:default,name:falcon-pod-a01 (17-Oct-2023 04:46:40.270) (total time: 194ms):
Trace[2130735987]: ---"Computing predicates done" 194ms (04:46:40.464)
Trace[2130735987]: [194.700808ms] [194.700808ms] END
I1017 04:46:40.465086       1 schedule_one.go:867] "Unable to schedule pod; no fit; waiting" pod="default/falcon-pod-a01" err="0/2 nodes are available: falcon-pod-a01 requires 1 gpu but only 0 gpu in the pool.. preemption: 0/2 nodes are available: 2 No preemption victims found for incoming pod.."
E1017 04:46:40.465190       1 schedule_one.go:902] "Error occurred" err="Pod default/falcon-pod-a01 is already present in the active queue"
I1017 04:46:40.470712       1 log.go:194] falcon-pod-a01 in Prefilter
I1017 04:46:40.470731       1 log.go:194] falcon-pod-a01 requires 1 gpu(s), and currently has 0 gpus(s) in total
I1017 04:46:40.664540       1 trace.go:219] Trace[1753663659]: "Scheduling" namespace:default,name:falcon-pod-a01 (17-Oct-2023 04:46:40.470) (total time: 193ms):
Trace[1753663659]: ---"Computing predicates done" 193ms (04:46:40.664)
Trace[1753663659]: [193.874844ms] [193.874844ms] END
I1017 04:46:40.664872       1 schedule_one.go:867] "Unable to schedule pod; no fit; waiting" pod="default/falcon-pod-a01" err="0/2 nodes are available: falcon-pod-a01 requires 1 gpu but only 0 gpu in the pool.. preemption: 0/2 nodes are available: 2 No preemption victims found for incoming pod.."
E1017 04:46:40.664949       1 schedule_one.go:902] "Error occurred" err="Pod default/falcon-pod-a01 is already present in the active queue"
I1017 04:46:40.670140       1 log.go:194] falcon-pod-a01 in Prefilter
I1017 04:46:40.670160       1 log.go:194] falcon-pod-a01 requires 1 gpu(s), and currently has 0 gpus(s) in total
I1017 04:46:40.863781       1 trace.go:219] Trace[1882263262]: "Scheduling" namespace:default,name:falcon-pod-a01 (17-Oct-2023 04:46:40.670) (total time: 193ms):
Trace[1882263262]: ---"Computing predicates done" 193ms (04:46:40.863)
Trace[1882263262]: [193.68651ms] [193.68651ms] END
I1017 04:46:40.863967       1 schedule_one.go:867] "Unable to schedule pod; no fit; waiting" pod="default/falcon-pod-a01" err="0/2 nodes are available: falcon-pod-a01 requires 1 gpu but only 0 gpu in the pool.. preemption: 0/2 nodes are available: 2 No preemption victims found for incoming pod.."
I1017 04:46:47.601029       1 log.go:194] falcon-pod-a01 in Prefilter
I1017 04:46:47.601060       1 log.go:194] falcon-pod-a01 requires 1 gpu(s), and currently has 1 gpus(s) in total
I1017 04:46:47.615456       1 schedule_one.go:252] "Successfully bound pod to node" pod="default/falcon-pod-a01" node="css-host-129" evaluatedNodes=2 feasibleNodes=1
I1017 04:46:54.613619       1 log.go:194] falcon-pod-a04 in Prefilter
I1017 04:46:54.613652       1 log.go:194] falcon-pod-a04 requires 1 gpu(s), and currently has 0 gpus(s) in total
I1017 04:46:54.619686       1 schedule_one.go:867] "Unable to schedule pod; no fit; waiting" pod="default/falcon-pod-a04" err="0/2 nodes are available: falcon-pod-a04 requires 1 gpu but only 0 gpu in the pool.. preemption: 0/2 nodes are available: 2 No preemption victims found for incoming pod.."
E1017 04:46:54.619768       1 schedule_one.go:902] "Error occurred" err="Pod default/falcon-pod-a04 is already present in the active queue"
I1017 04:46:54.626328       1 log.go:194] falcon-pod-a04 in Prefilter
I1017 04:46:54.626348       1 log.go:194] falcon-pod-a04 requires 1 gpu(s), and currently has 0 gpus(s) in total
I1017 04:46:54.631560       1 schedule_one.go:867] "Unable to schedule pod; no fit; waiting" pod="default/falcon-pod-a04" err="0/2 nodes are available: falcon-pod-a04 requires 1 gpu but only 0 gpu in the pool.. preemption: 0/2 nodes are available: 2 No preemption victims found for incoming pod.."
I1017 04:47:56.393264       1 log.go:194] falcon-pod-a04 in Prefilter
I1017 04:47:56.393299       1 log.go:194] falcon-pod-a04 requires 1 gpu(s), and currently has 2 gpus(s) in total
I1017 04:47:56.400946       1 schedule_one.go:867] "Unable to schedule pod; no fit; waiting" pod="default/falcon-pod-a04" err="0/2 nodes are available: 2 Insufficient cpu. preemption: 0/2 nodes are available: 2 No preemption victims found for incoming pod.."
I1017 04:49:00.771298       1 log.go:194] falcon-pod-a04 in Prefilter
I1017 04:49:00.771328       1 log.go:194] falcon-pod-a04 requires 1 gpu(s), and currently has 4 gpus(s) in total
I1017 04:49:00.785266       1 schedule_one.go:252] "Successfully bound pod to node" pod="default/falcon-pod-a04" node="css-host-129" evaluatedNodes=2 feasibleNodes=1
I1017 04:49:15.770970       1 log.go:194] falcon-pod-c01 in Prefilter
I1017 04:49:15.771012       1 log.go:194] falcon-pod-c01 requires 2 gpu(s), and currently has 3 gpus(s) in total
I1017 04:49:15.787621       1 event.go:307] "Event occurred" object="default/falcon-pod-c01" fieldPath="" kind="Pod" apiVersion="v1" type="Normal" reason="Reconfig" message="Pod falcon-pod-c01 needs reconfiguration"
I1017 04:50:15.978937       1 schedule_one.go:252] "Successfully bound pod to node" pod="default/falcon-pod-c01" node="css-host-128" evaluatedNodes=2 feasibleNodes=1
I1017 04:50:31.502057       1 log.go:194] falcon-pod-a06 in Prefilter
I1017 04:50:31.502102       1 log.go:194] falcon-pod-a06 requires 1 gpu(s), and currently has 3 gpus(s) in total
I1017 04:50:31.509216       1 schedule_one.go:867] "Unable to schedule pod; no fit; waiting" pod="default/falcon-pod-a06" err="0/2 nodes are available: 2 Insufficient cpu. preemption: 0/2 nodes are available: 2 No preemption victims found for incoming pod.."
E1017 04:50:31.509304       1 schedule_one.go:902] "Error occurred" err="Pod default/falcon-pod-a06 is already present in the active queue"
I1017 04:50:31.515954       1 log.go:194] falcon-pod-a06 in Prefilter
I1017 04:50:31.515977       1 log.go:194] falcon-pod-a06 requires 1 gpu(s), and currently has 3 gpus(s) in total
I1017 04:50:31.520743       1 schedule_one.go:867] "Unable to schedule pod; no fit; waiting" pod="default/falcon-pod-a06" err="0/2 nodes are available: 2 Insufficient cpu. preemption: 0/2 nodes are available: 2 No preemption victims found for incoming pod.."
I1017 04:51:01.628861       1 log.go:194] falcon-pod-a06 in Prefilter
I1017 04:51:01.628897       1 log.go:194] falcon-pod-a06 requires 1 gpu(s), and currently has 4 gpus(s) in total
I1017 04:51:01.640692       1 schedule_one.go:252] "Successfully bound pod to node" pod="default/falcon-pod-a06" node="css-host-128" evaluatedNodes=2 feasibleNodes=1
I1017 04:51:13.427093       1 log.go:194] falcon-pod-c06 in Prefilter
I1017 04:51:13.427129       1 log.go:194] falcon-pod-c06 requires 2 gpu(s), and currently has 3 gpus(s) in total
I1017 04:51:13.442560       1 schedule_one.go:252] "Successfully bound pod to node" pod="default/falcon-pod-c06" node="css-host-128" evaluatedNodes=2 feasibleNodes=1
I1017 04:51:22.604623       1 log.go:194] falcon-pod-c09 in Prefilter
I1017 04:51:22.604657       1 log.go:194] falcon-pod-c09 requires 2 gpu(s), and currently has -1 gpus(s) in total
I1017 04:51:22.610710       1 schedule_one.go:867] "Unable to schedule pod; no fit; waiting" pod="default/falcon-pod-c09" err="0/2 nodes are available: falcon-pod-c09 requires 2 gpu but only -1 gpu in the pool.. preemption: 0/2 nodes are available: 2 No preemption victims found for incoming pod.."
E1017 04:51:22.610782       1 schedule_one.go:902] "Error occurred" err="Pod default/falcon-pod-c09 is already present in the active queue"
I1017 04:51:22.615607       1 log.go:194] falcon-pod-c09 in Prefilter
I1017 04:51:22.615632       1 log.go:194] falcon-pod-c09 requires 2 gpu(s), and currently has -1 gpus(s) in total
I1017 04:51:22.621085       1 schedule_one.go:867] "Unable to schedule pod; no fit; waiting" pod="default/falcon-pod-c09" err="0/2 nodes are available: falcon-pod-c09 requires 2 gpu but only -1 gpu in the pool.. preemption: 0/2 nodes are available: 2 No preemption victims found for incoming pod.."
E1017 04:51:22.621148       1 schedule_one.go:902] "Error occurred" err="Pod default/falcon-pod-c09 is already present in the active queue"
I1017 04:51:22.625904       1 log.go:194] falcon-pod-c09 in Prefilter
I1017 04:51:22.625921       1 log.go:194] falcon-pod-c09 requires 2 gpu(s), and currently has -1 gpus(s) in total
I1017 04:51:22.630370       1 schedule_one.go:867] "Unable to schedule pod; no fit; waiting" pod="default/falcon-pod-c09" err="0/2 nodes are available: falcon-pod-c09 requires 2 gpu but only -1 gpu in the pool.. preemption: 0/2 nodes are available: 2 No preemption victims found for incoming pod.."
I1017 04:51:55.515632       1 log.go:194] falcon-pod-c09 in Prefilter
I1017 04:51:55.515668       1 log.go:194] falcon-pod-c09 requires 2 gpu(s), and currently has 2 gpus(s) in total
I1017 04:51:55.529549       1 schedule_one.go:252] "Successfully bound pod to node" pod="default/falcon-pod-c09" node="css-host-129" evaluatedNodes=2 feasibleNodes=1
I1017 04:52:04.815040       1 log.go:194] falcon-pod-a03 in Prefilter
I1017 04:52:04.815081       1 log.go:194] falcon-pod-a03 requires 1 gpu(s), and currently has 0 gpus(s) in total
I1017 04:52:04.825526       1 schedule_one.go:867] "Unable to schedule pod; no fit; waiting" pod="default/falcon-pod-a03" err="0/2 nodes are available: falcon-pod-a03 requires 1 gpu but only 0 gpu in the pool.. preemption: 0/2 nodes are available: 2 No preemption victims found for incoming pod.."
E1017 04:52:04.825619       1 schedule_one.go:902] "Error occurred" err="Pod default/falcon-pod-a03 is already present in the active queue"
I1017 04:52:04.832000       1 log.go:194] falcon-pod-a03 in Prefilter
I1017 04:52:04.832026       1 log.go:194] falcon-pod-a03 requires 1 gpu(s), and currently has 0 gpus(s) in total
I1017 04:52:04.836979       1 schedule_one.go:867] "Unable to schedule pod; no fit; waiting" pod="default/falcon-pod-a03" err="0/2 nodes are available: falcon-pod-a03 requires 1 gpu but only 0 gpu in the pool.. preemption: 0/2 nodes are available: 2 No preemption victims found for incoming pod.."
E1017 04:52:04.837053       1 schedule_one.go:902] "Error occurred" err="Pod default/falcon-pod-a03 is already present in the active queue"
I1017 04:52:04.842133       1 log.go:194] falcon-pod-a03 in Prefilter
I1017 04:52:04.842153       1 log.go:194] falcon-pod-a03 requires 1 gpu(s), and currently has 0 gpus(s) in total
I1017 04:52:04.848370       1 schedule_one.go:867] "Unable to schedule pod; no fit; waiting" pod="default/falcon-pod-a03" err="0/2 nodes are available: falcon-pod-a03 requires 1 gpu but only 0 gpu in the pool.. preemption: 0/2 nodes are available: 2 No preemption victims found for incoming pod.."
I1017 04:54:17.302988       1 log.go:194] falcon-pod-a03 in Prefilter
I1017 04:54:17.303020       1 log.go:194] falcon-pod-a03 requires 1 gpu(s), and currently has 1 gpus(s) in total
I1017 04:54:17.315539       1 schedule_one.go:252] "Successfully bound pod to node" pod="default/falcon-pod-a03" node="css-host-129" evaluatedNodes=2 feasibleNodes=1
I1017 04:54:24.543193       1 log.go:194] falcon-pod-a09 in Prefilter
I1017 04:54:24.543224       1 log.go:194] falcon-pod-a09 requires 1 gpu(s), and currently has 0 gpus(s) in total
I1017 04:54:24.548872       1 schedule_one.go:867] "Unable to schedule pod; no fit; waiting" pod="default/falcon-pod-a09" err="0/2 nodes are available: falcon-pod-a09 requires 1 gpu but only 0 gpu in the pool.. preemption: 0/2 nodes are available: 2 No preemption victims found for incoming pod.."
E1017 04:54:24.548990       1 schedule_one.go:902] "Error occurred" err="Pod default/falcon-pod-a09 is already present in the active queue"
I1017 04:54:24.554835       1 log.go:194] falcon-pod-a09 in Prefilter
I1017 04:54:24.554858       1 log.go:194] falcon-pod-a09 requires 1 gpu(s), and currently has 0 gpus(s) in total
I1017 04:54:24.559004       1 schedule_one.go:867] "Unable to schedule pod; no fit; waiting" pod="default/falcon-pod-a09" err="0/2 nodes are available: falcon-pod-a09 requires 1 gpu but only 0 gpu in the pool.. preemption: 0/2 nodes are available: 2 No preemption victims found for incoming pod.."
I1017 04:55:33.172475       1 log.go:194] falcon-pod-a09 in Prefilter
I1017 04:55:33.172514       1 log.go:194] falcon-pod-a09 requires 1 gpu(s), and currently has 2 gpus(s) in total
I1017 04:55:33.178689       1 schedule_one.go:867] "Unable to schedule pod; no fit; waiting" pod="default/falcon-pod-a09" err="0/2 nodes are available: 2 Insufficient cpu. preemption: 0/2 nodes are available: 2 No preemption victims found for incoming pod.."
I1017 04:56:14.651528       1 log.go:194] falcon-pod-a09 in Prefilter
I1017 04:56:14.651558       1 log.go:194] falcon-pod-a09 requires 1 gpu(s), and currently has 3 gpus(s) in total
I1017 04:56:14.665835       1 schedule_one.go:252] "Successfully bound pod to node" pod="default/falcon-pod-a09" node="css-host-128" evaluatedNodes=2 feasibleNodes=1
I1017 04:56:27.796459       1 log.go:194] falcon-pod-a02 in Prefilter
I1017 04:56:27.796495       1 log.go:194] falcon-pod-a02 requires 1 gpu(s), and currently has 2 gpus(s) in total
I1017 04:56:27.802196       1 schedule_one.go:867] "Unable to schedule pod; no fit; waiting" pod="default/falcon-pod-a02" err="0/2 nodes are available: 2 Insufficient cpu. preemption: 0/2 nodes are available: 2 No preemption victims found for incoming pod.."
E1017 04:56:27.802266       1 schedule_one.go:902] "Error occurred" err="Pod default/falcon-pod-a02 is already present in the active queue"
I1017 04:56:27.807198       1 log.go:194] falcon-pod-a02 in Prefilter
I1017 04:56:27.807219       1 log.go:194] falcon-pod-a02 requires 1 gpu(s), and currently has 2 gpus(s) in total
I1017 04:56:27.812587       1 schedule_one.go:867] "Unable to schedule pod; no fit; waiting" pod="default/falcon-pod-a02" err="0/2 nodes are available: 2 Insufficient cpu. preemption: 0/2 nodes are available: 2 No preemption victims found for incoming pod.."
I1017 04:56:29.740394       1 log.go:194] falcon-pod-a02 in Prefilter
I1017 04:56:29.740429       1 log.go:194] falcon-pod-a02 requires 1 gpu(s), and currently has 4 gpus(s) in total
I1017 04:56:29.753791       1 schedule_one.go:252] "Successfully bound pod to node" pod="default/falcon-pod-a02" node="css-host-128" evaluatedNodes=2 feasibleNodes=1
I1017 04:56:44.718408       1 log.go:194] falcon-pod-a08 in Prefilter
I1017 04:56:44.718448       1 log.go:194] falcon-pod-a08 requires 1 gpu(s), and currently has 3 gpus(s) in total
I1017 04:56:44.725434       1 schedule_one.go:867] "Unable to schedule pod; no fit; waiting" pod="default/falcon-pod-a08" err="0/2 nodes are available: 2 Insufficient cpu. preemption: 0/2 nodes are available: 2 No preemption victims found for incoming pod.."
E1017 04:56:44.725522       1 schedule_one.go:902] "Error occurred" err="Pod default/falcon-pod-a08 is already present in the active queue"
I1017 04:56:44.731827       1 log.go:194] falcon-pod-a08 in Prefilter
I1017 04:56:44.731852       1 log.go:194] falcon-pod-a08 requires 1 gpu(s), and currently has 3 gpus(s) in total
I1017 04:56:44.737703       1 schedule_one.go:867] "Unable to schedule pod; no fit; waiting" pod="default/falcon-pod-a08" err="0/2 nodes are available: 2 Insufficient cpu. preemption: 0/2 nodes are available: 2 No preemption victims found for incoming pod.."
I1017 04:57:07.246567       1 log.go:194] falcon-pod-a08 in Prefilter
I1017 04:57:07.246602       1 log.go:194] falcon-pod-a08 requires 1 gpu(s), and currently has 5 gpus(s) in total
I1017 04:57:07.261199       1 schedule_one.go:252] "Successfully bound pod to node" pod="default/falcon-pod-a08" node="css-host-129" evaluatedNodes=2 feasibleNodes=1
I1017 04:57:17.014950       1 log.go:194] falcon-pod-c05 in Prefilter
I1017 04:57:17.014982       1 log.go:194] falcon-pod-c05 requires 2 gpu(s), and currently has 4 gpus(s) in total
I1017 04:57:17.021221       1 schedule_one.go:867] "Unable to schedule pod; no fit; waiting" pod="default/falcon-pod-c05" err="0/2 nodes are available: 2 Insufficient cpu. preemption: 0/2 nodes are available: 2 No preemption victims found for incoming pod.."
E1017 04:57:17.021288       1 schedule_one.go:902] "Error occurred" err="Pod default/falcon-pod-c05 is already present in the active queue"
I1017 04:57:17.026903       1 log.go:194] falcon-pod-c05 in Prefilter
I1017 04:57:17.026920       1 log.go:194] falcon-pod-c05 requires 2 gpu(s), and currently has 4 gpus(s) in total
I1017 04:57:17.032807       1 schedule_one.go:867] "Unable to schedule pod; no fit; waiting" pod="default/falcon-pod-c05" err="0/2 nodes are available: 2 Insufficient cpu. preemption: 0/2 nodes are available: 2 No preemption victims found for incoming pod.."
I1017 04:59:25.073343       1 log.go:194] falcon-pod-c05 in Prefilter
I1017 04:59:25.073378       1 log.go:194] falcon-pod-c05 requires 2 gpu(s), and currently has 5 gpus(s) in total
I1017 04:59:25.087061       1 schedule_one.go:252] "Successfully bound pod to node" pod="default/falcon-pod-c05" node="css-host-129" evaluatedNodes=2 feasibleNodes=1
I1017 04:59:34.440908       1 log.go:194] falcon-pod-a10 in Prefilter
I1017 04:59:34.440950       1 log.go:194] falcon-pod-a10 requires 1 gpu(s), and currently has 3 gpus(s) in total
I1017 04:59:34.448579       1 schedule_one.go:867] "Unable to schedule pod; no fit; waiting" pod="default/falcon-pod-a10" err="0/2 nodes are available: 2 Insufficient cpu. preemption: 0/2 nodes are available: 2 No preemption victims found for incoming pod.."
E1017 04:59:34.448670       1 schedule_one.go:902] "Error occurred" err="Pod default/falcon-pod-a10 is already present in the active queue"
I1017 04:59:34.454818       1 log.go:194] falcon-pod-a10 in Prefilter
I1017 04:59:34.454838       1 log.go:194] falcon-pod-a10 requires 1 gpu(s), and currently has 3 gpus(s) in total
I1017 04:59:34.460303       1 schedule_one.go:867] "Unable to schedule pod; no fit; waiting" pod="default/falcon-pod-a10" err="0/2 nodes are available: 2 Insufficient cpu. preemption: 0/2 nodes are available: 2 No preemption victims found for incoming pod.."
E1017 04:59:34.460375       1 schedule_one.go:902] "Error occurred" err="Pod default/falcon-pod-a10 is already present in the active queue"
I1017 04:59:34.466300       1 log.go:194] falcon-pod-a10 in Prefilter
I1017 04:59:34.466323       1 log.go:194] falcon-pod-a10 requires 1 gpu(s), and currently has 3 gpus(s) in total
I1017 04:59:34.472259       1 schedule_one.go:867] "Unable to schedule pod; no fit; waiting" pod="default/falcon-pod-a10" err="0/2 nodes are available: 2 Insufficient cpu. preemption: 0/2 nodes are available: 2 No preemption victims found for incoming pod.."
I1017 05:01:28.429676       1 log.go:194] falcon-pod-a10 in Prefilter
I1017 05:01:28.429707       1 log.go:194] falcon-pod-a10 requires 1 gpu(s), and currently has 4 gpus(s) in total
I1017 05:01:28.443055       1 schedule_one.go:252] "Successfully bound pod to node" pod="default/falcon-pod-a10" node="css-host-128" evaluatedNodes=2 feasibleNodes=1
