I1003 13:29:58.990980       1 schedule_one.go:252] "Successfully bound pod to node" pod="default/falcon-pod-03" node="css-host-129" evaluatedNodes=2 feasibleNodes=1
I1003 13:36:51.729781       1 log.go:194] falcon-pod-01 in Prefilter
I1003 13:36:51.730228       1 log.go:194] falcon-pod-01 requires 8 gpu(s), and currently has 8 gpus(s) in total
I1003 13:36:51.737060       1 log.go:194] css-host-128 has 3 gpu, falcon-pod-01 requires 8 gpu -> score: -5
I1003 13:36:51.737171       1 log.go:194] css-host-129 has 5 gpu, falcon-pod-01 requires 8 gpu -> score: -3
I1003 13:36:51.751066       1 event.go:307] "Event occurred" object="default/falcon-pod-01" fieldPath="" kind="Pod" apiVersion="v1" type="Normal" reason="Reconfig" message="Pod falcon-pod-01 needs reconfiguration"
I1003 13:38:20.250853       1 schedule_one.go:252] "Successfully bound pod to node" pod="default/falcon-pod-01" node="css-host-129" evaluatedNodes=2 feasibleNodes=2
I1003 13:39:19.407292       1 log.go:194] falcon-pod-03 in Prefilter
I1003 13:39:19.407731       1 log.go:194] falcon-pod-03 requires 5 gpu(s), and currently has 8 gpus(s) in total
I1003 13:39:19.425302       1 event.go:307] "Event occurred" object="default/falcon-pod-03" fieldPath="" kind="Pod" apiVersion="v1" type="Normal" reason="Reconfig" message="Pod falcon-pod-03 needs reconfiguration"
I1003 13:41:34.763152       1 schedule_one.go:252] "Successfully bound pod to node" pod="default/falcon-pod-03" node="css-host-128" evaluatedNodes=2 feasibleNodes=1
I1003 13:45:32.705296       1 log.go:194] falcon-pod-01 in Prefilter
I1003 13:45:32.705828       1 log.go:194] falcon-pod-01 requires 8 gpu(s), and currently has 8 gpus(s) in total
I1003 13:45:32.727350       1 event.go:307] "Event occurred" object="default/falcon-pod-01" fieldPath="" kind="Pod" apiVersion="v1" type="Normal" reason="Reconfig" message="Pod falcon-pod-01 needs reconfiguration"
I1003 13:47:53.461367       1 schedule_one.go:252] "Successfully bound pod to node" pod="default/falcon-pod-01" node="css-host-129" evaluatedNodes=2 feasibleNodes=1
I1003 13:48:59.219671       1 log.go:194] falcon-pod-03 in Prefilter
I1003 13:48:59.220154       1 log.go:194] falcon-pod-03 requires 5 gpu(s), and currently has 8 gpus(s) in total
I1003 13:48:59.237669       1 event.go:307] "Event occurred" object="default/falcon-pod-03" fieldPath="" kind="Pod" apiVersion="v1" type="Normal" reason="Reconfig" message="Pod falcon-pod-03 needs reconfiguration"
I1003 13:51:07.339274       1 schedule_one.go:252] "Successfully bound pod to node" pod="default/falcon-pod-03" node="css-host-128" evaluatedNodes=2 feasibleNodes=1
I1003 13:52:38.612799       1 log.go:194] falcon-pod-01 in Prefilter
I1003 13:52:38.613216       1 log.go:194] falcon-pod-01 requires 8 gpu(s), and currently has 8 gpus(s) in total
I1003 13:52:38.633167       1 event.go:307] "Event occurred" object="default/falcon-pod-01" fieldPath="" kind="Pod" apiVersion="v1" type="Normal" reason="Reconfig" message="Pod falcon-pod-01 needs reconfiguration"
I1003 13:54:51.733447       1 schedule_one.go:252] "Successfully bound pod to node" pod="default/falcon-pod-01" node="css-host-129" evaluatedNodes=2 feasibleNodes=1
I1003 13:55:58.974095       1 log.go:194] falcon-pod-03 in Prefilter
I1003 13:55:58.974549       1 log.go:194] falcon-pod-03 requires 5 gpu(s), and currently has 8 gpus(s) in total
I1003 13:55:58.993786       1 event.go:307] "Event occurred" object="default/falcon-pod-03" fieldPath="" kind="Pod" apiVersion="v1" type="Normal" reason="Reconfig" message="Pod falcon-pod-03 needs reconfiguration"
I1003 13:57:57.879043       1 schedule_one.go:252] "Successfully bound pod to node" pod="default/falcon-pod-03" node="css-host-128" evaluatedNodes=2 feasibleNodes=1
I1003 13:59:29.369091       1 log.go:194] falcon-pod-01 in Prefilter
I1003 13:59:29.369596       1 log.go:194] falcon-pod-01 requires 8 gpu(s), and currently has 8 gpus(s) in total
I1003 13:59:29.388530       1 event.go:307] "Event occurred" object="default/falcon-pod-01" fieldPath="" kind="Pod" apiVersion="v1" type="Normal" reason="Reconfig" message="Pod falcon-pod-01 needs reconfiguration"
I1003 14:01:19.987530       1 schedule_one.go:252] "Successfully bound pod to node" pod="default/falcon-pod-01" node="css-host-129" evaluatedNodes=2 feasibleNodes=1
I1003 14:02:49.719718       1 log.go:194] falcon-pod-03 in Prefilter
I1003 14:02:49.720225       1 log.go:194] falcon-pod-03 requires 5 gpu(s), and currently has 8 gpus(s) in total
I1003 14:02:49.739765       1 event.go:307] "Event occurred" object="default/falcon-pod-03" fieldPath="" kind="Pod" apiVersion="v1" type="Normal" reason="Reconfig" message="Pod falcon-pod-03 needs reconfiguration"
I1003 14:04:55.884291       1 schedule_one.go:252] "Successfully bound pod to node" pod="default/falcon-pod-03" node="css-host-128" evaluatedNodes=2 feasibleNodes=1
I1003 14:06:20.169786       1 log.go:194] falcon-pod-01 in Prefilter
I1003 14:06:20.170260       1 log.go:194] falcon-pod-01 requires 8 gpu(s), and currently has 8 gpus(s) in total
I1003 14:06:20.188621       1 event.go:307] "Event occurred" object="default/falcon-pod-01" fieldPath="" kind="Pod" apiVersion="v1" type="Normal" reason="Reconfig" message="Pod falcon-pod-01 needs reconfiguration"
I1003 14:08:30.099008       1 schedule_one.go:252] "Successfully bound pod to node" pod="default/falcon-pod-01" node="css-host-129" evaluatedNodes=2 feasibleNodes=1
I1003 14:09:40.529109       1 log.go:194] falcon-pod-03 in Prefilter
I1003 14:09:40.529547       1 log.go:194] falcon-pod-03 requires 5 gpu(s), and currently has 8 gpus(s) in total
I1003 14:09:40.547264       1 event.go:307] "Event occurred" object="default/falcon-pod-03" fieldPath="" kind="Pod" apiVersion="v1" type="Normal" reason="Reconfig" message="Pod falcon-pod-03 needs reconfiguration"
I1003 14:11:45.028051       1 schedule_one.go:252] "Successfully bound pod to node" pod="default/falcon-pod-03" node="css-host-128" evaluatedNodes=2 feasibleNodes=1
I1003 14:25:20.804033       1 log.go:194] falcon-pod-01 in Prefilter
I1003 14:25:20.804599       1 log.go:194] falcon-pod-01 requires 8 gpu(s), and currently has 8 gpus(s) in total
I1003 14:25:20.823531       1 event.go:307] "Event occurred" object="default/falcon-pod-01" fieldPath="" kind="Pod" apiVersion="v1" type="Normal" reason="Reconfig" message="Pod falcon-pod-01 needs reconfiguration"
I1003 14:28:23.983856       1 schedule_one.go:252] "Successfully bound pod to node" pod="default/falcon-pod-01" node="css-host-129" evaluatedNodes=2 feasibleNodes=1
I1003 14:29:55.585876       1 log.go:194] falcon-pod-01 in Prefilter
I1003 14:29:55.586377       1 log.go:194] falcon-pod-01 requires 6 gpu(s), and currently has 8 gpus(s) in total
I1003 14:29:55.605880       1 event.go:307] "Event occurred" object="default/falcon-pod-01" fieldPath="" kind="Pod" apiVersion="v1" type="Normal" reason="Reconfig" message="Pod falcon-pod-01 needs reconfiguration"
I1003 14:32:11.768855       1 schedule_one.go:252] "Successfully bound pod to node" pod="default/falcon-pod-01" node="css-host-128" evaluatedNodes=2 feasibleNodes=1
I1003 14:33:08.414789       1 log.go:194] falcon-pod-03 in Prefilter
I1003 14:33:08.415299       1 log.go:194] falcon-pod-03 requires 8 gpu(s), and currently has 8 gpus(s) in total
I1003 14:33:08.434233       1 event.go:307] "Event occurred" object="default/falcon-pod-03" fieldPath="" kind="Pod" apiVersion="v1" type="Normal" reason="Reconfig" message="Pod falcon-pod-03 needs reconfiguration"
I1003 14:35:23.767656       1 schedule_one.go:252] "Successfully bound pod to node" pod="default/falcon-pod-03" node="css-host-129" evaluatedNodes=2 feasibleNodes=1
I1003 14:37:02.347481       1 log.go:194] falcon-pod-01 in Prefilter
I1003 14:37:02.347985       1 log.go:194] falcon-pod-01 requires 6 gpu(s), and currently has 8 gpus(s) in total
I1003 14:37:02.367567       1 event.go:307] "Event occurred" object="default/falcon-pod-01" fieldPath="" kind="Pod" apiVersion="v1" type="Normal" reason="Reconfig" message="Pod falcon-pod-01 needs reconfiguration"
I1003 14:39:41.929251       1 schedule_one.go:252] "Successfully bound pod to node" pod="default/falcon-pod-01" node="css-host-128" evaluatedNodes=2 feasibleNodes=1
I1003 14:41:12.710872       1 log.go:194] falcon-pod-03 in Prefilter
I1003 14:41:12.711367       1 log.go:194] falcon-pod-03 requires 8 gpu(s), and currently has 8 gpus(s) in total
I1003 14:41:12.731196       1 event.go:307] "Event occurred" object="default/falcon-pod-03" fieldPath="" kind="Pod" apiVersion="v1" type="Normal" reason="Reconfig" message="Pod falcon-pod-03 needs reconfiguration"
I1003 14:44:25.941272       1 schedule_one.go:252] "Successfully bound pod to node" pod="default/falcon-pod-03" node="css-host-129" evaluatedNodes=2 feasibleNodes=1
I1003 14:45:33.177745       1 log.go:194] falcon-pod-01 in Prefilter
I1003 14:45:33.178214       1 log.go:194] falcon-pod-01 requires 6 gpu(s), and currently has 8 gpus(s) in total
I1003 14:45:33.193936       1 event.go:307] "Event occurred" object="default/falcon-pod-01" fieldPath="" kind="Pod" apiVersion="v1" type="Normal" reason="Reconfig" message="Pod falcon-pod-01 needs reconfiguration"
I1003 14:48:13.462220       1 schedule_one.go:252] "Successfully bound pod to node" pod="default/falcon-pod-01" node="css-host-128" evaluatedNodes=2 feasibleNodes=1
I1003 14:49:43.747029       1 log.go:194] falcon-pod-03 in Prefilter
I1003 14:49:43.747505       1 log.go:194] falcon-pod-03 requires 8 gpu(s), and currently has 8 gpus(s) in total
I1003 14:49:43.766481       1 event.go:307] "Event occurred" object="default/falcon-pod-03" fieldPath="" kind="Pod" apiVersion="v1" type="Normal" reason="Reconfig" message="Pod falcon-pod-03 needs reconfiguration"
I1003 14:52:57.249955       1 schedule_one.go:252] "Successfully bound pod to node" pod="default/falcon-pod-03" node="css-host-129" evaluatedNodes=2 feasibleNodes=1
I1003 14:54:03.932139       1 log.go:194] falcon-pod-01 in Prefilter
I1003 14:54:03.932634       1 log.go:194] falcon-pod-01 requires 6 gpu(s), and currently has 8 gpus(s) in total
I1003 14:54:03.954205       1 event.go:307] "Event occurred" object="default/falcon-pod-01" fieldPath="" kind="Pod" apiVersion="v1" type="Normal" reason="Reconfig" message="Pod falcon-pod-01 needs reconfiguration"
E1003 15:06:10.357536       1 schedule_one.go:883] "Error scheduling pod; retrying" err="" pod="default/falcon-pod-01"
I1003 15:06:10.357593       1 schedule_one.go:890] "Pod doesn't exist in informer cache" pod="default/falcon-pod-01" err="pod \"falcon-pod-01\" not found"
E1003 15:06:10.361764       1 schedule_one.go:928] "Error updating pod" err="pods \"falcon-pod-01\" not found" pod="default/falcon-pod-01"
I1004 00:27:03.635373       1 log.go:194] falcon-pod-01 in Prefilter
I1004 00:27:03.635929       1 log.go:194] falcon-pod-01 requires 6 gpu(s), and currently has 8 gpus(s) in total
I1004 00:27:03.667202       1 schedule_one.go:252] "Successfully bound pod to node" pod="default/falcon-pod-01" node="css-host-128" evaluatedNodes=2 feasibleNodes=1
I1004 00:28:57.070165       1 log.go:194] falcon-pod-03 in Prefilter
I1004 00:28:57.070590       1 log.go:194] falcon-pod-03 requires 8 gpu(s), and currently has 8 gpus(s) in total
I1004 00:28:57.090496       1 event.go:307] "Event occurred" object="default/falcon-pod-03" fieldPath="" kind="Pod" apiVersion="v1" type="Normal" reason="Reconfig" message="Pod falcon-pod-03 needs reconfiguration"
I1004 00:31:50.056324       1 schedule_one.go:252] "Successfully bound pod to node" pod="default/falcon-pod-03" node="css-host-129" evaluatedNodes=2 feasibleNodes=1
I1004 00:45:13.364490       1 log.go:194] falcon-pod-01 in Prefilter
I1004 00:45:13.364996       1 log.go:194] falcon-pod-01 requires 6 gpu(s), and currently has 8 gpus(s) in total
I1004 00:45:13.394764       1 event.go:307] "Event occurred" object="default/falcon-pod-01" fieldPath="" kind="Pod" apiVersion="v1" type="Normal" reason="Reconfig" message="Pod falcon-pod-01 needs reconfiguration"
I1004 00:47:30.594087       1 schedule_one.go:252] "Successfully bound pod to node" pod="default/falcon-pod-01" node="css-host-128" evaluatedNodes=2 feasibleNodes=1
I1004 00:50:30.982892       1 log.go:194] falcon-pod-03 in Prefilter
I1004 00:50:30.983384       1 log.go:194] falcon-pod-03 requires 8 gpu(s), and currently has 8 gpus(s) in total
I1004 00:50:31.002301       1 event.go:307] "Event occurred" object="default/falcon-pod-03" fieldPath="" kind="Pod" apiVersion="v1" type="Normal" reason="Reconfig" message="Pod falcon-pod-03 needs reconfiguration"
I1004 00:52:48.528682       1 schedule_one.go:252] "Successfully bound pod to node" pod="default/falcon-pod-03" node="css-host-129" evaluatedNodes=2 feasibleNodes=1
I1004 00:54:42.095928       1 log.go:194] falcon-pod-01 in Prefilter
I1004 00:54:42.096448       1 log.go:194] falcon-pod-01 requires 6 gpu(s), and currently has 8 gpus(s) in total
I1004 00:54:42.322066       1 event.go:307] "Event occurred" object="default/falcon-pod-01" fieldPath="" kind="Pod" apiVersion="v1" type="Normal" reason="Reconfig" message="Pod falcon-pod-01 needs reconfiguration"
I1004 00:57:23.818293       1 schedule_one.go:252] "Successfully bound pod to node" pod="default/falcon-pod-01" node="css-host-128" evaluatedNodes=2 feasibleNodes=1
I1004 00:58:58.084156       1 log.go:194] falcon-pod-03 in Prefilter
I1004 00:58:58.084553       1 log.go:194] falcon-pod-03 requires 8 gpu(s), and currently has 8 gpus(s) in total
I1004 00:58:58.103492       1 event.go:307] "Event occurred" object="default/falcon-pod-03" fieldPath="" kind="Pod" apiVersion="v1" type="Normal" reason="Reconfig" message="Pod falcon-pod-03 needs reconfiguration"
I1004 01:01:50.869379       1 schedule_one.go:252] "Successfully bound pod to node" pod="default/falcon-pod-03" node="css-host-129" evaluatedNodes=2 feasibleNodes=1
